ply
format ascii 1.0
comment : MagicaVoxel @ Ephtracy
element vertex 3132
property float x
property float y
property float z
property uchar red
property uchar green
property uchar blue
end_header
-5 -11 0 68 68 68
7 -11 0 68 68 68
-5 -10 0 68 68 68
7 -10 0 68 68 68
-5 -9 0 68 68 68
7 -9 0 68 68 68
-5 9 0 68 68 68
7 9 0 68 68 68
-5 10 0 68 68 68
7 10 0 68 68 68
-5 11 0 68 68 68
7 11 0 68 68 68
-5 -14 1 51 166 184
7 -14 1 51 166 184
-5 -13 1 51 166 184
7 -13 1 51 166 184
-5 -12 1 68 68 68
-4 -12 1 187 187 187
-3 -12 1 187 187 187
-2 -12 1 187 187 187
-1 -12 1 187 187 187
0 -12 1 187 187 187
1 -12 1 187 187 187
2 -12 1 187 187 187
3 -12 1 187 187 187
4 -12 1 187 187 187
5 -12 1 187 187 187
6 -12 1 187 187 187
7 -12 1 68 68 68
-5 -11 1 136 136 136
-4 -11 1 238 238 238
-3 -11 1 238 238 238
-2 -11 1 238 238 238
-1 -11 1 238 238 238
0 -11 1 238 238 238
1 -11 1 238 238 238
2 -11 1 238 238 238
3 -11 1 238 238 238
4 -11 1 238 238 238
5 -11 1 238 238 238
6 -11 1 238 238 238
7 -11 1 136 136 136
-5 -10 1 136 136 136
-4 -10 1 238 238 238
-3 -10 1 238 238 238
-2 -10 1 238 238 238
-1 -10 1 238 238 238
0 -10 1 238 238 238
1 -10 1 238 238 238
2 -10 1 238 238 238
3 -10 1 238 238 238
4 -10 1 238 238 238
5 -10 1 238 238 238
6 -10 1 238 238 238
7 -10 1 136 136 136
-5 -9 1 136 136 136
-4 -9 1 238 238 238
-3 -9 1 238 238 238
-2 -9 1 238 238 238
-1 -9 1 238 238 238
0 -9 1 238 238 238
1 -9 1 238 238 238
2 -9 1 238 238 238
3 -9 1 238 238 238
4 -9 1 238 238 238
5 -9 1 238 238 238
6 -9 1 238 238 238
7 -9 1 136 136 136
-5 -8 1 68 68 68
-4 -8 1 238 238 238
-3 -8 1 238 238 238
-2 -8 1 238 238 238
-1 -8 1 238 238 238
0 -8 1 238 238 238
1 -8 1 238 238 238
2 -8 1 238 238 238
3 -8 1 238 238 238
4 -8 1 238 238 238
5 -8 1 238 238 238
6 -8 1 238 238 238
7 -8 1 68 68 68
-5 -7 1 51 166 184
-4 -7 1 238 238 238
-3 -7 1 238 238 238
-2 -7 1 238 238 238
-1 -7 1 238 238 238
0 -7 1 238 238 238
1 -7 1 238 238 238
2 -7 1 238 238 238
3 -7 1 238 238 238
4 -7 1 238 238 238
5 -7 1 238 238 238
6 -7 1 238 238 238
7 -7 1 51 166 184
-5 -6 1 51 166 184
-4 -6 1 238 238 238
-3 -6 1 238 238 238
-2 -6 1 238 238 238
-1 -6 1 238 238 238
0 -6 1 238 238 238
1 -6 1 238 238 238
2 -6 1 238 238 238
3 -6 1 238 238 238
4 -6 1 238 238 238
5 -6 1 238 238 238
6 -6 1 238 238 238
7 -6 1 51 166 184
-5 -5 1 51 166 184
-4 -5 1 238 238 238
-3 -5 1 238 238 238
-2 -5 1 238 238 238
-1 -5 1 238 238 238
0 -5 1 238 238 238
1 -5 1 238 238 238
2 -5 1 238 238 238
3 -5 1 238 238 238
4 -5 1 238 238 238
5 -5 1 238 238 238
6 -5 1 238 238 238
7 -5 1 51 166 184
-5 -4 1 51 166 184
-4 -4 1 238 238 238
-3 -4 1 238 238 238
-2 -4 1 238 238 238
-1 -4 1 238 238 238
0 -4 1 238 238 238
1 -4 1 238 238 238
2 -4 1 238 238 238
3 -4 1 238 238 238
4 -4 1 238 238 238
5 -4 1 238 238 238
6 -4 1 238 238 238
7 -4 1 51 166 184
-5 -3 1 51 166 184
-4 -3 1 238 238 238
-3 -3 1 238 238 238
-2 -3 1 238 238 238
-1 -3 1 238 238 238
0 -3 1 238 238 238
1 -3 1 238 238 238
2 -3 1 238 238 238
3 -3 1 238 238 238
4 -3 1 238 238 238
5 -3 1 238 238 238
6 -3 1 238 238 238
7 -3 1 51 166 184
-5 -2 1 51 166 184
-4 -2 1 238 238 238
-3 -2 1 238 238 238
-2 -2 1 238 238 238
-1 -2 1 238 238 238
0 -2 1 238 238 238
1 -2 1 238 238 238
2 -2 1 238 238 238
3 -2 1 238 238 238
4 -2 1 238 238 238
5 -2 1 238 238 238
6 -2 1 238 238 238
7 -2 1 51 166 184
-5 -1 1 51 166 184
-4 -1 1 238 238 238
-3 -1 1 238 238 238
-2 -1 1 238 238 238
-1 -1 1 238 238 238
0 -1 1 238 238 238
1 -1 1 238 238 238
2 -1 1 238 238 238
3 -1 1 238 238 238
4 -1 1 238 238 238
5 -1 1 238 238 238
6 -1 1 238 238 238
7 -1 1 51 166 184
-5 0 1 51 166 184
-4 0 1 238 238 238
-3 0 1 238 238 238
-2 0 1 238 238 238
-1 0 1 238 238 238
0 0 1 238 238 238
1 0 1 238 238 238
2 0 1 238 238 238
3 0 1 238 238 238
4 0 1 238 238 238
5 0 1 238 238 238
6 0 1 238 238 238
7 0 1 51 166 184
-5 1 1 51 166 184
-4 1 1 238 238 238
-3 1 1 238 238 238
-2 1 1 238 238 238
-1 1 1 238 238 238
0 1 1 238 238 238
1 1 1 238 238 238
2 1 1 238 238 238
3 1 1 238 238 238
4 1 1 238 238 238
5 1 1 238 238 238
6 1 1 238 238 238
7 1 1 51 166 184
-5 2 1 51 166 184
-4 2 1 238 238 238
-3 2 1 238 238 238
-2 2 1 238 238 238
-1 2 1 238 238 238
0 2 1 238 238 238
1 2 1 238 238 238
2 2 1 238 238 238
3 2 1 238 238 238
4 2 1 238 238 238
5 2 1 238 238 238
6 2 1 238 238 238
7 2 1 51 166 184
-5 3 1 51 166 184
-4 3 1 238 238 238
-3 3 1 238 238 238
-2 3 1 238 238 238
-1 3 1 238 238 238
0 3 1 238 238 238
1 3 1 238 238 238
2 3 1 238 238 238
3 3 1 238 238 238
4 3 1 238 238 238
5 3 1 238 238 238
6 3 1 238 238 238
7 3 1 51 166 184
-5 4 1 51 166 184
-4 4 1 238 238 238
-3 4 1 238 238 238
-2 4 1 238 238 238
-1 4 1 238 238 238
0 4 1 238 238 238
1 4 1 238 238 238
2 4 1 238 238 238
3 4 1 238 238 238
4 4 1 238 238 238
5 4 1 238 238 238
6 4 1 238 238 238
7 4 1 51 166 184
-5 5 1 51 166 184
-4 5 1 238 238 238
-3 5 1 238 238 238
-2 5 1 238 238 238
-1 5 1 238 238 238
0 5 1 238 238 238
1 5 1 238 238 238
2 5 1 238 238 238
3 5 1 238 238 238
4 5 1 238 238 238
5 5 1 238 238 238
6 5 1 238 238 238
7 5 1 51 166 184
-5 6 1 51 166 184
-4 6 1 238 238 238
-3 6 1 238 238 238
-2 6 1 238 238 238
-1 6 1 238 238 238
0 6 1 238 238 238
1 6 1 238 238 238
2 6 1 238 238 238
3 6 1 238 238 238
4 6 1 238 238 238
5 6 1 238 238 238
6 6 1 238 238 238
7 6 1 51 166 184
-5 7 1 51 166 184
-4 7 1 238 238 238
-3 7 1 238 238 238
-2 7 1 238 238 238
-1 7 1 238 238 238
0 7 1 238 238 238
1 7 1 238 238 238
2 7 1 238 238 238
3 7 1 238 238 238
4 7 1 238 238 238
5 7 1 238 238 238
6 7 1 238 238 238
7 7 1 51 166 184
-5 8 1 68 68 68
-4 8 1 238 238 238
-3 8 1 238 238 238
-2 8 1 238 238 238
-1 8 1 238 238 238
0 8 1 238 238 238
1 8 1 238 238 238
2 8 1 238 238 238
3 8 1 238 238 238
4 8 1 238 238 238
5 8 1 238 238 238
6 8 1 238 238 238
7 8 1 68 68 68
-5 9 1 136 136 136
-4 9 1 238 238 238
-3 9 1 238 238 238
-2 9 1 238 238 238
-1 9 1 238 238 238
0 9 1 238 238 238
1 9 1 238 238 238
2 9 1 238 238 238
3 9 1 238 238 238
4 9 1 238 238 238
5 9 1 238 238 238
6 9 1 238 238 238
7 9 1 136 136 136
-5 10 1 136 136 136
-4 10 1 238 238 238
-3 10 1 238 238 238
-2 10 1 238 238 238
-1 10 1 238 238 238
0 10 1 238 238 238
1 10 1 238 238 238
2 10 1 238 238 238
3 10 1 238 238 238
4 10 1 238 238 238
5 10 1 238 238 238
6 10 1 238 238 238
7 10 1 136 136 136
-5 11 1 136 136 136
-4 11 1 238 238 238
-3 11 1 238 238 238
-2 11 1 238 238 238
-1 11 1 238 238 238
0 11 1 238 238 238
1 11 1 238 238 238
2 11 1 238 238 238
3 11 1 238 238 238
4 11 1 238 238 238
5 11 1 238 238 238
6 11 1 238 238 238
7 11 1 136 136 136
-5 12 1 68 68 68
-4 12 1 238 238 238
-3 12 1 238 238 238
-2 12 1 238 238 238
-1 12 1 238 238 238
0 12 1 238 238 238
1 12 1 238 238 238
2 12 1 238 238 238
3 12 1 238 238 238
4 12 1 238 238 238
5 12 1 238 238 238
6 12 1 238 238 238
7 12 1 68 68 68
-5 13 1 51 166 184
-4 13 1 51 166 184
-3 13 1 238 238 238
-2 13 1 238 238 238
-1 13 1 238 238 238
0 13 1 238 238 238
1 13 1 238 238 238
2 13 1 238 238 238
3 13 1 238 238 238
4 13 1 238 238 238
5 13 1 238 238 238
6 13 1 51 166 184
7 13 1 51 166 184
-5 14 1 51 166 184
-4 14 1 51 166 184
-3 14 1 187 187 187
-2 14 1 187 187 187
-1 14 1 187 187 187
0 14 1 187 187 187
1 14 1 187 187 187
2 14 1 187 187 187
3 14 1 187 187 187
4 14 1 187 187 187
5 14 1 187 187 187
6 14 1 51 166 184
7 14 1 51 166 184
-6 -17 2 119 119 119
-5 -17 2 119 119 119
-4 -17 2 119 119 119
-3 -17 2 119 119 119
-2 -17 2 119 119 119
-1 -17 2 119 119 119
0 -17 2 119 119 119
1 -17 2 119 119 119
2 -17 2 119 119 119
3 -17 2 119 119 119
4 -17 2 119 119 119
5 -17 2 119 119 119
6 -17 2 119 119 119
7 -17 2 119 119 119
8 -17 2 119 119 119
-6 -16 2 119 119 119
-5 -16 2 119 119 119
-4 -16 2 119 119 119
-3 -16 2 119 119 119
-2 -16 2 119 119 119
-1 -16 2 119 119 119
0 -16 2 119 119 119
1 -16 2 119 119 119
2 -16 2 119 119 119
3 -16 2 119 119 119
4 -16 2 119 119 119
5 -16 2 119 119 119
6 -16 2 119 119 119
7 -16 2 119 119 119
8 -16 2 119 119 119
-6 -15 2 119 119 119
-5 -15 2 119 119 119
-4 -15 2 119 119 119
-3 -15 2 119 119 119
-2 -15 2 119 119 119
-1 -15 2 119 119 119
0 -15 2 119 119 119
1 -15 2 119 119 119
2 -15 2 119 119 119
3 -15 2 119 119 119
4 -15 2 119 119 119
5 -15 2 119 119 119
6 -15 2 119 119 119
7 -15 2 119 119 119
8 -15 2 119 119 119
-5 -14 2 51 166 184
-4 -14 2 187 187 187
-3 -14 2 187 187 187
-2 -14 2 187 187 187
-1 -14 2 187 187 187
0 -14 2 187 187 187
1 -14 2 187 187 187
2 -14 2 187 187 187
3 -14 2 187 187 187
4 -14 2 187 187 187
5 -14 2 187 187 187
6 -14 2 187 187 187
7 -14 2 51 166 184
-5 -13 2 51 166 184
-4 -13 2 187 187 187
-3 -13 2 187 187 187
-2 -13 2 187 187 187
-1 -13 2 187 187 187
0 -13 2 187 187 187
1 -13 2 187 187 187
2 -13 2 187 187 187
3 -13 2 187 187 187
4 -13 2 187 187 187
5 -13 2 187 187 187
6 -13 2 187 187 187
7 -13 2 51 166 184
-5 -12 2 68 68 68
-4 -12 2 238 238 238
-3 -12 2 238 238 238
-2 -12 2 238 238 238
-1 -12 2 238 238 238
0 -12 2 238 238 238
1 -12 2 238 238 238
2 -12 2 238 238 238
3 -12 2 238 238 238
4 -12 2 238 238 238
5 -12 2 238 238 238
6 -12 2 238 238 238
7 -12 2 68 68 68
-5 -11 2 136 136 136
-4 -11 2 238 238 238
-3 -11 2 238 238 238
-2 -11 2 51 166 184
-1 -11 2 51 166 184
0 -11 2 51 166 184
1 -11 2 51 166 184
2 -11 2 51 166 184
3 -11 2 51 166 184
4 -11 2 51 166 184
5 -11 2 238 238 238
6 -11 2 238 238 238
7 -11 2 136 136 136
-5 -10 2 136 136 136
-4 -10 2 68 68 68
-3 -10 2 238 238 238
-2 -10 2 51 166 184
-1 -10 2 51 166 184
0 -10 2 51 166 184
1 -10 2 51 166 184
2 -10 2 51 166 184
3 -10 2 51 166 184
4 -10 2 51 166 184
5 -10 2 68 68 68
6 -10 2 68 68 68
7 -10 2 136 136 136
-5 -9 2 136 136 136
-4 -9 2 170 170 170
-3 -9 2 238 238 238
-2 -9 2 51 166 184
-1 -9 2 51 166 184
0 -9 2 51 166 184
1 -9 2 51 166 184
2 -9 2 51 166 184
3 -9 2 51 166 184
4 -9 2 51 166 184
5 -9 2 170 170 170
6 -9 2 170 170 170
7 -9 2 136 136 136
-5 -8 2 68 68 68
-4 -8 2 170 170 170
-3 -8 2 238 238 238
-2 -8 2 51 166 184
-1 -8 2 51 166 184
0 -8 2 51 166 184
1 -8 2 51 166 184
2 -8 2 51 166 184
3 -8 2 51 166 184
4 -8 2 51 166 184
5 -8 2 170 170 170
6 -8 2 170 170 170
7 -8 2 68 68 68
-5 -7 2 51 166 184
-4 -7 2 170 170 170
-3 -7 2 238 238 238
-2 -7 2 51 166 184
-1 -7 2 51 166 184
0 -7 2 51 166 184
1 -7 2 51 166 184
2 -7 2 51 166 184
3 -7 2 51 166 184
4 -7 2 51 166 184
5 -7 2 170 170 170
6 -7 2 170 170 170
7 -7 2 51 166 184
-5 -6 2 51 166 184
-4 -6 2 68 68 68
-3 -6 2 238 238 238
-2 -6 2 51 166 184
-1 -6 2 51 166 184
0 -6 2 51 166 184
1 -6 2 51 166 184
2 -6 2 51 166 184
3 -6 2 51 166 184
4 -6 2 51 166 184
5 -6 2 68 68 68
6 -6 2 68 68 68
7 -6 2 51 166 184
-5 -5 2 51 166 184
-4 -5 2 238 238 238
-3 -5 2 238 238 238
-2 -5 2 51 166 184
-1 -5 2 51 166 184
0 -5 2 51 166 184
1 -5 2 51 166 184
2 -5 2 51 166 184
3 -5 2 51 166 184
4 -5 2 51 166 184
5 -5 2 238 238 238
6 -5 2 238 238 238
7 -5 2 51 166 184
-5 -4 2 51 166 184
-4 -4 2 238 238 238
-3 -4 2 238 238 238
-2 -4 2 51 166 184
-1 -4 2 51 166 184
0 -4 2 51 166 184
1 -4 2 51 166 184
2 -4 2 51 166 184
3 -4 2 51 166 184
4 -4 2 51 166 184
5 -4 2 238 238 238
6 -4 2 238 238 238
7 -4 2 51 166 184
-5 -3 2 51 166 184
-4 -3 2 238 238 238
-3 -3 2 238 238 238
-2 -3 2 51 166 184
-1 -3 2 51 166 184
0 -3 2 51 166 184
1 -3 2 51 166 184
2 -3 2 51 166 184
3 -3 2 51 166 184
4 -3 2 51 166 184
5 -3 2 238 238 238
6 -3 2 238 238 238
7 -3 2 51 166 184
-5 -2 2 51 166 184
-4 -2 2 238 238 238
-3 -2 2 238 238 238
-2 -2 2 51 166 184
-1 -2 2 51 166 184
0 -2 2 51 166 184
1 -2 2 51 166 184
2 -2 2 51 166 184
3 -2 2 51 166 184
4 -2 2 51 166 184
5 -2 2 238 238 238
6 -2 2 238 238 238
7 -2 2 51 166 184
-5 -1 2 51 166 184
-4 -1 2 238 238 238
-3 -1 2 238 238 238
-2 -1 2 51 166 184
-1 -1 2 51 166 184
0 -1 2 51 166 184
1 -1 2 51 166 184
2 -1 2 51 166 184
3 -1 2 51 166 184
4 -1 2 51 166 184
5 -1 2 238 238 238
6 -1 2 238 238 238
7 -1 2 51 166 184
-5 0 2 247 194 66
-4 0 2 238 238 238
-3 0 2 238 238 238
-2 0 2 51 166 184
-1 0 2 51 166 184
0 0 2 51 166 184
1 0 2 51 166 184
2 0 2 51 166 184
3 0 2 51 166 184
4 0 2 51 166 184
5 0 2 238 238 238
6 0 2 238 238 238
7 0 2 247 194 66
-5 1 2 247 194 66
-4 1 2 238 238 238
-3 1 2 238 238 238
-2 1 2 51 166 184
-1 1 2 51 166 184
0 1 2 51 166 184
1 1 2 51 166 184
2 1 2 51 166 184
3 1 2 51 166 184
4 1 2 51 166 184
5 1 2 238 238 238
6 1 2 238 238 238
7 1 2 247 194 66
-5 2 2 51 166 184
-4 2 2 238 238 238
-3 2 2 238 238 238
-2 2 2 51 166 184
-1 2 2 51 166 184
0 2 2 51 166 184
1 2 2 51 166 184
2 2 2 51 166 184
3 2 2 51 166 184
4 2 2 51 166 184
5 2 2 238 238 238
6 2 2 238 238 238
7 2 2 51 166 184
-5 3 2 51 166 184
-4 3 2 238 238 238
-3 3 2 238 238 238
-2 3 2 51 166 184
-1 3 2 51 166 184
0 3 2 51 166 184
1 3 2 51 166 184
2 3 2 51 166 184
3 3 2 51 166 184
4 3 2 51 166 184
5 3 2 238 238 238
6 3 2 238 238 238
7 3 2 51 166 184
-5 4 2 51 166 184
-4 4 2 238 238 238
-3 4 2 238 238 238
-2 4 2 51 166 184
-1 4 2 51 166 184
0 4 2 51 166 184
1 4 2 51 166 184
2 4 2 51 166 184
3 4 2 51 166 184
4 4 2 51 166 184
5 4 2 238 238 238
6 4 2 238 238 238
7 4 2 51 166 184
-5 5 2 51 166 184
-4 5 2 68 68 68
-3 5 2 238 238 238
-2 5 2 51 166 184
-1 5 2 51 166 184
0 5 2 51 166 184
1 5 2 51 166 184
2 5 2 51 166 184
3 5 2 51 166 184
4 5 2 51 166 184
5 5 2 68 68 68
6 5 2 68 68 68
7 5 2 51 166 184
-5 6 2 51 166 184
-4 6 2 170 170 170
-3 6 2 238 238 238
-2 6 2 51 166 184
-1 6 2 51 166 184
0 6 2 51 166 184
1 6 2 51 166 184
2 6 2 51 166 184
3 6 2 51 166 184
4 6 2 51 166 184
5 6 2 170 170 170
6 6 2 170 170 170
7 6 2 51 166 184
-5 7 2 51 166 184
-4 7 2 170 170 170
-3 7 2 238 238 238
-2 7 2 51 166 184
-1 7 2 51 166 184
0 7 2 51 166 184
1 7 2 51 166 184
2 7 2 51 166 184
3 7 2 51 166 184
4 7 2 51 166 184
5 7 2 170 170 170
6 7 2 170 170 170
7 7 2 51 166 184
-5 8 2 68 68 68
-4 8 2 170 170 170
-3 8 2 238 238 238
-2 8 2 51 166 184
-1 8 2 51 166 184
0 8 2 51 166 184
1 8 2 51 166 184
2 8 2 51 166 184
3 8 2 51 166 184
4 8 2 51 166 184
5 8 2 170 170 170
6 8 2 170 170 170
7 8 2 68 68 68
-5 9 2 136 136 136
-4 9 2 68 68 68
-3 9 2 238 238 238
-2 9 2 51 166 184
-1 9 2 51 166 184
0 9 2 51 166 184
1 9 2 51 166 184
2 9 2 51 166 184
3 9 2 51 166 184
4 9 2 51 166 184
5 9 2 68 68 68
6 9 2 68 68 68
7 9 2 136 136 136
-5 10 2 136 136 136
-4 10 2 238 238 238
-3 10 2 238 238 238
-2 10 2 238 238 238
-1 10 2 238 238 238
0 10 2 238 238 238
1 10 2 238 238 238
2 10 2 238 238 238
3 10 2 238 238 238
4 10 2 238 238 238
5 10 2 238 238 238
6 10 2 238 238 238
7 10 2 136 136 136
-5 11 2 136 136 136
-4 11 2 238 238 238
-3 11 2 238 238 238
-2 11 2 238 238 238
-1 11 2 238 238 238
0 11 2 238 238 238
1 11 2 238 238 238
2 11 2 238 238 238
3 11 2 238 238 238
4 11 2 238 238 238
5 11 2 238 238 238
6 11 2 238 238 238
7 11 2 136 136 136
-5 12 2 68 68 68
-4 12 2 238 238 238
-3 12 2 238 238 238
-2 12 2 238 238 238
-1 12 2 238 238 238
0 12 2 238 238 238
1 12 2 238 238 238
2 12 2 238 238 238
3 12 2 238 238 238
4 12 2 238 238 238
5 12 2 238 238 238
6 12 2 238 238 238
7 12 2 68 68 68
-5 13 2 51 166 184
-4 13 2 51 166 184
-3 13 2 238 238 238
-2 13 2 238 238 238
-1 13 2 238 238 238
0 13 2 238 238 238
1 13 2 238 238 238
2 13 2 238 238 238
3 13 2 238 238 238
4 13 2 238 238 238
5 13 2 238 238 238
6 13 2 51 166 184
7 13 2 51 166 184
-5 14 2 51 166 184
-4 14 2 51 166 184
-3 14 2 238 238 238
-2 14 2 238 238 238
-1 14 2 238 238 238
0 14 2 238 238 238
1 14 2 238 238 238
2 14 2 238 238 238
3 14 2 238 238 238
4 14 2 238 238 238
5 14 2 238 238 238
6 14 2 51 166 184
7 14 2 51 166 184
-6 15 2 119 119 119
-5 15 2 187 187 187
-4 15 2 187 187 187
-3 15 2 187 187 187
-2 15 2 187 187 187
-1 15 2 187 187 187
0 15 2 187 187 187
1 15 2 187 187 187
2 15 2 187 187 187
3 15 2 187 187 187
4 15 2 187 187 187
5 15 2 187 187 187
6 15 2 187 187 187
7 15 2 187 187 187
8 15 2 119 119 119
-6 16 2 119 119 119
-5 16 2 119 119 119
-4 16 2 119 119 119
-3 16 2 119 119 119
-2 16 2 119 119 119
-1 16 2 119 119 119
0 16 2 119 119 119
1 16 2 119 119 119
2 16 2 119 119 119
3 16 2 119 119 119
4 16 2 119 119 119
5 16 2 119 119 119
6 16 2 119 119 119
7 16 2 119 119 119
8 16 2 119 119 119
-6 -17 3 119 119 119
-5 -17 3 119 119 119
-4 -17 3 119 119 119
-3 -17 3 119 119 119
-2 -17 3 119 119 119
-1 -17 3 119 119 119
0 -17 3 119 119 119
1 -17 3 119 119 119
2 -17 3 119 119 119
3 -17 3 119 119 119
4 -17 3 119 119 119
5 -17 3 119 119 119
6 -17 3 119 119 119
7 -17 3 119 119 119
8 -17 3 119 119 119
-6 -16 3 119 119 119
-5 -16 3 119 119 119
-4 -16 3 119 119 119
-3 -16 3 119 119 119
-2 -16 3 119 119 119
-1 -16 3 119 119 119
0 -16 3 119 119 119
1 -16 3 119 119 119
2 -16 3 119 119 119
3 -16 3 119 119 119
4 -16 3 119 119 119
5 -16 3 119 119 119
6 -16 3 119 119 119
7 -16 3 119 119 119
8 -16 3 119 119 119
-6 -15 3 119 119 119
-5 -15 3 119 119 119
-4 -15 3 119 119 119
-3 -15 3 119 119 119
-2 -15 3 119 119 119
-1 -15 3 119 119 119
0 -15 3 119 119 119
1 -15 3 119 119 119
2 -15 3 119 119 119
3 -15 3 119 119 119
4 -15 3 119 119 119
5 -15 3 119 119 119
6 -15 3 119 119 119
7 -15 3 119 119 119
8 -15 3 119 119 119
-5 -14 3 51 166 184
-4 -14 3 238 238 238
-3 -14 3 119 119 119
-2 -14 3 119 119 119
-1 -14 3 238 238 238
0 -14 3 238 238 238
1 -14 3 238 238 238
2 -14 3 238 238 238
3 -14 3 238 238 238
4 -14 3 119 119 119
5 -14 3 119 119 119
6 -14 3 238 238 238
7 -14 3 51 166 184
-5 -13 3 51 166 184
-4 -13 3 238 238 238
-3 -13 3 51 166 184
-2 -13 3 51 166 184
-1 -13 3 238 238 238
0 -13 3 238 238 238
1 -13 3 238 238 238
2 -13 3 238 238 238
3 -13 3 238 238 238
4 -13 3 51 166 184
5 -13 3 51 166 184
6 -13 3 238 238 238
7 -13 3 51 166 184
-5 -12 3 68 68 68
-4 -12 3 238 238 238
-3 -12 3 238 238 238
-2 -12 3 51 166 184
-1 -12 3 51 166 184
0 -12 3 51 166 184
1 -12 3 51 166 184
2 -12 3 51 166 184
3 -12 3 51 166 184
4 -12 3 51 166 184
5 -12 3 238 238 238
6 -12 3 238 238 238
7 -12 3 68 68 68
-5 -11 3 136 136 136
-4 -11 3 238 238 238
-3 -11 3 238 238 238
-2 -11 3 51 166 184
-1 -11 3 51 166 184
0 -11 3 51 166 184
1 -11 3 51 166 184
2 -11 3 51 166 184
3 -11 3 51 166 184
4 -11 3 51 166 184
5 -11 3 238 238 238
6 -11 3 238 238 238
7 -11 3 136 136 136
-5 -10 3 136 136 136
-4 -10 3 68 68 68
-3 -10 3 51 166 184
-2 -10 3 51 166 184
-1 -10 3 51 166 184
0 -10 3 51 166 184
1 -10 3 51 166 184
2 -10 3 51 166 184
3 -10 3 51 166 184
4 -10 3 51 166 184
5 -10 3 68 68 68
6 -10 3 68 68 68
7 -10 3 136 136 136
-5 -9 3 136 136 136
-4 -9 3 170 170 170
-3 -9 3 51 166 184
-2 -9 3 51 166 184
-1 -9 3 51 166 184
0 -9 3 51 166 184
1 -9 3 51 166 184
2 -9 3 51 166 184
3 -9 3 51 166 184
4 -9 3 51 166 184
5 -9 3 170 170 170
6 -9 3 170 170 170
7 -9 3 136 136 136
-5 -8 3 68 68 68
-4 -8 3 170 170 170
-3 -8 3 51 166 184
-2 -8 3 51 166 184
-1 -8 3 51 166 184
0 -8 3 51 166 184
1 -8 3 51 166 184
2 -8 3 51 166 184
3 -8 3 51 166 184
4 -8 3 51 166 184
5 -8 3 170 170 170
6 -8 3 170 170 170
7 -8 3 68 68 68
-5 -7 3 51 166 184
-4 -7 3 170 170 170
-3 -7 3 51 166 184
-2 -7 3 51 166 184
-1 -7 3 51 166 184
0 -7 3 51 166 184
1 -7 3 51 166 184
2 -7 3 51 166 184
3 -7 3 51 166 184
4 -7 3 51 166 184
5 -7 3 170 170 170
6 -7 3 170 170 170
7 -7 3 51 166 184
-5 -6 3 51 166 184
-4 -6 3 68 68 68
-3 -6 3 51 166 184
-2 -6 3 51 166 184
-1 -6 3 51 166 184
0 -6 3 51 166 184
1 -6 3 51 166 184
2 -6 3 51 166 184
3 -6 3 51 166 184
4 -6 3 51 166 184
5 -6 3 68 68 68
6 -6 3 68 68 68
7 -6 3 51 166 184
-5 -5 3 51 166 184
-4 -5 3 238 238 238
-3 -5 3 238 238 238
-2 -5 3 238 238 238
-1 -5 3 238 238 238
0 -5 3 238 238 238
1 -5 3 238 238 238
2 -5 3 238 238 238
3 -5 3 238 238 238
4 -5 3 238 238 238
5 -5 3 238 238 238
6 -5 3 238 238 238
7 -5 3 51 166 184
-5 -4 3 51 166 184
-4 -4 3 238 238 238
-3 -4 3 238 238 238
-2 -4 3 238 238 238
-1 -4 3 238 238 238
0 -4 3 238 238 238
1 -4 3 238 238 238
2 -4 3 238 238 238
3 -4 3 238 238 238
4 -4 3 238 238 238
5 -4 3 238 238 238
6 -4 3 238 238 238
7 -4 3 51 166 184
-5 -3 3 51 166 184
-4 -3 3 238 238 238
-3 -3 3 238 238 238
-2 -3 3 238 238 238
-1 -3 3 238 238 238
0 -3 3 238 238 238
1 -3 3 238 238 238
2 -3 3 238 238 238
3 -3 3 238 238 238
4 -3 3 238 238 238
5 -3 3 238 238 238
6 -3 3 238 238 238
7 -3 3 51 166 184
-5 -2 3 51 166 184
-4 -2 3 238 238 238
-3 -2 3 238 238 238
-2 -2 3 238 238 238
-1 -2 3 238 238 238
0 -2 3 238 238 238
1 -2 3 238 238 238
2 -2 3 238 238 238
3 -2 3 238 238 238
4 -2 3 238 238 238
5 -2 3 238 238 238
6 -2 3 238 238 238
7 -2 3 51 166 184
-5 -1 3 247 194 66
-4 -1 3 238 238 238
-3 -1 3 238 238 238
-2 -1 3 238 238 238
-1 -1 3 238 238 238
0 -1 3 238 238 238
1 -1 3 238 238 238
2 -1 3 238 238 238
3 -1 3 238 238 238
4 -1 3 238 238 238
5 -1 3 238 238 238
6 -1 3 238 238 238
7 -1 3 247 194 66
-5 0 3 247 194 66
-4 0 3 238 238 238
-3 0 3 238 238 238
-2 0 3 238 238 238
-1 0 3 238 238 238
0 0 3 238 238 238
1 0 3 238 238 238
2 0 3 238 238 238
3 0 3 238 238 238
4 0 3 238 238 238
5 0 3 238 238 238
6 0 3 238 238 238
7 0 3 247 194 66
-5 1 3 247 194 66
-4 1 3 238 238 238
-3 1 3 238 238 238
-2 1 3 238 238 238
-1 1 3 238 238 238
0 1 3 238 238 238
1 1 3 238 238 238
2 1 3 238 238 238
3 1 3 238 238 238
4 1 3 238 238 238
5 1 3 238 238 238
6 1 3 238 238 238
7 1 3 247 194 66
-5 2 3 247 194 66
-4 2 3 238 238 238
-3 2 3 238 238 238
-2 2 3 238 238 238
-1 2 3 238 238 238
0 2 3 238 238 238
1 2 3 238 238 238
2 2 3 238 238 238
3 2 3 238 238 238
4 2 3 238 238 238
5 2 3 238 238 238
6 2 3 238 238 238
7 2 3 247 194 66
-5 3 3 51 166 184
-4 3 3 238 238 238
-3 3 3 238 238 238
-2 3 3 51 166 184
-1 3 3 51 166 184
0 3 3 51 166 184
1 3 3 51 166 184
2 3 3 51 166 184
3 3 3 51 166 184
4 3 3 51 166 184
5 3 3 238 238 238
6 3 3 238 238 238
7 3 3 51 166 184
-5 4 3 51 166 184
-4 4 3 238 238 238
-3 4 3 238 238 238
-2 4 3 51 166 184
-1 4 3 51 166 184
0 4 3 51 166 184
1 4 3 51 166 184
2 4 3 51 166 184
3 4 3 51 166 184
4 4 3 51 166 184
5 4 3 238 238 238
6 4 3 238 238 238
7 4 3 51 166 184
-5 5 3 51 166 184
-4 5 3 68 68 68
-3 5 3 51 166 184
-2 5 3 51 166 184
-1 5 3 51 166 184
0 5 3 51 166 184
1 5 3 51 166 184
2 5 3 51 166 184
3 5 3 51 166 184
4 5 3 51 166 184
5 5 3 68 68 68
6 5 3 68 68 68
7 5 3 51 166 184
-5 6 3 51 166 184
-4 6 3 170 170 170
-3 6 3 51 166 184
-2 6 3 51 166 184
-1 6 3 51 166 184
0 6 3 51 166 184
1 6 3 51 166 184
2 6 3 51 166 184
3 6 3 51 166 184
4 6 3 51 166 184
5 6 3 170 170 170
6 6 3 170 170 170
7 6 3 51 166 184
-5 7 3 51 166 184
-4 7 3 170 170 170
-3 7 3 51 166 184
-2 7 3 51 166 184
-1 7 3 51 166 184
0 7 3 51 166 184
1 7 3 51 166 184
2 7 3 51 166 184
3 7 3 51 166 184
4 7 3 51 166 184
5 7 3 170 170 170
6 7 3 170 170 170
7 7 3 51 166 184
-5 8 3 68 68 68
-4 8 3 170 170 170
-3 8 3 51 166 184
-2 8 3 51 166 184
-1 8 3 51 166 184
0 8 3 51 166 184
1 8 3 51 166 184
2 8 3 51 166 184
3 8 3 51 166 184
4 8 3 51 166 184
5 8 3 170 170 170
6 8 3 170 170 170
7 8 3 68 68 68
-5 9 3 136 136 136
-4 9 3 68 68 68
-3 9 3 51 166 184
-2 9 3 51 166 184
-1 9 3 51 166 184
0 9 3 51 166 184
1 9 3 51 166 184
2 9 3 51 166 184
3 9 3 51 166 184
4 9 3 51 166 184
5 9 3 68 68 68
6 9 3 68 68 68
7 9 3 136 136 136
-5 10 3 136 136 136
-4 10 3 238 238 238
-3 10 3 238 238 238
-2 10 3 51 166 184
-1 10 3 51 166 184
0 10 3 51 166 184
1 10 3 51 166 184
2 10 3 51 166 184
3 10 3 51 166 184
4 10 3 51 166 184
5 10 3 238 238 238
6 10 3 238 238 238
7 10 3 136 136 136
-5 11 3 136 136 136
-4 11 3 238 238 238
-3 11 3 238 238 238
-2 11 3 51 166 184
-1 11 3 51 166 184
0 11 3 51 166 184
1 11 3 51 166 184
2 11 3 51 166 184
3 11 3 51 166 184
4 11 3 51 166 184
5 11 3 238 238 238
6 11 3 238 238 238
7 11 3 136 136 136
-5 12 3 68 68 68
-4 12 3 238 238 238
-3 12 3 238 238 238
-2 12 3 238 238 238
-1 12 3 238 238 238
0 12 3 238 238 238
1 12 3 238 238 238
2 12 3 238 238 238
3 12 3 238 238 238
4 12 3 238 238 238
5 12 3 238 238 238
6 12 3 238 238 238
7 12 3 68 68 68
-5 13 3 51 166 184
-4 13 3 51 166 184
-3 13 3 238 238 238
-2 13 3 238 238 238
-1 13 3 238 238 238
0 13 3 238 238 238
1 13 3 238 238 238
2 13 3 238 238 238
3 13 3 238 238 238
4 13 3 238 238 238
5 13 3 238 238 238
6 13 3 51 166 184
7 13 3 51 166 184
-5 14 3 51 166 184
-4 14 3 51 166 184
-3 14 3 238 238 238
-2 14 3 238 238 238
-1 14 3 238 238 238
0 14 3 238 238 238
1 14 3 238 238 238
2 14 3 238 238 238
3 14 3 238 238 238
4 14 3 238 238 238
5 14 3 238 238 238
6 14 3 51 166 184
7 14 3 51 166 184
-6 15 3 119 119 119
-5 15 3 238 238 238
-4 15 3 238 238 238
-3 15 3 238 238 238
-2 15 3 238 238 238
-1 15 3 238 238 238
0 15 3 238 238 238
1 15 3 238 238 238
2 15 3 238 238 238
3 15 3 238 238 238
4 15 3 238 238 238
5 15 3 238 238 238
6 15 3 238 238 238
7 15 3 238 238 238
8 15 3 119 119 119
-6 16 3 119 119 119
-5 16 3 119 119 119
-4 16 3 119 119 119
-3 16 3 119 119 119
-2 16 3 119 119 119
-1 16 3 119 119 119
0 16 3 119 119 119
1 16 3 119 119 119
2 16 3 119 119 119
3 16 3 119 119 119
4 16 3 119 119 119
5 16 3 119 119 119
6 16 3 119 119 119
7 16 3 119 119 119
8 16 3 119 119 119
-5 -16 4 51 166 184
-4 -16 4 51 166 184
-3 -16 4 51 166 184
-2 -16 4 51 166 184
-1 -16 4 187 187 187
0 -16 4 187 187 187
1 -16 4 187 187 187
2 -16 4 187 187 187
3 -16 4 187 187 187
4 -16 4 51 166 184
5 -16 4 51 166 184
6 -16 4 51 166 184
7 -16 4 51 166 184
-5 -15 4 51 166 184
-4 -15 4 51 166 184
-3 -15 4 51 166 184
-2 -15 4 51 166 184
-1 -15 4 187 187 187
0 -15 4 187 187 187
1 -15 4 187 187 187
2 -15 4 187 187 187
3 -15 4 187 187 187
4 -15 4 51 166 184
5 -15 4 51 166 184
6 -15 4 51 166 184
7 -15 4 51 166 184
-5 -14 4 51 166 184
-4 -14 4 51 166 184
-3 -14 4 51 166 184
-2 -14 4 51 166 184
-1 -14 4 187 187 187
0 -14 4 187 187 187
1 -14 4 187 187 187
2 -14 4 187 187 187
3 -14 4 187 187 187
4 -14 4 51 166 184
5 -14 4 51 166 184
6 -14 4 51 166 184
7 -14 4 51 166 184
-5 -13 4 51 166 184
-4 -13 4 51 166 184
-3 -13 4 51 166 184
-2 -13 4 51 166 184
-1 -13 4 51 166 184
0 -13 4 51 166 184
1 -13 4 51 166 184
2 -13 4 51 166 184
3 -13 4 51 166 184
4 -13 4 51 166 184
5 -13 4 51 166 184
6 -13 4 51 166 184
7 -13 4 51 166 184
-5 -12 4 51 166 184
-4 -12 4 51 166 184
-3 -12 4 51 166 184
-2 -12 4 51 166 184
-1 -12 4 51 166 184
0 -12 4 51 166 184
1 -12 4 51 166 184
2 -12 4 51 166 184
3 -12 4 51 166 184
4 -12 4 51 166 184
5 -12 4 51 166 184
6 -12 4 51 166 184
7 -12 4 51 166 184
-5 -11 4 68 68 68
-4 -11 4 51 166 184
-3 -11 4 51 166 184
-2 -11 4 51 166 184
-1 -11 4 51 166 184
0 -11 4 51 166 184
1 -11 4 51 166 184
2 -11 4 51 166 184
3 -11 4 51 166 184
4 -11 4 51 166 184
5 -11 4 51 166 184
6 -11 4 51 166 184
7 -11 4 68 68 68
-5 -10 4 68 68 68
-4 -10 4 51 166 184
-3 -10 4 51 166 184
-2 -10 4 51 166 184
-1 -10 4 51 166 184
0 -10 4 51 166 184
1 -10 4 51 166 184
2 -10 4 51 166 184
3 -10 4 51 166 184
4 -10 4 51 166 184
5 -10 4 51 166 184
6 -10 4 51 166 184
7 -10 4 68 68 68
-5 -9 4 68 68 68
-4 -9 4 68 68 68
-3 -9 4 51 166 184
-2 -9 4 51 166 184
-1 -9 4 51 166 184
0 -9 4 51 166 184
1 -9 4 51 166 184
2 -9 4 51 166 184
3 -9 4 51 166 184
4 -9 4 51 166 184
5 -9 4 68 68 68
6 -9 4 68 68 68
7 -9 4 68 68 68
-5 -8 4 51 166 184
-4 -8 4 68 68 68
-3 -8 4 51 166 184
-2 -8 4 51 166 184
-1 -8 4 51 166 184
0 -8 4 51 166 184
1 -8 4 51 166 184
2 -8 4 51 166 184
3 -8 4 51 166 184
4 -8 4 51 166 184
5 -8 4 68 68 68
6 -8 4 68 68 68
7 -8 4 51 166 184
-5 -7 4 51 166 184
-4 -7 4 68 68 68
-3 -7 4 51 166 184
-2 -7 4 51 166 184
-1 -7 4 51 166 184
0 -7 4 51 166 184
1 -7 4 51 166 184
2 -7 4 51 166 184
3 -7 4 51 166 184
4 -7 4 51 166 184
5 -7 4 51 166 184
6 -7 4 68 68 68
7 -7 4 51 166 184
-5 -6 4 51 166 184
-4 -6 4 51 166 184
-3 -6 4 238 238 238
-2 -6 4 238 238 238
-1 -6 4 51 166 184
0 -6 4 51 166 184
1 -6 4 51 166 184
2 -6 4 51 166 184
3 -6 4 51 166 184
4 -6 4 238 238 238
5 -6 4 238 238 238
6 -6 4 51 166 184
7 -6 4 51 166 184
-5 -5 4 51 166 184
-4 -5 4 51 166 184
6 -5 4 51 166 184
7 -5 4 51 166 184
-5 -4 4 51 166 184
-4 -4 4 51 166 184
6 -4 4 51 166 184
7 -4 4 51 166 184
-5 -3 4 51 166 184
-4 -3 4 51 166 184
6 -3 4 51 166 184
7 -3 4 51 166 184
-5 -2 4 51 166 184
-4 -2 4 51 166 184
6 -2 4 51 166 184
7 -2 4 51 166 184
-5 -1 4 247 194 66
-4 -1 4 51 166 184
6 -1 4 51 166 184
7 -1 4 247 194 66
-5 0 4 247 194 66
-4 0 4 51 166 184
6 0 4 51 166 184
7 0 4 247 194 66
-5 1 4 247 194 66
-4 1 4 51 166 184
6 1 4 51 166 184
7 1 4 247 194 66
-5 2 4 247 194 66
-4 2 4 51 166 184
6 2 4 51 166 184
7 2 4 247 194 66
-5 3 4 51 166 184
-4 3 4 51 166 184
-3 3 4 238 238 238
-2 3 4 238 238 238
-1 3 4 238 238 238
0 3 4 238 238 238
1 3 4 238 238 238
2 3 4 238 238 238
3 3 4 238 238 238
4 3 4 238 238 238
5 3 4 238 238 238
6 3 4 51 166 184
7 3 4 51 166 184
-5 4 4 51 166 184
-4 4 4 51 166 184
-3 4 4 51 166 184
-2 4 4 51 166 184
-1 4 4 51 166 184
0 4 4 51 166 184
1 4 4 51 166 184
2 4 4 51 166 184
3 4 4 51 166 184
4 4 4 51 166 184
5 4 4 51 166 184
6 4 4 51 166 184
7 4 4 51 166 184
-5 5 4 51 166 184
-4 5 4 51 166 184
-3 5 4 51 166 184
-2 5 4 51 166 184
-1 5 4 51 166 184
0 5 4 51 166 184
1 5 4 51 166 184
2 5 4 51 166 184
3 5 4 51 166 184
4 5 4 51 166 184
5 5 4 51 166 184
6 5 4 51 166 184
7 5 4 51 166 184
-5 6 4 51 166 184
-4 6 4 68 68 68
-3 6 4 51 166 184
-2 6 4 51 166 184
-1 6 4 51 166 184
0 6 4 51 166 184
1 6 4 51 166 184
2 6 4 51 166 184
3 6 4 51 166 184
4 6 4 51 166 184
5 6 4 68 68 68
6 6 4 68 68 68
7 6 4 51 166 184
-5 7 4 51 166 184
-4 7 4 68 68 68
-3 7 4 51 166 184
-2 7 4 51 166 184
-1 7 4 51 166 184
0 7 4 51 166 184
1 7 4 51 166 184
2 7 4 51 166 184
3 7 4 51 166 184
4 7 4 51 166 184
5 7 4 68 68 68
6 7 4 68 68 68
7 7 4 51 166 184
-5 8 4 51 166 184
-4 8 4 68 68 68
-3 8 4 51 166 184
-2 8 4 51 166 184
-1 8 4 51 166 184
0 8 4 51 166 184
1 8 4 51 166 184
2 8 4 51 166 184
3 8 4 51 166 184
4 8 4 51 166 184
5 8 4 68 68 68
6 8 4 68 68 68
7 8 4 51 166 184
-5 9 4 68 68 68
-4 9 4 51 166 184
-3 9 4 51 166 184
-2 9 4 51 166 184
-1 9 4 51 166 184
0 9 4 51 166 184
1 9 4 51 166 184
2 9 4 51 166 184
3 9 4 51 166 184
4 9 4 51 166 184
5 9 4 51 166 184
6 9 4 51 166 184
7 9 4 68 68 68
-5 10 4 68 68 68
-4 10 4 51 166 184
-3 10 4 51 166 184
-2 10 4 51 166 184
-1 10 4 51 166 184
0 10 4 51 166 184
1 10 4 51 166 184
2 10 4 51 166 184
3 10 4 51 166 184
4 10 4 51 166 184
5 10 4 51 166 184
6 10 4 51 166 184
7 10 4 68 68 68
-5 11 4 68 68 68
-4 11 4 51 166 184
-3 11 4 51 166 184
-2 11 4 51 166 184
-1 11 4 51 166 184
0 11 4 51 166 184
1 11 4 51 166 184
2 11 4 51 166 184
3 11 4 51 166 184
4 11 4 51 166 184
5 11 4 51 166 184
6 11 4 51 166 184
7 11 4 68 68 68
-5 12 4 51 166 184
-4 12 4 51 166 184
-3 12 4 51 166 184
-2 12 4 51 166 184
-1 12 4 51 166 184
0 12 4 119 119 119
1 12 4 119 119 119
2 12 4 119 119 119
3 12 4 51 166 184
4 12 4 51 166 184
5 12 4 51 166 184
6 12 4 51 166 184
7 12 4 51 166 184
-5 13 4 51 166 184
-4 13 4 51 166 184
-3 13 4 51 166 184
-2 13 4 51 166 184
-1 13 4 51 166 184
0 13 4 119 119 119
1 13 4 119 119 119
2 13 4 119 119 119
3 13 4 51 166 184
4 13 4 51 166 184
5 13 4 51 166 184
6 13 4 51 166 184
7 13 4 51 166 184
-5 14 4 51 166 184
-4 14 4 51 166 184
-3 14 4 51 166 184
-2 14 4 51 166 184
-1 14 4 51 166 184
0 14 4 119 119 119
1 14 4 119 119 119
2 14 4 119 119 119
3 14 4 51 166 184
4 14 4 51 166 184
5 14 4 51 166 184
6 14 4 51 166 184
7 14 4 51 166 184
-5 15 4 51 166 184
-4 15 4 51 166 184
-3 15 4 51 166 184
-2 15 4 51 166 184
-1 15 4 51 166 184
0 15 4 68 68 68
1 15 4 68 68 68
2 15 4 68 68 68
3 15 4 51 166 184
4 15 4 51 166 184
5 15 4 51 166 184
6 15 4 51 166 184
7 15 4 51 166 184
-5 -16 5 159 53 58
-4 -16 5 159 53 58
-3 -16 5 159 53 58
-2 -16 5 51 166 184
-1 -16 5 187 187 187
0 -16 5 187 187 187
1 -16 5 187 187 187
2 -16 5 187 187 187
3 -16 5 187 187 187
4 -16 5 51 166 184
5 -16 5 159 53 58
6 -16 5 159 53 58
7 -16 5 159 53 58
-5 -15 5 51 166 184
-4 -15 5 51 166 184
-3 -15 5 51 166 184
-2 -15 5 51 166 184
-1 -15 5 187 187 187
0 -15 5 187 187 187
1 -15 5 187 187 187
2 -15 5 187 187 187
3 -15 5 187 187 187
4 -15 5 51 166 184
5 -15 5 51 166 184
6 -15 5 51 166 184
7 -15 5 238 238 238
-5 -14 5 238 238 238
-4 -14 5 51 166 184
-3 -14 5 51 166 184
-2 -14 5 51 166 184
-1 -14 5 187 187 187
0 -14 5 187 187 187
1 -14 5 187 187 187
2 -14 5 187 187 187
3 -14 5 187 187 187
4 -14 5 51 166 184
5 -14 5 51 166 184
6 -14 5 51 166 184
7 -14 5 238 238 238
-5 -13 5 238 238 238
-4 -13 5 51 166 184
-3 -13 5 51 166 184
-2 -13 5 51 166 184
-1 -13 5 51 166 184
0 -13 5 51 166 184
1 -13 5 51 166 184
2 -13 5 51 166 184
3 -13 5 51 166 184
4 -13 5 51 166 184
5 -13 5 51 166 184
6 -13 5 51 166 184
7 -13 5 238 238 238
-5 -12 5 238 238 238
-4 -12 5 51 166 184
-3 -12 5 51 166 184
-2 -12 5 51 166 184
-1 -12 5 51 166 184
0 -12 5 51 166 184
1 -12 5 51 166 184
2 -12 5 51 166 184
3 -12 5 51 166 184
4 -12 5 51 166 184
5 -12 5 51 166 184
6 -12 5 51 166 184
7 -12 5 238 238 238
-5 -11 5 238 238 238
-4 -11 5 51 166 184
-3 -11 5 51 166 184
-2 -11 5 51 166 184
-1 -11 5 51 166 184
0 -11 5 51 166 184
1 -11 5 51 166 184
2 -11 5 51 166 184
3 -11 5 51 166 184
4 -11 5 51 166 184
5 -11 5 51 166 184
6 -11 5 51 166 184
7 -11 5 238 238 238
-5 -10 5 238 238 238
-4 -10 5 51 166 184
-3 -10 5 51 166 184
-2 -10 5 51 166 184
-1 -10 5 51 166 184
0 -10 5 51 166 184
1 -10 5 51 166 184
2 -10 5 51 166 184
3 -10 5 51 166 184
4 -10 5 51 166 184
5 -10 5 51 166 184
6 -10 5 51 166 184
7 -10 5 238 238 238
-5 -9 5 238 238 238
-4 -9 5 51 166 184
-3 -9 5 51 166 184
-2 -9 5 51 166 184
-1 -9 5 51 166 184
0 -9 5 51 166 184
1 -9 5 51 166 184
2 -9 5 51 166 184
3 -9 5 51 166 184
4 -9 5 51 166 184
5 -9 5 51 166 184
6 -9 5 51 166 184
7 -9 5 238 238 238
-5 -8 5 238 238 238
-4 -8 5 51 166 184
-3 -8 5 51 166 184
-2 -8 5 51 166 184
-1 -8 5 51 166 184
0 -8 5 51 166 184
1 -8 5 51 166 184
2 -8 5 51 166 184
3 -8 5 51 166 184
4 -8 5 51 166 184
5 -8 5 51 166 184
6 -8 5 51 166 184
7 -8 5 238 238 238
-5 -7 5 238 238 238
-4 -7 5 51 166 184
-3 -7 5 51 166 184
-2 -7 5 51 166 184
-1 -7 5 51 166 184
0 -7 5 51 166 184
1 -7 5 51 166 184
2 -7 5 51 166 184
3 -7 5 51 166 184
4 -7 5 51 166 184
5 -7 5 51 166 184
6 -7 5 51 166 184
7 -7 5 238 238 238
-5 -6 5 238 238 238
-4 -6 5 51 166 184
-3 -6 5 238 238 238
-2 -6 5 238 238 238
-1 -6 5 51 166 184
0 -6 5 51 166 184
1 -6 5 51 166 184
2 -6 5 51 166 184
3 -6 5 51 166 184
4 -6 5 238 238 238
5 -6 5 238 238 238
6 -6 5 51 166 184
7 -6 5 238 238 238
-5 -5 5 238 238 238
-4 -5 5 51 166 184
6 -5 5 51 166 184
7 -5 5 238 238 238
-5 -4 5 238 238 238
-4 -4 5 51 166 184
6 -4 5 51 166 184
7 -4 5 238 238 238
-5 -3 5 238 238 238
-4 -3 5 51 166 184
6 -3 5 51 166 184
7 -3 5 238 238 238
-5 -2 5 238 238 238
-4 -2 5 51 166 184
6 -2 5 51 166 184
7 -2 5 238 238 238
-5 -1 5 238 238 238
-4 -1 5 51 166 184
6 -1 5 51 166 184
7 -1 5 238 238 238
-5 0 5 247 194 66
-4 0 5 51 166 184
6 0 5 51 166 184
7 0 5 247 194 66
-5 1 5 247 194 66
-4 1 5 51 166 184
6 1 5 51 166 184
7 1 5 247 194 66
-5 2 5 238 238 238
-4 2 5 51 166 184
6 2 5 51 166 184
7 2 5 238 238 238
-5 3 5 238 238 238
-4 3 5 51 166 184
-3 3 5 238 238 238
-2 3 5 238 238 238
-1 3 5 238 238 238
0 3 5 238 238 238
1 3 5 238 238 238
2 3 5 238 238 238
3 3 5 238 238 238
4 3 5 238 238 238
5 3 5 238 238 238
6 3 5 51 166 184
7 3 5 238 238 238
-5 4 5 238 238 238
-4 4 5 51 166 184
-3 4 5 51 166 184
-2 4 5 51 166 184
-1 4 5 51 166 184
0 4 5 51 166 184
1 4 5 51 166 184
2 4 5 51 166 184
3 4 5 51 166 184
4 4 5 51 166 184
5 4 5 51 166 184
6 4 5 51 166 184
7 4 5 238 238 238
-5 5 5 238 238 238
-4 5 5 51 166 184
-3 5 5 51 166 184
-2 5 5 51 166 184
-1 5 5 51 166 184
0 5 5 51 166 184
1 5 5 51 166 184
2 5 5 51 166 184
3 5 5 51 166 184
4 5 5 51 166 184
5 5 5 51 166 184
6 5 5 51 166 184
7 5 5 238 238 238
-5 6 5 238 238 238
-4 6 5 51 166 184
-3 6 5 51 166 184
-2 6 5 51 166 184
-1 6 5 51 166 184
0 6 5 51 166 184
1 6 5 51 166 184
2 6 5 51 166 184
3 6 5 51 166 184
4 6 5 51 166 184
5 6 5 51 166 184
6 6 5 51 166 184
7 6 5 238 238 238
-5 7 5 238 238 238
-4 7 5 51 166 184
-3 7 5 51 166 184
-2 7 5 51 166 184
-1 7 5 51 166 184
0 7 5 51 166 184
1 7 5 51 166 184
2 7 5 51 166 184
3 7 5 51 166 184
4 7 5 51 166 184
5 7 5 51 166 184
6 7 5 51 166 184
7 7 5 238 238 238
-5 8 5 238 238 238
-4 8 5 51 166 184
-3 8 5 51 166 184
-2 8 5 51 166 184
-1 8 5 51 166 184
0 8 5 51 166 184
1 8 5 51 166 184
2 8 5 51 166 184
3 8 5 51 166 184
4 8 5 51 166 184
5 8 5 51 166 184
6 8 5 51 166 184
7 8 5 238 238 238
-5 9 5 238 238 238
-4 9 5 51 166 184
-3 9 5 51 166 184
-2 9 5 51 166 184
-1 9 5 51 166 184
0 9 5 51 166 184
1 9 5 51 166 184
2 9 5 51 166 184
3 9 5 51 166 184
4 9 5 51 166 184
5 9 5 51 166 184
6 9 5 51 166 184
7 9 5 238 238 238
-5 10 5 238 238 238
-4 10 5 51 166 184
-3 10 5 51 166 184
-2 10 5 51 166 184
-1 10 5 51 166 184
0 10 5 51 166 184
1 10 5 51 166 184
2 10 5 51 166 184
3 10 5 51 166 184
4 10 5 51 166 184
5 10 5 51 166 184
6 10 5 51 166 184
7 10 5 238 238 238
-5 11 5 238 238 238
-4 11 5 51 166 184
-3 11 5 51 166 184
-2 11 5 51 166 184
-1 11 5 51 166 184
0 11 5 51 166 184
1 11 5 51 166 184
2 11 5 51 166 184
3 11 5 51 166 184
4 11 5 51 166 184
5 11 5 51 166 184
6 11 5 51 166 184
7 11 5 238 238 238
-5 12 5 238 238 238
-4 12 5 51 166 184
-3 12 5 51 166 184
-2 12 5 51 166 184
-1 12 5 51 166 184
0 12 5 51 166 184
1 12 5 51 166 184
2 12 5 51 166 184
3 12 5 51 166 184
4 12 5 51 166 184
5 12 5 51 166 184
6 12 5 51 166 184
7 12 5 238 238 238
-5 13 5 238 238 238
-4 13 5 51 166 184
-3 13 5 51 166 184
-2 13 5 51 166 184
-1 13 5 51 166 184
0 13 5 51 166 184
1 13 5 51 166 184
2 13 5 51 166 184
3 13 5 51 166 184
4 13 5 51 166 184
5 13 5 51 166 184
6 13 5 51 166 184
7 13 5 238 238 238
-5 14 5 238 238 238
-4 14 5 51 166 184
-3 14 5 51 166 184
-2 14 5 51 166 184
-1 14 5 51 166 184
0 14 5 51 166 184
1 14 5 51 166 184
2 14 5 51 166 184
3 14 5 51 166 184
4 14 5 51 166 184
5 14 5 51 166 184
6 14 5 51 166 184
7 14 5 238 238 238
-5 15 5 51 166 184
-4 15 5 238 238 238
-3 15 5 238 238 238
-2 15 5 238 238 238
-1 15 5 51 166 184
0 15 5 51 166 184
1 15 5 51 166 184
2 15 5 51 166 184
3 15 5 51 166 184
4 15 5 238 238 238
5 15 5 238 238 238
6 15 5 238 238 238
7 15 5 51 166 184
-5 -16 6 51 166 184
-4 -16 6 51 166 184
-3 -16 6 51 166 184
-2 -16 6 51 166 184
-1 -16 6 51 166 184
0 -16 6 51 166 184
1 -16 6 51 166 184
2 -16 6 51 166 184
3 -16 6 51 166 184
4 -16 6 51 166 184
5 -16 6 51 166 184
6 -16 6 51 166 184
7 -16 6 51 166 184
-5 -15 6 51 166 184
-4 -15 6 51 166 184
-3 -15 6 51 166 184
-2 -15 6 51 166 184
-1 -15 6 51 166 184
0 -15 6 51 166 184
1 -15 6 51 166 184
2 -15 6 51 166 184
3 -15 6 51 166 184
4 -15 6 51 166 184
5 -15 6 51 166 184
6 -15 6 51 166 184
7 -15 6 51 166 184
-5 -14 6 51 166 184
-4 -14 6 51 166 184
-3 -14 6 51 166 184
-2 -14 6 51 166 184
-1 -14 6 51 166 184
0 -14 6 51 166 184
1 -14 6 51 166 184
2 -14 6 51 166 184
3 -14 6 51 166 184
4 -14 6 51 166 184
5 -14 6 51 166 184
6 -14 6 51 166 184
7 -14 6 51 166 184
-5 -13 6 51 166 184
-4 -13 6 51 166 184
-3 -13 6 51 166 184
-2 -13 6 51 166 184
-1 -13 6 51 166 184
0 -13 6 51 166 184
1 -13 6 51 166 184
2 -13 6 51 166 184
3 -13 6 51 166 184
4 -13 6 51 166 184
5 -13 6 51 166 184
6 -13 6 51 166 184
7 -13 6 51 166 184
-5 -12 6 51 166 184
-4 -12 6 51 166 184
-3 -12 6 51 166 184
-2 -12 6 51 166 184
-1 -12 6 51 166 184
0 -12 6 51 166 184
1 -12 6 51 166 184
2 -12 6 51 166 184
3 -12 6 51 166 184
4 -12 6 51 166 184
5 -12 6 51 166 184
6 -12 6 51 166 184
7 -12 6 51 166 184
-5 -11 6 51 166 184
-4 -11 6 51 166 184
-3 -11 6 51 166 184
-2 -11 6 51 166 184
-1 -11 6 51 166 184
0 -11 6 51 166 184
1 -11 6 51 166 184
2 -11 6 51 166 184
3 -11 6 51 166 184
4 -11 6 51 166 184
5 -11 6 51 166 184
6 -11 6 51 166 184
7 -11 6 51 166 184
-5 -10 6 51 166 184
-4 -10 6 51 166 184
-3 -10 6 51 166 184
-2 -10 6 51 166 184
-1 -10 6 51 166 184
0 -10 6 51 166 184
1 -10 6 51 166 184
2 -10 6 51 166 184
3 -10 6 51 166 184
4 -10 6 51 166 184
5 -10 6 51 166 184
6 -10 6 51 166 184
7 -10 6 51 166 184
-5 -9 6 51 166 184
-4 -9 6 51 166 184
-3 -9 6 51 166 184
-2 -9 6 51 166 184
-1 -9 6 51 166 184
0 -9 6 51 166 184
1 -9 6 51 166 184
2 -9 6 51 166 184
3 -9 6 51 166 184
4 -9 6 51 166 184
5 -9 6 51 166 184
6 -9 6 51 166 184
7 -9 6 51 166 184
-5 -8 6 51 166 184
-4 -8 6 51 166 184
-3 -8 6 51 166 184
-2 -8 6 51 166 184
-1 -8 6 51 166 184
0 -8 6 51 166 184
1 -8 6 51 166 184
2 -8 6 51 166 184
3 -8 6 51 166 184
4 -8 6 51 166 184
5 -8 6 51 166 184
6 -8 6 51 166 184
7 -8 6 51 166 184
-5 -7 6 51 166 184
-4 -7 6 51 166 184
-3 -7 6 51 166 184
-2 -7 6 51 166 184
-1 -7 6 51 166 184
0 -7 6 51 166 184
1 -7 6 51 166 184
2 -7 6 51 166 184
3 -7 6 51 166 184
4 -7 6 51 166 184
5 -7 6 51 166 184
6 -7 6 51 166 184
7 -7 6 51 166 184
-5 -6 6 51 166 184
-4 -6 6 51 166 184
-3 -6 6 238 238 238
-2 -6 6 238 238 238
-1 -6 6 51 166 184
0 -6 6 51 166 184
1 -6 6 51 166 184
2 -6 6 51 166 184
3 -6 6 51 166 184
4 -6 6 238 238 238
5 -6 6 238 238 238
6 -6 6 51 166 184
7 -6 6 51 166 184
-5 -5 6 51 166 184
-4 -5 6 51 166 184
6 -5 6 51 166 184
7 -5 6 51 166 184
-5 -4 6 51 166 184
-4 -4 6 51 166 184
6 -4 6 51 166 184
7 -4 6 51 166 184
-5 -3 6 51 166 184
-4 -3 6 51 166 184
6 -3 6 51 166 184
7 -3 6 51 166 184
-5 -2 6 51 166 184
-4 -2 6 51 166 184
6 -2 6 51 166 184
7 -2 6 51 166 184
-5 -1 6 51 166 184
-4 -1 6 51 166 184
6 -1 6 51 166 184
7 -1 6 51 166 184
-5 0 6 51 166 184
-4 0 6 51 166 184
6 0 6 51 166 184
7 0 6 51 166 184
-5 1 6 51 166 184
-4 1 6 51 166 184
6 1 6 51 166 184
7 1 6 51 166 184
-5 2 6 51 166 184
-4 2 6 51 166 184
6 2 6 51 166 184
7 2 6 51 166 184
-5 3 6 51 166 184
-4 3 6 51 166 184
-3 3 6 238 238 238
-2 3 6 238 238 238
-1 3 6 238 238 238
0 3 6 238 238 238
1 3 6 238 238 238
2 3 6 238 238 238
3 3 6 238 238 238
4 3 6 238 238 238
5 3 6 238 238 238
6 3 6 51 166 184
7 3 6 51 166 184
-6 4 6 238 238 238
-5 4 6 51 166 184
-4 4 6 51 166 184
-3 4 6 51 166 184
-2 4 6 51 166 184
-1 4 6 51 166 184
0 4 6 51 166 184
1 4 6 51 166 184
2 4 6 51 166 184
3 4 6 51 166 184
4 4 6 51 166 184
5 4 6 51 166 184
6 4 6 51 166 184
7 4 6 51 166 184
8 4 6 238 238 238
-5 5 6 51 166 184
-4 5 6 51 166 184
-3 5 6 51 166 184
-2 5 6 51 166 184
-1 5 6 51 166 184
0 5 6 51 166 184
1 5 6 51 166 184
2 5 6 51 166 184
3 5 6 51 166 184
4 5 6 51 166 184
5 5 6 51 166 184
6 5 6 51 166 184
7 5 6 51 166 184
-5 6 6 51 166 184
-4 6 6 51 166 184
-3 6 6 51 166 184
-2 6 6 51 166 184
-1 6 6 51 166 184
0 6 6 51 166 184
1 6 6 51 166 184
2 6 6 51 166 184
3 6 6 51 166 184
4 6 6 51 166 184
5 6 6 51 166 184
6 6 6 51 166 184
7 6 6 51 166 184
-5 7 6 51 166 184
-4 7 6 51 166 184
-3 7 6 51 166 184
-2 7 6 51 166 184
-1 7 6 51 166 184
0 7 6 51 166 184
1 7 6 51 166 184
2 7 6 51 166 184
3 7 6 51 166 184
4 7 6 51 166 184
5 7 6 51 166 184
6 7 6 51 166 184
7 7 6 51 166 184
-5 8 6 51 166 184
-4 8 6 51 166 184
-3 8 6 51 166 184
-2 8 6 51 166 184
-1 8 6 51 166 184
0 8 6 51 166 184
1 8 6 51 166 184
2 8 6 51 166 184
3 8 6 51 166 184
4 8 6 51 166 184
5 8 6 51 166 184
6 8 6 51 166 184
7 8 6 51 166 184
-5 9 6 51 166 184
-4 9 6 51 166 184
-3 9 6 51 166 184
-2 9 6 51 166 184
-1 9 6 51 166 184
0 9 6 51 166 184
1 9 6 51 166 184
2 9 6 51 166 184
3 9 6 51 166 184
4 9 6 51 166 184
5 9 6 51 166 184
6 9 6 51 166 184
7 9 6 51 166 184
-5 10 6 51 166 184
-4 10 6 51 166 184
-3 10 6 51 166 184
-2 10 6 51 166 184
-1 10 6 51 166 184
0 10 6 51 166 184
1 10 6 51 166 184
2 10 6 51 166 184
3 10 6 51 166 184
4 10 6 51 166 184
5 10 6 51 166 184
6 10 6 51 166 184
7 10 6 51 166 184
-5 11 6 51 166 184
-4 11 6 51 166 184
-3 11 6 51 166 184
-2 11 6 51 166 184
-1 11 6 51 166 184
0 11 6 51 166 184
1 11 6 51 166 184
2 11 6 51 166 184
3 11 6 51 166 184
4 11 6 51 166 184
5 11 6 51 166 184
6 11 6 51 166 184
7 11 6 51 166 184
-5 12 6 51 166 184
-4 12 6 51 166 184
-3 12 6 51 166 184
-2 12 6 51 166 184
-1 12 6 51 166 184
0 12 6 51 166 184
1 12 6 51 166 184
2 12 6 51 166 184
3 12 6 51 166 184
4 12 6 51 166 184
5 12 6 51 166 184
6 12 6 51 166 184
7 12 6 51 166 184
-5 13 6 51 166 184
-4 13 6 51 166 184
-3 13 6 51 166 184
-2 13 6 51 166 184
-1 13 6 51 166 184
0 13 6 51 166 184
1 13 6 51 166 184
2 13 6 51 166 184
3 13 6 51 166 184
4 13 6 51 166 184
5 13 6 51 166 184
6 13 6 51 166 184
7 13 6 51 166 184
-5 14 6 51 166 184
-4 14 6 51 166 184
-3 14 6 51 166 184
-2 14 6 51 166 184
-1 14 6 51 166 184
0 14 6 51 166 184
1 14 6 51 166 184
2 14 6 51 166 184
3 14 6 51 166 184
4 14 6 51 166 184
5 14 6 51 166 184
6 14 6 51 166 184
7 14 6 51 166 184
-5 15 6 51 166 184
-4 15 6 51 166 184
-3 15 6 51 166 184
-2 15 6 51 166 184
-1 15 6 51 166 184
0 15 6 51 166 184
1 15 6 51 166 184
2 15 6 51 166 184
3 15 6 51 166 184
4 15 6 51 166 184
5 15 6 51 166 184
6 15 6 51 166 184
7 15 6 51 166 184
-5 -9 7 238 238 238
-4 -9 7 34 34 34
-3 -9 7 34 34 34
-2 -9 7 34 34 34
-1 -9 7 34 34 34
0 -9 7 34 34 34
1 -9 7 34 34 34
2 -9 7 34 34 34
3 -9 7 34 34 34
4 -9 7 34 34 34
5 -9 7 34 34 34
6 -9 7 34 34 34
7 -9 7 238 238 238
-5 -8 7 238 238 238
-4 -8 7 34 34 34
-3 -8 7 34 34 34
-2 -8 7 34 34 34
-1 -8 7 34 34 34
0 -8 7 34 34 34
1 -8 7 34 34 34
2 -8 7 34 34 34
3 -8 7 34 34 34
4 -8 7 34 34 34
5 -8 7 34 34 34
6 -8 7 34 34 34
7 -8 7 34 34 34
-5 -7 7 34 34 34
-4 -7 7 34 34 34
-3 -7 7 34 34 34
-2 -7 7 34 34 34
-1 -7 7 34 34 34
0 -7 7 34 34 34
1 -7 7 34 34 34
2 -7 7 34 34 34
3 -7 7 34 34 34
4 -7 7 34 34 34
5 -7 7 34 34 34
6 -7 7 34 34 34
7 -7 7 34 34 34
-5 -6 7 34 34 34
-4 -6 7 34 34 34
-3 -6 7 34 34 34
-2 -6 7 34 34 34
-1 -6 7 34 34 34
0 -6 7 34 34 34
1 -6 7 34 34 34
2 -6 7 34 34 34
3 -6 7 34 34 34
4 -6 7 34 34 34
5 -6 7 34 34 34
6 -6 7 34 34 34
7 -6 7 34 34 34
-5 -5 7 34 34 34
-4 -5 7 34 34 34
-3 -5 7 34 34 34
-2 -5 7 34 34 34
-1 -5 7 34 34 34
0 -5 7 34 34 34
1 -5 7 34 34 34
2 -5 7 34 34 34
3 -5 7 34 34 34
4 -5 7 34 34 34
5 -5 7 34 34 34
6 -5 7 34 34 34
7 -5 7 34 34 34
-5 -4 7 34 34 34
-4 -4 7 51 166 184
-3 -4 7 51 166 184
-2 -4 7 51 166 184
-1 -4 7 51 166 184
0 -4 7 51 166 184
1 -4 7 51 166 184
2 -4 7 51 166 184
3 -4 7 51 166 184
4 -4 7 51 166 184
5 -4 7 51 166 184
6 -4 7 51 166 184
7 -4 7 34 34 34
-5 -3 7 238 238 238
-4 -3 7 51 166 184
-3 -3 7 51 166 184
-2 -3 7 51 166 184
-1 -3 7 51 166 184
0 -3 7 51 166 184
1 -3 7 51 166 184
2 -3 7 51 166 184
3 -3 7 51 166 184
4 -3 7 51 166 184
5 -3 7 51 166 184
6 -3 7 51 166 184
7 -3 7 238 238 238
-5 -2 7 34 34 34
-4 -2 7 51 166 184
-3 -2 7 51 166 184
-2 -2 7 51 166 184
-1 -2 7 51 166 184
0 -2 7 51 166 184
1 -2 7 51 166 184
2 -2 7 51 166 184
3 -2 7 51 166 184
4 -2 7 51 166 184
5 -2 7 51 166 184
6 -2 7 51 166 184
7 -2 7 34 34 34
-5 -1 7 34 34 34
-4 -1 7 51 166 184
-3 -1 7 51 166 184
-2 -1 7 51 166 184
-1 -1 7 51 166 184
0 -1 7 51 166 184
1 -1 7 51 166 184
2 -1 7 51 166 184
3 -1 7 51 166 184
4 -1 7 51 166 184
5 -1 7 51 166 184
6 -1 7 51 166 184
7 -1 7 34 34 34
-5 0 7 34 34 34
-4 0 7 51 166 184
-3 0 7 51 166 184
-2 0 7 51 166 184
-1 0 7 51 166 184
0 0 7 51 166 184
1 0 7 51 166 184
2 0 7 51 166 184
3 0 7 51 166 184
4 0 7 51 166 184
5 0 7 51 166 184
6 0 7 51 166 184
7 0 7 34 34 34
-5 1 7 34 34 34
-4 1 7 51 166 184
-3 1 7 51 166 184
-2 1 7 51 166 184
-1 1 7 51 166 184
0 1 7 51 166 184
1 1 7 51 166 184
2 1 7 51 166 184
3 1 7 51 166 184
4 1 7 51 166 184
5 1 7 51 166 184
6 1 7 51 166 184
7 1 7 34 34 34
-5 2 7 34 34 34
-4 2 7 51 166 184
-3 2 7 51 166 184
-2 2 7 51 166 184
-1 2 7 51 166 184
0 2 7 51 166 184
1 2 7 51 166 184
2 2 7 51 166 184
3 2 7 51 166 184
4 2 7 51 166 184
5 2 7 51 166 184
6 2 7 51 166 184
7 2 7 34 34 34
-5 3 7 34 34 34
-4 3 7 51 166 184
-3 3 7 51 166 184
-2 3 7 51 166 184
-1 3 7 51 166 184
0 3 7 51 166 184
1 3 7 51 166 184
2 3 7 51 166 184
3 3 7 51 166 184
4 3 7 51 166 184
5 3 7 51 166 184
6 3 7 51 166 184
7 3 7 34 34 34
-6 4 7 238 238 238
-5 4 7 34 34 34
-4 4 7 51 166 184
-3 4 7 51 166 184
-2 4 7 51 166 184
-1 4 7 51 166 184
0 4 7 51 166 184
1 4 7 51 166 184
2 4 7 51 166 184
3 4 7 51 166 184
4 4 7 51 166 184
5 4 7 51 166 184
6 4 7 51 166 184
7 4 7 34 34 34
8 4 7 238 238 238
-5 5 7 238 238 238
-4 5 7 34 34 34
-3 5 7 34 34 34
-2 5 7 34 34 34
-1 5 7 34 34 34
0 5 7 34 34 34
1 5 7 34 34 34
2 5 7 34 34 34
3 5 7 34 34 34
4 5 7 34 34 34
5 5 7 34 34 34
6 5 7 34 34 34
7 5 7 238 238 238
-5 -9 8 238 238 238
-4 -9 8 34 34 34
-3 -9 8 34 34 34
-2 -9 8 34 34 34
-1 -9 8 34 34 34
0 -9 8 34 34 34
1 -9 8 34 34 34
2 -9 8 34 34 34
3 -9 8 34 34 34
4 -9 8 34 34 34
5 -9 8 34 34 34
6 -9 8 34 34 34
7 -9 8 238 238 238
-5 -8 8 238 238 238
-4 -8 8 34 34 34
-3 -8 8 34 34 34
-2 -8 8 34 34 34
-1 -8 8 34 34 34
0 -8 8 34 34 34
1 -8 8 34 34 34
2 -8 8 34 34 34
3 -8 8 34 34 34
4 -8 8 34 34 34
5 -8 8 34 34 34
6 -8 8 34 34 34
7 -8 8 34 34 34
-5 -7 8 34 34 34
-4 -7 8 34 34 34
-3 -7 8 34 34 34
-2 -7 8 34 34 34
-1 -7 8 34 34 34
0 -7 8 34 34 34
1 -7 8 34 34 34
2 -7 8 34 34 34
3 -7 8 34 34 34
4 -7 8 34 34 34
5 -7 8 34 34 34
6 -7 8 34 34 34
7 -7 8 34 34 34
-5 -6 8 34 34 34
-4 -6 8 34 34 34
-3 -6 8 34 34 34
-2 -6 8 34 34 34
-1 -6 8 34 34 34
0 -6 8 34 34 34
1 -6 8 34 34 34
2 -6 8 34 34 34
3 -6 8 34 34 34
4 -6 8 34 34 34
5 -6 8 34 34 34
6 -6 8 34 34 34
7 -6 8 34 34 34
-5 -5 8 34 34 34
-4 -5 8 34 34 34
-3 -5 8 34 34 34
-2 -5 8 34 34 34
-1 -5 8 34 34 34
0 -5 8 34 34 34
1 -5 8 34 34 34
2 -5 8 34 34 34
3 -5 8 34 34 34
4 -5 8 34 34 34
5 -5 8 34 34 34
6 -5 8 34 34 34
7 -5 8 34 34 34
-5 -4 8 34 34 34
-4 -4 8 51 166 184
-3 -4 8 51 166 184
-2 -4 8 51 166 184
-1 -4 8 51 166 184
0 -4 8 51 166 184
1 -4 8 51 166 184
2 -4 8 51 166 184
3 -4 8 51 166 184
4 -4 8 51 166 184
5 -4 8 51 166 184
6 -4 8 51 166 184
7 -4 8 34 34 34
-5 -3 8 238 238 238
-4 -3 8 51 166 184
-3 -3 8 51 166 184
-2 -3 8 51 166 184
-1 -3 8 51 166 184
0 -3 8 51 166 184
1 -3 8 51 166 184
2 -3 8 51 166 184
3 -3 8 51 166 184
4 -3 8 51 166 184
5 -3 8 51 166 184
6 -3 8 51 166 184
7 -3 8 238 238 238
-5 -2 8 34 34 34
-4 -2 8 51 166 184
-3 -2 8 51 166 184
-2 -2 8 51 166 184
-1 -2 8 51 166 184
0 -2 8 51 166 184
1 -2 8 51 166 184
2 -2 8 51 166 184
3 -2 8 51 166 184
4 -2 8 51 166 184
5 -2 8 51 166 184
6 -2 8 51 166 184
7 -2 8 34 34 34
-5 -1 8 34 34 34
-4 -1 8 51 166 184
-3 -1 8 51 166 184
-2 -1 8 51 166 184
-1 -1 8 51 166 184
0 -1 8 51 166 184
1 -1 8 51 166 184
2 -1 8 51 166 184
3 -1 8 51 166 184
4 -1 8 51 166 184
5 -1 8 51 166 184
6 -1 8 51 166 184
7 -1 8 34 34 34
-5 0 8 34 34 34
-4 0 8 51 166 184
-3 0 8 51 166 184
-2 0 8 51 166 184
-1 0 8 51 166 184
0 0 8 51 166 184
1 0 8 51 166 184
2 0 8 51 166 184
3 0 8 51 166 184
4 0 8 51 166 184
5 0 8 51 166 184
6 0 8 51 166 184
7 0 8 34 34 34
-5 1 8 34 34 34
-4 1 8 51 166 184
-3 1 8 51 166 184
-2 1 8 51 166 184
-1 1 8 51 166 184
0 1 8 51 166 184
1 1 8 51 166 184
2 1 8 51 166 184
3 1 8 51 166 184
4 1 8 51 166 184
5 1 8 51 166 184
6 1 8 51 166 184
7 1 8 34 34 34
-5 2 8 34 34 34
-4 2 8 51 166 184
-3 2 8 51 166 184
-2 2 8 51 166 184
-1 2 8 51 166 184
0 2 8 51 166 184
1 2 8 51 166 184
2 2 8 51 166 184
3 2 8 51 166 184
4 2 8 51 166 184
5 2 8 51 166 184
6 2 8 51 166 184
7 2 8 34 34 34
-5 3 8 34 34 34
-4 3 8 51 166 184
-3 3 8 51 166 184
-2 3 8 51 166 184
-1 3 8 51 166 184
0 3 8 51 166 184
1 3 8 51 166 184
2 3 8 51 166 184
3 3 8 51 166 184
4 3 8 51 166 184
5 3 8 51 166 184
6 3 8 51 166 184
7 3 8 34 34 34
-5 4 8 34 34 34
-4 4 8 51 166 184
-3 4 8 51 166 184
-2 4 8 51 166 184
-1 4 8 51 166 184
0 4 8 51 166 184
1 4 8 51 166 184
2 4 8 51 166 184
3 4 8 51 166 184
4 4 8 51 166 184
5 4 8 51 166 184
6 4 8 51 166 184
7 4 8 34 34 34
-5 5 8 238 238 238
-4 5 8 34 34 34
-3 5 8 34 34 34
-2 5 8 34 34 34
-1 5 8 34 34 34
0 5 8 34 34 34
1 5 8 34 34 34
2 5 8 34 34 34
3 5 8 34 34 34
4 5 8 34 34 34
5 5 8 34 34 34
6 5 8 34 34 34
7 5 8 238 238 238
-5 -9 9 238 238 238
-4 -9 9 34 34 34
-3 -9 9 34 34 34
-2 -9 9 34 34 34
-1 -9 9 34 34 34
0 -9 9 34 34 34
1 -9 9 34 34 34
2 -9 9 34 34 34
3 -9 9 34 34 34
4 -9 9 34 34 34
5 -9 9 34 34 34
6 -9 9 34 34 34
7 -9 9 238 238 238
-5 -8 9 238 238 238
-4 -8 9 34 34 34
-3 -8 9 34 34 34
-2 -8 9 34 34 34
-1 -8 9 34 34 34
0 -8 9 34 34 34
1 -8 9 34 34 34
2 -8 9 34 34 34
3 -8 9 34 34 34
4 -8 9 34 34 34
5 -8 9 34 34 34
6 -8 9 34 34 34
7 -8 9 34 34 34
-5 -7 9 34 34 34
-4 -7 9 34 34 34
-3 -7 9 34 34 34
-2 -7 9 34 34 34
-1 -7 9 34 34 34
0 -7 9 34 34 34
1 -7 9 34 34 34
2 -7 9 34 34 34
3 -7 9 34 34 34
4 -7 9 34 34 34
5 -7 9 34 34 34
6 -7 9 34 34 34
7 -7 9 34 34 34
-5 -6 9 34 34 34
-4 -6 9 34 34 34
-3 -6 9 34 34 34
-2 -6 9 34 34 34
-1 -6 9 34 34 34
0 -6 9 34 34 34
1 -6 9 34 34 34
2 -6 9 34 34 34
3 -6 9 34 34 34
4 -6 9 34 34 34
5 -6 9 34 34 34
6 -6 9 34 34 34
7 -6 9 34 34 34
-5 -5 9 34 34 34
-4 -5 9 34 34 34
-3 -5 9 34 34 34
-2 -5 9 34 34 34
-1 -5 9 34 34 34
0 -5 9 34 34 34
1 -5 9 34 34 34
2 -5 9 34 34 34
3 -5 9 34 34 34
4 -5 9 34 34 34
5 -5 9 34 34 34
6 -5 9 34 34 34
7 -5 9 34 34 34
-5 -4 9 34 34 34
-4 -4 9 51 166 184
-3 -4 9 51 166 184
-2 -4 9 51 166 184
-1 -4 9 51 166 184
0 -4 9 51 166 184
1 -4 9 51 166 184
2 -4 9 51 166 184
3 -4 9 51 166 184
4 -4 9 51 166 184
5 -4 9 51 166 184
6 -4 9 51 166 184
7 -4 9 34 34 34
-5 -3 9 238 238 238
-4 -3 9 51 166 184
-3 -3 9 51 166 184
-2 -3 9 51 166 184
-1 -3 9 51 166 184
0 -3 9 51 166 184
1 -3 9 51 166 184
2 -3 9 51 166 184
3 -3 9 51 166 184
4 -3 9 51 166 184
5 -3 9 51 166 184
6 -3 9 51 166 184
7 -3 9 238 238 238
-5 -2 9 34 34 34
-4 -2 9 51 166 184
-3 -2 9 51 166 184
-2 -2 9 51 166 184
-1 -2 9 51 166 184
0 -2 9 51 166 184
1 -2 9 51 166 184
2 -2 9 51 166 184
3 -2 9 51 166 184
4 -2 9 51 166 184
5 -2 9 51 166 184
6 -2 9 51 166 184
7 -2 9 34 34 34
-5 -1 9 34 34 34
-4 -1 9 51 166 184
-3 -1 9 51 166 184
-2 -1 9 51 166 184
-1 -1 9 51 166 184
0 -1 9 51 166 184
1 -1 9 51 166 184
2 -1 9 51 166 184
3 -1 9 51 166 184
4 -1 9 51 166 184
5 -1 9 51 166 184
6 -1 9 51 166 184
7 -1 9 34 34 34
-5 0 9 34 34 34
-4 0 9 51 166 184
-3 0 9 51 166 184
-2 0 9 51 166 184
-1 0 9 51 166 184
0 0 9 51 166 184
1 0 9 51 166 184
2 0 9 51 166 184
3 0 9 51 166 184
4 0 9 51 166 184
5 0 9 51 166 184
6 0 9 51 166 184
7 0 9 34 34 34
-5 1 9 34 34 34
-4 1 9 51 166 184
-3 1 9 51 166 184
-2 1 9 51 166 184
-1 1 9 51 166 184
0 1 9 51 166 184
1 1 9 51 166 184
2 1 9 51 166 184
3 1 9 51 166 184
4 1 9 51 166 184
5 1 9 51 166 184
6 1 9 51 166 184
7 1 9 34 34 34
-5 2 9 34 34 34
-4 2 9 51 166 184
-3 2 9 51 166 184
-2 2 9 51 166 184
-1 2 9 51 166 184
0 2 9 51 166 184
1 2 9 51 166 184
2 2 9 51 166 184
3 2 9 51 166 184
4 2 9 51 166 184
5 2 9 51 166 184
6 2 9 51 166 184
7 2 9 34 34 34
-5 3 9 34 34 34
-4 3 9 51 166 184
-3 3 9 51 166 184
-2 3 9 51 166 184
-1 3 9 51 166 184
0 3 9 51 166 184
1 3 9 51 166 184
2 3 9 51 166 184
3 3 9 51 166 184
4 3 9 51 166 184
5 3 9 51 166 184
6 3 9 51 166 184
7 3 9 34 34 34
-5 4 9 34 34 34
-4 4 9 51 166 184
-3 4 9 51 166 184
-2 4 9 51 166 184
-1 4 9 51 166 184
0 4 9 51 166 184
1 4 9 51 166 184
2 4 9 51 166 184
3 4 9 51 166 184
4 4 9 51 166 184
5 4 9 51 166 184
6 4 9 51 166 184
7 4 9 34 34 34
-5 5 9 238 238 238
-4 5 9 34 34 34
-3 5 9 34 34 34
-2 5 9 34 34 34
-1 5 9 34 34 34
0 5 9 34 34 34
1 5 9 34 34 34
2 5 9 34 34 34
3 5 9 34 34 34
4 5 9 34 34 34
5 5 9 34 34 34
6 5 9 34 34 34
7 5 9 238 238 238
-5 -9 10 238 238 238
-4 -9 10 238 238 238
-3 -9 10 238 238 238
-2 -9 10 238 238 238
-1 -9 10 238 238 238
0 -9 10 238 238 238
1 -9 10 238 238 238
2 -9 10 238 238 238
3 -9 10 238 238 238
4 -9 10 238 238 238
5 -9 10 238 238 238
6 -9 10 238 238 238
7 -9 10 238 238 238
-5 -8 10 238 238 238
-4 -8 10 238 238 238
-3 -8 10 238 238 238
-2 -8 10 238 238 238
-1 -8 10 238 238 238
0 -8 10 238 238 238
1 -8 10 238 238 238
2 -8 10 238 238 238
3 -8 10 238 238 238
4 -8 10 238 238 238
5 -8 10 238 238 238
6 -8 10 238 238 238
7 -8 10 238 238 238
-5 -7 10 238 238 238
-4 -7 10 238 238 238
-3 -7 10 238 238 238
-2 -7 10 238 238 238
-1 -7 10 238 238 238
0 -7 10 238 238 238
1 -7 10 238 238 238
2 -7 10 238 238 238
3 -7 10 238 238 238
4 -7 10 238 238 238
5 -7 10 238 238 238
6 -7 10 238 238 238
7 -7 10 238 238 238
-5 -6 10 238 238 238
-4 -6 10 238 238 238
-3 -6 10 238 238 238
-2 -6 10 238 238 238
-1 -6 10 238 238 238
0 -6 10 238 238 238
1 -6 10 238 238 238
2 -6 10 238 238 238
3 -6 10 238 238 238
4 -6 10 238 238 238
5 -6 10 238 238 238
6 -6 10 238 238 238
7 -6 10 238 238 238
-5 -5 10 238 238 238
-4 -5 10 238 238 238
-3 -5 10 238 238 238
-2 -5 10 238 238 238
-1 -5 10 238 238 238
0 -5 10 238 238 238
1 -5 10 238 238 238
2 -5 10 238 238 238
3 -5 10 238 238 238
4 -5 10 238 238 238
5 -5 10 238 238 238
6 -5 10 238 238 238
7 -5 10 238 238 238
-5 -4 10 238 238 238
-4 -4 10 238 238 238
-3 -4 10 238 238 238
-2 -4 10 238 238 238
-1 -4 10 238 238 238
0 -4 10 238 238 238
1 -4 10 238 238 238
2 -4 10 238 238 238
3 -4 10 238 238 238
4 -4 10 238 238 238
5 -4 10 238 238 238
6 -4 10 238 238 238
7 -4 10 238 238 238
-5 -3 10 238 238 238
-4 -3 10 238 238 238
-3 -3 10 238 238 238
-2 -3 10 238 238 238
-1 -3 10 238 238 238
0 -3 10 238 238 238
1 -3 10 238 238 238
2 -3 10 238 238 238
3 -3 10 238 238 238
4 -3 10 238 238 238
5 -3 10 238 238 238
6 -3 10 238 238 238
7 -3 10 238 238 238
-5 -2 10 238 238 238
-4 -2 10 238 238 238
-3 -2 10 238 238 238
-2 -2 10 238 238 238
-1 -2 10 238 238 238
0 -2 10 238 238 238
1 -2 10 238 238 238
2 -2 10 238 238 238
3 -2 10 238 238 238
4 -2 10 238 238 238
5 -2 10 238 238 238
6 -2 10 238 238 238
7 -2 10 238 238 238
-5 -1 10 238 238 238
-4 -1 10 238 238 238
-3 -1 10 238 238 238
-2 -1 10 238 238 238
-1 -1 10 238 238 238
0 -1 10 238 238 238
1 -1 10 238 238 238
2 -1 10 238 238 238
3 -1 10 238 238 238
4 -1 10 238 238 238
5 -1 10 238 238 238
6 -1 10 238 238 238
7 -1 10 238 238 238
-5 0 10 238 238 238
-4 0 10 238 238 238
-3 0 10 238 238 238
-2 0 10 238 238 238
-1 0 10 238 238 238
0 0 10 238 238 238
1 0 10 238 238 238
2 0 10 238 238 238
3 0 10 238 238 238
4 0 10 238 238 238
5 0 10 238 238 238
6 0 10 238 238 238
7 0 10 238 238 238
-5 1 10 238 238 238
-4 1 10 238 238 238
-3 1 10 238 238 238
-2 1 10 238 238 238
-1 1 10 238 238 238
0 1 10 238 238 238
1 1 10 238 238 238
2 1 10 238 238 238
3 1 10 238 238 238
4 1 10 238 238 238
5 1 10 238 238 238
6 1 10 238 238 238
7 1 10 238 238 238
-5 2 10 238 238 238
-4 2 10 238 238 238
-3 2 10 238 238 238
-2 2 10 238 238 238
-1 2 10 238 238 238
0 2 10 238 238 238
1 2 10 238 238 238
2 2 10 238 238 238
3 2 10 238 238 238
4 2 10 238 238 238
5 2 10 238 238 238
6 2 10 238 238 238
7 2 10 238 238 238
-5 3 10 238 238 238
-4 3 10 238 238 238
-3 3 10 238 238 238
-2 3 10 238 238 238
-1 3 10 238 238 238
0 3 10 238 238 238
1 3 10 238 238 238
2 3 10 238 238 238
3 3 10 238 238 238
4 3 10 238 238 238
5 3 10 238 238 238
6 3 10 238 238 238
7 3 10 238 238 238
-5 4 10 238 238 238
-4 4 10 238 238 238
-3 4 10 238 238 238
-2 4 10 238 238 238
-1 4 10 238 238 238
0 4 10 238 238 238
1 4 10 238 238 238
2 4 10 238 238 238
3 4 10 238 238 238
4 4 10 238 238 238
5 4 10 238 238 238
6 4 10 238 238 238
7 4 10 238 238 238
-5 5 10 238 238 238
-4 5 10 238 238 238
-3 5 10 238 238 238
-2 5 10 238 238 238
-1 5 10 238 238 238
0 5 10 238 238 238
1 5 10 238 238 238
2 5 10 238 238 238
3 5 10 238 238 238
4 5 10 238 238 238
5 5 10 238 238 238
6 5 10 238 238 238
7 5 10 238 238 238
-4 -2 11 187 187 187
6 -2 11 187 187 187
-4 -1 11 187 187 187
6 -1 11 187 187 187
-4 0 11 187 187 187
6 0 11 187 187 187
-5 -2 12 0 92 175
-4 -2 12 0 92 175
-3 -2 12 0 92 175
-2 -2 12 0 92 175
-1 -2 12 170 170 170
0 -2 12 170 170 170
1 -2 12 170 170 170
2 -2 12 170 170 170
3 -2 12 170 170 170
4 -2 12 159 53 58
5 -2 12 159 53 58
6 -2 12 159 53 58
7 -2 12 159 53 58
-5 -1 12 0 92 175
-4 -1 12 0 92 175
-3 -1 12 0 92 175
-2 -1 12 0 92 175
-1 -1 12 170 170 170
0 -1 12 170 170 170
1 -1 12 170 170 170
2 -1 12 170 170 170
3 -1 12 170 170 170
4 -1 12 159 53 58
5 -1 12 159 53 58
6 -1 12 159 53 58
7 -1 12 159 53 58
-5 0 12 0 92 175
-4 0 12 0 92 175
-3 0 12 0 92 175
-2 0 12 0 92 175
-1 0 12 170 170 170
0 0 12 170 170 170
1 0 12 170 170 170
2 0 12 170 170 170
3 0 12 170 170 170
4 0 12 159 53 58
5 0 12 159 53 58
6 0 12 159 53 58
7 0 12 159 53 58
