ply
format ascii 1.0
comment : MagicaVoxel @ Ephtracy
element vertex 97
property float x
property float y
property float z
property uchar red
property uchar green
property uchar blue
end_header
-3 -3 0 17 0 0
-2 -3 0 17 0 0
1 -3 0 17 0 0
2 -3 0 17 0 0
-3 -2 0 17 0 0
-2 -2 0 17 0 0
1 -2 0 17 0 0
2 -2 0 17 0 0
-3 1 0 17 0 0
-2 1 0 17 0 0
1 1 0 17 0 0
2 1 0 17 0 0
-3 2 0 17 0 0
-2 2 0 17 0 0
1 2 0 17 0 0
2 2 0 17 0 0
-2 -4 1 221 0 0
-1 -4 1 221 0 0
0 -4 1 221 0 0
1 -4 1 221 0 0
-3 -3 1 17 0 0
-2 -3 1 17 0 0
-1 -3 1 221 0 0
0 -3 1 221 0 0
1 -3 1 17 0 0
2 -3 1 17 0 0
-3 -2 1 17 0 0
-2 -2 1 17 0 0
-1 -2 1 221 0 0
0 -2 1 221 0 0
1 -2 1 17 0 0
2 -2 1 17 0 0
-2 -1 1 221 0 0
-1 -1 1 221 0 0
0 -1 1 221 0 0
1 -1 1 221 0 0
-2 0 1 221 0 0
-1 0 1 221 0 0
0 0 1 221 0 0
1 0 1 221 0 0
-3 1 1 17 0 0
-2 1 1 17 0 0
-1 1 1 221 0 0
0 1 1 221 0 0
1 1 1 17 0 0
2 1 1 17 0 0
-3 2 1 17 0 0
-2 2 1 17 0 0
-1 2 1 221 0 0
0 2 1 221 0 0
1 2 1 17 0 0
2 2 1 17 0 0
-1 -3 2 238 238 238
0 -3 2 238 238 238
-2 -2 2 221 0 0
-1 -2 2 221 0 0
0 -2 2 221 0 0
1 -2 2 221 0 0
-2 -1 2 221 0 0
-1 -1 2 221 0 0
0 -1 2 221 0 0
1 -1 2 221 0 0
-2 0 2 221 0 0
-1 0 2 221 0 0
0 0 2 221 0 0
1 0 2 221 0 0
-2 1 2 221 0 0
-1 1 2 221 0 0
0 1 2 221 0 0
1 1 2 221 0 0
-2 2 2 221 0 0
-1 2 2 221 0 0
0 2 2 221 0 0
1 2 2 221 0 0
-1 -2 3 238 238 238
0 -2 3 238 238 238
-1 -1 3 221 0 0
0 -1 3 221 0 0
-1 0 3 221 0 0
0 0 3 221 0 0
1 0 3 221 0 0
-2 1 3 221 0 0
-1 1 3 221 0 0
0 1 3 221 0 0
1 1 3 221 0 0
-2 2 3 221 0 0
-1 2 3 221 0 0
0 2 3 221 0 0
1 2 3 221 0 0
-2 2 4 221 0 0
1 2 4 221 0 0
-3 2 5 221 0 0
-2 2 5 221 0 0
-1 2 5 221 0 0
0 2 5 221 0 0
1 2 5 221 0 0
2 2 5 221 0 0
