ply
format ascii 1.0
comment : MagicaVoxel @ Ephtracy
element vertex 2680
property float x
property float y
property float z
property uchar red
property uchar green
property uchar blue
end_header
-10 -10 0 120 125 123
-9 -10 0 120 125 123
-8 -10 0 120 125 123
-7 -10 0 120 125 123
-6 -10 0 120 125 123
-5 -10 0 120 125 123
-4 -10 0 120 125 123
-3 -10 0 120 125 123
-2 -10 0 120 125 123
-1 -10 0 120 125 123
0 -10 0 120 125 123
1 -10 0 120 125 123
2 -10 0 120 125 123
3 -10 0 120 125 123
4 -10 0 120 125 123
5 -10 0 120 125 123
6 -10 0 120 125 123
7 -10 0 120 125 123
8 -10 0 120 125 123
9 -10 0 120 125 123
-10 -9 0 120 125 123
-9 -9 0 120 85 43
-8 -9 0 120 85 43
-7 -9 0 135 102 51
-6 -9 0 135 102 51
-5 -9 0 135 102 51
-4 -9 0 120 85 43
-3 -9 0 135 102 51
-2 -9 0 120 85 43
-1 -9 0 120 85 43
0 -9 0 120 85 43
1 -9 0 135 102 51
2 -9 0 135 102 51
3 -9 0 120 85 43
4 -9 0 120 85 43
5 -9 0 135 102 51
6 -9 0 135 102 51
7 -9 0 120 85 43
8 -9 0 120 85 43
9 -9 0 120 125 123
-10 -8 0 120 125 123
-9 -8 0 120 85 43
-8 -8 0 120 85 43
-7 -8 0 135 102 51
-6 -8 0 135 102 51
-5 -8 0 120 85 43
-4 -8 0 120 85 43
-3 -8 0 135 102 51
-2 -8 0 120 85 43
-1 -8 0 120 85 43
0 -8 0 120 85 43
1 -8 0 135 102 51
2 -8 0 120 85 43
3 -8 0 120 85 43
4 -8 0 120 85 43
5 -8 0 135 102 51
6 -8 0 135 102 51
7 -8 0 120 85 43
8 -8 0 120 85 43
9 -8 0 120 125 123
-10 -7 0 120 125 123
-9 -7 0 120 85 43
-8 -7 0 120 85 43
-7 -7 0 135 102 51
-6 -7 0 120 85 43
-5 -7 0 120 85 43
-4 -7 0 120 85 43
-3 -7 0 135 102 51
-2 -7 0 120 85 43
-1 -7 0 120 85 43
0 -7 0 120 85 43
1 -7 0 135 102 51
2 -7 0 120 85 43
3 -7 0 120 85 43
4 -7 0 120 85 43
5 -7 0 135 102 51
6 -7 0 120 85 43
7 -7 0 120 85 43
8 -7 0 120 85 43
9 -7 0 120 125 123
-10 -6 0 120 125 123
-9 -6 0 120 85 43
-8 -6 0 120 85 43
-7 -6 0 135 102 51
-6 -6 0 120 85 43
-5 -6 0 120 85 43
-4 -6 0 120 85 43
-3 -6 0 135 102 51
-2 -6 0 120 85 43
-1 -6 0 120 85 43
0 -6 0 120 85 43
1 -6 0 135 102 51
2 -6 0 120 85 43
3 -6 0 120 85 43
4 -6 0 120 85 43
5 -6 0 135 102 51
6 -6 0 120 85 43
7 -6 0 120 85 43
8 -6 0 120 85 43
9 -6 0 120 125 123
-10 -5 0 120 125 123
-9 -5 0 120 85 43
-8 -5 0 120 85 43
-7 -5 0 135 102 51
-6 -5 0 120 85 43
-5 -5 0 120 85 43
-4 -5 0 120 85 43
-3 -5 0 135 102 51
-2 -5 0 120 85 43
-1 -5 0 120 85 43
0 -5 0 120 85 43
1 -5 0 135 102 51
2 -5 0 120 85 43
3 -5 0 120 85 43
4 -5 0 120 85 43
5 -5 0 135 102 51
6 -5 0 120 85 43
7 -5 0 120 85 43
8 -5 0 120 85 43
9 -5 0 120 125 123
-10 -4 0 120 125 123
-9 -4 0 120 85 43
-8 -4 0 120 85 43
-7 -4 0 135 102 51
-6 -4 0 120 85 43
-5 -4 0 120 85 43
-4 -4 0 120 85 43
-3 -4 0 135 102 51
-2 -4 0 120 85 43
-1 -4 0 120 85 43
0 -4 0 120 85 43
1 -4 0 135 102 51
2 -4 0 120 85 43
3 -4 0 120 85 43
4 -4 0 120 85 43
5 -4 0 135 102 51
6 -4 0 120 85 43
7 -4 0 120 85 43
8 -4 0 120 85 43
9 -4 0 120 125 123
-10 -3 0 120 125 123
-9 -3 0 120 85 43
-8 -3 0 120 85 43
-7 -3 0 135 102 51
-6 -3 0 120 85 43
-5 -3 0 120 85 43
-4 -3 0 120 85 43
-3 -3 0 135 102 51
-2 -3 0 120 85 43
-1 -3 0 120 85 43
0 -3 0 120 85 43
1 -3 0 135 102 51
2 -3 0 120 85 43
3 -3 0 120 85 43
4 -3 0 120 85 43
5 -3 0 135 102 51
6 -3 0 120 85 43
7 -3 0 120 85 43
8 -3 0 120 85 43
9 -3 0 120 125 123
-10 -2 0 120 125 123
-9 -2 0 120 85 43
-8 -2 0 120 85 43
-7 -2 0 135 102 51
-6 -2 0 120 85 43
-5 -2 0 120 85 43
-4 -2 0 120 85 43
-3 -2 0 135 102 51
-2 -2 0 120 85 43
-1 -2 0 120 85 43
0 -2 0 120 85 43
1 -2 0 135 102 51
2 -2 0 120 85 43
3 -2 0 120 85 43
4 -2 0 120 85 43
5 -2 0 135 102 51
6 -2 0 120 85 43
7 -2 0 120 85 43
8 -2 0 120 85 43
9 -2 0 120 125 123
-10 -1 0 120 125 123
-9 -1 0 120 85 43
-8 -1 0 120 85 43
-7 -1 0 135 102 51
-6 -1 0 120 85 43
-5 -1 0 120 85 43
-4 -1 0 120 85 43
-3 -1 0 135 102 51
-2 -1 0 120 85 43
-1 -1 0 120 85 43
0 -1 0 120 85 43
1 -1 0 135 102 51
2 -1 0 120 85 43
3 -1 0 120 85 43
4 -1 0 120 85 43
5 -1 0 135 102 51
6 -1 0 120 85 43
7 -1 0 120 85 43
8 -1 0 120 85 43
9 -1 0 120 125 123
-10 0 0 120 125 123
-9 0 0 120 85 43
-8 0 0 120 85 43
-7 0 0 135 102 51
-6 0 0 120 85 43
-5 0 0 120 85 43
-4 0 0 120 85 43
-3 0 0 135 102 51
-2 0 0 120 85 43
-1 0 0 120 85 43
0 0 0 120 85 43
1 0 0 135 102 51
2 0 0 135 102 51
3 0 0 120 85 43
4 0 0 120 85 43
5 0 0 135 102 51
6 0 0 120 85 43
7 0 0 120 85 43
8 0 0 120 85 43
9 0 0 120 125 123
-10 1 0 120 125 123
-9 1 0 120 85 43
-8 1 0 120 85 43
-7 1 0 135 102 51
-6 1 0 120 85 43
-5 1 0 120 85 43
-4 1 0 120 85 43
-3 1 0 135 102 51
-2 1 0 120 85 43
-1 1 0 120 85 43
0 1 0 120 85 43
1 1 0 135 102 51
2 1 0 135 102 51
3 1 0 120 85 43
4 1 0 120 85 43
5 1 0 135 102 51
6 1 0 120 85 43
7 1 0 120 85 43
8 1 0 120 85 43
9 1 0 120 125 123
-10 2 0 120 125 123
-9 2 0 120 85 43
-8 2 0 120 85 43
-7 2 0 135 102 51
-6 2 0 120 85 43
-5 2 0 120 85 43
-4 2 0 120 85 43
-3 2 0 135 102 51
-2 2 0 120 85 43
-1 2 0 120 85 43
0 2 0 120 85 43
1 2 0 135 102 51
2 2 0 120 85 43
3 2 0 120 85 43
4 2 0 120 85 43
5 2 0 135 102 51
6 2 0 120 85 43
7 2 0 120 85 43
8 2 0 120 85 43
9 2 0 120 125 123
-10 3 0 120 125 123
-9 3 0 120 85 43
-8 3 0 120 85 43
-7 3 0 135 102 51
-6 3 0 120 85 43
-5 3 0 120 85 43
-4 3 0 120 85 43
-3 3 0 135 102 51
-2 3 0 120 85 43
-1 3 0 120 85 43
0 3 0 120 85 43
1 3 0 135 102 51
2 3 0 120 85 43
3 3 0 120 85 43
4 3 0 120 85 43
5 3 0 135 102 51
6 3 0 120 85 43
7 3 0 120 85 43
8 3 0 120 85 43
9 3 0 120 125 123
-10 4 0 120 125 123
-9 4 0 120 85 43
-8 4 0 120 85 43
-7 4 0 135 102 51
-6 4 0 120 85 43
-5 4 0 120 85 43
-4 4 0 120 85 43
-3 4 0 135 102 51
-2 4 0 120 85 43
-1 4 0 120 85 43
0 4 0 120 85 43
1 4 0 135 102 51
2 4 0 120 85 43
3 4 0 120 85 43
4 4 0 120 85 43
5 4 0 135 102 51
6 4 0 120 85 43
7 4 0 120 85 43
8 4 0 120 85 43
9 4 0 120 125 123
-10 5 0 120 125 123
-9 5 0 120 85 43
-8 5 0 120 85 43
-7 5 0 135 102 51
-6 5 0 120 85 43
-5 5 0 120 85 43
-4 5 0 120 85 43
-3 5 0 135 102 51
-2 5 0 120 85 43
-1 5 0 120 85 43
0 5 0 120 85 43
1 5 0 135 102 51
2 5 0 120 85 43
3 5 0 120 85 43
4 5 0 120 85 43
5 5 0 135 102 51
6 5 0 120 85 43
7 5 0 120 85 43
8 5 0 120 85 43
9 5 0 120 125 123
-10 6 0 120 125 123
-9 6 0 120 85 43
-8 6 0 120 85 43
-7 6 0 135 102 51
-6 6 0 120 85 43
-5 6 0 120 85 43
-4 6 0 120 85 43
-3 6 0 135 102 51
-2 6 0 120 85 43
-1 6 0 120 85 43
0 6 0 120 85 43
1 6 0 135 102 51
2 6 0 120 85 43
3 6 0 120 85 43
4 6 0 120 85 43
5 6 0 135 102 51
6 6 0 120 85 43
7 6 0 120 85 43
8 6 0 120 85 43
9 6 0 120 125 123
-10 7 0 120 125 123
-9 7 0 120 85 43
-8 7 0 135 102 51
-7 7 0 135 102 51
-6 7 0 120 85 43
-5 7 0 120 85 43
-4 7 0 120 85 43
-3 7 0 135 102 51
-2 7 0 120 85 43
-1 7 0 120 85 43
0 7 0 120 85 43
1 7 0 135 102 51
2 7 0 120 85 43
3 7 0 120 85 43
4 7 0 120 85 43
5 7 0 135 102 51
6 7 0 120 85 43
7 7 0 120 85 43
8 7 0 135 102 51
9 7 0 120 125 123
-10 8 0 120 125 123
-9 8 0 135 102 51
-8 8 0 135 102 51
-7 8 0 135 102 51
-6 8 0 120 85 43
-5 8 0 120 85 43
-4 8 0 135 102 51
-3 8 0 135 102 51
-2 8 0 120 85 43
-1 8 0 120 85 43
0 8 0 135 102 51
1 8 0 135 102 51
2 8 0 120 85 43
3 8 0 120 85 43
4 8 0 135 102 51
5 8 0 135 102 51
6 8 0 120 85 43
7 8 0 135 102 51
8 8 0 135 102 51
9 8 0 120 125 123
-10 9 0 120 125 123
-9 9 0 120 125 123
-8 9 0 120 125 123
-7 9 0 120 125 123
-6 9 0 120 125 123
-5 9 0 120 125 123
-4 9 0 120 125 123
-3 9 0 120 125 123
-2 9 0 120 125 123
-1 9 0 120 125 123
0 9 0 120 125 123
1 9 0 120 125 123
2 9 0 120 125 123
3 9 0 120 125 123
4 9 0 120 125 123
5 9 0 120 125 123
6 9 0 120 125 123
7 9 0 120 125 123
8 9 0 120 125 123
9 9 0 120 125 123
-10 -10 1 120 125 123
-9 -10 1 120 125 123
-8 -10 1 120 125 123
-7 -10 1 120 125 123
-6 -10 1 120 125 123
-5 -10 1 120 125 123
-4 -10 1 120 125 123
-3 -10 1 120 125 123
-2 -10 1 120 125 123
-1 -10 1 120 125 123
0 -10 1 120 125 123
1 -10 1 120 125 123
2 -10 1 120 125 123
3 -10 1 120 125 123
4 -10 1 120 125 123
5 -10 1 120 125 123
6 -10 1 120 125 123
7 -10 1 120 125 123
8 -10 1 120 125 123
9 -10 1 120 125 123
-10 -9 1 120 125 123
-9 -9 1 120 85 43
-4 -9 1 120 85 43
-2 -9 1 120 85 43
-1 -9 1 120 85 43
0 -9 1 120 85 43
3 -9 1 120 85 43
4 -9 1 120 85 43
7 -9 1 120 85 43
8 -9 1 120 85 43
9 -9 1 120 125 123
-10 -8 1 120 125 123
-9 -8 1 120 85 43
-8 -8 1 120 85 43
-5 -8 1 120 85 43
-4 -8 1 120 85 43
-2 -8 1 120 85 43
-1 -8 1 120 85 43
0 -8 1 120 85 43
2 -8 1 120 85 43
3 -8 1 120 85 43
4 -8 1 120 85 43
7 -8 1 120 85 43
8 -8 1 120 85 43
9 -8 1 120 125 123
-10 -7 1 120 125 123
-9 -7 1 120 85 43
-8 -7 1 120 85 43
-6 -7 1 120 85 43
-5 -7 1 120 85 43
-4 -7 1 120 85 43
-2 -7 1 120 85 43
-1 -7 1 120 85 43
0 -7 1 120 85 43
2 -7 1 120 85 43
3 -7 1 120 85 43
4 -7 1 120 85 43
6 -7 1 120 85 43
7 -7 1 120 85 43
8 -7 1 120 85 43
9 -7 1 120 125 123
-10 -6 1 120 125 123
-9 -6 1 120 85 43
-8 -6 1 120 85 43
-6 -6 1 120 85 43
-5 -6 1 120 85 43
-4 -6 1 120 85 43
-2 -6 1 120 85 43
-1 -6 1 120 85 43
0 -6 1 120 85 43
2 -6 1 120 85 43
3 -6 1 120 85 43
4 -6 1 120 85 43
6 -6 1 120 85 43
7 -6 1 120 85 43
8 -6 1 120 85 43
9 -6 1 120 125 123
-10 -5 1 120 125 123
-9 -5 1 120 85 43
-8 -5 1 120 85 43
-6 -5 1 120 85 43
-5 -5 1 120 85 43
-4 -5 1 120 85 43
-2 -5 1 120 85 43
-1 -5 1 120 85 43
0 -5 1 120 85 43
2 -5 1 120 85 43
3 -5 1 120 85 43
4 -5 1 120 85 43
6 -5 1 120 85 43
7 -5 1 120 85 43
8 -5 1 120 85 43
9 -5 1 120 125 123
-10 -4 1 120 125 123
-9 -4 1 120 85 43
-8 -4 1 120 85 43
-6 -4 1 120 85 43
-5 -4 1 120 85 43
-4 -4 1 120 85 43
-2 -4 1 120 85 43
-1 -4 1 120 85 43
0 -4 1 120 85 43
2 -4 1 120 85 43
3 -4 1 120 85 43
4 -4 1 120 85 43
6 -4 1 120 85 43
7 -4 1 120 85 43
8 -4 1 120 85 43
9 -4 1 120 125 123
-10 -3 1 120 125 123
-9 -3 1 120 85 43
-8 -3 1 120 85 43
-6 -3 1 120 85 43
-5 -3 1 120 85 43
-4 -3 1 120 85 43
-2 -3 1 120 85 43
-1 -3 1 120 85 43
0 -3 1 120 85 43
2 -3 1 120 85 43
3 -3 1 120 85 43
4 -3 1 120 85 43
6 -3 1 120 85 43
7 -3 1 120 85 43
8 -3 1 120 85 43
9 -3 1 120 125 123
-10 -2 1 120 125 123
-9 -2 1 120 85 43
-8 -2 1 120 85 43
-6 -2 1 120 85 43
-5 -2 1 120 85 43
-4 -2 1 120 85 43
-2 -2 1 120 85 43
-1 -2 1 120 85 43
0 -2 1 120 85 43
2 -2 1 120 85 43
3 -2 1 120 85 43
4 -2 1 120 85 43
6 -2 1 120 85 43
7 -2 1 120 85 43
8 -2 1 120 85 43
9 -2 1 120 125 123
-10 -1 1 120 125 123
-9 -1 1 120 85 43
-8 -1 1 120 85 43
-6 -1 1 120 85 43
-5 -1 1 120 85 43
-4 -1 1 120 85 43
-2 -1 1 120 85 43
-1 -1 1 120 85 43
0 -1 1 120 85 43
2 -1 1 120 85 43
3 -1 1 120 85 43
4 -1 1 120 85 43
6 -1 1 120 85 43
7 -1 1 120 85 43
8 -1 1 120 85 43
9 -1 1 120 125 123
-10 0 1 120 125 123
-9 0 1 120 85 43
-8 0 1 120 85 43
-6 0 1 120 85 43
-5 0 1 120 85 43
-4 0 1 120 85 43
-2 0 1 120 85 43
-1 0 1 120 85 43
0 0 1 120 85 43
3 0 1 120 85 43
4 0 1 120 85 43
6 0 1 120 85 43
7 0 1 120 85 43
8 0 1 120 85 43
9 0 1 120 125 123
-10 1 1 120 125 123
-9 1 1 120 85 43
-8 1 1 120 85 43
-6 1 1 120 85 43
-5 1 1 120 85 43
-4 1 1 120 85 43
-2 1 1 120 85 43
-1 1 1 120 85 43
0 1 1 120 85 43
3 1 1 120 85 43
4 1 1 120 85 43
6 1 1 120 85 43
7 1 1 120 85 43
8 1 1 120 85 43
9 1 1 120 125 123
-10 2 1 120 125 123
-9 2 1 120 85 43
-8 2 1 120 85 43
-6 2 1 120 85 43
-5 2 1 120 85 43
-4 2 1 120 85 43
-2 2 1 120 85 43
-1 2 1 120 85 43
0 2 1 120 85 43
2 2 1 120 85 43
3 2 1 120 85 43
4 2 1 120 85 43
6 2 1 120 85 43
7 2 1 120 85 43
8 2 1 120 85 43
9 2 1 120 125 123
-10 3 1 120 125 123
-9 3 1 120 85 43
-8 3 1 120 85 43
-6 3 1 120 85 43
-5 3 1 120 85 43
-4 3 1 120 85 43
-2 3 1 120 85 43
-1 3 1 120 85 43
0 3 1 120 85 43
2 3 1 120 85 43
3 3 1 120 85 43
4 3 1 120 85 43
6 3 1 120 85 43
7 3 1 120 85 43
8 3 1 120 85 43
9 3 1 120 125 123
-10 4 1 120 125 123
-9 4 1 120 85 43
-8 4 1 120 85 43
-6 4 1 120 85 43
-5 4 1 120 85 43
-4 4 1 120 85 43
-2 4 1 120 85 43
-1 4 1 120 85 43
0 4 1 120 85 43
2 4 1 120 85 43
3 4 1 120 85 43
4 4 1 120 85 43
6 4 1 120 85 43
7 4 1 120 85 43
8 4 1 120 85 43
9 4 1 120 125 123
-10 5 1 120 125 123
-9 5 1 120 85 43
-8 5 1 120 85 43
-6 5 1 120 85 43
-5 5 1 120 85 43
-4 5 1 120 85 43
-2 5 1 120 85 43
-1 5 1 120 85 43
0 5 1 120 85 43
2 5 1 120 85 43
3 5 1 120 85 43
4 5 1 120 85 43
6 5 1 120 85 43
7 5 1 120 85 43
8 5 1 120 85 43
9 5 1 120 125 123
-10 6 1 120 125 123
-9 6 1 120 85 43
-8 6 1 120 85 43
-6 6 1 120 85 43
-5 6 1 120 85 43
-4 6 1 120 85 43
-2 6 1 120 85 43
-1 6 1 120 85 43
0 6 1 120 85 43
2 6 1 120 85 43
3 6 1 120 85 43
4 6 1 120 85 43
6 6 1 120 85 43
7 6 1 120 85 43
8 6 1 120 85 43
9 6 1 120 125 123
-10 7 1 120 125 123
-9 7 1 120 85 43
-8 7 1 55 60 56
-6 7 1 120 85 43
-5 7 1 120 85 43
-4 7 1 120 85 43
-2 7 1 120 85 43
-1 7 1 120 85 43
0 7 1 120 85 43
2 7 1 120 85 43
3 7 1 120 85 43
4 7 1 120 85 43
6 7 1 120 85 43
7 7 1 120 85 43
9 7 1 120 125 123
-10 8 1 120 125 123
-9 8 1 55 60 56
-8 8 1 55 60 56
-6 8 1 120 85 43
-5 8 1 120 85 43
-2 8 1 120 85 43
-1 8 1 120 85 43
2 8 1 120 85 43
3 8 1 120 85 43
6 8 1 120 85 43
9 8 1 120 125 123
-10 9 1 120 125 123
-9 9 1 120 125 123
-8 9 1 120 125 123
-7 9 1 120 125 123
-6 9 1 120 125 123
-5 9 1 120 125 123
-4 9 1 120 125 123
-3 9 1 120 125 123
-2 9 1 120 125 123
-1 9 1 120 125 123
0 9 1 120 125 123
1 9 1 120 125 123
2 9 1 120 125 123
3 9 1 120 125 123
4 9 1 120 125 123
5 9 1 120 125 123
6 9 1 120 125 123
7 9 1 120 125 123
8 9 1 120 125 123
9 9 1 120 125 123
-10 -10 2 120 125 123
-9 -10 2 120 125 123
-8 -10 2 120 125 123
-7 -10 2 120 125 123
-6 -10 2 120 125 123
-5 -10 2 120 125 123
-4 -10 2 120 125 123
-3 -10 2 120 125 123
2 -10 2 120 125 123
3 -10 2 120 125 123
4 -10 2 120 125 123
5 -10 2 120 125 123
6 -10 2 120 125 123
7 -10 2 120 125 123
8 -10 2 120 125 123
9 -10 2 120 125 123
-10 -9 2 120 125 123
-9 -9 2 55 60 56
-8 -9 2 55 60 56
7 -9 2 55 60 56
8 -9 2 55 60 56
9 -9 2 120 125 123
-10 -8 2 120 125 123
-9 -8 2 55 60 56
-8 -8 2 55 60 56
7 -8 2 55 60 56
8 -8 2 55 60 56
9 -8 2 120 125 123
-10 -7 2 120 125 123
9 -7 2 120 125 123
-10 -6 2 120 125 123
9 -6 2 120 125 123
-10 -5 2 120 125 123
9 -5 2 120 125 123
-10 -4 2 120 125 123
9 -4 2 120 125 123
-10 -3 2 120 125 123
9 -3 2 120 125 123
-10 -2 2 120 125 123
9 -2 2 120 125 123
-10 -1 2 120 125 123
9 -1 2 120 125 123
-10 0 2 120 125 123
9 0 2 120 125 123
-10 1 2 120 125 123
9 1 2 120 125 123
-10 2 2 120 125 123
-9 2 2 67 52 27
-5 2 2 67 52 27
9 2 2 120 125 123
-10 3 2 120 125 123
-8 3 2 125 83 44
-7 3 2 125 83 44
-6 3 2 125 83 44
9 3 2 120 125 123
-10 4 2 120 125 123
-8 4 2 125 83 44
-7 4 2 125 83 44
-6 4 2 125 83 44
9 4 2 120 125 123
-10 5 2 120 125 123
-8 5 2 125 83 44
-7 5 2 125 83 44
-6 5 2 125 83 44
9 5 2 120 125 123
-10 6 2 120 125 123
-5 6 2 67 52 27
9 6 2 120 125 123
-10 7 2 120 125 123
-9 7 2 55 60 56
-8 7 2 55 60 56
7 7 2 55 60 56
8 7 2 55 60 56
9 7 2 120 125 123
-10 8 2 120 125 123
-9 8 2 55 60 56
-8 8 2 55 60 56
7 8 2 55 60 56
8 8 2 55 60 56
9 8 2 120 125 123
-10 9 2 120 125 123
-9 9 2 120 125 123
-8 9 2 120 125 123
-7 9 2 120 125 123
-6 9 2 120 125 123
-5 9 2 120 125 123
-4 9 2 120 125 123
-3 9 2 120 125 123
-2 9 2 120 125 123
-1 9 2 120 125 123
0 9 2 120 125 123
1 9 2 120 125 123
2 9 2 120 125 123
3 9 2 120 125 123
4 9 2 120 125 123
5 9 2 120 125 123
6 9 2 120 125 123
7 9 2 120 125 123
8 9 2 120 125 123
9 9 2 120 125 123
-10 -10 3 120 125 123
-9 -10 3 120 125 123
-8 -10 3 120 125 123
-7 -10 3 120 125 123
-6 -10 3 120 125 123
-5 -10 3 120 125 123
-4 -10 3 120 125 123
-3 -10 3 120 125 123
2 -10 3 120 125 123
3 -10 3 120 125 123
4 -10 3 120 125 123
5 -10 3 120 125 123
6 -10 3 120 125 123
7 -10 3 120 125 123
8 -10 3 120 125 123
9 -10 3 120 125 123
-10 -9 3 120 125 123
-9 -9 3 55 60 56
-8 -9 3 55 60 56
7 -9 3 55 60 56
8 -9 3 55 60 56
9 -9 3 120 125 123
-10 -8 3 120 125 123
-9 -8 3 55 60 56
-8 -8 3 55 60 56
7 -8 3 55 60 56
8 -8 3 55 60 56
9 -8 3 120 125 123
-10 -7 3 120 125 123
9 -7 3 120 125 123
-10 -6 3 120 125 123
9 -6 3 120 125 123
-10 -5 3 120 125 123
9 -5 3 120 125 123
-10 -4 3 120 125 123
9 -4 3 120 125 123
-10 -3 3 120 125 123
9 -3 3 120 125 123
-10 -2 3 120 125 123
9 -2 3 120 125 123
-10 -1 3 120 125 123
9 -1 3 120 125 123
-10 0 3 120 125 123
9 0 3 120 125 123
-10 1 3 120 125 123
9 1 3 120 125 123
-10 2 3 120 125 123
-9 2 3 67 52 27
-5 2 3 67 52 27
9 2 3 120 125 123
-10 3 3 120 125 123
-8 3 3 125 83 44
-7 3 3 125 83 44
-6 3 3 125 83 44
9 3 3 120 125 123
-10 4 3 120 125 123
-8 4 3 125 83 44
-7 4 3 125 83 44
-6 4 3 125 83 44
9 4 3 120 125 123
-10 5 3 120 125 123
-8 5 3 125 83 44
-7 5 3 125 83 44
-6 5 3 125 83 44
9 5 3 120 125 123
-10 6 3 120 125 123
-5 6 3 67 52 27
9 6 3 120 125 123
-10 7 3 120 125 123
-9 7 3 55 60 56
-8 7 3 55 60 56
7 7 3 55 60 56
8 7 3 55 60 56
9 7 3 120 125 123
-10 8 3 120 125 123
-9 8 3 55 60 56
-8 8 3 55 60 56
7 8 3 55 60 56
8 8 3 55 60 56
9 8 3 120 125 123
-10 9 3 120 125 123
-9 9 3 120 125 123
-8 9 3 120 125 123
-7 9 3 120 125 123
-6 9 3 120 125 123
-5 9 3 120 125 123
-4 9 3 120 125 123
-3 9 3 150 99 46
-2 9 3 150 99 46
-1 9 3 150 99 46
0 9 3 150 99 46
1 9 3 150 99 46
2 9 3 120 125 123
3 9 3 120 125 123
4 9 3 120 125 123
5 9 3 120 125 123
6 9 3 120 125 123
7 9 3 120 125 123
8 9 3 120 125 123
9 9 3 120 125 123
-10 -10 4 120 125 123
-9 -10 4 120 125 123
-8 -10 4 120 125 123
-7 -10 4 120 125 123
-6 -10 4 120 125 123
-5 -10 4 120 125 123
-4 -10 4 120 125 123
-3 -10 4 120 125 123
2 -10 4 120 125 123
3 -10 4 120 125 123
4 -10 4 120 125 123
5 -10 4 120 125 123
6 -10 4 120 125 123
7 -10 4 120 125 123
8 -10 4 120 125 123
9 -10 4 120 125 123
-10 -9 4 120 125 123
-9 -9 4 55 60 56
-8 -9 4 55 60 56
7 -9 4 55 60 56
8 -9 4 55 60 56
9 -9 4 120 125 123
-10 -8 4 120 125 123
-9 -8 4 55 60 56
-8 -8 4 55 60 56
7 -8 4 55 60 56
8 -8 4 55 60 56
9 -8 4 120 125 123
-10 -7 4 120 125 123
9 -7 4 120 125 123
-10 -6 4 120 125 123
9 -6 4 120 125 123
-10 -5 4 120 125 123
9 -5 4 120 125 123
-10 -4 4 120 125 123
9 -4 4 120 125 123
-10 -3 4 120 125 123
9 -3 4 120 125 123
-10 -2 4 120 125 123
9 -2 4 120 125 123
-10 -1 4 120 125 123
9 -1 4 120 125 123
-10 0 4 120 125 123
9 0 4 120 125 123
-10 1 4 120 125 123
9 1 4 120 125 123
-10 2 4 120 125 123
-9 2 4 67 52 27
-5 2 4 67 52 27
9 2 4 120 125 123
-10 3 4 120 125 123
-8 3 4 125 83 44
-7 3 4 125 83 44
-6 3 4 125 83 44
9 3 4 120 125 123
-10 4 4 120 125 123
-8 4 4 125 83 44
-7 4 4 125 83 44
-6 4 4 125 83 44
9 4 4 120 125 123
-10 5 4 120 125 123
-8 5 4 125 83 44
-7 5 4 125 83 44
-6 5 4 125 83 44
9 5 4 120 125 123
-10 6 4 120 125 123
-5 6 4 67 52 27
9 6 4 120 125 123
-10 7 4 120 125 123
-9 7 4 55 60 56
-8 7 4 55 60 56
7 7 4 55 60 56
8 7 4 55 60 56
9 7 4 120 125 123
-10 8 4 120 125 123
-9 8 4 55 60 56
-8 8 4 55 60 56
7 8 4 55 60 56
8 8 4 55 60 56
9 8 4 120 125 123
-10 9 4 120 125 123
-9 9 4 120 125 123
-8 9 4 120 125 123
-7 9 4 120 125 123
-6 9 4 120 125 123
-5 9 4 120 125 123
-4 9 4 120 125 123
-3 9 4 150 99 46
-2 9 4 0 137 108
-1 9 4 0 137 108
0 9 4 0 137 108
1 9 4 150 99 46
2 9 4 120 125 123
3 9 4 120 125 123
4 9 4 120 125 123
5 9 4 120 125 123
6 9 4 120 125 123
7 9 4 120 125 123
8 9 4 120 125 123
9 9 4 120 125 123
-10 -10 5 120 125 123
-9 -10 5 120 125 123
-8 -10 5 120 125 123
-7 -10 5 120 125 123
-6 -10 5 120 125 123
-5 -10 5 120 125 123
-4 -10 5 120 125 123
-3 -10 5 120 125 123
2 -10 5 120 125 123
3 -10 5 120 125 123
4 -10 5 120 125 123
5 -10 5 120 125 123
6 -10 5 120 125 123
7 -10 5 120 125 123
8 -10 5 120 125 123
9 -10 5 120 125 123
-10 -9 5 120 125 123
-9 -9 5 55 60 56
-8 -9 5 55 60 56
7 -9 5 55 60 56
8 -9 5 55 60 56
9 -9 5 120 125 123
-10 -8 5 120 125 123
-9 -8 5 55 60 56
-8 -8 5 55 60 56
7 -8 5 55 60 56
8 -8 5 55 60 56
9 -8 5 120 125 123
-10 -7 5 120 125 123
9 -7 5 120 125 123
-10 -6 5 120 125 123
9 -6 5 120 125 123
-10 -5 5 120 125 123
9 -5 5 120 125 123
-10 -4 5 120 125 123
9 -4 5 120 125 123
-10 -3 5 120 125 123
9 -3 5 120 125 123
-10 -2 5 120 125 123
9 -2 5 120 125 123
-10 -1 5 120 125 123
9 -1 5 120 125 123
-10 0 5 120 125 123
9 0 5 120 125 123
-10 1 5 120 125 123
9 1 5 120 125 123
-10 2 5 120 125 123
-9 2 5 67 52 27
-8 2 5 67 52 27
-7 2 5 67 52 27
-6 2 5 67 52 27
-5 2 5 67 52 27
9 2 5 120 125 123
-10 3 5 120 125 123
-9 3 5 67 52 27
-5 3 5 67 52 27
9 3 5 120 125 123
-10 4 5 120 125 123
-9 4 5 67 52 27
-5 4 5 67 52 27
9 4 5 120 125 123
-10 5 5 120 125 123
-9 5 5 67 52 27
-5 5 5 67 52 27
9 5 5 120 125 123
-10 6 5 120 125 123
-9 6 5 67 52 27
-8 6 5 67 52 27
-7 6 5 67 52 27
-6 6 5 67 52 27
-5 6 5 67 52 27
9 6 5 120 125 123
-10 7 5 120 125 123
-9 7 5 55 60 56
-8 7 5 55 60 56
7 7 5 55 60 56
8 7 5 55 60 56
9 7 5 120 125 123
-10 8 5 120 125 123
-9 8 5 55 60 56
-8 8 5 55 60 56
7 8 5 55 60 56
8 8 5 55 60 56
9 8 5 120 125 123
-10 9 5 120 125 123
-9 9 5 120 125 123
-8 9 5 120 125 123
-7 9 5 120 125 123
-6 9 5 120 125 123
-5 9 5 120 125 123
-4 9 5 120 125 123
-3 9 5 150 99 46
-2 9 5 125 185 222
-1 9 5 125 185 222
0 9 5 0 137 108
1 9 5 150 99 46
2 9 5 120 125 123
3 9 5 120 125 123
4 9 5 120 125 123
5 9 5 120 125 123
6 9 5 120 125 123
7 9 5 120 125 123
8 9 5 120 125 123
9 9 5 120 125 123
-10 -10 6 120 125 123
-9 -10 6 120 125 123
-8 -10 6 120 125 123
-7 -10 6 120 125 123
-6 -10 6 120 125 123
-5 -10 6 120 125 123
-4 -10 6 120 125 123
-3 -10 6 120 125 123
-2 -10 6 120 125 123
-1 -10 6 120 125 123
0 -10 6 120 125 123
1 -10 6 120 125 123
2 -10 6 120 125 123
3 -10 6 120 125 123
4 -10 6 120 125 123
5 -10 6 120 125 123
6 -10 6 120 125 123
7 -10 6 120 125 123
8 -10 6 120 125 123
9 -10 6 120 125 123
-10 -9 6 120 125 123
-9 -9 6 55 60 56
-8 -9 6 55 60 56
7 -9 6 55 60 56
8 -9 6 55 60 56
9 -9 6 120 125 123
-10 -8 6 120 125 123
-9 -8 6 55 60 56
-8 -8 6 55 60 56
7 -8 6 55 60 56
8 -8 6 55 60 56
9 -8 6 120 125 123
-10 -7 6 120 125 123
9 -7 6 120 125 123
-10 -6 6 120 125 123
9 -6 6 120 125 123
-10 -5 6 120 125 123
9 -5 6 120 125 123
-10 -4 6 120 125 123
9 -4 6 120 125 123
-10 -3 6 120 125 123
9 -3 6 120 125 123
-10 -2 6 120 125 123
9 -2 6 120 125 123
-10 -1 6 120 125 123
9 -1 6 120 125 123
-10 0 6 120 125 123
9 0 6 120 125 123
-10 1 6 120 125 123
9 1 6 120 125 123
-10 2 6 120 125 123
9 2 6 120 125 123
-10 3 6 120 125 123
9 3 6 120 125 123
-10 4 6 120 125 123
9 4 6 120 125 123
-10 5 6 120 125 123
9 5 6 120 125 123
-10 6 6 120 125 123
9 6 6 120 125 123
-10 7 6 120 125 123
-9 7 6 55 60 56
-8 7 6 55 60 56
7 7 6 55 60 56
8 7 6 55 60 56
9 7 6 120 125 123
-10 8 6 120 125 123
-9 8 6 55 60 56
-8 8 6 55 60 56
7 8 6 55 60 56
8 8 6 55 60 56
9 8 6 120 125 123
-10 9 6 120 125 123
-9 9 6 120 125 123
-8 9 6 120 125 123
-7 9 6 120 125 123
-6 9 6 120 125 123
-5 9 6 120 125 123
-4 9 6 120 125 123
-3 9 6 150 99 46
-2 9 6 125 185 222
-1 9 6 125 185 222
0 9 6 125 185 222
1 9 6 150 99 46
2 9 6 120 125 123
3 9 6 120 125 123
4 9 6 120 125 123
5 9 6 120 125 123
6 9 6 120 125 123
7 9 6 120 125 123
8 9 6 120 125 123
9 9 6 120 125 123
-10 -10 7 120 125 123
-9 -10 7 120 125 123
-8 -10 7 120 125 123
-7 -10 7 120 125 123
-6 -10 7 120 125 123
-5 -10 7 120 125 123
-4 -10 7 120 125 123
-3 -10 7 120 125 123
-2 -10 7 120 125 123
-1 -10 7 120 125 123
0 -10 7 120 125 123
1 -10 7 120 125 123
2 -10 7 120 125 123
3 -10 7 120 125 123
4 -10 7 120 125 123
5 -10 7 120 125 123
6 -10 7 120 125 123
7 -10 7 120 125 123
8 -10 7 120 125 123
9 -10 7 120 125 123
-10 -9 7 120 125 123
-9 -9 7 55 60 56
-8 -9 7 55 60 56
7 -9 7 55 60 56
8 -9 7 55 60 56
9 -9 7 120 125 123
-10 -8 7 120 125 123
-9 -8 7 55 60 56
-8 -8 7 55 60 56
7 -8 7 55 60 56
8 -8 7 55 60 56
9 -8 7 120 125 123
-10 -7 7 120 125 123
9 -7 7 120 125 123
-10 -6 7 120 125 123
9 -6 7 120 125 123
-10 -5 7 120 125 123
9 -5 7 120 125 123
-10 -4 7 120 125 123
9 -4 7 120 125 123
-10 -3 7 120 125 123
9 -3 7 120 125 123
-10 -2 7 120 125 123
9 -2 7 120 125 123
-10 -1 7 120 125 123
9 -1 7 120 125 123
-10 0 7 120 125 123
9 0 7 120 125 123
-10 1 7 120 125 123
9 1 7 120 125 123
-10 2 7 120 125 123
9 2 7 120 125 123
-10 3 7 120 125 123
9 3 7 120 125 123
-10 4 7 120 125 123
9 4 7 120 125 123
-10 5 7 120 125 123
9 5 7 120 125 123
-10 6 7 120 125 123
9 6 7 120 125 123
-10 7 7 120 125 123
-9 7 7 55 60 56
-8 7 7 55 60 56
7 7 7 55 60 56
8 7 7 55 60 56
9 7 7 120 125 123
-10 8 7 120 125 123
-9 8 7 55 60 56
-8 8 7 55 60 56
7 8 7 55 60 56
8 8 7 55 60 56
9 8 7 120 125 123
-10 9 7 120 125 123
-9 9 7 120 125 123
-8 9 7 120 125 123
-7 9 7 120 125 123
-6 9 7 120 125 123
-5 9 7 120 125 123
-4 9 7 120 125 123
-3 9 7 150 99 46
-2 9 7 150 99 46
-1 9 7 150 99 46
0 9 7 150 99 46
1 9 7 150 99 46
2 9 7 120 125 123
3 9 7 120 125 123
4 9 7 120 125 123
5 9 7 120 125 123
6 9 7 120 125 123
7 9 7 120 125 123
8 9 7 120 125 123
9 9 7 120 125 123
-10 -10 8 120 125 123
-9 -10 8 120 125 123
-8 -10 8 120 125 123
-7 -10 8 120 125 123
-6 -10 8 120 125 123
-5 -10 8 120 125 123
-4 -10 8 120 125 123
-3 -10 8 120 125 123
-2 -10 8 120 125 123
-1 -10 8 120 125 123
0 -10 8 120 125 123
1 -10 8 120 125 123
2 -10 8 120 125 123
3 -10 8 120 125 123
4 -10 8 120 125 123
5 -10 8 120 125 123
6 -10 8 120 125 123
7 -10 8 120 125 123
8 -10 8 120 125 123
9 -10 8 120 125 123
-10 -9 8 120 125 123
-9 -9 8 55 60 56
-8 -9 8 55 60 56
-7 -9 8 79 79 72
6 -9 8 79 79 72
7 -9 8 55 60 56
8 -9 8 55 60 56
9 -9 8 120 125 123
-10 -8 8 120 125 123
-9 -8 8 55 60 56
-8 -8 8 55 60 56
7 -8 8 55 60 56
8 -8 8 55 60 56
9 -8 8 120 125 123
-10 -7 8 120 125 123
-9 -7 8 79 79 72
8 -7 8 79 79 72
9 -7 8 120 125 123
-10 -6 8 120 125 123
9 -6 8 120 125 123
-10 -5 8 120 125 123
9 -5 8 120 125 123
-10 -4 8 120 125 123
9 -4 8 120 125 123
-10 -3 8 120 125 123
9 -3 8 120 125 123
-10 -2 8 120 125 123
9 -2 8 120 125 123
-10 -1 8 120 125 123
9 -1 8 120 125 123
-10 0 8 120 125 123
9 0 8 120 125 123
-10 1 8 120 125 123
9 1 8 120 125 123
-10 2 8 120 125 123
9 2 8 120 125 123
-10 3 8 120 125 123
9 3 8 120 125 123
-10 4 8 120 125 123
9 4 8 120 125 123
-10 5 8 120 125 123
9 5 8 120 125 123
-10 6 8 120 125 123
-9 6 8 79 79 72
8 6 8 79 79 72
9 6 8 120 125 123
-10 7 8 120 125 123
-9 7 8 55 60 56
-8 7 8 55 60 56
7 7 8 55 60 56
8 7 8 55 60 56
9 7 8 120 125 123
-10 8 8 120 125 123
-9 8 8 55 60 56
-8 8 8 55 60 56
-7 8 8 79 79 72
6 8 8 79 79 72
7 8 8 55 60 56
8 8 8 55 60 56
9 8 8 120 125 123
-10 9 8 120 125 123
-9 9 8 120 125 123
-8 9 8 120 125 123
-7 9 8 120 125 123
-6 9 8 120 125 123
-5 9 8 120 125 123
-4 9 8 120 125 123
-3 9 8 120 125 123
-2 9 8 120 125 123
-1 9 8 120 125 123
0 9 8 120 125 123
1 9 8 120 125 123
2 9 8 120 125 123
3 9 8 120 125 123
4 9 8 120 125 123
5 9 8 120 125 123
6 9 8 120 125 123
7 9 8 120 125 123
8 9 8 120 125 123
9 9 8 120 125 123
-10 -10 9 120 125 123
-9 -10 9 120 125 123
-8 -10 9 120 125 123
-7 -10 9 120 125 123
-6 -10 9 120 125 123
-5 -10 9 120 125 123
-4 -10 9 120 125 123
-3 -10 9 120 125 123
-2 -10 9 120 125 123
-1 -10 9 120 125 123
0 -10 9 120 125 123
1 -10 9 120 125 123
2 -10 9 120 125 123
3 -10 9 120 125 123
4 -10 9 120 125 123
5 -10 9 120 125 123
6 -10 9 120 125 123
7 -10 9 120 125 123
8 -10 9 120 125 123
9 -10 9 120 125 123
-10 -9 9 120 125 123
-9 -9 9 55 60 56
-8 -9 9 55 60 56
-7 -9 9 79 79 72
-6 -9 9 79 79 72
-5 -9 9 79 79 72
4 -9 9 79 79 72
5 -9 9 79 79 72
6 -9 9 79 79 72
7 -9 9 55 60 56
8 -9 9 55 60 56
9 -9 9 120 125 123
-10 -8 9 120 125 123
-9 -8 9 55 60 56
-8 -8 9 55 60 56
7 -8 9 55 60 56
8 -8 9 55 60 56
9 -8 9 120 125 123
-10 -7 9 120 125 123
-9 -7 9 79 79 72
8 -7 9 79 79 72
9 -7 9 120 125 123
-10 -6 9 120 125 123
-9 -6 9 79 79 72
8 -6 9 79 79 72
9 -6 9 120 125 123
-10 -5 9 120 125 123
-9 -5 9 79 79 72
8 -5 9 79 79 72
9 -5 9 120 125 123
-10 -4 9 120 125 123
9 -4 9 120 125 123
-10 -3 9 120 125 123
9 -3 9 120 125 123
-10 -2 9 120 125 123
9 -2 9 120 125 123
-10 -1 9 120 125 123
9 -1 9 120 125 123
-10 0 9 120 125 123
9 0 9 120 125 123
-10 1 9 120 125 123
9 1 9 120 125 123
-10 2 9 120 125 123
9 2 9 120 125 123
-10 3 9 120 125 123
9 3 9 120 125 123
-10 4 9 120 125 123
-9 4 9 79 79 72
8 4 9 79 79 72
9 4 9 120 125 123
-10 5 9 120 125 123
-9 5 9 79 79 72
8 5 9 79 79 72
9 5 9 120 125 123
-10 6 9 120 125 123
-9 6 9 79 79 72
8 6 9 79 79 72
9 6 9 120 125 123
-10 7 9 120 125 123
-9 7 9 55 60 56
-8 7 9 55 60 56
7 7 9 55 60 56
8 7 9 55 60 56
9 7 9 120 125 123
-10 8 9 120 125 123
-9 8 9 55 60 56
-8 8 9 55 60 56
-7 8 9 79 79 72
-6 8 9 79 79 72
-5 8 9 79 79 72
4 8 9 79 79 72
5 8 9 79 79 72
6 8 9 79 79 72
7 8 9 55 60 56
8 8 9 55 60 56
9 8 9 120 125 123
-10 9 9 120 125 123
-9 9 9 120 125 123
-8 9 9 120 125 123
-7 9 9 120 125 123
-6 9 9 120 125 123
-5 9 9 120 125 123
-4 9 9 120 125 123
-3 9 9 120 125 123
-2 9 9 120 125 123
-1 9 9 120 125 123
0 9 9 120 125 123
1 9 9 120 125 123
2 9 9 120 125 123
3 9 9 120 125 123
4 9 9 120 125 123
5 9 9 120 125 123
6 9 9 120 125 123
7 9 9 120 125 123
8 9 9 120 125 123
9 9 9 120 125 123
-10 -10 10 120 125 123
-9 -10 10 120 125 123
-8 -10 10 120 125 123
-7 -10 10 120 125 123
-6 -10 10 120 125 123
-5 -10 10 120 125 123
-4 -10 10 120 125 123
-3 -10 10 120 125 123
-2 -10 10 120 125 123
-1 -10 10 120 125 123
0 -10 10 120 125 123
1 -10 10 120 125 123
2 -10 10 120 125 123
3 -10 10 120 125 123
4 -10 10 120 125 123
5 -10 10 120 125 123
6 -10 10 120 125 123
7 -10 10 120 125 123
8 -10 10 120 125 123
9 -10 10 120 125 123
-10 -9 10 120 125 123
-9 -9 10 55 60 56
-8 -9 10 55 60 56
-7 -9 10 79 79 72
-6 -9 10 79 79 72
-5 -9 10 79 79 72
-4 -9 10 79 79 72
-3 -9 10 79 79 72
-2 -9 10 79 79 72
-1 -9 10 79 79 72
0 -9 10 79 79 72
1 -9 10 79 79 72
2 -9 10 79 79 72
3 -9 10 79 79 72
4 -9 10 79 79 72
5 -9 10 79 79 72
6 -9 10 79 79 72
7 -9 10 55 60 56
8 -9 10 55 60 56
9 -9 10 120 125 123
-10 -8 10 120 125 123
-9 -8 10 55 60 56
-8 -8 10 55 60 56
7 -8 10 55 60 56
8 -8 10 55 60 56
9 -8 10 120 125 123
-10 -7 10 120 125 123
-9 -7 10 79 79 72
8 -7 10 79 79 72
9 -7 10 120 125 123
-10 -6 10 120 125 123
-9 -6 10 79 79 72
8 -6 10 79 79 72
9 -6 10 120 125 123
-10 -5 10 120 125 123
-9 -5 10 79 79 72
8 -5 10 79 79 72
9 -5 10 120 125 123
-10 -4 10 120 125 123
-9 -4 10 79 79 72
8 -4 10 79 79 72
9 -4 10 120 125 123
-10 -3 10 120 125 123
-9 -3 10 79 79 72
8 -3 10 79 79 72
9 -3 10 120 125 123
-10 -2 10 120 125 123
-9 -2 10 79 79 72
8 -2 10 79 79 72
9 -2 10 120 125 123
-10 -1 10 120 125 123
-9 -1 10 79 79 72
8 -1 10 79 79 72
9 -1 10 120 125 123
-10 0 10 120 125 123
-9 0 10 79 79 72
8 0 10 79 79 72
9 0 10 120 125 123
-10 1 10 120 125 123
-9 1 10 79 79 72
8 1 10 79 79 72
9 1 10 120 125 123
-10 2 10 120 125 123
-9 2 10 79 79 72
8 2 10 79 79 72
9 2 10 120 125 123
-10 3 10 120 125 123
-9 3 10 79 79 72
8 3 10 79 79 72
9 3 10 120 125 123
-10 4 10 120 125 123
-9 4 10 79 79 72
8 4 10 79 79 72
9 4 10 120 125 123
-10 5 10 120 125 123
-9 5 10 79 79 72
8 5 10 79 79 72
9 5 10 120 125 123
-10 6 10 120 125 123
-9 6 10 79 79 72
8 6 10 79 79 72
9 6 10 120 125 123
-10 7 10 120 125 123
-9 7 10 55 60 56
-8 7 10 55 60 56
7 7 10 55 60 56
8 7 10 55 60 56
9 7 10 120 125 123
-10 8 10 120 125 123
-9 8 10 55 60 56
-8 8 10 55 60 56
-7 8 10 79 79 72
-6 8 10 79 79 72
-5 8 10 79 79 72
-4 8 10 79 79 72
-3 8 10 79 79 72
-2 8 10 79 79 72
-1 8 10 79 79 72
0 8 10 79 79 72
1 8 10 79 79 72
2 8 10 79 79 72
3 8 10 79 79 72
4 8 10 79 79 72
5 8 10 79 79 72
6 8 10 79 79 72
7 8 10 55 60 56
8 8 10 55 60 56
9 8 10 120 125 123
-10 9 10 120 125 123
-9 9 10 120 125 123
-8 9 10 120 125 123
-7 9 10 120 125 123
-6 9 10 120 125 123
-5 9 10 120 125 123
-4 9 10 120 125 123
-3 9 10 120 125 123
-2 9 10 120 125 123
-1 9 10 120 125 123
0 9 10 120 125 123
1 9 10 120 125 123
2 9 10 120 125 123
3 9 10 120 125 123
4 9 10 120 125 123
5 9 10 120 125 123
6 9 10 120 125 123
7 9 10 120 125 123
8 9 10 120 125 123
9 9 10 120 125 123
-10 -10 11 120 125 123
-9 -10 11 120 125 123
-8 -10 11 120 125 123
-7 -10 11 120 125 123
-6 -10 11 120 125 123
-5 -10 11 120 125 123
-4 -10 11 120 125 123
-3 -10 11 120 125 123
-2 -10 11 120 125 123
-1 -10 11 120 125 123
0 -10 11 120 125 123
1 -10 11 120 125 123
2 -10 11 120 125 123
3 -10 11 120 125 123
4 -10 11 120 125 123
5 -10 11 120 125 123
6 -10 11 120 125 123
7 -10 11 120 125 123
8 -10 11 120 125 123
9 -10 11 120 125 123
-10 -9 11 120 125 123
-9 -9 11 55 60 56
-8 -9 11 55 60 56
-6 -9 11 79 79 72
-5 -9 11 79 79 72
-4 -9 11 79 79 72
-3 -9 11 79 79 72
-2 -9 11 79 79 72
-1 -9 11 79 79 72
0 -9 11 79 79 72
1 -9 11 79 79 72
2 -9 11 79 79 72
3 -9 11 79 79 72
4 -9 11 79 79 72
5 -9 11 79 79 72
7 -9 11 55 60 56
8 -9 11 55 60 56
9 -9 11 120 125 123
-10 -8 11 120 125 123
-9 -8 11 55 60 56
-8 -8 11 55 60 56
7 -8 11 55 60 56
8 -8 11 55 60 56
9 -8 11 120 125 123
-10 -7 11 120 125 123
9 -7 11 120 125 123
-10 -6 11 120 125 123
-9 -6 11 79 79 72
8 -6 11 79 79 72
9 -6 11 120 125 123
-10 -5 11 120 125 123
-9 -5 11 79 79 72
8 -5 11 79 79 72
9 -5 11 120 125 123
-10 -4 11 120 125 123
-9 -4 11 79 79 72
8 -4 11 79 79 72
9 -4 11 120 125 123
-10 -3 11 120 125 123
-9 -3 11 79 79 72
8 -3 11 79 79 72
9 -3 11 120 125 123
-10 -2 11 120 125 123
-9 -2 11 79 79 72
8 -2 11 79 79 72
9 -2 11 120 125 123
-10 -1 11 120 125 123
-9 -1 11 79 79 72
8 -1 11 79 79 72
9 -1 11 120 125 123
-10 0 11 120 125 123
-9 0 11 79 79 72
8 0 11 79 79 72
9 0 11 120 125 123
-10 1 11 120 125 123
-9 1 11 79 79 72
8 1 11 79 79 72
9 1 11 120 125 123
-10 2 11 120 125 123
-9 2 11 79 79 72
8 2 11 79 79 72
9 2 11 120 125 123
-10 3 11 120 125 123
-9 3 11 79 79 72
8 3 11 79 79 72
9 3 11 120 125 123
-10 4 11 120 125 123
-9 4 11 79 79 72
8 4 11 79 79 72
9 4 11 120 125 123
-10 5 11 120 125 123
-9 5 11 79 79 72
8 5 11 79 79 72
9 5 11 120 125 123
-10 6 11 120 125 123
9 6 11 120 125 123
-10 7 11 120 125 123
-9 7 11 55 60 56
-8 7 11 55 60 56
7 7 11 55 60 56
8 7 11 55 60 56
9 7 11 120 125 123
-10 8 11 120 125 123
-9 8 11 55 60 56
-8 8 11 55 60 56
-6 8 11 79 79 72
-5 8 11 79 79 72
-4 8 11 79 79 72
-3 8 11 79 79 72
-2 8 11 79 79 72
-1 8 11 79 79 72
0 8 11 79 79 72
1 8 11 79 79 72
2 8 11 79 79 72
3 8 11 79 79 72
4 8 11 79 79 72
5 8 11 79 79 72
7 8 11 55 60 56
8 8 11 55 60 56
9 8 11 120 125 123
-10 9 11 120 125 123
-9 9 11 120 125 123
-8 9 11 120 125 123
-7 9 11 120 125 123
-6 9 11 120 125 123
-5 9 11 120 125 123
-4 9 11 120 125 123
-3 9 11 120 125 123
-2 9 11 120 125 123
-1 9 11 120 125 123
0 9 11 120 125 123
1 9 11 120 125 123
2 9 11 120 125 123
3 9 11 120 125 123
4 9 11 120 125 123
5 9 11 120 125 123
6 9 11 120 125 123
7 9 11 120 125 123
8 9 11 120 125 123
9 9 11 120 125 123
-10 -10 12 120 125 123
-9 -10 12 120 125 123
-8 -10 12 120 125 123
-7 -10 12 120 125 123
-6 -10 12 120 125 123
-5 -10 12 120 125 123
-4 -10 12 120 125 123
-3 -10 12 120 125 123
-2 -10 12 120 125 123
-1 -10 12 120 125 123
0 -10 12 120 125 123
1 -10 12 120 125 123
2 -10 12 120 125 123
3 -10 12 120 125 123
4 -10 12 120 125 123
5 -10 12 120 125 123
6 -10 12 120 125 123
7 -10 12 120 125 123
8 -10 12 120 125 123
9 -10 12 120 125 123
-10 -9 12 120 125 123
-9 -9 12 55 60 56
-8 -9 12 55 60 56
7 -9 12 55 60 56
8 -9 12 55 60 56
9 -9 12 120 125 123
-10 -8 12 120 125 123
-9 -8 12 55 60 56
-8 -8 12 55 60 56
7 -8 12 55 60 56
8 -8 12 55 60 56
9 -8 12 120 125 123
-10 -7 12 120 125 123
9 -7 12 120 125 123
-10 -6 12 120 125 123
9 -6 12 120 125 123
-10 -5 12 120 125 123
9 -5 12 120 125 123
-10 -4 12 120 125 123
9 -4 12 120 125 123
-10 -3 12 120 125 123
9 -3 12 120 125 123
-10 -2 12 120 125 123
9 -2 12 120 125 123
-10 -1 12 120 125 123
9 -1 12 120 125 123
-10 0 12 120 125 123
9 0 12 120 125 123
-10 1 12 120 125 123
9 1 12 120 125 123
-10 2 12 120 125 123
9 2 12 120 125 123
-10 3 12 120 125 123
9 3 12 120 125 123
-10 4 12 120 125 123
9 4 12 120 125 123
-10 5 12 120 125 123
9 5 12 120 125 123
-10 6 12 120 125 123
9 6 12 120 125 123
-10 7 12 120 125 123
-9 7 12 55 60 56
-8 7 12 55 60 56
7 7 12 55 60 56
8 7 12 55 60 56
9 7 12 120 125 123
-10 8 12 120 125 123
-9 8 12 55 60 56
-8 8 12 55 60 56
0 8 12 85 85 85
7 8 12 55 60 56
8 8 12 55 60 56
9 8 12 120 125 123
-10 9 12 120 125 123
-9 9 12 120 125 123
-8 9 12 120 125 123
-7 9 12 120 125 123
-6 9 12 120 125 123
-5 9 12 120 125 123
-4 9 12 120 125 123
-3 9 12 120 125 123
-2 9 12 120 125 123
-1 9 12 120 125 123
0 9 12 120 125 123
1 9 12 120 125 123
2 9 12 120 125 123
3 9 12 120 125 123
4 9 12 120 125 123
5 9 12 120 125 123
6 9 12 120 125 123
7 9 12 120 125 123
8 9 12 120 125 123
9 9 12 120 125 123
-10 -10 13 120 125 123
-9 -10 13 120 125 123
-8 -10 13 120 125 123
-7 -10 13 120 125 123
-6 -10 13 120 125 123
-5 -10 13 120 125 123
-4 -10 13 120 125 123
-3 -10 13 120 125 123
-2 -10 13 120 125 123
-1 -10 13 120 125 123
0 -10 13 120 125 123
1 -10 13 120 125 123
2 -10 13 120 125 123
3 -10 13 120 125 123
4 -10 13 120 125 123
5 -10 13 120 125 123
6 -10 13 120 125 123
7 -10 13 120 125 123
8 -10 13 120 125 123
9 -10 13 120 125 123
-10 -9 13 120 125 123
-9 -9 13 55 60 56
-8 -9 13 55 60 56
-6 -9 13 85 85 85
-5 -9 13 85 85 85
-4 -9 13 85 85 85
-1 -9 13 85 85 85
0 -9 13 85 85 85
1 -9 13 85 85 85
4 -9 13 85 85 85
5 -9 13 85 85 85
7 -9 13 55 60 56
8 -9 13 55 60 56
9 -9 13 120 125 123
-10 -8 13 120 125 123
-9 -8 13 55 60 56
-8 -8 13 55 60 56
7 -8 13 55 60 56
8 -8 13 55 60 56
9 -8 13 120 125 123
-10 -7 13 120 125 123
9 -7 13 120 125 123
-10 -6 13 120 125 123
9 -6 13 120 125 123
-10 -5 13 120 125 123
9 -5 13 120 125 123
-10 -4 13 120 125 123
9 -4 13 120 125 123
-10 -3 13 120 125 123
9 -3 13 120 125 123
-10 -2 13 120 125 123
9 -2 13 120 125 123
-10 -1 13 120 125 123
-9 -1 13 85 85 85
9 -1 13 120 125 123
-10 0 13 120 125 123
-9 0 13 85 85 85
9 0 13 120 125 123
-10 1 13 120 125 123
-9 1 13 85 85 85
9 1 13 120 125 123
-10 2 13 120 125 123
-9 2 13 85 85 85
9 2 13 120 125 123
-10 3 13 120 125 123
9 3 13 120 125 123
-10 4 13 120 125 123
9 4 13 120 125 123
-10 5 13 120 125 123
9 5 13 120 125 123
-10 6 13 120 125 123
9 6 13 120 125 123
-10 7 13 120 125 123
-9 7 13 55 60 56
-8 7 13 55 60 56
7 7 13 55 60 56
8 7 13 55 60 56
9 7 13 120 125 123
-10 8 13 120 125 123
-9 8 13 55 60 56
-8 8 13 55 60 56
-1 8 13 85 85 85
0 8 13 85 85 85
7 8 13 55 60 56
8 8 13 55 60 56
9 8 13 120 125 123
-10 9 13 120 125 123
-9 9 13 120 125 123
-8 9 13 120 125 123
-7 9 13 120 125 123
-6 9 13 120 125 123
-5 9 13 120 125 123
-4 9 13 120 125 123
-3 9 13 120 125 123
-2 9 13 120 125 123
-1 9 13 120 125 123
0 9 13 120 125 123
1 9 13 120 125 123
2 9 13 120 125 123
3 9 13 120 125 123
4 9 13 120 125 123
5 9 13 120 125 123
6 9 13 120 125 123
7 9 13 120 125 123
8 9 13 120 125 123
9 9 13 120 125 123
-10 -10 14 120 125 123
-9 -10 14 120 125 123
-8 -10 14 120 125 123
-7 -10 14 120 125 123
-6 -10 14 120 125 123
-5 -10 14 120 125 123
-4 -10 14 120 125 123
-3 -10 14 120 125 123
-2 -10 14 120 125 123
-1 -10 14 120 125 123
0 -10 14 120 125 123
1 -10 14 120 125 123
2 -10 14 120 125 123
3 -10 14 120 125 123
4 -10 14 120 125 123
5 -10 14 120 125 123
6 -10 14 120 125 123
7 -10 14 120 125 123
8 -10 14 120 125 123
9 -10 14 120 125 123
-10 -9 14 120 125 123
-9 -9 14 55 60 56
-8 -9 14 55 60 56
-6 -9 14 85 85 85
-5 -9 14 85 85 85
-4 -9 14 85 85 85
-3 -9 14 85 85 85
-1 -9 14 85 85 85
5 -9 14 85 85 85
7 -9 14 55 60 56
8 -9 14 55 60 56
9 -9 14 120 125 123
-10 -8 14 120 125 123
-9 -8 14 55 60 56
-8 -8 14 55 60 56
7 -8 14 55 60 56
8 -8 14 55 60 56
9 -8 14 120 125 123
-10 -7 14 120 125 123
9 -7 14 120 125 123
-10 -6 14 120 125 123
-9 -6 14 85 85 85
9 -6 14 120 125 123
-10 -5 14 120 125 123
-9 -5 14 85 85 85
9 -5 14 120 125 123
-10 -4 14 120 125 123
-9 -4 14 85 85 85
9 -4 14 120 125 123
-10 -3 14 120 125 123
-9 -3 14 85 85 85
9 -3 14 120 125 123
-10 -2 14 120 125 123
9 -2 14 120 125 123
-10 -1 14 120 125 123
-9 -1 14 85 85 85
9 -1 14 120 125 123
-10 0 14 120 125 123
9 0 14 120 125 123
-10 1 14 120 125 123
9 1 14 120 125 123
-10 2 14 120 125 123
9 2 14 120 125 123
-10 3 14 120 125 123
9 3 14 120 125 123
-10 4 14 120 125 123
8 4 14 208 16 76
9 4 14 120 125 123
-10 5 14 120 125 123
9 5 14 120 125 123
-10 6 14 120 125 123
9 6 14 120 125 123
-10 7 14 120 125 123
-9 7 14 55 60 56
-8 7 14 55 60 56
7 7 14 55 60 56
8 7 14 55 60 56
9 7 14 120 125 123
-10 8 14 120 125 123
-9 8 14 55 60 56
-8 8 14 55 60 56
-6 8 14 85 85 85
-5 8 14 85 85 85
-4 8 14 85 85 85
-3 8 14 85 85 85
1 8 14 85 85 85
2 8 14 85 85 85
3 8 14 85 85 85
7 8 14 55 60 56
8 8 14 55 60 56
9 8 14 120 125 123
-10 9 14 120 125 123
-9 9 14 120 125 123
-8 9 14 120 125 123
-7 9 14 120 125 123
-6 9 14 120 125 123
-5 9 14 120 125 123
-4 9 14 120 125 123
-3 9 14 120 125 123
-2 9 14 120 125 123
-1 9 14 120 125 123
0 9 14 120 125 123
1 9 14 120 125 123
2 9 14 120 125 123
3 9 14 120 125 123
4 9 14 120 125 123
5 9 14 120 125 123
6 9 14 120 125 123
7 9 14 120 125 123
8 9 14 120 125 123
9 9 14 120 125 123
-10 -10 15 120 125 123
-9 -10 15 120 125 123
-8 -10 15 120 125 123
-7 -10 15 120 125 123
-6 -10 15 120 125 123
-5 -10 15 120 125 123
-4 -10 15 120 125 123
-3 -10 15 120 125 123
-2 -10 15 120 125 123
-1 -10 15 120 125 123
0 -10 15 120 125 123
1 -10 15 120 125 123
2 -10 15 120 125 123
3 -10 15 120 125 123
4 -10 15 120 125 123
5 -10 15 120 125 123
6 -10 15 120 125 123
7 -10 15 120 125 123
8 -10 15 120 125 123
9 -10 15 120 125 123
-10 -9 15 120 125 123
-9 -9 15 55 60 56
-8 -9 15 55 60 56
-4 -9 15 85 85 85
1 -9 15 85 85 85
2 -9 15 85 85 85
3 -9 15 85 85 85
5 -9 15 85 85 85
7 -9 15 55 60 56
8 -9 15 55 60 56
9 -9 15 120 125 123
-10 -8 15 120 125 123
-9 -8 15 55 60 56
-8 -8 15 55 60 56
7 -8 15 55 60 56
8 -8 15 55 60 56
9 -8 15 120 125 123
-10 -7 15 120 125 123
9 -7 15 120 125 123
-10 -6 15 120 125 123
8 -6 15 208 16 76
9 -6 15 120 125 123
-10 -5 15 120 125 123
-9 -5 15 85 85 85
9 -5 15 120 125 123
-10 -4 15 120 125 123
-9 -4 15 85 85 85
9 -4 15 120 125 123
-10 -3 15 120 125 123
-9 -3 15 85 85 85
9 -3 15 120 125 123
-10 -2 15 120 125 123
9 -2 15 120 125 123
-10 -1 15 120 125 123
9 -1 15 120 125 123
-10 0 15 120 125 123
9 0 15 120 125 123
-10 1 15 120 125 123
-9 1 15 85 85 85
9 1 15 120 125 123
-10 2 15 120 125 123
9 2 15 120 125 123
-10 3 15 120 125 123
9 3 15 120 125 123
-10 4 15 120 125 123
8 4 15 208 16 76
9 4 15 120 125 123
-10 5 15 120 125 123
9 5 15 120 125 123
-10 6 15 120 125 123
8 6 15 208 16 76
9 6 15 120 125 123
-10 7 15 120 125 123
-9 7 15 55 60 56
-8 7 15 55 60 56
7 7 15 55 60 56
8 7 15 55 60 56
9 7 15 120 125 123
-10 8 15 120 125 123
-9 8 15 55 60 56
-8 8 15 55 60 56
-4 8 15 85 85 85
-3 8 15 85 85 85
-2 8 15 85 85 85
1 8 15 85 85 85
2 8 15 85 85 85
3 8 15 85 85 85
4 8 15 85 85 85
7 8 15 55 60 56
8 8 15 55 60 56
9 8 15 120 125 123
-10 9 15 120 125 123
-9 9 15 120 125 123
-8 9 15 120 125 123
-7 9 15 120 125 123
-6 9 15 120 125 123
-5 9 15 120 125 123
-4 9 15 120 125 123
-3 9 15 120 125 123
-2 9 15 120 125 123
-1 9 15 120 125 123
0 9 15 120 125 123
1 9 15 120 125 123
2 9 15 120 125 123
3 9 15 120 125 123
4 9 15 120 125 123
5 9 15 120 125 123
6 9 15 120 125 123
7 9 15 120 125 123
8 9 15 120 125 123
9 9 15 120 125 123
-10 -10 16 120 125 123
-9 -10 16 120 125 123
-8 -10 16 120 125 123
-7 -10 16 120 125 123
-6 -10 16 120 125 123
-5 -10 16 120 125 123
-4 -10 16 120 125 123
-3 -10 16 120 125 123
-2 -10 16 120 125 123
-1 -10 16 120 125 123
0 -10 16 120 125 123
1 -10 16 120 125 123
2 -10 16 120 125 123
3 -10 16 120 125 123
4 -10 16 120 125 123
5 -10 16 120 125 123
6 -10 16 120 125 123
7 -10 16 120 125 123
8 -10 16 120 125 123
9 -10 16 120 125 123
-10 -9 16 120 125 123
-9 -9 16 55 60 56
-8 -9 16 55 60 56
-6 -9 16 85 85 85
-2 -9 16 85 85 85
-1 -9 16 85 85 85
0 -9 16 85 85 85
1 -9 16 85 85 85
2 -9 16 85 85 85
7 -9 16 55 60 56
8 -9 16 55 60 56
9 -9 16 120 125 123
-10 -8 16 120 125 123
-9 -8 16 55 60 56
-8 -8 16 55 60 56
7 -8 16 55 60 56
8 -8 16 55 60 56
9 -8 16 120 125 123
-10 -7 16 120 125 123
8 -7 16 208 16 76
9 -7 16 120 125 123
-10 -6 16 120 125 123
8 -6 16 208 16 76
9 -6 16 120 125 123
-10 -5 16 120 125 123
9 -5 16 120 125 123
-10 -4 16 120 125 123
8 -4 16 208 16 76
9 -4 16 120 125 123
-10 -3 16 120 125 123
9 -3 16 120 125 123
-10 -2 16 120 125 123
9 -2 16 120 125 123
-10 -1 16 120 125 123
9 -1 16 120 125 123
-10 0 16 120 125 123
9 0 16 120 125 123
-10 1 16 120 125 123
-9 1 16 85 85 85
9 1 16 120 125 123
-10 2 16 120 125 123
-9 2 16 85 85 85
8 2 16 208 16 76
9 2 16 120 125 123
-10 3 16 120 125 123
-9 3 16 85 85 85
9 3 16 120 125 123
-10 4 16 120 125 123
8 4 16 208 16 76
9 4 16 120 125 123
-10 5 16 120 125 123
8 5 16 159 53 58
9 5 16 120 125 123
-10 6 16 120 125 123
8 6 16 208 16 76
9 6 16 120 125 123
-10 7 16 120 125 123
-9 7 16 55 60 56
-8 7 16 55 60 56
7 7 16 55 60 56
8 7 16 55 60 56
9 7 16 120 125 123
-10 8 16 120 125 123
-9 8 16 55 60 56
-8 8 16 55 60 56
-5 8 16 85 85 85
-4 8 16 85 85 85
-3 8 16 85 85 85
7 8 16 55 60 56
8 8 16 55 60 56
9 8 16 120 125 123
-10 9 16 120 125 123
-9 9 16 120 125 123
-8 9 16 120 125 123
-7 9 16 120 125 123
-6 9 16 120 125 123
-5 9 16 120 125 123
-4 9 16 120 125 123
-3 9 16 120 125 123
-2 9 16 120 125 123
-1 9 16 120 125 123
0 9 16 120 125 123
1 9 16 120 125 123
2 9 16 120 125 123
3 9 16 120 125 123
4 9 16 120 125 123
5 9 16 120 125 123
6 9 16 120 125 123
7 9 16 120 125 123
8 9 16 120 125 123
9 9 16 120 125 123
-10 -10 17 120 125 123
-9 -10 17 120 125 123
-8 -10 17 120 125 123
-7 -10 17 120 125 123
-6 -10 17 120 125 123
-5 -10 17 120 125 123
-4 -10 17 120 125 123
-3 -10 17 120 125 123
-2 -10 17 120 125 123
-1 -10 17 120 125 123
0 -10 17 120 125 123
1 -10 17 120 125 123
2 -10 17 120 125 123
3 -10 17 120 125 123
4 -10 17 120 125 123
5 -10 17 120 125 123
6 -10 17 120 125 123
7 -10 17 120 125 123
8 -10 17 120 125 123
9 -10 17 120 125 123
-10 -9 17 120 125 123
-9 -9 17 55 60 56
-8 -9 17 55 60 56
-6 -9 17 85 85 85
-2 -9 17 85 85 85
-1 -9 17 85 85 85
0 -9 17 85 85 85
7 -9 17 55 60 56
8 -9 17 55 60 56
9 -9 17 120 125 123
-10 -8 17 120 125 123
-9 -8 17 55 60 56
-8 -8 17 55 60 56
7 -8 17 55 60 56
8 -8 17 55 60 56
9 -8 17 120 125 123
-10 -7 17 120 125 123
8 -7 17 159 53 58
9 -7 17 120 125 123
-10 -6 17 120 125 123
8 -6 17 159 53 58
9 -6 17 120 125 123
-10 -5 17 120 125 123
9 -5 17 120 125 123
-10 -4 17 120 125 123
-9 -4 17 85 85 85
8 -4 17 208 16 76
9 -4 17 120 125 123
-10 -3 17 120 125 123
-9 -3 17 85 85 85
8 -3 17 208 16 76
9 -3 17 120 125 123
-10 -2 17 120 125 123
-9 -2 17 85 85 85
9 -2 17 120 125 123
-10 -1 17 120 125 123
-9 -1 17 85 85 85
9 -1 17 120 125 123
-10 0 17 120 125 123
9 0 17 120 125 123
-10 1 17 120 125 123
8 1 17 159 53 58
9 1 17 120 125 123
-10 2 17 120 125 123
-9 2 17 85 85 85
8 2 17 208 16 76
9 2 17 120 125 123
-10 3 17 120 125 123
-9 3 17 85 85 85
9 3 17 120 125 123
-10 4 17 120 125 123
8 4 17 208 16 76
9 4 17 120 125 123
-10 5 17 120 125 123
8 5 17 159 53 58
9 5 17 120 125 123
-10 6 17 120 125 123
8 6 17 208 16 76
9 6 17 120 125 123
-10 7 17 120 125 123
-9 7 17 55 60 56
-8 7 17 55 60 56
7 7 17 55 60 56
8 7 17 55 60 56
9 7 17 120 125 123
-10 8 17 120 125 123
-9 8 17 55 60 56
-8 8 17 55 60 56
-5 8 17 85 85 85
0 8 17 85 85 85
1 8 17 85 85 85
3 8 17 85 85 85
4 8 17 85 85 85
5 8 17 85 85 85
7 8 17 55 60 56
8 8 17 55 60 56
9 8 17 120 125 123
-10 9 17 120 125 123
-9 9 17 120 125 123
-8 9 17 120 125 123
-7 9 17 120 125 123
-6 9 17 120 125 123
-5 9 17 120 125 123
-4 9 17 120 125 123
-3 9 17 120 125 123
-2 9 17 120 125 123
-1 9 17 120 125 123
0 9 17 120 125 123
1 9 17 120 125 123
2 9 17 120 125 123
3 9 17 120 125 123
4 9 17 120 125 123
5 9 17 120 125 123
6 9 17 120 125 123
7 9 17 120 125 123
8 9 17 120 125 123
9 9 17 120 125 123
-10 -10 18 120 125 123
-9 -10 18 120 125 123
-8 -10 18 120 125 123
-7 -10 18 120 125 123
-6 -10 18 120 125 123
-5 -10 18 120 125 123
-4 -10 18 120 125 123
-3 -10 18 120 125 123
-2 -10 18 120 125 123
-1 -10 18 120 125 123
0 -10 18 120 125 123
1 -10 18 120 125 123
2 -10 18 120 125 123
3 -10 18 120 125 123
4 -10 18 120 125 123
5 -10 18 120 125 123
6 -10 18 120 125 123
7 -10 18 120 125 123
8 -10 18 120 125 123
9 -10 18 120 125 123
-10 -9 18 120 125 123
-9 -9 18 55 60 56
-8 -9 18 55 60 56
-6 -9 18 85 85 85
-5 -9 18 85 85 85
-4 -9 18 85 85 85
4 -9 18 85 85 85
5 -9 18 85 85 85
7 -9 18 55 60 56
8 -9 18 55 60 56
9 -9 18 120 125 123
-10 -8 18 120 125 123
-9 -8 18 55 60 56
-8 -8 18 55 60 56
7 -8 18 55 60 56
8 -8 18 55 60 56
9 -8 18 120 125 123
-10 -7 18 120 125 123
8 -7 18 159 53 58
9 -7 18 120 125 123
-10 -6 18 120 125 123
8 -6 18 159 53 58
9 -6 18 120 125 123
-10 -5 18 120 125 123
-9 -5 18 85 85 85
8 -5 18 208 16 76
9 -5 18 120 125 123
-10 -4 18 120 125 123
-9 -4 18 85 85 85
8 -4 18 208 16 76
9 -4 18 120 125 123
-10 -3 18 120 125 123
-9 -3 18 85 85 85
8 -3 18 159 53 58
9 -3 18 120 125 123
-10 -2 18 120 125 123
-9 -2 18 85 85 85
8 -2 18 208 16 76
9 -2 18 120 125 123
-10 -1 18 120 125 123
8 -1 18 208 16 76
9 -1 18 120 125 123
-10 0 18 120 125 123
9 0 18 120 125 123
-10 1 18 120 125 123
8 1 18 208 16 76
9 1 18 120 125 123
-10 2 18 120 125 123
8 2 18 159 53 58
9 2 18 120 125 123
-10 3 18 120 125 123
8 3 18 208 16 76
9 3 18 120 125 123
-10 4 18 120 125 123
8 4 18 208 16 76
9 4 18 120 125 123
-10 5 18 120 125 123
8 5 18 159 53 58
9 5 18 120 125 123
-10 6 18 120 125 123
8 6 18 208 16 76
9 6 18 120 125 123
-10 7 18 120 125 123
-9 7 18 55 60 56
-8 7 18 55 60 56
7 7 18 55 60 56
8 7 18 55 60 56
9 7 18 120 125 123
-10 8 18 120 125 123
-9 8 18 55 60 56
-8 8 18 55 60 56
-1 8 18 85 85 85
0 8 18 85 85 85
1 8 18 85 85 85
3 8 18 85 85 85
4 8 18 85 85 85
5 8 18 85 85 85
7 8 18 55 60 56
8 8 18 55 60 56
9 8 18 120 125 123
-10 9 18 120 125 123
-9 9 18 120 125 123
-8 9 18 120 125 123
-7 9 18 120 125 123
-6 9 18 120 125 123
-5 9 18 120 125 123
-4 9 18 120 125 123
-3 9 18 120 125 123
-2 9 18 120 125 123
-1 9 18 120 125 123
0 9 18 120 125 123
1 9 18 120 125 123
2 9 18 120 125 123
3 9 18 120 125 123
4 9 18 120 125 123
5 9 18 120 125 123
6 9 18 120 125 123
7 9 18 120 125 123
8 9 18 120 125 123
9 9 18 120 125 123
-10 -10 19 120 125 123
-9 -10 19 120 125 123
-8 -10 19 120 125 123
-7 -10 19 120 125 123
-6 -10 19 120 125 123
-5 -10 19 120 125 123
-4 -10 19 120 125 123
-3 -10 19 120 125 123
-2 -10 19 120 125 123
-1 -10 19 120 125 123
0 -10 19 120 125 123
1 -10 19 120 125 123
2 -10 19 120 125 123
3 -10 19 120 125 123
4 -10 19 120 125 123
5 -10 19 120 125 123
6 -10 19 120 125 123
7 -10 19 120 125 123
8 -10 19 120 125 123
9 -10 19 120 125 123
-10 -9 19 120 125 123
-9 -9 19 55 60 56
-8 -9 19 55 60 56
7 -9 19 55 60 56
8 -9 19 55 60 56
9 -9 19 120 125 123
-10 -8 19 120 125 123
-9 -8 19 55 60 56
-8 -8 19 55 60 56
7 -8 19 55 60 56
8 -8 19 55 60 56
9 -8 19 120 125 123
-10 -7 19 120 125 123
8 -7 19 159 53 58
9 -7 19 120 125 123
-10 -6 19 120 125 123
8 -6 19 159 53 58
9 -6 19 120 125 123
-10 -5 19 120 125 123
8 -5 19 159 53 58
9 -5 19 120 125 123
-10 -4 19 120 125 123
8 -4 19 159 53 58
9 -4 19 120 125 123
-10 -3 19 120 125 123
8 -3 19 159 53 58
9 -3 19 120 125 123
-10 -2 19 120 125 123
8 -2 19 159 53 58
9 -2 19 120 125 123
-10 -1 19 120 125 123
8 -1 19 159 53 58
9 -1 19 120 125 123
-10 0 19 120 125 123
8 0 19 159 53 58
9 0 19 120 125 123
-10 1 19 120 125 123
8 1 19 159 53 58
9 1 19 120 125 123
-10 2 19 120 125 123
8 2 19 159 53 58
9 2 19 120 125 123
-10 3 19 120 125 123
8 3 19 159 53 58
9 3 19 120 125 123
-10 4 19 120 125 123
8 4 19 159 53 58
9 4 19 120 125 123
-10 5 19 120 125 123
8 5 19 159 53 58
9 5 19 120 125 123
-10 6 19 120 125 123
8 6 19 159 53 58
9 6 19 120 125 123
-10 7 19 120 125 123
-9 7 19 55 60 56
-8 7 19 55 60 56
7 7 19 55 60 56
8 7 19 55 60 56
9 7 19 120 125 123
-10 8 19 120 125 123
-9 8 19 55 60 56
-8 8 19 55 60 56
7 8 19 55 60 56
8 8 19 55 60 56
9 8 19 120 125 123
-10 9 19 120 125 123
-9 9 19 120 125 123
-8 9 19 120 125 123
-7 9 19 120 125 123
-6 9 19 120 125 123
-5 9 19 120 125 123
-4 9 19 120 125 123
-3 9 19 120 125 123
-2 9 19 120 125 123
-1 9 19 120 125 123
0 9 19 120 125 123
1 9 19 120 125 123
2 9 19 120 125 123
3 9 19 120 125 123
4 9 19 120 125 123
5 9 19 120 125 123
6 9 19 120 125 123
7 9 19 120 125 123
8 9 19 120 125 123
9 9 19 120 125 123
