ply
format ascii 1.0
comment : MagicaVoxel @ Ephtracy
element vertex 3878
property float x
property float y
property float z
property uchar red
property uchar green
property uchar blue
end_header
-12 -12 0 27 129 62
-11 -12 0 27 129 62
-10 -12 0 27 129 62
-9 -12 0 27 129 62
-8 -12 0 27 129 62
-7 -12 0 27 129 62
-6 -12 0 27 129 62
-5 -12 0 27 129 62
-4 -12 0 27 129 62
-3 -12 0 27 129 62
-2 -12 0 27 129 62
-1 -12 0 27 129 62
0 -12 0 27 129 62
1 -12 0 27 129 62
2 -12 0 27 129 62
3 -12 0 27 129 62
4 -12 0 27 129 62
5 -12 0 27 129 62
6 -12 0 27 129 62
7 -12 0 27 129 62
8 -12 0 27 129 62
9 -12 0 27 129 62
10 -12 0 27 129 62
11 -12 0 27 129 62
12 -12 0 27 129 62
-12 -11 0 27 129 62
-11 -11 0 27 129 62
-10 -11 0 27 129 62
-9 -11 0 27 129 62
-8 -11 0 27 129 62
-7 -11 0 27 129 62
-6 -11 0 27 129 62
-5 -11 0 27 129 62
-4 -11 0 27 129 62
-3 -11 0 27 129 62
-2 -11 0 27 129 62
-1 -11 0 27 129 62
0 -11 0 27 129 62
1 -11 0 27 129 62
2 -11 0 27 129 62
3 -11 0 27 129 62
4 -11 0 27 129 62
5 -11 0 27 129 62
6 -11 0 27 129 62
7 -11 0 27 129 62
8 -11 0 27 129 62
9 -11 0 27 129 62
10 -11 0 27 129 62
11 -11 0 27 129 62
12 -11 0 27 129 62
-12 -10 0 27 129 62
-11 -10 0 27 129 62
-10 -10 0 27 129 62
-9 -10 0 27 129 62
-8 -10 0 27 129 62
-7 -10 0 27 129 62
-6 -10 0 27 129 62
-5 -10 0 27 129 62
-4 -10 0 27 129 62
-3 -10 0 27 129 62
-2 -10 0 27 129 62
-1 -10 0 27 129 62
0 -10 0 27 129 62
1 -10 0 27 129 62
2 -10 0 27 129 62
3 -10 0 27 129 62
4 -10 0 27 129 62
5 -10 0 27 129 62
6 -10 0 27 129 62
7 -10 0 27 129 62
8 -10 0 27 129 62
9 -10 0 27 129 62
10 -10 0 27 129 62
11 -10 0 27 129 62
12 -10 0 27 129 62
-12 -9 0 27 129 62
-11 -9 0 27 129 62
-10 -9 0 27 129 62
-9 -9 0 27 129 62
-8 -9 0 27 129 62
-7 -9 0 27 129 62
-6 -9 0 27 129 62
-5 -9 0 27 129 62
-4 -9 0 27 129 62
-3 -9 0 27 129 62
-2 -9 0 27 129 62
-1 -9 0 27 129 62
0 -9 0 27 129 62
1 -9 0 27 129 62
2 -9 0 27 129 62
3 -9 0 27 129 62
4 -9 0 27 129 62
5 -9 0 27 129 62
6 -9 0 27 129 62
7 -9 0 27 129 62
8 -9 0 27 129 62
9 -9 0 27 129 62
10 -9 0 27 129 62
11 -9 0 27 129 62
12 -9 0 27 129 62
-12 -8 0 27 129 62
-11 -8 0 27 129 62
-10 -8 0 27 129 62
-9 -8 0 27 129 62
-8 -8 0 27 129 62
-7 -8 0 27 129 62
-6 -8 0 27 129 62
-5 -8 0 27 129 62
-4 -8 0 27 129 62
-3 -8 0 27 129 62
-2 -8 0 27 129 62
-1 -8 0 27 129 62
0 -8 0 27 129 62
1 -8 0 27 129 62
2 -8 0 27 129 62
3 -8 0 27 129 62
4 -8 0 27 129 62
5 -8 0 27 129 62
6 -8 0 27 129 62
7 -8 0 27 129 62
8 -8 0 27 129 62
9 -8 0 27 129 62
10 -8 0 27 129 62
11 -8 0 27 129 62
12 -8 0 27 129 62
-12 -7 0 27 129 62
-11 -7 0 27 129 62
-10 -7 0 27 129 62
-9 -7 0 27 129 62
-8 -7 0 27 129 62
-7 -7 0 27 129 62
-6 -7 0 27 129 62
-5 -7 0 27 129 62
-4 -7 0 27 129 62
-3 -7 0 27 129 62
-2 -7 0 27 129 62
-1 -7 0 27 129 62
0 -7 0 27 129 62
1 -7 0 27 129 62
2 -7 0 27 129 62
3 -7 0 27 129 62
4 -7 0 27 129 62
5 -7 0 27 129 62
6 -7 0 27 129 62
7 -7 0 27 129 62
8 -7 0 27 129 62
9 -7 0 27 129 62
10 -7 0 27 129 62
11 -7 0 27 129 62
12 -7 0 27 129 62
-12 -6 0 27 129 62
-11 -6 0 27 129 62
-10 -6 0 27 129 62
-9 -6 0 27 129 62
-8 -6 0 27 129 62
-7 -6 0 27 129 62
-6 -6 0 27 129 62
-5 -6 0 27 129 62
-4 -6 0 27 129 62
-3 -6 0 27 129 62
-2 -6 0 27 129 62
-1 -6 0 27 129 62
0 -6 0 27 129 62
1 -6 0 27 129 62
2 -6 0 27 129 62
3 -6 0 27 129 62
4 -6 0 27 129 62
5 -6 0 27 129 62
6 -6 0 27 129 62
7 -6 0 27 129 62
8 -6 0 27 129 62
9 -6 0 27 129 62
10 -6 0 27 129 62
11 -6 0 27 129 62
12 -6 0 27 129 62
-12 -5 0 27 129 62
-11 -5 0 27 129 62
-10 -5 0 27 129 62
-9 -5 0 27 129 62
-8 -5 0 27 129 62
-7 -5 0 27 129 62
-6 -5 0 27 129 62
-5 -5 0 27 129 62
-4 -5 0 27 129 62
-3 -5 0 27 129 62
-2 -5 0 27 129 62
-1 -5 0 27 129 62
0 -5 0 27 129 62
1 -5 0 27 129 62
2 -5 0 27 129 62
3 -5 0 27 129 62
4 -5 0 27 129 62
5 -5 0 27 129 62
6 -5 0 27 129 62
7 -5 0 27 129 62
8 -5 0 27 129 62
9 -5 0 27 129 62
10 -5 0 27 129 62
11 -5 0 27 129 62
12 -5 0 27 129 62
-12 -4 0 27 129 62
-11 -4 0 27 129 62
-10 -4 0 27 129 62
-9 -4 0 27 129 62
-8 -4 0 27 129 62
-7 -4 0 27 129 62
-6 -4 0 27 129 62
-5 -4 0 27 129 62
-4 -4 0 27 129 62
-3 -4 0 27 129 62
-2 -4 0 27 129 62
-1 -4 0 27 129 62
0 -4 0 27 129 62
1 -4 0 27 129 62
2 -4 0 27 129 62
3 -4 0 27 129 62
4 -4 0 27 129 62
5 -4 0 27 129 62
6 -4 0 27 129 62
7 -4 0 27 129 62
8 -4 0 27 129 62
9 -4 0 27 129 62
10 -4 0 27 129 62
11 -4 0 27 129 62
12 -4 0 27 129 62
-12 -3 0 27 129 62
-11 -3 0 27 129 62
-10 -3 0 27 129 62
-9 -3 0 27 129 62
-8 -3 0 27 129 62
-7 -3 0 27 129 62
-6 -3 0 27 129 62
-5 -3 0 27 129 62
-4 -3 0 27 129 62
-3 -3 0 27 129 62
-2 -3 0 27 129 62
-1 -3 0 27 129 62
0 -3 0 27 129 62
1 -3 0 27 129 62
2 -3 0 27 129 62
3 -3 0 27 129 62
4 -3 0 27 129 62
5 -3 0 27 129 62
6 -3 0 27 129 62
7 -3 0 27 129 62
8 -3 0 27 129 62
9 -3 0 27 129 62
10 -3 0 27 129 62
11 -3 0 27 129 62
12 -3 0 27 129 62
-12 -2 0 27 129 62
-11 -2 0 27 129 62
-10 -2 0 27 129 62
-9 -2 0 27 129 62
-8 -2 0 27 129 62
-7 -2 0 27 129 62
-6 -2 0 27 129 62
-5 -2 0 27 129 62
-4 -2 0 27 129 62
-3 -2 0 27 129 62
-2 -2 0 27 129 62
-1 -2 0 27 129 62
0 -2 0 27 129 62
1 -2 0 27 129 62
2 -2 0 27 129 62
3 -2 0 27 129 62
4 -2 0 27 129 62
5 -2 0 27 129 62
6 -2 0 27 129 62
7 -2 0 27 129 62
8 -2 0 27 129 62
9 -2 0 27 129 62
10 -2 0 27 129 62
11 -2 0 27 129 62
12 -2 0 27 129 62
-12 -1 0 27 129 62
-11 -1 0 27 129 62
-10 -1 0 27 129 62
-9 -1 0 27 129 62
-8 -1 0 27 129 62
-7 -1 0 27 129 62
-6 -1 0 27 129 62
-5 -1 0 27 129 62
-4 -1 0 27 129 62
-3 -1 0 27 129 62
-2 -1 0 27 129 62
-1 -1 0 27 129 62
0 -1 0 27 129 62
1 -1 0 27 129 62
2 -1 0 27 129 62
3 -1 0 27 129 62
4 -1 0 27 129 62
5 -1 0 27 129 62
6 -1 0 27 129 62
7 -1 0 27 129 62
8 -1 0 27 129 62
9 -1 0 27 129 62
10 -1 0 27 129 62
11 -1 0 27 129 62
12 -1 0 27 129 62
-12 0 0 27 129 62
-11 0 0 27 129 62
-10 0 0 27 129 62
-9 0 0 27 129 62
-8 0 0 27 129 62
-7 0 0 27 129 62
-6 0 0 27 129 62
-5 0 0 27 129 62
-4 0 0 27 129 62
-3 0 0 27 129 62
-2 0 0 27 129 62
-1 0 0 27 129 62
0 0 0 27 129 62
1 0 0 27 129 62
2 0 0 27 129 62
3 0 0 27 129 62
4 0 0 27 129 62
5 0 0 27 129 62
6 0 0 27 129 62
7 0 0 27 129 62
8 0 0 27 129 62
9 0 0 27 129 62
10 0 0 27 129 62
11 0 0 27 129 62
12 0 0 27 129 62
-12 1 0 27 129 62
-11 1 0 27 129 62
-10 1 0 27 129 62
-9 1 0 27 129 62
-8 1 0 27 129 62
-7 1 0 27 129 62
-6 1 0 27 129 62
-5 1 0 27 129 62
-4 1 0 27 129 62
-3 1 0 27 129 62
-2 1 0 27 129 62
-1 1 0 27 129 62
0 1 0 27 129 62
1 1 0 27 129 62
2 1 0 27 129 62
3 1 0 27 129 62
4 1 0 27 129 62
5 1 0 27 129 62
6 1 0 27 129 62
7 1 0 27 129 62
8 1 0 27 129 62
9 1 0 27 129 62
10 1 0 27 129 62
11 1 0 27 129 62
12 1 0 27 129 62
-12 2 0 27 129 62
-11 2 0 27 129 62
-10 2 0 27 129 62
-9 2 0 27 129 62
-8 2 0 27 129 62
-7 2 0 27 129 62
-6 2 0 27 129 62
-5 2 0 27 129 62
-4 2 0 27 129 62
-3 2 0 27 129 62
-2 2 0 27 129 62
-1 2 0 27 129 62
0 2 0 27 129 62
1 2 0 27 129 62
2 2 0 27 129 62
3 2 0 27 129 62
4 2 0 27 129 62
5 2 0 27 129 62
6 2 0 27 129 62
7 2 0 27 129 62
8 2 0 27 129 62
9 2 0 27 129 62
10 2 0 27 129 62
11 2 0 27 129 62
12 2 0 27 129 62
-12 3 0 27 129 62
-11 3 0 27 129 62
-10 3 0 27 129 62
-9 3 0 27 129 62
-8 3 0 27 129 62
-7 3 0 27 129 62
-6 3 0 27 129 62
-5 3 0 27 129 62
-4 3 0 27 129 62
-3 3 0 27 129 62
-2 3 0 27 129 62
-1 3 0 27 129 62
0 3 0 27 129 62
1 3 0 27 129 62
2 3 0 27 129 62
3 3 0 27 129 62
4 3 0 27 129 62
5 3 0 27 129 62
6 3 0 27 129 62
7 3 0 27 129 62
8 3 0 27 129 62
9 3 0 27 129 62
10 3 0 27 129 62
11 3 0 27 129 62
12 3 0 27 129 62
-12 4 0 27 129 62
-11 4 0 27 129 62
-10 4 0 27 129 62
-9 4 0 27 129 62
-8 4 0 27 129 62
-7 4 0 27 129 62
-6 4 0 27 129 62
-5 4 0 27 129 62
-4 4 0 27 129 62
-3 4 0 27 129 62
-2 4 0 27 129 62
-1 4 0 27 129 62
0 4 0 27 129 62
1 4 0 27 129 62
2 4 0 27 129 62
3 4 0 27 129 62
4 4 0 27 129 62
5 4 0 27 129 62
6 4 0 27 129 62
7 4 0 27 129 62
8 4 0 27 129 62
9 4 0 27 129 62
10 4 0 27 129 62
11 4 0 27 129 62
12 4 0 27 129 62
-12 5 0 27 129 62
-11 5 0 27 129 62
-10 5 0 27 129 62
-9 5 0 27 129 62
-8 5 0 27 129 62
-7 5 0 27 129 62
-6 5 0 27 129 62
-5 5 0 27 129 62
-4 5 0 27 129 62
-3 5 0 27 129 62
-2 5 0 27 129 62
-1 5 0 27 129 62
0 5 0 27 129 62
1 5 0 27 129 62
2 5 0 27 129 62
3 5 0 27 129 62
4 5 0 27 129 62
5 5 0 27 129 62
6 5 0 27 129 62
7 5 0 27 129 62
8 5 0 27 129 62
9 5 0 27 129 62
10 5 0 27 129 62
11 5 0 27 129 62
12 5 0 27 129 62
-12 6 0 27 129 62
-11 6 0 27 129 62
-10 6 0 27 129 62
-9 6 0 27 129 62
-8 6 0 27 129 62
-7 6 0 27 129 62
-6 6 0 27 129 62
-5 6 0 27 129 62
-4 6 0 27 129 62
-3 6 0 27 129 62
-2 6 0 27 129 62
-1 6 0 27 129 62
0 6 0 27 129 62
1 6 0 27 129 62
2 6 0 27 129 62
3 6 0 27 129 62
4 6 0 27 129 62
5 6 0 27 129 62
6 6 0 27 129 62
7 6 0 27 129 62
8 6 0 27 129 62
9 6 0 27 129 62
10 6 0 27 129 62
11 6 0 27 129 62
12 6 0 27 129 62
-12 7 0 27 129 62
-11 7 0 27 129 62
-10 7 0 27 129 62
-9 7 0 27 129 62
-8 7 0 27 129 62
-7 7 0 27 129 62
-6 7 0 27 129 62
-5 7 0 27 129 62
-4 7 0 27 129 62
-3 7 0 27 129 62
-2 7 0 27 129 62
-1 7 0 27 129 62
0 7 0 27 129 62
1 7 0 27 129 62
2 7 0 27 129 62
3 7 0 27 129 62
4 7 0 27 129 62
5 7 0 27 129 62
6 7 0 27 129 62
7 7 0 27 129 62
8 7 0 27 129 62
9 7 0 27 129 62
10 7 0 27 129 62
11 7 0 27 129 62
12 7 0 27 129 62
-12 8 0 27 129 62
-11 8 0 27 129 62
-10 8 0 27 129 62
-9 8 0 27 129 62
-8 8 0 27 129 62
-7 8 0 27 129 62
-6 8 0 27 129 62
-5 8 0 27 129 62
-4 8 0 27 129 62
-3 8 0 27 129 62
-2 8 0 27 129 62
-1 8 0 27 129 62
0 8 0 27 129 62
1 8 0 27 129 62
2 8 0 27 129 62
3 8 0 27 129 62
4 8 0 27 129 62
5 8 0 27 129 62
6 8 0 27 129 62
7 8 0 27 129 62
8 8 0 27 129 62
9 8 0 27 129 62
10 8 0 27 129 62
11 8 0 27 129 62
12 8 0 27 129 62
-12 9 0 27 129 62
-11 9 0 27 129 62
-10 9 0 27 129 62
-9 9 0 27 129 62
-8 9 0 27 129 62
-7 9 0 27 129 62
-6 9 0 27 129 62
-5 9 0 27 129 62
-4 9 0 27 129 62
-3 9 0 27 129 62
-2 9 0 27 129 62
-1 9 0 27 129 62
0 9 0 27 129 62
1 9 0 27 129 62
2 9 0 27 129 62
3 9 0 27 129 62
4 9 0 27 129 62
5 9 0 27 129 62
6 9 0 27 129 62
7 9 0 27 129 62
8 9 0 27 129 62
9 9 0 27 129 62
10 9 0 27 129 62
11 9 0 27 129 62
12 9 0 27 129 62
-12 10 0 27 129 62
-11 10 0 27 129 62
-10 10 0 27 129 62
-9 10 0 27 129 62
-8 10 0 27 129 62
-7 10 0 27 129 62
-6 10 0 27 129 62
-5 10 0 27 129 62
-4 10 0 27 129 62
-3 10 0 27 129 62
-2 10 0 27 129 62
-1 10 0 27 129 62
0 10 0 27 129 62
1 10 0 27 129 62
2 10 0 27 129 62
3 10 0 27 129 62
4 10 0 27 129 62
5 10 0 27 129 62
6 10 0 27 129 62
7 10 0 27 129 62
8 10 0 27 129 62
9 10 0 27 129 62
10 10 0 27 129 62
11 10 0 27 129 62
12 10 0 27 129 62
-12 11 0 27 129 62
-11 11 0 27 129 62
-10 11 0 27 129 62
-9 11 0 27 129 62
-8 11 0 27 129 62
-7 11 0 27 129 62
-6 11 0 27 129 62
-5 11 0 27 129 62
-4 11 0 27 129 62
-3 11 0 27 129 62
-2 11 0 27 129 62
-1 11 0 27 129 62
0 11 0 27 129 62
1 11 0 27 129 62
2 11 0 27 129 62
3 11 0 27 129 62
4 11 0 27 129 62
5 11 0 27 129 62
6 11 0 27 129 62
7 11 0 27 129 62
8 11 0 27 129 62
9 11 0 27 129 62
10 11 0 27 129 62
11 11 0 27 129 62
12 11 0 27 129 62
-12 12 0 27 129 62
-11 12 0 27 129 62
-10 12 0 27 129 62
-9 12 0 27 129 62
-8 12 0 27 129 62
-7 12 0 27 129 62
-6 12 0 27 129 62
-5 12 0 27 129 62
-4 12 0 27 129 62
-3 12 0 27 129 62
-2 12 0 27 129 62
-1 12 0 27 129 62
0 12 0 27 129 62
1 12 0 27 129 62
2 12 0 27 129 62
3 12 0 27 129 62
4 12 0 27 129 62
5 12 0 27 129 62
6 12 0 27 129 62
7 12 0 27 129 62
8 12 0 27 129 62
9 12 0 27 129 62
10 12 0 27 129 62
11 12 0 27 129 62
12 12 0 27 129 62
-12 -12 1 27 129 62
-11 -12 1 27 129 62
-10 -12 1 27 129 62
-9 -12 1 27 129 62
-8 -12 1 27 129 62
-7 -12 1 27 129 62
-6 -12 1 27 129 62
-5 -12 1 27 129 62
-4 -12 1 27 129 62
-3 -12 1 27 129 62
-2 -12 1 27 129 62
-1 -12 1 27 129 62
0 -12 1 27 129 62
1 -12 1 27 129 62
2 -12 1 27 129 62
3 -12 1 27 129 62
4 -12 1 27 129 62
5 -12 1 27 129 62
6 -12 1 27 129 62
7 -12 1 27 129 62
8 -12 1 27 129 62
9 -12 1 27 129 62
10 -12 1 27 129 62
11 -12 1 27 129 62
12 -12 1 27 129 62
-12 -11 1 27 129 62
-11 -11 1 27 129 62
-10 -11 1 27 129 62
-9 -11 1 27 129 62
-8 -11 1 27 129 62
-7 -11 1 27 129 62
-6 -11 1 27 129 62
-5 -11 1 27 129 62
-4 -11 1 27 129 62
-3 -11 1 27 129 62
-2 -11 1 27 129 62
-1 -11 1 27 129 62
0 -11 1 27 129 62
1 -11 1 27 129 62
2 -11 1 27 129 62
3 -11 1 27 129 62
4 -11 1 27 129 62
5 -11 1 27 129 62
6 -11 1 27 129 62
7 -11 1 27 129 62
8 -11 1 27 129 62
9 -11 1 27 129 62
10 -11 1 27 129 62
11 -11 1 27 129 62
12 -11 1 27 129 62
-12 -10 1 27 129 62
-11 -10 1 27 129 62
-10 -10 1 27 129 62
-9 -10 1 27 129 62
-8 -10 1 27 129 62
-7 -10 1 27 129 62
-6 -10 1 27 129 62
-5 -10 1 27 129 62
-4 -10 1 27 129 62
-3 -10 1 27 129 62
-2 -10 1 27 129 62
-1 -10 1 27 129 62
0 -10 1 27 129 62
1 -10 1 27 129 62
2 -10 1 27 129 62
3 -10 1 27 129 62
4 -10 1 27 129 62
5 -10 1 27 129 62
6 -10 1 27 129 62
7 -10 1 27 129 62
8 -10 1 27 129 62
9 -10 1 27 129 62
10 -10 1 27 129 62
11 -10 1 27 129 62
12 -10 1 27 129 62
-12 -9 1 27 129 62
-11 -9 1 27 129 62
-10 -9 1 27 129 62
-9 -9 1 27 129 62
-8 -9 1 27 129 62
-7 -9 1 27 129 62
-6 -9 1 27 129 62
-5 -9 1 27 129 62
-4 -9 1 27 129 62
-3 -9 1 27 129 62
-2 -9 1 27 129 62
-1 -9 1 27 129 62
0 -9 1 27 129 62
1 -9 1 27 129 62
2 -9 1 27 129 62
3 -9 1 27 129 62
4 -9 1 27 129 62
5 -9 1 27 129 62
6 -9 1 27 129 62
7 -9 1 27 129 62
8 -9 1 27 129 62
9 -9 1 27 129 62
10 -9 1 27 129 62
11 -9 1 27 129 62
12 -9 1 27 129 62
-12 -8 1 27 129 62
-11 -8 1 27 129 62
-10 -8 1 27 129 62
-9 -8 1 27 129 62
-8 -8 1 27 129 62
-7 -8 1 27 129 62
-6 -8 1 27 129 62
-5 -8 1 27 129 62
-4 -8 1 27 129 62
-3 -8 1 27 129 62
-2 -8 1 27 129 62
-1 -8 1 27 129 62
0 -8 1 27 129 62
1 -8 1 27 129 62
2 -8 1 27 129 62
3 -8 1 27 129 62
4 -8 1 27 129 62
5 -8 1 27 129 62
6 -8 1 27 129 62
7 -8 1 27 129 62
8 -8 1 27 129 62
9 -8 1 27 129 62
10 -8 1 27 129 62
11 -8 1 27 129 62
12 -8 1 27 129 62
-12 -7 1 27 129 62
-11 -7 1 27 129 62
-10 -7 1 27 129 62
-9 -7 1 27 129 62
-8 -7 1 27 129 62
-7 -7 1 27 129 62
-6 -7 1 27 129 62
-5 -7 1 27 129 62
-4 -7 1 27 129 62
-3 -7 1 27 129 62
-2 -7 1 27 129 62
-1 -7 1 27 129 62
0 -7 1 27 129 62
1 -7 1 27 129 62
2 -7 1 27 129 62
3 -7 1 27 129 62
4 -7 1 27 129 62
5 -7 1 27 129 62
6 -7 1 27 129 62
7 -7 1 27 129 62
8 -7 1 27 129 62
9 -7 1 27 129 62
10 -7 1 27 129 62
11 -7 1 27 129 62
12 -7 1 27 129 62
-12 -6 1 27 129 62
-11 -6 1 27 129 62
-10 -6 1 27 129 62
-9 -6 1 27 129 62
-8 -6 1 27 129 62
-7 -6 1 27 129 62
-6 -6 1 27 129 62
-5 -6 1 27 129 62
-4 -6 1 27 129 62
-3 -6 1 27 129 62
-2 -6 1 27 129 62
-1 -6 1 27 129 62
0 -6 1 27 129 62
1 -6 1 27 129 62
2 -6 1 27 129 62
3 -6 1 27 129 62
4 -6 1 27 129 62
5 -6 1 27 129 62
6 -6 1 27 129 62
7 -6 1 27 129 62
8 -6 1 27 129 62
9 -6 1 27 129 62
10 -6 1 27 129 62
11 -6 1 27 129 62
12 -6 1 27 129 62
-12 -5 1 27 129 62
-11 -5 1 27 129 62
-10 -5 1 27 129 62
-9 -5 1 27 129 62
-8 -5 1 27 129 62
-7 -5 1 27 129 62
-6 -5 1 27 129 62
-5 -5 1 27 129 62
-4 -5 1 27 129 62
-3 -5 1 27 129 62
-2 -5 1 27 129 62
-1 -5 1 27 129 62
0 -5 1 27 129 62
1 -5 1 27 129 62
2 -5 1 27 129 62
3 -5 1 27 129 62
4 -5 1 27 129 62
5 -5 1 27 129 62
6 -5 1 27 129 62
7 -5 1 27 129 62
8 -5 1 27 129 62
9 -5 1 27 129 62
10 -5 1 27 129 62
11 -5 1 27 129 62
12 -5 1 27 129 62
-12 -4 1 27 129 62
-11 -4 1 27 129 62
-10 -4 1 27 129 62
-9 -4 1 27 129 62
-8 -4 1 27 129 62
-7 -4 1 27 129 62
-6 -4 1 27 129 62
-5 -4 1 27 129 62
-4 -4 1 27 129 62
-3 -4 1 27 129 62
-2 -4 1 27 129 62
-1 -4 1 27 129 62
0 -4 1 27 129 62
1 -4 1 27 129 62
2 -4 1 27 129 62
3 -4 1 27 129 62
4 -4 1 27 129 62
5 -4 1 27 129 62
6 -4 1 27 129 62
7 -4 1 27 129 62
8 -4 1 27 129 62
9 -4 1 27 129 62
10 -4 1 27 129 62
11 -4 1 27 129 62
12 -4 1 27 129 62
-12 -3 1 27 129 62
-11 -3 1 27 129 62
-10 -3 1 27 129 62
-9 -3 1 27 129 62
-8 -3 1 27 129 62
-7 -3 1 27 129 62
-6 -3 1 27 129 62
-5 -3 1 27 129 62
-4 -3 1 27 129 62
-3 -3 1 27 129 62
-2 -3 1 27 129 62
-1 -3 1 27 129 62
0 -3 1 27 129 62
1 -3 1 27 129 62
2 -3 1 27 129 62
3 -3 1 27 129 62
4 -3 1 27 129 62
5 -3 1 27 129 62
6 -3 1 27 129 62
7 -3 1 27 129 62
8 -3 1 27 129 62
9 -3 1 27 129 62
10 -3 1 27 129 62
11 -3 1 27 129 62
12 -3 1 27 129 62
-12 -2 1 27 129 62
-11 -2 1 27 129 62
-10 -2 1 27 129 62
-9 -2 1 27 129 62
-8 -2 1 27 129 62
-7 -2 1 27 129 62
-6 -2 1 27 129 62
-5 -2 1 27 129 62
-4 -2 1 27 129 62
-3 -2 1 27 129 62
-2 -2 1 27 129 62
-1 -2 1 27 129 62
0 -2 1 27 129 62
1 -2 1 27 129 62
2 -2 1 27 129 62
3 -2 1 27 129 62
4 -2 1 27 129 62
5 -2 1 27 129 62
6 -2 1 27 129 62
7 -2 1 27 129 62
8 -2 1 27 129 62
9 -2 1 27 129 62
10 -2 1 27 129 62
11 -2 1 27 129 62
12 -2 1 27 129 62
-12 -1 1 27 129 62
-11 -1 1 27 129 62
-10 -1 1 27 129 62
-9 -1 1 27 129 62
-8 -1 1 27 129 62
-7 -1 1 27 129 62
-6 -1 1 27 129 62
-5 -1 1 27 129 62
-4 -1 1 27 129 62
-3 -1 1 27 129 62
-2 -1 1 27 129 62
-1 -1 1 27 129 62
0 -1 1 27 129 62
1 -1 1 27 129 62
2 -1 1 27 129 62
3 -1 1 27 129 62
4 -1 1 27 129 62
5 -1 1 27 129 62
6 -1 1 27 129 62
7 -1 1 27 129 62
8 -1 1 27 129 62
9 -1 1 27 129 62
10 -1 1 27 129 62
11 -1 1 27 129 62
12 -1 1 27 129 62
-12 0 1 27 129 62
-11 0 1 27 129 62
-10 0 1 27 129 62
-9 0 1 27 129 62
-8 0 1 27 129 62
-7 0 1 27 129 62
-6 0 1 27 129 62
-5 0 1 27 129 62
-4 0 1 27 129 62
-3 0 1 27 129 62
-2 0 1 27 129 62
-1 0 1 27 129 62
0 0 1 27 129 62
1 0 1 27 129 62
2 0 1 27 129 62
3 0 1 27 129 62
4 0 1 27 129 62
5 0 1 27 129 62
6 0 1 27 129 62
7 0 1 27 129 62
8 0 1 27 129 62
9 0 1 27 129 62
10 0 1 27 129 62
11 0 1 27 129 62
12 0 1 27 129 62
-12 1 1 27 129 62
-11 1 1 27 129 62
-10 1 1 27 129 62
-9 1 1 27 129 62
-8 1 1 27 129 62
-7 1 1 27 129 62
-6 1 1 27 129 62
-5 1 1 27 129 62
-4 1 1 27 129 62
-3 1 1 27 129 62
-2 1 1 27 129 62
-1 1 1 27 129 62
0 1 1 27 129 62
1 1 1 27 129 62
2 1 1 27 129 62
3 1 1 27 129 62
4 1 1 27 129 62
5 1 1 27 129 62
6 1 1 27 129 62
7 1 1 27 129 62
8 1 1 27 129 62
9 1 1 27 129 62
10 1 1 27 129 62
11 1 1 27 129 62
12 1 1 27 129 62
-12 2 1 27 129 62
-11 2 1 27 129 62
-10 2 1 27 129 62
-9 2 1 27 129 62
-8 2 1 27 129 62
-7 2 1 27 129 62
-6 2 1 27 129 62
-5 2 1 27 129 62
-4 2 1 27 129 62
-3 2 1 27 129 62
-2 2 1 27 129 62
-1 2 1 27 129 62
0 2 1 27 129 62
1 2 1 27 129 62
2 2 1 27 129 62
3 2 1 27 129 62
4 2 1 27 129 62
5 2 1 27 129 62
6 2 1 27 129 62
7 2 1 27 129 62
8 2 1 27 129 62
9 2 1 27 129 62
10 2 1 27 129 62
11 2 1 27 129 62
12 2 1 27 129 62
-12 3 1 27 129 62
-11 3 1 27 129 62
-10 3 1 27 129 62
-9 3 1 27 129 62
-8 3 1 27 129 62
-7 3 1 27 129 62
-6 3 1 27 129 62
-5 3 1 27 129 62
-4 3 1 27 129 62
-3 3 1 27 129 62
-2 3 1 27 129 62
-1 3 1 27 129 62
0 3 1 27 129 62
1 3 1 27 129 62
2 3 1 27 129 62
3 3 1 27 129 62
4 3 1 27 129 62
5 3 1 27 129 62
6 3 1 27 129 62
7 3 1 27 129 62
8 3 1 27 129 62
9 3 1 27 129 62
10 3 1 27 129 62
11 3 1 27 129 62
12 3 1 27 129 62
-12 4 1 27 129 62
-11 4 1 27 129 62
-10 4 1 27 129 62
-9 4 1 27 129 62
-8 4 1 27 129 62
-7 4 1 27 129 62
-6 4 1 27 129 62
-5 4 1 27 129 62
-4 4 1 27 129 62
-3 4 1 27 129 62
-2 4 1 27 129 62
-1 4 1 27 129 62
0 4 1 27 129 62
1 4 1 27 129 62
2 4 1 27 129 62
3 4 1 27 129 62
4 4 1 27 129 62
5 4 1 27 129 62
6 4 1 27 129 62
7 4 1 27 129 62
8 4 1 27 129 62
9 4 1 27 129 62
10 4 1 27 129 62
11 4 1 27 129 62
12 4 1 27 129 62
-12 5 1 27 129 62
-11 5 1 27 129 62
-10 5 1 27 129 62
-9 5 1 27 129 62
-8 5 1 27 129 62
-7 5 1 27 129 62
-6 5 1 27 129 62
-5 5 1 27 129 62
-4 5 1 27 129 62
-3 5 1 27 129 62
-2 5 1 27 129 62
-1 5 1 27 129 62
0 5 1 27 129 62
1 5 1 27 129 62
2 5 1 27 129 62
3 5 1 27 129 62
4 5 1 27 129 62
5 5 1 27 129 62
6 5 1 27 129 62
7 5 1 27 129 62
8 5 1 27 129 62
9 5 1 27 129 62
10 5 1 27 129 62
11 5 1 27 129 62
12 5 1 27 129 62
-12 6 1 27 129 62
-11 6 1 27 129 62
-10 6 1 27 129 62
-9 6 1 27 129 62
-8 6 1 27 129 62
-7 6 1 27 129 62
-6 6 1 27 129 62
-5 6 1 27 129 62
-4 6 1 27 129 62
-3 6 1 27 129 62
-2 6 1 27 129 62
-1 6 1 27 129 62
0 6 1 27 129 62
1 6 1 27 129 62
2 6 1 27 129 62
3 6 1 27 129 62
4 6 1 27 129 62
5 6 1 27 129 62
6 6 1 27 129 62
7 6 1 27 129 62
8 6 1 27 129 62
9 6 1 27 129 62
10 6 1 27 129 62
11 6 1 27 129 62
12 6 1 27 129 62
-12 7 1 27 129 62
-11 7 1 27 129 62
-10 7 1 27 129 62
-9 7 1 27 129 62
-8 7 1 27 129 62
-7 7 1 27 129 62
-6 7 1 27 129 62
-5 7 1 27 129 62
-4 7 1 27 129 62
-3 7 1 27 129 62
-2 7 1 27 129 62
-1 7 1 27 129 62
0 7 1 27 129 62
1 7 1 27 129 62
2 7 1 27 129 62
3 7 1 27 129 62
4 7 1 27 129 62
5 7 1 27 129 62
6 7 1 27 129 62
7 7 1 27 129 62
8 7 1 27 129 62
9 7 1 27 129 62
10 7 1 27 129 62
11 7 1 27 129 62
12 7 1 27 129 62
-12 8 1 27 129 62
-11 8 1 27 129 62
-10 8 1 27 129 62
-9 8 1 27 129 62
-8 8 1 27 129 62
-7 8 1 27 129 62
-6 8 1 27 129 62
-5 8 1 27 129 62
-4 8 1 27 129 62
-3 8 1 27 129 62
-2 8 1 27 129 62
-1 8 1 27 129 62
0 8 1 27 129 62
1 8 1 27 129 62
2 8 1 27 129 62
3 8 1 27 129 62
4 8 1 27 129 62
5 8 1 27 129 62
6 8 1 27 129 62
7 8 1 27 129 62
8 8 1 27 129 62
9 8 1 27 129 62
10 8 1 27 129 62
11 8 1 27 129 62
12 8 1 27 129 62
-12 9 1 27 129 62
-11 9 1 27 129 62
-10 9 1 27 129 62
-9 9 1 27 129 62
-8 9 1 27 129 62
-7 9 1 27 129 62
-6 9 1 27 129 62
-5 9 1 27 129 62
-4 9 1 27 129 62
-3 9 1 27 129 62
-2 9 1 27 129 62
-1 9 1 27 129 62
0 9 1 27 129 62
1 9 1 27 129 62
2 9 1 27 129 62
3 9 1 27 129 62
4 9 1 27 129 62
5 9 1 27 129 62
6 9 1 27 129 62
7 9 1 27 129 62
8 9 1 27 129 62
9 9 1 27 129 62
10 9 1 27 129 62
11 9 1 27 129 62
12 9 1 27 129 62
-12 10 1 27 129 62
-11 10 1 27 129 62
-10 10 1 27 129 62
-9 10 1 27 129 62
-8 10 1 27 129 62
-7 10 1 27 129 62
-6 10 1 27 129 62
-5 10 1 27 129 62
-4 10 1 27 129 62
-3 10 1 27 129 62
-2 10 1 27 129 62
-1 10 1 27 129 62
0 10 1 27 129 62
1 10 1 27 129 62
2 10 1 27 129 62
3 10 1 27 129 62
4 10 1 27 129 62
5 10 1 27 129 62
6 10 1 27 129 62
7 10 1 27 129 62
8 10 1 27 129 62
9 10 1 27 129 62
10 10 1 27 129 62
11 10 1 27 129 62
12 10 1 27 129 62
-12 11 1 27 129 62
-11 11 1 27 129 62
-10 11 1 27 129 62
-9 11 1 27 129 62
-8 11 1 27 129 62
-7 11 1 27 129 62
-6 11 1 27 129 62
-5 11 1 27 129 62
-4 11 1 27 129 62
-3 11 1 27 129 62
-2 11 1 27 129 62
-1 11 1 27 129 62
0 11 1 27 129 62
1 11 1 27 129 62
2 11 1 27 129 62
3 11 1 27 129 62
4 11 1 27 129 62
5 11 1 27 129 62
6 11 1 27 129 62
7 11 1 27 129 62
8 11 1 27 129 62
9 11 1 27 129 62
10 11 1 27 129 62
11 11 1 27 129 62
12 11 1 27 129 62
-12 12 1 27 129 62
-11 12 1 27 129 62
-10 12 1 27 129 62
-9 12 1 27 129 62
-8 12 1 27 129 62
-7 12 1 27 129 62
-6 12 1 27 129 62
-5 12 1 27 129 62
-4 12 1 27 129 62
-3 12 1 27 129 62
-2 12 1 27 129 62
-1 12 1 27 129 62
0 12 1 27 129 62
1 12 1 27 129 62
2 12 1 27 129 62
3 12 1 27 129 62
4 12 1 27 129 62
5 12 1 27 129 62
6 12 1 27 129 62
7 12 1 27 129 62
8 12 1 27 129 62
9 12 1 27 129 62
10 12 1 27 129 62
11 12 1 27 129 62
12 12 1 27 129 62
-7 -9 2 250 214 137
-6 -9 2 250 214 137
-5 -9 2 250 214 137
-4 -9 2 250 214 137
-3 -9 2 250 214 137
5 -9 2 250 214 137
6 -9 2 250 214 137
7 -9 2 250 214 137
8 -9 2 250 214 137
9 -9 2 250 214 137
-7 -8 2 250 214 137
-6 -8 2 250 214 137
-5 -8 2 250 214 137
-4 -8 2 250 214 137
-3 -8 2 250 214 137
5 -8 2 250 214 137
6 -8 2 250 214 137
7 -8 2 250 214 137
8 -8 2 250 214 137
9 -8 2 250 214 137
-7 -7 2 250 214 137
-6 -7 2 250 214 137
-5 -7 2 250 214 137
-4 -7 2 250 214 137
-3 -7 2 250 214 137
5 -7 2 250 214 137
6 -7 2 250 214 137
7 -7 2 250 214 137
8 -7 2 250 214 137
9 -7 2 250 214 137
-6 -6 2 250 214 137
-5 -6 2 250 214 137
-4 -6 2 250 214 137
-3 -6 2 250 214 137
5 -6 2 250 214 137
6 -6 2 250 214 137
7 -6 2 250 214 137
8 -6 2 250 214 137
-5 -5 2 250 214 137
7 -5 2 250 214 137
-6 -4 2 250 214 137
-5 -4 2 250 214 137
7 -4 2 250 214 137
8 -4 2 250 214 137
-7 -3 2 250 214 137
-6 -3 2 250 214 137
-5 -3 2 250 214 137
7 -3 2 250 214 137
8 -3 2 250 214 137
9 -3 2 250 214 137
-7 -2 2 250 214 137
-6 -2 2 250 214 137
-5 -2 2 250 214 137
7 -2 2 250 214 137
8 -2 2 250 214 137
9 -2 2 250 214 137
-7 -1 2 250 214 137
-6 -1 2 250 214 137
-5 -1 2 250 214 137
7 -1 2 250 214 137
8 -1 2 250 214 137
9 -1 2 250 214 137
-7 0 2 250 214 137
-6 0 2 250 214 137
-5 0 2 250 214 137
7 0 2 250 214 137
8 0 2 250 214 137
9 0 2 250 214 137
-7 1 2 250 214 137
-6 1 2 250 214 137
-5 1 2 250 214 137
7 1 2 250 214 137
8 1 2 250 214 137
9 1 2 250 214 137
-7 2 2 250 214 137
-6 2 2 250 214 137
-5 2 2 250 214 137
7 2 2 250 214 137
8 2 2 250 214 137
9 2 2 250 214 137
-7 3 2 250 214 137
-6 3 2 250 214 137
-5 3 2 250 214 137
7 3 2 250 214 137
8 3 2 250 214 137
9 3 2 250 214 137
-6 4 2 250 214 137
-5 4 2 250 214 137
7 4 2 250 214 137
8 4 2 250 214 137
-5 5 2 250 214 137
7 5 2 250 214 137
-6 6 2 250 214 137
-5 6 2 250 214 137
-4 6 2 250 214 137
-3 6 2 250 214 137
5 6 2 250 214 137
6 6 2 250 214 137
7 6 2 250 214 137
8 6 2 250 214 137
-7 7 2 250 214 137
-6 7 2 250 214 137
-5 7 2 250 214 137
-4 7 2 250 214 137
-3 7 2 250 214 137
5 7 2 250 214 137
6 7 2 250 214 137
7 7 2 250 214 137
8 7 2 250 214 137
9 7 2 250 214 137
-7 8 2 250 214 137
-6 8 2 250 214 137
-5 8 2 250 214 137
-4 8 2 250 214 137
-3 8 2 250 214 137
5 8 2 250 214 137
6 8 2 250 214 137
7 8 2 250 214 137
8 8 2 250 214 137
9 8 2 250 214 137
-7 9 2 250 214 137
-6 9 2 250 214 137
-5 9 2 250 214 137
-4 9 2 250 214 137
-3 9 2 250 214 137
5 9 2 250 214 137
6 9 2 250 214 137
7 9 2 250 214 137
8 9 2 250 214 137
9 9 2 250 214 137
-7 -9 3 250 214 137
-6 -9 3 250 214 137
-5 -9 3 250 214 137
-4 -9 3 250 214 137
-3 -9 3 250 214 137
5 -9 3 250 214 137
6 -9 3 250 214 137
7 -9 3 250 214 137
8 -9 3 250 214 137
9 -9 3 250 214 137
-7 -8 3 250 214 137
-6 -8 3 250 214 137
-5 -8 3 250 214 137
-4 -8 3 250 214 137
-3 -8 3 250 214 137
5 -8 3 250 214 137
6 -8 3 250 214 137
7 -8 3 250 214 137
8 -8 3 250 214 137
9 -8 3 250 214 137
-7 -7 3 250 214 137
-6 -7 3 250 214 137
-5 -7 3 250 214 137
-4 -7 3 250 214 137
-3 -7 3 250 214 137
5 -7 3 250 214 137
6 -7 3 250 214 137
7 -7 3 250 214 137
8 -7 3 250 214 137
9 -7 3 250 214 137
-6 -6 3 250 214 137
-5 -6 3 250 214 137
-4 -6 3 250 214 137
-3 -6 3 250 214 137
5 -6 3 250 214 137
6 -6 3 250 214 137
7 -6 3 250 214 137
8 -6 3 250 214 137
-5 -5 3 250 214 137
7 -5 3 250 214 137
-6 -4 3 250 214 137
-5 -4 3 250 214 137
7 -4 3 250 214 137
8 -4 3 250 214 137
-7 -3 3 250 214 137
-6 -3 3 250 214 137
-5 -3 3 250 214 137
7 -3 3 250 214 137
8 -3 3 250 214 137
9 -3 3 250 214 137
-7 -2 3 250 214 137
-6 -2 3 250 214 137
-5 -2 3 250 214 137
7 -2 3 250 214 137
8 -2 3 250 214 137
9 -2 3 250 214 137
-7 -1 3 250 214 137
-6 -1 3 250 214 137
-5 -1 3 250 214 137
7 -1 3 250 214 137
8 -1 3 250 214 137
9 -1 3 250 214 137
-7 0 3 250 214 137
-6 0 3 250 214 137
-5 0 3 250 214 137
7 0 3 250 214 137
8 0 3 250 214 137
9 0 3 250 214 137
-7 1 3 250 214 137
-6 1 3 250 214 137
-5 1 3 250 214 137
7 1 3 250 214 137
8 1 3 250 214 137
9 1 3 250 214 137
-7 2 3 250 214 137
-6 2 3 250 214 137
-5 2 3 250 214 137
7 2 3 250 214 137
8 2 3 250 214 137
9 2 3 250 214 137
-7 3 3 250 214 137
-6 3 3 250 214 137
-5 3 3 250 214 137
7 3 3 250 214 137
8 3 3 250 214 137
9 3 3 250 214 137
-6 4 3 250 214 137
-5 4 3 250 214 137
7 4 3 250 214 137
8 4 3 250 214 137
-5 5 3 250 214 137
7 5 3 250 214 137
-6 6 3 250 214 137
-5 6 3 250 214 137
-4 6 3 250 214 137
-3 6 3 250 214 137
5 6 3 250 214 137
6 6 3 250 214 137
7 6 3 250 214 137
8 6 3 250 214 137
-7 7 3 250 214 137
-6 7 3 250 214 137
-5 7 3 250 214 137
-4 7 3 250 214 137
-3 7 3 250 214 137
5 7 3 250 214 137
6 7 3 250 214 137
7 7 3 250 214 137
8 7 3 250 214 137
9 7 3 250 214 137
-7 8 3 250 214 137
-6 8 3 250 214 137
-5 8 3 250 214 137
-4 8 3 250 214 137
-3 8 3 250 214 137
5 8 3 250 214 137
6 8 3 250 214 137
7 8 3 250 214 137
8 8 3 250 214 137
9 8 3 250 214 137
-7 9 3 250 214 137
-6 9 3 250 214 137
-5 9 3 250 214 137
-4 9 3 250 214 137
-3 9 3 250 214 137
5 9 3 250 214 137
6 9 3 250 214 137
7 9 3 250 214 137
8 9 3 250 214 137
9 9 3 250 214 137
-7 -9 4 250 214 137
-6 -9 4 250 214 137
-5 -9 4 250 214 137
-4 -9 4 250 214 137
-3 -9 4 250 214 137
5 -9 4 250 214 137
6 -9 4 250 214 137
7 -9 4 250 214 137
8 -9 4 250 214 137
9 -9 4 250 214 137
-7 -8 4 250 214 137
-6 -8 4 250 214 137
-5 -8 4 250 214 137
-4 -8 4 250 214 137
-3 -8 4 250 214 137
5 -8 4 250 214 137
6 -8 4 250 214 137
7 -8 4 250 214 137
8 -8 4 250 214 137
9 -8 4 250 214 137
-7 -7 4 250 214 137
-6 -7 4 250 214 137
-5 -7 4 250 214 137
-4 -7 4 250 214 137
-3 -7 4 250 214 137
5 -7 4 250 214 137
6 -7 4 250 214 137
7 -7 4 250 214 137
8 -7 4 250 214 137
9 -7 4 250 214 137
-6 -6 4 250 214 137
-5 -6 4 250 214 137
-4 -6 4 250 214 137
-3 -6 4 250 214 137
5 -6 4 250 214 137
6 -6 4 250 214 137
7 -6 4 250 214 137
8 -6 4 250 214 137
-5 -5 4 250 214 137
7 -5 4 250 214 137
-6 -4 4 250 214 137
-5 -4 4 250 214 137
7 -4 4 250 214 137
8 -4 4 250 214 137
-7 -3 4 250 214 137
-6 -3 4 250 214 137
-5 -3 4 250 214 137
7 -3 4 250 214 137
8 -3 4 250 214 137
9 -3 4 250 214 137
-7 -2 4 250 214 137
-6 -2 4 250 214 137
-5 -2 4 250 214 137
7 -2 4 250 214 137
8 -2 4 250 214 137
9 -2 4 250 214 137
-7 -1 4 250 214 137
-6 -1 4 250 214 137
-5 -1 4 250 214 137
7 -1 4 250 214 137
8 -1 4 250 214 137
9 -1 4 250 214 137
-7 0 4 250 214 137
-6 0 4 250 214 137
-5 0 4 250 214 137
7 0 4 250 214 137
8 0 4 250 214 137
9 0 4 250 214 137
-7 1 4 250 214 137
-6 1 4 250 214 137
-5 1 4 250 214 137
7 1 4 250 214 137
8 1 4 250 214 137
9 1 4 250 214 137
-7 2 4 250 214 137
-6 2 4 250 214 137
-5 2 4 250 214 137
7 2 4 250 214 137
8 2 4 250 214 137
9 2 4 250 214 137
-7 3 4 250 214 137
-6 3 4 250 214 137
-5 3 4 250 214 137
7 3 4 250 214 137
8 3 4 250 214 137
9 3 4 250 214 137
-6 4 4 250 214 137
-5 4 4 250 214 137
7 4 4 250 214 137
8 4 4 250 214 137
-5 5 4 250 214 137
7 5 4 250 214 137
-6 6 4 250 214 137
-5 6 4 250 214 137
-4 6 4 250 214 137
-3 6 4 250 214 137
5 6 4 250 214 137
6 6 4 250 214 137
7 6 4 250 214 137
8 6 4 250 214 137
-7 7 4 250 214 137
-6 7 4 250 214 137
-5 7 4 250 214 137
-4 7 4 250 214 137
-3 7 4 250 214 137
5 7 4 250 214 137
6 7 4 250 214 137
7 7 4 250 214 137
8 7 4 250 214 137
9 7 4 250 214 137
-7 8 4 250 214 137
-6 8 4 250 214 137
-5 8 4 250 214 137
-4 8 4 250 214 137
-3 8 4 250 214 137
5 8 4 250 214 137
6 8 4 250 214 137
7 8 4 250 214 137
8 8 4 250 214 137
9 8 4 250 214 137
-7 9 4 250 214 137
-6 9 4 250 214 137
-5 9 4 250 214 137
-4 9 4 250 214 137
-3 9 4 250 214 137
5 9 4 250 214 137
6 9 4 250 214 137
7 9 4 250 214 137
8 9 4 250 214 137
9 9 4 250 214 137
-7 -9 5 250 214 137
-6 -9 5 250 214 137
-5 -9 5 250 214 137
-4 -9 5 250 214 137
-3 -9 5 250 214 137
5 -9 5 250 214 137
6 -9 5 250 214 137
7 -9 5 250 214 137
8 -9 5 250 214 137
9 -9 5 250 214 137
-7 -8 5 250 214 137
-6 -8 5 250 214 137
-5 -8 5 250 214 137
-4 -8 5 250 214 137
-3 -8 5 250 214 137
5 -8 5 250 214 137
6 -8 5 250 214 137
7 -8 5 250 214 137
8 -8 5 250 214 137
9 -8 5 250 214 137
-7 -7 5 250 214 137
-6 -7 5 250 214 137
-5 -7 5 250 214 137
-4 -7 5 250 214 137
-3 -7 5 250 214 137
5 -7 5 250 214 137
6 -7 5 250 214 137
7 -7 5 250 214 137
8 -7 5 250 214 137
9 -7 5 250 214 137
-6 -6 5 250 214 137
-5 -6 5 250 214 137
-4 -6 5 250 214 137
-3 -6 5 250 214 137
5 -6 5 250 214 137
6 -6 5 250 214 137
7 -6 5 250 214 137
8 -6 5 250 214 137
-5 -5 5 250 214 137
7 -5 5 250 214 137
-6 -4 5 250 214 137
-5 -4 5 250 214 137
7 -4 5 250 214 137
8 -4 5 250 214 137
-7 -3 5 250 214 137
-6 -3 5 250 214 137
-5 -3 5 250 214 137
7 -3 5 250 214 137
8 -3 5 250 214 137
9 -3 5 250 214 137
-7 -2 5 250 214 137
-6 -2 5 250 214 137
-5 -2 5 250 214 137
7 -2 5 250 214 137
8 -2 5 250 214 137
9 -2 5 250 214 137
-7 -1 5 250 214 137
-6 -1 5 250 214 137
-5 -1 5 250 214 137
7 -1 5 250 214 137
8 -1 5 250 214 137
9 -1 5 250 214 137
-7 0 5 250 214 137
-6 0 5 250 214 137
-5 0 5 250 214 137
7 0 5 250 214 137
8 0 5 250 214 137
9 0 5 250 214 137
-7 1 5 250 214 137
-6 1 5 250 214 137
-5 1 5 250 214 137
7 1 5 250 214 137
8 1 5 250 214 137
9 1 5 250 214 137
-7 2 5 250 214 137
-6 2 5 250 214 137
-5 2 5 250 214 137
7 2 5 250 214 137
8 2 5 250 214 137
9 2 5 250 214 137
-7 3 5 250 214 137
-6 3 5 250 214 137
-5 3 5 250 214 137
7 3 5 250 214 137
8 3 5 250 214 137
9 3 5 250 214 137
-6 4 5 250 214 137
-5 4 5 250 214 137
7 4 5 250 214 137
8 4 5 250 214 137
-5 5 5 250 214 137
7 5 5 250 214 137
-6 6 5 250 214 137
-5 6 5 250 214 137
-4 6 5 250 214 137
-3 6 5 250 214 137
5 6 5 250 214 137
6 6 5 250 214 137
7 6 5 250 214 137
8 6 5 250 214 137
-7 7 5 250 214 137
-6 7 5 250 214 137
-5 7 5 250 214 137
-4 7 5 250 214 137
-3 7 5 250 214 137
5 7 5 250 214 137
6 7 5 250 214 137
7 7 5 250 214 137
8 7 5 250 214 137
9 7 5 250 214 137
-7 8 5 250 214 137
-6 8 5 250 214 137
-5 8 5 250 214 137
-4 8 5 250 214 137
-3 8 5 250 214 137
5 8 5 250 214 137
6 8 5 250 214 137
7 8 5 250 214 137
8 8 5 250 214 137
9 8 5 250 214 137
-7 9 5 250 214 137
-6 9 5 250 214 137
-5 9 5 250 214 137
-4 9 5 250 214 137
-3 9 5 250 214 137
5 9 5 250 214 137
6 9 5 250 214 137
7 9 5 250 214 137
8 9 5 250 214 137
9 9 5 250 214 137
-7 -9 6 250 214 137
-6 -9 6 250 214 137
-5 -9 6 250 214 137
-4 -9 6 250 214 137
-3 -9 6 250 214 137
5 -9 6 250 214 137
6 -9 6 250 214 137
7 -9 6 250 214 137
8 -9 6 250 214 137
9 -9 6 250 214 137
-7 -8 6 250 214 137
-6 -8 6 250 214 137
-5 -8 6 250 214 137
-4 -8 6 250 214 137
-3 -8 6 250 214 137
5 -8 6 250 214 137
6 -8 6 250 214 137
7 -8 6 250 214 137
8 -8 6 250 214 137
9 -8 6 250 214 137
-7 -7 6 250 214 137
-6 -7 6 250 214 137
-5 -7 6 250 214 137
-4 -7 6 250 214 137
-3 -7 6 250 214 137
5 -7 6 250 214 137
6 -7 6 250 214 137
7 -7 6 250 214 137
8 -7 6 250 214 137
9 -7 6 250 214 137
-7 -6 6 250 214 137
-6 -6 6 250 214 137
-5 -6 6 250 214 137
-4 -6 6 250 214 137
-3 -6 6 250 214 137
5 -6 6 250 214 137
6 -6 6 250 214 137
7 -6 6 250 214 137
8 -6 6 250 214 137
9 -6 6 250 214 137
-7 -5 6 250 214 137
-6 -5 6 250 214 137
-5 -5 6 250 214 137
7 -5 6 250 214 137
8 -5 6 250 214 137
9 -5 6 250 214 137
-7 -4 6 250 214 137
-6 -4 6 250 214 137
-5 -4 6 250 214 137
7 -4 6 250 214 137
8 -4 6 250 214 137
9 -4 6 250 214 137
-7 -3 6 250 214 137
-6 -3 6 250 214 137
-5 -3 6 250 214 137
7 -3 6 250 214 137
8 -3 6 250 214 137
9 -3 6 250 214 137
-7 -2 6 250 214 137
-6 -2 6 250 214 137
-5 -2 6 250 214 137
7 -2 6 250 214 137
8 -2 6 250 214 137
9 -2 6 250 214 137
-7 -1 6 250 214 137
-6 -1 6 250 214 137
-5 -1 6 250 214 137
7 -1 6 250 214 137
8 -1 6 250 214 137
9 -1 6 250 214 137
-7 0 6 250 214 137
-6 0 6 250 214 137
-5 0 6 250 214 137
7 0 6 250 214 137
8 0 6 250 214 137
9 0 6 250 214 137
-7 1 6 250 214 137
-6 1 6 250 214 137
-5 1 6 250 214 137
7 1 6 250 214 137
8 1 6 250 214 137
9 1 6 250 214 137
-7 2 6 250 214 137
-6 2 6 250 214 137
-5 2 6 250 214 137
7 2 6 250 214 137
8 2 6 250 214 137
9 2 6 250 214 137
-7 3 6 250 214 137
-6 3 6 250 214 137
-5 3 6 250 214 137
7 3 6 250 214 137
8 3 6 250 214 137
9 3 6 250 214 137
-7 4 6 250 214 137
-6 4 6 250 214 137
-5 4 6 250 214 137
7 4 6 250 214 137
8 4 6 250 214 137
9 4 6 250 214 137
-7 5 6 250 214 137
-6 5 6 250 214 137
-5 5 6 250 214 137
7 5 6 250 214 137
8 5 6 250 214 137
9 5 6 250 214 137
-7 6 6 250 214 137
-6 6 6 250 214 137
-5 6 6 250 214 137
-4 6 6 250 214 137
-3 6 6 250 214 137
5 6 6 250 214 137
6 6 6 250 214 137
7 6 6 250 214 137
8 6 6 250 214 137
9 6 6 250 214 137
-7 7 6 250 214 137
-6 7 6 250 214 137
-5 7 6 250 214 137
-4 7 6 250 214 137
-3 7 6 250 214 137
5 7 6 250 214 137
6 7 6 250 214 137
7 7 6 250 214 137
8 7 6 250 214 137
9 7 6 250 214 137
-7 8 6 250 214 137
-6 8 6 250 214 137
-5 8 6 250 214 137
-4 8 6 250 214 137
-3 8 6 250 214 137
5 8 6 250 214 137
6 8 6 250 214 137
7 8 6 250 214 137
8 8 6 250 214 137
9 8 6 250 214 137
-7 9 6 250 214 137
-6 9 6 250 214 137
-5 9 6 250 214 137
-4 9 6 250 214 137
-3 9 6 250 214 137
5 9 6 250 214 137
6 9 6 250 214 137
7 9 6 250 214 137
8 9 6 250 214 137
9 9 6 250 214 137
-7 -9 7 250 214 137
-6 -9 7 250 214 137
-5 -9 7 250 214 137
-4 -9 7 250 214 137
-3 -9 7 250 214 137
5 -9 7 250 214 137
6 -9 7 250 214 137
7 -9 7 250 214 137
8 -9 7 250 214 137
9 -9 7 250 214 137
-7 -8 7 250 214 137
-6 -8 7 250 214 137
-5 -8 7 250 214 137
-4 -8 7 250 214 137
-3 -8 7 250 214 137
5 -8 7 250 214 137
6 -8 7 250 214 137
7 -8 7 250 214 137
8 -8 7 250 214 137
9 -8 7 250 214 137
-7 -7 7 250 214 137
-6 -7 7 250 214 137
-5 -7 7 250 214 137
-4 -7 7 250 214 137
-3 -7 7 250 214 137
5 -7 7 250 214 137
6 -7 7 250 214 137
7 -7 7 250 214 137
8 -7 7 250 214 137
9 -7 7 250 214 137
-7 -6 7 250 214 137
-6 -6 7 250 214 137
-5 -6 7 250 214 137
-4 -6 7 250 214 137
-3 -6 7 250 214 137
5 -6 7 250 214 137
6 -6 7 250 214 137
7 -6 7 250 214 137
8 -6 7 250 214 137
9 -6 7 250 214 137
-7 -5 7 250 214 137
-6 -5 7 250 214 137
-5 -5 7 250 214 137
7 -5 7 250 214 137
8 -5 7 250 214 137
9 -5 7 250 214 137
-7 -4 7 250 214 137
-6 -4 7 250 214 137
-5 -4 7 250 214 137
7 -4 7 250 214 137
8 -4 7 250 214 137
9 -4 7 250 214 137
-7 -3 7 250 214 137
-6 -3 7 250 214 137
-5 -3 7 250 214 137
7 -3 7 250 214 137
8 -3 7 250 214 137
9 -3 7 250 214 137
-7 -2 7 250 214 137
-6 -2 7 250 214 137
-5 -2 7 250 214 137
7 -2 7 250 214 137
8 -2 7 250 214 137
9 -2 7 250 214 137
-7 -1 7 250 214 137
-6 -1 7 250 214 137
-5 -1 7 250 214 137
7 -1 7 250 214 137
8 -1 7 250 214 137
9 -1 7 250 214 137
-7 0 7 250 214 137
-6 0 7 250 214 137
-5 0 7 250 214 137
7 0 7 250 214 137
8 0 7 250 214 137
9 0 7 250 214 137
-7 1 7 250 214 137
-6 1 7 250 214 137
-5 1 7 250 214 137
7 1 7 250 214 137
8 1 7 250 214 137
9 1 7 250 214 137
-7 2 7 250 214 137
-6 2 7 250 214 137
-5 2 7 250 214 137
7 2 7 250 214 137
8 2 7 250 214 137
9 2 7 250 214 137
-7 3 7 250 214 137
-6 3 7 250 214 137
-5 3 7 250 214 137
7 3 7 250 214 137
8 3 7 250 214 137
9 3 7 250 214 137
-7 4 7 250 214 137
-6 4 7 250 214 137
-5 4 7 250 214 137
7 4 7 250 214 137
8 4 7 250 214 137
9 4 7 250 214 137
-7 5 7 250 214 137
-6 5 7 250 214 137
-5 5 7 250 214 137
7 5 7 250 214 137
8 5 7 250 214 137
9 5 7 250 214 137
-7 6 7 250 214 137
-6 6 7 250 214 137
-5 6 7 250 214 137
-4 6 7 250 214 137
-3 6 7 250 214 137
5 6 7 250 214 137
6 6 7 250 214 137
7 6 7 250 214 137
8 6 7 250 214 137
9 6 7 250 214 137
-7 7 7 250 214 137
-6 7 7 250 214 137
-5 7 7 250 214 137
-4 7 7 250 214 137
-3 7 7 250 214 137
5 7 7 250 214 137
6 7 7 250 214 137
7 7 7 250 214 137
8 7 7 250 214 137
9 7 7 250 214 137
-7 8 7 250 214 137
-6 8 7 250 214 137
-5 8 7 250 214 137
-4 8 7 250 214 137
-3 8 7 250 214 137
5 8 7 250 214 137
6 8 7 250 214 137
7 8 7 250 214 137
8 8 7 250 214 137
9 8 7 250 214 137
-7 9 7 250 214 137
-6 9 7 250 214 137
-5 9 7 250 214 137
-4 9 7 250 214 137
-3 9 7 250 214 137
5 9 7 250 214 137
6 9 7 250 214 137
7 9 7 250 214 137
8 9 7 250 214 137
9 9 7 250 214 137
-7 -9 8 250 214 137
-6 -9 8 250 214 137
-5 -9 8 250 214 137
-4 -9 8 250 214 137
-3 -9 8 250 214 137
5 -9 8 250 214 137
6 -9 8 250 214 137
7 -9 8 250 214 137
8 -9 8 250 214 137
9 -9 8 250 214 137
-7 -8 8 250 214 137
-6 -8 8 250 214 137
-5 -8 8 250 214 137
-4 -8 8 250 214 137
-3 -8 8 250 214 137
5 -8 8 250 214 137
6 -8 8 250 214 137
7 -8 8 250 214 137
8 -8 8 250 214 137
9 -8 8 250 214 137
-7 -7 8 250 214 137
-6 -7 8 250 214 137
-5 -7 8 250 214 137
-4 -7 8 250 214 137
-3 -7 8 250 214 137
5 -7 8 250 214 137
6 -7 8 250 214 137
7 -7 8 250 214 137
8 -7 8 250 214 137
9 -7 8 250 214 137
-7 -6 8 250 214 137
-6 -6 8 250 214 137
-5 -6 8 250 214 137
-4 -6 8 250 214 137
-3 -6 8 250 214 137
5 -6 8 250 214 137
6 -6 8 250 214 137
7 -6 8 250 214 137
8 -6 8 250 214 137
9 -6 8 250 214 137
-7 -5 8 250 214 137
-6 -5 8 250 214 137
-5 -5 8 250 214 137
7 -5 8 250 214 137
8 -5 8 250 214 137
9 -5 8 250 214 137
-7 -4 8 250 214 137
-6 -4 8 250 214 137
-5 -4 8 250 214 137
7 -4 8 250 214 137
8 -4 8 250 214 137
9 -4 8 250 214 137
-7 -3 8 250 214 137
-6 -3 8 250 214 137
-5 -3 8 250 214 137
7 -3 8 250 214 137
8 -3 8 250 214 137
9 -3 8 250 214 137
-7 -2 8 250 214 137
-6 -2 8 250 214 137
-5 -2 8 250 214 137
7 -2 8 250 214 137
8 -2 8 250 214 137
9 -2 8 250 214 137
-7 -1 8 250 214 137
-6 -1 8 250 214 137
-5 -1 8 250 214 137
7 -1 8 250 214 137
8 -1 8 250 214 137
9 -1 8 250 214 137
-7 0 8 250 214 137
-6 0 8 250 214 137
-5 0 8 250 214 137
7 0 8 250 214 137
8 0 8 250 214 137
9 0 8 250 214 137
-7 1 8 250 214 137
-6 1 8 250 214 137
-5 1 8 250 214 137
7 1 8 250 214 137
8 1 8 250 214 137
9 1 8 250 214 137
-7 2 8 250 214 137
-6 2 8 250 214 137
-5 2 8 250 214 137
7 2 8 250 214 137
8 2 8 250 214 137
9 2 8 250 214 137
-7 3 8 250 214 137
-6 3 8 250 214 137
-5 3 8 250 214 137
7 3 8 250 214 137
8 3 8 250 214 137
9 3 8 250 214 137
-7 4 8 250 214 137
-6 4 8 250 214 137
-5 4 8 250 214 137
7 4 8 250 214 137
8 4 8 250 214 137
9 4 8 250 214 137
-7 5 8 250 214 137
-6 5 8 250 214 137
-5 5 8 250 214 137
7 5 8 250 214 137
8 5 8 250 214 137
9 5 8 250 214 137
-7 6 8 250 214 137
-6 6 8 250 214 137
-5 6 8 250 214 137
-4 6 8 250 214 137
-3 6 8 250 214 137
5 6 8 250 214 137
6 6 8 250 214 137
7 6 8 250 214 137
8 6 8 250 214 137
9 6 8 250 214 137
-7 7 8 250 214 137
-6 7 8 250 214 137
-5 7 8 250 214 137
-4 7 8 250 214 137
-3 7 8 250 214 137
5 7 8 250 214 137
6 7 8 250 214 137
7 7 8 250 214 137
8 7 8 250 214 137
9 7 8 250 214 137
-7 8 8 250 214 137
-6 8 8 250 214 137
-5 8 8 250 214 137
-4 8 8 250 214 137
-3 8 8 250 214 137
5 8 8 250 214 137
6 8 8 250 214 137
7 8 8 250 214 137
8 8 8 250 214 137
9 8 8 250 214 137
-7 9 8 250 214 137
-6 9 8 250 214 137
-5 9 8 250 214 137
-4 9 8 250 214 137
-3 9 8 250 214 137
5 9 8 250 214 137
6 9 8 250 214 137
7 9 8 250 214 137
8 9 8 250 214 137
9 9 8 250 214 137
-7 -10 9 250 214 137
-6 -10 9 250 214 137
-5 -10 9 250 214 137
-4 -10 9 250 214 137
-3 -10 9 250 214 137
5 -10 9 250 214 137
6 -10 9 250 214 137
7 -10 9 250 214 137
8 -10 9 250 214 137
9 -10 9 250 214 137
-8 -9 9 250 214 137
-7 -9 9 250 214 137
-6 -9 9 250 214 137
-5 -9 9 250 214 137
-4 -9 9 250 214 137
-3 -9 9 250 214 137
-2 -9 9 250 214 137
4 -9 9 250 214 137
5 -9 9 250 214 137
6 -9 9 250 214 137
7 -9 9 250 214 137
8 -9 9 250 214 137
9 -9 9 250 214 137
10 -9 9 250 214 137
-8 -8 9 250 214 137
-7 -8 9 250 214 137
-6 -8 9 250 214 137
-5 -8 9 250 214 137
-4 -8 9 250 214 137
-3 -8 9 250 214 137
-2 -8 9 250 214 137
4 -8 9 250 214 137
5 -8 9 250 214 137
6 -8 9 250 214 137
7 -8 9 250 214 137
8 -8 9 250 214 137
9 -8 9 250 214 137
10 -8 9 250 214 137
-8 -7 9 250 214 137
-7 -7 9 250 214 137
-6 -7 9 250 214 137
-5 -7 9 250 214 137
-4 -7 9 250 214 137
-3 -7 9 250 214 137
-2 -7 9 250 214 137
4 -7 9 250 214 137
5 -7 9 250 214 137
6 -7 9 250 214 137
7 -7 9 250 214 137
8 -7 9 250 214 137
9 -7 9 250 214 137
10 -7 9 250 214 137
-8 -6 9 250 214 137
-7 -6 9 250 214 137
-6 -6 9 250 214 137
-5 -6 9 250 214 137
-4 -6 9 250 214 137
-3 -6 9 250 214 137
-2 -6 9 250 214 137
4 -6 9 250 214 137
5 -6 9 250 214 137
6 -6 9 250 214 137
7 -6 9 250 214 137
8 -6 9 250 214 137
9 -6 9 250 214 137
10 -6 9 250 214 137
-8 -5 9 250 214 137
-7 -5 9 250 214 137
-6 -5 9 250 214 137
-5 -5 9 250 214 137
7 -5 9 250 214 137
8 -5 9 250 214 137
9 -5 9 250 214 137
10 -5 9 250 214 137
-8 -4 9 250 214 137
-7 -4 9 250 214 137
-6 -4 9 250 214 137
-5 -4 9 250 214 137
7 -4 9 250 214 137
8 -4 9 250 214 137
9 -4 9 250 214 137
10 -4 9 250 214 137
-8 -3 9 250 214 137
-7 -3 9 250 214 137
-6 -3 9 250 214 137
-5 -3 9 250 214 137
7 -3 9 250 214 137
8 -3 9 250 214 137
9 -3 9 250 214 137
10 -3 9 250 214 137
-8 -2 9 250 214 137
-7 -2 9 250 214 137
-6 -2 9 250 214 137
-5 -2 9 250 214 137
7 -2 9 250 214 137
8 -2 9 250 214 137
9 -2 9 250 214 137
10 -2 9 250 214 137
-8 -1 9 250 214 137
-7 -1 9 250 214 137
-6 -1 9 250 214 137
-5 -1 9 250 214 137
7 -1 9 250 214 137
8 -1 9 250 214 137
9 -1 9 250 214 137
10 -1 9 250 214 137
-8 0 9 250 214 137
-7 0 9 250 214 137
-6 0 9 250 214 137
-5 0 9 250 214 137
7 0 9 250 214 137
8 0 9 250 214 137
9 0 9 250 214 137
10 0 9 250 214 137
-8 1 9 250 214 137
-7 1 9 250 214 137
-6 1 9 250 214 137
-5 1 9 250 214 137
7 1 9 250 214 137
8 1 9 250 214 137
9 1 9 250 214 137
10 1 9 250 214 137
-8 2 9 250 214 137
-7 2 9 250 214 137
-6 2 9 250 214 137
-5 2 9 250 214 137
7 2 9 250 214 137
8 2 9 250 214 137
9 2 9 250 214 137
10 2 9 250 214 137
-8 3 9 250 214 137
-7 3 9 250 214 137
-6 3 9 250 214 137
-5 3 9 250 214 137
7 3 9 250 214 137
8 3 9 250 214 137
9 3 9 250 214 137
10 3 9 250 214 137
-8 4 9 250 214 137
-7 4 9 250 214 137
-6 4 9 250 214 137
-5 4 9 250 214 137
7 4 9 250 214 137
8 4 9 250 214 137
9 4 9 250 214 137
10 4 9 250 214 137
-8 5 9 250 214 137
-7 5 9 250 214 137
-6 5 9 250 214 137
-5 5 9 250 214 137
7 5 9 250 214 137
8 5 9 250 214 137
9 5 9 250 214 137
10 5 9 250 214 137
-8 6 9 250 214 137
-7 6 9 250 214 137
-6 6 9 250 214 137
-5 6 9 250 214 137
-4 6 9 250 214 137
-3 6 9 250 214 137
-2 6 9 250 214 137
4 6 9 250 214 137
5 6 9 250 214 137
6 6 9 250 214 137
7 6 9 250 214 137
8 6 9 250 214 137
9 6 9 250 214 137
10 6 9 250 214 137
-8 7 9 250 214 137
-7 7 9 250 214 137
-6 7 9 250 214 137
-5 7 9 250 214 137
-4 7 9 250 214 137
-3 7 9 250 214 137
-2 7 9 250 214 137
4 7 9 250 214 137
5 7 9 250 214 137
6 7 9 250 214 137
7 7 9 250 214 137
8 7 9 250 214 137
9 7 9 250 214 137
10 7 9 250 214 137
-8 8 9 250 214 137
-7 8 9 250 214 137
-6 8 9 250 214 137
-5 8 9 250 214 137
-4 8 9 250 214 137
-3 8 9 250 214 137
-2 8 9 250 214 137
4 8 9 250 214 137
5 8 9 250 214 137
6 8 9 250 214 137
7 8 9 250 214 137
8 8 9 250 214 137
9 8 9 250 214 137
10 8 9 250 214 137
-8 9 9 250 214 137
-7 9 9 250 214 137
-6 9 9 250 214 137
-5 9 9 250 214 137
-4 9 9 250 214 137
-3 9 9 250 214 137
-2 9 9 250 214 137
4 9 9 250 214 137
5 9 9 250 214 137
6 9 9 250 214 137
7 9 9 250 214 137
8 9 9 250 214 137
9 9 9 250 214 137
10 9 9 250 214 137
-7 10 9 250 214 137
-6 10 9 250 214 137
-5 10 9 250 214 137
-4 10 9 250 214 137
-3 10 9 250 214 137
5 10 9 250 214 137
6 10 9 250 214 137
7 10 9 250 214 137
8 10 9 250 214 137
9 10 9 250 214 137
-7 -9 10 250 214 137
-6 -9 10 250 214 137
-5 -9 10 250 214 137
-4 -9 10 250 214 137
-3 -9 10 250 214 137
5 -9 10 250 214 137
6 -9 10 250 214 137
7 -9 10 250 214 137
8 -9 10 250 214 137
9 -9 10 250 214 137
-7 -8 10 250 214 137
-6 -8 10 250 214 137
-5 -8 10 250 214 137
-4 -8 10 250 214 137
-3 -8 10 250 214 137
5 -8 10 250 214 137
6 -8 10 250 214 137
7 -8 10 250 214 137
8 -8 10 250 214 137
9 -8 10 250 214 137
-7 -7 10 250 214 137
-6 -7 10 250 214 137
-5 -7 10 250 214 137
-4 -7 10 250 214 137
-3 -7 10 250 214 137
5 -7 10 250 214 137
6 -7 10 250 214 137
7 -7 10 250 214 137
8 -7 10 250 214 137
9 -7 10 250 214 137
-7 -6 10 250 214 137
-6 -6 10 250 214 137
-5 -6 10 250 214 137
-4 -6 10 250 214 137
-3 -6 10 250 214 137
5 -6 10 250 214 137
6 -6 10 250 214 137
7 -6 10 250 214 137
8 -6 10 250 214 137
9 -6 10 250 214 137
-7 -5 10 250 214 137
-6 -5 10 250 214 137
-5 -5 10 250 214 137
7 -5 10 250 214 137
8 -5 10 250 214 137
9 -5 10 250 214 137
-7 -4 10 250 214 137
-6 -4 10 250 214 137
-5 -4 10 250 214 137
7 -4 10 250 214 137
8 -4 10 250 214 137
9 -4 10 250 214 137
-7 -3 10 250 214 137
-6 -3 10 250 214 137
-5 -3 10 250 214 137
7 -3 10 250 214 137
8 -3 10 250 214 137
9 -3 10 250 214 137
-7 -2 10 250 214 137
-6 -2 10 250 214 137
-5 -2 10 250 214 137
7 -2 10 250 214 137
8 -2 10 250 214 137
9 -2 10 250 214 137
-7 -1 10 250 214 137
-6 -1 10 250 214 137
-5 -1 10 250 214 137
7 -1 10 250 214 137
8 -1 10 250 214 137
9 -1 10 250 214 137
-7 0 10 250 214 137
-6 0 10 250 214 137
-5 0 10 250 214 137
7 0 10 250 214 137
8 0 10 250 214 137
9 0 10 250 214 137
-7 1 10 250 214 137
-6 1 10 250 214 137
-5 1 10 250 214 137
7 1 10 250 214 137
8 1 10 250 214 137
9 1 10 250 214 137
-7 2 10 250 214 137
-6 2 10 250 214 137
-5 2 10 250 214 137
7 2 10 250 214 137
8 2 10 250 214 137
9 2 10 250 214 137
-7 3 10 250 214 137
-6 3 10 250 214 137
-5 3 10 250 214 137
7 3 10 250 214 137
8 3 10 250 214 137
9 3 10 250 214 137
-7 4 10 250 214 137
-6 4 10 250 214 137
-5 4 10 250 214 137
7 4 10 250 214 137
8 4 10 250 214 137
9 4 10 250 214 137
-7 5 10 250 214 137
-6 5 10 250 214 137
-5 5 10 250 214 137
7 5 10 250 214 137
8 5 10 250 214 137
9 5 10 250 214 137
-7 6 10 250 214 137
-6 6 10 250 214 137
-5 6 10 250 214 137
-4 6 10 250 214 137
-3 6 10 250 214 137
5 6 10 250 214 137
6 6 10 250 214 137
7 6 10 250 214 137
8 6 10 250 214 137
9 6 10 250 214 137
-7 7 10 250 214 137
-6 7 10 250 214 137
-5 7 10 250 214 137
-4 7 10 250 214 137
-3 7 10 250 214 137
5 7 10 250 214 137
6 7 10 250 214 137
7 7 10 250 214 137
8 7 10 250 214 137
9 7 10 250 214 137
-7 8 10 250 214 137
-6 8 10 250 214 137
-5 8 10 250 214 137
-4 8 10 250 214 137
-3 8 10 250 214 137
5 8 10 250 214 137
6 8 10 250 214 137
7 8 10 250 214 137
8 8 10 250 214 137
9 8 10 250 214 137
-7 9 10 250 214 137
-6 9 10 250 214 137
-5 9 10 250 214 137
-4 9 10 250 214 137
-3 9 10 250 214 137
5 9 10 250 214 137
6 9 10 250 214 137
7 9 10 250 214 137
8 9 10 250 214 137
9 9 10 250 214 137
-7 -9 11 250 214 137
-6 -9 11 250 214 137
-5 -9 11 250 214 137
-4 -9 11 250 214 137
-3 -9 11 250 214 137
-2 -9 11 250 214 137
4 -9 11 250 214 137
5 -9 11 250 214 137
6 -9 11 250 214 137
7 -9 11 250 214 137
8 -9 11 250 214 137
9 -9 11 250 214 137
-7 -8 11 250 214 137
-6 -8 11 250 214 137
-5 -8 11 250 214 137
-4 -8 11 250 214 137
-3 -8 11 250 214 137
-2 -8 11 250 214 137
-1 -8 11 250 214 137
3 -8 11 250 214 137
4 -8 11 250 214 137
5 -8 11 250 214 137
6 -8 11 250 214 137
7 -8 11 250 214 137
8 -8 11 250 214 137
9 -8 11 250 214 137
-7 -7 11 250 214 137
-6 -7 11 250 214 137
-5 -7 11 250 214 137
-4 -7 11 250 214 137
-3 -7 11 250 214 137
-2 -7 11 250 214 137
-1 -7 11 250 214 137
0 -7 11 250 214 137
1 -7 11 250 214 137
2 -7 11 250 214 137
3 -7 11 250 214 137
4 -7 11 250 214 137
5 -7 11 250 214 137
6 -7 11 250 214 137
7 -7 11 250 214 137
8 -7 11 250 214 137
9 -7 11 250 214 137
-7 -6 11 250 214 137
-6 -6 11 250 214 137
-5 -6 11 250 214 137
-4 -6 11 250 214 137
-3 -6 11 250 214 137
-2 -6 11 250 214 137
-1 -6 11 250 214 137
0 -6 11 250 214 137
1 -6 11 250 214 137
2 -6 11 250 214 137
3 -6 11 250 214 137
4 -6 11 250 214 137
5 -6 11 250 214 137
6 -6 11 250 214 137
7 -6 11 250 214 137
8 -6 11 250 214 137
9 -6 11 250 214 137
-7 -5 11 250 214 137
-6 -5 11 250 214 137
-5 -5 11 250 214 137
7 -5 11 250 214 137
8 -5 11 250 214 137
9 -5 11 250 214 137
-7 -4 11 250 214 137
-6 -4 11 250 214 137
-5 -4 11 250 214 137
7 -4 11 250 214 137
8 -4 11 250 214 137
9 -4 11 250 214 137
-7 -3 11 250 214 137
-6 -3 11 250 214 137
-5 -3 11 250 214 137
7 -3 11 250 214 137
8 -3 11 250 214 137
9 -3 11 250 214 137
-7 -2 11 250 214 137
-6 -2 11 250 214 137
-5 -2 11 250 214 137
7 -2 11 250 214 137
8 -2 11 250 214 137
9 -2 11 250 214 137
-7 -1 11 250 214 137
-6 -1 11 250 214 137
-5 -1 11 250 214 137
7 -1 11 250 214 137
8 -1 11 250 214 137
9 -1 11 250 214 137
-7 0 11 250 214 137
-6 0 11 250 214 137
-5 0 11 250 214 137
7 0 11 250 214 137
8 0 11 250 214 137
9 0 11 250 214 137
-7 1 11 250 214 137
-6 1 11 250 214 137
-5 1 11 250 214 137
7 1 11 250 214 137
8 1 11 250 214 137
9 1 11 250 214 137
-7 2 11 250 214 137
-6 2 11 250 214 137
-5 2 11 250 214 137
7 2 11 250 214 137
8 2 11 250 214 137
9 2 11 250 214 137
-7 3 11 250 214 137
-6 3 11 250 214 137
-5 3 11 250 214 137
7 3 11 250 214 137
8 3 11 250 214 137
9 3 11 250 214 137
-7 4 11 250 214 137
-6 4 11 250 214 137
-5 4 11 250 214 137
7 4 11 250 214 137
8 4 11 250 214 137
9 4 11 250 214 137
-7 5 11 250 214 137
-6 5 11 250 214 137
-5 5 11 250 214 137
7 5 11 250 214 137
8 5 11 250 214 137
9 5 11 250 214 137
-7 6 11 250 214 137
-6 6 11 250 214 137
-5 6 11 250 214 137
-4 6 11 250 214 137
-3 6 11 250 214 137
-2 6 11 250 214 137
-1 6 11 250 214 137
0 6 11 250 214 137
1 6 11 250 214 137
2 6 11 250 214 137
3 6 11 250 214 137
4 6 11 250 214 137
5 6 11 250 214 137
6 6 11 250 214 137
7 6 11 250 214 137
8 6 11 250 214 137
9 6 11 250 214 137
-7 7 11 250 214 137
-6 7 11 250 214 137
-5 7 11 250 214 137
-4 7 11 250 214 137
-3 7 11 250 214 137
-2 7 11 250 214 137
-1 7 11 250 214 137
0 7 11 250 214 137
1 7 11 250 214 137
2 7 11 250 214 137
3 7 11 250 214 137
4 7 11 250 214 137
5 7 11 250 214 137
6 7 11 250 214 137
7 7 11 250 214 137
8 7 11 250 214 137
9 7 11 250 214 137
-7 8 11 250 214 137
-6 8 11 250 214 137
-5 8 11 250 214 137
-4 8 11 250 214 137
-3 8 11 250 214 137
-2 8 11 250 214 137
-1 8 11 250 214 137
3 8 11 250 214 137
4 8 11 250 214 137
5 8 11 250 214 137
6 8 11 250 214 137
7 8 11 250 214 137
8 8 11 250 214 137
9 8 11 250 214 137
-7 9 11 250 214 137
-6 9 11 250 214 137
-5 9 11 250 214 137
-4 9 11 250 214 137
-3 9 11 250 214 137
-2 9 11 250 214 137
4 9 11 250 214 137
5 9 11 250 214 137
6 9 11 250 214 137
7 9 11 250 214 137
8 9 11 250 214 137
9 9 11 250 214 137
-7 -9 12 250 214 137
-6 -9 12 250 214 137
-5 -9 12 250 214 137
-4 -9 12 250 214 137
-3 -9 12 250 214 137
-2 -9 12 250 214 137
-1 -9 12 250 214 137
3 -9 12 250 214 137
4 -9 12 250 214 137
5 -9 12 250 214 137
6 -9 12 250 214 137
7 -9 12 250 214 137
8 -9 12 250 214 137
9 -9 12 250 214 137
-7 -8 12 250 214 137
-6 -8 12 250 214 137
-5 -8 12 250 214 137
-4 -8 12 250 214 137
-3 -8 12 250 214 137
-2 -8 12 250 214 137
-1 -8 12 250 214 137
0 -8 12 250 214 137
1 -8 12 250 214 137
2 -8 12 250 214 137
3 -8 12 250 214 137
4 -8 12 250 214 137
5 -8 12 250 214 137
6 -8 12 250 214 137
7 -8 12 250 214 137
8 -8 12 250 214 137
9 -8 12 250 214 137
-7 -7 12 250 214 137
-6 -7 12 250 214 137
-5 -7 12 250 214 137
-4 -7 12 250 214 137
-3 -7 12 250 214 137
-2 -7 12 250 214 137
-1 -7 12 250 214 137
0 -7 12 250 214 137
1 -7 12 250 214 137
2 -7 12 250 214 137
3 -7 12 250 214 137
4 -7 12 250 214 137
5 -7 12 250 214 137
6 -7 12 250 214 137
7 -7 12 250 214 137
8 -7 12 250 214 137
9 -7 12 250 214 137
-7 -6 12 250 214 137
-6 -6 12 250 214 137
-5 -6 12 250 214 137
-4 -6 12 250 214 137
-3 -6 12 250 214 137
-2 -6 12 250 214 137
-1 -6 12 250 214 137
0 -6 12 250 214 137
1 -6 12 250 214 137
2 -6 12 250 214 137
3 -6 12 250 214 137
4 -6 12 250 214 137
5 -6 12 250 214 137
6 -6 12 250 214 137
7 -6 12 250 214 137
8 -6 12 250 214 137
9 -6 12 250 214 137
-7 -5 12 250 214 137
-6 -5 12 250 214 137
-5 -5 12 250 214 137
7 -5 12 250 214 137
8 -5 12 250 214 137
9 -5 12 250 214 137
-7 -4 12 250 214 137
-6 -4 12 250 214 137
-5 -4 12 250 214 137
7 -4 12 250 214 137
8 -4 12 250 214 137
9 -4 12 250 214 137
-7 -3 12 250 214 137
-6 -3 12 250 214 137
-5 -3 12 250 214 137
7 -3 12 250 214 137
8 -3 12 250 214 137
9 -3 12 250 214 137
-7 -2 12 250 214 137
-6 -2 12 250 214 137
-5 -2 12 250 214 137
7 -2 12 250 214 137
8 -2 12 250 214 137
9 -2 12 250 214 137
-7 -1 12 250 214 137
-6 -1 12 250 214 137
-5 -1 12 250 214 137
7 -1 12 250 214 137
8 -1 12 250 214 137
9 -1 12 250 214 137
-7 0 12 250 214 137
-6 0 12 250 214 137
-5 0 12 250 214 137
7 0 12 250 214 137
8 0 12 250 214 137
9 0 12 250 214 137
-7 1 12 250 214 137
-6 1 12 250 214 137
-5 1 12 250 214 137
7 1 12 250 214 137
8 1 12 250 214 137
9 1 12 250 214 137
-7 2 12 250 214 137
-6 2 12 250 214 137
-5 2 12 250 214 137
7 2 12 250 214 137
8 2 12 250 214 137
9 2 12 250 214 137
-7 3 12 250 214 137
-6 3 12 250 214 137
-5 3 12 250 214 137
7 3 12 250 214 137
8 3 12 250 214 137
9 3 12 250 214 137
-7 4 12 250 214 137
-6 4 12 250 214 137
-5 4 12 250 214 137
7 4 12 250 214 137
8 4 12 250 214 137
9 4 12 250 214 137
-7 5 12 250 214 137
-6 5 12 250 214 137
-5 5 12 250 214 137
7 5 12 250 214 137
8 5 12 250 214 137
9 5 12 250 214 137
-7 6 12 250 214 137
-6 6 12 250 214 137
-5 6 12 250 214 137
-4 6 12 250 214 137
-3 6 12 250 214 137
-2 6 12 250 214 137
-1 6 12 250 214 137
0 6 12 250 214 137
1 6 12 250 214 137
2 6 12 250 214 137
3 6 12 250 214 137
4 6 12 250 214 137
5 6 12 250 214 137
6 6 12 250 214 137
7 6 12 250 214 137
8 6 12 250 214 137
9 6 12 250 214 137
-7 7 12 250 214 137
-6 7 12 250 214 137
-5 7 12 250 214 137
-4 7 12 250 214 137
-3 7 12 250 214 137
-2 7 12 250 214 137
-1 7 12 250 214 137
0 7 12 250 214 137
1 7 12 250 214 137
2 7 12 250 214 137
3 7 12 250 214 137
4 7 12 250 214 137
5 7 12 250 214 137
6 7 12 250 214 137
7 7 12 250 214 137
8 7 12 250 214 137
9 7 12 250 214 137
-7 8 12 250 214 137
-6 8 12 250 214 137
-5 8 12 250 214 137
-4 8 12 250 214 137
-3 8 12 250 214 137
-2 8 12 250 214 137
-1 8 12 250 214 137
0 8 12 250 214 137
1 8 12 250 214 137
2 8 12 250 214 137
3 8 12 250 214 137
4 8 12 250 214 137
5 8 12 250 214 137
6 8 12 250 214 137
7 8 12 250 214 137
8 8 12 250 214 137
9 8 12 250 214 137
-7 9 12 250 214 137
-6 9 12 250 214 137
-5 9 12 250 214 137
-4 9 12 250 214 137
-3 9 12 250 214 137
-2 9 12 250 214 137
-1 9 12 250 214 137
3 9 12 250 214 137
4 9 12 250 214 137
5 9 12 250 214 137
6 9 12 250 214 137
7 9 12 250 214 137
8 9 12 250 214 137
9 9 12 250 214 137
-7 -9 13 250 214 137
-5 -9 13 250 214 137
-3 -9 13 250 214 137
-2 -9 13 250 214 137
-1 -9 13 250 214 137
0 -9 13 250 214 137
1 -9 13 250 214 137
2 -9 13 250 214 137
3 -9 13 250 214 137
4 -9 13 250 214 137
5 -9 13 250 214 137
7 -9 13 250 214 137
9 -9 13 250 214 137
-7 -8 13 250 214 137
-6 -8 13 250 214 137
-5 -8 13 250 214 137
-4 -8 13 250 214 137
-3 -8 13 250 214 137
-2 -8 13 250 214 137
-1 -8 13 250 214 137
0 -8 13 250 214 137
1 -8 13 250 214 137
2 -8 13 250 214 137
3 -8 13 250 214 137
4 -8 13 250 214 137
5 -8 13 250 214 137
6 -8 13 250 214 137
7 -8 13 250 214 137
8 -8 13 250 214 137
9 -8 13 250 214 137
-6 -7 13 250 214 137
-5 -7 13 250 214 137
-4 -7 13 250 214 137
-3 -7 13 250 214 137
-2 -7 13 250 214 137
-1 -7 13 250 214 137
0 -7 13 250 214 137
1 -7 13 250 214 137
2 -7 13 250 214 137
3 -7 13 250 214 137
4 -7 13 250 214 137
5 -7 13 250 214 137
6 -7 13 250 214 137
7 -7 13 250 214 137
8 -7 13 250 214 137
-7 -6 13 250 214 137
-6 -6 13 250 214 137
-5 -6 13 250 214 137
-4 -6 13 250 214 137
-3 -6 13 250 214 137
-2 -6 13 250 214 137
-1 -6 13 250 214 137
0 -6 13 250 214 137
1 -6 13 250 214 137
2 -6 13 250 214 137
3 -6 13 250 214 137
4 -6 13 250 214 137
5 -6 13 250 214 137
6 -6 13 250 214 137
7 -6 13 250 214 137
8 -6 13 250 214 137
9 -6 13 250 214 137
-6 -5 13 250 214 137
-5 -5 13 250 214 137
7 -5 13 250 214 137
8 -5 13 250 214 137
-7 -4 13 250 214 137
-6 -4 13 250 214 137
-5 -4 13 250 214 137
7 -4 13 250 214 137
8 -4 13 250 214 137
9 -4 13 250 214 137
-6 -3 13 250 214 137
-5 -3 13 250 214 137
7 -3 13 250 214 137
8 -3 13 250 214 137
-7 -2 13 250 214 137
-6 -2 13 250 214 137
-5 -2 13 250 214 137
7 -2 13 250 214 137
8 -2 13 250 214 137
9 -2 13 250 214 137
-6 -1 13 250 214 137
-5 -1 13 250 214 137
7 -1 13 250 214 137
8 -1 13 250 214 137
-7 0 13 250 214 137
-6 0 13 250 214 137
-5 0 13 250 214 137
7 0 13 250 214 137
8 0 13 250 214 137
9 0 13 250 214 137
-6 1 13 250 214 137
-5 1 13 250 214 137
7 1 13 250 214 137
8 1 13 250 214 137
-7 2 13 250 214 137
-6 2 13 250 214 137
-5 2 13 250 214 137
7 2 13 250 214 137
8 2 13 250 214 137
9 2 13 250 214 137
-6 3 13 250 214 137
-5 3 13 250 214 137
7 3 13 250 214 137
8 3 13 250 214 137
-7 4 13 250 214 137
-6 4 13 250 214 137
-5 4 13 250 214 137
7 4 13 250 214 137
8 4 13 250 214 137
9 4 13 250 214 137
-6 5 13 250 214 137
-5 5 13 250 214 137
7 5 13 250 214 137
8 5 13 250 214 137
-7 6 13 250 214 137
-6 6 13 250 214 137
-5 6 13 250 214 137
-4 6 13 250 214 137
-3 6 13 250 214 137
-2 6 13 250 214 137
-1 6 13 250 214 137
0 6 13 250 214 137
1 6 13 250 214 137
2 6 13 250 214 137
3 6 13 250 214 137
4 6 13 250 214 137
5 6 13 250 214 137
6 6 13 250 214 137
7 6 13 250 214 137
8 6 13 250 214 137
9 6 13 250 214 137
-6 7 13 250 214 137
-5 7 13 250 214 137
-4 7 13 250 214 137
-3 7 13 250 214 137
-2 7 13 250 214 137
-1 7 13 250 214 137
0 7 13 250 214 137
1 7 13 250 214 137
2 7 13 250 214 137
3 7 13 250 214 137
4 7 13 250 214 137
5 7 13 250 214 137
6 7 13 250 214 137
7 7 13 250 214 137
8 7 13 250 214 137
-7 8 13 250 214 137
-6 8 13 250 214 137
-5 8 13 250 214 137
-4 8 13 250 214 137
-3 8 13 250 214 137
-2 8 13 250 214 137
-1 8 13 250 214 137
0 8 13 250 214 137
1 8 13 250 214 137
2 8 13 250 214 137
3 8 13 250 214 137
4 8 13 250 214 137
5 8 13 250 214 137
6 8 13 250 214 137
7 8 13 250 214 137
8 8 13 250 214 137
9 8 13 250 214 137
-7 9 13 250 214 137
-5 9 13 250 214 137
-3 9 13 250 214 137
-2 9 13 250 214 137
-1 9 13 250 214 137
0 9 13 250 214 137
1 9 13 250 214 137
2 9 13 250 214 137
3 9 13 250 214 137
4 9 13 250 214 137
5 9 13 250 214 137
7 9 13 250 214 137
9 9 13 250 214 137
-7 -9 14 250 214 137
-6 -9 14 250 214 137
-5 -9 14 250 214 137
-4 -9 14 250 214 137
-3 -9 14 250 214 137
-2 -9 14 250 214 137
-1 -9 14 250 214 137
0 -9 14 250 214 137
1 -9 14 250 214 137
2 -9 14 250 214 137
3 -9 14 250 214 137
4 -9 14 250 214 137
5 -9 14 250 214 137
6 -9 14 250 214 137
7 -9 14 250 214 137
8 -9 14 250 214 137
9 -9 14 250 214 137
-7 -8 14 250 214 137
-6 -8 14 250 214 137
-5 -8 14 250 214 137
-4 -8 14 250 214 137
-3 -8 14 250 214 137
-2 -8 14 250 214 137
-1 -8 14 250 214 137
0 -8 14 250 214 137
1 -8 14 250 214 137
2 -8 14 250 214 137
3 -8 14 250 214 137
4 -8 14 250 214 137
5 -8 14 250 214 137
6 -8 14 250 214 137
7 -8 14 250 214 137
8 -8 14 250 214 137
9 -8 14 250 214 137
-7 -7 14 250 214 137
-6 -7 14 250 214 137
-5 -7 14 250 214 137
-4 -7 14 250 214 137
-3 -7 14 250 214 137
-2 -7 14 250 214 137
-1 -7 14 250 214 137
0 -7 14 250 214 137
1 -7 14 250 214 137
2 -7 14 250 214 137
3 -7 14 250 214 137
4 -7 14 250 214 137
5 -7 14 250 214 137
6 -7 14 250 214 137
7 -7 14 250 214 137
8 -7 14 250 214 137
9 -7 14 250 214 137
-7 -6 14 250 214 137
-6 -6 14 250 214 137
-5 -6 14 250 214 137
-4 -6 14 250 214 137
-3 -6 14 250 214 137
-1 -6 14 250 214 137
0 -6 14 250 214 137
1 -6 14 250 214 137
2 -6 14 250 214 137
3 -6 14 250 214 137
5 -6 14 250 214 137
6 -6 14 250 214 137
7 -6 14 250 214 137
8 -6 14 250 214 137
9 -6 14 250 214 137
-7 -5 14 250 214 137
-6 -5 14 250 214 137
-5 -5 14 250 214 137
7 -5 14 250 214 137
8 -5 14 250 214 137
9 -5 14 250 214 137
-7 -4 14 250 214 137
-6 -4 14 250 214 137
-5 -4 14 250 214 137
7 -4 14 250 214 137
8 -4 14 250 214 137
9 -4 14 250 214 137
-7 -3 14 250 214 137
-6 -3 14 250 214 137
8 -3 14 250 214 137
9 -3 14 250 214 137
-7 -2 14 250 214 137
-6 -2 14 250 214 137
-5 -2 14 250 214 137
7 -2 14 250 214 137
8 -2 14 250 214 137
9 -2 14 250 214 137
-7 -1 14 250 214 137
-6 -1 14 250 214 137
-5 -1 14 250 214 137
7 -1 14 250 214 137
8 -1 14 250 214 137
9 -1 14 250 214 137
-7 0 14 250 214 137
-6 0 14 250 214 137
-5 0 14 250 214 137
7 0 14 250 214 137
8 0 14 250 214 137
9 0 14 250 214 137
-7 1 14 250 214 137
-6 1 14 250 214 137
-5 1 14 250 214 137
7 1 14 250 214 137
8 1 14 250 214 137
9 1 14 250 214 137
-7 2 14 250 214 137
-6 2 14 250 214 137
-5 2 14 250 214 137
7 2 14 250 214 137
8 2 14 250 214 137
9 2 14 250 214 137
-7 3 14 250 214 137
-6 3 14 250 214 137
8 3 14 250 214 137
9 3 14 250 214 137
-7 4 14 250 214 137
-6 4 14 250 214 137
-5 4 14 250 214 137
7 4 14 250 214 137
8 4 14 250 214 137
9 4 14 250 214 137
-7 5 14 250 214 137
-6 5 14 250 214 137
-5 5 14 250 214 137
7 5 14 250 214 137
8 5 14 250 214 137
9 5 14 250 214 137
-7 6 14 250 214 137
-6 6 14 250 214 137
-5 6 14 250 214 137
-4 6 14 250 214 137
-3 6 14 250 214 137
-1 6 14 250 214 137
0 6 14 250 214 137
1 6 14 250 214 137
2 6 14 250 214 137
3 6 14 250 214 137
5 6 14 250 214 137
6 6 14 250 214 137
7 6 14 250 214 137
8 6 14 250 214 137
9 6 14 250 214 137
-7 7 14 250 214 137
-6 7 14 250 214 137
-5 7 14 250 214 137
-4 7 14 250 214 137
-3 7 14 250 214 137
-2 7 14 250 214 137
-1 7 14 250 214 137
0 7 14 250 214 137
1 7 14 250 214 137
2 7 14 250 214 137
3 7 14 250 214 137
4 7 14 250 214 137
5 7 14 250 214 137
6 7 14 250 214 137
7 7 14 250 214 137
8 7 14 250 214 137
9 7 14 250 214 137
-7 8 14 250 214 137
-6 8 14 250 214 137
-5 8 14 250 214 137
-4 8 14 250 214 137
-3 8 14 250 214 137
-2 8 14 250 214 137
-1 8 14 250 214 137
0 8 14 250 214 137
1 8 14 250 214 137
2 8 14 250 214 137
3 8 14 250 214 137
4 8 14 250 214 137
5 8 14 250 214 137
6 8 14 250 214 137
7 8 14 250 214 137
8 8 14 250 214 137
9 8 14 250 214 137
-7 9 14 250 214 137
-6 9 14 250 214 137
-5 9 14 250 214 137
-4 9 14 250 214 137
-3 9 14 250 214 137
-2 9 14 250 214 137
-1 9 14 250 214 137
0 9 14 250 214 137
1 9 14 250 214 137
2 9 14 250 214 137
3 9 14 250 214 137
4 9 14 250 214 137
5 9 14 250 214 137
6 9 14 250 214 137
7 9 14 250 214 137
8 9 14 250 214 137
9 9 14 250 214 137
-8 -10 15 250 214 137
-7 -10 15 250 214 137
-6 -10 15 250 214 137
-5 -10 15 250 214 137
-4 -10 15 250 214 137
-3 -10 15 250 214 137
-2 -10 15 250 214 137
-1 -10 15 250 214 137
0 -10 15 250 214 137
1 -10 15 250 214 137
2 -10 15 250 214 137
3 -10 15 250 214 137
4 -10 15 250 214 137
5 -10 15 250 214 137
6 -10 15 250 214 137
7 -10 15 250 214 137
8 -10 15 250 214 137
9 -10 15 250 214 137
10 -10 15 250 214 137
-8 -9 15 250 214 137
-7 -9 15 250 214 137
-6 -9 15 250 214 137
8 -9 15 250 214 137
9 -9 15 250 214 137
10 -9 15 250 214 137
-8 -8 15 250 214 137
-7 -8 15 250 214 137
-6 -8 15 250 214 137
8 -8 15 250 214 137
9 -8 15 250 214 137
10 -8 15 250 214 137
-8 -7 15 250 214 137
-7 -7 15 250 214 137
-6 -7 15 250 214 137
8 -7 15 250 214 137
9 -7 15 250 214 137
10 -7 15 250 214 137
-8 -6 15 250 214 137
-5 -6 15 250 214 137
-4 -6 15 250 214 137
-3 -6 15 250 214 137
-2 -6 15 250 214 137
-1 -6 15 250 214 137
0 -6 15 250 214 137
1 -6 15 250 214 137
2 -6 15 250 214 137
3 -6 15 250 214 137
4 -6 15 250 214 137
5 -6 15 250 214 137
6 -6 15 250 214 137
7 -6 15 250 214 137
10 -6 15 250 214 137
-8 -5 15 250 214 137
-5 -5 15 250 214 137
7 -5 15 250 214 137
10 -5 15 250 214 137
-8 -4 15 250 214 137
-5 -4 15 250 214 137
7 -4 15 250 214 137
10 -4 15 250 214 137
-8 -3 15 250 214 137
-5 -3 15 250 214 137
7 -3 15 250 214 137
10 -3 15 250 214 137
-8 -2 15 250 214 137
-5 -2 15 250 214 137
7 -2 15 250 214 137
10 -2 15 250 214 137
-8 -1 15 250 214 137
-5 -1 15 250 214 137
7 -1 15 250 214 137
10 -1 15 250 214 137
-8 0 15 250 214 137
-5 0 15 250 214 137
7 0 15 250 214 137
10 0 15 250 214 137
-8 1 15 250 214 137
-5 1 15 250 214 137
7 1 15 250 214 137
10 1 15 250 214 137
-8 2 15 250 214 137
-5 2 15 250 214 137
7 2 15 250 214 137
10 2 15 250 214 137
-8 3 15 250 214 137
-5 3 15 250 214 137
7 3 15 250 214 137
10 3 15 250 214 137
-8 4 15 250 214 137
-5 4 15 250 214 137
7 4 15 250 214 137
10 4 15 250 214 137
-8 5 15 250 214 137
-5 5 15 250 214 137
7 5 15 250 214 137
10 5 15 250 214 137
-8 6 15 250 214 137
-5 6 15 250 214 137
-4 6 15 250 214 137
-3 6 15 250 214 137
-2 6 15 250 214 137
-1 6 15 250 214 137
0 6 15 250 214 137
1 6 15 250 214 137
2 6 15 250 214 137
3 6 15 250 214 137
4 6 15 250 214 137
5 6 15 250 214 137
6 6 15 250 214 137
7 6 15 250 214 137
10 6 15 250 214 137
-8 7 15 250 214 137
-7 7 15 250 214 137
-6 7 15 250 214 137
8 7 15 250 214 137
9 7 15 250 214 137
10 7 15 250 214 137
-8 8 15 250 214 137
-7 8 15 250 214 137
-6 8 15 250 214 137
8 8 15 250 214 137
9 8 15 250 214 137
10 8 15 250 214 137
-8 9 15 250 214 137
-7 9 15 250 214 137
-6 9 15 250 214 137
8 9 15 250 214 137
9 9 15 250 214 137
10 9 15 250 214 137
-8 10 15 250 214 137
-7 10 15 250 214 137
-6 10 15 250 214 137
-5 10 15 250 214 137
-4 10 15 250 214 137
-3 10 15 250 214 137
-2 10 15 250 214 137
-1 10 15 250 214 137
0 10 15 250 214 137
1 10 15 250 214 137
2 10 15 250 214 137
3 10 15 250 214 137
4 10 15 250 214 137
5 10 15 250 214 137
6 10 15 250 214 137
7 10 15 250 214 137
8 10 15 250 214 137
9 10 15 250 214 137
10 10 15 250 214 137
-7 -10 16 250 214 137
-5 -10 16 250 214 137
-3 -10 16 250 214 137
-1 -10 16 250 214 137
1 -10 16 250 214 137
3 -10 16 250 214 137
5 -10 16 250 214 137
7 -10 16 250 214 137
9 -10 16 250 214 137
-8 -9 16 250 214 137
-7 -9 16 250 214 137
-6 -9 16 250 214 137
8 -9 16 250 214 137
9 -9 16 250 214 137
10 -9 16 250 214 137
-8 -8 16 250 214 137
-7 -8 16 250 214 137
-6 -8 16 250 214 137
8 -8 16 250 214 137
9 -8 16 250 214 137
10 -8 16 250 214 137
-8 -7 16 250 214 137
-7 -7 16 250 214 137
-6 -7 16 250 214 137
8 -7 16 250 214 137
9 -7 16 250 214 137
10 -7 16 250 214 137
-5 -6 16 250 214 137
-3 -6 16 250 214 137
-1 -6 16 250 214 137
1 -6 16 250 214 137
3 -6 16 250 214 137
5 -6 16 250 214 137
7 -6 16 250 214 137
-8 -5 16 250 214 137
10 -5 16 250 214 137
-5 -4 16 250 214 137
7 -4 16 250 214 137
-8 -3 16 250 214 137
10 -3 16 250 214 137
-5 -2 16 250 214 137
7 -2 16 250 214 137
-8 -1 16 250 214 137
10 -1 16 250 214 137
-5 0 16 250 214 137
7 0 16 250 214 137
-8 1 16 250 214 137
10 1 16 250 214 137
-5 2 16 250 214 137
7 2 16 250 214 137
-8 3 16 250 214 137
10 3 16 250 214 137
-5 4 16 250 214 137
7 4 16 250 214 137
-8 5 16 250 214 137
10 5 16 250 214 137
-5 6 16 250 214 137
-3 6 16 250 214 137
-1 6 16 250 214 137
1 6 16 250 214 137
3 6 16 250 214 137
5 6 16 250 214 137
7 6 16 250 214 137
-8 7 16 250 214 137
-7 7 16 250 214 137
-6 7 16 250 214 137
8 7 16 250 214 137
9 7 16 250 214 137
10 7 16 250 214 137
-8 8 16 250 214 137
-7 8 16 250 214 137
-6 8 16 250 214 137
8 8 16 250 214 137
9 8 16 250 214 137
10 8 16 250 214 137
-8 9 16 250 214 137
-7 9 16 250 214 137
-6 9 16 250 214 137
8 9 16 250 214 137
9 9 16 250 214 137
10 9 16 250 214 137
-7 10 16 250 214 137
-5 10 16 250 214 137
-3 10 16 250 214 137
-1 10 16 250 214 137
1 10 16 250 214 137
3 10 16 250 214 137
5 10 16 250 214 137
7 10 16 250 214 137
9 10 16 250 214 137
-7 -9 17 250 214 137
9 -9 17 250 214 137
-8 -8 17 250 214 137
-7 -8 17 250 214 137
-6 -8 17 250 214 137
8 -8 17 250 214 137
9 -8 17 250 214 137
10 -8 17 250 214 137
-7 -7 17 250 214 137
9 -7 17 250 214 137
-7 7 17 250 214 137
9 7 17 250 214 137
-8 8 17 250 214 137
-7 8 17 250 214 137
-6 8 17 250 214 137
8 8 17 250 214 137
9 8 17 250 214 137
10 8 17 250 214 137
-7 9 17 250 214 137
9 9 17 250 214 137
-9 -10 18 250 214 137
-8 -10 18 250 214 137
-7 -10 18 250 214 137
-6 -10 18 250 214 137
-5 -10 18 250 214 137
7 -10 18 250 214 137
8 -10 18 250 214 137
9 -10 18 250 214 137
10 -10 18 250 214 137
11 -10 18 250 214 137
-9 -9 18 250 214 137
-8 -9 18 250 214 137
-7 -9 18 250 214 137
-6 -9 18 250 214 137
-5 -9 18 250 214 137
7 -9 18 250 214 137
8 -9 18 250 214 137
9 -9 18 250 214 137
10 -9 18 250 214 137
11 -9 18 250 214 137
-9 -8 18 250 214 137
-8 -8 18 250 214 137
-7 -8 18 250 214 137
-6 -8 18 250 214 137
-5 -8 18 250 214 137
7 -8 18 250 214 137
8 -8 18 250 214 137
9 -8 18 250 214 137
10 -8 18 250 214 137
11 -8 18 250 214 137
-9 -7 18 250 214 137
-8 -7 18 250 214 137
-7 -7 18 250 214 137
-6 -7 18 250 214 137
-5 -7 18 250 214 137
7 -7 18 250 214 137
8 -7 18 250 214 137
9 -7 18 250 214 137
10 -7 18 250 214 137
11 -7 18 250 214 137
-9 -6 18 250 214 137
-8 -6 18 250 214 137
-7 -6 18 250 214 137
-6 -6 18 250 214 137
-5 -6 18 250 214 137
7 -6 18 250 214 137
8 -6 18 250 214 137
9 -6 18 250 214 137
10 -6 18 250 214 137
11 -6 18 250 214 137
-9 6 18 250 214 137
-8 6 18 250 214 137
-7 6 18 250 214 137
-6 6 18 250 214 137
-5 6 18 250 214 137
7 6 18 250 214 137
8 6 18 250 214 137
9 6 18 250 214 137
10 6 18 250 214 137
11 6 18 250 214 137
-9 7 18 250 214 137
-8 7 18 250 214 137
-7 7 18 250 214 137
-6 7 18 250 214 137
-5 7 18 250 214 137
7 7 18 250 214 137
8 7 18 250 214 137
9 7 18 250 214 137
10 7 18 250 214 137
11 7 18 250 214 137
-9 8 18 250 214 137
-8 8 18 250 214 137
-7 8 18 250 214 137
-6 8 18 250 214 137
-5 8 18 250 214 137
7 8 18 250 214 137
8 8 18 250 214 137
9 8 18 250 214 137
10 8 18 250 214 137
11 8 18 250 214 137
-9 9 18 250 214 137
-8 9 18 250 214 137
-7 9 18 250 214 137
-6 9 18 250 214 137
-5 9 18 250 214 137
7 9 18 250 214 137
8 9 18 250 214 137
9 9 18 250 214 137
10 9 18 250 214 137
11 9 18 250 214 137
-9 10 18 250 214 137
-8 10 18 250 214 137
-7 10 18 250 214 137
-6 10 18 250 214 137
-5 10 18 250 214 137
7 10 18 250 214 137
8 10 18 250 214 137
9 10 18 250 214 137
10 10 18 250 214 137
11 10 18 250 214 137
-9 -10 19 250 214 137
-8 -10 19 250 214 137
-7 -10 19 250 214 137
-6 -10 19 250 214 137
-5 -10 19 250 214 137
7 -10 19 250 214 137
8 -10 19 250 214 137
9 -10 19 250 214 137
10 -10 19 250 214 137
11 -10 19 250 214 137
-9 -9 19 250 214 137
-5 -9 19 250 214 137
7 -9 19 250 214 137
11 -9 19 250 214 137
-9 -8 19 250 214 137
-5 -8 19 250 214 137
7 -8 19 250 214 137
11 -8 19 250 214 137
-9 -7 19 250 214 137
-5 -7 19 250 214 137
7 -7 19 250 214 137
11 -7 19 250 214 137
-9 -6 19 250 214 137
-8 -6 19 250 214 137
-7 -6 19 250 214 137
-6 -6 19 250 214 137
-5 -6 19 250 214 137
7 -6 19 250 214 137
8 -6 19 250 214 137
9 -6 19 250 214 137
10 -6 19 250 214 137
11 -6 19 250 214 137
-9 6 19 250 214 137
-8 6 19 250 214 137
-7 6 19 250 214 137
-6 6 19 250 214 137
-5 6 19 250 214 137
7 6 19 250 214 137
8 6 19 250 214 137
9 6 19 250 214 137
10 6 19 250 214 137
11 6 19 250 214 137
-9 7 19 250 214 137
-5 7 19 250 214 137
7 7 19 250 214 137
11 7 19 250 214 137
-9 8 19 250 214 137
-5 8 19 250 214 137
7 8 19 250 214 137
11 8 19 250 214 137
-9 9 19 250 214 137
-5 9 19 250 214 137
7 9 19 250 214 137
11 9 19 250 214 137
-9 10 19 250 214 137
-8 10 19 250 214 137
-7 10 19 250 214 137
-6 10 19 250 214 137
-5 10 19 250 214 137
7 10 19 250 214 137
8 10 19 250 214 137
9 10 19 250 214 137
10 10 19 250 214 137
11 10 19 250 214 137
-9 -10 20 250 214 137
-7 -10 20 250 214 137
-5 -10 20 250 214 137
7 -10 20 250 214 137
9 -10 20 250 214 137
11 -10 20 250 214 137
-9 -8 20 250 214 137
-5 -8 20 250 214 137
7 -8 20 250 214 137
11 -8 20 250 214 137
-9 -6 20 250 214 137
-7 -6 20 250 214 137
-5 -6 20 250 214 137
7 -6 20 250 214 137
9 -6 20 250 214 137
11 -6 20 250 214 137
-9 6 20 250 214 137
-7 6 20 250 214 137
-5 6 20 250 214 137
7 6 20 250 214 137
9 6 20 250 214 137
11 6 20 250 214 137
-9 8 20 250 214 137
-5 8 20 250 214 137
7 8 20 250 214 137
11 8 20 250 214 137
-9 10 20 250 214 137
-7 10 20 250 214 137
-5 10 20 250 214 137
7 10 20 250 214 137
9 10 20 250 214 137
11 10 20 250 214 137
-9 -10 21 250 214 137
-8 -10 21 250 214 137
-7 -10 21 250 214 137
-6 -10 21 250 214 137
-5 -10 21 250 214 137
7 -10 21 250 214 137
8 -10 21 250 214 137
9 -10 21 250 214 137
10 -10 21 250 214 137
11 -10 21 250 214 137
-9 -9 21 250 214 137
-5 -9 21 250 214 137
7 -9 21 250 214 137
11 -9 21 250 214 137
-9 -8 21 250 214 137
-5 -8 21 250 214 137
7 -8 21 250 214 137
11 -8 21 250 214 137
-9 -7 21 250 214 137
-5 -7 21 250 214 137
7 -7 21 250 214 137
11 -7 21 250 214 137
-9 -6 21 250 214 137
-8 -6 21 250 214 137
-7 -6 21 250 214 137
-6 -6 21 250 214 137
-5 -6 21 250 214 137
7 -6 21 250 214 137
8 -6 21 250 214 137
9 -6 21 250 214 137
10 -6 21 250 214 137
11 -6 21 250 214 137
-9 6 21 250 214 137
-8 6 21 250 214 137
-7 6 21 250 214 137
-6 6 21 250 214 137
-5 6 21 250 214 137
7 6 21 250 214 137
8 6 21 250 214 137
9 6 21 250 214 137
10 6 21 250 214 137
11 6 21 250 214 137
-9 7 21 250 214 137
-5 7 21 250 214 137
7 7 21 250 214 137
11 7 21 250 214 137
-9 8 21 250 214 137
-5 8 21 250 214 137
7 8 21 250 214 137
11 8 21 250 214 137
-9 9 21 250 214 137
-5 9 21 250 214 137
7 9 21 250 214 137
11 9 21 250 214 137
-9 10 21 250 214 137
-8 10 21 250 214 137
-7 10 21 250 214 137
-6 10 21 250 214 137
-5 10 21 250 214 137
7 10 21 250 214 137
8 10 21 250 214 137
9 10 21 250 214 137
10 10 21 250 214 137
11 10 21 250 214 137
-9 -10 22 250 214 137
-7 -10 22 250 214 137
-5 -10 22 250 214 137
7 -10 22 250 214 137
9 -10 22 250 214 137
11 -10 22 250 214 137
-9 -8 22 250 214 137
-5 -8 22 250 214 137
7 -8 22 250 214 137
11 -8 22 250 214 137
-9 -6 22 250 214 137
-7 -6 22 250 214 137
-5 -6 22 250 214 137
7 -6 22 250 214 137
9 -6 22 250 214 137
11 -6 22 250 214 137
-9 6 22 250 214 137
-7 6 22 250 214 137
-5 6 22 250 214 137
7 6 22 250 214 137
9 6 22 250 214 137
11 6 22 250 214 137
-9 8 22 250 214 137
-5 8 22 250 214 137
7 8 22 250 214 137
11 8 22 250 214 137
-9 10 22 250 214 137
-7 10 22 250 214 137
-5 10 22 250 214 137
7 10 22 250 214 137
9 10 22 250 214 137
11 10 22 250 214 137
