ply
format ascii 1.0
comment : MagicaVoxel @ Ephtracy
element vertex 370
property float x
property float y
property float z
property uchar red
property uchar green
property uchar blue
end_header
-2 -5 0 100 72 24
-1 -5 0 100 72 24
0 -5 0 100 72 24
1 -5 0 100 72 24
-5 -4 0 64 64 64
-4 -4 0 64 64 64
-3 -4 0 64 64 64
-2 -4 0 64 64 64
-1 -4 0 100 72 24
0 -4 0 100 72 24
1 -4 0 64 64 64
2 -4 0 64 64 64
3 -4 0 64 64 64
4 -4 0 64 64 64
-5 -3 0 64 64 64
-4 -3 0 64 64 64
-3 -3 0 64 64 64
-2 -3 0 64 64 64
-1 -3 0 64 64 64
0 -3 0 64 64 64
1 -3 0 64 64 64
2 -3 0 64 64 64
3 -3 0 64 64 64
4 -3 0 64 64 64
-5 -2 0 64 64 64
-4 -2 0 64 64 64
-3 -2 0 64 64 64
-2 -2 0 64 64 64
-1 -2 0 64 64 64
0 -2 0 64 64 64
1 -2 0 64 64 64
2 -2 0 64 64 64
3 -2 0 64 64 64
4 -2 0 64 64 64
-5 -1 0 64 64 64
-4 -1 0 64 64 64
-3 -1 0 64 64 64
-2 -1 0 64 64 64
-1 -1 0 64 64 64
0 -1 0 64 64 64
1 -1 0 64 64 64
2 -1 0 64 64 64
3 -1 0 64 64 64
4 -1 0 64 64 64
-5 0 0 64 64 64
-4 0 0 64 64 64
-3 0 0 64 64 64
-2 0 0 64 64 64
-1 0 0 64 64 64
0 0 0 64 64 64
1 0 0 64 64 64
2 0 0 64 64 64
3 0 0 64 64 64
4 0 0 64 64 64
-5 1 0 64 64 64
-4 1 0 64 64 64
-3 1 0 64 64 64
-2 1 0 64 64 64
-1 1 0 64 64 64
0 1 0 64 64 64
1 1 0 64 64 64
2 1 0 64 64 64
3 1 0 64 64 64
4 1 0 64 64 64
-5 2 0 64 64 64
-4 2 0 64 64 64
-3 2 0 64 64 64
-2 2 0 64 64 64
-1 2 0 64 64 64
0 2 0 64 64 64
1 2 0 64 64 64
2 2 0 64 64 64
3 2 0 64 64 64
4 2 0 64 64 64
-5 3 0 64 64 64
-4 3 0 64 64 64
-3 3 0 64 64 64
-2 3 0 64 64 64
-1 3 0 64 64 64
0 3 0 64 64 64
1 3 0 64 64 64
2 3 0 64 64 64
3 3 0 64 64 64
4 3 0 64 64 64
-5 4 0 64 64 64
-4 4 0 64 64 64
-3 4 0 64 64 64
-2 4 0 64 64 64
-1 4 0 64 64 64
0 4 0 64 64 64
1 4 0 64 64 64
2 4 0 64 64 64
3 4 0 64 64 64
4 4 0 64 64 64
-4 -4 1 100 72 24
-3 -4 1 100 72 24
2 -4 1 100 72 24
3 -4 1 100 72 24
-4 -3 1 100 72 24
-3 -3 1 64 64 64
-2 -3 1 108 108 108
-1 -3 1 108 108 108
0 -3 1 68 40 0
1 -3 1 108 108 108
2 -3 1 64 64 64
3 -3 1 100 72 24
-3 -2 1 108 108 108
2 -2 1 108 108 108
-3 -1 1 108 108 108
2 -1 1 108 108 108
-3 0 1 108 108 108
2 0 1 108 108 108
-3 1 1 108 108 108
2 1 1 108 108 108
-4 2 1 100 72 24
-3 2 1 64 64 64
-2 2 1 108 108 108
-1 2 1 108 108 108
0 2 1 108 108 108
1 2 1 108 108 108
2 2 1 64 64 64
3 2 1 100 72 24
-4 3 1 100 72 24
-3 3 1 100 72 24
2 3 1 100 72 24
3 3 1 100 72 24
-4 -4 2 100 72 24
-3 -4 2 100 72 24
2 -4 2 100 72 24
3 -4 2 100 72 24
-4 -3 2 100 72 24
-3 -3 2 108 108 108
-2 -3 2 108 108 108
-1 -3 2 108 108 108
0 -3 2 68 40 0
1 -3 2 108 108 108
2 -3 2 108 108 108
3 -3 2 100 72 24
-3 -2 2 108 108 108
2 -2 2 108 108 108
-3 -1 2 108 108 108
2 -1 2 108 108 108
-3 0 2 108 108 108
2 0 2 108 108 108
-3 1 2 108 108 108
2 1 2 108 108 108
-4 2 2 100 72 24
-3 2 2 108 108 108
-2 2 2 108 108 108
-1 2 2 108 108 108
0 2 2 108 108 108
1 2 2 108 108 108
2 2 2 108 108 108
3 2 2 100 72 24
-4 3 2 100 72 24
-3 3 2 100 72 24
2 3 2 100 72 24
3 3 2 100 72 24
-4 -4 3 100 72 24
-3 -4 3 100 72 24
2 -4 3 100 72 24
3 -4 3 100 72 24
-4 -3 3 100 72 24
-3 -3 3 144 144 144
-2 -3 3 144 144 144
-1 -3 3 144 144 144
0 -3 3 144 144 144
1 -3 3 144 144 144
2 -3 3 144 144 144
3 -3 3 100 72 24
-3 -2 3 144 144 144
2 -2 3 144 144 144
-3 -1 3 144 144 144
2 -1 3 144 144 144
-3 0 3 144 144 144
2 0 3 144 144 144
-3 1 3 144 144 144
2 1 3 144 144 144
-4 2 3 100 72 24
-3 2 3 144 144 144
-2 2 3 144 144 144
-1 2 3 144 144 144
0 2 3 144 144 144
1 2 3 144 144 144
2 2 3 144 144 144
3 2 3 100 72 24
-4 3 3 100 72 24
-3 3 3 100 72 24
2 3 3 100 72 24
3 3 3 100 72 24
-4 -5 4 160 132 68
-3 -5 4 160 132 68
-2 -5 4 160 132 68
-1 -5 4 160 132 68
0 -5 4 160 132 68
1 -5 4 160 132 68
2 -5 4 160 132 68
3 -5 4 160 132 68
-4 -4 4 160 132 68
-3 -4 4 68 40 0
-2 -4 4 68 40 0
-1 -4 4 68 40 0
0 -4 4 68 40 0
1 -4 4 68 40 0
2 -4 4 68 40 0
3 -4 4 160 132 68
-4 -3 4 100 72 24
-3 -3 4 144 144 144
-2 -3 4 68 40 0
-1 -3 4 68 40 0
0 -3 4 68 40 0
1 -3 4 68 40 0
2 -3 4 144 144 144
3 -3 4 100 72 24
-4 -2 4 100 72 24
-3 -2 4 144 144 144
-2 -2 4 68 40 0
-1 -2 4 68 40 0
0 -2 4 68 40 0
1 -2 4 68 40 0
2 -2 4 144 144 144
3 -2 4 100 72 24
-4 -1 4 100 72 24
-3 -1 4 144 144 144
-2 -1 4 68 40 0
-1 -1 4 68 40 0
0 -1 4 68 40 0
1 -1 4 68 40 0
2 -1 4 144 144 144
3 -1 4 100 72 24
-4 0 4 100 72 24
-3 0 4 144 144 144
-2 0 4 68 40 0
-1 0 4 68 40 0
0 0 4 68 40 0
1 0 4 68 40 0
2 0 4 144 144 144
3 0 4 100 72 24
-4 1 4 100 72 24
-3 1 4 144 144 144
-2 1 4 68 40 0
-1 1 4 68 40 0
0 1 4 68 40 0
1 1 4 68 40 0
2 1 4 144 144 144
3 1 4 100 72 24
-4 2 4 100 72 24
-3 2 4 144 144 144
-2 2 4 68 40 0
-1 2 4 68 40 0
0 2 4 68 40 0
1 2 4 68 40 0
2 2 4 144 144 144
3 2 4 100 72 24
-4 3 4 160 132 68
-3 3 4 68 40 0
-2 3 4 68 40 0
-1 3 4 68 40 0
0 3 4 68 40 0
1 3 4 68 40 0
2 3 4 68 40 0
3 3 4 160 132 68
-4 4 4 160 132 68
-3 4 4 160 132 68
-2 4 4 160 132 68
-1 4 4 160 132 68
0 4 4 160 132 68
1 4 4 160 132 68
2 4 4 160 132 68
3 4 4 160 132 68
-4 -4 5 160 132 68
3 -4 5 160 132 68
-4 -3 5 160 132 68
-3 -3 5 68 40 0
-2 -3 5 68 40 0
-1 -3 5 68 40 0
0 -3 5 68 40 0
1 -3 5 68 40 0
2 -3 5 68 40 0
3 -3 5 160 132 68
-3 -2 5 68 40 0
-2 -2 5 68 40 0
-1 -2 5 68 40 0
0 -2 5 68 40 0
1 -2 5 68 40 0
2 -2 5 68 40 0
-3 -1 5 68 40 0
-2 -1 5 68 40 0
-1 -1 5 68 40 0
0 -1 5 68 40 0
1 -1 5 68 40 0
2 -1 5 68 40 0
-3 0 5 68 40 0
-2 0 5 68 40 0
-1 0 5 68 40 0
0 0 5 68 40 0
1 0 5 68 40 0
2 0 5 68 40 0
-3 1 5 68 40 0
-2 1 5 68 40 0
-1 1 5 68 40 0
0 1 5 68 40 0
1 1 5 68 40 0
2 1 5 68 40 0
-4 2 5 160 132 68
-3 2 5 68 40 0
-2 2 5 68 40 0
-1 2 5 68 40 0
0 2 5 68 40 0
1 2 5 68 40 0
2 2 5 68 40 0
3 2 5 160 132 68
-4 3 5 160 132 68
3 3 5 160 132 68
-4 -3 6 160 132 68
3 -3 6 160 132 68
-4 -2 6 160 132 68
-3 -2 6 68 40 0
-2 -2 6 68 40 0
-1 -2 6 68 40 0
0 -2 6 68 40 0
1 -2 6 68 40 0
2 -2 6 68 40 0
3 -2 6 160 132 68
-3 -1 6 68 40 0
-2 -1 6 68 40 0
-1 -1 6 68 40 0
0 -1 6 68 40 0
1 -1 6 68 40 0
2 -1 6 68 40 0
-3 0 6 68 40 0
-2 0 6 68 40 0
-1 0 6 68 40 0
0 0 6 68 40 0
1 0 6 68 40 0
2 0 6 68 40 0
-4 1 6 160 132 68
-3 1 6 68 40 0
-2 1 6 68 40 0
-1 1 6 68 40 0
0 1 6 68 40 0
1 1 6 68 40 0
2 1 6 68 40 0
3 1 6 160 132 68
-4 2 6 160 132 68
3 2 6 160 132 68
-4 -2 7 160 132 68
3 -2 7 160 132 68
-4 -1 7 160 132 68
-3 -1 7 68 40 0
-2 -1 7 68 40 0
-1 -1 7 68 40 0
0 -1 7 68 40 0
1 -1 7 68 40 0
2 -1 7 68 40 0
3 -1 7 160 132 68
-4 0 7 160 132 68
-3 0 7 68 40 0
-2 0 7 68 40 0
-1 0 7 68 40 0
0 0 7 68 40 0
1 0 7 68 40 0
2 0 7 68 40 0
3 0 7 160 132 68
-4 1 7 160 132 68
3 1 7 160 132 68
-4 -1 8 160 132 68
3 -1 8 160 132 68
-4 0 8 160 132 68
3 0 8 160 132 68
