ply
format ascii 1.0
comment : MagicaVoxel @ Ephtracy
element vertex 8710
property float x
property float y
property float z
property uchar red
property uchar green
property uchar blue
end_header
3 -45 -19 100 72 24
4 -45 -19 100 72 24
5 -45 -19 100 72 24
6 -45 -19 100 72 24
7 -45 -19 100 72 24
8 -45 -19 100 72 24
9 -45 -19 100 72 24
10 -45 -19 100 72 24
11 -45 -19 100 72 24
12 -45 -19 100 72 24
13 -45 -19 100 72 24
14 -45 -19 100 72 24
15 -45 -19 100 72 24
16 -45 -19 100 72 24
17 -45 -19 100 72 24
18 -45 -19 100 72 24
19 -45 -19 100 72 24
20 -45 -19 100 72 24
21 -45 -19 100 72 24
22 -45 -19 100 72 24
23 -45 -19 100 72 24
24 -45 -19 100 72 24
25 -45 -19 100 72 24
26 -45 -19 100 72 24
27 -45 -19 100 72 24
28 -45 -19 100 72 24
29 -45 -19 100 72 24
30 -45 -19 100 72 24
31 -45 -19 100 72 24
32 -45 -19 100 72 24
33 -45 -19 100 72 24
34 -45 -19 100 72 24
35 -45 -19 100 72 24
36 -45 -19 100 72 24
37 -45 -19 100 72 24
38 -45 -19 100 72 24
39 -45 -19 100 72 24
40 -45 -19 100 72 24
41 -45 -19 100 72 24
42 -45 -19 100 72 24
43 -45 -19 100 72 24
44 -45 -19 100 72 24
45 -45 -19 100 72 24
46 -45 -19 100 72 24
47 -45 -19 100 72 24
48 -45 -19 100 72 24
49 -45 -19 100 72 24
50 -45 -19 100 72 24
51 -45 -19 100 72 24
52 -45 -19 100 72 24
53 -45 -19 100 72 24
54 -45 -19 100 72 24
55 -45 -19 100 72 24
56 -45 -19 100 72 24
57 -45 -19 100 72 24
58 -45 -19 100 72 24
59 -45 -19 100 72 24
60 -45 -19 100 72 24
61 -45 -19 100 72 24
62 -45 -19 100 72 24
3 -45 -18 100 72 24
4 -45 -18 100 72 24
5 -45 -18 100 72 24
6 -45 -18 100 72 24
7 -45 -18 100 72 24
8 -45 -18 100 72 24
9 -45 -18 100 72 24
10 -45 -18 100 72 24
11 -45 -18 100 72 24
12 -45 -18 100 72 24
13 -45 -18 100 72 24
14 -45 -18 100 72 24
15 -45 -18 100 72 24
16 -45 -18 100 72 24
17 -45 -18 100 72 24
18 -45 -18 100 72 24
19 -45 -18 100 72 24
20 -45 -18 100 72 24
21 -45 -18 100 72 24
22 -45 -18 100 72 24
23 -45 -18 100 72 24
24 -45 -18 100 72 24
25 -45 -18 100 72 24
26 -45 -18 100 72 24
27 -45 -18 100 72 24
28 -45 -18 100 72 24
29 -45 -18 100 72 24
30 -45 -18 100 72 24
31 -45 -18 100 72 24
32 -45 -18 100 72 24
33 -45 -18 100 72 24
34 -45 -18 100 72 24
35 -45 -18 100 72 24
36 -45 -18 100 72 24
37 -45 -18 100 72 24
38 -45 -18 100 72 24
39 -45 -18 100 72 24
40 -45 -18 100 72 24
41 -45 -18 100 72 24
42 -45 -18 100 72 24
43 -45 -18 100 72 24
44 -45 -18 100 72 24
45 -45 -18 100 72 24
46 -45 -18 100 72 24
47 -45 -18 100 72 24
48 -45 -18 100 72 24
49 -45 -18 100 72 24
50 -45 -18 100 72 24
51 -45 -18 100 72 24
52 -45 -18 100 72 24
53 -45 -18 100 72 24
54 -45 -18 100 72 24
55 -45 -18 100 72 24
56 -45 -18 100 72 24
57 -45 -18 100 72 24
58 -45 -18 100 72 24
59 -45 -18 100 72 24
60 -45 -18 100 72 24
61 -45 -18 100 72 24
62 -45 -18 100 72 24
4 -44 -18 132 104 48
5 -44 -18 132 104 48
6 -44 -18 132 104 48
7 -44 -18 132 104 48
8 -44 -18 132 104 48
9 -44 -18 132 104 48
10 -44 -18 132 104 48
11 -44 -18 132 104 48
12 -44 -18 132 104 48
13 -44 -18 132 104 48
14 -44 -18 132 104 48
15 -44 -18 132 104 48
16 -44 -18 132 104 48
17 -44 -18 132 104 48
18 -44 -18 132 104 48
19 -44 -18 132 104 48
20 -44 -18 132 104 48
21 -44 -18 132 104 48
22 -44 -18 132 104 48
23 -44 -18 132 104 48
24 -44 -18 132 104 48
25 -44 -18 132 104 48
26 -44 -18 132 104 48
27 -44 -18 132 104 48
28 -44 -18 132 104 48
29 -44 -18 132 104 48
30 -44 -18 132 104 48
31 -44 -18 132 104 48
32 -44 -18 132 104 48
33 -44 -18 132 104 48
34 -44 -18 132 104 48
35 -44 -18 132 104 48
36 -44 -18 132 104 48
37 -44 -18 132 104 48
38 -44 -18 132 104 48
39 -44 -18 132 104 48
40 -44 -18 132 104 48
41 -44 -18 132 104 48
42 -44 -18 132 104 48
43 -44 -18 132 104 48
44 -44 -18 132 104 48
45 -44 -18 132 104 48
46 -44 -18 132 104 48
47 -44 -18 132 104 48
48 -44 -18 132 104 48
49 -44 -18 132 104 48
50 -44 -18 132 104 48
51 -44 -18 132 104 48
52 -44 -18 132 104 48
53 -44 -18 132 104 48
54 -44 -18 132 104 48
55 -44 -18 132 104 48
56 -44 -18 132 104 48
57 -44 -18 132 104 48
58 -44 -18 132 104 48
59 -44 -18 132 104 48
60 -44 -18 132 104 48
61 -44 -18 132 104 48
3 -45 -17 100 72 24
4 -45 -17 100 72 24
5 -45 -17 100 72 24
6 -45 -17 100 72 24
7 -45 -17 100 72 24
8 -45 -17 100 72 24
9 -45 -17 100 72 24
10 -45 -17 100 72 24
11 -45 -17 100 72 24
12 -45 -17 100 72 24
13 -45 -17 100 72 24
14 -45 -17 100 72 24
15 -45 -17 100 72 24
16 -45 -17 100 72 24
17 -45 -17 100 72 24
18 -45 -17 100 72 24
19 -45 -17 100 72 24
20 -45 -17 100 72 24
21 -45 -17 100 72 24
22 -45 -17 100 72 24
23 -45 -17 100 72 24
24 -45 -17 100 72 24
25 -45 -17 100 72 24
26 -45 -17 100 72 24
27 -45 -17 100 72 24
28 -45 -17 100 72 24
29 -45 -17 100 72 24
30 -45 -17 100 72 24
31 -45 -17 100 72 24
32 -45 -17 100 72 24
33 -45 -17 100 72 24
34 -45 -17 100 72 24
35 -45 -17 100 72 24
36 -45 -17 100 72 24
37 -45 -17 100 72 24
38 -45 -17 100 72 24
39 -45 -17 100 72 24
40 -45 -17 100 72 24
41 -45 -17 100 72 24
42 -45 -17 100 72 24
43 -45 -17 100 72 24
44 -45 -17 100 72 24
45 -45 -17 100 72 24
46 -45 -17 100 72 24
47 -45 -17 100 72 24
48 -45 -17 100 72 24
49 -45 -17 100 72 24
50 -45 -17 100 72 24
51 -45 -17 100 72 24
52 -45 -17 100 72 24
53 -45 -17 100 72 24
54 -45 -17 100 72 24
55 -45 -17 100 72 24
56 -45 -17 100 72 24
57 -45 -17 100 72 24
58 -45 -17 100 72 24
59 -45 -17 100 72 24
60 -45 -17 100 72 24
61 -45 -17 100 72 24
62 -45 -17 100 72 24
4 -44 -17 132 104 48
5 -44 -17 160 132 68
6 -44 -17 160 132 68
7 -44 -17 160 132 68
8 -44 -17 160 132 68
9 -44 -17 160 132 68
10 -44 -17 160 132 68
11 -44 -17 160 132 68
12 -44 -17 184 156 88
13 -44 -17 184 156 88
14 -44 -17 132 104 48
15 -44 -17 160 132 68
16 -44 -17 160 132 68
17 -44 -17 160 132 68
18 -44 -17 160 132 68
19 -44 -17 160 132 68
20 -44 -17 160 132 68
21 -44 -17 160 132 68
22 -44 -17 160 132 68
23 -44 -17 160 132 68
24 -44 -17 160 132 68
25 -44 -17 160 132 68
26 -44 -17 160 132 68
27 -44 -17 160 132 68
28 -44 -17 184 156 88
29 -44 -17 184 156 88
30 -44 -17 132 104 48
31 -44 -17 160 132 68
32 -44 -17 160 132 68
33 -44 -17 160 132 68
34 -44 -17 160 132 68
35 -44 -17 160 132 68
36 -44 -17 160 132 68
37 -44 -17 160 132 68
38 -44 -17 160 132 68
39 -44 -17 160 132 68
40 -44 -17 160 132 68
41 -44 -17 160 132 68
42 -44 -17 160 132 68
43 -44 -17 160 132 68
44 -44 -17 184 156 88
45 -44 -17 184 156 88
46 -44 -17 132 104 48
47 -44 -17 160 132 68
48 -44 -17 160 132 68
49 -44 -17 160 132 68
50 -44 -17 160 132 68
51 -44 -17 160 132 68
52 -44 -17 160 132 68
53 -44 -17 160 132 68
54 -44 -17 160 132 68
55 -44 -17 160 132 68
56 -44 -17 184 156 88
57 -44 -17 184 156 88
58 -44 -17 132 104 48
59 -44 -17 160 132 68
60 -44 -17 160 132 68
61 -44 -17 132 104 48
3 -45 -16 100 72 24
4 -45 -16 100 72 24
5 -45 -16 100 72 24
6 -45 -16 100 72 24
7 -45 -16 100 72 24
8 -45 -16 100 72 24
9 -45 -16 100 72 24
10 -45 -16 100 72 24
11 -45 -16 100 72 24
12 -45 -16 100 72 24
13 -45 -16 100 72 24
14 -45 -16 100 72 24
15 -45 -16 100 72 24
16 -45 -16 100 72 24
17 -45 -16 100 72 24
18 -45 -16 100 72 24
19 -45 -16 100 72 24
20 -45 -16 100 72 24
21 -45 -16 100 72 24
22 -45 -16 100 72 24
23 -45 -16 100 72 24
24 -45 -16 100 72 24
25 -45 -16 100 72 24
26 -45 -16 100 72 24
27 -45 -16 100 72 24
28 -45 -16 100 72 24
29 -45 -16 100 72 24
30 -45 -16 100 72 24
31 -45 -16 100 72 24
32 -45 -16 100 72 24
33 -45 -16 100 72 24
34 -45 -16 100 72 24
35 -45 -16 100 72 24
36 -45 -16 100 72 24
37 -45 -16 100 72 24
38 -45 -16 100 72 24
39 -45 -16 100 72 24
40 -45 -16 100 72 24
41 -45 -16 100 72 24
42 -45 -16 100 72 24
43 -45 -16 100 72 24
44 -45 -16 100 72 24
45 -45 -16 100 72 24
46 -45 -16 100 72 24
47 -45 -16 100 72 24
48 -45 -16 100 72 24
49 -45 -16 100 72 24
50 -45 -16 100 72 24
51 -45 -16 100 72 24
52 -45 -16 100 72 24
53 -45 -16 100 72 24
54 -45 -16 100 72 24
55 -45 -16 100 72 24
56 -45 -16 100 72 24
57 -45 -16 100 72 24
58 -45 -16 100 72 24
59 -45 -16 100 72 24
60 -45 -16 100 72 24
61 -45 -16 100 72 24
62 -45 -16 100 72 24
4 -44 -16 132 104 48
5 -44 -16 160 132 68
6 -44 -16 160 132 68
7 -44 -16 160 132 68
8 -44 -16 160 132 68
9 -44 -16 160 132 68
10 -44 -16 160 132 68
11 -44 -16 160 132 68
12 -44 -16 160 132 68
13 -44 -16 184 156 88
14 -44 -16 132 104 48
15 -44 -16 160 132 68
16 -44 -16 160 132 68
17 -44 -16 160 132 68
18 -44 -16 160 132 68
19 -44 -16 160 132 68
20 -44 -16 160 132 68
21 -44 -16 160 132 68
22 -44 -16 160 132 68
23 -44 -16 160 132 68
24 -44 -16 160 132 68
25 -44 -16 160 132 68
26 -44 -16 160 132 68
27 -44 -16 160 132 68
28 -44 -16 160 132 68
29 -44 -16 184 156 88
30 -44 -16 132 104 48
31 -44 -16 160 132 68
32 -44 -16 160 132 68
33 -44 -16 160 132 68
34 -44 -16 160 132 68
35 -44 -16 160 132 68
36 -44 -16 160 132 68
37 -44 -16 160 132 68
38 -44 -16 160 132 68
39 -44 -16 160 132 68
40 -44 -16 160 132 68
41 -44 -16 160 132 68
42 -44 -16 160 132 68
43 -44 -16 160 132 68
44 -44 -16 160 132 68
45 -44 -16 184 156 88
46 -44 -16 132 104 48
47 -44 -16 160 132 68
48 -44 -16 160 132 68
49 -44 -16 160 132 68
50 -44 -16 160 132 68
51 -44 -16 160 132 68
52 -44 -16 160 132 68
53 -44 -16 160 132 68
54 -44 -16 160 132 68
55 -44 -16 160 132 68
56 -44 -16 160 132 68
57 -44 -16 184 156 88
58 -44 -16 132 104 48
59 -44 -16 160 132 68
60 -44 -16 160 132 68
61 -44 -16 132 104 48
3 -45 -15 100 72 24
4 -45 -15 100 72 24
5 -45 -15 100 72 24
6 -45 -15 100 72 24
7 -45 -15 100 72 24
8 -45 -15 100 72 24
9 -45 -15 100 72 24
10 -45 -15 100 72 24
11 -45 -15 100 72 24
12 -45 -15 100 72 24
13 -45 -15 100 72 24
14 -45 -15 100 72 24
15 -45 -15 100 72 24
16 -45 -15 100 72 24
17 -45 -15 100 72 24
18 -45 -15 100 72 24
19 -45 -15 100 72 24
20 -45 -15 100 72 24
21 -45 -15 100 72 24
22 -45 -15 100 72 24
23 -45 -15 100 72 24
24 -45 -15 100 72 24
25 -45 -15 100 72 24
26 -45 -15 100 72 24
27 -45 -15 100 72 24
28 -45 -15 100 72 24
29 -45 -15 100 72 24
30 -45 -15 100 72 24
31 -45 -15 100 72 24
32 -45 -15 100 72 24
33 -45 -15 100 72 24
34 -45 -15 100 72 24
35 -45 -15 100 72 24
36 -45 -15 100 72 24
37 -45 -15 100 72 24
38 -45 -15 100 72 24
39 -45 -15 100 72 24
40 -45 -15 100 72 24
41 -45 -15 100 72 24
42 -45 -15 100 72 24
43 -45 -15 100 72 24
44 -45 -15 100 72 24
45 -45 -15 100 72 24
46 -45 -15 100 72 24
47 -45 -15 100 72 24
48 -45 -15 100 72 24
49 -45 -15 100 72 24
50 -45 -15 100 72 24
51 -45 -15 100 72 24
52 -45 -15 100 72 24
53 -45 -15 100 72 24
54 -45 -15 100 72 24
55 -45 -15 100 72 24
56 -45 -15 100 72 24
57 -45 -15 100 72 24
58 -45 -15 100 72 24
59 -45 -15 100 72 24
60 -45 -15 100 72 24
61 -45 -15 100 72 24
62 -45 -15 100 72 24
4 -44 -15 132 104 48
5 -44 -15 160 132 68
6 -44 -15 160 132 68
7 -44 -15 160 132 68
8 -44 -15 160 132 68
9 -44 -15 160 132 68
10 -44 -15 160 132 68
11 -44 -15 160 132 68
12 -44 -15 160 132 68
13 -44 -15 184 156 88
14 -44 -15 132 104 48
15 -44 -15 160 132 68
16 -44 -15 160 132 68
17 -44 -15 160 132 68
18 -44 -15 160 132 68
19 -44 -15 160 132 68
20 -44 -15 160 132 68
21 -44 -15 160 132 68
22 -44 -15 160 132 68
23 -44 -15 160 132 68
24 -44 -15 160 132 68
25 -44 -15 160 132 68
26 -44 -15 160 132 68
27 -44 -15 160 132 68
28 -44 -15 160 132 68
29 -44 -15 184 156 88
30 -44 -15 132 104 48
31 -44 -15 160 132 68
32 -44 -15 160 132 68
33 -44 -15 160 132 68
34 -44 -15 160 132 68
35 -44 -15 160 132 68
36 -44 -15 160 132 68
37 -44 -15 160 132 68
38 -44 -15 160 132 68
39 -44 -15 160 132 68
40 -44 -15 160 132 68
41 -44 -15 160 132 68
42 -44 -15 160 132 68
43 -44 -15 160 132 68
44 -44 -15 160 132 68
45 -44 -15 184 156 88
46 -44 -15 132 104 48
47 -44 -15 160 132 68
48 -44 -15 160 132 68
49 -44 -15 160 132 68
50 -44 -15 160 132 68
51 -44 -15 160 132 68
52 -44 -15 160 132 68
53 -44 -15 160 132 68
54 -44 -15 160 132 68
55 -44 -15 160 132 68
56 -44 -15 160 132 68
57 -44 -15 184 156 88
58 -44 -15 132 104 48
59 -44 -15 160 132 68
60 -44 -15 160 132 68
61 -44 -15 132 104 48
3 -45 -14 100 72 24
4 -45 -14 100 72 24
5 -45 -14 100 72 24
6 -45 -14 100 72 24
7 -45 -14 100 72 24
8 -45 -14 100 72 24
9 -45 -14 100 72 24
10 -45 -14 100 72 24
11 -45 -14 100 72 24
12 -45 -14 100 72 24
13 -45 -14 100 72 24
14 -45 -14 100 72 24
15 -45 -14 100 72 24
16 -45 -14 100 72 24
17 -45 -14 100 72 24
18 -45 -14 100 72 24
19 -45 -14 100 72 24
20 -45 -14 100 72 24
21 -45 -14 100 72 24
22 -45 -14 100 72 24
23 -45 -14 100 72 24
24 -45 -14 100 72 24
25 -45 -14 100 72 24
26 -45 -14 100 72 24
27 -45 -14 100 72 24
28 -45 -14 100 72 24
29 -45 -14 100 72 24
30 -45 -14 100 72 24
31 -45 -14 100 72 24
32 -45 -14 100 72 24
33 -45 -14 100 72 24
34 -45 -14 100 72 24
35 -45 -14 100 72 24
36 -45 -14 100 72 24
37 -45 -14 100 72 24
38 -45 -14 100 72 24
39 -45 -14 100 72 24
40 -45 -14 100 72 24
41 -45 -14 100 72 24
42 -45 -14 100 72 24
43 -45 -14 100 72 24
44 -45 -14 100 72 24
45 -45 -14 100 72 24
46 -45 -14 100 72 24
47 -45 -14 100 72 24
48 -45 -14 100 72 24
49 -45 -14 100 72 24
50 -45 -14 100 72 24
51 -45 -14 100 72 24
52 -45 -14 100 72 24
53 -45 -14 100 72 24
54 -45 -14 100 72 24
55 -45 -14 100 72 24
56 -45 -14 100 72 24
57 -45 -14 100 72 24
58 -45 -14 100 72 24
59 -45 -14 100 72 24
60 -45 -14 100 72 24
61 -45 -14 100 72 24
62 -45 -14 100 72 24
4 -44 -14 132 104 48
5 -44 -14 132 104 48
6 -44 -14 132 104 48
7 -44 -14 132 104 48
8 -44 -14 132 104 48
9 -44 -14 132 104 48
10 -44 -14 132 104 48
11 -44 -14 132 104 48
12 -44 -14 132 104 48
13 -44 -14 132 104 48
14 -44 -14 132 104 48
15 -44 -14 132 104 48
16 -44 -14 132 104 48
17 -44 -14 132 104 48
18 -44 -14 132 104 48
19 -44 -14 132 104 48
20 -44 -14 132 104 48
21 -44 -14 132 104 48
22 -44 -14 132 104 48
23 -44 -14 132 104 48
24 -44 -14 132 104 48
25 -44 -14 132 104 48
26 -44 -14 132 104 48
27 -44 -14 132 104 48
28 -44 -14 132 104 48
29 -44 -14 132 104 48
30 -44 -14 132 104 48
31 -44 -14 132 104 48
32 -44 -14 132 104 48
33 -44 -14 132 104 48
34 -44 -14 132 104 48
35 -44 -14 132 104 48
36 -44 -14 132 104 48
37 -44 -14 132 104 48
38 -44 -14 132 104 48
39 -44 -14 132 104 48
40 -44 -14 132 104 48
41 -44 -14 132 104 48
42 -44 -14 132 104 48
43 -44 -14 132 104 48
44 -44 -14 132 104 48
45 -44 -14 132 104 48
46 -44 -14 132 104 48
47 -44 -14 132 104 48
48 -44 -14 132 104 48
49 -44 -14 132 104 48
50 -44 -14 132 104 48
51 -44 -14 132 104 48
52 -44 -14 132 104 48
53 -44 -14 132 104 48
54 -44 -14 132 104 48
55 -44 -14 132 104 48
56 -44 -14 132 104 48
57 -44 -14 132 104 48
58 -44 -14 132 104 48
59 -44 -14 132 104 48
60 -44 -14 132 104 48
61 -44 -14 132 104 48
3 -45 -13 100 72 24
4 -45 -13 100 72 24
5 -45 -13 100 72 24
6 -45 -13 100 72 24
7 -45 -13 100 72 24
8 -45 -13 100 72 24
9 -45 -13 100 72 24
10 -45 -13 100 72 24
11 -45 -13 100 72 24
12 -45 -13 100 72 24
13 -45 -13 100 72 24
14 -45 -13 100 72 24
15 -45 -13 100 72 24
16 -45 -13 100 72 24
17 -45 -13 100 72 24
18 -45 -13 100 72 24
19 -45 -13 100 72 24
20 -45 -13 100 72 24
21 -45 -13 100 72 24
22 -45 -13 100 72 24
23 -45 -13 100 72 24
24 -45 -13 100 72 24
25 -45 -13 100 72 24
26 -45 -13 100 72 24
27 -45 -13 100 72 24
28 -45 -13 100 72 24
29 -45 -13 100 72 24
30 -45 -13 100 72 24
31 -45 -13 100 72 24
32 -45 -13 100 72 24
33 -45 -13 100 72 24
34 -45 -13 100 72 24
35 -45 -13 100 72 24
36 -45 -13 100 72 24
37 -45 -13 100 72 24
38 -45 -13 100 72 24
39 -45 -13 100 72 24
40 -45 -13 100 72 24
41 -45 -13 100 72 24
42 -45 -13 100 72 24
43 -45 -13 100 72 24
44 -45 -13 100 72 24
45 -45 -13 100 72 24
46 -45 -13 100 72 24
47 -45 -13 100 72 24
48 -45 -13 100 72 24
49 -45 -13 100 72 24
50 -45 -13 100 72 24
51 -45 -13 100 72 24
52 -45 -13 100 72 24
53 -45 -13 100 72 24
54 -45 -13 100 72 24
55 -45 -13 100 72 24
56 -45 -13 100 72 24
57 -45 -13 100 72 24
58 -45 -13 100 72 24
59 -45 -13 100 72 24
60 -45 -13 100 72 24
61 -45 -13 100 72 24
62 -45 -13 100 72 24
4 -44 -13 132 104 48
5 -44 -13 160 132 68
6 -44 -13 160 132 68
7 -44 -13 160 132 68
8 -44 -13 160 132 68
9 -44 -13 184 156 88
10 -44 -13 184 156 88
11 -44 -13 132 104 48
12 -44 -13 160 132 68
13 -44 -13 160 132 68
14 -44 -13 160 132 68
15 -44 -13 160 132 68
16 -44 -13 160 132 68
17 -44 -13 160 132 68
18 -44 -13 160 132 68
19 -44 -13 160 132 68
20 -44 -13 160 132 68
21 -44 -13 160 132 68
22 -44 -13 160 132 68
23 -44 -13 160 132 68
24 -44 -13 160 132 68
25 -44 -13 184 156 88
26 -44 -13 184 156 88
27 -44 -13 132 104 48
28 -44 -13 160 132 68
29 -44 -13 160 132 68
30 -44 -13 160 132 68
31 -44 -13 160 132 68
32 -44 -13 160 132 68
33 -44 -13 160 132 68
34 -44 -13 160 132 68
35 -44 -13 160 132 68
36 -44 -13 160 132 68
37 -44 -13 160 132 68
38 -44 -13 160 132 68
39 -44 -13 160 132 68
40 -44 -13 160 132 68
41 -44 -13 184 156 88
42 -44 -13 184 156 88
43 -44 -13 132 104 48
44 -44 -13 160 132 68
45 -44 -13 160 132 68
46 -44 -13 160 132 68
47 -44 -13 160 132 68
48 -44 -13 160 132 68
49 -44 -13 160 132 68
50 -44 -13 160 132 68
51 -44 -13 160 132 68
52 -44 -13 160 132 68
53 -44 -13 184 156 88
54 -44 -13 184 156 88
55 -44 -13 132 104 48
56 -44 -13 160 132 68
57 -44 -13 160 132 68
58 -44 -13 160 132 68
59 -44 -13 160 132 68
60 -44 -13 160 132 68
61 -44 -13 132 104 48
3 -45 -12 100 72 24
4 -45 -12 100 72 24
5 -45 -12 100 72 24
6 -45 -12 100 72 24
7 -45 -12 100 72 24
8 -45 -12 100 72 24
9 -45 -12 100 72 24
10 -45 -12 100 72 24
11 -45 -12 100 72 24
12 -45 -12 100 72 24
13 -45 -12 100 72 24
14 -45 -12 100 72 24
15 -45 -12 100 72 24
16 -45 -12 100 72 24
17 -45 -12 100 72 24
18 -45 -12 100 72 24
19 -45 -12 100 72 24
20 -45 -12 100 72 24
21 -45 -12 100 72 24
22 -45 -12 100 72 24
23 -45 -12 100 72 24
24 -45 -12 100 72 24
25 -45 -12 100 72 24
26 -45 -12 100 72 24
27 -45 -12 100 72 24
28 -45 -12 100 72 24
29 -45 -12 100 72 24
30 -45 -12 100 72 24
31 -45 -12 100 72 24
32 -45 -12 100 72 24
33 -45 -12 100 72 24
34 -45 -12 100 72 24
35 -45 -12 100 72 24
36 -45 -12 100 72 24
37 -45 -12 100 72 24
38 -45 -12 100 72 24
39 -45 -12 100 72 24
40 -45 -12 100 72 24
41 -45 -12 100 72 24
42 -45 -12 100 72 24
43 -45 -12 100 72 24
44 -45 -12 100 72 24
45 -45 -12 100 72 24
46 -45 -12 100 72 24
47 -45 -12 100 72 24
48 -45 -12 100 72 24
49 -45 -12 100 72 24
50 -45 -12 100 72 24
51 -45 -12 100 72 24
52 -45 -12 100 72 24
53 -45 -12 100 72 24
54 -45 -12 100 72 24
55 -45 -12 100 72 24
56 -45 -12 100 72 24
57 -45 -12 100 72 24
58 -45 -12 100 72 24
59 -45 -12 100 72 24
60 -45 -12 100 72 24
61 -45 -12 100 72 24
62 -45 -12 100 72 24
4 -44 -12 132 104 48
5 -44 -12 160 132 68
6 -44 -12 160 132 68
7 -44 -12 160 132 68
8 -44 -12 160 132 68
9 -44 -12 160 132 68
10 -44 -12 184 156 88
11 -44 -12 132 104 48
12 -44 -12 160 132 68
13 -44 -12 160 132 68
14 -44 -12 160 132 68
15 -44 -12 160 132 68
16 -44 -12 160 132 68
17 -44 -12 160 132 68
18 -44 -12 160 132 68
19 -44 -12 160 132 68
20 -44 -12 160 132 68
21 -44 -12 160 132 68
22 -44 -12 160 132 68
23 -44 -12 160 132 68
24 -44 -12 160 132 68
25 -44 -12 160 132 68
26 -44 -12 184 156 88
27 -44 -12 132 104 48
28 -44 -12 160 132 68
29 -44 -12 160 132 68
30 -44 -12 160 132 68
31 -44 -12 160 132 68
32 -44 -12 160 132 68
33 -44 -12 160 132 68
34 -44 -12 160 132 68
35 -44 -12 160 132 68
36 -44 -12 160 132 68
37 -44 -12 160 132 68
38 -44 -12 160 132 68
39 -44 -12 160 132 68
40 -44 -12 160 132 68
41 -44 -12 160 132 68
42 -44 -12 184 156 88
43 -44 -12 132 104 48
44 -44 -12 160 132 68
45 -44 -12 160 132 68
46 -44 -12 160 132 68
47 -44 -12 160 132 68
48 -44 -12 160 132 68
49 -44 -12 160 132 68
50 -44 -12 160 132 68
51 -44 -12 160 132 68
52 -44 -12 160 132 68
53 -44 -12 160 132 68
54 -44 -12 184 156 88
55 -44 -12 132 104 48
56 -44 -12 160 132 68
57 -44 -12 160 132 68
58 -44 -12 160 132 68
59 -44 -12 160 132 68
60 -44 -12 160 132 68
61 -44 -12 132 104 48
3 -45 -11 100 72 24
4 -45 -11 100 72 24
5 -45 -11 100 72 24
6 -45 -11 100 72 24
7 -45 -11 100 72 24
8 -45 -11 100 72 24
9 -45 -11 100 72 24
10 -45 -11 100 72 24
11 -45 -11 100 72 24
12 -45 -11 100 72 24
13 -45 -11 100 72 24
14 -45 -11 100 72 24
15 -45 -11 100 72 24
16 -45 -11 100 72 24
17 -45 -11 100 72 24
18 -45 -11 100 72 24
19 -45 -11 100 72 24
20 -45 -11 100 72 24
21 -45 -11 100 72 24
22 -45 -11 100 72 24
23 -45 -11 100 72 24
24 -45 -11 100 72 24
25 -45 -11 100 72 24
26 -45 -11 100 72 24
27 -45 -11 100 72 24
28 -45 -11 100 72 24
29 -45 -11 100 72 24
30 -45 -11 100 72 24
31 -45 -11 100 72 24
32 -45 -11 100 72 24
33 -45 -11 100 72 24
34 -45 -11 100 72 24
35 -45 -11 100 72 24
36 -45 -11 100 72 24
37 -45 -11 100 72 24
38 -45 -11 100 72 24
39 -45 -11 100 72 24
40 -45 -11 100 72 24
41 -45 -11 100 72 24
42 -45 -11 100 72 24
43 -45 -11 100 72 24
44 -45 -11 100 72 24
45 -45 -11 100 72 24
46 -45 -11 100 72 24
47 -45 -11 100 72 24
48 -45 -11 100 72 24
49 -45 -11 100 72 24
50 -45 -11 100 72 24
51 -45 -11 100 72 24
52 -45 -11 100 72 24
53 -45 -11 100 72 24
54 -45 -11 100 72 24
55 -45 -11 100 72 24
56 -45 -11 100 72 24
57 -45 -11 100 72 24
58 -45 -11 100 72 24
59 -45 -11 100 72 24
60 -45 -11 100 72 24
61 -45 -11 100 72 24
62 -45 -11 100 72 24
4 -44 -11 132 104 48
5 -44 -11 160 132 68
6 -44 -11 160 132 68
7 -44 -11 160 132 68
8 -44 -11 160 132 68
9 -44 -11 160 132 68
10 -44 -11 184 156 88
11 -44 -11 132 104 48
12 -44 -11 160 132 68
13 -44 -11 160 132 68
14 -44 -11 160 132 68
15 -44 -11 160 132 68
16 -44 -11 160 132 68
17 -44 -11 160 132 68
18 -44 -11 160 132 68
19 -44 -11 160 132 68
20 -44 -11 160 132 68
21 -44 -11 160 132 68
22 -44 -11 160 132 68
23 -44 -11 160 132 68
24 -44 -11 160 132 68
25 -44 -11 160 132 68
26 -44 -11 184 156 88
27 -44 -11 132 104 48
28 -44 -11 160 132 68
29 -44 -11 160 132 68
30 -44 -11 160 132 68
31 -44 -11 160 132 68
32 -44 -11 160 132 68
33 -44 -11 160 132 68
34 -44 -11 160 132 68
35 -44 -11 160 132 68
36 -44 -11 160 132 68
37 -44 -11 160 132 68
38 -44 -11 160 132 68
39 -44 -11 160 132 68
40 -44 -11 160 132 68
41 -44 -11 160 132 68
42 -44 -11 184 156 88
43 -44 -11 132 104 48
44 -44 -11 160 132 68
45 -44 -11 160 132 68
46 -44 -11 160 132 68
47 -44 -11 160 132 68
48 -44 -11 160 132 68
49 -44 -11 160 132 68
50 -44 -11 160 132 68
51 -44 -11 160 132 68
52 -44 -11 160 132 68
53 -44 -11 160 132 68
54 -44 -11 184 156 88
55 -44 -11 132 104 48
56 -44 -11 160 132 68
57 -44 -11 160 132 68
58 -44 -11 160 132 68
59 -44 -11 160 132 68
60 -44 -11 160 132 68
61 -44 -11 132 104 48
3 -45 -10 100 72 24
4 -45 -10 100 72 24
5 -45 -10 100 72 24
6 -45 -10 100 72 24
7 -45 -10 100 72 24
8 -45 -10 100 72 24
9 -45 -10 100 72 24
10 -45 -10 100 72 24
11 -45 -10 100 72 24
12 -45 -10 100 72 24
13 -45 -10 100 72 24
14 -45 -10 100 72 24
15 -45 -10 100 72 24
16 -45 -10 100 72 24
17 -45 -10 100 72 24
18 -45 -10 100 72 24
19 -45 -10 100 72 24
20 -45 -10 100 72 24
21 -45 -10 100 72 24
22 -45 -10 100 72 24
23 -45 -10 100 72 24
24 -45 -10 100 72 24
25 -45 -10 100 72 24
26 -45 -10 100 72 24
27 -45 -10 100 72 24
28 -45 -10 100 72 24
29 -45 -10 100 72 24
30 -45 -10 100 72 24
31 -45 -10 100 72 24
32 -45 -10 100 72 24
33 -45 -10 100 72 24
34 -45 -10 100 72 24
35 -45 -10 100 72 24
36 -45 -10 100 72 24
37 -45 -10 100 72 24
38 -45 -10 100 72 24
39 -45 -10 100 72 24
40 -45 -10 100 72 24
41 -45 -10 100 72 24
42 -45 -10 100 72 24
43 -45 -10 100 72 24
44 -45 -10 100 72 24
45 -45 -10 100 72 24
46 -45 -10 100 72 24
47 -45 -10 100 72 24
48 -45 -10 100 72 24
49 -45 -10 100 72 24
50 -45 -10 100 72 24
51 -45 -10 100 72 24
52 -45 -10 100 72 24
53 -45 -10 100 72 24
54 -45 -10 100 72 24
55 -45 -10 100 72 24
56 -45 -10 100 72 24
57 -45 -10 100 72 24
58 -45 -10 100 72 24
59 -45 -10 100 72 24
60 -45 -10 100 72 24
61 -45 -10 100 72 24
62 -45 -10 100 72 24
4 -44 -10 132 104 48
5 -44 -10 132 104 48
6 -44 -10 132 104 48
7 -44 -10 132 104 48
8 -44 -10 132 104 48
9 -44 -10 132 104 48
10 -44 -10 132 104 48
11 -44 -10 132 104 48
12 -44 -10 132 104 48
13 -44 -10 132 104 48
14 -44 -10 132 104 48
15 -44 -10 132 104 48
16 -44 -10 132 104 48
17 -44 -10 132 104 48
18 -44 -10 132 104 48
19 -44 -10 132 104 48
20 -44 -10 132 104 48
21 -44 -10 132 104 48
22 -44 -10 132 104 48
23 -44 -10 132 104 48
24 -44 -10 132 104 48
25 -44 -10 132 104 48
26 -44 -10 132 104 48
27 -44 -10 132 104 48
28 -44 -10 132 104 48
29 -44 -10 132 104 48
30 -44 -10 132 104 48
31 -44 -10 132 104 48
32 -44 -10 132 104 48
33 -44 -10 132 104 48
34 -44 -10 132 104 48
35 -44 -10 132 104 48
36 -44 -10 132 104 48
37 -44 -10 132 104 48
38 -44 -10 132 104 48
39 -44 -10 132 104 48
40 -44 -10 132 104 48
41 -44 -10 132 104 48
42 -44 -10 132 104 48
43 -44 -10 132 104 48
44 -44 -10 132 104 48
45 -44 -10 132 104 48
46 -44 -10 132 104 48
47 -44 -10 132 104 48
48 -44 -10 132 104 48
49 -44 -10 132 104 48
50 -44 -10 132 104 48
51 -44 -10 132 104 48
52 -44 -10 132 104 48
53 -44 -10 132 104 48
54 -44 -10 132 104 48
55 -44 -10 132 104 48
56 -44 -10 132 104 48
57 -44 -10 132 104 48
58 -44 -10 132 104 48
59 -44 -10 132 104 48
60 -44 -10 132 104 48
61 -44 -10 132 104 48
3 -45 -9 100 72 24
4 -45 -9 100 72 24
5 -45 -9 100 72 24
6 -45 -9 100 72 24
7 -45 -9 100 72 24
8 -45 -9 100 72 24
9 -45 -9 100 72 24
10 -45 -9 100 72 24
11 -45 -9 100 72 24
12 -45 -9 100 72 24
13 -45 -9 100 72 24
14 -45 -9 100 72 24
15 -45 -9 100 72 24
16 -45 -9 100 72 24
17 -45 -9 100 72 24
18 -45 -9 100 72 24
19 -45 -9 100 72 24
20 -45 -9 100 72 24
21 -45 -9 100 72 24
22 -45 -9 100 72 24
23 -45 -9 100 72 24
24 -45 -9 100 72 24
25 -45 -9 100 72 24
26 -45 -9 100 72 24
27 -45 -9 100 72 24
28 -45 -9 100 72 24
29 -45 -9 100 72 24
30 -45 -9 100 72 24
31 -45 -9 100 72 24
32 -45 -9 100 72 24
33 -45 -9 100 72 24
34 -45 -9 100 72 24
35 -45 -9 100 72 24
36 -45 -9 100 72 24
37 -45 -9 100 72 24
38 -45 -9 100 72 24
39 -45 -9 100 72 24
40 -45 -9 100 72 24
41 -45 -9 100 72 24
42 -45 -9 100 72 24
43 -45 -9 100 72 24
44 -45 -9 100 72 24
45 -45 -9 100 72 24
46 -45 -9 100 72 24
47 -45 -9 100 72 24
48 -45 -9 100 72 24
49 -45 -9 100 72 24
50 -45 -9 100 72 24
51 -45 -9 100 72 24
52 -45 -9 100 72 24
53 -45 -9 100 72 24
54 -45 -9 100 72 24
55 -45 -9 100 72 24
56 -45 -9 100 72 24
57 -45 -9 100 72 24
58 -45 -9 100 72 24
59 -45 -9 100 72 24
60 -45 -9 100 72 24
61 -45 -9 100 72 24
62 -45 -9 100 72 24
4 -44 -9 132 104 48
5 -44 -9 184 156 88
6 -44 -9 132 104 48
7 -44 -9 160 132 68
8 -44 -9 160 132 68
9 -44 -9 160 132 68
10 -44 -9 160 132 68
11 -44 -9 160 132 68
12 -44 -9 160 132 68
13 -44 -9 160 132 68
14 -44 -9 160 132 68
15 -44 -9 160 132 68
16 -44 -9 160 132 68
17 -44 -9 160 132 68
18 -44 -9 160 132 68
19 -44 -9 160 132 68
20 -44 -9 184 156 88
21 -44 -9 184 156 88
22 -44 -9 132 104 48
23 -44 -9 160 132 68
24 -44 -9 160 132 68
25 -44 -9 160 132 68
26 -44 -9 160 132 68
27 -44 -9 160 132 68
28 -44 -9 160 132 68
29 -44 -9 160 132 68
30 -44 -9 160 132 68
31 -44 -9 160 132 68
32 -44 -9 160 132 68
33 -44 -9 160 132 68
34 -44 -9 160 132 68
35 -44 -9 160 132 68
36 -44 -9 184 156 88
37 -44 -9 184 156 88
38 -44 -9 132 104 48
39 -44 -9 160 132 68
40 -44 -9 160 132 68
41 -44 -9 160 132 68
42 -44 -9 160 132 68
43 -44 -9 160 132 68
44 -44 -9 160 132 68
45 -44 -9 160 132 68
46 -44 -9 160 132 68
47 -44 -9 160 132 68
48 -44 -9 184 156 88
49 -44 -9 184 156 88
50 -44 -9 132 104 48
51 -44 -9 160 132 68
52 -44 -9 160 132 68
53 -44 -9 160 132 68
54 -44 -9 160 132 68
55 -44 -9 160 132 68
56 -44 -9 160 132 68
57 -44 -9 160 132 68
58 -44 -9 160 132 68
59 -44 -9 160 132 68
60 -44 -9 160 132 68
61 -44 -9 132 104 48
3 -45 -8 100 72 24
4 -45 -8 100 72 24
5 -45 -8 100 72 24
6 -45 -8 100 72 24
7 -45 -8 100 72 24
8 -45 -8 100 72 24
9 -45 -8 100 72 24
10 -45 -8 100 72 24
11 -45 -8 100 72 24
12 -45 -8 100 72 24
13 -45 -8 100 72 24
14 -45 -8 100 72 24
15 -45 -8 100 72 24
16 -45 -8 100 72 24
17 -45 -8 100 72 24
18 -45 -8 100 72 24
19 -45 -8 100 72 24
20 -45 -8 100 72 24
21 -45 -8 100 72 24
22 -45 -8 100 72 24
23 -45 -8 100 72 24
24 -45 -8 100 72 24
25 -45 -8 100 72 24
26 -45 -8 100 72 24
27 -45 -8 100 72 24
28 -45 -8 100 72 24
29 -45 -8 100 72 24
30 -45 -8 100 72 24
31 -45 -8 100 72 24
32 -45 -8 100 72 24
33 -45 -8 100 72 24
34 -45 -8 100 72 24
35 -45 -8 100 72 24
36 -45 -8 100 72 24
37 -45 -8 100 72 24
38 -45 -8 100 72 24
39 -45 -8 100 72 24
40 -45 -8 100 72 24
41 -45 -8 100 72 24
42 -45 -8 100 72 24
43 -45 -8 100 72 24
44 -45 -8 100 72 24
45 -45 -8 100 72 24
46 -45 -8 100 72 24
47 -45 -8 100 72 24
48 -45 -8 100 72 24
49 -45 -8 100 72 24
50 -45 -8 100 72 24
51 -45 -8 100 72 24
52 -45 -8 100 72 24
53 -45 -8 100 72 24
54 -45 -8 100 72 24
55 -45 -8 100 72 24
56 -45 -8 100 72 24
57 -45 -8 100 72 24
58 -45 -8 100 72 24
59 -45 -8 100 72 24
60 -45 -8 100 72 24
61 -45 -8 100 72 24
62 -45 -8 100 72 24
4 -44 -8 132 104 48
5 -44 -8 184 156 88
6 -44 -8 132 104 48
7 -44 -8 160 132 68
8 -44 -8 160 132 68
9 -44 -8 160 132 68
10 -44 -8 160 132 68
11 -44 -8 160 132 68
12 -44 -8 160 132 68
13 -44 -8 160 132 68
14 -44 -8 160 132 68
15 -44 -8 160 132 68
16 -44 -8 160 132 68
17 -44 -8 160 132 68
18 -44 -8 160 132 68
19 -44 -8 160 132 68
20 -44 -8 160 132 68
21 -44 -8 184 156 88
22 -44 -8 132 104 48
23 -44 -8 160 132 68
24 -44 -8 160 132 68
25 -44 -8 160 132 68
26 -44 -8 160 132 68
27 -44 -8 160 132 68
28 -44 -8 160 132 68
29 -44 -8 160 132 68
30 -44 -8 160 132 68
31 -44 -8 160 132 68
32 -44 -8 160 132 68
33 -44 -8 160 132 68
34 -44 -8 160 132 68
35 -44 -8 160 132 68
36 -44 -8 160 132 68
37 -44 -8 184 156 88
38 -44 -8 132 104 48
39 -44 -8 160 132 68
40 -44 -8 160 132 68
41 -44 -8 160 132 68
42 -44 -8 160 132 68
43 -44 -8 160 132 68
44 -44 -8 160 132 68
45 -44 -8 160 132 68
46 -44 -8 160 132 68
47 -44 -8 160 132 68
48 -44 -8 160 132 68
49 -44 -8 184 156 88
50 -44 -8 132 104 48
51 -44 -8 160 132 68
52 -44 -8 160 132 68
53 -44 -8 160 132 68
54 -44 -8 160 132 68
55 -44 -8 160 132 68
56 -44 -8 160 132 68
57 -44 -8 160 132 68
58 -44 -8 160 132 68
59 -44 -8 160 132 68
60 -44 -8 160 132 68
61 -44 -8 132 104 48
3 -45 -7 100 72 24
4 -45 -7 100 72 24
5 -45 -7 100 72 24
6 -45 -7 100 72 24
7 -45 -7 100 72 24
8 -45 -7 100 72 24
9 -45 -7 100 72 24
10 -45 -7 100 72 24
11 -45 -7 100 72 24
12 -45 -7 100 72 24
13 -45 -7 100 72 24
14 -45 -7 100 72 24
15 -45 -7 100 72 24
16 -45 -7 100 72 24
17 -45 -7 100 72 24
18 -45 -7 100 72 24
19 -45 -7 100 72 24
20 -45 -7 100 72 24
21 -45 -7 100 72 24
22 -45 -7 100 72 24
23 -45 -7 100 72 24
24 -45 -7 100 72 24
25 -45 -7 100 72 24
26 -45 -7 100 72 24
27 -45 -7 100 72 24
28 -45 -7 100 72 24
29 -45 -7 100 72 24
30 -45 -7 100 72 24
31 -45 -7 100 72 24
32 -45 -7 100 72 24
33 -45 -7 100 72 24
34 -45 -7 100 72 24
35 -45 -7 100 72 24
36 -45 -7 100 72 24
37 -45 -7 100 72 24
38 -45 -7 100 72 24
39 -45 -7 100 72 24
40 -45 -7 100 72 24
41 -45 -7 100 72 24
42 -45 -7 100 72 24
43 -45 -7 100 72 24
44 -45 -7 100 72 24
45 -45 -7 100 72 24
46 -45 -7 100 72 24
47 -45 -7 100 72 24
48 -45 -7 100 72 24
49 -45 -7 100 72 24
50 -45 -7 100 72 24
51 -45 -7 100 72 24
52 -45 -7 100 72 24
53 -45 -7 100 72 24
54 -45 -7 100 72 24
55 -45 -7 100 72 24
56 -45 -7 100 72 24
57 -45 -7 100 72 24
58 -45 -7 100 72 24
59 -45 -7 100 72 24
60 -45 -7 100 72 24
61 -45 -7 100 72 24
62 -45 -7 100 72 24
4 -44 -7 132 104 48
5 -44 -7 184 156 88
6 -44 -7 132 104 48
7 -44 -7 160 132 68
8 -44 -7 160 132 68
9 -44 -7 160 132 68
10 -44 -7 160 132 68
11 -44 -7 160 132 68
12 -44 -7 160 132 68
13 -44 -7 160 132 68
14 -44 -7 160 132 68
15 -44 -7 160 132 68
16 -44 -7 160 132 68
17 -44 -7 160 132 68
18 -44 -7 160 132 68
19 -44 -7 160 132 68
20 -44 -7 160 132 68
21 -44 -7 184 156 88
22 -44 -7 132 104 48
23 -44 -7 160 132 68
24 -44 -7 160 132 68
25 -44 -7 160 132 68
26 -44 -7 160 132 68
27 -44 -7 160 132 68
28 -44 -7 160 132 68
29 -44 -7 160 132 68
30 -44 -7 160 132 68
31 -44 -7 160 132 68
32 -44 -7 160 132 68
33 -44 -7 160 132 68
34 -44 -7 160 132 68
35 -44 -7 160 132 68
36 -44 -7 160 132 68
37 -44 -7 184 156 88
38 -44 -7 132 104 48
39 -44 -7 160 132 68
40 -44 -7 160 132 68
41 -44 -7 160 132 68
42 -44 -7 160 132 68
43 -44 -7 160 132 68
44 -44 -7 160 132 68
45 -44 -7 160 132 68
46 -44 -7 160 132 68
47 -44 -7 160 132 68
48 -44 -7 160 132 68
49 -44 -7 184 156 88
50 -44 -7 132 104 48
51 -44 -7 160 132 68
52 -44 -7 160 132 68
53 -44 -7 160 132 68
54 -44 -7 160 132 68
55 -44 -7 160 132 68
56 -44 -7 160 132 68
57 -44 -7 160 132 68
58 -44 -7 160 132 68
59 -44 -7 160 132 68
60 -44 -7 160 132 68
61 -44 -7 132 104 48
3 -45 -6 100 72 24
4 -45 -6 100 72 24
5 -45 -6 100 72 24
6 -45 -6 100 72 24
7 -45 -6 100 72 24
8 -45 -6 100 72 24
9 -45 -6 100 72 24
10 -45 -6 100 72 24
11 -45 -6 100 72 24
12 -45 -6 100 72 24
13 -45 -6 100 72 24
14 -45 -6 100 72 24
15 -45 -6 100 72 24
16 -45 -6 100 72 24
17 -45 -6 100 72 24
18 -45 -6 100 72 24
19 -45 -6 100 72 24
20 -45 -6 100 72 24
21 -45 -6 100 72 24
22 -45 -6 100 72 24
23 -45 -6 100 72 24
24 -45 -6 100 72 24
25 -45 -6 100 72 24
26 -45 -6 100 72 24
27 -45 -6 100 72 24
28 -45 -6 100 72 24
29 -45 -6 100 72 24
30 -45 -6 100 72 24
31 -45 -6 100 72 24
32 -45 -6 100 72 24
33 -45 -6 100 72 24
34 -45 -6 100 72 24
35 -45 -6 100 72 24
36 -45 -6 100 72 24
37 -45 -6 100 72 24
38 -45 -6 100 72 24
39 -45 -6 100 72 24
40 -45 -6 100 72 24
41 -45 -6 100 72 24
42 -45 -6 100 72 24
43 -45 -6 100 72 24
44 -45 -6 100 72 24
45 -45 -6 100 72 24
46 -45 -6 100 72 24
47 -45 -6 100 72 24
48 -45 -6 100 72 24
49 -45 -6 100 72 24
50 -45 -6 100 72 24
51 -45 -6 100 72 24
52 -45 -6 100 72 24
53 -45 -6 100 72 24
54 -45 -6 100 72 24
55 -45 -6 100 72 24
56 -45 -6 100 72 24
57 -45 -6 100 72 24
58 -45 -6 100 72 24
59 -45 -6 100 72 24
60 -45 -6 100 72 24
61 -45 -6 100 72 24
62 -45 -6 100 72 24
4 -44 -6 132 104 48
5 -44 -6 132 104 48
6 -44 -6 132 104 48
7 -44 -6 132 104 48
8 -44 -6 132 104 48
9 -44 -6 132 104 48
10 -44 -6 132 104 48
11 -44 -6 132 104 48
12 -44 -6 132 104 48
13 -44 -6 132 104 48
14 -44 -6 132 104 48
15 -44 -6 132 104 48
16 -44 -6 132 104 48
17 -44 -6 132 104 48
18 -44 -6 132 104 48
19 -44 -6 132 104 48
20 -44 -6 132 104 48
21 -44 -6 132 104 48
22 -44 -6 132 104 48
23 -44 -6 132 104 48
24 -44 -6 132 104 48
25 -44 -6 132 104 48
26 -44 -6 132 104 48
27 -44 -6 132 104 48
28 -44 -6 132 104 48
29 -44 -6 132 104 48
30 -44 -6 132 104 48
31 -44 -6 132 104 48
32 -44 -6 132 104 48
33 -44 -6 132 104 48
34 -44 -6 132 104 48
35 -44 -6 132 104 48
36 -44 -6 132 104 48
37 -44 -6 132 104 48
38 -44 -6 132 104 48
39 -44 -6 132 104 48
40 -44 -6 132 104 48
41 -44 -6 132 104 48
42 -44 -6 132 104 48
43 -44 -6 132 104 48
44 -44 -6 132 104 48
45 -44 -6 132 104 48
46 -44 -6 132 104 48
47 -44 -6 132 104 48
48 -44 -6 132 104 48
49 -44 -6 132 104 48
50 -44 -6 132 104 48
51 -44 -6 132 104 48
52 -44 -6 132 104 48
53 -44 -6 132 104 48
54 -44 -6 132 104 48
55 -44 -6 132 104 48
56 -44 -6 132 104 48
57 -44 -6 132 104 48
58 -44 -6 132 104 48
59 -44 -6 132 104 48
60 -44 -6 132 104 48
61 -44 -6 132 104 48
3 -45 -5 100 72 24
4 -45 -5 100 72 24
5 -45 -5 100 72 24
6 -45 -5 100 72 24
7 -45 -5 100 72 24
8 -45 -5 100 72 24
9 -45 -5 100 72 24
10 -45 -5 100 72 24
11 -45 -5 100 72 24
12 -45 -5 100 72 24
13 -45 -5 100 72 24
14 -45 -5 100 72 24
15 -45 -5 100 72 24
16 -45 -5 100 72 24
17 -45 -5 100 72 24
18 -45 -5 100 72 24
19 -45 -5 100 72 24
20 -45 -5 100 72 24
21 -45 -5 100 72 24
22 -45 -5 100 72 24
23 -45 -5 100 72 24
24 -45 -5 100 72 24
25 -45 -5 100 72 24
26 -45 -5 100 72 24
27 -45 -5 100 72 24
28 -45 -5 100 72 24
29 -45 -5 100 72 24
30 -45 -5 100 72 24
31 -45 -5 100 72 24
32 -45 -5 100 72 24
33 -45 -5 100 72 24
34 -45 -5 100 72 24
35 -45 -5 100 72 24
36 -45 -5 100 72 24
37 -45 -5 100 72 24
38 -45 -5 100 72 24
39 -45 -5 100 72 24
40 -45 -5 100 72 24
41 -45 -5 100 72 24
42 -45 -5 100 72 24
43 -45 -5 100 72 24
44 -45 -5 100 72 24
45 -45 -5 100 72 24
46 -45 -5 100 72 24
47 -45 -5 100 72 24
48 -45 -5 100 72 24
49 -45 -5 100 72 24
50 -45 -5 100 72 24
51 -45 -5 100 72 24
52 -45 -5 100 72 24
53 -45 -5 100 72 24
54 -45 -5 100 72 24
55 -45 -5 100 72 24
56 -45 -5 100 72 24
57 -45 -5 100 72 24
58 -45 -5 100 72 24
59 -45 -5 100 72 24
60 -45 -5 100 72 24
61 -45 -5 100 72 24
62 -45 -5 100 72 24
4 -44 -5 132 104 48
5 -44 -5 160 132 68
6 -44 -5 160 132 68
7 -44 -5 160 132 68
8 -44 -5 160 132 68
9 -44 -5 184 156 88
10 -44 -5 184 156 88
11 -44 -5 132 104 48
12 -44 -5 160 132 68
13 -44 -5 160 132 68
14 -44 -5 160 132 68
15 -44 -5 160 132 68
16 -44 -5 160 132 68
17 -44 -5 160 132 68
18 -44 -5 160 132 68
19 -44 -5 160 132 68
20 -44 -5 160 132 68
21 -44 -5 160 132 68
22 -44 -5 160 132 68
23 -44 -5 160 132 68
24 -44 -5 160 132 68
25 -44 -5 184 156 88
26 -44 -5 184 156 88
27 -44 -5 132 104 48
28 -44 -5 160 132 68
29 -44 -5 160 132 68
30 -44 -5 160 132 68
31 -44 -5 160 132 68
32 -44 -5 160 132 68
33 -44 -5 160 132 68
34 -44 -5 160 132 68
35 -44 -5 160 132 68
36 -44 -5 160 132 68
37 -44 -5 160 132 68
38 -44 -5 160 132 68
39 -44 -5 160 132 68
40 -44 -5 160 132 68
41 -44 -5 184 156 88
42 -44 -5 184 156 88
43 -44 -5 132 104 48
44 -44 -5 160 132 68
45 -44 -5 160 132 68
46 -44 -5 160 132 68
47 -44 -5 160 132 68
48 -44 -5 160 132 68
49 -44 -5 160 132 68
50 -44 -5 160 132 68
51 -44 -5 160 132 68
52 -44 -5 160 132 68
53 -44 -5 184 156 88
54 -44 -5 184 156 88
55 -44 -5 132 104 48
56 -44 -5 160 132 68
57 -44 -5 160 132 68
58 -44 -5 160 132 68
59 -44 -5 160 132 68
60 -44 -5 160 132 68
61 -44 -5 132 104 48
3 -45 -4 100 72 24
4 -45 -4 100 72 24
5 -45 -4 100 72 24
6 -45 -4 100 72 24
7 -45 -4 100 72 24
8 -45 -4 100 72 24
9 -45 -4 100 72 24
10 -45 -4 100 72 24
11 -45 -4 100 72 24
12 -45 -4 100 72 24
13 -45 -4 100 72 24
14 -45 -4 100 72 24
15 -45 -4 100 72 24
16 -45 -4 100 72 24
17 -45 -4 100 72 24
18 -45 -4 100 72 24
19 -45 -4 100 72 24
20 -45 -4 100 72 24
21 -45 -4 100 72 24
22 -45 -4 100 72 24
23 -45 -4 100 72 24
24 -45 -4 100 72 24
25 -45 -4 100 72 24
26 -45 -4 100 72 24
27 -45 -4 100 72 24
28 -45 -4 100 72 24
29 -45 -4 100 72 24
30 -45 -4 100 72 24
31 -45 -4 100 72 24
32 -45 -4 100 72 24
33 -45 -4 100 72 24
34 -45 -4 100 72 24
35 -45 -4 100 72 24
36 -45 -4 100 72 24
37 -45 -4 100 72 24
38 -45 -4 100 72 24
39 -45 -4 100 72 24
40 -45 -4 100 72 24
41 -45 -4 100 72 24
42 -45 -4 100 72 24
43 -45 -4 100 72 24
44 -45 -4 100 72 24
45 -45 -4 100 72 24
46 -45 -4 100 72 24
47 -45 -4 100 72 24
48 -45 -4 100 72 24
49 -45 -4 100 72 24
50 -45 -4 100 72 24
51 -45 -4 100 72 24
52 -45 -4 100 72 24
53 -45 -4 100 72 24
54 -45 -4 100 72 24
55 -45 -4 100 72 24
56 -45 -4 100 72 24
57 -45 -4 100 72 24
58 -45 -4 100 72 24
59 -45 -4 100 72 24
60 -45 -4 100 72 24
61 -45 -4 100 72 24
62 -45 -4 100 72 24
4 -44 -4 132 104 48
5 -44 -4 160 132 68
6 -44 -4 160 132 68
7 -44 -4 160 132 68
8 -44 -4 160 132 68
9 -44 -4 160 132 68
10 -44 -4 184 156 88
11 -44 -4 132 104 48
12 -44 -4 160 132 68
13 -44 -4 160 132 68
14 -44 -4 160 132 68
15 -44 -4 160 132 68
16 -44 -4 160 132 68
17 -44 -4 160 132 68
18 -44 -4 160 132 68
19 -44 -4 160 132 68
20 -44 -4 160 132 68
21 -44 -4 160 132 68
22 -44 -4 160 132 68
23 -44 -4 160 132 68
24 -44 -4 160 132 68
25 -44 -4 160 132 68
26 -44 -4 184 156 88
27 -44 -4 132 104 48
28 -44 -4 160 132 68
29 -44 -4 160 132 68
30 -44 -4 160 132 68
31 -44 -4 160 132 68
32 -44 -4 160 132 68
33 -44 -4 160 132 68
34 -44 -4 160 132 68
35 -44 -4 160 132 68
36 -44 -4 160 132 68
37 -44 -4 160 132 68
38 -44 -4 160 132 68
39 -44 -4 160 132 68
40 -44 -4 160 132 68
41 -44 -4 160 132 68
42 -44 -4 184 156 88
43 -44 -4 132 104 48
44 -44 -4 160 132 68
45 -44 -4 160 132 68
46 -44 -4 160 132 68
47 -44 -4 160 132 68
48 -44 -4 160 132 68
49 -44 -4 160 132 68
50 -44 -4 160 132 68
51 -44 -4 160 132 68
52 -44 -4 160 132 68
53 -44 -4 160 132 68
54 -44 -4 184 156 88
55 -44 -4 132 104 48
56 -44 -4 160 132 68
57 -44 -4 160 132 68
58 -44 -4 160 132 68
59 -44 -4 160 132 68
60 -44 -4 160 132 68
61 -44 -4 132 104 48
3 -45 -3 100 72 24
4 -45 -3 100 72 24
5 -45 -3 100 72 24
6 -45 -3 100 72 24
7 -45 -3 100 72 24
8 -45 -3 100 72 24
9 -45 -3 100 72 24
10 -45 -3 100 72 24
11 -45 -3 100 72 24
12 -45 -3 100 72 24
13 -45 -3 100 72 24
14 -45 -3 100 72 24
15 -45 -3 100 72 24
16 -45 -3 100 72 24
17 -45 -3 100 72 24
18 -45 -3 100 72 24
19 -45 -3 100 72 24
20 -45 -3 100 72 24
21 -45 -3 100 72 24
22 -45 -3 100 72 24
23 -45 -3 100 72 24
24 -45 -3 100 72 24
25 -45 -3 100 72 24
26 -45 -3 100 72 24
27 -45 -3 100 72 24
28 -45 -3 100 72 24
29 -45 -3 100 72 24
30 -45 -3 100 72 24
31 -45 -3 100 72 24
32 -45 -3 100 72 24
33 -45 -3 100 72 24
34 -45 -3 100 72 24
35 -45 -3 100 72 24
36 -45 -3 100 72 24
37 -45 -3 100 72 24
38 -45 -3 100 72 24
39 -45 -3 100 72 24
40 -45 -3 100 72 24
41 -45 -3 100 72 24
42 -45 -3 100 72 24
43 -45 -3 100 72 24
44 -45 -3 100 72 24
45 -45 -3 100 72 24
46 -45 -3 100 72 24
47 -45 -3 100 72 24
48 -45 -3 100 72 24
49 -45 -3 100 72 24
50 -45 -3 100 72 24
51 -45 -3 100 72 24
52 -45 -3 100 72 24
53 -45 -3 100 72 24
54 -45 -3 100 72 24
55 -45 -3 100 72 24
56 -45 -3 100 72 24
57 -45 -3 100 72 24
58 -45 -3 100 72 24
59 -45 -3 100 72 24
60 -45 -3 100 72 24
61 -45 -3 100 72 24
62 -45 -3 100 72 24
4 -44 -3 132 104 48
5 -44 -3 160 132 68
6 -44 -3 160 132 68
7 -44 -3 160 132 68
8 -44 -3 160 132 68
9 -44 -3 160 132 68
10 -44 -3 184 156 88
11 -44 -3 132 104 48
12 -44 -3 160 132 68
13 -44 -3 160 132 68
14 -44 -3 160 132 68
15 -44 -3 160 132 68
16 -44 -3 160 132 68
17 -44 -3 160 132 68
18 -44 -3 160 132 68
19 -44 -3 160 132 68
20 -44 -3 160 132 68
21 -44 -3 160 132 68
22 -44 -3 160 132 68
23 -44 -3 160 132 68
24 -44 -3 160 132 68
25 -44 -3 160 132 68
26 -44 -3 184 156 88
27 -44 -3 132 104 48
28 -44 -3 160 132 68
29 -44 -3 160 132 68
30 -44 -3 160 132 68
31 -44 -3 160 132 68
32 -44 -3 160 132 68
33 -44 -3 160 132 68
34 -44 -3 160 132 68
35 -44 -3 160 132 68
36 -44 -3 160 132 68
37 -44 -3 160 132 68
38 -44 -3 160 132 68
39 -44 -3 160 132 68
40 -44 -3 160 132 68
41 -44 -3 160 132 68
42 -44 -3 184 156 88
43 -44 -3 132 104 48
44 -44 -3 160 132 68
45 -44 -3 160 132 68
46 -44 -3 160 132 68
47 -44 -3 160 132 68
48 -44 -3 160 132 68
49 -44 -3 160 132 68
50 -44 -3 160 132 68
51 -44 -3 160 132 68
52 -44 -3 160 132 68
53 -44 -3 160 132 68
54 -44 -3 184 156 88
55 -44 -3 132 104 48
56 -44 -3 160 132 68
57 -44 -3 160 132 68
58 -44 -3 160 132 68
59 -44 -3 160 132 68
60 -44 -3 160 132 68
61 -44 -3 132 104 48
3 -45 -2 100 72 24
4 -45 -2 100 72 24
5 -45 -2 100 72 24
6 -45 -2 100 72 24
7 -45 -2 100 72 24
8 -45 -2 100 72 24
9 -45 -2 100 72 24
10 -45 -2 100 72 24
11 -45 -2 100 72 24
12 -45 -2 100 72 24
13 -45 -2 100 72 24
14 -45 -2 100 72 24
15 -45 -2 100 72 24
16 -45 -2 100 72 24
17 -45 -2 100 72 24
18 -45 -2 100 72 24
19 -45 -2 100 72 24
20 -45 -2 100 72 24
21 -45 -2 100 72 24
22 -45 -2 100 72 24
23 -45 -2 100 72 24
24 -45 -2 100 72 24
25 -45 -2 100 72 24
26 -45 -2 100 72 24
27 -45 -2 100 72 24
28 -45 -2 100 72 24
29 -45 -2 100 72 24
30 -45 -2 100 72 24
31 -45 -2 100 72 24
32 -45 -2 100 72 24
33 -45 -2 100 72 24
34 -45 -2 100 72 24
35 -45 -2 100 72 24
36 -45 -2 100 72 24
37 -45 -2 100 72 24
38 -45 -2 100 72 24
39 -45 -2 100 72 24
40 -45 -2 100 72 24
41 -45 -2 100 72 24
42 -45 -2 100 72 24
43 -45 -2 100 72 24
44 -45 -2 100 72 24
45 -45 -2 100 72 24
46 -45 -2 100 72 24
47 -45 -2 100 72 24
48 -45 -2 100 72 24
49 -45 -2 100 72 24
50 -45 -2 100 72 24
51 -45 -2 100 72 24
52 -45 -2 100 72 24
53 -45 -2 100 72 24
54 -45 -2 100 72 24
55 -45 -2 100 72 24
56 -45 -2 100 72 24
57 -45 -2 100 72 24
58 -45 -2 100 72 24
59 -45 -2 100 72 24
60 -45 -2 100 72 24
61 -45 -2 100 72 24
62 -45 -2 100 72 24
4 -44 -2 132 104 48
5 -44 -2 132 104 48
6 -44 -2 132 104 48
7 -44 -2 132 104 48
8 -44 -2 132 104 48
9 -44 -2 132 104 48
10 -44 -2 132 104 48
11 -44 -2 132 104 48
12 -44 -2 132 104 48
13 -44 -2 132 104 48
14 -44 -2 132 104 48
15 -44 -2 132 104 48
16 -44 -2 132 104 48
17 -44 -2 132 104 48
18 -44 -2 132 104 48
19 -44 -2 132 104 48
20 -44 -2 132 104 48
21 -44 -2 132 104 48
22 -44 -2 132 104 48
23 -44 -2 132 104 48
24 -44 -2 132 104 48
25 -44 -2 132 104 48
26 -44 -2 132 104 48
27 -44 -2 132 104 48
28 -44 -2 132 104 48
29 -44 -2 132 104 48
30 -44 -2 132 104 48
31 -44 -2 132 104 48
32 -44 -2 132 104 48
33 -44 -2 132 104 48
34 -44 -2 132 104 48
35 -44 -2 132 104 48
36 -44 -2 132 104 48
37 -44 -2 132 104 48
38 -44 -2 132 104 48
39 -44 -2 132 104 48
40 -44 -2 132 104 48
41 -44 -2 132 104 48
42 -44 -2 132 104 48
43 -44 -2 132 104 48
44 -44 -2 132 104 48
45 -44 -2 132 104 48
46 -44 -2 132 104 48
47 -44 -2 132 104 48
48 -44 -2 132 104 48
49 -44 -2 132 104 48
50 -44 -2 132 104 48
51 -44 -2 132 104 48
52 -44 -2 132 104 48
53 -44 -2 132 104 48
54 -44 -2 132 104 48
55 -44 -2 132 104 48
56 -44 -2 132 104 48
57 -44 -2 132 104 48
58 -44 -2 132 104 48
59 -44 -2 132 104 48
60 -44 -2 132 104 48
61 -44 -2 132 104 48
3 -45 -1 100 72 24
4 -45 -1 100 72 24
5 -45 -1 100 72 24
6 -45 -1 100 72 24
7 -45 -1 100 72 24
8 -45 -1 100 72 24
9 -45 -1 100 72 24
10 -45 -1 100 72 24
11 -45 -1 100 72 24
12 -45 -1 100 72 24
13 -45 -1 100 72 24
14 -45 -1 100 72 24
15 -45 -1 100 72 24
16 -45 -1 100 72 24
17 -45 -1 100 72 24
18 -45 -1 100 72 24
19 -45 -1 100 72 24
20 -45 -1 100 72 24
21 -45 -1 100 72 24
22 -45 -1 100 72 24
23 -45 -1 100 72 24
24 -45 -1 100 72 24
25 -45 -1 100 72 24
26 -45 -1 100 72 24
27 -45 -1 100 72 24
28 -45 -1 100 72 24
29 -45 -1 100 72 24
30 -45 -1 100 72 24
31 -45 -1 100 72 24
32 -45 -1 100 72 24
33 -45 -1 100 72 24
34 -45 -1 100 72 24
35 -45 -1 100 72 24
36 -45 -1 100 72 24
37 -45 -1 100 72 24
38 -45 -1 100 72 24
39 -45 -1 100 72 24
40 -45 -1 100 72 24
41 -45 -1 100 72 24
42 -45 -1 100 72 24
43 -45 -1 100 72 24
44 -45 -1 100 72 24
45 -45 -1 100 72 24
46 -45 -1 100 72 24
47 -45 -1 100 72 24
48 -45 -1 100 72 24
49 -45 -1 100 72 24
50 -45 -1 100 72 24
51 -45 -1 100 72 24
52 -45 -1 100 72 24
53 -45 -1 100 72 24
54 -45 -1 100 72 24
55 -45 -1 100 72 24
56 -45 -1 100 72 24
57 -45 -1 100 72 24
58 -45 -1 100 72 24
59 -45 -1 100 72 24
60 -45 -1 100 72 24
61 -45 -1 100 72 24
62 -45 -1 100 72 24
4 -44 -1 132 104 48
5 -44 -1 160 132 68
6 -44 -1 160 132 68
7 -44 -1 160 132 68
8 -44 -1 160 132 68
9 -44 -1 160 132 68
10 -44 -1 160 132 68
11 -44 -1 160 132 68
12 -44 -1 160 132 68
13 -44 -1 160 132 68
14 -44 -1 184 156 88
15 -44 -1 184 156 88
16 -44 -1 132 104 48
17 -44 -1 160 132 68
18 -44 -1 160 132 68
19 -44 -1 160 132 68
20 -44 -1 160 132 68
21 -44 -1 160 132 68
22 -44 -1 160 132 68
23 -44 -1 160 132 68
24 -44 -1 160 132 68
25 -44 -1 160 132 68
26 -44 -1 160 132 68
27 -44 -1 160 132 68
28 -44 -1 184 156 88
29 -44 -1 184 156 88
30 -44 -1 132 104 48
31 -44 -1 160 132 68
32 -44 -1 160 132 68
33 -44 -1 160 132 68
34 -44 -1 160 132 68
35 -44 -1 160 132 68
36 -44 -1 160 132 68
37 -44 -1 160 132 68
38 -44 -1 160 132 68
39 -44 -1 160 132 68
40 -44 -1 160 132 68
41 -44 -1 160 132 68
42 -44 -1 160 132 68
43 -44 -1 160 132 68
44 -44 -1 184 156 88
45 -44 -1 184 156 88
46 -44 -1 132 104 48
47 -44 -1 160 132 68
48 -44 -1 160 132 68
49 -44 -1 160 132 68
50 -44 -1 160 132 68
51 -44 -1 160 132 68
52 -44 -1 160 132 68
53 -44 -1 160 132 68
54 -44 -1 160 132 68
55 -44 -1 160 132 68
56 -44 -1 184 156 88
57 -44 -1 184 156 88
58 -44 -1 132 104 48
59 -44 -1 160 132 68
60 -44 -1 160 132 68
61 -44 -1 132 104 48
3 -45 0 100 72 24
4 -45 0 100 72 24
5 -45 0 100 72 24
6 -45 0 100 72 24
7 -45 0 100 72 24
8 -45 0 100 72 24
9 -45 0 100 72 24
10 -45 0 100 72 24
11 -45 0 100 72 24
12 -45 0 100 72 24
13 -45 0 100 72 24
14 -45 0 100 72 24
15 -45 0 100 72 24
16 -45 0 100 72 24
17 -45 0 100 72 24
18 -45 0 100 72 24
19 -45 0 100 72 24
20 -45 0 100 72 24
21 -45 0 100 72 24
22 -45 0 100 72 24
23 -45 0 100 72 24
24 -45 0 100 72 24
25 -45 0 100 72 24
26 -45 0 100 72 24
27 -45 0 100 72 24
28 -45 0 100 72 24
29 -45 0 100 72 24
30 -45 0 100 72 24
31 -45 0 100 72 24
32 -45 0 100 72 24
33 -45 0 100 72 24
34 -45 0 100 72 24
35 -45 0 100 72 24
36 -45 0 100 72 24
37 -45 0 100 72 24
38 -45 0 100 72 24
39 -45 0 100 72 24
40 -45 0 100 72 24
41 -45 0 100 72 24
42 -45 0 100 72 24
43 -45 0 100 72 24
44 -45 0 100 72 24
45 -45 0 100 72 24
46 -45 0 100 72 24
47 -45 0 100 72 24
48 -45 0 100 72 24
49 -45 0 100 72 24
50 -45 0 100 72 24
51 -45 0 100 72 24
52 -45 0 100 72 24
53 -45 0 100 72 24
54 -45 0 100 72 24
55 -45 0 100 72 24
56 -45 0 100 72 24
57 -45 0 100 72 24
58 -45 0 100 72 24
59 -45 0 100 72 24
60 -45 0 100 72 24
61 -45 0 100 72 24
62 -45 0 100 72 24
4 -44 0 132 104 48
5 -44 0 160 132 68
6 -44 0 160 132 68
7 -44 0 160 132 68
8 -44 0 160 132 68
9 -44 0 160 132 68
10 -44 0 160 132 68
11 -44 0 160 132 68
12 -44 0 160 132 68
13 -44 0 160 132 68
14 -44 0 160 132 68
15 -44 0 184 156 88
16 -44 0 132 104 48
17 -44 0 160 132 68
18 -44 0 160 132 68
19 -44 0 160 132 68
20 -44 0 160 132 68
21 -44 0 160 132 68
22 -44 0 160 132 68
23 -44 0 160 132 68
24 -44 0 160 132 68
25 -44 0 160 132 68
26 -44 0 160 132 68
27 -44 0 160 132 68
28 -44 0 160 132 68
29 -44 0 184 156 88
30 -44 0 132 104 48
31 -44 0 160 132 68
32 -44 0 160 132 68
33 -44 0 160 132 68
34 -44 0 160 132 68
35 -44 0 160 132 68
36 -44 0 160 132 68
37 -44 0 160 132 68
38 -44 0 160 132 68
39 -44 0 160 132 68
40 -44 0 160 132 68
41 -44 0 160 132 68
42 -44 0 160 132 68
43 -44 0 160 132 68
44 -44 0 160 132 68
45 -44 0 184 156 88
46 -44 0 132 104 48
47 -44 0 160 132 68
48 -44 0 160 132 68
49 -44 0 160 132 68
50 -44 0 160 132 68
51 -44 0 160 132 68
52 -44 0 160 132 68
53 -44 0 160 132 68
54 -44 0 160 132 68
55 -44 0 160 132 68
56 -44 0 160 132 68
57 -44 0 184 156 88
58 -44 0 132 104 48
59 -44 0 160 132 68
60 -44 0 160 132 68
61 -44 0 132 104 48
3 -45 1 100 72 24
4 -45 1 100 72 24
5 -45 1 100 72 24
6 -45 1 100 72 24
7 -45 1 100 72 24
8 -45 1 100 72 24
9 -45 1 100 72 24
10 -45 1 100 72 24
11 -45 1 100 72 24
12 -45 1 100 72 24
13 -45 1 100 72 24
14 -45 1 100 72 24
15 -45 1 100 72 24
16 -45 1 100 72 24
17 -45 1 100 72 24
18 -45 1 100 72 24
19 -45 1 100 72 24
20 -45 1 100 72 24
21 -45 1 100 72 24
22 -45 1 100 72 24
23 -45 1 100 72 24
24 -45 1 100 72 24
25 -45 1 100 72 24
26 -45 1 100 72 24
27 -45 1 100 72 24
28 -45 1 100 72 24
29 -45 1 100 72 24
30 -45 1 100 72 24
31 -45 1 100 72 24
32 -45 1 100 72 24
33 -45 1 100 72 24
34 -45 1 100 72 24
35 -45 1 100 72 24
36 -45 1 100 72 24
37 -45 1 100 72 24
38 -45 1 100 72 24
39 -45 1 100 72 24
40 -45 1 100 72 24
41 -45 1 100 72 24
42 -45 1 100 72 24
43 -45 1 100 72 24
44 -45 1 100 72 24
45 -45 1 100 72 24
46 -45 1 100 72 24
47 -45 1 100 72 24
48 -45 1 100 72 24
49 -45 1 100 72 24
50 -45 1 100 72 24
51 -45 1 100 72 24
52 -45 1 100 72 24
53 -45 1 100 72 24
54 -45 1 100 72 24
55 -45 1 100 72 24
56 -45 1 100 72 24
57 -45 1 100 72 24
58 -45 1 100 72 24
59 -45 1 100 72 24
60 -45 1 100 72 24
61 -45 1 100 72 24
62 -45 1 100 72 24
4 -44 1 132 104 48
5 -44 1 160 132 68
6 -44 1 160 132 68
7 -44 1 160 132 68
8 -44 1 160 132 68
9 -44 1 160 132 68
10 -44 1 160 132 68
11 -44 1 160 132 68
12 -44 1 160 132 68
13 -44 1 160 132 68
14 -44 1 160 132 68
15 -44 1 184 156 88
16 -44 1 132 104 48
17 -44 1 160 132 68
18 -44 1 160 132 68
19 -44 1 160 132 68
20 -44 1 160 132 68
21 -44 1 160 132 68
22 -44 1 160 132 68
23 -44 1 160 132 68
24 -44 1 160 132 68
25 -44 1 160 132 68
26 -44 1 160 132 68
27 -44 1 160 132 68
28 -44 1 160 132 68
29 -44 1 184 156 88
30 -44 1 132 104 48
31 -44 1 160 132 68
32 -44 1 160 132 68
33 -44 1 160 132 68
34 -44 1 160 132 68
35 -44 1 160 132 68
36 -44 1 160 132 68
37 -44 1 160 132 68
38 -44 1 160 132 68
39 -44 1 160 132 68
40 -44 1 160 132 68
41 -44 1 160 132 68
42 -44 1 160 132 68
43 -44 1 160 132 68
44 -44 1 160 132 68
45 -44 1 184 156 88
46 -44 1 132 104 48
47 -44 1 160 132 68
48 -44 1 160 132 68
49 -44 1 160 132 68
50 -44 1 160 132 68
51 -44 1 160 132 68
52 -44 1 160 132 68
53 -44 1 160 132 68
54 -44 1 160 132 68
55 -44 1 160 132 68
56 -44 1 160 132 68
57 -44 1 184 156 88
58 -44 1 132 104 48
59 -44 1 160 132 68
60 -44 1 160 132 68
61 -44 1 132 104 48
22 -43 1 192 88 88
23 -43 1 192 88 88
24 -43 1 192 88 88
25 -43 1 192 88 88
26 -43 1 192 88 88
27 -43 1 192 88 88
28 -43 1 192 88 88
29 -43 1 192 88 88
30 -43 1 192 88 88
31 -43 1 192 88 88
32 -43 1 192 88 88
33 -43 1 192 88 88
34 -43 1 192 88 88
35 -43 1 192 88 88
36 -43 1 192 88 88
37 -43 1 192 88 88
38 -43 1 192 88 88
39 -43 1 192 88 88
40 -43 1 192 88 88
41 -43 1 192 88 88
22 -30 1 92 156 92
23 -30 1 92 156 92
24 -30 1 92 156 92
25 -30 1 252 252 104
26 -30 1 252 252 104
27 -30 1 252 252 104
36 -30 1 80 92 192
37 -30 1 80 92 192
38 -30 1 80 92 192
39 -30 1 208 128 92
40 -30 1 208 128 92
41 -30 1 208 128 92
22 -29 1 92 156 92
23 -29 1 92 156 92
24 -29 1 92 156 92
25 -29 1 252 252 104
26 -29 1 252 252 104
27 -29 1 252 252 104
36 -29 1 80 92 192
37 -29 1 80 92 192
38 -29 1 80 92 192
39 -29 1 208 128 92
40 -29 1 208 128 92
41 -29 1 208 128 92
22 -28 1 192 88 88
23 -28 1 192 88 88
26 -28 1 104 116 208
27 -28 1 104 116 208
36 -28 1 124 208 172
37 -28 1 124 208 172
40 -28 1 160 112 204
41 -28 1 160 112 204
22 -27 1 192 88 88
23 -27 1 192 88 88
26 -27 1 104 116 208
27 -27 1 104 116 208
36 -27 1 124 208 172
37 -27 1 124 208 172
40 -27 1 160 112 204
41 -27 1 160 112 204
3 -45 2 100 72 24
4 -45 2 100 72 24
5 -45 2 100 72 24
6 -45 2 100 72 24
7 -45 2 100 72 24
8 -45 2 100 72 24
9 -45 2 100 72 24
10 -45 2 100 72 24
11 -45 2 100 72 24
12 -45 2 100 72 24
13 -45 2 100 72 24
14 -45 2 100 72 24
15 -45 2 100 72 24
16 -45 2 100 72 24
17 -45 2 100 72 24
18 -45 2 100 72 24
19 -45 2 100 72 24
20 -45 2 100 72 24
21 -45 2 100 72 24
22 -45 2 100 72 24
23 -45 2 100 72 24
24 -45 2 100 72 24
25 -45 2 100 72 24
26 -45 2 100 72 24
27 -45 2 100 72 24
28 -45 2 100 72 24
29 -45 2 100 72 24
30 -45 2 100 72 24
31 -45 2 100 72 24
32 -45 2 100 72 24
33 -45 2 100 72 24
34 -45 2 100 72 24
35 -45 2 100 72 24
36 -45 2 100 72 24
37 -45 2 100 72 24
38 -45 2 100 72 24
39 -45 2 100 72 24
40 -45 2 100 72 24
41 -45 2 100 72 24
42 -45 2 100 72 24
43 -45 2 100 72 24
44 -45 2 100 72 24
45 -45 2 100 72 24
46 -45 2 100 72 24
47 -45 2 100 72 24
48 -45 2 100 72 24
49 -45 2 100 72 24
50 -45 2 100 72 24
51 -45 2 100 72 24
52 -45 2 100 72 24
53 -45 2 100 72 24
54 -45 2 100 72 24
55 -45 2 100 72 24
56 -45 2 100 72 24
57 -45 2 100 72 24
58 -45 2 100 72 24
59 -45 2 100 72 24
60 -45 2 100 72 24
61 -45 2 100 72 24
62 -45 2 100 72 24
4 -44 2 132 104 48
5 -44 2 132 104 48
6 -44 2 132 104 48
7 -44 2 132 104 48
8 -44 2 132 104 48
9 -44 2 132 104 48
10 -44 2 132 104 48
11 -44 2 132 104 48
12 -44 2 132 104 48
13 -44 2 132 104 48
14 -44 2 132 104 48
15 -44 2 132 104 48
16 -44 2 132 104 48
17 -44 2 132 104 48
18 -44 2 132 104 48
19 -44 2 132 104 48
20 -44 2 132 104 48
21 -44 2 132 104 48
22 -44 2 132 104 48
23 -44 2 132 104 48
24 -44 2 132 104 48
25 -44 2 132 104 48
26 -44 2 132 104 48
27 -44 2 132 104 48
28 -44 2 132 104 48
29 -44 2 132 104 48
30 -44 2 132 104 48
31 -44 2 132 104 48
32 -44 2 132 104 48
33 -44 2 132 104 48
34 -44 2 132 104 48
35 -44 2 132 104 48
36 -44 2 132 104 48
37 -44 2 132 104 48
38 -44 2 132 104 48
39 -44 2 132 104 48
40 -44 2 132 104 48
41 -44 2 132 104 48
42 -44 2 132 104 48
43 -44 2 132 104 48
44 -44 2 132 104 48
45 -44 2 132 104 48
46 -44 2 132 104 48
47 -44 2 132 104 48
48 -44 2 132 104 48
49 -44 2 132 104 48
50 -44 2 132 104 48
51 -44 2 132 104 48
52 -44 2 132 104 48
53 -44 2 132 104 48
54 -44 2 132 104 48
55 -44 2 132 104 48
56 -44 2 132 104 48
57 -44 2 132 104 48
58 -44 2 132 104 48
59 -44 2 132 104 48
60 -44 2 132 104 48
61 -44 2 132 104 48
22 -43 2 192 88 88
23 -43 2 192 88 88
24 -43 2 192 88 88
25 -43 2 192 88 88
26 -43 2 192 88 88
27 -43 2 192 88 88
28 -43 2 192 88 88
29 -43 2 192 88 88
30 -43 2 192 88 88
31 -43 2 192 88 88
32 -43 2 192 88 88
33 -43 2 192 88 88
34 -43 2 192 88 88
35 -43 2 192 88 88
36 -43 2 192 88 88
37 -43 2 192 88 88
38 -43 2 192 88 88
39 -43 2 192 88 88
40 -43 2 192 88 88
41 -43 2 192 88 88
23 -42 2 192 88 88
24 -42 2 192 88 88
25 -42 2 192 88 88
26 -42 2 192 88 88
37 -42 2 120 60 164
38 -42 2 120 60 164
39 -42 2 120 60 164
40 -42 2 120 60 164
23 -41 2 192 88 88
24 -41 2 192 88 88
25 -41 2 192 88 88
26 -41 2 192 88 88
37 -41 2 120 60 164
38 -41 2 120 60 164
39 -41 2 120 60 164
40 -41 2 120 60 164
23 -40 2 176 88 156
24 -40 2 176 88 156
25 -40 2 252 252 104
26 -40 2 252 252 104
37 -40 2 252 252 104
38 -40 2 252 252 104
39 -40 2 176 88 156
40 -40 2 176 88 156
23 -39 2 176 88 156
24 -39 2 176 88 156
25 -39 2 252 252 104
26 -39 2 252 252 104
37 -39 2 252 252 104
38 -39 2 252 252 104
39 -39 2 176 88 156
40 -39 2 176 88 156
23 -38 2 92 156 92
24 -38 2 92 156 92
25 -38 2 92 156 92
26 -38 2 92 156 92
37 -38 2 104 116 208
38 -38 2 104 116 208
39 -38 2 104 116 208
40 -38 2 104 116 208
23 -37 2 92 156 92
24 -37 2 92 156 92
25 -37 2 92 156 92
26 -37 2 92 156 92
37 -37 2 104 116 208
38 -37 2 104 116 208
39 -37 2 104 116 208
40 -37 2 104 116 208
23 -36 2 192 88 88
24 -36 2 192 88 88
25 -36 2 120 60 164
26 -36 2 120 60 164
37 -36 2 120 60 164
38 -36 2 120 60 164
39 -36 2 192 88 88
40 -36 2 192 88 88
23 -35 2 192 88 88
24 -35 2 192 88 88
25 -35 2 120 60 164
26 -35 2 120 60 164
37 -35 2 120 60 164
38 -35 2 120 60 164
39 -35 2 192 88 88
40 -35 2 192 88 88
23 -34 2 208 128 92
24 -34 2 208 128 92
25 -34 2 208 128 92
26 -34 2 208 128 92
37 -34 2 56 64 176
38 -34 2 56 64 176
39 -34 2 56 64 176
40 -34 2 56 64 176
23 -33 2 208 128 92
24 -33 2 208 128 92
25 -33 2 208 128 92
26 -33 2 208 128 92
37 -33 2 56 64 176
38 -33 2 56 64 176
39 -33 2 56 64 176
40 -33 2 56 64 176
23 -32 2 232 232 92
24 -32 2 232 232 92
25 -32 2 192 88 88
26 -32 2 192 88 88
37 -32 2 192 88 88
38 -32 2 192 88 88
39 -32 2 232 232 92
40 -32 2 232 232 92
23 -31 2 232 232 92
24 -31 2 232 232 92
25 -31 2 192 88 88
26 -31 2 192 88 88
27 -31 2 208 128 92
28 -31 2 208 128 92
29 -31 2 208 128 92
30 -31 2 208 128 92
31 -31 2 208 128 92
32 -31 2 208 128 92
33 -31 2 208 128 92
34 -31 2 208 128 92
35 -31 2 208 128 92
36 -31 2 208 128 92
37 -31 2 192 88 88
38 -31 2 192 88 88
39 -31 2 232 232 92
40 -31 2 232 232 92
22 -30 2 92 156 92
23 -30 2 92 156 92
24 -30 2 92 156 92
25 -30 2 252 252 104
26 -30 2 252 252 104
27 -30 2 252 252 104
28 -30 2 208 128 92
29 -30 2 208 128 92
30 -30 2 208 128 92
31 -30 2 208 128 92
32 -30 2 208 128 92
33 -30 2 208 128 92
34 -30 2 208 128 92
35 -30 2 208 128 92
36 -30 2 80 92 192
37 -30 2 80 92 192
38 -30 2 80 92 192
39 -30 2 208 128 92
40 -30 2 208 128 92
41 -30 2 208 128 92
22 -29 2 92 156 92
23 -29 2 92 156 92
24 -29 2 92 156 92
25 -29 2 252 252 104
26 -29 2 252 252 104
27 -29 2 252 252 104
28 -29 2 208 128 92
29 -29 2 208 128 92
34 -29 2 208 128 92
35 -29 2 208 128 92
36 -29 2 80 92 192
37 -29 2 80 92 192
38 -29 2 80 92 192
39 -29 2 208 128 92
40 -29 2 208 128 92
41 -29 2 208 128 92
22 -28 2 192 88 88
23 -28 2 192 88 88
26 -28 2 104 116 208
27 -28 2 104 116 208
36 -28 2 124 208 172
37 -28 2 124 208 172
40 -28 2 160 112 204
41 -28 2 160 112 204
22 -27 2 192 88 88
23 -27 2 192 88 88
26 -27 2 104 116 208
27 -27 2 104 116 208
36 -27 2 124 208 172
37 -27 2 124 208 172
40 -27 2 160 112 204
41 -27 2 160 112 204
3 -45 3 100 72 24
4 -45 3 100 72 24
5 -45 3 100 72 24
6 -45 3 100 72 24
7 -45 3 100 72 24
8 -45 3 100 72 24
9 -45 3 100 72 24
10 -45 3 100 72 24
11 -45 3 100 72 24
12 -45 3 100 72 24
13 -45 3 100 72 24
14 -45 3 100 72 24
15 -45 3 100 72 24
16 -45 3 100 72 24
17 -45 3 100 72 24
18 -45 3 100 72 24
19 -45 3 100 72 24
20 -45 3 100 72 24
21 -45 3 100 72 24
22 -45 3 100 72 24
23 -45 3 100 72 24
24 -45 3 100 72 24
25 -45 3 100 72 24
26 -45 3 100 72 24
27 -45 3 100 72 24
28 -45 3 100 72 24
29 -45 3 100 72 24
30 -45 3 100 72 24
31 -45 3 100 72 24
32 -45 3 100 72 24
33 -45 3 100 72 24
34 -45 3 100 72 24
35 -45 3 100 72 24
36 -45 3 100 72 24
37 -45 3 100 72 24
38 -45 3 100 72 24
39 -45 3 100 72 24
40 -45 3 100 72 24
41 -45 3 100 72 24
42 -45 3 100 72 24
43 -45 3 100 72 24
44 -45 3 100 72 24
45 -45 3 100 72 24
46 -45 3 100 72 24
47 -45 3 100 72 24
48 -45 3 100 72 24
49 -45 3 100 72 24
50 -45 3 100 72 24
51 -45 3 100 72 24
52 -45 3 100 72 24
53 -45 3 100 72 24
54 -45 3 100 72 24
55 -45 3 100 72 24
56 -45 3 100 72 24
57 -45 3 100 72 24
58 -45 3 100 72 24
59 -45 3 100 72 24
60 -45 3 100 72 24
61 -45 3 100 72 24
62 -45 3 100 72 24
4 -44 3 132 104 48
5 -44 3 160 132 68
6 -44 3 160 132 68
7 -44 3 160 132 68
8 -44 3 160 132 68
9 -44 3 184 156 88
10 -44 3 184 156 88
11 -44 3 132 104 48
12 -44 3 160 132 68
13 -44 3 160 132 68
14 -44 3 160 132 68
15 -44 3 160 132 68
16 -44 3 160 132 68
17 -44 3 160 132 68
18 -44 3 160 132 68
19 -44 3 160 132 68
20 -44 3 160 132 68
21 -44 3 160 132 68
22 -44 3 160 132 68
23 -44 3 160 132 68
24 -44 3 160 132 68
25 -44 3 184 156 88
26 -44 3 184 156 88
27 -44 3 132 104 48
28 -44 3 160 132 68
29 -44 3 160 132 68
30 -44 3 160 132 68
31 -44 3 160 132 68
32 -44 3 160 132 68
33 -44 3 160 132 68
34 -44 3 160 132 68
35 -44 3 160 132 68
36 -44 3 160 132 68
37 -44 3 160 132 68
38 -44 3 160 132 68
39 -44 3 160 132 68
40 -44 3 160 132 68
41 -44 3 184 156 88
42 -44 3 184 156 88
43 -44 3 132 104 48
44 -44 3 160 132 68
45 -44 3 160 132 68
46 -44 3 160 132 68
47 -44 3 160 132 68
48 -44 3 160 132 68
49 -44 3 160 132 68
50 -44 3 160 132 68
51 -44 3 160 132 68
52 -44 3 160 132 68
53 -44 3 184 156 88
54 -44 3 184 156 88
55 -44 3 132 104 48
56 -44 3 160 132 68
57 -44 3 160 132 68
58 -44 3 160 132 68
59 -44 3 160 132 68
60 -44 3 160 132 68
61 -44 3 132 104 48
22 -43 3 192 88 88
23 -43 3 192 88 88
24 -43 3 192 88 88
25 -43 3 192 88 88
26 -43 3 192 88 88
27 -43 3 192 88 88
28 -43 3 192 88 88
29 -43 3 192 88 88
30 -43 3 192 88 88
31 -43 3 192 88 88
32 -43 3 192 88 88
33 -43 3 192 88 88
34 -43 3 192 88 88
35 -43 3 192 88 88
36 -43 3 192 88 88
37 -43 3 192 88 88
38 -43 3 192 88 88
39 -43 3 192 88 88
40 -43 3 192 88 88
41 -43 3 192 88 88
23 -42 3 192 88 88
24 -42 3 192 88 88
25 -42 3 192 88 88
26 -42 3 192 88 88
37 -42 3 120 60 164
38 -42 3 120 60 164
39 -42 3 120 60 164
40 -42 3 120 60 164
23 -41 3 192 88 88
24 -41 3 192 88 88
25 -41 3 192 88 88
26 -41 3 192 88 88
37 -41 3 120 60 164
38 -41 3 120 60 164
39 -41 3 120 60 164
40 -41 3 120 60 164
23 -40 3 176 88 156
24 -40 3 176 88 156
25 -40 3 252 252 104
26 -40 3 252 252 104
37 -40 3 252 252 104
38 -40 3 252 252 104
39 -40 3 176 88 156
40 -40 3 176 88 156
23 -39 3 176 88 156
24 -39 3 176 88 156
25 -39 3 252 252 104
26 -39 3 252 252 104
37 -39 3 252 252 104
38 -39 3 252 252 104
39 -39 3 176 88 156
40 -39 3 176 88 156
23 -38 3 92 156 92
24 -38 3 92 156 92
25 -38 3 92 156 92
26 -38 3 92 156 92
37 -38 3 104 116 208
38 -38 3 104 116 208
39 -38 3 104 116 208
40 -38 3 104 116 208
23 -37 3 92 156 92
24 -37 3 92 156 92
25 -37 3 92 156 92
26 -37 3 92 156 92
37 -37 3 104 116 208
38 -37 3 104 116 208
39 -37 3 104 116 208
40 -37 3 104 116 208
23 -36 3 192 88 88
24 -36 3 192 88 88
25 -36 3 120 60 164
26 -36 3 120 60 164
37 -36 3 120 60 164
38 -36 3 120 60 164
39 -36 3 192 88 88
40 -36 3 192 88 88
23 -35 3 192 88 88
24 -35 3 192 88 88
25 -35 3 120 60 164
26 -35 3 120 60 164
37 -35 3 120 60 164
38 -35 3 120 60 164
39 -35 3 192 88 88
40 -35 3 192 88 88
23 -34 3 208 128 92
24 -34 3 208 128 92
25 -34 3 208 128 92
26 -34 3 208 128 92
27 -34 3 124 208 172
36 -34 3 124 208 172
37 -34 3 56 64 176
38 -34 3 56 64 176
39 -34 3 56 64 176
40 -34 3 56 64 176
23 -33 3 208 128 92
24 -33 3 208 128 92
25 -33 3 208 128 92
26 -33 3 208 128 92
27 -33 3 124 208 172
28 -33 3 124 208 172
35 -33 3 124 208 172
36 -33 3 124 208 172
37 -33 3 56 64 176
38 -33 3 56 64 176
39 -33 3 56 64 176
40 -33 3 56 64 176
23 -32 3 232 232 92
24 -32 3 232 232 92
25 -32 3 192 88 88
26 -32 3 192 88 88
27 -32 3 124 208 172
28 -32 3 124 208 172
29 -32 3 124 208 172
30 -32 3 124 208 172
31 -32 3 124 208 172
32 -32 3 124 208 172
33 -32 3 124 208 172
34 -32 3 124 208 172
35 -32 3 124 208 172
36 -32 3 124 208 172
37 -32 3 192 88 88
38 -32 3 192 88 88
39 -32 3 232 232 92
40 -32 3 232 232 92
23 -31 3 232 232 92
24 -31 3 232 232 92
25 -31 3 192 88 88
26 -31 3 192 88 88
27 -31 3 124 208 172
28 -31 3 124 208 172
29 -31 3 124 208 172
30 -31 3 124 208 172
31 -31 3 124 208 172
32 -31 3 124 208 172
33 -31 3 124 208 172
34 -31 3 124 208 172
35 -31 3 124 208 172
36 -31 3 124 208 172
37 -31 3 192 88 88
38 -31 3 192 88 88
39 -31 3 232 232 92
40 -31 3 232 232 92
22 -30 3 92 156 92
23 -30 3 92 156 92
24 -30 3 92 156 92
25 -30 3 252 252 104
26 -30 3 252 252 104
27 -30 3 252 252 104
36 -30 3 80 92 192
37 -30 3 80 92 192
38 -30 3 80 92 192
39 -30 3 208 128 92
40 -30 3 208 128 92
41 -30 3 208 128 92
22 -29 3 92 156 92
23 -29 3 92 156 92
24 -29 3 92 156 92
25 -29 3 252 252 104
26 -29 3 252 252 104
37 -29 3 80 92 192
38 -29 3 80 92 192
39 -29 3 208 128 92
40 -29 3 208 128 92
41 -29 3 208 128 92
3 -45 4 100 72 24
4 -45 4 100 72 24
5 -45 4 100 72 24
6 -45 4 100 72 24
7 -45 4 100 72 24
8 -45 4 100 72 24
9 -45 4 100 72 24
10 -45 4 100 72 24
11 -45 4 100 72 24
12 -45 4 100 72 24
13 -45 4 100 72 24
14 -45 4 100 72 24
15 -45 4 100 72 24
16 -45 4 100 72 24
17 -45 4 100 72 24
18 -45 4 100 72 24
19 -45 4 100 72 24
20 -45 4 100 72 24
21 -45 4 100 72 24
22 -45 4 100 72 24
23 -45 4 100 72 24
24 -45 4 100 72 24
25 -45 4 100 72 24
26 -45 4 100 72 24
27 -45 4 100 72 24
28 -45 4 100 72 24
29 -45 4 100 72 24
30 -45 4 100 72 24
31 -45 4 100 72 24
32 -45 4 100 72 24
33 -45 4 100 72 24
34 -45 4 100 72 24
35 -45 4 100 72 24
36 -45 4 100 72 24
37 -45 4 100 72 24
38 -45 4 100 72 24
39 -45 4 100 72 24
40 -45 4 100 72 24
41 -45 4 100 72 24
42 -45 4 100 72 24
43 -45 4 100 72 24
44 -45 4 100 72 24
45 -45 4 100 72 24
46 -45 4 100 72 24
47 -45 4 100 72 24
48 -45 4 100 72 24
49 -45 4 100 72 24
50 -45 4 100 72 24
51 -45 4 100 72 24
52 -45 4 100 72 24
53 -45 4 100 72 24
54 -45 4 100 72 24
55 -45 4 100 72 24
56 -45 4 100 72 24
57 -45 4 100 72 24
58 -45 4 100 72 24
59 -45 4 100 72 24
60 -45 4 100 72 24
61 -45 4 100 72 24
62 -45 4 100 72 24
4 -44 4 132 104 48
5 -44 4 160 132 68
6 -44 4 160 132 68
7 -44 4 160 132 68
8 -44 4 160 132 68
9 -44 4 160 132 68
10 -44 4 184 156 88
11 -44 4 132 104 48
12 -44 4 160 132 68
13 -44 4 160 132 68
14 -44 4 160 132 68
15 -44 4 160 132 68
16 -44 4 160 132 68
17 -44 4 160 132 68
18 -44 4 160 132 68
19 -44 4 160 132 68
20 -44 4 160 132 68
21 -44 4 160 132 68
22 -44 4 160 132 68
23 -44 4 160 132 68
24 -44 4 160 132 68
25 -44 4 160 132 68
26 -44 4 184 156 88
27 -44 4 132 104 48
28 -44 4 160 132 68
29 -44 4 160 132 68
30 -44 4 160 132 68
31 -44 4 160 132 68
32 -44 4 160 132 68
33 -44 4 160 132 68
34 -44 4 160 132 68
35 -44 4 160 132 68
36 -44 4 160 132 68
37 -44 4 160 132 68
38 -44 4 160 132 68
39 -44 4 160 132 68
40 -44 4 160 132 68
41 -44 4 160 132 68
42 -44 4 184 156 88
43 -44 4 132 104 48
44 -44 4 160 132 68
45 -44 4 160 132 68
46 -44 4 160 132 68
47 -44 4 160 132 68
48 -44 4 160 132 68
49 -44 4 160 132 68
50 -44 4 160 132 68
51 -44 4 160 132 68
52 -44 4 160 132 68
53 -44 4 160 132 68
54 -44 4 184 156 88
55 -44 4 132 104 48
56 -44 4 160 132 68
57 -44 4 160 132 68
58 -44 4 160 132 68
59 -44 4 160 132 68
60 -44 4 160 132 68
61 -44 4 132 104 48
22 -43 4 192 88 88
23 -43 4 192 88 88
24 -43 4 192 88 88
25 -43 4 192 88 88
26 -43 4 192 88 88
27 -43 4 192 88 88
28 -43 4 192 88 88
29 -43 4 192 88 88
30 -43 4 192 88 88
31 -43 4 192 88 88
32 -43 4 192 88 88
33 -43 4 192 88 88
34 -43 4 192 88 88
35 -43 4 192 88 88
36 -43 4 192 88 88
37 -43 4 192 88 88
38 -43 4 192 88 88
39 -43 4 192 88 88
40 -43 4 192 88 88
41 -43 4 192 88 88
23 -42 4 120 60 164
24 -42 4 120 60 164
25 -42 4 120 60 164
26 -42 4 120 60 164
37 -42 4 192 88 88
38 -42 4 192 88 88
39 -42 4 192 88 88
40 -42 4 192 88 88
23 -41 4 120 60 164
24 -41 4 120 60 164
25 -41 4 120 60 164
26 -41 4 120 60 164
37 -41 4 192 88 88
38 -41 4 192 88 88
39 -41 4 192 88 88
40 -41 4 192 88 88
23 -40 4 176 88 156
24 -40 4 176 88 156
25 -40 4 252 252 104
26 -40 4 252 252 104
37 -40 4 252 252 104
38 -40 4 252 252 104
39 -40 4 176 88 156
40 -40 4 176 88 156
23 -39 4 176 88 156
24 -39 4 176 88 156
25 -39 4 252 252 104
26 -39 4 252 252 104
37 -39 4 252 252 104
38 -39 4 252 252 104
39 -39 4 176 88 156
40 -39 4 176 88 156
23 -38 4 104 116 208
24 -38 4 104 116 208
25 -38 4 104 116 208
26 -38 4 104 116 208
37 -38 4 92 156 92
38 -38 4 92 156 92
39 -38 4 92 156 92
40 -38 4 92 156 92
23 -37 4 104 116 208
24 -37 4 104 116 208
25 -37 4 104 116 208
26 -37 4 104 116 208
37 -37 4 92 156 92
38 -37 4 92 156 92
39 -37 4 92 156 92
40 -37 4 92 156 92
23 -36 4 192 88 88
24 -36 4 192 88 88
25 -36 4 120 60 164
26 -36 4 120 60 164
37 -36 4 120 60 164
38 -36 4 120 60 164
39 -36 4 192 88 88
40 -36 4 192 88 88
23 -35 4 192 88 88
24 -35 4 192 88 88
25 -35 4 120 60 164
26 -35 4 120 60 164
37 -35 4 120 60 164
38 -35 4 120 60 164
39 -35 4 192 88 88
40 -35 4 192 88 88
23 -34 4 56 64 176
24 -34 4 56 64 176
25 -34 4 56 64 176
26 -34 4 56 64 176
27 -34 4 124 208 172
36 -34 4 124 208 172
37 -34 4 208 128 92
38 -34 4 208 128 92
39 -34 4 208 128 92
40 -34 4 208 128 92
23 -33 4 56 64 176
24 -33 4 56 64 176
25 -33 4 56 64 176
26 -33 4 56 64 176
27 -33 4 124 208 172
28 -33 4 124 208 172
35 -33 4 124 208 172
36 -33 4 124 208 172
37 -33 4 208 128 92
38 -33 4 208 128 92
39 -33 4 208 128 92
40 -33 4 208 128 92
23 -32 4 232 232 92
24 -32 4 232 232 92
25 -32 4 192 88 88
26 -32 4 192 88 88
27 -32 4 124 208 172
28 -32 4 124 208 172
29 -32 4 124 208 172
30 -32 4 124 208 172
31 -32 4 124 208 172
32 -32 4 124 208 172
33 -32 4 124 208 172
34 -32 4 124 208 172
35 -32 4 124 208 172
36 -32 4 124 208 172
37 -32 4 192 88 88
38 -32 4 192 88 88
39 -32 4 232 232 92
40 -32 4 232 232 92
23 -31 4 232 232 92
24 -31 4 232 232 92
25 -31 4 192 88 88
26 -31 4 192 88 88
27 -31 4 124 208 172
28 -31 4 124 208 172
29 -31 4 124 208 172
30 -31 4 124 208 172
31 -31 4 124 208 172
32 -31 4 124 208 172
33 -31 4 124 208 172
34 -31 4 124 208 172
35 -31 4 124 208 172
36 -31 4 124 208 172
37 -31 4 192 88 88
38 -31 4 192 88 88
39 -31 4 232 232 92
40 -31 4 232 232 92
22 -30 4 208 128 92
23 -30 4 208 128 92
24 -30 4 208 128 92
25 -30 4 80 92 192
26 -30 4 80 92 192
27 -30 4 80 92 192
36 -30 4 252 252 104
37 -30 4 252 252 104
38 -30 4 252 252 104
39 -30 4 92 156 92
40 -30 4 92 156 92
41 -30 4 92 156 92
22 -29 4 208 128 92
23 -29 4 208 128 92
24 -29 4 208 128 92
25 -29 4 80 92 192
26 -29 4 80 92 192
37 -29 4 252 252 104
38 -29 4 252 252 104
39 -29 4 92 156 92
40 -29 4 92 156 92
41 -29 4 92 156 92
3 -45 5 100 72 24
4 -45 5 100 72 24
5 -45 5 100 72 24
6 -45 5 100 72 24
7 -45 5 100 72 24
8 -45 5 100 72 24
9 -45 5 100 72 24
10 -45 5 100 72 24
11 -45 5 100 72 24
12 -45 5 100 72 24
13 -45 5 100 72 24
14 -45 5 100 72 24
15 -45 5 100 72 24
16 -45 5 100 72 24
17 -45 5 100 72 24
18 -45 5 100 72 24
19 -45 5 100 72 24
20 -45 5 100 72 24
21 -45 5 100 72 24
22 -45 5 100 72 24
23 -45 5 100 72 24
24 -45 5 100 72 24
25 -45 5 100 72 24
26 -45 5 100 72 24
27 -45 5 100 72 24
28 -45 5 100 72 24
29 -45 5 100 72 24
30 -45 5 100 72 24
31 -45 5 100 72 24
32 -45 5 100 72 24
33 -45 5 100 72 24
34 -45 5 100 72 24
35 -45 5 100 72 24
36 -45 5 100 72 24
37 -45 5 100 72 24
38 -45 5 100 72 24
39 -45 5 100 72 24
40 -45 5 100 72 24
41 -45 5 100 72 24
42 -45 5 100 72 24
43 -45 5 100 72 24
44 -45 5 100 72 24
45 -45 5 100 72 24
46 -45 5 100 72 24
47 -45 5 100 72 24
48 -45 5 100 72 24
49 -45 5 100 72 24
50 -45 5 100 72 24
51 -45 5 100 72 24
52 -45 5 100 72 24
53 -45 5 100 72 24
54 -45 5 100 72 24
55 -45 5 100 72 24
56 -45 5 100 72 24
57 -45 5 100 72 24
58 -45 5 100 72 24
59 -45 5 100 72 24
60 -45 5 100 72 24
61 -45 5 100 72 24
62 -45 5 100 72 24
4 -44 5 132 104 48
5 -44 5 160 132 68
6 -44 5 160 132 68
7 -44 5 160 132 68
8 -44 5 160 132 68
9 -44 5 160 132 68
10 -44 5 184 156 88
11 -44 5 132 104 48
12 -44 5 160 132 68
13 -44 5 160 132 68
14 -44 5 160 132 68
15 -44 5 160 132 68
16 -44 5 160 132 68
17 -44 5 160 132 68
18 -44 5 160 132 68
19 -44 5 160 132 68
20 -44 5 160 132 68
21 -44 5 160 132 68
22 -44 5 160 132 68
23 -44 5 160 132 68
24 -44 5 160 132 68
25 -44 5 160 132 68
26 -44 5 184 156 88
27 -44 5 132 104 48
28 -44 5 160 132 68
29 -44 5 160 132 68
30 -44 5 160 132 68
31 -44 5 160 132 68
32 -44 5 160 132 68
33 -44 5 160 132 68
34 -44 5 160 132 68
35 -44 5 160 132 68
36 -44 5 160 132 68
37 -44 5 160 132 68
38 -44 5 160 132 68
39 -44 5 160 132 68
40 -44 5 160 132 68
41 -44 5 160 132 68
42 -44 5 184 156 88
43 -44 5 132 104 48
44 -44 5 160 132 68
45 -44 5 160 132 68
46 -44 5 160 132 68
47 -44 5 160 132 68
48 -44 5 160 132 68
49 -44 5 160 132 68
50 -44 5 160 132 68
51 -44 5 160 132 68
52 -44 5 160 132 68
53 -44 5 160 132 68
54 -44 5 184 156 88
55 -44 5 132 104 48
56 -44 5 160 132 68
57 -44 5 160 132 68
58 -44 5 160 132 68
59 -44 5 160 132 68
60 -44 5 160 132 68
61 -44 5 132 104 48
22 -43 5 192 88 88
23 -43 5 192 88 88
24 -43 5 192 88 88
25 -43 5 192 88 88
26 -43 5 192 88 88
27 -43 5 192 88 88
28 -43 5 192 88 88
29 -43 5 192 88 88
30 -43 5 192 88 88
31 -43 5 192 88 88
32 -43 5 192 88 88
33 -43 5 192 88 88
34 -43 5 192 88 88
35 -43 5 192 88 88
36 -43 5 192 88 88
37 -43 5 192 88 88
38 -43 5 192 88 88
39 -43 5 192 88 88
40 -43 5 192 88 88
41 -43 5 192 88 88
23 -42 5 120 60 164
24 -42 5 120 60 164
25 -42 5 120 60 164
26 -42 5 120 60 164
37 -42 5 192 88 88
38 -42 5 192 88 88
39 -42 5 192 88 88
40 -42 5 192 88 88
23 -41 5 120 60 164
24 -41 5 120 60 164
25 -41 5 120 60 164
26 -41 5 120 60 164
37 -41 5 192 88 88
38 -41 5 192 88 88
39 -41 5 192 88 88
40 -41 5 192 88 88
23 -40 5 176 88 156
24 -40 5 176 88 156
25 -40 5 252 252 104
26 -40 5 252 252 104
37 -40 5 252 252 104
38 -40 5 252 252 104
39 -40 5 176 88 156
40 -40 5 176 88 156
23 -39 5 176 88 156
24 -39 5 176 88 156
25 -39 5 252 252 104
26 -39 5 252 252 104
37 -39 5 252 252 104
38 -39 5 252 252 104
39 -39 5 176 88 156
40 -39 5 176 88 156
23 -38 5 104 116 208
24 -38 5 104 116 208
25 -38 5 104 116 208
26 -38 5 104 116 208
37 -38 5 92 156 92
38 -38 5 92 156 92
39 -38 5 92 156 92
40 -38 5 92 156 92
23 -37 5 104 116 208
24 -37 5 104 116 208
25 -37 5 104 116 208
26 -37 5 104 116 208
37 -37 5 92 156 92
38 -37 5 92 156 92
39 -37 5 92 156 92
40 -37 5 92 156 92
23 -36 5 192 88 88
24 -36 5 192 88 88
25 -36 5 120 60 164
26 -36 5 120 60 164
37 -36 5 120 60 164
38 -36 5 120 60 164
39 -36 5 192 88 88
40 -36 5 192 88 88
23 -35 5 192 88 88
24 -35 5 192 88 88
25 -35 5 120 60 164
26 -35 5 120 60 164
37 -35 5 120 60 164
38 -35 5 120 60 164
39 -35 5 192 88 88
40 -35 5 192 88 88
23 -34 5 56 64 176
24 -34 5 56 64 176
25 -34 5 56 64 176
26 -34 5 56 64 176
37 -34 5 208 128 92
38 -34 5 208 128 92
39 -34 5 208 128 92
40 -34 5 208 128 92
23 -33 5 56 64 176
24 -33 5 56 64 176
25 -33 5 56 64 176
26 -33 5 56 64 176
37 -33 5 208 128 92
38 -33 5 208 128 92
39 -33 5 208 128 92
40 -33 5 208 128 92
23 -32 5 232 232 92
24 -32 5 232 232 92
25 -32 5 192 88 88
26 -32 5 192 88 88
37 -32 5 192 88 88
38 -32 5 192 88 88
39 -32 5 232 232 92
40 -32 5 232 232 92
23 -31 5 232 232 92
24 -31 5 232 232 92
25 -31 5 192 88 88
26 -31 5 192 88 88
37 -31 5 192 88 88
38 -31 5 192 88 88
39 -31 5 232 232 92
40 -31 5 232 232 92
22 -30 5 208 128 92
23 -30 5 208 128 92
24 -30 5 208 128 92
25 -30 5 80 92 192
26 -30 5 80 92 192
27 -30 5 80 92 192
36 -30 5 252 252 104
37 -30 5 252 252 104
38 -30 5 252 252 104
39 -30 5 92 156 92
40 -30 5 92 156 92
41 -30 5 92 156 92
22 -29 5 208 128 92
23 -29 5 208 128 92
24 -29 5 208 128 92
25 -29 5 80 92 192
26 -29 5 80 92 192
27 -29 5 80 92 192
36 -29 5 252 252 104
37 -29 5 252 252 104
38 -29 5 252 252 104
39 -29 5 92 156 92
40 -29 5 92 156 92
41 -29 5 92 156 92
22 -28 5 160 112 204
23 -28 5 160 112 204
26 -28 5 124 208 172
27 -28 5 124 208 172
36 -28 5 104 116 208
37 -28 5 104 116 208
40 -28 5 192 88 88
41 -28 5 192 88 88
22 -27 5 160 112 204
23 -27 5 160 112 204
26 -27 5 124 208 172
27 -27 5 124 208 172
36 -27 5 104 116 208
37 -27 5 104 116 208
40 -27 5 192 88 88
41 -27 5 192 88 88
3 -45 6 100 72 24
4 -45 6 100 72 24
5 -45 6 100 72 24
6 -45 6 100 72 24
7 -45 6 100 72 24
8 -45 6 100 72 24
9 -45 6 100 72 24
10 -45 6 100 72 24
11 -45 6 100 72 24
12 -45 6 100 72 24
13 -45 6 100 72 24
14 -45 6 100 72 24
15 -45 6 100 72 24
16 -45 6 100 72 24
17 -45 6 100 72 24
18 -45 6 100 72 24
19 -45 6 100 72 24
20 -45 6 100 72 24
21 -45 6 100 72 24
22 -45 6 100 72 24
23 -45 6 100 72 24
24 -45 6 100 72 24
25 -45 6 100 72 24
26 -45 6 100 72 24
27 -45 6 100 72 24
28 -45 6 100 72 24
29 -45 6 100 72 24
30 -45 6 100 72 24
31 -45 6 100 72 24
32 -45 6 100 72 24
33 -45 6 100 72 24
34 -45 6 100 72 24
35 -45 6 100 72 24
36 -45 6 100 72 24
37 -45 6 100 72 24
38 -45 6 100 72 24
39 -45 6 100 72 24
40 -45 6 100 72 24
41 -45 6 100 72 24
42 -45 6 100 72 24
43 -45 6 100 72 24
44 -45 6 100 72 24
45 -45 6 100 72 24
46 -45 6 100 72 24
47 -45 6 100 72 24
48 -45 6 100 72 24
49 -45 6 100 72 24
50 -45 6 100 72 24
51 -45 6 100 72 24
52 -45 6 100 72 24
53 -45 6 100 72 24
54 -45 6 100 72 24
55 -45 6 100 72 24
56 -45 6 100 72 24
57 -45 6 100 72 24
58 -45 6 100 72 24
59 -45 6 100 72 24
60 -45 6 100 72 24
61 -45 6 100 72 24
62 -45 6 100 72 24
4 -44 6 132 104 48
5 -44 6 132 104 48
6 -44 6 132 104 48
7 -44 6 132 104 48
8 -44 6 132 104 48
9 -44 6 132 104 48
10 -44 6 132 104 48
11 -44 6 132 104 48
12 -44 6 132 104 48
13 -44 6 132 104 48
14 -44 6 132 104 48
15 -44 6 132 104 48
16 -44 6 132 104 48
17 -44 6 132 104 48
18 -44 6 132 104 48
19 -44 6 132 104 48
20 -44 6 132 104 48
21 -44 6 132 104 48
22 -44 6 132 104 48
23 -44 6 132 104 48
24 -44 6 132 104 48
25 -44 6 132 104 48
26 -44 6 132 104 48
27 -44 6 132 104 48
28 -44 6 132 104 48
29 -44 6 132 104 48
30 -44 6 132 104 48
31 -44 6 132 104 48
32 -44 6 132 104 48
33 -44 6 132 104 48
34 -44 6 132 104 48
35 -44 6 132 104 48
36 -44 6 132 104 48
37 -44 6 132 104 48
38 -44 6 132 104 48
39 -44 6 132 104 48
40 -44 6 132 104 48
41 -44 6 132 104 48
42 -44 6 132 104 48
43 -44 6 132 104 48
44 -44 6 132 104 48
45 -44 6 132 104 48
46 -44 6 132 104 48
47 -44 6 132 104 48
48 -44 6 132 104 48
49 -44 6 132 104 48
50 -44 6 132 104 48
51 -44 6 132 104 48
52 -44 6 132 104 48
53 -44 6 132 104 48
54 -44 6 132 104 48
55 -44 6 132 104 48
56 -44 6 132 104 48
57 -44 6 132 104 48
58 -44 6 132 104 48
59 -44 6 132 104 48
60 -44 6 132 104 48
61 -44 6 132 104 48
22 -43 6 192 88 88
23 -43 6 192 88 88
24 -43 6 192 88 88
25 -43 6 192 88 88
26 -43 6 192 88 88
27 -43 6 192 88 88
28 -43 6 192 88 88
29 -43 6 192 88 88
30 -43 6 192 88 88
31 -43 6 192 88 88
32 -43 6 192 88 88
33 -43 6 192 88 88
34 -43 6 192 88 88
35 -43 6 192 88 88
36 -43 6 192 88 88
37 -43 6 192 88 88
38 -43 6 192 88 88
39 -43 6 192 88 88
40 -43 6 192 88 88
41 -43 6 192 88 88
24 -34 6 80 92 192
25 -34 6 80 92 192
38 -34 6 192 88 88
39 -34 6 192 88 88
24 -33 6 80 92 192
25 -33 6 80 92 192
38 -33 6 192 88 88
39 -33 6 192 88 88
24 -32 6 80 92 192
25 -32 6 80 92 192
38 -32 6 192 88 88
39 -32 6 192 88 88
23 -31 6 120 60 164
24 -31 6 80 92 192
25 -31 6 80 92 192
38 -31 6 192 88 88
39 -31 6 192 88 88
40 -31 6 92 156 92
22 -30 6 208 128 92
23 -30 6 208 128 92
24 -30 6 208 128 92
25 -30 6 80 92 192
26 -30 6 80 92 192
27 -30 6 80 92 192
36 -30 6 252 252 104
37 -30 6 252 252 104
38 -30 6 252 252 104
39 -30 6 92 156 92
40 -30 6 92 156 92
41 -30 6 92 156 92
22 -29 6 208 128 92
23 -29 6 208 128 92
26 -29 6 80 92 192
27 -29 6 80 92 192
36 -29 6 252 252 104
37 -29 6 252 252 104
40 -29 6 92 156 92
41 -29 6 92 156 92
22 -28 6 160 112 204
23 -28 6 160 112 204
26 -28 6 124 208 172
27 -28 6 124 208 172
36 -28 6 104 116 208
37 -28 6 104 116 208
40 -28 6 192 88 88
41 -28 6 192 88 88
22 -27 6 160 112 204
23 -27 6 160 112 204
26 -27 6 124 208 172
27 -27 6 124 208 172
36 -27 6 104 116 208
37 -27 6 104 116 208
40 -27 6 192 88 88
41 -27 6 192 88 88
3 -45 7 100 72 24
4 -45 7 100 72 24
5 -45 7 100 72 24
6 -45 7 100 72 24
7 -45 7 100 72 24
8 -45 7 100 72 24
9 -45 7 100 72 24
10 -45 7 100 72 24
11 -45 7 100 72 24
12 -45 7 100 72 24
13 -45 7 100 72 24
14 -45 7 100 72 24
15 -45 7 100 72 24
16 -45 7 100 72 24
17 -45 7 100 72 24
18 -45 7 100 72 24
19 -45 7 100 72 24
20 -45 7 100 72 24
21 -45 7 100 72 24
22 -45 7 100 72 24
23 -45 7 100 72 24
24 -45 7 100 72 24
25 -45 7 100 72 24
26 -45 7 100 72 24
27 -45 7 100 72 24
28 -45 7 100 72 24
29 -45 7 100 72 24
30 -45 7 100 72 24
31 -45 7 100 72 24
32 -45 7 100 72 24
33 -45 7 100 72 24
34 -45 7 100 72 24
35 -45 7 100 72 24
36 -45 7 100 72 24
37 -45 7 100 72 24
38 -45 7 100 72 24
39 -45 7 100 72 24
40 -45 7 100 72 24
41 -45 7 100 72 24
42 -45 7 100 72 24
43 -45 7 100 72 24
44 -45 7 100 72 24
45 -45 7 100 72 24
46 -45 7 100 72 24
47 -45 7 100 72 24
48 -45 7 100 72 24
49 -45 7 100 72 24
50 -45 7 100 72 24
51 -45 7 100 72 24
52 -45 7 100 72 24
53 -45 7 100 72 24
54 -45 7 100 72 24
55 -45 7 100 72 24
56 -45 7 100 72 24
57 -45 7 100 72 24
58 -45 7 100 72 24
59 -45 7 100 72 24
60 -45 7 100 72 24
61 -45 7 100 72 24
62 -45 7 100 72 24
4 -44 7 132 104 48
5 -44 7 184 156 88
6 -44 7 184 156 88
7 -44 7 132 104 48
8 -44 7 160 132 68
9 -44 7 160 132 68
10 -44 7 160 132 68
11 -44 7 160 132 68
12 -44 7 160 132 68
13 -44 7 160 132 68
14 -44 7 160 132 68
15 -44 7 160 132 68
16 -44 7 160 132 68
17 -44 7 160 132 68
18 -44 7 160 132 68
19 -44 7 160 132 68
20 -44 7 184 156 88
21 -44 7 184 156 88
22 -44 7 132 104 48
23 -44 7 160 132 68
24 -44 7 160 132 68
25 -44 7 160 132 68
26 -44 7 160 132 68
27 -44 7 160 132 68
28 -44 7 160 132 68
29 -44 7 160 132 68
30 -44 7 160 132 68
31 -44 7 160 132 68
32 -44 7 160 132 68
33 -44 7 160 132 68
34 -44 7 160 132 68
35 -44 7 160 132 68
36 -44 7 184 156 88
37 -44 7 184 156 88
38 -44 7 132 104 48
39 -44 7 160 132 68
40 -44 7 160 132 68
41 -44 7 160 132 68
42 -44 7 160 132 68
43 -44 7 160 132 68
44 -44 7 160 132 68
45 -44 7 160 132 68
46 -44 7 160 132 68
47 -44 7 160 132 68
48 -44 7 184 156 88
49 -44 7 184 156 88
50 -44 7 132 104 48
51 -44 7 160 132 68
52 -44 7 160 132 68
53 -44 7 160 132 68
54 -44 7 160 132 68
55 -44 7 160 132 68
56 -44 7 160 132 68
57 -44 7 160 132 68
58 -44 7 160 132 68
59 -44 7 160 132 68
60 -44 7 160 132 68
61 -44 7 132 104 48
22 -43 7 192 88 88
23 -43 7 192 88 88
24 -43 7 192 88 88
25 -43 7 192 88 88
26 -43 7 192 88 88
27 -43 7 192 88 88
28 -43 7 192 88 88
29 -43 7 192 88 88
30 -43 7 192 88 88
31 -43 7 192 88 88
32 -43 7 192 88 88
33 -43 7 192 88 88
34 -43 7 192 88 88
35 -43 7 192 88 88
36 -43 7 192 88 88
37 -43 7 192 88 88
38 -43 7 192 88 88
39 -43 7 192 88 88
40 -43 7 192 88 88
41 -43 7 192 88 88
24 -33 7 80 92 192
25 -33 7 80 92 192
38 -33 7 192 88 88
39 -33 7 192 88 88
24 -32 7 80 92 192
25 -32 7 80 92 192
38 -32 7 192 88 88
39 -32 7 192 88 88
23 -31 7 120 60 164
24 -31 7 80 92 192
25 -31 7 80 92 192
38 -31 7 192 88 88
39 -31 7 192 88 88
40 -31 7 92 156 92
23 -30 7 120 60 164
40 -30 7 92 156 92
23 -29 7 120 60 164
40 -29 7 92 156 92
3 -45 8 100 72 24
4 -45 8 100 72 24
5 -45 8 100 72 24
6 -45 8 100 72 24
7 -45 8 100 72 24
8 -45 8 100 72 24
9 -45 8 100 72 24
10 -45 8 100 72 24
11 -45 8 100 72 24
12 -45 8 100 72 24
13 -45 8 100 72 24
14 -45 8 100 72 24
15 -45 8 100 72 24
16 -45 8 100 72 24
17 -45 8 100 72 24
18 -45 8 100 72 24
19 -45 8 100 72 24
20 -45 8 100 72 24
21 -45 8 100 72 24
22 -45 8 100 72 24
23 -45 8 100 72 24
24 -45 8 100 72 24
25 -45 8 100 72 24
26 -45 8 100 72 24
27 -45 8 100 72 24
28 -45 8 100 72 24
29 -45 8 100 72 24
30 -45 8 100 72 24
31 -45 8 100 72 24
32 -45 8 100 72 24
33 -45 8 100 72 24
34 -45 8 100 72 24
35 -45 8 100 72 24
36 -45 8 100 72 24
37 -45 8 100 72 24
38 -45 8 100 72 24
39 -45 8 100 72 24
40 -45 8 100 72 24
41 -45 8 100 72 24
42 -45 8 100 72 24
43 -45 8 100 72 24
44 -45 8 100 72 24
45 -45 8 100 72 24
46 -45 8 100 72 24
47 -45 8 100 72 24
48 -45 8 100 72 24
49 -45 8 100 72 24
50 -45 8 100 72 24
51 -45 8 100 72 24
52 -45 8 100 72 24
53 -45 8 100 72 24
54 -45 8 100 72 24
55 -45 8 100 72 24
56 -45 8 100 72 24
57 -45 8 100 72 24
58 -45 8 100 72 24
59 -45 8 100 72 24
60 -45 8 100 72 24
61 -45 8 100 72 24
62 -45 8 100 72 24
4 -44 8 132 104 48
5 -44 8 160 132 68
6 -44 8 184 156 88
7 -44 8 132 104 48
8 -44 8 160 132 68
9 -44 8 160 132 68
10 -44 8 160 132 68
11 -44 8 160 132 68
12 -44 8 160 132 68
13 -44 8 160 132 68
14 -44 8 160 132 68
15 -44 8 160 132 68
16 -44 8 160 132 68
17 -44 8 160 132 68
18 -44 8 160 132 68
19 -44 8 160 132 68
20 -44 8 160 132 68
21 -44 8 184 156 88
22 -44 8 132 104 48
23 -44 8 160 132 68
24 -44 8 160 132 68
25 -44 8 160 132 68
26 -44 8 160 132 68
27 -44 8 160 132 68
28 -44 8 160 132 68
29 -44 8 160 132 68
30 -44 8 160 132 68
31 -44 8 160 132 68
32 -44 8 160 132 68
33 -44 8 160 132 68
34 -44 8 160 132 68
35 -44 8 160 132 68
36 -44 8 160 132 68
37 -44 8 184 156 88
38 -44 8 132 104 48
39 -44 8 160 132 68
40 -44 8 160 132 68
41 -44 8 160 132 68
42 -44 8 160 132 68
43 -44 8 160 132 68
44 -44 8 160 132 68
45 -44 8 160 132 68
46 -44 8 160 132 68
47 -44 8 160 132 68
48 -44 8 160 132 68
49 -44 8 184 156 88
50 -44 8 132 104 48
51 -44 8 160 132 68
52 -44 8 160 132 68
53 -44 8 160 132 68
54 -44 8 160 132 68
55 -44 8 160 132 68
56 -44 8 160 132 68
57 -44 8 160 132 68
58 -44 8 160 132 68
59 -44 8 160 132 68
60 -44 8 160 132 68
61 -44 8 132 104 48
22 -43 8 192 88 88
23 -43 8 192 88 88
24 -43 8 192 88 88
25 -43 8 192 88 88
26 -43 8 192 88 88
27 -43 8 192 88 88
28 -43 8 192 88 88
29 -43 8 192 88 88
30 -43 8 192 88 88
31 -43 8 192 88 88
32 -43 8 192 88 88
33 -43 8 192 88 88
34 -43 8 192 88 88
35 -43 8 192 88 88
36 -43 8 192 88 88
37 -43 8 192 88 88
38 -43 8 192 88 88
39 -43 8 192 88 88
40 -43 8 192 88 88
41 -43 8 192 88 88
24 -32 8 80 92 192
25 -32 8 80 92 192
38 -32 8 192 88 88
39 -32 8 192 88 88
23 -31 8 120 60 164
24 -31 8 80 92 192
25 -31 8 80 92 192
38 -31 8 192 88 88
39 -31 8 192 88 88
40 -31 8 92 156 92
23 -30 8 120 60 164
40 -30 8 92 156 92
23 -29 8 120 60 164
40 -29 8 92 156 92
3 -45 9 100 72 24
4 -45 9 100 72 24
5 -45 9 100 72 24
6 -45 9 100 72 24
7 -45 9 100 72 24
8 -45 9 100 72 24
9 -45 9 100 72 24
10 -45 9 100 72 24
11 -45 9 100 72 24
12 -45 9 100 72 24
13 -45 9 100 72 24
14 -45 9 100 72 24
15 -45 9 100 72 24
16 -45 9 100 72 24
17 -45 9 100 72 24
18 -45 9 100 72 24
19 -45 9 100 72 24
20 -45 9 100 72 24
21 -45 9 100 72 24
22 -45 9 100 72 24
23 -45 9 100 72 24
24 -45 9 100 72 24
25 -45 9 100 72 24
26 -45 9 100 72 24
27 -45 9 100 72 24
28 -45 9 100 72 24
29 -45 9 100 72 24
30 -45 9 100 72 24
31 -45 9 100 72 24
32 -45 9 100 72 24
33 -45 9 100 72 24
34 -45 9 100 72 24
35 -45 9 100 72 24
36 -45 9 100 72 24
37 -45 9 100 72 24
38 -45 9 100 72 24
39 -45 9 100 72 24
40 -45 9 100 72 24
41 -45 9 100 72 24
42 -45 9 100 72 24
43 -45 9 100 72 24
44 -45 9 100 72 24
45 -45 9 100 72 24
46 -45 9 100 72 24
47 -45 9 100 72 24
48 -45 9 100 72 24
49 -45 9 100 72 24
50 -45 9 100 72 24
51 -45 9 100 72 24
52 -45 9 100 72 24
53 -45 9 100 72 24
54 -45 9 100 72 24
55 -45 9 100 72 24
56 -45 9 100 72 24
57 -45 9 100 72 24
58 -45 9 100 72 24
59 -45 9 100 72 24
60 -45 9 100 72 24
61 -45 9 100 72 24
62 -45 9 100 72 24
4 -44 9 132 104 48
5 -44 9 160 132 68
6 -44 9 184 156 88
7 -44 9 132 104 48
8 -44 9 160 132 68
9 -44 9 160 132 68
10 -44 9 160 132 68
11 -44 9 160 132 68
12 -44 9 160 132 68
13 -44 9 160 132 68
14 -44 9 160 132 68
15 -44 9 160 132 68
16 -44 9 160 132 68
17 -44 9 160 132 68
18 -44 9 160 132 68
19 -44 9 160 132 68
20 -44 9 160 132 68
21 -44 9 184 156 88
22 -44 9 132 104 48
23 -44 9 160 132 68
24 -44 9 160 132 68
25 -44 9 160 132 68
26 -44 9 160 132 68
27 -44 9 160 132 68
28 -44 9 160 132 68
29 -44 9 160 132 68
30 -44 9 160 132 68
31 -44 9 160 132 68
32 -44 9 160 132 68
33 -44 9 160 132 68
34 -44 9 160 132 68
35 -44 9 160 132 68
36 -44 9 160 132 68
37 -44 9 184 156 88
38 -44 9 132 104 48
39 -44 9 160 132 68
40 -44 9 160 132 68
41 -44 9 160 132 68
42 -44 9 160 132 68
43 -44 9 160 132 68
44 -44 9 160 132 68
45 -44 9 160 132 68
46 -44 9 160 132 68
47 -44 9 160 132 68
48 -44 9 160 132 68
49 -44 9 184 156 88
50 -44 9 132 104 48
51 -44 9 160 132 68
52 -44 9 160 132 68
53 -44 9 160 132 68
54 -44 9 160 132 68
55 -44 9 160 132 68
56 -44 9 160 132 68
57 -44 9 160 132 68
58 -44 9 160 132 68
59 -44 9 160 132 68
60 -44 9 160 132 68
61 -44 9 132 104 48
22 -43 9 192 88 88
23 -43 9 192 88 88
24 -43 9 192 88 88
25 -43 9 192 88 88
26 -43 9 192 88 88
27 -43 9 192 88 88
28 -43 9 192 88 88
29 -43 9 192 88 88
30 -43 9 192 88 88
31 -43 9 192 88 88
32 -43 9 192 88 88
33 -43 9 192 88 88
34 -43 9 192 88 88
35 -43 9 192 88 88
36 -43 9 192 88 88
37 -43 9 192 88 88
38 -43 9 192 88 88
39 -43 9 192 88 88
40 -43 9 192 88 88
41 -43 9 192 88 88
24 -32 9 80 92 192
25 -32 9 80 92 192
38 -32 9 192 88 88
39 -32 9 192 88 88
23 -31 9 120 60 164
24 -31 9 80 92 192
25 -31 9 80 92 192
38 -31 9 192 88 88
39 -31 9 192 88 88
40 -31 9 92 156 92
23 -30 9 120 60 164
40 -30 9 92 156 92
3 -45 10 100 72 24
4 -45 10 100 72 24
5 -45 10 100 72 24
6 -45 10 100 72 24
7 -45 10 100 72 24
8 -45 10 100 72 24
9 -45 10 100 72 24
10 -45 10 100 72 24
11 -45 10 100 72 24
12 -45 10 100 72 24
13 -45 10 100 72 24
14 -45 10 100 72 24
15 -45 10 100 72 24
16 -45 10 100 72 24
17 -45 10 100 72 24
18 -45 10 100 72 24
19 -45 10 100 72 24
20 -45 10 100 72 24
21 -45 10 100 72 24
22 -45 10 100 72 24
23 -45 10 100 72 24
24 -45 10 100 72 24
25 -45 10 100 72 24
26 -45 10 100 72 24
27 -45 10 100 72 24
28 -45 10 100 72 24
29 -45 10 100 72 24
30 -45 10 100 72 24
31 -45 10 100 72 24
32 -45 10 100 72 24
33 -45 10 100 72 24
34 -45 10 100 72 24
35 -45 10 100 72 24
36 -45 10 100 72 24
37 -45 10 100 72 24
38 -45 10 100 72 24
39 -45 10 100 72 24
40 -45 10 100 72 24
41 -45 10 100 72 24
42 -45 10 100 72 24
43 -45 10 100 72 24
44 -45 10 100 72 24
45 -45 10 100 72 24
46 -45 10 100 72 24
47 -45 10 100 72 24
48 -45 10 100 72 24
49 -45 10 100 72 24
50 -45 10 100 72 24
51 -45 10 100 72 24
52 -45 10 100 72 24
53 -45 10 100 72 24
54 -45 10 100 72 24
55 -45 10 100 72 24
56 -45 10 100 72 24
57 -45 10 100 72 24
58 -45 10 100 72 24
59 -45 10 100 72 24
60 -45 10 100 72 24
61 -45 10 100 72 24
62 -45 10 100 72 24
4 -44 10 132 104 48
5 -44 10 132 104 48
6 -44 10 132 104 48
7 -44 10 132 104 48
8 -44 10 132 104 48
9 -44 10 132 104 48
10 -44 10 132 104 48
11 -44 10 132 104 48
12 -44 10 132 104 48
13 -44 10 132 104 48
14 -44 10 132 104 48
15 -44 10 132 104 48
16 -44 10 132 104 48
17 -44 10 132 104 48
18 -44 10 132 104 48
19 -44 10 132 104 48
20 -44 10 132 104 48
21 -44 10 132 104 48
22 -44 10 132 104 48
23 -44 10 132 104 48
24 -44 10 132 104 48
25 -44 10 132 104 48
26 -44 10 132 104 48
27 -44 10 132 104 48
28 -44 10 132 104 48
29 -44 10 132 104 48
30 -44 10 132 104 48
31 -44 10 132 104 48
32 -44 10 132 104 48
33 -44 10 132 104 48
34 -44 10 132 104 48
35 -44 10 132 104 48
36 -44 10 132 104 48
37 -44 10 132 104 48
38 -44 10 132 104 48
39 -44 10 132 104 48
40 -44 10 132 104 48
41 -44 10 132 104 48
42 -44 10 132 104 48
43 -44 10 132 104 48
44 -44 10 132 104 48
45 -44 10 132 104 48
46 -44 10 132 104 48
47 -44 10 132 104 48
48 -44 10 132 104 48
49 -44 10 132 104 48
50 -44 10 132 104 48
51 -44 10 132 104 48
52 -44 10 132 104 48
53 -44 10 132 104 48
54 -44 10 132 104 48
55 -44 10 132 104 48
56 -44 10 132 104 48
57 -44 10 132 104 48
58 -44 10 132 104 48
59 -44 10 132 104 48
60 -44 10 132 104 48
61 -44 10 132 104 48
22 -43 10 192 88 88
23 -43 10 192 88 88
24 -43 10 192 88 88
25 -43 10 192 88 88
26 -43 10 192 88 88
27 -43 10 192 88 88
28 -43 10 192 88 88
29 -43 10 192 88 88
30 -43 10 192 88 88
31 -43 10 192 88 88
32 -43 10 192 88 88
33 -43 10 192 88 88
34 -43 10 192 88 88
35 -43 10 192 88 88
36 -43 10 192 88 88
37 -43 10 192 88 88
38 -43 10 192 88 88
39 -43 10 192 88 88
40 -43 10 192 88 88
41 -43 10 192 88 88
24 -32 10 80 92 192
25 -32 10 80 92 192
38 -32 10 192 88 88
39 -32 10 192 88 88
23 -31 10 120 60 164
24 -31 10 80 92 192
25 -31 10 80 92 192
38 -31 10 192 88 88
39 -31 10 192 88 88
40 -31 10 92 156 92
23 -30 10 120 60 164
40 -30 10 92 156 92
3 -45 11 100 72 24
4 -45 11 100 72 24
5 -45 11 100 72 24
6 -45 11 100 72 24
7 -45 11 100 72 24
8 -45 11 100 72 24
9 -45 11 100 72 24
10 -45 11 100 72 24
11 -45 11 100 72 24
12 -45 11 100 72 24
13 -45 11 100 72 24
14 -45 11 100 72 24
15 -45 11 100 72 24
16 -45 11 100 72 24
17 -45 11 100 72 24
18 -45 11 100 72 24
19 -45 11 100 72 24
20 -45 11 100 72 24
21 -45 11 100 72 24
22 -45 11 100 72 24
23 -45 11 100 72 24
24 -45 11 100 72 24
25 -45 11 100 72 24
26 -45 11 100 72 24
27 -45 11 100 72 24
28 -45 11 100 72 24
29 -45 11 100 72 24
30 -45 11 100 72 24
31 -45 11 100 72 24
32 -45 11 100 72 24
33 -45 11 100 72 24
34 -45 11 100 72 24
35 -45 11 100 72 24
36 -45 11 100 72 24
37 -45 11 100 72 24
38 -45 11 100 72 24
39 -45 11 100 72 24
40 -45 11 100 72 24
41 -45 11 100 72 24
42 -45 11 100 72 24
43 -45 11 100 72 24
44 -45 11 100 72 24
45 -45 11 100 72 24
46 -45 11 100 72 24
47 -45 11 100 72 24
48 -45 11 100 72 24
49 -45 11 100 72 24
50 -45 11 100 72 24
51 -45 11 100 72 24
52 -45 11 100 72 24
53 -45 11 100 72 24
54 -45 11 100 72 24
55 -45 11 100 72 24
56 -45 11 100 72 24
57 -45 11 100 72 24
58 -45 11 100 72 24
59 -45 11 100 72 24
60 -45 11 100 72 24
61 -45 11 100 72 24
62 -45 11 100 72 24
4 -44 11 132 104 48
5 -44 11 160 132 68
6 -44 11 160 132 68
7 -44 11 160 132 68
8 -44 11 160 132 68
9 -44 11 184 156 88
10 -44 11 184 156 88
11 -44 11 132 104 48
12 -44 11 160 132 68
13 -44 11 160 132 68
14 -44 11 160 132 68
15 -44 11 160 132 68
16 -44 11 160 132 68
17 -44 11 160 132 68
18 -44 11 160 132 68
19 -44 11 160 132 68
20 -44 11 160 132 68
21 -44 11 160 132 68
22 -44 11 160 132 68
23 -44 11 160 132 68
24 -44 11 160 132 68
25 -44 11 160 132 68
26 -44 11 160 132 68
27 -44 11 184 156 88
28 -44 11 184 156 88
29 -44 11 132 104 48
30 -44 11 160 132 68
31 -44 11 160 132 68
32 -44 11 160 132 68
33 -44 11 160 132 68
34 -44 11 160 132 68
35 -44 11 160 132 68
36 -44 11 160 132 68
37 -44 11 160 132 68
38 -44 11 160 132 68
39 -44 11 160 132 68
40 -44 11 160 132 68
41 -44 11 184 156 88
42 -44 11 184 156 88
43 -44 11 132 104 48
44 -44 11 160 132 68
45 -44 11 160 132 68
46 -44 11 160 132 68
47 -44 11 160 132 68
48 -44 11 160 132 68
49 -44 11 160 132 68
50 -44 11 160 132 68
51 -44 11 160 132 68
52 -44 11 160 132 68
53 -44 11 184 156 88
54 -44 11 184 156 88
55 -44 11 132 104 48
56 -44 11 160 132 68
57 -44 11 160 132 68
58 -44 11 160 132 68
59 -44 11 160 132 68
60 -44 11 160 132 68
61 -44 11 132 104 48
22 -43 11 192 88 88
23 -43 11 192 88 88
24 -43 11 192 88 88
25 -43 11 192 88 88
26 -43 11 192 88 88
27 -43 11 192 88 88
28 -43 11 192 88 88
29 -43 11 192 88 88
30 -43 11 192 88 88
31 -43 11 192 88 88
32 -43 11 192 88 88
33 -43 11 192 88 88
34 -43 11 192 88 88
35 -43 11 192 88 88
36 -43 11 192 88 88
37 -43 11 192 88 88
38 -43 11 192 88 88
39 -43 11 192 88 88
40 -43 11 192 88 88
41 -43 11 192 88 88
24 -32 11 80 92 192
25 -32 11 80 92 192
38 -32 11 192 88 88
39 -32 11 192 88 88
23 -31 11 120 60 164
24 -31 11 80 92 192
25 -31 11 80 92 192
38 -31 11 192 88 88
39 -31 11 192 88 88
40 -31 11 92 156 92
23 -30 11 120 60 164
40 -30 11 92 156 92
3 -45 12 100 72 24
4 -45 12 100 72 24
5 -45 12 100 72 24
6 -45 12 100 72 24
7 -45 12 100 72 24
8 -45 12 100 72 24
9 -45 12 100 72 24
10 -45 12 100 72 24
11 -45 12 100 72 24
12 -45 12 100 72 24
13 -45 12 100 72 24
14 -45 12 100 72 24
15 -45 12 100 72 24
16 -45 12 100 72 24
17 -45 12 100 72 24
18 -45 12 100 72 24
19 -45 12 100 72 24
20 -45 12 100 72 24
21 -45 12 100 72 24
22 -45 12 100 72 24
23 -45 12 100 72 24
24 -45 12 100 72 24
25 -45 12 100 72 24
26 -45 12 100 72 24
27 -45 12 100 72 24
28 -45 12 100 72 24
29 -45 12 100 72 24
30 -45 12 100 72 24
31 -45 12 100 72 24
32 -45 12 100 72 24
33 -45 12 100 72 24
34 -45 12 100 72 24
35 -45 12 100 72 24
36 -45 12 100 72 24
37 -45 12 100 72 24
38 -45 12 100 72 24
39 -45 12 100 72 24
40 -45 12 100 72 24
41 -45 12 100 72 24
42 -45 12 100 72 24
43 -45 12 100 72 24
44 -45 12 100 72 24
45 -45 12 100 72 24
46 -45 12 100 72 24
47 -45 12 100 72 24
48 -45 12 100 72 24
49 -45 12 100 72 24
50 -45 12 100 72 24
51 -45 12 100 72 24
52 -45 12 100 72 24
53 -45 12 100 72 24
54 -45 12 100 72 24
55 -45 12 100 72 24
56 -45 12 100 72 24
57 -45 12 100 72 24
58 -45 12 100 72 24
59 -45 12 100 72 24
60 -45 12 100 72 24
61 -45 12 100 72 24
62 -45 12 100 72 24
4 -44 12 132 104 48
5 -44 12 160 132 68
6 -44 12 160 132 68
7 -44 12 160 132 68
8 -44 12 160 132 68
9 -44 12 160 132 68
10 -44 12 184 156 88
11 -44 12 132 104 48
12 -44 12 160 132 68
13 -44 12 160 132 68
14 -44 12 160 132 68
15 -44 12 160 132 68
16 -44 12 160 132 68
17 -44 12 160 132 68
18 -44 12 160 132 68
19 -44 12 160 132 68
20 -44 12 160 132 68
21 -44 12 160 132 68
22 -44 12 160 132 68
23 -44 12 160 132 68
24 -44 12 160 132 68
25 -44 12 160 132 68
26 -44 12 160 132 68
27 -44 12 160 132 68
28 -44 12 184 156 88
29 -44 12 132 104 48
30 -44 12 160 132 68
31 -44 12 160 132 68
32 -44 12 160 132 68
33 -44 12 160 132 68
34 -44 12 160 132 68
35 -44 12 160 132 68
36 -44 12 160 132 68
37 -44 12 160 132 68
38 -44 12 160 132 68
39 -44 12 160 132 68
40 -44 12 160 132 68
41 -44 12 160 132 68
42 -44 12 184 156 88
43 -44 12 132 104 48
44 -44 12 160 132 68
45 -44 12 160 132 68
46 -44 12 160 132 68
47 -44 12 160 132 68
48 -44 12 160 132 68
49 -44 12 160 132 68
50 -44 12 160 132 68
51 -44 12 160 132 68
52 -44 12 160 132 68
53 -44 12 160 132 68
54 -44 12 184 156 88
55 -44 12 132 104 48
56 -44 12 160 132 68
57 -44 12 160 132 68
58 -44 12 160 132 68
59 -44 12 160 132 68
60 -44 12 160 132 68
61 -44 12 132 104 48
22 -43 12 192 88 88
23 -43 12 192 88 88
24 -43 12 192 88 88
25 -43 12 192 88 88
26 -43 12 192 88 88
27 -43 12 192 88 88
28 -43 12 192 88 88
29 -43 12 192 88 88
30 -43 12 192 88 88
31 -43 12 192 88 88
32 -43 12 192 88 88
33 -43 12 192 88 88
34 -43 12 192 88 88
35 -43 12 192 88 88
36 -43 12 192 88 88
37 -43 12 192 88 88
38 -43 12 192 88 88
39 -43 12 192 88 88
40 -43 12 192 88 88
41 -43 12 192 88 88
24 -32 12 80 92 192
25 -32 12 80 92 192
38 -32 12 192 88 88
39 -32 12 192 88 88
23 -31 12 120 60 164
24 -31 12 80 92 192
25 -31 12 80 92 192
38 -31 12 192 88 88
39 -31 12 192 88 88
40 -31 12 92 156 92
23 -30 12 120 60 164
40 -30 12 92 156 92
3 -45 13 100 72 24
4 -45 13 100 72 24
5 -45 13 100 72 24
6 -45 13 100 72 24
7 -45 13 100 72 24
8 -45 13 100 72 24
9 -45 13 100 72 24
10 -45 13 100 72 24
11 -45 13 100 72 24
12 -45 13 100 72 24
13 -45 13 100 72 24
14 -45 13 100 72 24
15 -45 13 100 72 24
16 -45 13 100 72 24
17 -45 13 100 72 24
18 -45 13 100 72 24
19 -45 13 100 72 24
20 -45 13 100 72 24
21 -45 13 100 72 24
22 -45 13 100 72 24
23 -45 13 100 72 24
24 -45 13 100 72 24
25 -45 13 100 72 24
26 -45 13 100 72 24
27 -45 13 100 72 24
28 -45 13 100 72 24
29 -45 13 100 72 24
30 -45 13 100 72 24
31 -45 13 100 72 24
32 -45 13 100 72 24
33 -45 13 100 72 24
34 -45 13 100 72 24
35 -45 13 100 72 24
36 -45 13 100 72 24
37 -45 13 100 72 24
38 -45 13 100 72 24
39 -45 13 100 72 24
40 -45 13 100 72 24
41 -45 13 100 72 24
42 -45 13 100 72 24
43 -45 13 100 72 24
44 -45 13 100 72 24
45 -45 13 100 72 24
46 -45 13 100 72 24
47 -45 13 100 72 24
48 -45 13 100 72 24
49 -45 13 100 72 24
50 -45 13 100 72 24
51 -45 13 100 72 24
52 -45 13 100 72 24
53 -45 13 100 72 24
54 -45 13 100 72 24
55 -45 13 100 72 24
56 -45 13 100 72 24
57 -45 13 100 72 24
58 -45 13 100 72 24
59 -45 13 100 72 24
60 -45 13 100 72 24
61 -45 13 100 72 24
62 -45 13 100 72 24
4 -44 13 132 104 48
5 -44 13 160 132 68
6 -44 13 160 132 68
7 -44 13 160 132 68
8 -44 13 160 132 68
9 -44 13 160 132 68
10 -44 13 184 156 88
11 -44 13 132 104 48
12 -44 13 160 132 68
13 -44 13 160 132 68
14 -44 13 160 132 68
15 -44 13 160 132 68
16 -44 13 160 132 68
17 -44 13 160 132 68
18 -44 13 160 132 68
19 -44 13 160 132 68
20 -44 13 160 132 68
21 -44 13 160 132 68
22 -44 13 160 132 68
23 -44 13 160 132 68
24 -44 13 160 132 68
25 -44 13 160 132 68
26 -44 13 160 132 68
27 -44 13 160 132 68
28 -44 13 184 156 88
29 -44 13 132 104 48
30 -44 13 160 132 68
31 -44 13 160 132 68
32 -44 13 160 132 68
33 -44 13 160 132 68
34 -44 13 160 132 68
35 -44 13 160 132 68
36 -44 13 160 132 68
37 -44 13 160 132 68
38 -44 13 160 132 68
39 -44 13 160 132 68
40 -44 13 160 132 68
41 -44 13 160 132 68
42 -44 13 184 156 88
43 -44 13 132 104 48
44 -44 13 160 132 68
45 -44 13 160 132 68
46 -44 13 160 132 68
47 -44 13 160 132 68
48 -44 13 160 132 68
49 -44 13 160 132 68
50 -44 13 160 132 68
51 -44 13 160 132 68
52 -44 13 160 132 68
53 -44 13 160 132 68
54 -44 13 184 156 88
55 -44 13 132 104 48
56 -44 13 160 132 68
57 -44 13 160 132 68
58 -44 13 160 132 68
59 -44 13 160 132 68
60 -44 13 160 132 68
61 -44 13 132 104 48
22 -43 13 192 88 88
23 -43 13 192 88 88
24 -43 13 192 88 88
25 -43 13 192 88 88
26 -43 13 192 88 88
27 -43 13 192 88 88
28 -43 13 192 88 88
29 -43 13 192 88 88
30 -43 13 192 88 88
31 -43 13 192 88 88
32 -43 13 192 88 88
33 -43 13 192 88 88
34 -43 13 192 88 88
35 -43 13 192 88 88
36 -43 13 192 88 88
37 -43 13 192 88 88
38 -43 13 192 88 88
39 -43 13 192 88 88
40 -43 13 192 88 88
41 -43 13 192 88 88
24 -32 13 80 92 192
25 -32 13 80 92 192
38 -32 13 192 88 88
39 -32 13 192 88 88
23 -31 13 120 60 164
24 -31 13 80 92 192
25 -31 13 80 92 192
38 -31 13 192 88 88
39 -31 13 192 88 88
40 -31 13 92 156 92
23 -30 13 120 60 164
40 -30 13 92 156 92
23 -29 13 120 60 164
40 -29 13 92 156 92
3 -45 14 100 72 24
4 -45 14 100 72 24
5 -45 14 100 72 24
6 -45 14 100 72 24
7 -45 14 100 72 24
8 -45 14 100 72 24
9 -45 14 100 72 24
10 -45 14 100 72 24
11 -45 14 100 72 24
12 -45 14 100 72 24
13 -45 14 100 72 24
14 -45 14 100 72 24
15 -45 14 100 72 24
16 -45 14 100 72 24
17 -45 14 100 72 24
18 -45 14 100 72 24
19 -45 14 100 72 24
20 -45 14 100 72 24
21 -45 14 100 72 24
22 -45 14 100 72 24
23 -45 14 100 72 24
24 -45 14 100 72 24
25 -45 14 100 72 24
26 -45 14 100 72 24
27 -45 14 100 72 24
28 -45 14 100 72 24
29 -45 14 100 72 24
30 -45 14 100 72 24
31 -45 14 100 72 24
32 -45 14 100 72 24
33 -45 14 100 72 24
34 -45 14 100 72 24
35 -45 14 100 72 24
36 -45 14 100 72 24
37 -45 14 100 72 24
38 -45 14 100 72 24
39 -45 14 100 72 24
40 -45 14 100 72 24
41 -45 14 100 72 24
42 -45 14 100 72 24
43 -45 14 100 72 24
44 -45 14 100 72 24
45 -45 14 100 72 24
46 -45 14 100 72 24
47 -45 14 100 72 24
48 -45 14 100 72 24
49 -45 14 100 72 24
50 -45 14 100 72 24
51 -45 14 100 72 24
52 -45 14 100 72 24
53 -45 14 100 72 24
54 -45 14 100 72 24
55 -45 14 100 72 24
56 -45 14 100 72 24
57 -45 14 100 72 24
58 -45 14 100 72 24
59 -45 14 100 72 24
60 -45 14 100 72 24
61 -45 14 100 72 24
62 -45 14 100 72 24
4 -44 14 132 104 48
5 -44 14 132 104 48
6 -44 14 132 104 48
7 -44 14 132 104 48
8 -44 14 132 104 48
9 -44 14 132 104 48
10 -44 14 132 104 48
11 -44 14 132 104 48
12 -44 14 132 104 48
