ply
format ascii 1.0
comment : MagicaVoxel @ Ephtracy
element vertex 772
property float x
property float y
property float z
property uchar red
property uchar green
property uchar blue
end_header
-10 -5 0 136 136 136
-9 -5 0 136 136 136
-8 -5 0 136 136 136
-7 -5 0 136 136 136
-6 -5 0 136 136 136
-5 -5 0 136 136 136
-4 -5 0 136 136 136
-3 -5 0 136 136 136
-2 -5 0 136 136 136
-1 -5 0 136 136 136
0 -5 0 136 136 136
1 -5 0 136 136 136
2 -5 0 136 136 136
3 -5 0 136 136 136
4 -5 0 136 136 136
5 -5 0 136 136 136
6 -5 0 136 136 136
7 -5 0 136 136 136
8 -5 0 136 136 136
9 -5 0 136 136 136
-10 -4 0 136 136 136
-9 -4 0 136 136 136
-8 -4 0 136 136 136
-7 -4 0 136 136 136
-6 -4 0 136 136 136
-5 -4 0 136 136 136
-4 -4 0 136 136 136
-3 -4 0 136 136 136
-2 -4 0 136 136 136
-1 -4 0 136 136 136
0 -4 0 136 136 136
1 -4 0 136 136 136
2 -4 0 136 136 136
3 -4 0 136 136 136
4 -4 0 136 136 136
5 -4 0 136 136 136
6 -4 0 136 136 136
7 -4 0 136 136 136
8 -4 0 136 136 136
9 -4 0 136 136 136
-10 -3 0 136 136 136
-9 -3 0 136 136 136
-8 -3 0 136 136 136
-7 -3 0 136 136 136
-6 -3 0 136 136 136
-5 -3 0 136 136 136
-4 -3 0 136 136 136
-3 -3 0 136 136 136
-2 -3 0 136 136 136
-1 -3 0 136 136 136
0 -3 0 136 136 136
1 -3 0 136 136 136
2 -3 0 136 136 136
3 -3 0 136 136 136
4 -3 0 136 136 136
5 -3 0 136 136 136
6 -3 0 136 136 136
7 -3 0 136 136 136
8 -3 0 136 136 136
9 -3 0 136 136 136
-10 -2 0 136 136 136
-9 -2 0 136 136 136
-8 -2 0 136 136 136
-7 -2 0 136 136 136
-6 -2 0 136 136 136
-5 -2 0 136 136 136
-4 -2 0 136 136 136
-3 -2 0 136 136 136
-2 -2 0 136 136 136
-1 -2 0 136 136 136
0 -2 0 136 136 136
1 -2 0 136 136 136
2 -2 0 136 136 136
3 -2 0 136 136 136
4 -2 0 136 136 136
5 -2 0 136 136 136
6 -2 0 136 136 136
7 -2 0 136 136 136
8 -2 0 136 136 136
9 -2 0 136 136 136
-10 -1 0 136 136 136
-9 -1 0 136 136 136
-8 -1 0 136 136 136
-7 -1 0 136 136 136
-6 -1 0 136 136 136
-5 -1 0 136 136 136
-4 -1 0 136 136 136
-3 -1 0 136 136 136
-2 -1 0 136 136 136
-1 -1 0 136 136 136
0 -1 0 136 136 136
1 -1 0 136 136 136
2 -1 0 136 136 136
3 -1 0 136 136 136
4 -1 0 136 136 136
5 -1 0 136 136 136
6 -1 0 136 136 136
7 -1 0 136 136 136
8 -1 0 136 136 136
9 -1 0 136 136 136
-10 0 0 136 136 136
-9 0 0 136 136 136
-8 0 0 136 136 136
-7 0 0 136 136 136
-6 0 0 136 136 136
-5 0 0 136 136 136
-4 0 0 136 136 136
-3 0 0 136 136 136
-2 0 0 136 136 136
-1 0 0 136 136 136
0 0 0 136 136 136
1 0 0 136 136 136
2 0 0 136 136 136
3 0 0 136 136 136
4 0 0 136 136 136
5 0 0 136 136 136
6 0 0 136 136 136
7 0 0 136 136 136
8 0 0 136 136 136
9 0 0 136 136 136
-10 1 0 136 136 136
-9 1 0 136 136 136
-8 1 0 136 136 136
-7 1 0 136 136 136
-6 1 0 136 136 136
-5 1 0 136 136 136
-4 1 0 136 136 136
-3 1 0 136 136 136
-2 1 0 136 136 136
-1 1 0 136 136 136
0 1 0 136 136 136
1 1 0 136 136 136
2 1 0 136 136 136
3 1 0 136 136 136
4 1 0 136 136 136
5 1 0 136 136 136
6 1 0 136 136 136
7 1 0 136 136 136
8 1 0 136 136 136
9 1 0 136 136 136
-10 2 0 136 136 136
-9 2 0 136 136 136
-8 2 0 136 136 136
-7 2 0 136 136 136
-6 2 0 136 136 136
-5 2 0 136 136 136
-4 2 0 136 136 136
-3 2 0 136 136 136
-2 2 0 136 136 136
-1 2 0 136 136 136
0 2 0 136 136 136
1 2 0 136 136 136
2 2 0 136 136 136
3 2 0 136 136 136
4 2 0 136 136 136
5 2 0 136 136 136
6 2 0 136 136 136
7 2 0 136 136 136
8 2 0 136 136 136
9 2 0 136 136 136
-10 3 0 136 136 136
-9 3 0 136 136 136
-8 3 0 136 136 136
-7 3 0 136 136 136
-6 3 0 136 136 136
-5 3 0 136 136 136
-4 3 0 136 136 136
-3 3 0 136 136 136
-2 3 0 136 136 136
-1 3 0 136 136 136
0 3 0 136 136 136
1 3 0 136 136 136
2 3 0 136 136 136
3 3 0 136 136 136
4 3 0 136 136 136
5 3 0 136 136 136
6 3 0 136 136 136
7 3 0 136 136 136
8 3 0 136 136 136
9 3 0 136 136 136
-10 4 0 136 136 136
-9 4 0 136 136 136
-8 4 0 136 136 136
-7 4 0 136 136 136
-6 4 0 136 136 136
-5 4 0 136 136 136
-4 4 0 136 136 136
-3 4 0 136 136 136
-2 4 0 136 136 136
-1 4 0 136 136 136
0 4 0 136 136 136
1 4 0 136 136 136
2 4 0 136 136 136
3 4 0 136 136 136
4 4 0 136 136 136
5 4 0 136 136 136
6 4 0 136 136 136
7 4 0 136 136 136
8 4 0 136 136 136
9 4 0 136 136 136
-10 -5 1 136 136 136
-9 -5 1 136 136 136
-8 -5 1 119 119 119
-7 -5 1 136 136 136
-6 -5 1 136 136 136
-5 -5 1 136 136 136
-4 -5 1 136 136 136
-3 -5 1 136 136 136
-2 -5 1 136 136 136
-1 -5 1 119 119 119
0 -5 1 136 136 136
1 -5 1 136 136 136
2 -5 1 136 136 136
3 -5 1 136 136 136
4 -5 1 136 136 136
5 -5 1 136 136 136
6 -5 1 136 136 136
7 -5 1 136 136 136
8 -5 1 136 136 136
9 -5 1 136 136 136
-10 -4 1 68 68 68
-9 -4 1 102 51 0
8 -4 1 102 51 0
9 -4 1 68 68 68
-9 -3 1 102 51 0
8 -3 1 102 51 0
-9 -2 1 102 51 0
8 -2 1 102 51 0
-9 -1 1 102 51 0
8 -1 1 102 51 0
-9 0 1 102 51 0
8 0 1 102 51 0
-9 1 1 102 51 0
8 1 1 102 51 0
-9 2 1 102 51 0
8 2 1 102 51 0
-10 3 1 68 68 68
-9 3 1 102 51 0
8 3 1 102 51 0
9 3 1 68 68 68
-10 4 1 136 136 136
-9 4 1 136 136 136
-8 4 1 119 119 119
-7 4 1 136 136 136
-6 4 1 136 136 136
-5 4 1 136 136 136
-4 4 1 136 136 136
-3 4 1 136 136 136
-2 4 1 136 136 136
-1 4 1 119 119 119
0 4 1 136 136 136
1 4 1 136 136 136
2 4 1 136 136 136
3 4 1 136 136 136
4 4 1 136 136 136
5 4 1 136 136 136
6 4 1 136 136 136
7 4 1 136 136 136
8 4 1 136 136 136
9 4 1 136 136 136
-10 -5 2 136 136 136
-9 -5 2 136 136 136
-8 -5 2 119 119 119
-7 -5 2 136 136 136
-6 -5 2 136 136 136
-5 -5 2 136 136 136
-4 -5 2 136 136 136
-3 -5 2 136 136 136
-2 -5 2 136 136 136
-1 -5 2 119 119 119
0 -5 2 136 136 136
1 -5 2 136 136 136
2 -5 2 136 136 136
3 -5 2 136 136 136
4 -5 2 136 136 136
5 -5 2 136 136 136
6 -5 2 136 136 136
7 -5 2 136 136 136
8 -5 2 136 136 136
9 -5 2 136 136 136
-10 -4 2 68 68 68
9 -4 2 68 68 68
-9 -2 2 102 51 0
8 -2 2 102 51 0
-9 1 2 102 51 0
8 1 2 102 51 0
-10 3 2 68 68 68
9 3 2 68 68 68
-10 4 2 136 136 136
-9 4 2 136 136 136
-8 4 2 119 119 119
-7 4 2 136 136 136
-6 4 2 136 136 136
-5 4 2 136 136 136
-4 4 2 136 136 136
-3 4 2 136 136 136
-2 4 2 136 136 136
-1 4 2 119 119 119
0 4 2 136 136 136
1 4 2 136 136 136
2 4 2 136 136 136
3 4 2 136 136 136
4 4 2 136 136 136
5 4 2 136 136 136
6 4 2 136 136 136
7 4 2 136 136 136
8 4 2 136 136 136
9 4 2 136 136 136
-10 -5 3 136 136 136
-9 -5 3 119 119 119
-8 -5 3 119 119 119
-7 -5 3 119 119 119
-6 -5 3 119 119 119
-5 -5 3 119 119 119
-4 -5 3 119 119 119
-3 -5 3 119 119 119
-2 -5 3 119 119 119
-1 -5 3 119 119 119
0 -5 3 119 119 119
1 -5 3 119 119 119
2 -5 3 119 119 119
3 -5 3 119 119 119
4 -5 3 119 119 119
5 -5 3 119 119 119
6 -5 3 119 119 119
7 -5 3 119 119 119
8 -5 3 119 119 119
9 -5 3 136 136 136
-10 -4 3 68 68 68
9 -4 3 68 68 68
-10 3 3 68 68 68
9 3 3 68 68 68
-10 4 3 136 136 136
-9 4 3 119 119 119
-8 4 3 119 119 119
-7 4 3 119 119 119
-6 4 3 119 119 119
-5 4 3 119 119 119
-4 4 3 119 119 119
-3 4 3 119 119 119
-2 4 3 119 119 119
-1 4 3 119 119 119
0 4 3 119 119 119
1 4 3 119 119 119
2 4 3 119 119 119
3 4 3 119 119 119
4 4 3 119 119 119
5 4 3 119 119 119
6 4 3 119 119 119
7 4 3 119 119 119
8 4 3 119 119 119
9 4 3 136 136 136
-10 -5 4 136 136 136
-9 -5 4 136 136 136
-8 -5 4 136 136 136
-7 -5 4 136 136 136
-6 -5 4 136 136 136
-5 -5 4 136 136 136
-4 -5 4 136 136 136
-3 -5 4 136 136 136
-2 -5 4 136 136 136
-1 -5 4 136 136 136
0 -5 4 136 136 136
1 -5 4 136 136 136
2 -5 4 136 136 136
3 -5 4 136 136 136
4 -5 4 119 119 119
5 -5 4 136 136 136
6 -5 4 136 136 136
7 -5 4 136 136 136
8 -5 4 136 136 136
9 -5 4 136 136 136
-10 -4 4 68 68 68
9 -4 4 68 68 68
-10 3 4 68 68 68
9 3 4 68 68 68
-10 4 4 136 136 136
-9 4 4 136 136 136
-8 4 4 136 136 136
-7 4 4 136 136 136
-6 4 4 136 136 136
-5 4 4 136 136 136
-4 4 4 136 136 136
-3 4 4 136 136 136
-2 4 4 136 136 136
-1 4 4 136 136 136
0 4 4 136 136 136
1 4 4 136 136 136
2 4 4 136 136 136
3 4 4 136 136 136
4 4 4 119 119 119
5 4 4 136 136 136
6 4 4 136 136 136
7 4 4 136 136 136
8 4 4 136 136 136
9 4 4 136 136 136
-10 -5 5 136 136 136
-9 -5 5 136 136 136
-8 -5 5 136 136 136
-7 -5 5 136 136 136
-6 -5 5 136 136 136
-5 -5 5 136 136 136
-4 -5 5 136 136 136
-3 -5 5 136 136 136
-2 -5 5 136 136 136
-1 -5 5 136 136 136
0 -5 5 136 136 136
1 -5 5 136 136 136
2 -5 5 136 136 136
3 -5 5 136 136 136
4 -5 5 119 119 119
5 -5 5 136 136 136
6 -5 5 136 136 136
7 -5 5 136 136 136
8 -5 5 136 136 136
9 -5 5 136 136 136
-10 -4 5 68 68 68
9 -4 5 68 68 68
-10 3 5 68 68 68
9 3 5 68 68 68
-10 4 5 136 136 136
-9 4 5 136 136 136
-8 4 5 136 136 136
-7 4 5 136 136 136
-6 4 5 136 136 136
-5 4 5 136 136 136
-4 4 5 136 136 136
-3 4 5 136 136 136
-2 4 5 136 136 136
-1 4 5 136 136 136
0 4 5 136 136 136
1 4 5 136 136 136
2 4 5 136 136 136
3 4 5 136 136 136
4 4 5 119 119 119
5 4 5 136 136 136
6 4 5 136 136 136
7 4 5 136 136 136
8 4 5 136 136 136
9 4 5 136 136 136
-10 -5 6 136 136 136
-9 -5 6 119 119 119
-8 -5 6 119 119 119
-7 -5 6 119 119 119
-6 -5 6 119 119 119
-5 -5 6 119 119 119
-4 -5 6 119 119 119
-3 -5 6 119 119 119
-2 -5 6 119 119 119
-1 -5 6 119 119 119
0 -5 6 119 119 119
1 -5 6 119 119 119
2 -5 6 119 119 119
3 -5 6 119 119 119
4 -5 6 119 119 119
5 -5 6 119 119 119
6 -5 6 119 119 119
7 -5 6 119 119 119
8 -5 6 119 119 119
9 -5 6 136 136 136
-10 -4 6 68 68 68
9 -4 6 68 68 68
-10 3 6 68 68 68
9 3 6 68 68 68
-10 4 6 136 136 136
-9 4 6 119 119 119
-8 4 6 119 119 119
-7 4 6 119 119 119
-6 4 6 119 119 119
-5 4 6 119 119 119
-4 4 6 119 119 119
-3 4 6 119 119 119
-2 4 6 119 119 119
-1 4 6 119 119 119
0 4 6 119 119 119
1 4 6 119 119 119
2 4 6 119 119 119
3 4 6 119 119 119
4 4 6 119 119 119
5 4 6 119 119 119
6 4 6 119 119 119
7 4 6 119 119 119
8 4 6 119 119 119
9 4 6 136 136 136
-10 -5 7 136 136 136
-9 -5 7 136 136 136
-8 -5 7 136 136 136
-7 -5 7 136 136 136
-6 -5 7 136 136 136
-5 -5 7 136 136 136
-4 -5 7 119 119 119
-3 -5 7 136 136 136
-2 -5 7 136 136 136
-1 -5 7 136 136 136
0 -5 7 136 136 136
1 -5 7 136 136 136
2 -5 7 136 136 136
3 -5 7 136 136 136
4 -5 7 136 136 136
5 -5 7 136 136 136
6 -5 7 136 136 136
7 -5 7 136 136 136
8 -5 7 136 136 136
9 -5 7 136 136 136
-10 -4 7 68 68 68
9 -4 7 68 68 68
-10 3 7 68 68 68
9 3 7 68 68 68
-10 4 7 136 136 136
-9 4 7 136 136 136
-8 4 7 136 136 136
-7 4 7 136 136 136
-6 4 7 136 136 136
-5 4 7 136 136 136
-4 4 7 119 119 119
-3 4 7 136 136 136
-2 4 7 136 136 136
-1 4 7 136 136 136
0 4 7 136 136 136
1 4 7 136 136 136
2 4 7 136 136 136
3 4 7 136 136 136
4 4 7 136 136 136
5 4 7 136 136 136
6 4 7 136 136 136
7 4 7 136 136 136
8 4 7 136 136 136
9 4 7 136 136 136
-10 -5 8 136 136 136
-9 -5 8 136 136 136
-8 -5 8 136 136 136
-7 -5 8 136 136 136
-6 -5 8 136 136 136
-5 -5 8 136 136 136
-4 -5 8 119 119 119
-3 -5 8 136 136 136
-2 -5 8 136 136 136
-1 -5 8 136 136 136
0 -5 8 136 136 136
1 -5 8 136 136 136
2 -5 8 136 136 136
3 -5 8 136 136 136
4 -5 8 136 136 136
5 -5 8 136 136 136
6 -5 8 136 136 136
7 -5 8 136 136 136
8 -5 8 136 136 136
9 -5 8 136 136 136
-10 -4 8 68 68 68
9 -4 8 68 68 68
-10 3 8 68 68 68
9 3 8 68 68 68
-10 4 8 136 136 136
-9 4 8 136 136 136
-8 4 8 136 136 136
-7 4 8 136 136 136
-6 4 8 136 136 136
-5 4 8 136 136 136
-4 4 8 119 119 119
-3 4 8 136 136 136
-2 4 8 136 136 136
-1 4 8 136 136 136
0 4 8 136 136 136
1 4 8 136 136 136
2 4 8 136 136 136
3 4 8 136 136 136
4 4 8 136 136 136
5 4 8 136 136 136
6 4 8 136 136 136
7 4 8 136 136 136
8 4 8 136 136 136
9 4 8 136 136 136
-10 -5 9 136 136 136
-9 -5 9 119 119 119
-8 -5 9 119 119 119
-7 -5 9 119 119 119
-6 -5 9 119 119 119
-5 -5 9 119 119 119
-4 -5 9 119 119 119
-3 -5 9 119 119 119
-2 -5 9 119 119 119
-1 -5 9 119 119 119
0 -5 9 119 119 119
1 -5 9 119 119 119
2 -5 9 119 119 119
3 -5 9 119 119 119
4 -5 9 119 119 119
5 -5 9 119 119 119
6 -5 9 119 119 119
7 -5 9 119 119 119
8 -5 9 119 119 119
9 -5 9 136 136 136
-10 -4 9 68 68 68
-9 -4 9 119 119 119
-8 -4 9 119 119 119
-7 -4 9 119 119 119
-6 -4 9 119 119 119
-5 -4 9 119 119 119
-4 -4 9 119 119 119
-3 -4 9 119 119 119
-2 -4 9 119 119 119
-1 -4 9 119 119 119
0 -4 9 119 119 119
1 -4 9 119 119 119
2 -4 9 119 119 119
3 -4 9 119 119 119
4 -4 9 119 119 119
5 -4 9 119 119 119
6 -4 9 119 119 119
7 -4 9 119 119 119
8 -4 9 119 119 119
9 -4 9 68 68 68
-10 -3 9 119 119 119
-9 -3 9 119 119 119
-8 -3 9 119 119 119
-7 -3 9 119 119 119
-6 -3 9 119 119 119
-5 -3 9 119 119 119
-4 -3 9 119 119 119
-3 -3 9 119 119 119
-2 -3 9 119 119 119
-1 -3 9 119 119 119
0 -3 9 119 119 119
1 -3 9 119 119 119
2 -3 9 119 119 119
3 -3 9 119 119 119
4 -3 9 119 119 119
5 -3 9 119 119 119
6 -3 9 119 119 119
7 -3 9 119 119 119
8 -3 9 119 119 119
9 -3 9 119 119 119
-10 -2 9 119 119 119
-9 -2 9 119 119 119
-8 -2 9 119 119 119
-7 -2 9 119 119 119
-6 -2 9 119 119 119
-5 -2 9 119 119 119
-4 -2 9 119 119 119
-3 -2 9 119 119 119
-2 -2 9 119 119 119
-1 -2 9 119 119 119
0 -2 9 119 119 119
1 -2 9 119 119 119
2 -2 9 119 119 119
3 -2 9 119 119 119
4 -2 9 119 119 119
5 -2 9 119 119 119
6 -2 9 119 119 119
7 -2 9 119 119 119
8 -2 9 119 119 119
9 -2 9 119 119 119
-10 -1 9 119 119 119
-9 -1 9 119 119 119
-8 -1 9 119 119 119
-7 -1 9 119 119 119
-6 -1 9 119 119 119
-5 -1 9 119 119 119
-4 -1 9 119 119 119
-3 -1 9 119 119 119
-2 -1 9 119 119 119
-1 -1 9 119 119 119
0 -1 9 119 119 119
1 -1 9 119 119 119
2 -1 9 119 119 119
3 -1 9 119 119 119
4 -1 9 119 119 119
5 -1 9 119 119 119
6 -1 9 119 119 119
7 -1 9 119 119 119
8 -1 9 119 119 119
9 -1 9 119 119 119
-10 0 9 119 119 119
-9 0 9 119 119 119
-8 0 9 119 119 119
-7 0 9 119 119 119
-6 0 9 119 119 119
-5 0 9 119 119 119
-4 0 9 119 119 119
-3 0 9 119 119 119
-2 0 9 119 119 119
-1 0 9 119 119 119
0 0 9 119 119 119
1 0 9 119 119 119
2 0 9 119 119 119
3 0 9 119 119 119
4 0 9 119 119 119
5 0 9 119 119 119
6 0 9 119 119 119
7 0 9 119 119 119
8 0 9 119 119 119
9 0 9 119 119 119
-10 1 9 119 119 119
-9 1 9 119 119 119
-8 1 9 119 119 119
-7 1 9 119 119 119
-6 1 9 119 119 119
-5 1 9 119 119 119
-4 1 9 119 119 119
-3 1 9 119 119 119
-2 1 9 119 119 119
-1 1 9 119 119 119
0 1 9 119 119 119
1 1 9 119 119 119
2 1 9 119 119 119
3 1 9 119 119 119
4 1 9 119 119 119
5 1 9 119 119 119
6 1 9 119 119 119
7 1 9 119 119 119
8 1 9 119 119 119
9 1 9 119 119 119
-10 2 9 119 119 119
-9 2 9 119 119 119
-8 2 9 119 119 119
-7 2 9 119 119 119
-6 2 9 119 119 119
-5 2 9 119 119 119
-4 2 9 119 119 119
-3 2 9 119 119 119
-2 2 9 119 119 119
-1 2 9 119 119 119
0 2 9 119 119 119
1 2 9 119 119 119
2 2 9 119 119 119
3 2 9 119 119 119
4 2 9 119 119 119
5 2 9 119 119 119
6 2 9 119 119 119
7 2 9 119 119 119
8 2 9 119 119 119
9 2 9 119 119 119
-10 3 9 68 68 68
-9 3 9 119 119 119
-8 3 9 119 119 119
-7 3 9 119 119 119
-6 3 9 119 119 119
-5 3 9 119 119 119
-4 3 9 119 119 119
-3 3 9 119 119 119
-2 3 9 119 119 119
-1 3 9 119 119 119
0 3 9 119 119 119
1 3 9 119 119 119
2 3 9 119 119 119
3 3 9 119 119 119
4 3 9 119 119 119
5 3 9 119 119 119
6 3 9 119 119 119
7 3 9 119 119 119
8 3 9 119 119 119
9 3 9 68 68 68
-10 4 9 136 136 136
-9 4 9 119 119 119
-8 4 9 119 119 119
-7 4 9 119 119 119
-6 4 9 119 119 119
-5 4 9 119 119 119
-4 4 9 119 119 119
-3 4 9 119 119 119
-2 4 9 119 119 119
-1 4 9 119 119 119
0 4 9 119 119 119
1 4 9 119 119 119
2 4 9 119 119 119
3 4 9 119 119 119
4 4 9 119 119 119
5 4 9 119 119 119
6 4 9 119 119 119
7 4 9 119 119 119
8 4 9 119 119 119
9 4 9 136 136 136
