ply
format ascii 1.0
comment : MagicaVoxel @ Ephtracy
element vertex 1880
property float x
property float y
property float z
property uchar red
property uchar green
property uchar blue
end_header
-5 -10 0 136 136 136
-4 -10 0 136 136 136
-3 -10 0 136 136 136
-2 -10 0 136 136 136
-1 -10 0 136 136 136
0 -10 0 136 136 136
1 -10 0 136 136 136
2 -10 0 136 136 136
3 -10 0 136 136 136
4 -10 0 136 136 136
-5 -9 0 136 136 136
-4 -9 0 136 136 136
-3 -9 0 136 136 136
-2 -9 0 136 136 136
-1 -9 0 136 136 136
0 -9 0 136 136 136
1 -9 0 136 136 136
2 -9 0 136 136 136
3 -9 0 136 136 136
4 -9 0 136 136 136
-5 -8 0 136 136 136
-4 -8 0 136 136 136
-3 -8 0 136 136 136
-2 -8 0 136 136 136
-1 -8 0 136 136 136
0 -8 0 136 136 136
1 -8 0 136 136 136
2 -8 0 136 136 136
3 -8 0 136 136 136
4 -8 0 136 136 136
-5 -7 0 136 136 136
-4 -7 0 136 136 136
-3 -7 0 136 136 136
-2 -7 0 136 136 136
-1 -7 0 136 136 136
0 -7 0 136 136 136
1 -7 0 136 136 136
2 -7 0 136 136 136
3 -7 0 136 136 136
4 -7 0 136 136 136
-5 -6 0 136 136 136
-4 -6 0 85 85 85
-3 -6 0 85 85 85
-2 -6 0 85 85 85
-1 -6 0 85 85 85
0 -6 0 85 85 85
1 -6 0 85 85 85
2 -6 0 85 85 85
3 -6 0 85 85 85
4 -6 0 85 85 85
-5 -5 0 136 136 136
-4 -5 0 136 136 136
-3 -5 0 136 136 136
-2 -5 0 136 136 136
-1 -5 0 136 136 136
0 -5 0 136 136 136
1 -5 0 136 136 136
2 -5 0 136 136 136
3 -5 0 136 136 136
4 -5 0 136 136 136
-5 -4 0 136 136 136
-4 -4 0 85 85 85
-3 -4 0 85 85 85
-2 -4 0 85 85 85
-1 -4 0 85 85 85
0 -4 0 85 85 85
1 -4 0 85 85 85
2 -4 0 85 85 85
3 -4 0 85 85 85
4 -4 0 85 85 85
-5 -3 0 136 136 136
-4 -3 0 136 136 136
-3 -3 0 136 136 136
-2 -3 0 136 136 136
-1 -3 0 136 136 136
0 -3 0 136 136 136
1 -3 0 136 136 136
2 -3 0 136 136 136
3 -3 0 136 136 136
4 -3 0 136 136 136
-5 -2 0 136 136 136
-4 -2 0 85 85 85
-3 -2 0 85 85 85
-2 -2 0 85 85 85
-1 -2 0 85 85 85
0 -2 0 85 85 85
1 -2 0 85 85 85
2 -2 0 85 85 85
3 -2 0 85 85 85
4 -2 0 85 85 85
-5 -1 0 136 136 136
-4 -1 0 136 136 136
-3 -1 0 136 136 136
-2 -1 0 136 136 136
-1 -1 0 136 136 136
0 -1 0 136 136 136
1 -1 0 136 136 136
2 -1 0 136 136 136
3 -1 0 136 136 136
4 -1 0 136 136 136
-5 0 0 136 136 136
-4 0 0 85 85 85
-3 0 0 85 85 85
-2 0 0 85 85 85
-1 0 0 85 85 85
0 0 0 85 85 85
1 0 0 85 85 85
2 0 0 85 85 85
3 0 0 85 85 85
4 0 0 85 85 85
-5 1 0 136 136 136
-4 1 0 136 136 136
-3 1 0 136 136 136
-2 1 0 136 136 136
-1 1 0 136 136 136
0 1 0 136 136 136
1 1 0 136 136 136
2 1 0 136 136 136
3 1 0 136 136 136
4 1 0 136 136 136
-5 2 0 136 136 136
-4 2 0 85 85 85
-3 2 0 85 85 85
-2 2 0 85 85 85
-1 2 0 85 85 85
0 2 0 85 85 85
1 2 0 85 85 85
2 2 0 85 85 85
3 2 0 85 85 85
4 2 0 85 85 85
-5 3 0 136 136 136
-4 3 0 136 136 136
-3 3 0 136 136 136
-2 3 0 136 136 136
-1 3 0 136 136 136
0 3 0 136 136 136
1 3 0 136 136 136
2 3 0 136 136 136
3 3 0 136 136 136
4 3 0 136 136 136
-5 4 0 136 136 136
-4 4 0 136 136 136
-3 4 0 136 136 136
-2 4 0 136 136 136
-1 4 0 136 136 136
0 4 0 136 136 136
1 4 0 136 136 136
2 4 0 136 136 136
3 4 0 136 136 136
4 4 0 136 136 136
-5 5 0 136 136 136
-4 5 0 136 136 136
-3 5 0 136 136 136
-2 5 0 136 136 136
-1 5 0 136 136 136
0 5 0 136 136 136
1 5 0 136 136 136
2 5 0 136 136 136
3 5 0 136 136 136
4 5 0 136 136 136
-5 6 0 136 136 136
-4 6 0 136 136 136
-3 6 0 136 136 136
-2 6 0 136 136 136
-1 6 0 136 136 136
0 6 0 136 136 136
1 6 0 136 136 136
2 6 0 136 136 136
3 6 0 136 136 136
4 6 0 136 136 136
-5 7 0 136 136 136
-4 7 0 136 136 136
-3 7 0 136 136 136
-2 7 0 136 136 136
-1 7 0 136 136 136
0 7 0 136 136 136
1 7 0 136 136 136
2 7 0 136 136 136
3 7 0 136 136 136
4 7 0 136 136 136
-5 8 0 136 136 136
-4 8 0 136 136 136
-3 8 0 136 136 136
-2 8 0 136 136 136
-1 8 0 136 136 136
0 8 0 136 136 136
1 8 0 136 136 136
2 8 0 136 136 136
3 8 0 136 136 136
4 8 0 136 136 136
-5 9 0 136 136 136
-4 9 0 136 136 136
-3 9 0 136 136 136
-2 9 0 136 136 136
-1 9 0 136 136 136
0 9 0 136 136 136
1 9 0 136 136 136
2 9 0 136 136 136
3 9 0 136 136 136
4 9 0 136 136 136
-5 -10 1 136 136 136
-4 -10 1 136 136 136
-3 -10 1 136 136 136
-2 -10 1 136 136 136
-1 -10 1 136 136 136
0 -10 1 136 136 136
1 -10 1 136 136 136
2 -10 1 136 136 136
3 -10 1 136 136 136
4 -10 1 136 136 136
-5 -9 1 136 136 136
-4 -9 1 136 136 136
-3 -9 1 136 136 136
-2 -9 1 136 136 136
-1 -9 1 136 136 136
0 -9 1 136 136 136
1 -9 1 136 136 136
2 -9 1 136 136 136
3 -9 1 136 136 136
4 -9 1 136 136 136
-5 -8 1 136 136 136
-4 -8 1 136 136 136
-3 -8 1 136 136 136
-2 -8 1 136 136 136
-1 -8 1 136 136 136
0 -8 1 136 136 136
1 -8 1 136 136 136
2 -8 1 136 136 136
3 -8 1 136 136 136
4 -8 1 136 136 136
-5 -7 1 136 136 136
-4 -7 1 136 136 136
-3 -7 1 136 136 136
-2 -7 1 136 136 136
-1 -7 1 136 136 136
0 -7 1 136 136 136
1 -7 1 136 136 136
2 -7 1 136 136 136
3 -7 1 136 136 136
4 -7 1 136 136 136
-5 -6 1 85 85 85
-4 -6 1 85 85 85
-3 -6 1 85 85 85
-2 -6 1 85 85 85
-1 -6 1 85 85 85
0 -6 1 85 85 85
1 -6 1 85 85 85
2 -6 1 85 85 85
3 -6 1 85 85 85
4 -6 1 85 85 85
-5 -5 1 136 136 136
-4 -5 1 136 136 136
-3 -5 1 136 136 136
-2 -5 1 136 136 136
-1 -5 1 136 136 136
0 -5 1 136 136 136
1 -5 1 136 136 136
2 -5 1 136 136 136
3 -5 1 136 136 136
4 -5 1 136 136 136
-5 -4 1 85 85 85
-4 -4 1 85 85 85
-3 -4 1 85 85 85
-2 -4 1 85 85 85
-1 -4 1 85 85 85
0 -4 1 85 85 85
1 -4 1 85 85 85
2 -4 1 85 85 85
3 -4 1 85 85 85
4 -4 1 85 85 85
-5 -3 1 136 136 136
-4 -3 1 136 136 136
-3 -3 1 136 136 136
-2 -3 1 136 136 136
-1 -3 1 136 136 136
0 -3 1 136 136 136
1 -3 1 136 136 136
2 -3 1 136 136 136
3 -3 1 136 136 136
4 -3 1 136 136 136
-5 -2 1 85 85 85
-4 -2 1 85 85 85
-3 -2 1 85 85 85
-2 -2 1 85 85 85
-1 -2 1 85 85 85
0 -2 1 85 85 85
1 -2 1 85 85 85
2 -2 1 85 85 85
3 -2 1 85 85 85
4 -2 1 85 85 85
-5 -1 1 136 136 136
-4 -1 1 136 136 136
-3 -1 1 136 136 136
-2 -1 1 136 136 136
-1 -1 1 136 136 136
0 -1 1 136 136 136
1 -1 1 136 136 136
2 -1 1 136 136 136
3 -1 1 136 136 136
4 -1 1 136 136 136
-5 0 1 85 85 85
-4 0 1 85 85 85
-3 0 1 85 85 85
-2 0 1 85 85 85
-1 0 1 85 85 85
0 0 1 85 85 85
1 0 1 85 85 85
2 0 1 85 85 85
3 0 1 85 85 85
4 0 1 85 85 85
-5 1 1 136 136 136
-4 1 1 136 136 136
-3 1 1 136 136 136
-2 1 1 136 136 136
-1 1 1 136 136 136
0 1 1 136 136 136
1 1 1 136 136 136
2 1 1 136 136 136
3 1 1 136 136 136
4 1 1 136 136 136
-5 2 1 85 85 85
-4 2 1 85 85 85
-3 2 1 85 85 85
-2 2 1 85 85 85
-1 2 1 85 85 85
0 2 1 85 85 85
1 2 1 85 85 85
2 2 1 85 85 85
3 2 1 85 85 85
4 2 1 85 85 85
-5 3 1 136 136 136
4 3 1 136 136 136
-5 4 1 136 136 136
4 4 1 136 136 136
-5 5 1 136 136 136
4 5 1 136 136 136
-5 6 1 136 136 136
4 6 1 136 136 136
-5 7 1 136 136 136
4 7 1 136 136 136
-5 8 1 136 136 136
4 8 1 136 136 136
-5 9 1 136 136 136
4 9 1 136 136 136
-5 -10 2 136 136 136
-4 -10 2 136 136 136
-3 -10 2 136 136 136
-2 -10 2 136 136 136
-1 -10 2 136 136 136
0 -10 2 136 136 136
1 -10 2 136 136 136
2 -10 2 136 136 136
3 -10 2 136 136 136
4 -10 2 136 136 136
-5 -9 2 136 136 136
-4 -9 2 136 136 136
-3 -9 2 136 136 136
-2 -9 2 136 136 136
-1 -9 2 136 136 136
0 -9 2 136 136 136
1 -9 2 136 136 136
2 -9 2 136 136 136
3 -9 2 136 136 136
4 -9 2 136 136 136
-5 -8 2 136 136 136
-4 -8 2 136 136 136
-3 -8 2 136 136 136
-2 -8 2 136 136 136
-1 -8 2 136 136 136
0 -8 2 136 136 136
1 -8 2 136 136 136
2 -8 2 136 136 136
3 -8 2 136 136 136
4 -8 2 136 136 136
-5 -7 2 136 136 136
-4 -7 2 136 136 136
-3 -7 2 136 136 136
-2 -7 2 136 136 136
-1 -7 2 136 136 136
0 -7 2 136 136 136
1 -7 2 136 136 136
2 -7 2 136 136 136
3 -7 2 136 136 136
4 -7 2 136 136 136
-5 -6 2 85 85 85
-4 -6 2 85 85 85
-3 -6 2 85 85 85
-2 -6 2 85 85 85
-1 -6 2 85 85 85
0 -6 2 85 85 85
1 -6 2 85 85 85
2 -6 2 85 85 85
3 -6 2 85 85 85
4 -6 2 85 85 85
-5 -5 2 136 136 136
-4 -5 2 136 136 136
-3 -5 2 136 136 136
-2 -5 2 136 136 136
-1 -5 2 136 136 136
0 -5 2 136 136 136
1 -5 2 136 136 136
2 -5 2 136 136 136
3 -5 2 136 136 136
4 -5 2 136 136 136
-5 -4 2 85 85 85
-4 -4 2 85 85 85
-3 -4 2 85 85 85
-2 -4 2 85 85 85
-1 -4 2 85 85 85
0 -4 2 85 85 85
1 -4 2 85 85 85
2 -4 2 85 85 85
3 -4 2 85 85 85
4 -4 2 85 85 85
-5 -3 2 136 136 136
-4 -3 2 136 136 136
-3 -3 2 136 136 136
-2 -3 2 136 136 136
-1 -3 2 136 136 136
0 -3 2 136 136 136
1 -3 2 136 136 136
2 -3 2 136 136 136
3 -3 2 136 136 136
4 -3 2 136 136 136
-5 -2 2 85 85 85
-4 -2 2 85 85 85
-3 -2 2 85 85 85
-2 -2 2 85 85 85
-1 -2 2 85 85 85
0 -2 2 85 85 85
1 -2 2 85 85 85
2 -2 2 85 85 85
3 -2 2 85 85 85
4 -2 2 85 85 85
-5 -1 2 136 136 136
-4 -1 2 136 136 136
-3 -1 2 136 136 136
-2 -1 2 136 136 136
-1 -1 2 136 136 136
0 -1 2 136 136 136
1 -1 2 136 136 136
2 -1 2 136 136 136
3 -1 2 136 136 136
4 -1 2 136 136 136
-5 0 2 85 85 85
-4 0 2 85 85 85
-3 0 2 85 85 85
-2 0 2 85 85 85
-1 0 2 85 85 85
0 0 2 85 85 85
1 0 2 85 85 85
2 0 2 85 85 85
3 0 2 85 85 85
4 0 2 85 85 85
-5 1 2 136 136 136
-4 1 2 136 136 136
-3 1 2 136 136 136
-2 1 2 136 136 136
-1 1 2 136 136 136
0 1 2 136 136 136
1 1 2 136 136 136
2 1 2 136 136 136
3 1 2 136 136 136
4 1 2 136 136 136
-5 2 2 136 136 136
4 2 2 136 136 136
-5 3 2 136 136 136
4 3 2 136 136 136
-5 4 2 136 136 136
4 4 2 136 136 136
-5 5 2 136 136 136
4 5 2 136 136 136
-5 6 2 136 136 136
4 6 2 136 136 136
-5 7 2 136 136 136
4 7 2 136 136 136
-5 8 2 136 136 136
4 8 2 136 136 136
-5 9 2 136 136 136
4 9 2 136 136 136
-5 -10 3 136 136 136
-4 -10 3 136 136 136
-3 -10 3 136 136 136
-2 -10 3 136 136 136
-1 -10 3 136 136 136
0 -10 3 136 136 136
1 -10 3 136 136 136
2 -10 3 136 136 136
3 -10 3 136 136 136
4 -10 3 136 136 136
-5 -9 3 136 136 136
-4 -9 3 136 136 136
-3 -9 3 136 136 136
-2 -9 3 136 136 136
-1 -9 3 136 136 136
0 -9 3 136 136 136
1 -9 3 136 136 136
2 -9 3 136 136 136
3 -9 3 136 136 136
4 -9 3 136 136 136
-5 -8 3 136 136 136
-4 -8 3 136 136 136
-3 -8 3 136 136 136
-2 -8 3 136 136 136
-1 -8 3 136 136 136
0 -8 3 136 136 136
1 -8 3 136 136 136
2 -8 3 136 136 136
3 -8 3 136 136 136
4 -8 3 136 136 136
-5 -7 3 136 136 136
-4 -7 3 136 136 136
-3 -7 3 136 136 136
-2 -7 3 136 136 136
-1 -7 3 136 136 136
0 -7 3 136 136 136
1 -7 3 136 136 136
2 -7 3 136 136 136
3 -7 3 136 136 136
4 -7 3 136 136 136
-5 -6 3 85 85 85
-4 -6 3 85 85 85
-3 -6 3 85 85 85
-2 -6 3 85 85 85
-1 -6 3 85 85 85
0 -6 3 85 85 85
1 -6 3 85 85 85
2 -6 3 85 85 85
3 -6 3 85 85 85
4 -6 3 85 85 85
-5 -5 3 136 136 136
-4 -5 3 136 136 136
-3 -5 3 136 136 136
-2 -5 3 136 136 136
-1 -5 3 136 136 136
0 -5 3 136 136 136
1 -5 3 136 136 136
2 -5 3 136 136 136
3 -5 3 136 136 136
4 -5 3 136 136 136
-5 -4 3 85 85 85
-4 -4 3 85 85 85
-3 -4 3 85 85 85
-2 -4 3 85 85 85
-1 -4 3 85 85 85
0 -4 3 85 85 85
1 -4 3 85 85 85
2 -4 3 85 85 85
3 -4 3 85 85 85
4 -4 3 85 85 85
-5 -3 3 136 136 136
-4 -3 3 136 136 136
-3 -3 3 136 136 136
-2 -3 3 136 136 136
-1 -3 3 136 136 136
0 -3 3 136 136 136
1 -3 3 136 136 136
2 -3 3 136 136 136
3 -3 3 136 136 136
4 -3 3 136 136 136
-5 -2 3 85 85 85
-4 -2 3 85 85 85
-3 -2 3 85 85 85
-2 -2 3 85 85 85
-1 -2 3 85 85 85
0 -2 3 85 85 85
1 -2 3 85 85 85
2 -2 3 85 85 85
3 -2 3 85 85 85
4 -2 3 85 85 85
-5 -1 3 136 136 136
-4 -1 3 136 136 136
-3 -1 3 136 136 136
-2 -1 3 136 136 136
-1 -1 3 136 136 136
0 -1 3 136 136 136
1 -1 3 136 136 136
2 -1 3 136 136 136
3 -1 3 136 136 136
4 -1 3 136 136 136
-5 0 3 85 85 85
-4 0 3 85 85 85
-3 0 3 85 85 85
-2 0 3 85 85 85
-1 0 3 85 85 85
0 0 3 85 85 85
1 0 3 85 85 85
2 0 3 85 85 85
3 0 3 85 85 85
4 0 3 85 85 85
-5 1 3 136 136 136
4 1 3 136 136 136
-5 2 3 136 136 136
4 2 3 136 136 136
-5 3 3 136 136 136
4 3 3 136 136 136
-5 4 3 136 136 136
4 4 3 136 136 136
-5 5 3 136 136 136
4 5 3 136 136 136
-5 6 3 136 136 136
4 6 3 136 136 136
-5 7 3 136 136 136
4 7 3 136 136 136
-5 8 3 136 136 136
4 8 3 136 136 136
-5 9 3 136 136 136
4 9 3 136 136 136
-5 -10 4 136 136 136
-4 -10 4 136 136 136
-3 -10 4 136 136 136
-2 -10 4 136 136 136
-1 -10 4 136 136 136
0 -10 4 136 136 136
1 -10 4 136 136 136
2 -10 4 136 136 136
3 -10 4 136 136 136
4 -10 4 136 136 136
-5 -9 4 136 136 136
-4 -9 4 136 136 136
-3 -9 4 136 136 136
-2 -9 4 136 136 136
-1 -9 4 136 136 136
0 -9 4 136 136 136
1 -9 4 136 136 136
2 -9 4 136 136 136
3 -9 4 136 136 136
4 -9 4 136 136 136
-5 -8 4 136 136 136
-4 -8 4 136 136 136
-3 -8 4 136 136 136
-2 -8 4 136 136 136
-1 -8 4 136 136 136
0 -8 4 136 136 136
1 -8 4 136 136 136
2 -8 4 136 136 136
3 -8 4 136 136 136
4 -8 4 136 136 136
-5 -7 4 136 136 136
-4 -7 4 136 136 136
-3 -7 4 136 136 136
-2 -7 4 136 136 136
-1 -7 4 136 136 136
0 -7 4 136 136 136
1 -7 4 136 136 136
2 -7 4 136 136 136
3 -7 4 136 136 136
4 -7 4 136 136 136
-5 -6 4 85 85 85
-4 -6 4 85 85 85
-3 -6 4 85 85 85
-2 -6 4 85 85 85
-1 -6 4 85 85 85
0 -6 4 85 85 85
1 -6 4 85 85 85
2 -6 4 85 85 85
3 -6 4 85 85 85
4 -6 4 85 85 85
-5 -5 4 136 136 136
-4 -5 4 136 136 136
-3 -5 4 136 136 136
-2 -5 4 136 136 136
-1 -5 4 136 136 136
0 -5 4 136 136 136
1 -5 4 136 136 136
2 -5 4 136 136 136
3 -5 4 136 136 136
4 -5 4 136 136 136
-5 -4 4 85 85 85
-4 -4 4 85 85 85
-3 -4 4 85 85 85
-2 -4 4 85 85 85
-1 -4 4 85 85 85
0 -4 4 85 85 85
1 -4 4 85 85 85
2 -4 4 85 85 85
3 -4 4 85 85 85
4 -4 4 85 85 85
-5 -3 4 136 136 136
-4 -3 4 136 136 136
-3 -3 4 136 136 136
-2 -3 4 136 136 136
-1 -3 4 136 136 136
0 -3 4 136 136 136
1 -3 4 136 136 136
2 -3 4 136 136 136
3 -3 4 136 136 136
4 -3 4 136 136 136
-5 -2 4 85 85 85
-4 -2 4 85 85 85
-3 -2 4 85 85 85
-2 -2 4 85 85 85
-1 -2 4 85 85 85
0 -2 4 85 85 85
1 -2 4 85 85 85
2 -2 4 85 85 85
3 -2 4 85 85 85
4 -2 4 85 85 85
-5 -1 4 136 136 136
-4 -1 4 136 136 136
-3 -1 4 136 136 136
-2 -1 4 136 136 136
-1 -1 4 136 136 136
0 -1 4 136 136 136
1 -1 4 136 136 136
2 -1 4 136 136 136
3 -1 4 136 136 136
4 -1 4 136 136 136
-5 0 4 136 136 136
4 0 4 136 136 136
-5 1 4 136 136 136
4 1 4 136 136 136
-5 2 4 136 136 136
4 2 4 136 136 136
-5 3 4 136 136 136
4 3 4 136 136 136
-5 4 4 136 136 136
4 4 4 136 136 136
-5 5 4 136 136 136
4 5 4 136 136 136
-5 6 4 136 136 136
4 6 4 136 136 136
-5 7 4 136 136 136
4 7 4 136 136 136
-5 8 4 136 136 136
4 8 4 136 136 136
-5 9 4 136 136 136
4 9 4 136 136 136
-5 -10 5 136 136 136
-4 -10 5 136 136 136
-3 -10 5 136 136 136
-2 -10 5 136 136 136
-1 -10 5 136 136 136
0 -10 5 136 136 136
1 -10 5 136 136 136
2 -10 5 136 136 136
3 -10 5 136 136 136
4 -10 5 136 136 136
-5 -9 5 136 136 136
-4 -9 5 136 136 136
-3 -9 5 136 136 136
-2 -9 5 136 136 136
-1 -9 5 136 136 136
0 -9 5 136 136 136
1 -9 5 136 136 136
2 -9 5 136 136 136
3 -9 5 136 136 136
4 -9 5 136 136 136
-5 -8 5 136 136 136
-4 -8 5 136 136 136
-3 -8 5 136 136 136
-2 -8 5 136 136 136
-1 -8 5 136 136 136
0 -8 5 136 136 136
1 -8 5 136 136 136
2 -8 5 136 136 136
3 -8 5 136 136 136
4 -8 5 136 136 136
-5 -7 5 136 136 136
-4 -7 5 136 136 136
-3 -7 5 136 136 136
-2 -7 5 136 136 136
-1 -7 5 136 136 136
0 -7 5 136 136 136
1 -7 5 136 136 136
2 -7 5 136 136 136
3 -7 5 136 136 136
4 -7 5 136 136 136
-5 -6 5 85 85 85
-4 -6 5 85 85 85
-3 -6 5 85 85 85
-2 -6 5 85 85 85
-1 -6 5 85 85 85
0 -6 5 85 85 85
1 -6 5 85 85 85
2 -6 5 85 85 85
3 -6 5 85 85 85
4 -6 5 85 85 85
-5 -5 5 136 136 136
-4 -5 5 136 136 136
-3 -5 5 136 136 136
-2 -5 5 136 136 136
-1 -5 5 136 136 136
0 -5 5 136 136 136
1 -5 5 136 136 136
2 -5 5 136 136 136
3 -5 5 136 136 136
4 -5 5 136 136 136
-5 -4 5 85 85 85
-4 -4 5 85 85 85
-3 -4 5 85 85 85
-2 -4 5 85 85 85
-1 -4 5 85 85 85
0 -4 5 85 85 85
1 -4 5 85 85 85
2 -4 5 85 85 85
3 -4 5 85 85 85
4 -4 5 85 85 85
-5 -3 5 136 136 136
-4 -3 5 136 136 136
-3 -3 5 136 136 136
-2 -3 5 136 136 136
-1 -3 5 136 136 136
0 -3 5 136 136 136
1 -3 5 136 136 136
2 -3 5 136 136 136
3 -3 5 136 136 136
4 -3 5 136 136 136
-5 -2 5 85 85 85
-4 -2 5 85 85 85
-3 -2 5 85 85 85
-2 -2 5 85 85 85
-1 -2 5 85 85 85
0 -2 5 85 85 85
1 -2 5 85 85 85
2 -2 5 85 85 85
3 -2 5 85 85 85
4 -2 5 85 85 85
-5 -1 5 136 136 136
4 -1 5 136 136 136
-5 0 5 136 136 136
4 0 5 136 136 136
-5 1 5 136 136 136
4 1 5 136 136 136
-5 2 5 136 136 136
4 2 5 136 136 136
-5 3 5 136 136 136
4 3 5 136 136 136
-5 4 5 136 136 136
4 4 5 136 136 136
-5 5 5 136 136 136
4 5 5 136 136 136
-5 6 5 136 136 136
4 6 5 136 136 136
-5 7 5 136 136 136
4 7 5 136 136 136
-5 8 5 136 136 136
4 8 5 136 136 136
-5 9 5 136 136 136
4 9 5 136 136 136
-5 -10 6 136 136 136
-4 -10 6 136 136 136
-3 -10 6 136 136 136
-2 -10 6 136 136 136
-1 -10 6 136 136 136
0 -10 6 136 136 136
1 -10 6 136 136 136
2 -10 6 136 136 136
3 -10 6 136 136 136
4 -10 6 136 136 136
-5 -9 6 136 136 136
-4 -9 6 136 136 136
-3 -9 6 136 136 136
-2 -9 6 136 136 136
-1 -9 6 136 136 136
0 -9 6 136 136 136
1 -9 6 136 136 136
2 -9 6 136 136 136
3 -9 6 136 136 136
4 -9 6 136 136 136
-5 -8 6 136 136 136
-4 -8 6 136 136 136
-3 -8 6 136 136 136
-2 -8 6 136 136 136
-1 -8 6 136 136 136
0 -8 6 136 136 136
1 -8 6 136 136 136
2 -8 6 136 136 136
3 -8 6 136 136 136
4 -8 6 136 136 136
-5 -7 6 136 136 136
-4 -7 6 136 136 136
-3 -7 6 136 136 136
-2 -7 6 136 136 136
-1 -7 6 136 136 136
0 -7 6 136 136 136
1 -7 6 136 136 136
2 -7 6 136 136 136
3 -7 6 136 136 136
4 -7 6 136 136 136
-5 -6 6 85 85 85
-4 -6 6 85 85 85
-3 -6 6 85 85 85
-2 -6 6 85 85 85
-1 -6 6 85 85 85
0 -6 6 85 85 85
1 -6 6 85 85 85
2 -6 6 85 85 85
3 -6 6 85 85 85
4 -6 6 85 85 85
-5 -5 6 136 136 136
-4 -5 6 136 136 136
-3 -5 6 136 136 136
-2 -5 6 136 136 136
-1 -5 6 136 136 136
0 -5 6 136 136 136
1 -5 6 136 136 136
2 -5 6 136 136 136
3 -5 6 136 136 136
4 -5 6 136 136 136
-5 -4 6 85 85 85
-4 -4 6 85 85 85
-3 -4 6 85 85 85
-2 -4 6 85 85 85
-1 -4 6 85 85 85
0 -4 6 85 85 85
1 -4 6 85 85 85
2 -4 6 85 85 85
3 -4 6 85 85 85
4 -4 6 85 85 85
-5 -3 6 136 136 136
-4 -3 6 136 136 136
-3 -3 6 136 136 136
-2 -3 6 136 136 136
-1 -3 6 136 136 136
0 -3 6 136 136 136
1 -3 6 136 136 136
2 -3 6 136 136 136
3 -3 6 136 136 136
4 -3 6 136 136 136
-5 -2 6 136 136 136
4 -2 6 136 136 136
-5 -1 6 136 136 136
4 -1 6 136 136 136
-5 0 6 136 136 136
4 0 6 136 136 136
-5 1 6 136 136 136
4 1 6 136 136 136
-5 2 6 136 136 136
4 2 6 136 136 136
-5 3 6 136 136 136
4 3 6 136 136 136
-5 4 6 136 136 136
4 4 6 136 136 136
-5 5 6 136 136 136
4 5 6 136 136 136
-5 6 6 136 136 136
4 6 6 136 136 136
-5 7 6 136 136 136
4 7 6 136 136 136
-5 8 6 136 136 136
4 8 6 136 136 136
-5 9 6 136 136 136
4 9 6 136 136 136
-5 -10 7 136 136 136
-4 -10 7 136 136 136
-3 -10 7 136 136 136
-2 -10 7 136 136 136
-1 -10 7 136 136 136
0 -10 7 136 136 136
1 -10 7 136 136 136
2 -10 7 136 136 136
3 -10 7 136 136 136
4 -10 7 136 136 136
-5 -9 7 136 136 136
-4 -9 7 136 136 136
-3 -9 7 136 136 136
-2 -9 7 136 136 136
-1 -9 7 136 136 136
0 -9 7 136 136 136
1 -9 7 136 136 136
2 -9 7 136 136 136
3 -9 7 136 136 136
4 -9 7 136 136 136
-5 -8 7 136 136 136
-4 -8 7 136 136 136
-3 -8 7 136 136 136
-2 -8 7 136 136 136
-1 -8 7 136 136 136
0 -8 7 136 136 136
1 -8 7 136 136 136
2 -8 7 136 136 136
3 -8 7 136 136 136
4 -8 7 136 136 136
-5 -7 7 136 136 136
-4 -7 7 136 136 136
-3 -7 7 136 136 136
-2 -7 7 136 136 136
-1 -7 7 136 136 136
0 -7 7 136 136 136
1 -7 7 136 136 136
2 -7 7 136 136 136
3 -7 7 136 136 136
4 -7 7 136 136 136
-5 -6 7 85 85 85
-4 -6 7 85 85 85
-3 -6 7 85 85 85
-2 -6 7 85 85 85
-1 -6 7 85 85 85
0 -6 7 85 85 85
1 -6 7 85 85 85
2 -6 7 85 85 85
3 -6 7 85 85 85
4 -6 7 85 85 85
-5 -5 7 136 136 136
-4 -5 7 136 136 136
-3 -5 7 136 136 136
-2 -5 7 136 136 136
-1 -5 7 136 136 136
0 -5 7 136 136 136
1 -5 7 136 136 136
2 -5 7 136 136 136
3 -5 7 136 136 136
4 -5 7 136 136 136
-5 -4 7 85 85 85
-4 -4 7 85 85 85
-3 -4 7 85 85 85
-2 -4 7 85 85 85
-1 -4 7 85 85 85
0 -4 7 85 85 85
1 -4 7 85 85 85
2 -4 7 85 85 85
3 -4 7 85 85 85
4 -4 7 85 85 85
-5 -3 7 136 136 136
4 -3 7 136 136 136
-5 -2 7 136 136 136
4 -2 7 136 136 136
-5 -1 7 136 136 136
4 -1 7 136 136 136
-5 0 7 136 136 136
4 0 7 136 136 136
-5 1 7 136 136 136
4 1 7 136 136 136
-5 2 7 136 136 136
4 2 7 136 136 136
-5 3 7 136 136 136
4 3 7 136 136 136
-5 4 7 136 136 136
4 4 7 136 136 136
-5 5 7 136 136 136
4 5 7 136 136 136
-5 6 7 136 136 136
4 6 7 136 136 136
-5 7 7 136 136 136
4 7 7 136 136 136
-5 8 7 136 136 136
4 8 7 136 136 136
-5 9 7 136 136 136
4 9 7 136 136 136
-5 -10 8 136 136 136
-4 -10 8 136 136 136
-3 -10 8 136 136 136
-2 -10 8 136 136 136
-1 -10 8 136 136 136
0 -10 8 136 136 136
1 -10 8 136 136 136
2 -10 8 136 136 136
3 -10 8 136 136 136
4 -10 8 136 136 136
-5 -9 8 136 136 136
-4 -9 8 136 136 136
-3 -9 8 136 136 136
-2 -9 8 136 136 136
-1 -9 8 136 136 136
0 -9 8 136 136 136
1 -9 8 136 136 136
2 -9 8 136 136 136
3 -9 8 136 136 136
4 -9 8 136 136 136
-5 -8 8 136 136 136
-4 -8 8 136 136 136
-3 -8 8 136 136 136
-2 -8 8 136 136 136
-1 -8 8 136 136 136
0 -8 8 136 136 136
1 -8 8 136 136 136
2 -8 8 136 136 136
3 -8 8 136 136 136
4 -8 8 136 136 136
-5 -7 8 136 136 136
-4 -7 8 136 136 136
-3 -7 8 136 136 136
-2 -7 8 136 136 136
-1 -7 8 136 136 136
0 -7 8 136 136 136
1 -7 8 136 136 136
2 -7 8 136 136 136
3 -7 8 136 136 136
4 -7 8 136 136 136
-5 -6 8 85 85 85
-4 -6 8 85 85 85
-3 -6 8 85 85 85
-2 -6 8 85 85 85
-1 -6 8 85 85 85
0 -6 8 85 85 85
1 -6 8 85 85 85
2 -6 8 85 85 85
3 -6 8 85 85 85
4 -6 8 85 85 85
-5 -5 8 136 136 136
-4 -5 8 136 136 136
-3 -5 8 136 136 136
-2 -5 8 136 136 136
-1 -5 8 136 136 136
0 -5 8 136 136 136
1 -5 8 136 136 136
2 -5 8 136 136 136
3 -5 8 136 136 136
4 -5 8 136 136 136
-5 -4 8 136 136 136
4 -4 8 136 136 136
-5 -3 8 136 136 136
4 -3 8 136 136 136
-5 -2 8 136 136 136
4 -2 8 136 136 136
-5 -1 8 136 136 136
4 -1 8 136 136 136
-5 0 8 136 136 136
4 0 8 136 136 136
-5 1 8 136 136 136
4 1 8 136 136 136
-5 2 8 136 136 136
4 2 8 136 136 136
-5 3 8 136 136 136
4 3 8 136 136 136
-5 4 8 136 136 136
4 4 8 136 136 136
-5 5 8 136 136 136
4 5 8 136 136 136
-5 6 8 136 136 136
4 6 8 136 136 136
-5 7 8 136 136 136
4 7 8 136 136 136
-5 8 8 136 136 136
4 8 8 136 136 136
-5 9 8 136 136 136
4 9 8 136 136 136
-5 -10 9 136 136 136
-4 -10 9 136 136 136
-3 -10 9 136 136 136
-2 -10 9 136 136 136
-1 -10 9 136 136 136
0 -10 9 136 136 136
1 -10 9 136 136 136
2 -10 9 136 136 136
3 -10 9 136 136 136
4 -10 9 136 136 136
-5 -9 9 136 136 136
-4 -9 9 136 136 136
-3 -9 9 136 136 136
-2 -9 9 136 136 136
-1 -9 9 136 136 136
0 -9 9 136 136 136
1 -9 9 136 136 136
2 -9 9 136 136 136
3 -9 9 136 136 136
4 -9 9 136 136 136
-5 -8 9 136 136 136
-4 -8 9 136 136 136
-3 -8 9 136 136 136
-2 -8 9 136 136 136
-1 -8 9 136 136 136
0 -8 9 136 136 136
1 -8 9 136 136 136
2 -8 9 136 136 136
3 -8 9 136 136 136
4 -8 9 136 136 136
-5 -7 9 136 136 136
-4 -7 9 136 136 136
-3 -7 9 136 136 136
-2 -7 9 136 136 136
-1 -7 9 136 136 136
0 -7 9 136 136 136
1 -7 9 136 136 136
2 -7 9 136 136 136
3 -7 9 136 136 136
4 -7 9 136 136 136
-5 -6 9 85 85 85
-4 -6 9 85 85 85
-3 -6 9 85 85 85
-2 -6 9 85 85 85
-1 -6 9 85 85 85
0 -6 9 85 85 85
1 -6 9 85 85 85
2 -6 9 85 85 85
3 -6 9 85 85 85
4 -6 9 85 85 85
-5 -5 9 136 136 136
4 -5 9 136 136 136
-5 -4 9 136 136 136
4 -4 9 136 136 136
-5 -3 9 136 136 136
4 -3 9 136 136 136
-5 -2 9 136 136 136
4 -2 9 136 136 136
-5 -1 9 136 136 136
4 -1 9 136 136 136
-5 0 9 136 136 136
4 0 9 136 136 136
-5 1 9 136 136 136
4 1 9 136 136 136
-5 2 9 136 136 136
4 2 9 136 136 136
-5 3 9 136 136 136
4 3 9 136 136 136
-5 4 9 136 136 136
4 4 9 136 136 136
-5 5 9 136 136 136
4 5 9 136 136 136
-5 6 9 136 136 136
4 6 9 136 136 136
-5 7 9 136 136 136
4 7 9 136 136 136
-5 8 9 136 136 136
4 8 9 136 136 136
-5 9 9 136 136 136
-4 9 9 136 136 136
-3 9 9 136 136 136
-2 9 9 136 136 136
-1 9 9 136 136 136
0 9 9 136 136 136
1 9 9 136 136 136
2 9 9 136 136 136
3 9 9 136 136 136
4 9 9 136 136 136
-5 -10 10 136 136 136
-4 -10 10 136 136 136
-3 -10 10 136 136 136
-2 -10 10 136 136 136
-1 -10 10 136 136 136
0 -10 10 136 136 136
1 -10 10 136 136 136
2 -10 10 136 136 136
3 -10 10 136 136 136
4 -10 10 136 136 136
-5 -9 10 136 136 136
-4 -9 10 136 136 136
-3 -9 10 136 136 136
-2 -9 10 136 136 136
-1 -9 10 136 136 136
0 -9 10 136 136 136
1 -9 10 136 136 136
2 -9 10 136 136 136
3 -9 10 136 136 136
4 -9 10 136 136 136
-5 -8 10 136 136 136
-4 -8 10 136 136 136
-3 -8 10 136 136 136
-2 -8 10 136 136 136
-1 -8 10 136 136 136
0 -8 10 136 136 136
1 -8 10 136 136 136
2 -8 10 136 136 136
3 -8 10 136 136 136
4 -8 10 136 136 136
-5 -7 10 136 136 136
-4 -7 10 136 136 136
-3 -7 10 136 136 136
-2 -7 10 136 136 136
-1 -7 10 136 136 136
0 -7 10 136 136 136
1 -7 10 136 136 136
2 -7 10 136 136 136
3 -7 10 136 136 136
4 -7 10 136 136 136
-5 -6 10 136 136 136
4 -6 10 136 136 136
-5 -5 10 136 136 136
4 -5 10 136 136 136
-5 -4 10 136 136 136
4 -4 10 136 136 136
-5 -3 10 136 136 136
4 -3 10 136 136 136
-5 -2 10 136 136 136
4 -2 10 136 136 136
-5 -1 10 136 136 136
4 -1 10 136 136 136
-5 0 10 136 136 136
4 0 10 136 136 136
-5 1 10 136 136 136
4 1 10 136 136 136
-5 2 10 136 136 136
4 2 10 136 136 136
-5 3 10 136 136 136
4 3 10 136 136 136
-5 4 10 136 136 136
4 4 10 136 136 136
-5 5 10 136 136 136
4 5 10 136 136 136
-5 6 10 136 136 136
4 6 10 136 136 136
-5 7 10 136 136 136
4 7 10 136 136 136
-5 8 10 136 136 136
4 8 10 136 136 136
-5 9 10 136 136 136
-4 9 10 136 136 136
-3 9 10 136 136 136
-2 9 10 136 136 136
-1 9 10 136 136 136
0 9 10 136 136 136
1 9 10 136 136 136
2 9 10 136 136 136
3 9 10 136 136 136
4 9 10 136 136 136
-5 -10 11 136 136 136
4 -10 11 136 136 136
-5 -9 11 136 136 136
4 -9 11 136 136 136
-5 -8 11 136 136 136
4 -8 11 136 136 136
-5 -7 11 136 136 136
4 -7 11 136 136 136
-5 -6 11 136 136 136
4 -6 11 136 136 136
-5 -5 11 136 136 136
4 -5 11 136 136 136
-5 -4 11 136 136 136
4 -4 11 136 136 136
-5 -3 11 136 136 136
4 -3 11 136 136 136
-5 -2 11 136 136 136
4 -2 11 136 136 136
-5 -1 11 136 136 136
4 -1 11 136 136 136
-5 0 11 136 136 136
4 0 11 136 136 136
-5 1 11 136 136 136
4 1 11 136 136 136
-5 2 11 136 136 136
4 2 11 136 136 136
-5 3 11 136 136 136
4 3 11 136 136 136
-5 4 11 136 136 136
4 4 11 136 136 136
-5 5 11 136 136 136
4 5 11 136 136 136
-5 6 11 136 136 136
4 6 11 136 136 136
-5 7 11 136 136 136
4 7 11 136 136 136
-5 8 11 136 136 136
4 8 11 136 136 136
-5 9 11 136 136 136
-4 9 11 136 136 136
-3 9 11 136 136 136
-2 9 11 136 136 136
-1 9 11 136 136 136
0 9 11 136 136 136
1 9 11 136 136 136
2 9 11 136 136 136
3 9 11 136 136 136
4 9 11 136 136 136
-5 -10 12 136 136 136
4 -10 12 136 136 136
-5 -9 12 136 136 136
4 -9 12 136 136 136
-5 -8 12 136 136 136
4 -8 12 136 136 136
-5 -7 12 136 136 136
4 -7 12 136 136 136
-5 -6 12 136 136 136
4 -6 12 136 136 136
-5 -5 12 136 136 136
4 -5 12 136 136 136
-5 -4 12 136 136 136
4 -4 12 136 136 136
-5 -3 12 136 136 136
4 -3 12 136 136 136
-5 -2 12 136 136 136
4 -2 12 136 136 136
-5 -1 12 136 136 136
4 -1 12 136 136 136
-5 0 12 136 136 136
4 0 12 136 136 136
-5 1 12 136 136 136
4 1 12 136 136 136
-5 2 12 136 136 136
4 2 12 136 136 136
-5 3 12 136 136 136
4 3 12 136 136 136
-5 4 12 136 136 136
4 4 12 136 136 136
-5 5 12 136 136 136
4 5 12 136 136 136
-5 6 12 136 136 136
4 6 12 136 136 136
-5 7 12 136 136 136
4 7 12 136 136 136
-5 8 12 136 136 136
4 8 12 136 136 136
-5 9 12 136 136 136
-4 9 12 136 136 136
-3 9 12 136 136 136
-2 9 12 136 136 136
-1 9 12 136 136 136
0 9 12 136 136 136
1 9 12 136 136 136
2 9 12 136 136 136
3 9 12 136 136 136
4 9 12 136 136 136
-5 -10 13 136 136 136
4 -10 13 136 136 136
-5 -9 13 136 136 136
4 -9 13 136 136 136
-5 -8 13 136 136 136
4 -8 13 136 136 136
-5 -7 13 136 136 136
4 -7 13 136 136 136
-5 -6 13 136 136 136
4 -6 13 136 136 136
-5 -5 13 136 136 136
4 -5 13 136 136 136
-5 -4 13 136 136 136
4 -4 13 136 136 136
-5 -3 13 136 136 136
4 -3 13 136 136 136
-5 -2 13 136 136 136
4 -2 13 136 136 136
-5 -1 13 136 136 136
4 -1 13 136 136 136
-5 0 13 136 136 136
4 0 13 136 136 136
-5 1 13 136 136 136
4 1 13 136 136 136
-5 2 13 136 136 136
4 2 13 136 136 136
-5 3 13 136 136 136
4 3 13 136 136 136
-5 4 13 136 136 136
4 4 13 136 136 136
-5 5 13 136 136 136
4 5 13 136 136 136
-5 6 13 136 136 136
4 6 13 136 136 136
-5 7 13 136 136 136
4 7 13 136 136 136
-5 8 13 136 136 136
4 8 13 136 136 136
-5 9 13 136 136 136
-4 9 13 136 136 136
-3 9 13 136 136 136
-2 9 13 136 136 136
-1 9 13 136 136 136
0 9 13 136 136 136
1 9 13 136 136 136
2 9 13 136 136 136
3 9 13 136 136 136
4 9 13 136 136 136
-5 -10 14 136 136 136
4 -10 14 136 136 136
-5 -9 14 136 136 136
4 -9 14 136 136 136
-5 -8 14 136 136 136
4 -8 14 136 136 136
-5 -7 14 136 136 136
4 -7 14 136 136 136
-5 -6 14 136 136 136
4 -6 14 136 136 136
-5 -5 14 136 136 136
4 -5 14 136 136 136
-5 -4 14 136 136 136
4 -4 14 136 136 136
-5 -3 14 136 136 136
4 -3 14 136 136 136
-5 -2 14 136 136 136
4 -2 14 136 136 136
-5 -1 14 136 136 136
4 -1 14 136 136 136
-5 0 14 136 136 136
4 0 14 136 136 136
-5 1 14 136 136 136
4 1 14 136 136 136
-5 2 14 136 136 136
4 2 14 136 136 136
-5 3 14 136 136 136
4 3 14 136 136 136
-5 4 14 136 136 136
4 4 14 136 136 136
-5 5 14 136 136 136
4 5 14 136 136 136
-5 6 14 136 136 136
4 6 14 136 136 136
-5 7 14 136 136 136
4 7 14 136 136 136
-5 8 14 136 136 136
4 8 14 136 136 136
-5 9 14 136 136 136
-4 9 14 136 136 136
-3 9 14 136 136 136
-2 9 14 136 136 136
-1 9 14 136 136 136
0 9 14 136 136 136
1 9 14 136 136 136
2 9 14 136 136 136
3 9 14 136 136 136
4 9 14 136 136 136
-5 -10 15 136 136 136
4 -10 15 136 136 136
-5 -9 15 136 136 136
4 -9 15 136 136 136
-5 -8 15 136 136 136
4 -8 15 136 136 136
-5 -7 15 136 136 136
4 -7 15 136 136 136
-5 -6 15 136 136 136
4 -6 15 136 136 136
-5 -5 15 136 136 136
4 -5 15 136 136 136
-5 -4 15 136 136 136
4 -4 15 136 136 136
-5 -3 15 136 136 136
4 -3 15 136 136 136
-5 -2 15 136 136 136
4 -2 15 136 136 136
-5 -1 15 136 136 136
4 -1 15 136 136 136
-5 0 15 136 136 136
4 0 15 136 136 136
-5 1 15 136 136 136
4 1 15 136 136 136
-5 2 15 136 136 136
4 2 15 136 136 136
-5 3 15 136 136 136
4 3 15 136 136 136
-5 4 15 136 136 136
4 4 15 136 136 136
-5 5 15 136 136 136
4 5 15 136 136 136
-5 6 15 136 136 136
4 6 15 136 136 136
-5 7 15 136 136 136
4 7 15 136 136 136
-5 8 15 136 136 136
4 8 15 136 136 136
-5 9 15 136 136 136
-4 9 15 136 136 136
-3 9 15 136 136 136
-2 9 15 136 136 136
-1 9 15 136 136 136
0 9 15 136 136 136
1 9 15 136 136 136
2 9 15 136 136 136
3 9 15 136 136 136
4 9 15 136 136 136
-5 -10 16 136 136 136
4 -10 16 136 136 136
-5 -9 16 136 136 136
4 -9 16 136 136 136
-5 -8 16 136 136 136
4 -8 16 136 136 136
-5 -7 16 136 136 136
4 -7 16 136 136 136
-5 -6 16 136 136 136
4 -6 16 136 136 136
-5 -5 16 136 136 136
4 -5 16 136 136 136
-5 -4 16 136 136 136
4 -4 16 136 136 136
-5 -3 16 136 136 136
4 -3 16 136 136 136
-5 -2 16 136 136 136
4 -2 16 136 136 136
-5 -1 16 136 136 136
4 -1 16 136 136 136
-5 0 16 136 136 136
4 0 16 136 136 136
-5 1 16 136 136 136
4 1 16 136 136 136
-5 2 16 136 136 136
4 2 16 136 136 136
-5 3 16 136 136 136
4 3 16 136 136 136
-5 4 16 136 136 136
4 4 16 136 136 136
-5 5 16 136 136 136
4 5 16 136 136 136
-5 6 16 136 136 136
4 6 16 136 136 136
-5 7 16 136 136 136
4 7 16 136 136 136
-5 8 16 136 136 136
4 8 16 136 136 136
-5 9 16 136 136 136
-4 9 16 136 136 136
-3 9 16 136 136 136
-2 9 16 136 136 136
-1 9 16 136 136 136
0 9 16 136 136 136
1 9 16 136 136 136
2 9 16 136 136 136
3 9 16 136 136 136
4 9 16 136 136 136
-5 -10 17 136 136 136
4 -10 17 136 136 136
-5 -9 17 136 136 136
4 -9 17 136 136 136
-5 -8 17 136 136 136
4 -8 17 136 136 136
-5 -7 17 136 136 136
4 -7 17 136 136 136
-5 -6 17 136 136 136
4 -6 17 136 136 136
-5 -5 17 136 136 136
4 -5 17 136 136 136
-5 -4 17 136 136 136
4 -4 17 136 136 136
-5 -3 17 136 136 136
4 -3 17 136 136 136
-5 -2 17 136 136 136
4 -2 17 136 136 136
-5 -1 17 136 136 136
4 -1 17 136 136 136
-5 0 17 136 136 136
4 0 17 136 136 136
-5 1 17 136 136 136
4 1 17 136 136 136
-5 2 17 136 136 136
4 2 17 136 136 136
-5 3 17 136 136 136
4 3 17 136 136 136
-5 4 17 136 136 136
4 4 17 136 136 136
-5 5 17 136 136 136
4 5 17 136 136 136
-5 6 17 136 136 136
4 6 17 136 136 136
-5 7 17 136 136 136
4 7 17 136 136 136
-5 8 17 136 136 136
4 8 17 136 136 136
-5 9 17 136 136 136
-4 9 17 136 136 136
-3 9 17 136 136 136
-2 9 17 136 136 136
-1 9 17 136 136 136
0 9 17 136 136 136
1 9 17 136 136 136
2 9 17 136 136 136
3 9 17 136 136 136
4 9 17 136 136 136
-5 -10 18 136 136 136
4 -10 18 136 136 136
-5 -9 18 136 136 136
4 -9 18 136 136 136
-5 -8 18 136 136 136
4 -8 18 136 136 136
-5 -7 18 136 136 136
4 -7 18 136 136 136
-5 -6 18 136 136 136
4 -6 18 136 136 136
-5 -5 18 136 136 136
4 -5 18 136 136 136
-5 -4 18 136 136 136
4 -4 18 136 136 136
-5 -3 18 136 136 136
4 -3 18 136 136 136
-5 -2 18 136 136 136
4 -2 18 136 136 136
-5 -1 18 136 136 136
4 -1 18 136 136 136
-5 0 18 136 136 136
4 0 18 136 136 136
-5 1 18 136 136 136
4 1 18 136 136 136
-5 2 18 136 136 136
4 2 18 136 136 136
-5 3 18 136 136 136
4 3 18 136 136 136
-5 4 18 136 136 136
4 4 18 136 136 136
-5 5 18 136 136 136
4 5 18 136 136 136
-5 6 18 136 136 136
4 6 18 136 136 136
-5 7 18 136 136 136
4 7 18 136 136 136
-5 8 18 136 136 136
4 8 18 136 136 136
-5 9 18 136 136 136
-4 9 18 136 136 136
-3 9 18 136 136 136
-2 9 18 136 136 136
-1 9 18 136 136 136
0 9 18 136 136 136
1 9 18 136 136 136
2 9 18 136 136 136
3 9 18 136 136 136
4 9 18 136 136 136
-5 -10 19 136 136 136
-4 -10 19 136 136 136
-3 -10 19 136 136 136
-2 -10 19 136 136 136
-1 -10 19 136 136 136
0 -10 19 136 136 136
1 -10 19 136 136 136
2 -10 19 136 136 136
3 -10 19 136 136 136
4 -10 19 136 136 136
-5 -9 19 136 136 136
-4 -9 19 136 136 136
-3 -9 19 136 136 136
-2 -9 19 136 136 136
-1 -9 19 136 136 136
0 -9 19 136 136 136
1 -9 19 136 136 136
2 -9 19 136 136 136
3 -9 19 136 136 136
4 -9 19 136 136 136
-5 -8 19 136 136 136
-4 -8 19 136 136 136
-3 -8 19 136 136 136
-2 -8 19 136 136 136
-1 -8 19 136 136 136
0 -8 19 136 136 136
1 -8 19 136 136 136
2 -8 19 136 136 136
3 -8 19 136 136 136
4 -8 19 136 136 136
-5 -7 19 136 136 136
-4 -7 19 136 136 136
-3 -7 19 136 136 136
-2 -7 19 136 136 136
-1 -7 19 136 136 136
0 -7 19 136 136 136
1 -7 19 136 136 136
2 -7 19 136 136 136
3 -7 19 136 136 136
4 -7 19 136 136 136
-5 -6 19 136 136 136
-4 -6 19 136 136 136
-3 -6 19 136 136 136
-2 -6 19 136 136 136
-1 -6 19 136 136 136
0 -6 19 136 136 136
1 -6 19 136 136 136
2 -6 19 136 136 136
3 -6 19 136 136 136
4 -6 19 136 136 136
-5 -5 19 136 136 136
-4 -5 19 136 136 136
-3 -5 19 136 136 136
-2 -5 19 136 136 136
-1 -5 19 136 136 136
0 -5 19 136 136 136
1 -5 19 136 136 136
2 -5 19 136 136 136
3 -5 19 136 136 136
4 -5 19 136 136 136
-5 -4 19 136 136 136
-4 -4 19 136 136 136
-3 -4 19 136 136 136
-2 -4 19 136 136 136
-1 -4 19 136 136 136
0 -4 19 136 136 136
1 -4 19 136 136 136
2 -4 19 136 136 136
3 -4 19 136 136 136
4 -4 19 136 136 136
-5 -3 19 136 136 136
-4 -3 19 136 136 136
-3 -3 19 136 136 136
-2 -3 19 136 136 136
-1 -3 19 136 136 136
0 -3 19 136 136 136
1 -3 19 136 136 136
2 -3 19 136 136 136
3 -3 19 136 136 136
4 -3 19 136 136 136
-5 -2 19 136 136 136
-4 -2 19 136 136 136
-3 -2 19 136 136 136
-2 -2 19 136 136 136
-1 -2 19 136 136 136
0 -2 19 136 136 136
1 -2 19 136 136 136
2 -2 19 136 136 136
3 -2 19 136 136 136
4 -2 19 136 136 136
-5 -1 19 136 136 136
-4 -1 19 136 136 136
-3 -1 19 136 136 136
-2 -1 19 136 136 136
-1 -1 19 136 136 136
0 -1 19 136 136 136
1 -1 19 136 136 136
2 -1 19 136 136 136
3 -1 19 136 136 136
4 -1 19 136 136 136
-5 0 19 136 136 136
-4 0 19 136 136 136
-3 0 19 136 136 136
-2 0 19 136 136 136
-1 0 19 136 136 136
0 0 19 136 136 136
1 0 19 136 136 136
2 0 19 136 136 136
3 0 19 136 136 136
4 0 19 136 136 136
-5 1 19 136 136 136
-4 1 19 136 136 136
-3 1 19 136 136 136
-2 1 19 136 136 136
-1 1 19 136 136 136
0 1 19 136 136 136
1 1 19 136 136 136
2 1 19 136 136 136
3 1 19 136 136 136
4 1 19 136 136 136
-5 2 19 136 136 136
-4 2 19 136 136 136
-3 2 19 136 136 136
-2 2 19 136 136 136
-1 2 19 136 136 136
0 2 19 136 136 136
1 2 19 136 136 136
2 2 19 136 136 136
3 2 19 136 136 136
4 2 19 136 136 136
-5 3 19 136 136 136
-4 3 19 136 136 136
-3 3 19 136 136 136
-2 3 19 136 136 136
-1 3 19 136 136 136
0 3 19 136 136 136
1 3 19 136 136 136
2 3 19 136 136 136
3 3 19 136 136 136
4 3 19 136 136 136
-5 4 19 136 136 136
-4 4 19 136 136 136
-3 4 19 136 136 136
-2 4 19 136 136 136
-1 4 19 136 136 136
0 4 19 136 136 136
1 4 19 136 136 136
2 4 19 136 136 136
3 4 19 136 136 136
4 4 19 136 136 136
-5 5 19 136 136 136
-4 5 19 136 136 136
-3 5 19 136 136 136
-2 5 19 136 136 136
-1 5 19 136 136 136
0 5 19 136 136 136
1 5 19 136 136 136
2 5 19 136 136 136
3 5 19 136 136 136
4 5 19 136 136 136
-5 6 19 136 136 136
-4 6 19 136 136 136
-3 6 19 136 136 136
-2 6 19 136 136 136
-1 6 19 136 136 136
0 6 19 136 136 136
1 6 19 136 136 136
2 6 19 136 136 136
3 6 19 136 136 136
4 6 19 136 136 136
-5 7 19 136 136 136
-4 7 19 136 136 136
-3 7 19 136 136 136
-2 7 19 136 136 136
-1 7 19 136 136 136
0 7 19 136 136 136
1 7 19 136 136 136
2 7 19 136 136 136
3 7 19 136 136 136
4 7 19 136 136 136
-5 8 19 136 136 136
-4 8 19 136 136 136
-3 8 19 136 136 136
-2 8 19 136 136 136
-1 8 19 136 136 136
0 8 19 136 136 136
1 8 19 136 136 136
2 8 19 136 136 136
3 8 19 136 136 136
4 8 19 136 136 136
-5 9 19 136 136 136
-4 9 19 136 136 136
-3 9 19 136 136 136
-2 9 19 136 136 136
-1 9 19 136 136 136
0 9 19 136 136 136
1 9 19 136 136 136
2 9 19 136 136 136
3 9 19 136 136 136
4 9 19 136 136 136
