ply
format ascii 1.0
comment : MagicaVoxel @ Ephtracy
element vertex 8865
property float x
property float y
property float z
property uchar red
property uchar green
property uchar blue
end_header
-15 -15 0 176 176 176
-14 -15 0 176 176 176
-13 -15 0 176 176 176
-12 -15 0 176 176 176
-11 -15 0 176 176 176
-10 -15 0 176 176 176
-9 -15 0 176 176 176
-8 -15 0 176 176 176
-7 -15 0 176 176 176
-6 -15 0 176 176 176
-5 -15 0 176 176 176
-4 -15 0 176 176 176
-3 -15 0 176 176 176
-2 -15 0 176 176 176
-1 -15 0 176 176 176
0 -15 0 176 176 176
1 -15 0 176 176 176
2 -15 0 176 176 176
3 -15 0 176 176 176
4 -15 0 176 176 176
5 -15 0 176 176 176
6 -15 0 176 176 176
7 -15 0 176 176 176
8 -15 0 176 176 176
9 -15 0 176 176 176
10 -15 0 176 176 176
11 -15 0 176 176 176
12 -15 0 176 176 176
13 -15 0 176 176 176
14 -15 0 176 176 176
-15 -14 0 176 176 176
-14 -14 0 176 176 176
-13 -14 0 176 176 176
-12 -14 0 176 176 176
-11 -14 0 176 176 176
-10 -14 0 176 176 176
-9 -14 0 176 176 176
-8 -14 0 176 176 176
-7 -14 0 176 176 176
-6 -14 0 176 176 176
-5 -14 0 176 176 176
-4 -14 0 176 176 176
-3 -14 0 176 176 176
-2 -14 0 176 176 176
-1 -14 0 176 176 176
0 -14 0 176 176 176
1 -14 0 176 176 176
2 -14 0 176 176 176
3 -14 0 176 176 176
4 -14 0 176 176 176
5 -14 0 176 176 176
6 -14 0 176 176 176
7 -14 0 176 176 176
8 -14 0 176 176 176
9 -14 0 176 176 176
10 -14 0 176 176 176
11 -14 0 176 176 176
12 -14 0 176 176 176
13 -14 0 176 176 176
14 -14 0 176 176 176
-15 -13 0 176 176 176
-14 -13 0 176 176 176
-13 -13 0 176 176 176
-12 -13 0 176 176 176
-11 -13 0 176 176 176
-10 -13 0 176 176 176
-9 -13 0 176 176 176
-8 -13 0 176 176 176
-7 -13 0 176 176 176
-6 -13 0 176 176 176
-5 -13 0 176 176 176
-4 -13 0 176 176 176
-3 -13 0 176 176 176
-2 -13 0 176 176 176
-1 -13 0 176 176 176
0 -13 0 176 176 176
1 -13 0 176 176 176
2 -13 0 176 176 176
3 -13 0 176 176 176
4 -13 0 176 176 176
5 -13 0 176 176 176
6 -13 0 176 176 176
7 -13 0 176 176 176
8 -13 0 176 176 176
9 -13 0 176 176 176
10 -13 0 176 176 176
11 -13 0 176 176 176
12 -13 0 176 176 176
13 -13 0 176 176 176
14 -13 0 176 176 176
-15 -12 0 176 176 176
-14 -12 0 176 176 176
-13 -12 0 176 176 176
-12 -12 0 176 176 176
-11 -12 0 176 176 176
-10 -12 0 176 176 176
-9 -12 0 176 176 176
-8 -12 0 176 176 176
-7 -12 0 176 176 176
-6 -12 0 176 176 176
-5 -12 0 176 176 176
-4 -12 0 176 176 176
-3 -12 0 176 176 176
-2 -12 0 176 176 176
-1 -12 0 176 176 176
0 -12 0 176 176 176
1 -12 0 176 176 176
2 -12 0 176 176 176
3 -12 0 176 176 176
4 -12 0 176 176 176
5 -12 0 176 176 176
6 -12 0 176 176 176
7 -12 0 176 176 176
8 -12 0 176 176 176
9 -12 0 176 176 176
10 -12 0 176 176 176
11 -12 0 176 176 176
12 -12 0 176 176 176
13 -12 0 176 176 176
14 -12 0 176 176 176
-15 -11 0 176 176 176
-14 -11 0 176 176 176
-13 -11 0 176 176 176
-12 -11 0 176 176 176
-11 -11 0 176 176 176
-10 -11 0 176 176 176
-9 -11 0 176 176 176
-8 -11 0 176 176 176
-7 -11 0 176 176 176
-6 -11 0 176 176 176
-5 -11 0 176 176 176
-4 -11 0 176 176 176
-3 -11 0 176 176 176
-2 -11 0 176 176 176
-1 -11 0 176 176 176
0 -11 0 176 176 176
1 -11 0 176 176 176
2 -11 0 176 176 176
3 -11 0 176 176 176
4 -11 0 176 176 176
5 -11 0 176 176 176
6 -11 0 176 176 176
7 -11 0 176 176 176
8 -11 0 176 176 176
9 -11 0 176 176 176
10 -11 0 176 176 176
11 -11 0 176 176 176
12 -11 0 176 176 176
13 -11 0 176 176 176
14 -11 0 176 176 176
-15 -10 0 176 176 176
-14 -10 0 176 176 176
-13 -10 0 176 176 176
-12 -10 0 176 176 176
-11 -10 0 176 176 176
-10 -10 0 176 176 176
-9 -10 0 176 176 176
-8 -10 0 176 176 176
-7 -10 0 176 176 176
-6 -10 0 176 176 176
-5 -10 0 176 176 176
-4 -10 0 176 176 176
-3 -10 0 176 176 176
-2 -10 0 176 176 176
-1 -10 0 176 176 176
0 -10 0 176 176 176
1 -10 0 176 176 176
2 -10 0 176 176 176
3 -10 0 176 176 176
4 -10 0 176 176 176
5 -10 0 176 176 176
6 -10 0 176 176 176
7 -10 0 176 176 176
8 -10 0 176 176 176
9 -10 0 176 176 176
10 -10 0 176 176 176
11 -10 0 176 176 176
12 -10 0 176 176 176
13 -10 0 176 176 176
14 -10 0 176 176 176
-15 -9 0 176 176 176
-14 -9 0 176 176 176
-13 -9 0 176 176 176
-12 -9 0 176 176 176
-11 -9 0 176 176 176
-10 -9 0 176 176 176
-9 -9 0 176 176 176
-8 -9 0 176 176 176
-7 -9 0 176 176 176
-6 -9 0 176 176 176
-5 -9 0 176 176 176
-4 -9 0 176 176 176
-3 -9 0 176 176 176
-2 -9 0 176 176 176
-1 -9 0 176 176 176
0 -9 0 176 176 176
1 -9 0 176 176 176
2 -9 0 176 176 176
3 -9 0 176 176 176
4 -9 0 176 176 176
5 -9 0 176 176 176
6 -9 0 176 176 176
7 -9 0 176 176 176
8 -9 0 176 176 176
9 -9 0 176 176 176
10 -9 0 176 176 176
11 -9 0 176 176 176
12 -9 0 176 176 176
13 -9 0 176 176 176
14 -9 0 176 176 176
-15 -8 0 176 176 176
-14 -8 0 176 176 176
-13 -8 0 176 176 176
-12 -8 0 176 176 176
-11 -8 0 176 176 176
-10 -8 0 176 176 176
-9 -8 0 176 176 176
-8 -8 0 176 176 176
-7 -8 0 176 176 176
-6 -8 0 176 176 176
-5 -8 0 176 176 176
-4 -8 0 176 176 176
-3 -8 0 176 176 176
-2 -8 0 176 176 176
-1 -8 0 176 176 176
0 -8 0 176 176 176
1 -8 0 176 176 176
2 -8 0 176 176 176
3 -8 0 176 176 176
4 -8 0 176 176 176
5 -8 0 176 176 176
6 -8 0 176 176 176
7 -8 0 176 176 176
8 -8 0 176 176 176
9 -8 0 176 176 176
10 -8 0 176 176 176
11 -8 0 176 176 176
12 -8 0 176 176 176
13 -8 0 176 176 176
14 -8 0 176 176 176
-15 -7 0 176 176 176
-14 -7 0 176 176 176
-13 -7 0 176 176 176
-12 -7 0 176 176 176
-11 -7 0 176 176 176
-10 -7 0 176 176 176
-9 -7 0 176 176 176
-8 -7 0 176 176 176
-7 -7 0 176 176 176
-6 -7 0 176 176 176
-5 -7 0 176 176 176
-4 -7 0 176 176 176
-3 -7 0 176 176 176
-2 -7 0 176 176 176
-1 -7 0 176 176 176
0 -7 0 176 176 176
1 -7 0 176 176 176
2 -7 0 176 176 176
3 -7 0 176 176 176
4 -7 0 176 176 176
5 -7 0 176 176 176
6 -7 0 176 176 176
7 -7 0 176 176 176
8 -7 0 176 176 176
9 -7 0 176 176 176
10 -7 0 176 176 176
11 -7 0 176 176 176
12 -7 0 176 176 176
13 -7 0 176 176 176
14 -7 0 176 176 176
-15 -6 0 176 176 176
-14 -6 0 176 176 176
-13 -6 0 176 176 176
-12 -6 0 176 176 176
-11 -6 0 176 176 176
-10 -6 0 176 176 176
-9 -6 0 176 176 176
-8 -6 0 176 176 176
-7 -6 0 176 176 176
-6 -6 0 176 176 176
-5 -6 0 176 176 176
-4 -6 0 176 176 176
-3 -6 0 176 176 176
-2 -6 0 176 176 176
-1 -6 0 176 176 176
0 -6 0 176 176 176
1 -6 0 176 176 176
2 -6 0 176 176 176
3 -6 0 176 176 176
4 -6 0 176 176 176
5 -6 0 176 176 176
6 -6 0 176 176 176
7 -6 0 176 176 176
8 -6 0 176 176 176
9 -6 0 176 176 176
10 -6 0 176 176 176
11 -6 0 176 176 176
12 -6 0 176 176 176
13 -6 0 176 176 176
14 -6 0 176 176 176
-15 -5 0 176 176 176
-14 -5 0 176 176 176
-13 -5 0 176 176 176
-12 -5 0 176 176 176
-11 -5 0 176 176 176
-10 -5 0 176 176 176
-9 -5 0 176 176 176
-8 -5 0 176 176 176
-7 -5 0 176 176 176
-6 -5 0 176 176 176
-5 -5 0 176 176 176
-4 -5 0 176 176 176
-3 -5 0 176 176 176
-2 -5 0 176 176 176
-1 -5 0 176 176 176
0 -5 0 176 176 176
1 -5 0 176 176 176
2 -5 0 176 176 176
3 -5 0 176 176 176
4 -5 0 176 176 176
5 -5 0 176 176 176
6 -5 0 176 176 176
7 -5 0 176 176 176
8 -5 0 176 176 176
9 -5 0 176 176 176
10 -5 0 176 176 176
11 -5 0 176 176 176
12 -5 0 176 176 176
13 -5 0 176 176 176
14 -5 0 176 176 176
-15 -4 0 176 176 176
-14 -4 0 176 176 176
-13 -4 0 176 176 176
-12 -4 0 176 176 176
-11 -4 0 176 176 176
-10 -4 0 176 176 176
-9 -4 0 176 176 176
-8 -4 0 176 176 176
-7 -4 0 176 176 176
-6 -4 0 176 176 176
-5 -4 0 176 176 176
-4 -4 0 176 176 176
-3 -4 0 176 176 176
-2 -4 0 176 176 176
-1 -4 0 176 176 176
0 -4 0 176 176 176
1 -4 0 176 176 176
2 -4 0 176 176 176
3 -4 0 176 176 176
4 -4 0 176 176 176
5 -4 0 176 176 176
6 -4 0 176 176 176
7 -4 0 176 176 176
8 -4 0 176 176 176
9 -4 0 176 176 176
10 -4 0 176 176 176
11 -4 0 176 176 176
12 -4 0 176 176 176
13 -4 0 176 176 176
14 -4 0 176 176 176
-15 -3 0 176 176 176
-14 -3 0 176 176 176
-13 -3 0 176 176 176
-12 -3 0 176 176 176
-11 -3 0 176 176 176
-10 -3 0 176 176 176
-9 -3 0 176 176 176
-8 -3 0 176 176 176
-7 -3 0 176 176 176
-6 -3 0 176 176 176
-5 -3 0 176 176 176
-4 -3 0 176 176 176
-3 -3 0 176 176 176
-2 -3 0 176 176 176
-1 -3 0 176 176 176
0 -3 0 176 176 176
1 -3 0 176 176 176
2 -3 0 176 176 176
3 -3 0 176 176 176
4 -3 0 176 176 176
5 -3 0 176 176 176
6 -3 0 176 176 176
7 -3 0 176 176 176
8 -3 0 176 176 176
9 -3 0 176 176 176
10 -3 0 176 176 176
11 -3 0 176 176 176
12 -3 0 176 176 176
13 -3 0 176 176 176
14 -3 0 176 176 176
-15 -2 0 176 176 176
-14 -2 0 176 176 176
-13 -2 0 176 176 176
-12 -2 0 176 176 176
-11 -2 0 176 176 176
-10 -2 0 176 176 176
-9 -2 0 176 176 176
-8 -2 0 176 176 176
-7 -2 0 176 176 176
-6 -2 0 176 176 176
-5 -2 0 176 176 176
-4 -2 0 176 176 176
-3 -2 0 176 176 176
-2 -2 0 176 176 176
-1 -2 0 176 176 176
0 -2 0 176 176 176
1 -2 0 176 176 176
2 -2 0 176 176 176
3 -2 0 176 176 176
4 -2 0 176 176 176
5 -2 0 176 176 176
6 -2 0 176 176 176
7 -2 0 176 176 176
8 -2 0 176 176 176
9 -2 0 176 176 176
10 -2 0 176 176 176
11 -2 0 176 176 176
12 -2 0 176 176 176
13 -2 0 176 176 176
14 -2 0 176 176 176
-15 -1 0 176 176 176
-14 -1 0 176 176 176
-13 -1 0 176 176 176
-12 -1 0 176 176 176
-11 -1 0 176 176 176
-10 -1 0 176 176 176
-9 -1 0 176 176 176
-8 -1 0 176 176 176
-7 -1 0 176 176 176
-6 -1 0 176 176 176
-5 -1 0 176 176 176
-4 -1 0 176 176 176
-3 -1 0 176 176 176
-2 -1 0 176 176 176
-1 -1 0 176 176 176
0 -1 0 176 176 176
1 -1 0 176 176 176
2 -1 0 176 176 176
3 -1 0 176 176 176
4 -1 0 176 176 176
5 -1 0 176 176 176
6 -1 0 176 176 176
7 -1 0 176 176 176
8 -1 0 176 176 176
9 -1 0 176 176 176
10 -1 0 176 176 176
11 -1 0 176 176 176
12 -1 0 176 176 176
13 -1 0 176 176 176
14 -1 0 176 176 176
-15 0 0 176 176 176
-14 0 0 176 176 176
-13 0 0 176 176 176
-12 0 0 176 176 176
-11 0 0 176 176 176
-10 0 0 176 176 176
-9 0 0 176 176 176
-8 0 0 176 176 176
-7 0 0 176 176 176
-6 0 0 176 176 176
-5 0 0 176 176 176
-4 0 0 176 176 176
-3 0 0 176 176 176
-2 0 0 176 176 176
-1 0 0 176 176 176
0 0 0 176 176 176
1 0 0 176 176 176
2 0 0 176 176 176
3 0 0 176 176 176
4 0 0 176 176 176
5 0 0 176 176 176
6 0 0 176 176 176
7 0 0 176 176 176
8 0 0 176 176 176
9 0 0 176 176 176
10 0 0 176 176 176
11 0 0 176 176 176
12 0 0 176 176 176
13 0 0 176 176 176
14 0 0 176 176 176
-15 1 0 176 176 176
-14 1 0 176 176 176
-13 1 0 176 176 176
-12 1 0 176 176 176
-11 1 0 176 176 176
-10 1 0 176 176 176
-9 1 0 176 176 176
-8 1 0 176 176 176
-7 1 0 176 176 176
-6 1 0 176 176 176
-5 1 0 176 176 176
-4 1 0 176 176 176
-3 1 0 176 176 176
-2 1 0 176 176 176
-1 1 0 176 176 176
0 1 0 176 176 176
1 1 0 176 176 176
2 1 0 176 176 176
3 1 0 176 176 176
4 1 0 176 176 176
5 1 0 176 176 176
6 1 0 176 176 176
7 1 0 176 176 176
8 1 0 176 176 176
9 1 0 176 176 176
10 1 0 176 176 176
11 1 0 176 176 176
12 1 0 176 176 176
13 1 0 176 176 176
14 1 0 176 176 176
-15 2 0 176 176 176
-14 2 0 176 176 176
-13 2 0 176 176 176
-12 2 0 176 176 176
-11 2 0 176 176 176
-10 2 0 176 176 176
-9 2 0 176 176 176
-8 2 0 176 176 176
-7 2 0 176 176 176
-6 2 0 176 176 176
-5 2 0 176 176 176
-4 2 0 176 176 176
-3 2 0 176 176 176
-2 2 0 176 176 176
-1 2 0 176 176 176
0 2 0 176 176 176
1 2 0 176 176 176
2 2 0 176 176 176
3 2 0 176 176 176
4 2 0 176 176 176
5 2 0 176 176 176
6 2 0 176 176 176
7 2 0 176 176 176
8 2 0 176 176 176
9 2 0 176 176 176
10 2 0 176 176 176
11 2 0 176 176 176
12 2 0 176 176 176
13 2 0 176 176 176
14 2 0 176 176 176
-15 3 0 176 176 176
-14 3 0 176 176 176
-13 3 0 176 176 176
-12 3 0 176 176 176
-11 3 0 176 176 176
-10 3 0 176 176 176
-9 3 0 176 176 176
-8 3 0 176 176 176
-7 3 0 176 176 176
-6 3 0 176 176 176
-5 3 0 176 176 176
-4 3 0 176 176 176
-3 3 0 176 176 176
-2 3 0 176 176 176
-1 3 0 176 176 176
0 3 0 176 176 176
1 3 0 176 176 176
2 3 0 176 176 176
3 3 0 176 176 176
4 3 0 176 176 176
5 3 0 176 176 176
6 3 0 176 176 176
7 3 0 176 176 176
8 3 0 176 176 176
9 3 0 176 176 176
10 3 0 176 176 176
11 3 0 176 176 176
12 3 0 176 176 176
13 3 0 176 176 176
14 3 0 176 176 176
-15 4 0 176 176 176
-14 4 0 176 176 176
-13 4 0 176 176 176
-12 4 0 176 176 176
-11 4 0 176 176 176
-10 4 0 176 176 176
-9 4 0 176 176 176
-8 4 0 176 176 176
-7 4 0 176 176 176
-6 4 0 176 176 176
-5 4 0 176 176 176
-4 4 0 176 176 176
-3 4 0 176 176 176
-2 4 0 176 176 176
-1 4 0 176 176 176
0 4 0 176 176 176
1 4 0 176 176 176
2 4 0 176 176 176
3 4 0 176 176 176
4 4 0 176 176 176
5 4 0 176 176 176
6 4 0 176 176 176
7 4 0 176 176 176
8 4 0 176 176 176
9 4 0 176 176 176
10 4 0 176 176 176
11 4 0 176 176 176
12 4 0 176 176 176
13 4 0 176 176 176
14 4 0 176 176 176
-15 5 0 176 176 176
-14 5 0 176 176 176
-13 5 0 176 176 176
-12 5 0 176 176 176
-11 5 0 176 176 176
-10 5 0 176 176 176
-9 5 0 176 176 176
-8 5 0 176 176 176
-7 5 0 176 176 176
-6 5 0 176 176 176
-5 5 0 176 176 176
-4 5 0 176 176 176
-3 5 0 176 176 176
-2 5 0 176 176 176
-1 5 0 176 176 176
0 5 0 176 176 176
1 5 0 176 176 176
2 5 0 176 176 176
3 5 0 176 176 176
4 5 0 176 176 176
5 5 0 176 176 176
6 5 0 176 176 176
7 5 0 176 176 176
8 5 0 176 176 176
9 5 0 176 176 176
10 5 0 176 176 176
11 5 0 176 176 176
12 5 0 176 176 176
13 5 0 176 176 176
14 5 0 176 176 176
-15 6 0 176 176 176
-14 6 0 176 176 176
-13 6 0 176 176 176
-12 6 0 176 176 176
-11 6 0 176 176 176
-10 6 0 176 176 176
-9 6 0 176 176 176
-8 6 0 176 176 176
-7 6 0 176 176 176
-6 6 0 176 176 176
-5 6 0 176 176 176
-4 6 0 176 176 176
-3 6 0 176 176 176
-2 6 0 176 176 176
-1 6 0 176 176 176
0 6 0 176 176 176
1 6 0 176 176 176
2 6 0 176 176 176
3 6 0 176 176 176
4 6 0 176 176 176
5 6 0 176 176 176
6 6 0 176 176 176
7 6 0 176 176 176
8 6 0 176 176 176
9 6 0 176 176 176
10 6 0 176 176 176
11 6 0 176 176 176
12 6 0 176 176 176
13 6 0 176 176 176
14 6 0 176 176 176
-15 7 0 176 176 176
-14 7 0 176 176 176
-13 7 0 176 176 176
-12 7 0 176 176 176
-11 7 0 176 176 176
-10 7 0 176 176 176
-9 7 0 176 176 176
-8 7 0 176 176 176
-7 7 0 176 176 176
-6 7 0 176 176 176
-5 7 0 176 176 176
-4 7 0 176 176 176
-3 7 0 176 176 176
-2 7 0 176 176 176
-1 7 0 176 176 176
0 7 0 176 176 176
1 7 0 176 176 176
2 7 0 176 176 176
3 7 0 176 176 176
4 7 0 176 176 176
5 7 0 176 176 176
6 7 0 176 176 176
7 7 0 176 176 176
8 7 0 176 176 176
9 7 0 176 176 176
10 7 0 176 176 176
11 7 0 176 176 176
12 7 0 176 176 176
13 7 0 176 176 176
14 7 0 176 176 176
-15 8 0 176 176 176
-14 8 0 176 176 176
-13 8 0 176 176 176
-12 8 0 176 176 176
-11 8 0 176 176 176
-10 8 0 176 176 176
-9 8 0 176 176 176
-8 8 0 176 176 176
-7 8 0 176 176 176
-6 8 0 176 176 176
-5 8 0 176 176 176
-4 8 0 176 176 176
-3 8 0 176 176 176
-2 8 0 176 176 176
-1 8 0 176 176 176
0 8 0 176 176 176
1 8 0 176 176 176
2 8 0 176 176 176
3 8 0 176 176 176
4 8 0 176 176 176
5 8 0 176 176 176
6 8 0 176 176 176
7 8 0 176 176 176
8 8 0 176 176 176
9 8 0 176 176 176
10 8 0 176 176 176
11 8 0 176 176 176
12 8 0 176 176 176
13 8 0 176 176 176
14 8 0 176 176 176
-15 9 0 176 176 176
-14 9 0 176 176 176
-13 9 0 176 176 176
-12 9 0 176 176 176
-11 9 0 176 176 176
-10 9 0 176 176 176
-9 9 0 176 176 176
-8 9 0 176 176 176
-7 9 0 176 176 176
-6 9 0 176 176 176
-5 9 0 176 176 176
-4 9 0 176 176 176
-3 9 0 176 176 176
-2 9 0 176 176 176
-1 9 0 176 176 176
0 9 0 176 176 176
1 9 0 176 176 176
2 9 0 176 176 176
3 9 0 176 176 176
4 9 0 176 176 176
5 9 0 176 176 176
6 9 0 176 176 176
7 9 0 176 176 176
8 9 0 176 176 176
9 9 0 176 176 176
10 9 0 176 176 176
11 9 0 176 176 176
12 9 0 176 176 176
13 9 0 176 176 176
14 9 0 176 176 176
-15 10 0 176 176 176
-14 10 0 176 176 176
-13 10 0 176 176 176
-12 10 0 176 176 176
-11 10 0 176 176 176
-10 10 0 176 176 176
-9 10 0 176 176 176
-8 10 0 176 176 176
-7 10 0 176 176 176
-6 10 0 176 176 176
-5 10 0 176 176 176
-4 10 0 176 176 176
-3 10 0 176 176 176
-2 10 0 176 176 176
-1 10 0 176 176 176
0 10 0 176 176 176
1 10 0 176 176 176
2 10 0 176 176 176
3 10 0 176 176 176
4 10 0 176 176 176
5 10 0 176 176 176
6 10 0 176 176 176
7 10 0 176 176 176
8 10 0 176 176 176
9 10 0 176 176 176
10 10 0 176 176 176
11 10 0 176 176 176
12 10 0 176 176 176
13 10 0 176 176 176
14 10 0 176 176 176
-15 11 0 176 176 176
-14 11 0 176 176 176
-13 11 0 176 176 176
-12 11 0 176 176 176
-11 11 0 176 176 176
-10 11 0 176 176 176
-9 11 0 176 176 176
-8 11 0 176 176 176
-7 11 0 176 176 176
-6 11 0 176 176 176
-5 11 0 176 176 176
-4 11 0 176 176 176
-3 11 0 176 176 176
-2 11 0 176 176 176
-1 11 0 176 176 176
0 11 0 176 176 176
1 11 0 176 176 176
2 11 0 176 176 176
3 11 0 176 176 176
4 11 0 176 176 176
5 11 0 176 176 176
6 11 0 176 176 176
7 11 0 176 176 176
8 11 0 176 176 176
9 11 0 176 176 176
10 11 0 176 176 176
11 11 0 176 176 176
12 11 0 176 176 176
13 11 0 176 176 176
14 11 0 176 176 176
-15 12 0 176 176 176
-14 12 0 176 176 176
-13 12 0 176 176 176
-12 12 0 176 176 176
-11 12 0 176 176 176
-10 12 0 176 176 176
-9 12 0 176 176 176
-8 12 0 176 176 176
-7 12 0 176 176 176
-6 12 0 176 176 176
-5 12 0 176 176 176
-4 12 0 176 176 176
-3 12 0 176 176 176
-2 12 0 176 176 176
-1 12 0 176 176 176
0 12 0 176 176 176
1 12 0 176 176 176
2 12 0 176 176 176
3 12 0 176 176 176
4 12 0 176 176 176
5 12 0 176 176 176
6 12 0 176 176 176
7 12 0 176 176 176
8 12 0 176 176 176
9 12 0 176 176 176
10 12 0 176 176 176
11 12 0 176 176 176
12 12 0 176 176 176
13 12 0 176 176 176
14 12 0 176 176 176
-15 13 0 176 176 176
-14 13 0 176 176 176
-13 13 0 176 176 176
-12 13 0 176 176 176
-11 13 0 176 176 176
-10 13 0 176 176 176
-9 13 0 176 176 176
-8 13 0 176 176 176
-7 13 0 176 176 176
-6 13 0 176 176 176
-5 13 0 176 176 176
-4 13 0 176 176 176
-3 13 0 176 176 176
-2 13 0 176 176 176
-1 13 0 176 176 176
0 13 0 176 176 176
1 13 0 176 176 176
2 13 0 176 176 176
3 13 0 176 176 176
4 13 0 176 176 176
5 13 0 176 176 176
6 13 0 176 176 176
7 13 0 176 176 176
8 13 0 176 176 176
9 13 0 176 176 176
10 13 0 176 176 176
11 13 0 176 176 176
12 13 0 176 176 176
13 13 0 176 176 176
14 13 0 176 176 176
-15 14 0 176 176 176
-14 14 0 176 176 176
-13 14 0 176 176 176
-12 14 0 176 176 176
-11 14 0 176 176 176
-10 14 0 176 176 176
-9 14 0 176 176 176
-8 14 0 176 176 176
-7 14 0 176 176 176
-6 14 0 176 176 176
-5 14 0 176 176 176
-4 14 0 176 176 176
-3 14 0 176 176 176
-2 14 0 176 176 176
-1 14 0 176 176 176
0 14 0 176 176 176
1 14 0 176 176 176
2 14 0 176 176 176
3 14 0 176 176 176
4 14 0 176 176 176
5 14 0 176 176 176
6 14 0 176 176 176
7 14 0 176 176 176
8 14 0 176 176 176
9 14 0 176 176 176
10 14 0 176 176 176
11 14 0 176 176 176
12 14 0 176 176 176
13 14 0 176 176 176
14 14 0 176 176 176
-15 -15 1 176 176 176
-14 -15 1 176 176 176
-13 -15 1 176 176 176
-12 -15 1 176 176 176
-11 -15 1 176 176 176
-10 -15 1 176 176 176
-9 -15 1 176 176 176
-8 -15 1 176 176 176
-7 -15 1 176 176 176
-6 -15 1 176 176 176
-5 -15 1 176 176 176
-4 -15 1 176 176 176
-3 -15 1 176 176 176
-2 -15 1 176 176 176
-1 -15 1 176 176 176
0 -15 1 176 176 176
1 -15 1 176 176 176
2 -15 1 176 176 176
3 -15 1 176 176 176
4 -15 1 176 176 176
5 -15 1 176 176 176
6 -15 1 176 176 176
7 -15 1 176 176 176
8 -15 1 176 176 176
9 -15 1 176 176 176
10 -15 1 176 176 176
11 -15 1 176 176 176
12 -15 1 176 176 176
13 -15 1 176 176 176
14 -15 1 176 176 176
-15 -14 1 176 176 176
-14 -14 1 176 176 176
-13 -14 1 176 176 176
-12 -14 1 176 176 176
-11 -14 1 176 176 176
-10 -14 1 176 176 176
-9 -14 1 176 176 176
-8 -14 1 176 176 176
-7 -14 1 176 176 176
-6 -14 1 176 176 176
-5 -14 1 176 176 176
-4 -14 1 176 176 176
-3 -14 1 176 176 176
-2 -14 1 176 176 176
-1 -14 1 176 176 176
0 -14 1 176 176 176
1 -14 1 176 176 176
2 -14 1 176 176 176
3 -14 1 176 176 176
4 -14 1 176 176 176
5 -14 1 176 176 176
6 -14 1 176 176 176
7 -14 1 176 176 176
8 -14 1 176 176 176
9 -14 1 176 176 176
10 -14 1 176 176 176
11 -14 1 176 176 176
12 -14 1 176 176 176
13 -14 1 176 176 176
14 -14 1 176 176 176
-15 -13 1 176 176 176
-14 -13 1 176 176 176
-13 -13 1 176 176 176
-12 -13 1 176 176 176
-11 -13 1 176 176 176
-10 -13 1 176 176 176
-9 -13 1 176 176 176
-8 -13 1 176 176 176
-7 -13 1 176 176 176
-6 -13 1 176 176 176
-5 -13 1 176 176 176
-4 -13 1 176 176 176
-3 -13 1 176 176 176
-2 -13 1 176 176 176
-1 -13 1 176 176 176
0 -13 1 176 176 176
1 -13 1 176 176 176
2 -13 1 176 176 176
3 -13 1 176 176 176
4 -13 1 176 176 176
5 -13 1 176 176 176
6 -13 1 176 176 176
7 -13 1 176 176 176
8 -13 1 176 176 176
9 -13 1 176 176 176
10 -13 1 176 176 176
11 -13 1 176 176 176
12 -13 1 176 176 176
13 -13 1 176 176 176
14 -13 1 176 176 176
-15 -12 1 176 176 176
-14 -12 1 176 176 176
-13 -12 1 176 176 176
12 -12 1 176 176 176
13 -12 1 176 176 176
14 -12 1 176 176 176
-15 -11 1 176 176 176
-14 -11 1 176 176 176
-13 -11 1 176 176 176
12 -11 1 176 176 176
13 -11 1 176 176 176
14 -11 1 176 176 176
-15 -10 1 176 176 176
-14 -10 1 176 176 176
-13 -10 1 176 176 176
12 -10 1 176 176 176
13 -10 1 176 176 176
14 -10 1 176 176 176
-15 -9 1 176 176 176
-14 -9 1 176 176 176
-13 -9 1 176 176 176
12 -9 1 176 176 176
13 -9 1 176 176 176
14 -9 1 176 176 176
-15 -8 1 176 176 176
-14 -8 1 176 176 176
-13 -8 1 176 176 176
12 -8 1 176 176 176
13 -8 1 176 176 176
14 -8 1 176 176 176
-15 -7 1 176 176 176
-14 -7 1 176 176 176
-13 -7 1 176 176 176
12 -7 1 176 176 176
13 -7 1 176 176 176
14 -7 1 176 176 176
-15 -6 1 176 176 176
-14 -6 1 176 176 176
-13 -6 1 176 176 176
12 -6 1 176 176 176
13 -6 1 176 176 176
14 -6 1 176 176 176
-15 -5 1 176 176 176
-14 -5 1 176 176 176
-13 -5 1 176 176 176
12 -5 1 176 176 176
13 -5 1 176 176 176
14 -5 1 176 176 176
-15 -4 1 176 176 176
-14 -4 1 176 176 176
-13 -4 1 176 176 176
-12 -4 1 176 176 176
-11 -4 1 176 176 176
-10 -4 1 176 176 176
12 -4 1 176 176 176
13 -4 1 176 176 176
14 -4 1 176 176 176
-15 -3 1 176 176 176
-14 -3 1 176 176 176
-13 -3 1 176 176 176
-12 -3 1 176 176 176
-11 -3 1 176 176 176
-10 -3 1 176 176 176
12 -3 1 176 176 176
13 -3 1 176 176 176
14 -3 1 176 176 176
-15 -2 1 176 176 176
-14 -2 1 176 176 176
-13 -2 1 176 176 176
-12 -2 1 176 176 176
-11 -2 1 176 176 176
-10 -2 1 176 176 176
12 -2 1 176 176 176
13 -2 1 176 176 176
14 -2 1 176 176 176
-15 -1 1 176 176 176
-14 -1 1 176 176 176
-13 -1 1 176 176 176
-12 -1 1 176 176 176
-11 -1 1 176 176 176
-10 -1 1 176 176 176
12 -1 1 176 176 176
13 -1 1 176 176 176
14 -1 1 176 176 176
-15 0 1 176 176 176
-14 0 1 176 176 176
-13 0 1 176 176 176
-12 0 1 176 176 176
-11 0 1 176 176 176
-10 0 1 176 176 176
12 0 1 176 176 176
13 0 1 176 176 176
14 0 1 176 176 176
-15 1 1 176 176 176
-14 1 1 176 176 176
-13 1 1 176 176 176
-12 1 1 176 176 176
-11 1 1 176 176 176
-10 1 1 176 176 176
12 1 1 176 176 176
13 1 1 176 176 176
14 1 1 176 176 176
-15 2 1 176 176 176
-14 2 1 176 176 176
-13 2 1 176 176 176
-12 2 1 176 176 176
-11 2 1 176 176 176
-10 2 1 176 176 176
12 2 1 176 176 176
13 2 1 176 176 176
14 2 1 176 176 176
-15 3 1 176 176 176
-14 3 1 176 176 176
-13 3 1 176 176 176
12 3 1 176 176 176
13 3 1 176 176 176
14 3 1 176 176 176
-15 4 1 176 176 176
-14 4 1 176 176 176
-13 4 1 176 176 176
12 4 1 176 176 176
13 4 1 176 176 176
14 4 1 176 176 176
-15 5 1 176 176 176
-14 5 1 176 176 176
-13 5 1 176 176 176
12 5 1 176 176 176
13 5 1 176 176 176
14 5 1 176 176 176
-15 6 1 176 176 176
-14 6 1 176 176 176
-13 6 1 176 176 176
12 6 1 176 176 176
13 6 1 176 176 176
14 6 1 176 176 176
-15 7 1 176 176 176
-14 7 1 176 176 176
-13 7 1 176 176 176
12 7 1 176 176 176
13 7 1 176 176 176
14 7 1 176 176 176
-15 8 1 176 176 176
-14 8 1 176 176 176
-13 8 1 176 176 176
12 8 1 176 176 176
13 8 1 176 176 176
14 8 1 176 176 176
-15 9 1 176 176 176
-14 9 1 176 176 176
-13 9 1 176 176 176
12 9 1 176 176 176
13 9 1 176 176 176
14 9 1 176 176 176
-15 10 1 176 176 176
-14 10 1 176 176 176
-13 10 1 176 176 176
12 10 1 176 176 176
13 10 1 176 176 176
14 10 1 176 176 176
-15 11 1 176 176 176
-14 11 1 176 176 176
-13 11 1 176 176 176
12 11 1 176 176 176
13 11 1 176 176 176
14 11 1 176 176 176
-15 12 1 176 176 176
-14 12 1 176 176 176
-13 12 1 176 176 176
-12 12 1 176 176 176
-11 12 1 176 176 176
-10 12 1 176 176 176
-9 12 1 176 176 176
-8 12 1 176 176 176
-7 12 1 176 176 176
-6 12 1 176 176 176
-5 12 1 176 176 176
-4 12 1 176 176 176
-3 12 1 176 176 176
-2 12 1 176 176 176
-1 12 1 176 176 176
0 12 1 176 176 176
1 12 1 176 176 176
2 12 1 176 176 176
3 12 1 176 176 176
4 12 1 176 176 176
5 12 1 176 176 176
6 12 1 176 176 176
7 12 1 176 176 176
8 12 1 176 176 176
9 12 1 176 176 176
10 12 1 176 176 176
11 12 1 176 176 176
12 12 1 176 176 176
13 12 1 176 176 176
14 12 1 176 176 176
-15 13 1 176 176 176
-14 13 1 176 176 176
-13 13 1 176 176 176
-12 13 1 176 176 176
-11 13 1 176 176 176
-10 13 1 176 176 176
-9 13 1 176 176 176
-8 13 1 176 176 176
-7 13 1 176 176 176
-6 13 1 176 176 176
-5 13 1 176 176 176
-4 13 1 176 176 176
-3 13 1 176 176 176
-2 13 1 176 176 176
-1 13 1 176 176 176
0 13 1 176 176 176
1 13 1 176 176 176
2 13 1 176 176 176
3 13 1 176 176 176
4 13 1 176 176 176
5 13 1 176 176 176
6 13 1 176 176 176
7 13 1 176 176 176
8 13 1 176 176 176
9 13 1 176 176 176
10 13 1 176 176 176
11 13 1 176 176 176
12 13 1 176 176 176
13 13 1 176 176 176
14 13 1 176 176 176
-15 14 1 176 176 176
-14 14 1 176 176 176
-13 14 1 176 176 176
-12 14 1 176 176 176
-11 14 1 176 176 176
-10 14 1 176 176 176
-9 14 1 176 176 176
-8 14 1 176 176 176
-7 14 1 176 176 176
-6 14 1 176 176 176
-5 14 1 176 176 176
-4 14 1 176 176 176
-3 14 1 176 176 176
-2 14 1 176 176 176
-1 14 1 176 176 176
0 14 1 176 176 176
1 14 1 176 176 176
2 14 1 176 176 176
3 14 1 176 176 176
4 14 1 176 176 176
5 14 1 176 176 176
6 14 1 176 176 176
7 14 1 176 176 176
8 14 1 176 176 176
9 14 1 176 176 176
10 14 1 176 176 176
11 14 1 176 176 176
12 14 1 176 176 176
13 14 1 176 176 176
14 14 1 176 176 176
-15 -15 2 176 176 176
-14 -15 2 176 176 176
-13 -15 2 176 176 176
-12 -15 2 176 176 176
-11 -15 2 176 176 176
-10 -15 2 176 176 176
-9 -15 2 176 176 176
-8 -15 2 176 176 176
-7 -15 2 176 176 176
-6 -15 2 176 176 176
-5 -15 2 176 176 176
-4 -15 2 176 176 176
-3 -15 2 176 176 176
-2 -15 2 176 176 176
-1 -15 2 176 176 176
0 -15 2 176 176 176
1 -15 2 176 176 176
2 -15 2 176 176 176
3 -15 2 176 176 176
4 -15 2 176 176 176
5 -15 2 176 176 176
6 -15 2 176 176 176
7 -15 2 176 176 176
8 -15 2 176 176 176
9 -15 2 176 176 176
10 -15 2 176 176 176
11 -15 2 176 176 176
12 -15 2 176 176 176
13 -15 2 176 176 176
14 -15 2 176 176 176
-15 -14 2 176 176 176
-14 -14 2 176 176 176
-13 -14 2 176 176 176
-12 -14 2 176 176 176
-11 -14 2 176 176 176
-10 -14 2 176 176 176
-9 -14 2 176 176 176
-8 -14 2 176 176 176
-7 -14 2 176 176 176
-6 -14 2 176 176 176
-5 -14 2 176 176 176
-4 -14 2 176 176 176
-3 -14 2 176 176 176
-2 -14 2 176 176 176
-1 -14 2 176 176 176
0 -14 2 176 176 176
1 -14 2 176 176 176
2 -14 2 176 176 176
3 -14 2 176 176 176
4 -14 2 176 176 176
5 -14 2 176 176 176
6 -14 2 176 176 176
7 -14 2 176 176 176
8 -14 2 176 176 176
9 -14 2 176 176 176
10 -14 2 176 176 176
11 -14 2 176 176 176
12 -14 2 176 176 176
13 -14 2 176 176 176
14 -14 2 176 176 176
-15 -13 2 176 176 176
-14 -13 2 176 176 176
-13 -13 2 176 176 176
-12 -13 2 176 176 176
-11 -13 2 176 176 176
-10 -13 2 176 176 176
-9 -13 2 176 176 176
-8 -13 2 176 176 176
-7 -13 2 176 176 176
-6 -13 2 176 176 176
-5 -13 2 176 176 176
-4 -13 2 176 176 176
-3 -13 2 176 176 176
-2 -13 2 176 176 176
-1 -13 2 176 176 176
0 -13 2 176 176 176
1 -13 2 176 176 176
2 -13 2 176 176 176
3 -13 2 176 176 176
4 -13 2 176 176 176
5 -13 2 176 176 176
6 -13 2 176 176 176
7 -13 2 176 176 176
8 -13 2 176 176 176
9 -13 2 176 176 176
10 -13 2 176 176 176
11 -13 2 176 176 176
12 -13 2 176 176 176
13 -13 2 176 176 176
14 -13 2 176 176 176
-15 -12 2 176 176 176
-14 -12 2 176 176 176
-13 -12 2 176 176 176
12 -12 2 176 176 176
13 -12 2 176 176 176
14 -12 2 176 176 176
-15 -11 2 176 176 176
-14 -11 2 176 176 176
-13 -11 2 176 176 176
12 -11 2 176 176 176
13 -11 2 176 176 176
14 -11 2 176 176 176
-15 -10 2 176 176 176
-14 -10 2 176 176 176
-13 -10 2 176 176 176
12 -10 2 176 176 176
13 -10 2 176 176 176
14 -10 2 176 176 176
-15 -9 2 176 176 176
-14 -9 2 176 176 176
-13 -9 2 176 176 176
12 -9 2 176 176 176
13 -9 2 176 176 176
14 -9 2 176 176 176
-15 -8 2 176 176 176
-14 -8 2 176 176 176
-13 -8 2 176 176 176
12 -8 2 176 176 176
13 -8 2 176 176 176
14 -8 2 176 176 176
-15 -7 2 176 176 176
-14 -7 2 176 176 176
-13 -7 2 176 176 176
12 -7 2 176 176 176
13 -7 2 176 176 176
14 -7 2 176 176 176
-15 -6 2 176 176 176
-14 -6 2 176 176 176
-13 -6 2 176 176 176
12 -6 2 176 176 176
13 -6 2 176 176 176
14 -6 2 176 176 176
-15 -5 2 176 176 176
-14 -5 2 176 176 176
-13 -5 2 176 176 176
12 -5 2 176 176 176
13 -5 2 176 176 176
14 -5 2 176 176 176
-15 -4 2 176 176 176
-14 -4 2 176 176 176
-13 -4 2 176 176 176
-12 -4 2 176 176 176
-11 -4 2 176 176 176
-10 -4 2 176 176 176
12 -4 2 176 176 176
13 -4 2 176 176 176
14 -4 2 176 176 176
-15 -3 2 176 176 176
-14 -3 2 176 176 176
-13 -3 2 176 176 176
-12 -3 2 176 176 176
-11 -3 2 176 176 176
12 -3 2 176 176 176
13 -3 2 176 176 176
14 -3 2 176 176 176
-15 -2 2 176 176 176
-14 -2 2 176 176 176
-13 -2 2 176 176 176
-12 -2 2 176 176 176
-11 -2 2 176 176 176
12 -2 2 176 176 176
13 -2 2 176 176 176
14 -2 2 176 176 176
-15 -1 2 176 176 176
-14 -1 2 176 176 176
-13 -1 2 176 176 176
-12 -1 2 176 176 176
-11 -1 2 176 176 176
12 -1 2 176 176 176
13 -1 2 176 176 176
14 -1 2 176 176 176
-15 0 2 176 176 176
-14 0 2 176 176 176
-13 0 2 176 176 176
-12 0 2 176 176 176
-11 0 2 176 176 176
12 0 2 176 176 176
13 0 2 176 176 176
14 0 2 176 176 176
-15 1 2 176 176 176
-14 1 2 176 176 176
-13 1 2 176 176 176
-12 1 2 176 176 176
-11 1 2 176 176 176
12 1 2 176 176 176
13 1 2 176 176 176
14 1 2 176 176 176
-15 2 2 176 176 176
-14 2 2 176 176 176
-13 2 2 176 176 176
-12 2 2 176 176 176
-11 2 2 176 176 176
-10 2 2 176 176 176
12 2 2 176 176 176
13 2 2 176 176 176
14 2 2 176 176 176
-15 3 2 176 176 176
-14 3 2 176 176 176
-13 3 2 176 176 176
12 3 2 176 176 176
13 3 2 176 176 176
14 3 2 176 176 176
-15 4 2 176 176 176
-14 4 2 176 176 176
-13 4 2 176 176 176
12 4 2 176 176 176
13 4 2 176 176 176
14 4 2 176 176 176
-15 5 2 176 176 176
-14 5 2 176 176 176
-13 5 2 176 176 176
12 5 2 176 176 176
13 5 2 176 176 176
14 5 2 176 176 176
-15 6 2 176 176 176
-14 6 2 176 176 176
-13 6 2 176 176 176
12 6 2 176 176 176
13 6 2 176 176 176
14 6 2 176 176 176
-15 7 2 176 176 176
-14 7 2 176 176 176
-13 7 2 176 176 176
12 7 2 176 176 176
13 7 2 176 176 176
14 7 2 176 176 176
-15 8 2 176 176 176
-14 8 2 176 176 176
-13 8 2 176 176 176
12 8 2 176 176 176
13 8 2 176 176 176
14 8 2 176 176 176
-15 9 2 176 176 176
-14 9 2 176 176 176
-13 9 2 176 176 176
12 9 2 176 176 176
13 9 2 176 176 176
14 9 2 176 176 176
-15 10 2 176 176 176
-14 10 2 176 176 176
-13 10 2 176 176 176
12 10 2 176 176 176
13 10 2 176 176 176
14 10 2 176 176 176
-15 11 2 176 176 176
-14 11 2 176 176 176
-13 11 2 176 176 176
12 11 2 176 176 176
13 11 2 176 176 176
14 11 2 176 176 176
-15 12 2 176 176 176
-14 12 2 176 176 176
-13 12 2 176 176 176
-12 12 2 176 176 176
-11 12 2 176 176 176
-10 12 2 176 176 176
-9 12 2 176 176 176
-8 12 2 176 176 176
-7 12 2 176 176 176
-6 12 2 176 176 176
-5 12 2 176 176 176
-4 12 2 176 176 176
-3 12 2 176 176 176
-2 12 2 176 176 176
-1 12 2 176 176 176
0 12 2 176 176 176
1 12 2 176 176 176
2 12 2 176 176 176
3 12 2 176 176 176
4 12 2 176 176 176
5 12 2 176 176 176
6 12 2 176 176 176
7 12 2 176 176 176
8 12 2 176 176 176
9 12 2 176 176 176
10 12 2 176 176 176
11 12 2 176 176 176
12 12 2 176 176 176
13 12 2 176 176 176
14 12 2 176 176 176
-15 13 2 176 176 176
-14 13 2 176 176 176
-13 13 2 176 176 176
-12 13 2 176 176 176
-11 13 2 176 176 176
-10 13 2 176 176 176
-9 13 2 176 176 176
-8 13 2 176 176 176
-7 13 2 176 176 176
-6 13 2 176 176 176
-5 13 2 176 176 176
-4 13 2 176 176 176
-3 13 2 176 176 176
-2 13 2 176 176 176
-1 13 2 176 176 176
0 13 2 176 176 176
1 13 2 176 176 176
2 13 2 176 176 176
3 13 2 176 176 176
4 13 2 176 176 176
5 13 2 176 176 176
6 13 2 176 176 176
7 13 2 176 176 176
8 13 2 176 176 176
9 13 2 176 176 176
10 13 2 176 176 176
11 13 2 176 176 176
12 13 2 176 176 176
13 13 2 176 176 176
14 13 2 176 176 176
-15 14 2 176 176 176
-14 14 2 176 176 176
-13 14 2 176 176 176
-12 14 2 176 176 176
-11 14 2 176 176 176
-10 14 2 176 176 176
-9 14 2 176 176 176
-8 14 2 176 176 176
-7 14 2 176 176 176
-6 14 2 176 176 176
-5 14 2 176 176 176
-4 14 2 176 176 176
-3 14 2 176 176 176
-2 14 2 176 176 176
-1 14 2 176 176 176
0 14 2 176 176 176
1 14 2 176 176 176
2 14 2 176 176 176
3 14 2 176 176 176
4 14 2 176 176 176
5 14 2 176 176 176
6 14 2 176 176 176
7 14 2 176 176 176
8 14 2 176 176 176
9 14 2 176 176 176
10 14 2 176 176 176
11 14 2 176 176 176
12 14 2 176 176 176
13 14 2 176 176 176
14 14 2 176 176 176
-15 -15 3 176 176 176
-14 -15 3 176 176 176
-13 -15 3 176 176 176
-12 -15 3 176 176 176
-11 -15 3 176 176 176
-10 -15 3 176 176 176
-9 -15 3 176 176 176
-8 -15 3 176 176 176
-7 -15 3 176 176 176
-6 -15 3 176 176 176
-5 -15 3 176 176 176
-4 -15 3 176 176 176
-3 -15 3 176 176 176
-2 -15 3 176 176 176
-1 -15 3 176 176 176
0 -15 3 176 176 176
1 -15 3 176 176 176
2 -15 3 176 176 176
3 -15 3 176 176 176
4 -15 3 176 176 176
5 -15 3 176 176 176
6 -15 3 176 176 176
7 -15 3 176 176 176
8 -15 3 176 176 176
9 -15 3 176 176 176
10 -15 3 176 176 176
11 -15 3 176 176 176
12 -15 3 176 176 176
13 -15 3 176 176 176
14 -15 3 176 176 176
-15 -14 3 176 176 176
-14 -14 3 176 176 176
-13 -14 3 176 176 176
-12 -14 3 176 176 176
-11 -14 3 176 176 176
-10 -14 3 176 176 176
-9 -14 3 176 176 176
-8 -14 3 176 176 176
-7 -14 3 176 176 176
-6 -14 3 176 176 176
-5 -14 3 176 176 176
-4 -14 3 176 176 176
-3 -14 3 176 176 176
-2 -14 3 176 176 176
-1 -14 3 176 176 176
0 -14 3 176 176 176
1 -14 3 176 176 176
2 -14 3 176 176 176
3 -14 3 176 176 176
4 -14 3 176 176 176
5 -14 3 176 176 176
6 -14 3 176 176 176
7 -14 3 176 176 176
8 -14 3 176 176 176
9 -14 3 176 176 176
10 -14 3 176 176 176
11 -14 3 176 176 176
12 -14 3 176 176 176
13 -14 3 176 176 176
14 -14 3 176 176 176
-15 -13 3 176 176 176
-14 -13 3 176 176 176
-13 -13 3 176 176 176
-12 -13 3 176 176 176
-11 -13 3 176 176 176
-10 -13 3 176 176 176
-9 -13 3 176 176 176
-8 -13 3 176 176 176
-7 -13 3 176 176 176
-6 -13 3 176 176 176
-5 -13 3 176 176 176
-4 -13 3 176 176 176
-3 -13 3 176 176 176
-2 -13 3 176 176 176
-1 -13 3 176 176 176
0 -13 3 176 176 176
1 -13 3 176 176 176
2 -13 3 176 176 176
3 -13 3 176 176 176
4 -13 3 176 176 176
5 -13 3 176 176 176
6 -13 3 176 176 176
7 -13 3 176 176 176
8 -13 3 176 176 176
9 -13 3 176 176 176
10 -13 3 176 176 176
11 -13 3 176 176 176
12 -13 3 176 176 176
13 -13 3 176 176 176
14 -13 3 176 176 176
-15 -12 3 176 176 176
-14 -12 3 176 176 176
-13 -12 3 176 176 176
12 -12 3 176 176 176
13 -12 3 176 176 176
14 -12 3 176 176 176
-15 -11 3 176 176 176
-14 -11 3 176 176 176
-13 -11 3 176 176 176
12 -11 3 176 176 176
13 -11 3 176 176 176
14 -11 3 176 176 176
-15 -10 3 176 176 176
-14 -10 3 176 176 176
-13 -10 3 176 176 176
12 -10 3 176 176 176
13 -10 3 176 176 176
14 -10 3 176 176 176
-15 -9 3 176 176 176
-14 -9 3 176 176 176
-13 -9 3 176 176 176
12 -9 3 176 176 176
13 -9 3 176 176 176
14 -9 3 176 176 176
-15 -8 3 176 176 176
-14 -8 3 176 176 176
-13 -8 3 176 176 176
12 -8 3 176 176 176
13 -8 3 176 176 176
14 -8 3 176 176 176
-15 -7 3 176 176 176
-14 -7 3 176 176 176
-13 -7 3 176 176 176
12 -7 3 176 176 176
13 -7 3 176 176 176
14 -7 3 176 176 176
-15 -6 3 176 176 176
-14 -6 3 176 176 176
-13 -6 3 176 176 176
12 -6 3 176 176 176
13 -6 3 176 176 176
14 -6 3 176 176 176
-15 -5 3 176 176 176
-14 -5 3 176 176 176
-13 -5 3 176 176 176
12 -5 3 176 176 176
13 -5 3 176 176 176
14 -5 3 176 176 176
-15 -4 3 176 176 176
-14 -4 3 176 176 176
-13 -4 3 176 176 176
-12 -4 3 176 176 176
-11 -4 3 176 176 176
-10 -4 3 176 176 176
12 -4 3 176 176 176
13 -4 3 176 176 176
14 -4 3 176 176 176
-15 -3 3 176 176 176
-14 -3 3 176 176 176
-13 -3 3 176 176 176
-12 -3 3 176 176 176
12 -3 3 176 176 176
13 -3 3 176 176 176
14 -3 3 176 176 176
-15 -2 3 176 176 176
-14 -2 3 176 176 176
-13 -2 3 176 176 176
-12 -2 3 176 176 176
12 -2 3 176 176 176
13 -2 3 176 176 176
14 -2 3 176 176 176
-15 -1 3 176 176 176
-14 -1 3 176 176 176
-13 -1 3 176 176 176
-12 -1 3 176 176 176
12 -1 3 176 176 176
13 -1 3 176 176 176
14 -1 3 176 176 176
-15 0 3 176 176 176
-14 0 3 176 176 176
-13 0 3 176 176 176
-12 0 3 176 176 176
12 0 3 176 176 176
13 0 3 176 176 176
14 0 3 176 176 176
-15 1 3 176 176 176
-14 1 3 176 176 176
-13 1 3 176 176 176
-12 1 3 176 176 176
12 1 3 176 176 176
13 1 3 176 176 176
14 1 3 176 176 176
-15 2 3 176 176 176
-14 2 3 176 176 176
-13 2 3 176 176 176
-12 2 3 176 176 176
-11 2 3 176 176 176
-10 2 3 176 176 176
12 2 3 176 176 176
13 2 3 176 176 176
14 2 3 176 176 176
-15 3 3 176 176 176
-14 3 3 176 176 176
-13 3 3 176 176 176
12 3 3 176 176 176
13 3 3 176 176 176
14 3 3 176 176 176
-15 4 3 176 176 176
-14 4 3 176 176 176
-13 4 3 176 176 176
12 4 3 176 176 176
13 4 3 176 176 176
14 4 3 176 176 176
-15 5 3 176 176 176
-14 5 3 176 176 176
-13 5 3 176 176 176
12 5 3 176 176 176
13 5 3 176 176 176
14 5 3 176 176 176
-15 6 3 176 176 176
-14 6 3 176 176 176
-13 6 3 176 176 176
12 6 3 176 176 176
13 6 3 176 176 176
14 6 3 176 176 176
-15 7 3 176 176 176
-14 7 3 176 176 176
-13 7 3 176 176 176
12 7 3 176 176 176
13 7 3 176 176 176
14 7 3 176 176 176
-15 8 3 176 176 176
-14 8 3 176 176 176
-13 8 3 176 176 176
12 8 3 176 176 176
13 8 3 176 176 176
14 8 3 176 176 176
-15 9 3 176 176 176
-14 9 3 176 176 176
-13 9 3 176 176 176
12 9 3 176 176 176
13 9 3 176 176 176
14 9 3 176 176 176
-15 10 3 176 176 176
-14 10 3 176 176 176
-13 10 3 176 176 176
12 10 3 176 176 176
13 10 3 176 176 176
14 10 3 176 176 176
-15 11 3 176 176 176
-14 11 3 176 176 176
-13 11 3 176 176 176
12 11 3 176 176 176
13 11 3 176 176 176
14 11 3 176 176 176
-15 12 3 176 176 176
-14 12 3 176 176 176
-13 12 3 176 176 176
-12 12 3 176 176 176
-11 12 3 176 176 176
-10 12 3 176 176 176
-9 12 3 176 176 176
-8 12 3 176 176 176
-7 12 3 176 176 176
-6 12 3 176 176 176
-5 12 3 176 176 176
-4 12 3 176 176 176
-3 12 3 176 176 176
-2 12 3 176 176 176
-1 12 3 176 176 176
0 12 3 176 176 176
1 12 3 176 176 176
2 12 3 176 176 176
3 12 3 176 176 176
4 12 3 176 176 176
5 12 3 176 176 176
6 12 3 176 176 176
7 12 3 176 176 176
8 12 3 176 176 176
9 12 3 176 176 176
10 12 3 176 176 176
11 12 3 176 176 176
12 12 3 176 176 176
13 12 3 176 176 176
14 12 3 176 176 176
-15 13 3 176 176 176
-14 13 3 176 176 176
-13 13 3 176 176 176
-12 13 3 176 176 176
-11 13 3 176 176 176
-10 13 3 176 176 176
-9 13 3 176 176 176
-8 13 3 176 176 176
-7 13 3 176 176 176
-6 13 3 176 176 176
-5 13 3 176 176 176
-4 13 3 176 176 176
-3 13 3 176 176 176
-2 13 3 176 176 176
-1 13 3 176 176 176
0 13 3 176 176 176
1 13 3 176 176 176
2 13 3 176 176 176
3 13 3 176 176 176
4 13 3 176 176 176
5 13 3 176 176 176
6 13 3 176 176 176
7 13 3 176 176 176
8 13 3 176 176 176
9 13 3 176 176 176
10 13 3 176 176 176
11 13 3 176 176 176
12 13 3 176 176 176
13 13 3 176 176 176
14 13 3 176 176 176
-15 14 3 176 176 176
-14 14 3 176 176 176
-13 14 3 176 176 176
-12 14 3 176 176 176
-11 14 3 176 176 176
-10 14 3 176 176 176
-9 14 3 176 176 176
-8 14 3 176 176 176
-7 14 3 176 176 176
-6 14 3 176 176 176
-5 14 3 176 176 176
-4 14 3 176 176 176
-3 14 3 176 176 176
-2 14 3 176 176 176
-1 14 3 176 176 176
0 14 3 176 176 176
1 14 3 176 176 176
2 14 3 176 176 176
3 14 3 176 176 176
4 14 3 176 176 176
5 14 3 176 176 176
6 14 3 176 176 176
7 14 3 176 176 176
8 14 3 176 176 176
9 14 3 176 176 176
10 14 3 176 176 176
11 14 3 176 176 176
12 14 3 176 176 176
13 14 3 176 176 176
14 14 3 176 176 176
-15 -15 4 176 176 176
-14 -15 4 176 176 176
-13 -15 4 176 176 176
-12 -15 4 176 176 176
-11 -15 4 176 176 176
-10 -15 4 176 176 176
-9 -15 4 176 176 176
-8 -15 4 176 176 176
-7 -15 4 176 176 176
-6 -15 4 176 176 176
-5 -15 4 176 176 176
-4 -15 4 176 176 176
-3 -15 4 176 176 176
-2 -15 4 176 176 176
-1 -15 4 176 176 176
0 -15 4 176 176 176
1 -15 4 176 176 176
2 -15 4 176 176 176
3 -15 4 176 176 176
4 -15 4 176 176 176
5 -15 4 176 176 176
6 -15 4 176 176 176
7 -15 4 176 176 176
8 -15 4 176 176 176
9 -15 4 176 176 176
10 -15 4 176 176 176
11 -15 4 176 176 176
12 -15 4 176 176 176
13 -15 4 176 176 176
14 -15 4 176 176 176
-15 -14 4 176 176 176
-14 -14 4 176 176 176
-13 -14 4 176 176 176
-12 -14 4 176 176 176
-11 -14 4 176 176 176
-10 -14 4 176 176 176
-9 -14 4 176 176 176
-8 -14 4 176 176 176
-7 -14 4 176 176 176
-6 -14 4 176 176 176
-5 -14 4 176 176 176
-4 -14 4 176 176 176
-3 -14 4 176 176 176
-2 -14 4 176 176 176
-1 -14 4 176 176 176
0 -14 4 176 176 176
1 -14 4 176 176 176
2 -14 4 176 176 176
3 -14 4 176 176 176
4 -14 4 176 176 176
5 -14 4 176 176 176
6 -14 4 176 176 176
7 -14 4 176 176 176
8 -14 4 176 176 176
9 -14 4 176 176 176
10 -14 4 176 176 176
11 -14 4 176 176 176
12 -14 4 176 176 176
13 -14 4 176 176 176
14 -14 4 176 176 176
-15 -13 4 176 176 176
-14 -13 4 176 176 176
-13 -13 4 176 176 176
-12 -13 4 176 176 176
-11 -13 4 176 176 176
-10 -13 4 176 176 176
-9 -13 4 176 176 176
-8 -13 4 176 176 176
-7 -13 4 176 176 176
-6 -13 4 176 176 176
-5 -13 4 176 176 176
-4 -13 4 176 176 176
-3 -13 4 176 176 176
-2 -13 4 176 176 176
-1 -13 4 176 176 176
0 -13 4 176 176 176
1 -13 4 176 176 176
2 -13 4 176 176 176
3 -13 4 176 176 176
4 -13 4 176 176 176
5 -13 4 176 176 176
6 -13 4 176 176 176
7 -13 4 176 176 176
8 -13 4 176 176 176
9 -13 4 176 176 176
10 -13 4 176 176 176
11 -13 4 176 176 176
12 -13 4 176 176 176
13 -13 4 176 176 176
14 -13 4 176 176 176
-15 -12 4 176 176 176
-14 -12 4 176 176 176
-13 -12 4 176 176 176
12 -12 4 176 176 176
13 -12 4 176 176 176
14 -12 4 176 176 176
-15 -11 4 176 176 176
-14 -11 4 176 176 176
-13 -11 4 176 176 176
12 -11 4 176 176 176
13 -11 4 176 176 176
14 -11 4 176 176 176
-15 -10 4 176 176 176
-14 -10 4 176 176 176
-13 -10 4 176 176 176
12 -10 4 176 176 176
13 -10 4 176 176 176
14 -10 4 176 176 176
-15 -9 4 176 176 176
-14 -9 4 176 176 176
-13 -9 4 176 176 176
12 -9 4 176 176 176
13 -9 4 176 176 176
14 -9 4 176 176 176
-15 -8 4 176 176 176
-14 -8 4 176 176 176
-13 -8 4 176 176 176
12 -8 4 176 176 176
13 -8 4 176 176 176
14 -8 4 176 176 176
-15 -7 4 176 176 176
-14 -7 4 176 176 176
-13 -7 4 176 176 176
12 -7 4 176 176 176
13 -7 4 176 176 176
14 -7 4 176 176 176
-15 -6 4 176 176 176
-14 -6 4 176 176 176
-13 -6 4 176 176 176
12 -6 4 176 176 176
13 -6 4 176 176 176
14 -6 4 176 176 176
-15 -5 4 176 176 176
-14 -5 4 176 176 176
-13 -5 4 176 176 176
12 -5 4 176 176 176
13 -5 4 176 176 176
14 -5 4 176 176 176
-15 -4 4 176 176 176
-14 -4 4 176 176 176
-13 -4 4 176 176 176
-12 -4 4 176 176 176
-11 -4 4 176 176 176
-10 -4 4 176 176 176
12 -4 4 176 176 176
13 -4 4 176 176 176
14 -4 4 176 176 176
-15 -3 4 176 176 176
-14 -3 4 176 176 176
-13 -3 4 176 176 176
12 -3 4 176 176 176
13 -3 4 176 176 176
14 -3 4 176 176 176
-15 -2 4 176 176 176
-14 -2 4 176 176 176
-13 -2 4 176 176 176
12 -2 4 176 176 176
13 -2 4 176 176 176
14 -2 4 176 176 176
-15 -1 4 176 176 176
-14 -1 4 176 176 176
-13 -1 4 176 176 176
12 -1 4 176 176 176
13 -1 4 176 176 176
14 -1 4 176 176 176
-15 0 4 176 176 176
-14 0 4 176 176 176
-13 0 4 176 176 176
12 0 4 176 176 176
13 0 4 176 176 176
14 0 4 176 176 176
-15 1 4 176 176 176
-14 1 4 176 176 176
-13 1 4 176 176 176
12 1 4 176 176 176
13 1 4 176 176 176
14 1 4 176 176 176
-15 2 4 176 176 176
-14 2 4 176 176 176
-13 2 4 176 176 176
-12 2 4 176 176 176
-11 2 4 176 176 176
-10 2 4 176 176 176
12 2 4 176 176 176
13 2 4 176 176 176
14 2 4 176 176 176
-15 3 4 176 176 176
-14 3 4 176 176 176
-13 3 4 176 176 176
12 3 4 176 176 176
13 3 4 176 176 176
14 3 4 176 176 176
-15 4 4 176 176 176
-14 4 4 176 176 176
-13 4 4 176 176 176
12 4 4 176 176 176
13 4 4 176 176 176
14 4 4 176 176 176
-15 5 4 176 176 176
-14 5 4 176 176 176
-13 5 4 176 176 176
12 5 4 176 176 176
13 5 4 176 176 176
14 5 4 176 176 176
-15 6 4 176 176 176
-14 6 4 176 176 176
-13 6 4 176 176 176
12 6 4 176 176 176
13 6 4 176 176 176
14 6 4 176 176 176
-15 7 4 176 176 176
-14 7 4 176 176 176
-13 7 4 176 176 176
12 7 4 176 176 176
13 7 4 176 176 176
14 7 4 176 176 176
-15 8 4 176 176 176
-14 8 4 176 176 176
-13 8 4 176 176 176
12 8 4 176 176 176
13 8 4 176 176 176
14 8 4 176 176 176
-15 9 4 176 176 176
-14 9 4 176 176 176
-13 9 4 176 176 176
12 9 4 176 176 176
13 9 4 176 176 176
14 9 4 176 176 176
-15 10 4 176 176 176
-14 10 4 176 176 176
-13 10 4 176 176 176
12 10 4 176 176 176
13 10 4 176 176 176
14 10 4 176 176 176
-15 11 4 176 176 176
-14 11 4 176 176 176
-13 11 4 176 176 176
12 11 4 176 176 176
13 11 4 176 176 176
14 11 4 176 176 176
-15 12 4 176 176 176
-14 12 4 176 176 176
-13 12 4 176 176 176
-12 12 4 176 176 176
-11 12 4 176 176 176
-10 12 4 176 176 176
-9 12 4 176 176 176
-8 12 4 176 176 176
-7 12 4 176 176 176
-6 12 4 176 176 176
-5 12 4 176 176 176
-4 12 4 176 176 176
-3 12 4 176 176 176
-2 12 4 176 176 176
-1 12 4 176 176 176
0 12 4 176 176 176
1 12 4 176 176 176
2 12 4 176 176 176
3 12 4 176 176 176
4 12 4 176 176 176
5 12 4 176 176 176
6 12 4 176 176 176
7 12 4 176 176 176
8 12 4 176 176 176
9 12 4 176 176 176
10 12 4 176 176 176
11 12 4 176 176 176
12 12 4 176 176 176
13 12 4 176 176 176
14 12 4 176 176 176
-15 13 4 176 176 176
-14 13 4 176 176 176
-13 13 4 176 176 176
-12 13 4 176 176 176
-11 13 4 176 176 176
-10 13 4 176 176 176
-9 13 4 176 176 176
-8 13 4 176 176 176
-7 13 4 176 176 176
-6 13 4 176 176 176
-5 13 4 176 176 176
-4 13 4 176 176 176
-3 13 4 176 176 176
-2 13 4 176 176 176
-1 13 4 176 176 176
0 13 4 176 176 176
1 13 4 176 176 176
2 13 4 176 176 176
3 13 4 176 176 176
4 13 4 176 176 176
5 13 4 176 176 176
6 13 4 176 176 176
7 13 4 176 176 176
8 13 4 176 176 176
9 13 4 176 176 176
10 13 4 176 176 176
11 13 4 176 176 176
12 13 4 176 176 176
13 13 4 176 176 176
14 13 4 176 176 176
-15 14 4 176 176 176
-14 14 4 176 176 176
-13 14 4 176 176 176
-12 14 4 176 176 176
-11 14 4 176 176 176
-10 14 4 176 176 176
-9 14 4 176 176 176
-8 14 4 176 176 176
-7 14 4 176 176 176
-6 14 4 176 176 176
-5 14 4 176 176 176
-4 14 4 176 176 176
-3 14 4 176 176 176
-2 14 4 176 176 176
-1 14 4 176 176 176
0 14 4 176 176 176
1 14 4 176 176 176
2 14 4 176 176 176
3 14 4 176 176 176
4 14 4 176 176 176
5 14 4 176 176 176
6 14 4 176 176 176
7 14 4 176 176 176
8 14 4 176 176 176
9 14 4 176 176 176
10 14 4 176 176 176
11 14 4 176 176 176
12 14 4 176 176 176
13 14 4 176 176 176
14 14 4 176 176 176
-15 -15 5 176 176 176
-14 -15 5 176 176 176
-13 -15 5 176 176 176
-12 -15 5 176 176 176
-11 -15 5 176 176 176
-10 -15 5 176 176 176
-9 -15 5 176 176 176
-8 -15 5 176 176 176
-7 -15 5 176 176 176
-6 -15 5 176 176 176
-5 -15 5 176 176 176
-4 -15 5 176 176 176
-3 -15 5 176 176 176
-2 -15 5 176 176 176
-1 -15 5 176 176 176
0 -15 5 176 176 176
1 -15 5 176 176 176
2 -15 5 176 176 176
3 -15 5 176 176 176
4 -15 5 176 176 176
5 -15 5 176 176 176
6 -15 5 176 176 176
7 -15 5 176 176 176
8 -15 5 176 176 176
9 -15 5 176 176 176
10 -15 5 176 176 176
11 -15 5 176 176 176
12 -15 5 176 176 176
13 -15 5 176 176 176
14 -15 5 176 176 176
-15 -14 5 176 176 176
-14 -14 5 176 176 176
-13 -14 5 176 176 176
-12 -14 5 176 176 176
-11 -14 5 176 176 176
-10 -14 5 176 176 176
-9 -14 5 176 176 176
-8 -14 5 176 176 176
-7 -14 5 176 176 176
-6 -14 5 176 176 176
-5 -14 5 176 176 176
-4 -14 5 176 176 176
-3 -14 5 176 176 176
-2 -14 5 176 176 176
-1 -14 5 176 176 176
0 -14 5 176 176 176
1 -14 5 176 176 176
2 -14 5 176 176 176
3 -14 5 176 176 176
4 -14 5 176 176 176
5 -14 5 176 176 176
6 -14 5 176 176 176
7 -14 5 176 176 176
8 -14 5 176 176 176
9 -14 5 176 176 176
10 -14 5 176 176 176
11 -14 5 176 176 176
12 -14 5 176 176 176
13 -14 5 176 176 176
14 -14 5 176 176 176
-15 -13 5 176 176 176
-14 -13 5 176 176 176
-13 -13 5 176 176 176
-12 -13 5 176 176 176
-11 -13 5 176 176 176
-10 -13 5 176 176 176
-9 -13 5 176 176 176
-8 -13 5 176 176 176
-7 -13 5 176 176 176
-6 -13 5 176 176 176
-5 -13 5 176 176 176
-4 -13 5 176 176 176
-3 -13 5 176 176 176
-2 -13 5 176 176 176
-1 -13 5 176 176 176
0 -13 5 176 176 176
1 -13 5 176 176 176
2 -13 5 176 176 176
3 -13 5 176 176 176
4 -13 5 176 176 176
5 -13 5 176 176 176
6 -13 5 176 176 176
7 -13 5 176 176 176
8 -13 5 176 176 176
9 -13 5 176 176 176
10 -13 5 176 176 176
11 -13 5 176 176 176
12 -13 5 176 176 176
13 -13 5 176 176 176
14 -13 5 176 176 176
-15 -12 5 176 176 176
-14 -12 5 176 176 176
-13 -12 5 176 176 176
12 -12 5 176 176 176
13 -12 5 176 176 176
14 -12 5 176 176 176
-15 -11 5 176 176 176
-14 -11 5 176 176 176
-13 -11 5 176 176 176
12 -11 5 176 176 176
13 -11 5 176 176 176
14 -11 5 176 176 176
-15 -10 5 176 176 176
-14 -10 5 176 176 176
-13 -10 5 176 176 176
12 -10 5 176 176 176
13 -10 5 176 176 176
14 -10 5 176 176 176
-15 -9 5 176 176 176
-14 -9 5 176 176 176
-13 -9 5 176 176 176
12 -9 5 176 176 176
13 -9 5 176 176 176
14 -9 5 176 176 176
-15 -8 5 176 176 176
-14 -8 5 176 176 176
-13 -8 5 176 176 176
12 -8 5 176 176 176
13 -8 5 176 176 176
14 -8 5 176 176 176
-15 -7 5 176 176 176
-14 -7 5 176 176 176
-13 -7 5 176 176 176
12 -7 5 176 176 176
13 -7 5 176 176 176
14 -7 5 176 176 176
-15 -6 5 176 176 176
-14 -6 5 176 176 176
-13 -6 5 176 176 176
12 -6 5 176 176 176
13 -6 5 176 176 176
14 -6 5 176 176 176
-15 -5 5 176 176 176
-14 -5 5 176 176 176
-13 -5 5 176 176 176
12 -5 5 176 176 176
13 -5 5 176 176 176
14 -5 5 176 176 176
-15 -4 5 176 176 176
-14 -4 5 176 176 176
-13 -4 5 176 176 176
-12 -4 5 176 176 176
-11 -4 5 176 176 176
-10 -4 5 176 176 176
12 -4 5 176 176 176
13 -4 5 176 176 176
14 -4 5 176 176 176
-15 -3 5 176 176 176
-14 -3 5 176 176 176
-13 -3 5 176 176 176
12 -3 5 176 176 176
13 -3 5 176 176 176
14 -3 5 176 176 176
-15 -2 5 176 176 176
-14 -2 5 176 176 176
-13 -2 5 176 176 176
12 -2 5 176 176 176
13 -2 5 176 176 176
14 -2 5 176 176 176
-15 -1 5 176 176 176
-14 -1 5 176 176 176
-13 -1 5 176 176 176
12 -1 5 176 176 176
13 -1 5 176 176 176
14 -1 5 176 176 176
-15 0 5 176 176 176
-14 0 5 176 176 176
-13 0 5 176 176 176
12 0 5 176 176 176
13 0 5 176 176 176
14 0 5 176 176 176
-15 1 5 176 176 176
-14 1 5 176 176 176
-13 1 5 176 176 176
12 1 5 176 176 176
13 1 5 176 176 176
14 1 5 176 176 176
-15 2 5 176 176 176
-14 2 5 176 176 176
-13 2 5 176 176 176
-12 2 5 176 176 176
-11 2 5 176 176 176
-10 2 5 176 176 176
12 2 5 176 176 176
13 2 5 176 176 176
14 2 5 176 176 176
-15 3 5 176 176 176
-14 3 5 176 176 176
-13 3 5 176 176 176
12 3 5 176 176 176
13 3 5 176 176 176
14 3 5 176 176 176
-15 4 5 176 176 176
-14 4 5 176 176 176
-13 4 5 176 176 176
12 4 5 176 176 176
13 4 5 176 176 176
14 4 5 176 176 176
-15 5 5 176 176 176
-14 5 5 176 176 176
-13 5 5 176 176 176
12 5 5 176 176 176
13 5 5 176 176 176
14 5 5 176 176 176
-15 6 5 176 176 176
-14 6 5 176 176 176
-13 6 5 176 176 176
12 6 5 176 176 176
13 6 5 176 176 176
14 6 5 176 176 176
-15 7 5 176 176 176
-14 7 5 176 176 176
-13 7 5 176 176 176
12 7 5 176 176 176
13 7 5 176 176 176
14 7 5 176 176 176
-15 8 5 176 176 176
-14 8 5 176 176 176
-13 8 5 176 176 176
12 8 5 176 176 176
13 8 5 176 176 176
14 8 5 176 176 176
-15 9 5 176 176 176
-14 9 5 176 176 176
-13 9 5 176 176 176
12 9 5 176 176 176
13 9 5 176 176 176
14 9 5 176 176 176
-15 10 5 176 176 176
-14 10 5 176 176 176
-13 10 5 176 176 176
12 10 5 176 176 176
13 10 5 176 176 176
14 10 5 176 176 176
-15 11 5 176 176 176
-14 11 5 176 176 176
-13 11 5 176 176 176
12 11 5 176 176 176
13 11 5 176 176 176
14 11 5 176 176 176
-15 12 5 176 176 176
-14 12 5 176 176 176
-13 12 5 176 176 176
-12 12 5 176 176 176
-11 12 5 176 176 176
-10 12 5 176 176 176
-9 12 5 176 176 176
-8 12 5 176 176 176
-7 12 5 176 176 176
-6 12 5 176 176 176
-5 12 5 176 176 176
-4 12 5 176 176 176
-3 12 5 176 176 176
-2 12 5 176 176 176
-1 12 5 176 176 176
0 12 5 176 176 176
1 12 5 176 176 176
2 12 5 176 176 176
3 12 5 176 176 176
4 12 5 176 176 176
5 12 5 176 176 176
6 12 5 176 176 176
7 12 5 176 176 176
8 12 5 176 176 176
9 12 5 176 176 176
10 12 5 176 176 176
11 12 5 176 176 176
12 12 5 176 176 176
13 12 5 176 176 176
14 12 5 176 176 176
-15 13 5 176 176 176
-14 13 5 176 176 176
-13 13 5 176 176 176
-12 13 5 176 176 176
-11 13 5 176 176 176
-10 13 5 176 176 176
-9 13 5 176 176 176
-8 13 5 176 176 176
-7 13 5 176 176 176
-6 13 5 176 176 176
-5 13 5 176 176 176
-4 13 5 176 176 176
-3 13 5 176 176 176
-2 13 5 176 176 176
-1 13 5 176 176 176
0 13 5 176 176 176
1 13 5 176 176 176
2 13 5 176 176 176
3 13 5 176 176 176
4 13 5 176 176 176
5 13 5 176 176 176
6 13 5 176 176 176
7 13 5 176 176 176
8 13 5 176 176 176
9 13 5 176 176 176
10 13 5 176 176 176
11 13 5 176 176 176
12 13 5 176 176 176
13 13 5 176 176 176
14 13 5 176 176 176
-15 14 5 176 176 176
-14 14 5 176 176 176
-13 14 5 176 176 176
-12 14 5 176 176 176
-11 14 5 176 176 176
-10 14 5 176 176 176
-9 14 5 176 176 176
-8 14 5 176 176 176
-7 14 5 176 176 176
-6 14 5 176 176 176
-5 14 5 176 176 176
-4 14 5 176 176 176
-3 14 5 176 176 176
-2 14 5 176 176 176
-1 14 5 176 176 176
0 14 5 176 176 176
1 14 5 176 176 176
2 14 5 176 176 176
3 14 5 176 176 176
4 14 5 176 176 176
5 14 5 176 176 176
6 14 5 176 176 176
7 14 5 176 176 176
8 14 5 176 176 176
9 14 5 176 176 176
10 14 5 176 176 176
11 14 5 176 176 176
12 14 5 176 176 176
13 14 5 176 176 176
14 14 5 176 176 176
-15 -15 6 176 176 176
-14 -15 6 176 176 176
-13 -15 6 176 176 176
-12 -15 6 176 176 176
-11 -15 6 176 176 176
-10 -15 6 176 176 176
-9 -15 6 176 176 176
-8 -15 6 176 176 176
-7 -15 6 176 176 176
-6 -15 6 176 176 176
-5 -15 6 176 176 176
-4 -15 6 176 176 176
-3 -15 6 176 176 176
-2 -15 6 176 176 176
-1 -15 6 176 176 176
0 -15 6 176 176 176
1 -15 6 176 176 176
2 -15 6 176 176 176
3 -15 6 176 176 176
4 -15 6 176 176 176
5 -15 6 176 176 176
6 -15 6 176 176 176
7 -15 6 176 176 176
8 -15 6 176 176 176
9 -15 6 176 176 176
10 -15 6 176 176 176
11 -15 6 176 176 176
12 -15 6 176 176 176
13 -15 6 176 176 176
14 -15 6 176 176 176
-15 -14 6 176 176 176
-14 -14 6 176 176 176
-13 -14 6 176 176 176
-12 -14 6 176 176 176
-11 -14 6 176 176 176
-10 -14 6 176 176 176
-9 -14 6 176 176 176
-8 -14 6 176 176 176
-7 -14 6 176 176 176
-6 -14 6 176 176 176
-5 -14 6 176 176 176
-4 -14 6 176 176 176
-3 -14 6 176 176 176
-2 -14 6 176 176 176
-1 -14 6 176 176 176
0 -14 6 176 176 176
1 -14 6 176 176 176
2 -14 6 176 176 176
3 -14 6 176 176 176
4 -14 6 176 176 176
5 -14 6 176 176 176
6 -14 6 176 176 176
7 -14 6 176 176 176
8 -14 6 176 176 176
9 -14 6 176 176 176
10 -14 6 176 176 176
11 -14 6 176 176 176
12 -14 6 176 176 176
13 -14 6 176 176 176
14 -14 6 176 176 176
-15 -13 6 176 176 176
-14 -13 6 176 176 176
-13 -13 6 176 176 176
-12 -13 6 176 176 176
-11 -13 6 176 176 176
-10 -13 6 176 176 176
-9 -13 6 176 176 176
-8 -13 6 176 176 176
-7 -13 6 176 176 176
-6 -13 6 176 176 176
-5 -13 6 176 176 176
-4 -13 6 176 176 176
-3 -13 6 176 176 176
-2 -13 6 176 176 176
-1 -13 6 176 176 176
0 -13 6 176 176 176
1 -13 6 176 176 176
2 -13 6 176 176 176
3 -13 6 176 176 176
4 -13 6 176 176 176
5 -13 6 176 176 176
6 -13 6 176 176 176
7 -13 6 176 176 176
8 -13 6 176 176 176
9 -13 6 176 176 176
10 -13 6 176 176 176
11 -13 6 176 176 176
12 -13 6 176 176 176
13 -13 6 176 176 176
14 -13 6 176 176 176
-15 -12 6 176 176 176
-14 -12 6 176 176 176
-13 -12 6 176 176 176
12 -12 6 176 176 176
13 -12 6 176 176 176
14 -12 6 176 176 176
-15 -11 6 176 176 176
-14 -11 6 176 176 176
-13 -11 6 176 176 176
12 -11 6 176 176 176
13 -11 6 176 176 176
14 -11 6 176 176 176
-15 -10 6 176 176 176
-14 -10 6 176 176 176
-13 -10 6 176 176 176
12 -10 6 176 176 176
13 -10 6 176 176 176
14 -10 6 176 176 176
-15 -9 6 176 176 176
-14 -9 6 176 176 176
-13 -9 6 176 176 176
12 -9 6 176 176 176
13 -9 6 176 176 176
14 -9 6 176 176 176
-15 -8 6 176 176 176
-14 -8 6 176 176 176
-13 -8 6 176 176 176
12 -8 6 176 176 176
13 -8 6 176 176 176
14 -8 6 176 176 176
-15 -7 6 176 176 176
-14 -7 6 176 176 176
-13 -7 6 176 176 176
12 -7 6 176 176 176
13 -7 6 176 176 176
14 -7 6 176 176 176
-15 -6 6 176 176 176
-14 -6 6 176 176 176
-13 -6 6 176 176 176
12 -6 6 176 176 176
13 -6 6 176 176 176
14 -6 6 176 176 176
-15 -5 6 176 176 176
-14 -5 6 176 176 176
-13 -5 6 176 176 176
12 -5 6 176 176 176
13 -5 6 176 176 176
14 -5 6 176 176 176
-15 -4 6 176 176 176
-14 -4 6 176 176 176
-13 -4 6 176 176 176
-12 -4 6 176 176 176
-11 -4 6 176 176 176
-10 -4 6 176 176 176
12 -4 6 176 176 176
13 -4 6 176 176 176
14 -4 6 176 176 176
-15 -3 6 176 176 176
-14 -3 6 176 176 176
-13 -3 6 176 176 176
-10 -3 6 176 176 176
12 -3 6 176 176 176
13 -3 6 176 176 176
14 -3 6 176 176 176
-15 -2 6 176 176 176
-14 -2 6 176 176 176
-13 -2 6 176 176 176
-10 -2 6 176 176 176
12 -2 6 176 176 176
13 -2 6 176 176 176
14 -2 6 176 176 176
-15 -1 6 176 176 176
-14 -1 6 176 176 176
-13 -1 6 176 176 176
-10 -1 6 176 176 176
12 -1 6 176 176 176
13 -1 6 176 176 176
14 -1 6 176 176 176
-15 0 6 176 176 176
-14 0 6 176 176 176
-13 0 6 176 176 176
-10 0 6 176 176 176
12 0 6 176 176 176
13 0 6 176 176 176
14 0 6 176 176 176
-15 1 6 176 176 176
-14 1 6 176 176 176
-13 1 6 176 176 176
-10 1 6 176 176 176
12 1 6 176 176 176
13 1 6 176 176 176
14 1 6 176 176 176
-15 2 6 176 176 176
-14 2 6 176 176 176
-13 2 6 176 176 176
-12 2 6 176 176 176
-11 2 6 176 176 176
-10 2 6 176 176 176
12 2 6 176 176 176
13 2 6 176 176 176
14 2 6 176 176 176
-15 3 6 176 176 176
-14 3 6 176 176 176
-13 3 6 176 176 176
12 3 6 176 176 176
13 3 6 176 176 176
14 3 6 176 176 176
-15 4 6 176 176 176
-14 4 6 176 176 176
-13 4 6 176 176 176
12 4 6 176 176 176
13 4 6 176 176 176
14 4 6 176 176 176
-15 5 6 176 176 176
-14 5 6 176 176 176
-13 5 6 176 176 176
12 5 6 176 176 176
13 5 6 176 176 176
14 5 6 176 176 176
-15 6 6 176 176 176
-14 6 6 176 176 176
-13 6 6 176 176 176
12 6 6 176 176 176
13 6 6 176 176 176
14 6 6 176 176 176
-15 7 6 176 176 176
-14 7 6 176 176 176
-13 7 6 176 176 176
12 7 6 176 176 176
13 7 6 176 176 176
14 7 6 176 176 176
-15 8 6 176 176 176
-14 8 6 176 176 176
-13 8 6 176 176 176
12 8 6 176 176 176
13 8 6 176 176 176
14 8 6 176 176 176
-15 9 6 176 176 176
-14 9 6 176 176 176
-13 9 6 176 176 176
12 9 6 176 176 176
13 9 6 176 176 176
14 9 6 176 176 176
-15 10 6 176 176 176
-14 10 6 176 176 176
-13 10 6 176 176 176
12 10 6 176 176 176
13 10 6 176 176 176
14 10 6 176 176 176
-15 11 6 176 176 176
-14 11 6 176 176 176
-13 11 6 176 176 176
12 11 6 176 176 176
13 11 6 176 176 176
14 11 6 176 176 176
-15 12 6 176 176 176
-14 12 6 176 176 176
-13 12 6 176 176 176
-12 12 6 176 176 176
-11 12 6 176 176 176
-10 12 6 176 176 176
-9 12 6 176 176 176
-8 12 6 176 176 176
-7 12 6 176 176 176
-6 12 6 176 176 176
-5 12 6 176 176 176
-4 12 6 176 176 176
-3 12 6 176 176 176
-2 12 6 176 176 176
-1 12 6 176 176 176
0 12 6 176 176 176
1 12 6 176 176 176
2 12 6 176 176 176
3 12 6 176 176 176
4 12 6 176 176 176
5 12 6 176 176 176
6 12 6 176 176 176
7 12 6 176 176 176
8 12 6 176 176 176
9 12 6 176 176 176
10 12 6 176 176 176
11 12 6 176 176 176
12 12 6 176 176 176
13 12 6 176 176 176
14 12 6 176 176 176
-15 13 6 176 176 176
-14 13 6 176 176 176
-13 13 6 176 176 176
-12 13 6 176 176 176
-11 13 6 176 176 176
-10 13 6 176 176 176
-9 13 6 176 176 176
-8 13 6 176 176 176
-7 13 6 176 176 176
-6 13 6 176 176 176
-5 13 6 176 176 176
-4 13 6 176 176 176
-3 13 6 176 176 176
-2 13 6 176 176 176
-1 13 6 176 176 176
0 13 6 176 176 176
1 13 6 176 176 176
2 13 6 176 176 176
3 13 6 176 176 176
4 13 6 176 176 176
5 13 6 176 176 176
6 13 6 176 176 176
7 13 6 176 176 176
8 13 6 176 176 176
9 13 6 176 176 176
10 13 6 176 176 176
11 13 6 176 176 176
12 13 6 176 176 176
13 13 6 176 176 176
14 13 6 176 176 176
-15 14 6 176 176 176
-14 14 6 176 176 176
-13 14 6 176 176 176
-12 14 6 176 176 176
-11 14 6 176 176 176
-10 14 6 176 176 176
-9 14 6 176 176 176
-8 14 6 176 176 176
-7 14 6 176 176 176
-6 14 6 176 176 176
-5 14 6 176 176 176
-4 14 6 176 176 176
-3 14 6 176 176 176
-2 14 6 176 176 176
-1 14 6 176 176 176
0 14 6 176 176 176
1 14 6 176 176 176
2 14 6 176 176 176
3 14 6 176 176 176
4 14 6 176 176 176
5 14 6 176 176 176
6 14 6 176 176 176
7 14 6 176 176 176
8 14 6 176 176 176
9 14 6 176 176 176
10 14 6 176 176 176
11 14 6 176 176 176
12 14 6 176 176 176
13 14 6 176 176 176
14 14 6 176 176 176
-15 -15 7 176 176 176
-14 -15 7 176 176 176
-13 -15 7 176 176 176
-12 -15 7 176 176 176
-11 -15 7 176 176 176
-10 -15 7 176 176 176
-9 -15 7 176 176 176
-8 -15 7 176 176 176
-7 -15 7 176 176 176
-6 -15 7 176 176 176
-5 -15 7 176 176 176
-4 -15 7 176 176 176
-3 -15 7 176 176 176
-2 -15 7 176 176 176
-1 -15 7 176 176 176
0 -15 7 176 176 176
1 -15 7 176 176 176
2 -15 7 176 176 176
3 -15 7 176 176 176
4 -15 7 176 176 176
5 -15 7 176 176 176
6 -15 7 176 176 176
7 -15 7 176 176 176
8 -15 7 176 176 176
9 -15 7 176 176 176
10 -15 7 176 176 176
11 -15 7 176 176 176
12 -15 7 176 176 176
13 -15 7 176 176 176
14 -15 7 176 176 176
-15 -14 7 176 176 176
-14 -14 7 176 176 176
-13 -14 7 176 176 176
-12 -14 7 176 176 176
-11 -14 7 176 176 176
-10 -14 7 176 176 176
-9 -14 7 176 176 176
-8 -14 7 176 176 176
-7 -14 7 176 176 176
-6 -14 7 176 176 176
-5 -14 7 176 176 176
-4 -14 7 176 176 176
-3 -14 7 176 176 176
-2 -14 7 176 176 176
-1 -14 7 176 176 176
0 -14 7 176 176 176
1 -14 7 176 176 176
2 -14 7 176 176 176
3 -14 7 176 176 176
4 -14 7 176 176 176
5 -14 7 176 176 176
6 -14 7 176 176 176
7 -14 7 176 176 176
8 -14 7 176 176 176
9 -14 7 176 176 176
10 -14 7 176 176 176
11 -14 7 176 176 176
12 -14 7 176 176 176
13 -14 7 176 176 176
14 -14 7 176 176 176
-15 -13 7 176 176 176
-14 -13 7 176 176 176
-13 -13 7 176 176 176
-12 -13 7 176 176 176
-11 -13 7 176 176 176
-10 -13 7 176 176 176
-9 -13 7 176 176 176
-8 -13 7 176 176 176
-7 -13 7 176 176 176
-6 -13 7 176 176 176
-5 -13 7 176 176 176
-4 -13 7 176 176 176
-3 -13 7 176 176 176
-2 -13 7 176 176 176
-1 -13 7 176 176 176
0 -13 7 176 176 176
1 -13 7 176 176 176
2 -13 7 176 176 176
3 -13 7 176 176 176
4 -13 7 176 176 176
5 -13 7 176 176 176
6 -13 7 176 176 176
7 -13 7 176 176 176
8 -13 7 176 176 176
9 -13 7 176 176 176
10 -13 7 176 176 176
11 -13 7 176 176 176
12 -13 7 176 176 176
13 -13 7 176 176 176
14 -13 7 176 176 176
-15 -12 7 176 176 176
-14 -12 7 176 176 176
-13 -12 7 176 176 176
12 -12 7 176 176 176
13 -12 7 176 176 176
14 -12 7 176 176 176
-15 -11 7 176 176 176
-14 -11 7 176 176 176
-13 -11 7 176 176 176
12 -11 7 176 176 176
13 -11 7 176 176 176
14 -11 7 176 176 176
-15 -10 7 176 176 176
-14 -10 7 176 176 176
-13 -10 7 176 176 176
12 -10 7 176 176 176
13 -10 7 176 176 176
14 -10 7 176 176 176
-15 -9 7 176 176 176
-14 -9 7 176 176 176
-13 -9 7 176 176 176
12 -9 7 176 176 176
13 -9 7 176 176 176
14 -9 7 176 176 176
-15 -8 7 176 176 176
-14 -8 7 176 176 176
-13 -8 7 176 176 176
12 -8 7 176 176 176
13 -8 7 176 176 176
14 -8 7 176 176 176
-15 -7 7 176 176 176
-14 -7 7 176 176 176
-13 -7 7 176 176 176
12 -7 7 176 176 176
13 -7 7 176 176 176
14 -7 7 176 176 176
-15 -6 7 176 176 176
-14 -6 7 176 176 176
-13 -6 7 176 176 176
12 -6 7 176 176 176
13 -6 7 176 176 176
14 -6 7 176 176 176
-15 -5 7 176 176 176
-14 -5 7 176 176 176
-13 -5 7 176 176 176
12 -5 7 176 176 176
13 -5 7 176 176 176
14 -5 7 176 176 176
-15 -4 7 176 176 176
-14 -4 7 176 176 176
-13 -4 7 176 176 176
-12 -4 7 176 176 176
-11 -4 7 176 176 176
-10 -4 7 176 176 176
-9 -4 7 176 176 176
12 -4 7 176 176 176
13 -4 7 176 176 176
14 -4 7 176 176 176
-15 -3 7 176 176 176
-14 -3 7 176 176 176
-13 -3 7 176 176 176
-9 -3 7 176 176 176
12 -3 7 176 176 176
13 -3 7 176 176 176
14 -3 7 176 176 176
-15 -2 7 176 176 176
-14 -2 7 176 176 176
-13 -2 7 176 176 176
-9 -2 7 176 176 176
12 -2 7 176 176 176
13 -2 7 176 176 176
14 -2 7 176 176 176
-15 -1 7 176 176 176
-14 -1 7 176 176 176
-13 -1 7 176 176 176
-9 -1 7 176 176 176
12 -1 7 176 176 176
13 -1 7 176 176 176
14 -1 7 176 176 176
-15 0 7 176 176 176
-14 0 7 176 176 176
-13 0 7 176 176 176
-9 0 7 176 176 176
12 0 7 176 176 176
13 0 7 176 176 176
14 0 7 176 176 176
-15 1 7 176 176 176
-14 1 7 176 176 176
-13 1 7 176 176 176
-9 1 7 176 176 176
12 1 7 176 176 176
13 1 7 176 176 176
14 1 7 176 176 176
-15 2 7 176 176 176
-14 2 7 176 176 176
-13 2 7 176 176 176
-12 2 7 176 176 176
-11 2 7 176 176 176
-10 2 7 176 176 176
-9 2 7 176 176 176
12 2 7 176 176 176
13 2 7 176 176 176
14 2 7 176 176 176
-15 3 7 176 176 176
-14 3 7 176 176 176
-13 3 7 176 176 176
12 3 7 176 176 176
13 3 7 176 176 176
14 3 7 176 176 176
-15 4 7 176 176 176
-14 4 7 176 176 176
-13 4 7 176 176 176
12 4 7 176 176 176
13 4 7 176 176 176
14 4 7 176 176 176
-15 5 7 176 176 176
-14 5 7 176 176 176
-13 5 7 176 176 176
12 5 7 176 176 176
13 5 7 176 176 176
14 5 7 176 176 176
-15 6 7 176 176 176
-14 6 7 176 176 176
-13 6 7 176 176 176
12 6 7 176 176 176
13 6 7 176 176 176
14 6 7 176 176 176
-15 7 7 176 176 176
-14 7 7 176 176 176
-13 7 7 176 176 176
12 7 7 176 176 176
13 7 7 176 176 176
14 7 7 176 176 176
-15 8 7 176 176 176
-14 8 7 176 176 176
-13 8 7 176 176 176
12 8 7 176 176 176
13 8 7 176 176 176
14 8 7 176 176 176
-15 9 7 176 176 176
-14 9 7 176 176 176
-13 9 7 176 176 176
12 9 7 176 176 176
13 9 7 176 176 176
14 9 7 176 176 176
-15 10 7 176 176 176
-14 10 7 176 176 176
-13 10 7 176 176 176
12 10 7 176 176 176
13 10 7 176 176 176
14 10 7 176 176 176
-15 11 7 176 176 176
-14 11 7 176 176 176
-13 11 7 176 176 176
12 11 7 176 176 176
13 11 7 176 176 176
14 11 7 176 176 176
-15 12 7 176 176 176
-14 12 7 176 176 176
-13 12 7 176 176 176
-12 12 7 176 176 176
-11 12 7 176 176 176
-10 12 7 176 176 176
-9 12 7 176 176 176
-8 12 7 176 176 176
-7 12 7 176 176 176
-6 12 7 176 176 176
-5 12 7 176 176 176
-4 12 7 176 176 176
-3 12 7 176 176 176
-2 12 7 176 176 176
-1 12 7 176 176 176
0 12 7 176 176 176
1 12 7 176 176 176
2 12 7 176 176 176
3 12 7 176 176 176
4 12 7 176 176 176
5 12 7 176 176 176
6 12 7 176 176 176
7 12 7 176 176 176
8 12 7 176 176 176
9 12 7 176 176 176
10 12 7 176 176 176
11 12 7 176 176 176
12 12 7 176 176 176
13 12 7 176 176 176
14 12 7 176 176 176
-15 13 7 176 176 176
-14 13 7 176 176 176
-13 13 7 176 176 176
-12 13 7 176 176 176
-11 13 7 176 176 176
-10 13 7 176 176 176
-9 13 7 176 176 176
-8 13 7 176 176 176
-7 13 7 176 176 176
-6 13 7 176 176 176
-5 13 7 176 176 176
-4 13 7 176 176 176
-3 13 7 176 176 176
-2 13 7 176 176 176
-1 13 7 176 176 176
0 13 7 176 176 176
1 13 7 176 176 176
2 13 7 176 176 176
3 13 7 176 176 176
4 13 7 176 176 176
5 13 7 176 176 176
6 13 7 176 176 176
7 13 7 176 176 176
8 13 7 176 176 176
9 13 7 176 176 176
10 13 7 176 176 176
11 13 7 176 176 176
12 13 7 176 176 176
13 13 7 176 176 176
14 13 7 176 176 176
-15 14 7 176 176 176
-14 14 7 176 176 176
-13 14 7 176 176 176
-12 14 7 176 176 176
-11 14 7 176 176 176
-10 14 7 176 176 176
-9 14 7 176 176 176
-8 14 7 176 176 176
-7 14 7 176 176 176
-6 14 7 176 176 176
-5 14 7 176 176 176
-4 14 7 176 176 176
-3 14 7 176 176 176
-2 14 7 176 176 176
-1 14 7 176 176 176
0 14 7 176 176 176
1 14 7 176 176 176
2 14 7 176 176 176
3 14 7 176 176 176
4 14 7 176 176 176
5 14 7 176 176 176
6 14 7 176 176 176
7 14 7 176 176 176
8 14 7 176 176 176
9 14 7 176 176 176
10 14 7 176 176 176
11 14 7 176 176 176
12 14 7 176 176 176
13 14 7 176 176 176
14 14 7 176 176 176
-15 -15 8 176 176 176
-14 -15 8 176 176 176
-13 -15 8 176 176 176
-12 -15 8 176 176 176
-11 -15 8 176 176 176
-10 -15 8 176 176 176
-9 -15 8 176 176 176
-8 -15 8 176 176 176
-7 -15 8 176 176 176
-6 -15 8 176 176 176
-5 -15 8 176 176 176
-4 -15 8 176 176 176
-3 -15 8 176 176 176
-2 -15 8 176 176 176
-1 -15 8 176 176 176
0 -15 8 176 176 176
1 -15 8 176 176 176
2 -15 8 176 176 176
3 -15 8 176 176 176
4 -15 8 176 176 176
5 -15 8 176 176 176
6 -15 8 176 176 176
7 -15 8 176 176 176
8 -15 8 176 176 176
9 -15 8 176 176 176
10 -15 8 176 176 176
11 -15 8 176 176 176
12 -15 8 176 176 176
13 -15 8 176 176 176
14 -15 8 176 176 176
-15 -14 8 176 176 176
-14 -14 8 176 176 176
-13 -14 8 176 176 176
-12 -14 8 176 176 176
-11 -14 8 176 176 176
-10 -14 8 176 176 176
-9 -14 8 176 176 176
-8 -14 8 176 176 176
-7 -14 8 176 176 176
-6 -14 8 176 176 176
-5 -14 8 176 176 176
-4 -14 8 176 176 176
-3 -14 8 176 176 176
-2 -14 8 176 176 176
-1 -14 8 176 176 176
0 -14 8 176 176 176
1 -14 8 176 176 176
2 -14 8 176 176 176
3 -14 8 176 176 176
4 -14 8 176 176 176
5 -14 8 176 176 176
6 -14 8 176 176 176
7 -14 8 176 176 176
8 -14 8 176 176 176
9 -14 8 176 176 176
10 -14 8 176 176 176
11 -14 8 176 176 176
12 -14 8 176 176 176
13 -14 8 176 176 176
14 -14 8 176 176 176
-15 -13 8 176 176 176
-14 -13 8 176 176 176
-13 -13 8 176 176 176
-12 -13 8 176 176 176
-11 -13 8 176 176 176
-10 -13 8 176 176 176
-9 -13 8 176 176 176
-8 -13 8 176 176 176
-7 -13 8 176 176 176
-6 -13 8 176 176 176
-5 -13 8 176 176 176
-4 -13 8 176 176 176
-3 -13 8 176 176 176
-2 -13 8 176 176 176
-1 -13 8 176 176 176
0 -13 8 176 176 176
1 -13 8 176 176 176
2 -13 8 176 176 176
3 -13 8 176 176 176
4 -13 8 176 176 176
5 -13 8 176 176 176
6 -13 8 176 176 176
7 -13 8 176 176 176
8 -13 8 176 176 176
9 -13 8 176 176 176
10 -13 8 176 176 176
11 -13 8 176 176 176
12 -13 8 176 176 176
13 -13 8 176 176 176
14 -13 8 176 176 176
-15 -12 8 176 176 176
-14 -12 8 176 176 176
-13 -12 8 176 176 176
12 -12 8 176 176 176
13 -12 8 176 176 176
14 -12 8 176 176 176
-15 -11 8 176 176 176
-14 -11 8 176 176 176
-13 -11 8 176 176 176
12 -11 8 176 176 176
13 -11 8 176 176 176
14 -11 8 176 176 176
-15 -10 8 176 176 176
-14 -10 8 176 176 176
-13 -10 8 176 176 176
12 -10 8 176 176 176
13 -10 8 176 176 176
14 -10 8 176 176 176
-15 -9 8 176 176 176
-14 -9 8 176 176 176
-13 -9 8 176 176 176
12 -9 8 176 176 176
13 -9 8 176 176 176
14 -9 8 176 176 176
-15 -8 8 176 176 176
-14 -8 8 176 176 176
-13 -8 8 176 176 176
12 -8 8 176 176 176
13 -8 8 176 176 176
14 -8 8 176 176 176
-15 -7 8 176 176 176
-14 -7 8 176 176 176
-13 -7 8 176 176 176
12 -7 8 176 176 176
13 -7 8 176 176 176
14 -7 8 176 176 176
-15 -6 8 176 176 176
-14 -6 8 176 176 176
-13 -6 8 176 176 176
12 -6 8 176 176 176
13 -6 8 176 176 176
14 -6 8 176 176 176
-15 -5 8 176 176 176
-14 -5 8 176 176 176
-13 -5 8 176 176 176
12 -5 8 176 176 176
13 -5 8 176 176 176
14 -5 8 176 176 176
-15 -4 8 176 176 176
-14 -4 8 176 176 176
-13 -4 8 176 176 176
-12 -4 8 176 176 176
-11 -4 8 176 176 176
-10 -4 8 176 176 176
-9 -4 8 176 176 176
12 -4 8 176 176 176
13 -4 8 176 176 176
14 -4 8 176 176 176
-15 -3 8 176 176 176
-14 -3 8 176 176 176
-13 -3 8 176 176 176
-9 -3 8 176 176 176
12 -3 8 176 176 176
13 -3 8 176 176 176
14 -3 8 176 176 176
-15 -2 8 176 176 176
-14 -2 8 176 176 176
-13 -2 8 176 176 176
-9 -2 8 176 176 176
12 -2 8 176 176 176
13 -2 8 176 176 176
14 -2 8 176 176 176
-15 -1 8 176 176 176
-14 -1 8 176 176 176
-13 -1 8 176 176 176
-9 -1 8 176 176 176
12 -1 8 176 176 176
13 -1 8 176 176 176
14 -1 8 176 176 176
-15 0 8 176 176 176
-14 0 8 176 176 176
-13 0 8 176 176 176
-9 0 8 176 176 176
12 0 8 176 176 176
13 0 8 176 176 176
14 0 8 176 176 176
-15 1 8 176 176 176
-14 1 8 176 176 176
-13 1 8 176 176 176
-9 1 8 176 176 176
12 1 8 176 176 176
13 1 8 176 176 176
14 1 8 176 176 176
-15 2 8 176 176 176
-14 2 8 176 176 176
-13 2 8 176 176 176
-12 2 8 176 176 176
-11 2 8 176 176 176
-10 2 8 176 176 176
-9 2 8 176 176 176
12 2 8 176 176 176
13 2 8 176 176 176
14 2 8 176 176 176
-15 3 8 176 176 176
-14 3 8 176 176 176
-13 3 8 176 176 176
12 3 8 176 176 176
13 3 8 176 176 176
14 3 8 176 176 176
-15 4 8 176 176 176
-14 4 8 176 176 176
-13 4 8 176 176 176
12 4 8 176 176 176
13 4 8 176 176 176
14 4 8 176 176 176
-15 5 8 176 176 176
-14 5 8 176 176 176
-13 5 8 176 176 176
12 5 8 176 176 176
13 5 8 176 176 176
14 5 8 176 176 176
-15 6 8 176 176 176
-14 6 8 176 176 176
-13 6 8 176 176 176
12 6 8 176 176 176
13 6 8 176 176 176
14 6 8 176 176 176
-15 7 8 176 176 176
-14 7 8 176 176 176
-13 7 8 176 176 176
12 7 8 176 176 176
13 7 8 176 176 176
14 7 8 176 176 176
-15 8 8 176 176 176
-14 8 8 176 176 176
-13 8 8 176 176 176
12 8 8 176 176 176
13 8 8 176 176 176
14 8 8 176 176 176
-15 9 8 176 176 176
-14 9 8 176 176 176
-13 9 8 176 176 176
12 9 8 176 176 176
13 9 8 176 176 176
14 9 8 176 176 176
-15 10 8 176 176 176
-14 10 8 176 176 176
-13 10 8 176 176 176
12 10 8 176 176 176
13 10 8 176 176 176
14 10 8 176 176 176
-15 11 8 176 176 176
-14 11 8 176 176 176
-13 11 8 176 176 176
12 11 8 176 176 176
13 11 8 176 176 176
14 11 8 176 176 176
-15 12 8 176 176 176
-14 12 8 176 176 176
-13 12 8 176 176 176
-12 12 8 176 176 176
-11 12 8 176 176 176
-10 12 8 176 176 176
-9 12 8 176 176 176
-8 12 8 176 176 176
-7 12 8 176 176 176
-6 12 8 176 176 176
-5 12 8 176 176 176
-4 12 8 176 176 176
-3 12 8 176 176 176
-2 12 8 176 176 176
-1 12 8 176 176 176
0 12 8 176 176 176
1 12 8 176 176 176
2 12 8 176 176 176
3 12 8 176 176 176
4 12 8 176 176 176
5 12 8 176 176 176
6 12 8 176 176 176
7 12 8 176 176 176
8 12 8 176 176 176
9 12 8 176 176 176
10 12 8 176 176 176
11 12 8 176 176 176
12 12 8 176 176 176
13 12 8 176 176 176
14 12 8 176 176 176
-15 13 8 176 176 176
-14 13 8 176 176 176
-13 13 8 176 176 176
-12 13 8 176 176 176
-11 13 8 176 176 176
-10 13 8 176 176 176
-9 13 8 176 176 176
-8 13 8 176 176 176
-7 13 8 176 176 176
-6 13 8 176 176 176
-5 13 8 176 176 176
-4 13 8 176 176 176
-3 13 8 176 176 176
-2 13 8 176 176 176
-1 13 8 176 176 176
0 13 8 176 176 176
1 13 8 176 176 176
2 13 8 176 176 176
3 13 8 176 176 176
4 13 8 176 176 176
5 13 8 176 176 176
6 13 8 176 176 176
7 13 8 176 176 176
8 13 8 176 176 176
9 13 8 176 176 176
10 13 8 176 176 176
11 13 8 176 176 176
12 13 8 176 176 176
13 13 8 176 176 176
14 13 8 176 176 176
-15 14 8 176 176 176
-14 14 8 176 176 176
-13 14 8 176 176 176
-12 14 8 176 176 176
-11 14 8 176 176 176
-10 14 8 176 176 176
-9 14 8 176 176 176
-8 14 8 176 176 176
-7 14 8 176 176 176
-6 14 8 176 176 176
-5 14 8 176 176 176
-4 14 8 176 176 176
-3 14 8 176 176 176
-2 14 8 176 176 176
-1 14 8 176 176 176
0 14 8 176 176 176
1 14 8 176 176 176
2 14 8 176 176 176
3 14 8 176 176 176
4 14 8 176 176 176
5 14 8 176 176 176
6 14 8 176 176 176
7 14 8 176 176 176
8 14 8 176 176 176
9 14 8 176 176 176
10 14 8 176 176 176
11 14 8 176 176 176
12 14 8 176 176 176
13 14 8 176 176 176
14 14 8 176 176 176
-15 -15 9 176 176 176
-14 -15 9 176 176 176
-13 -15 9 176 176 176
-12 -15 9 176 176 176
-11 -15 9 176 176 176
-10 -15 9 176 176 176
-9 -15 9 176 176 176
-8 -15 9 176 176 176
-7 -15 9 176 176 176
-6 -15 9 176 176 176
-5 -15 9 176 176 176
-4 -15 9 176 176 176
-3 -15 9 176 176 176
-2 -15 9 176 176 176
-1 -15 9 176 176 176
0 -15 9 176 176 176
1 -15 9 176 176 176
2 -15 9 176 176 176
3 -15 9 176 176 176
4 -15 9 176 176 176
5 -15 9 176 176 176
6 -15 9 176 176 176
7 -15 9 176 176 176
8 -15 9 176 176 176
9 -15 9 176 176 176
10 -15 9 176 176 176
11 -15 9 176 176 176
12 -15 9 176 176 176
13 -15 9 176 176 176
14 -15 9 176 176 176
-15 -14 9 176 176 176
-14 -14 9 176 176 176
-13 -14 9 176 176 176
-12 -14 9 176 176 176
-11 -14 9 176 176 176
-10 -14 9 176 176 176
-9 -14 9 176 176 176
-8 -14 9 176 176 176
-7 -14 9 176 176 176
-6 -14 9 176 176 176
-5 -14 9 176 176 176
-4 -14 9 176 176 176
-3 -14 9 176 176 176
-2 -14 9 176 176 176
-1 -14 9 176 176 176
0 -14 9 176 176 176
1 -14 9 176 176 176
2 -14 9 176 176 176
3 -14 9 176 176 176
4 -14 9 176 176 176
5 -14 9 176 176 176
6 -14 9 176 176 176
7 -14 9 176 176 176
8 -14 9 176 176 176
9 -14 9 176 176 176
10 -14 9 176 176 176
11 -14 9 176 176 176
12 -14 9 176 176 176
13 -14 9 176 176 176
14 -14 9 176 176 176
-15 -13 9 176 176 176
-14 -13 9 176 176 176
-13 -13 9 176 176 176
-12 -13 9 176 176 176
-11 -13 9 176 176 176
-10 -13 9 176 176 176
-9 -13 9 176 176 176
-8 -13 9 176 176 176
-7 -13 9 176 176 176
-6 -13 9 176 176 176
-5 -13 9 176 176 176
-4 -13 9 176 176 176
-3 -13 9 176 176 176
-2 -13 9 176 176 176
-1 -13 9 176 176 176
0 -13 9 176 176 176
1 -13 9 176 176 176
2 -13 9 176 176 176
3 -13 9 176 176 176
4 -13 9 176 176 176
5 -13 9 176 176 176
6 -13 9 176 176 176
7 -13 9 176 176 176
8 -13 9 176 176 176
9 -13 9 176 176 176
10 -13 9 176 176 176
11 -13 9 176 176 176
12 -13 9 176 176 176
13 -13 9 176 176 176
14 -13 9 176 176 176
-15 -12 9 176 176 176
-14 -12 9 176 176 176
-13 -12 9 176 176 176
12 -12 9 176 176 176
13 -12 9 176 176 176
14 -12 9 176 176 176
-15 -11 9 176 176 176
-14 -11 9 176 176 176
-13 -11 9 176 176 176
12 -11 9 176 176 176
13 -11 9 176 176 176
14 -11 9 176 176 176
-15 -10 9 176 176 176
-14 -10 9 176 176 176
-13 -10 9 176 176 176
12 -10 9 176 176 176
13 -10 9 176 176 176
14 -10 9 176 176 176
-15 -9 9 176 176 176
-14 -9 9 176 176 176
-13 -9 9 176 176 176
12 -9 9 176 176 176
13 -9 9 176 176 176
14 -9 9 176 176 176
-15 -8 9 176 176 176
-14 -8 9 176 176 176
-13 -8 9 176 176 176
12 -8 9 176 176 176
13 -8 9 176 176 176
14 -8 9 176 176 176
-15 -7 9 176 176 176
-14 -7 9 176 176 176
-13 -7 9 176 176 176
12 -7 9 176 176 176
13 -7 9 176 176 176
14 -7 9 176 176 176
-15 -6 9 176 176 176
-14 -6 9 176 176 176
-13 -6 9 176 176 176
12 -6 9 176 176 176
13 -6 9 176 176 176
14 -6 9 176 176 176
-15 -5 9 176 176 176
-14 -5 9 176 176 176
-13 -5 9 176 176 176
12 -5 9 176 176 176
13 -5 9 176 176 176
14 -5 9 176 176 176
-15 -4 9 176 176 176
-14 -4 9 176 176 176
-13 -4 9 176 176 176
-12 -4 9 176 176 176
-11 -4 9 176 176 176
-10 -4 9 176 176 176
-9 -4 9 176 176 176
12 -4 9 176 176 176
13 -4 9 176 176 176
14 -4 9 176 176 176
-15 -3 9 176 176 176
-14 -3 9 176 176 176
-13 -3 9 176 176 176
-9 -3 9 176 176 176
12 -3 9 176 176 176
13 -3 9 176 176 176
14 -3 9 176 176 176
-15 -2 9 176 176 176
-14 -2 9 176 176 176
-13 -2 9 176 176 176
-9 -2 9 176 176 176
12 -2 9 176 176 176
13 -2 9 176 176 176
14 -2 9 176 176 176
-15 -1 9 176 176 176
-14 -1 9 176 176 176
-13 -1 9 176 176 176
-9 -1 9 176 176 176
12 -1 9 176 176 176
13 -1 9 176 176 176
14 -1 9 176 176 176
-15 0 9 176 176 176
-14 0 9 176 176 176
-13 0 9 176 176 176
-9 0 9 176 176 176
12 0 9 176 176 176
13 0 9 176 176 176
14 0 9 176 176 176
-15 1 9 176 176 176
-14 1 9 176 176 176
-13 1 9 176 176 176
-9 1 9 176 176 176
12 1 9 176 176 176
13 1 9 176 176 176
14 1 9 176 176 176
-15 2 9 176 176 176
-14 2 9 176 176 176
-13 2 9 176 176 176
-12 2 9 176 176 176
-11 2 9 176 176 176
-10 2 9 176 176 176
-9 2 9 176 176 176
12 2 9 176 176 176
13 2 9 176 176 176
14 2 9 176 176 176
-15 3 9 176 176 176
-14 3 9 176 176 176
-13 3 9 176 176 176
12 3 9 176 176 176
13 3 9 176 176 176
14 3 9 176 176 176
-15 4 9 176 176 176
-14 4 9 176 176 176
-13 4 9 176 176 176
12 4 9 176 176 176
13 4 9 176 176 176
14 4 9 176 176 176
-15 5 9 176 176 176
-14 5 9 176 176 176
-13 5 9 176 176 176
12 5 9 176 176 176
13 5 9 176 176 176
14 5 9 176 176 176
-15 6 9 176 176 176
-14 6 9 176 176 176
-13 6 9 176 176 176
12 6 9 176 176 176
13 6 9 176 176 176
14 6 9 176 176 176
-15 7 9 176 176 176
-14 7 9 176 176 176
-13 7 9 176 176 176
12 7 9 176 176 176
13 7 9 176 176 176
14 7 9 176 176 176
-15 8 9 176 176 176
-14 8 9 176 176 176
-13 8 9 176 176 176
12 8 9 176 176 176
13 8 9 176 176 176
14 8 9 176 176 176
-15 9 9 176 176 176
-14 9 9 176 176 176
-13 9 9 176 176 176
12 9 9 176 176 176
13 9 9 176 176 176
14 9 9 176 176 176
-15 10 9 176 176 176
-14 10 9 176 176 176
-13 10 9 176 176 176
12 10 9 176 176 176
13 10 9 176 176 176
14 10 9 176 176 176
-15 11 9 176 176 176
-14 11 9 176 176 176
-13 11 9 176 176 176
12 11 9 176 176 176
13 11 9 176 176 176
14 11 9 176 176 176
-15 12 9 176 176 176
-14 12 9 176 176 176
-13 12 9 176 176 176
-12 12 9 176 176 176
-11 12 9 176 176 176
-10 12 9 176 176 176
-9 12 9 176 176 176
-8 12 9 176 176 176
-7 12 9 176 176 176
-6 12 9 176 176 176
-5 12 9 176 176 176
-4 12 9 176 176 176
-3 12 9 176 176 176
-2 12 9 176 176 176
-1 12 9 176 176 176
0 12 9 176 176 176
1 12 9 176 176 176
2 12 9 176 176 176
3 12 9 176 176 176
4 12 9 176 176 176
5 12 9 176 176 176
6 12 9 176 176 176
7 12 9 176 176 176
8 12 9 176 176 176
9 12 9 176 176 176
10 12 9 176 176 176
11 12 9 176 176 176
12 12 9 176 176 176
13 12 9 176 176 176
14 12 9 176 176 176
-15 13 9 176 176 176
-14 13 9 176 176 176
-13 13 9 176 176 176
-12 13 9 176 176 176
-11 13 9 176 176 176
-10 13 9 176 176 176
-9 13 9 176 176 176
-8 13 9 176 176 176
-7 13 9 176 176 176
-6 13 9 176 176 176
-5 13 9 176 176 176
-4 13 9 176 176 176
-3 13 9 176 176 176
-2 13 9 176 176 176
-1 13 9 176 176 176
0 13 9 176 176 176
1 13 9 176 176 176
2 13 9 176 176 176
3 13 9 176 176 176
4 13 9 176 176 176
5 13 9 176 176 176
6 13 9 176 176 176
7 13 9 176 176 176
8 13 9 176 176 176
9 13 9 176 176 176
10 13 9 176 176 176
11 13 9 176 176 176
12 13 9 176 176 176
13 13 9 176 176 176
14 13 9 176 176 176
-15 14 9 176 176 176
-14 14 9 176 176 176
-13 14 9 176 176 176
-12 14 9 176 176 176
-11 14 9 176 176 176
-10 14 9 176 176 176
-9 14 9 176 176 176
-8 14 9 176 176 176
-7 14 9 176 176 176
-6 14 9 176 176 176
-5 14 9 176 176 176
-4 14 9 176 176 176
-3 14 9 176 176 176
-2 14 9 176 176 176
-1 14 9 176 176 176
0 14 9 176 176 176
1 14 9 176 176 176
2 14 9 176 176 176
3 14 9 176 176 176
4 14 9 176 176 176
5 14 9 176 176 176
6 14 9 176 176 176
7 14 9 176 176 176
8 14 9 176 176 176
9 14 9 176 176 176
10 14 9 176 176 176
11 14 9 176 176 176
12 14 9 176 176 176
13 14 9 176 176 176
14 14 9 176 176 176
-15 -15 10 176 176 176
-14 -15 10 176 176 176
-13 -15 10 176 176 176
-12 -15 10 176 176 176
-11 -15 10 176 176 176
-10 -15 10 176 176 176
-9 -15 10 176 176 176
-8 -15 10 176 176 176
-7 -15 10 176 176 176
-6 -15 10 176 176 176
-5 -15 10 176 176 176
-4 -15 10 176 176 176
-3 -15 10 176 176 176
-2 -15 10 176 176 176
-1 -15 10 176 176 176
0 -15 10 176 176 176
1 -15 10 176 176 176
2 -15 10 176 176 176
3 -15 10 176 176 176
4 -15 10 176 176 176
5 -15 10 176 176 176
6 -15 10 176 176 176
7 -15 10 176 176 176
8 -15 10 176 176 176
9 -15 10 176 176 176
10 -15 10 176 176 176
11 -15 10 176 176 176
12 -15 10 176 176 176
13 -15 10 176 176 176
14 -15 10 176 176 176
-15 -14 10 176 176 176
-14 -14 10 176 176 176
-13 -14 10 176 176 176
-12 -14 10 176 176 176
-11 -14 10 176 176 176
-10 -14 10 176 176 176
-9 -14 10 176 176 176
-8 -14 10 176 176 176
-7 -14 10 176 176 176
-6 -14 10 176 176 176
-5 -14 10 176 176 176
-4 -14 10 176 176 176
-3 -14 10 176 176 176
-2 -14 10 176 176 176
-1 -14 10 176 176 176
0 -14 10 176 176 176
1 -14 10 176 176 176
2 -14 10 176 176 176
3 -14 10 176 176 176
4 -14 10 176 176 176
5 -14 10 176 176 176
6 -14 10 176 176 176
7 -14 10 176 176 176
8 -14 10 176 176 176
9 -14 10 176 176 176
10 -14 10 176 176 176
11 -14 10 176 176 176
12 -14 10 176 176 176
13 -14 10 176 176 176
14 -14 10 176 176 176
-15 -13 10 176 176 176
-14 -13 10 176 176 176
-13 -13 10 176 176 176
-12 -13 10 176 176 176
-11 -13 10 176 176 176
-10 -13 10 176 176 176
-9 -13 10 176 176 176
-8 -13 10 176 176 176
-7 -13 10 176 176 176
-6 -13 10 176 176 176
-5 -13 10 176 176 176
-4 -13 10 176 176 176
-3 -13 10 176 176 176
-2 -13 10 176 176 176
-1 -13 10 176 176 176
0 -13 10 176 176 176
1 -13 10 176 176 176
2 -13 10 176 176 176
3 -13 10 176 176 176
4 -13 10 176 176 176
5 -13 10 176 176 176
6 -13 10 176 176 176
7 -13 10 176 176 176
8 -13 10 176 176 176
9 -13 10 176 176 176
10 -13 10 176 176 176
11 -13 10 176 176 176
12 -13 10 176 176 176
13 -13 10 176 176 176
14 -13 10 176 176 176
-15 -12 10 176 176 176
-14 -12 10 176 176 176
-13 -12 10 176 176 176
12 -12 10 176 176 176
13 -12 10 176 176 176
14 -12 10 176 176 176
-15 -11 10 176 176 176
-14 -11 10 176 176 176
-13 -11 10 176 176 176
12 -11 10 176 176 176
13 -11 10 176 176 176
14 -11 10 176 176 176
-15 -10 10 176 176 176
-14 -10 10 176 176 176
-13 -10 10 176 176 176
12 -10 10 176 176 176
13 -10 10 176 176 176
14 -10 10 176 176 176
-15 -9 10 176 176 176
-14 -9 10 176 176 176
-13 -9 10 176 176 176
12 -9 10 176 176 176
13 -9 10 176 176 176
14 -9 10 176 176 176
-15 -8 10 176 176 176
-14 -8 10 176 176 176
-13 -8 10 176 176 176
12 -8 10 176 176 176
13 -8 10 176 176 176
14 -8 10 176 176 176
-15 -7 10 176 176 176
-14 -7 10 176 176 176
-13 -7 10 176 176 176
12 -7 10 176 176 176
13 -7 10 176 176 176
14 -7 10 176 176 176
-15 -6 10 176 176 176
-14 -6 10 176 176 176
-13 -6 10 176 176 176
12 -6 10 176 176 176
13 -6 10 176 176 176
14 -6 10 176 176 176
-15 -5 10 176 176 176
-14 -5 10 176 176 176
-13 -5 10 176 176 176
12 -5 10 176 176 176
13 -5 10 176 176 176
14 -5 10 176 176 176
-15 -4 10 176 176 176
-14 -4 10 176 176 176
-13 -4 10 176 176 176
-12 -4 10 176 176 176
-11 -4 10 176 176 176
-10 -4 10 176 176 176
-9 -4 10 176 176 176
12 -4 10 176 176 176
13 -4 10 176 176 176
14 -4 10 176 176 176
-15 -3 10 176 176 176
-14 -3 10 176 176 176
-9 -3 10 176 176 176
12 -3 10 176 176 176
13 -3 10 176 176 176
14 -3 10 176 176 176
-15 -2 10 176 176 176
-14 -2 10 176 176 176
-9 -2 10 176 176 176
12 -2 10 176 176 176
13 -2 10 176 176 176
14 -2 10 176 176 176
-15 -1 10 176 176 176
-14 -1 10 176 176 176
-9 -1 10 176 176 176
12 -1 10 176 176 176
13 -1 10 176 176 176
14 -1 10 176 176 176
-15 0 10 176 176 176
-14 0 10 176 176 176
-9 0 10 176 176 176
12 0 10 176 176 176
13 0 10 176 176 176
14 0 10 176 176 176
-15 1 10 176 176 176
-14 1 10 176 176 176
-9 1 10 176 176 176
12 1 10 176 176 176
13 1 10 176 176 176
14 1 10 176 176 176
-15 2 10 176 176 176
-14 2 10 176 176 176
-13 2 10 176 176 176
-12 2 10 176 176 176
-11 2 10 176 176 176
-10 2 10 176 176 176
-9 2 10 176 176 176
12 2 10 176 176 176
13 2 10 176 176 176
14 2 10 176 176 176
-15 3 10 176 176 176
-14 3 10 176 176 176
-13 3 10 176 176 176
12 3 10 176 176 176
13 3 10 176 176 176
14 3 10 176 176 176
-15 4 10 176 176 176
-14 4 10 176 176 176
-13 4 10 176 176 176
12 4 10 176 176 176
13 4 10 176 176 176
14 4 10 176 176 176
-15 5 10 176 176 176
-14 5 10 176 176 176
-13 5 10 176 176 176
12 5 10 176 176 176
13 5 10 176 176 176
14 5 10 176 176 176
-15 6 10 176 176 176
-14 6 10 176 176 176
-13 6 10 176 176 176
12 6 10 176 176 176
13 6 10 176 176 176
14 6 10 176 176 176
-15 7 10 176 176 176
-14 7 10 176 176 176
-13 7 10 176 176 176
12 7 10 176 176 176
13 7 10 176 176 176
14 7 10 176 176 176
-15 8 10 176 176 176
-14 8 10 176 176 176
-13 8 10 176 176 176
12 8 10 176 176 176
13 8 10 176 176 176
14 8 10 176 176 176
-15 9 10 176 176 176
-14 9 10 176 176 176
-13 9 10 176 176 176
12 9 10 176 176 176
13 9 10 176 176 176
14 9 10 176 176 176
-15 10 10 176 176 176
-14 10 10 176 176 176
-13 10 10 176 176 176
12 10 10 176 176 176
13 10 10 176 176 176
14 10 10 176 176 176
-15 11 10 176 176 176
-14 11 10 176 176 176
-13 11 10 176 176 176
12 11 10 176 176 176
13 11 10 176 176 176
14 11 10 176 176 176
-15 12 10 176 176 176
-14 12 10 176 176 176
-13 12 10 176 176 176
-12 12 10 176 176 176
-11 12 10 176 176 176
-10 12 10 176 176 176
-9 12 10 176 176 176
-8 12 10 176 176 176
-7 12 10 176 176 176
-6 12 10 176 176 176
-5 12 10 176 176 176
-4 12 10 176 176 176
-3 12 10 176 176 176
-2 12 10 176 176 176
-1 12 10 176 176 176
0 12 10 176 176 176
1 12 10 176 176 176
2 12 10 176 176 176
3 12 10 176 176 176
4 12 10 176 176 176
5 12 10 176 176 176
6 12 10 176 176 176
7 12 10 176 176 176
8 12 10 176 176 176
9 12 10 176 176 176
10 12 10 176 176 176
11 12 10 176 176 176
12 12 10 176 176 176
13 12 10 176 176 176
14 12 10 176 176 176
-15 13 10 176 176 176
-14 13 10 176 176 176
-13 13 10 176 176 176
-12 13 10 176 176 176
-11 13 10 176 176 176
-10 13 10 176 176 176
-9 13 10 176 176 176
-8 13 10 176 176 176
-7 13 10 176 176 176
-6 13 10 176 176 176
-5 13 10 176 176 176
-4 13 10 176 176 176
-3 13 10 176 176 176
-2 13 10 176 176 176
-1 13 10 176 176 176
0 13 10 176 176 176
1 13 10 176 176 176
2 13 10 176 176 176
3 13 10 176 176 176
4 13 10 176 176 176
5 13 10 176 176 176
6 13 10 176 176 176
7 13 10 176 176 176
8 13 10 176 176 176
9 13 10 176 176 176
10 13 10 176 176 176
11 13 10 176 176 176
12 13 10 176 176 176
13 13 10 176 176 176
14 13 10 176 176 176
-15 14 10 176 176 176
-14 14 10 176 176 176
-13 14 10 176 176 176
-12 14 10 176 176 176
-11 14 10 176 176 176
-10 14 10 176 176 176
-9 14 10 176 176 176
-8 14 10 176 176 176
-7 14 10 176 176 176
-6 14 10 176 176 176
-5 14 10 176 176 176
-4 14 10 176 176 176
-3 14 10 176 176 176
-2 14 10 176 176 176
-1 14 10 176 176 176
0 14 10 176 176 176
1 14 10 176 176 176
2 14 10 176 176 176
3 14 10 176 176 176
4 14 10 176 176 176
5 14 10 176 176 176
6 14 10 176 176 176
7 14 10 176 176 176
8 14 10 176 176 176
9 14 10 176 176 176
10 14 10 176 176 176
11 14 10 176 176 176
12 14 10 176 176 176
13 14 10 176 176 176
14 14 10 176 176 176
-15 -15 11 176 176 176
-14 -15 11 176 176 176
-13 -15 11 176 176 176
-12 -15 11 176 176 176
-11 -15 11 176 176 176
-10 -15 11 176 176 176
-9 -15 11 176 176 176
-8 -15 11 176 176 176
-7 -15 11 176 176 176
-6 -15 11 176 176 176
-5 -15 11 176 176 176
-4 -15 11 176 176 176
-3 -15 11 176 176 176
-2 -15 11 176 176 176
-1 -15 11 176 176 176
0 -15 11 176 176 176
1 -15 11 176 176 176
2 -15 11 176 176 176
3 -15 11 176 176 176
4 -15 11 176 176 176
5 -15 11 176 176 176
6 -15 11 176 176 176
7 -15 11 176 176 176
8 -15 11 176 176 176
9 -15 11 176 176 176
10 -15 11 176 176 176
11 -15 11 176 176 176
12 -15 11 176 176 176
13 -15 11 176 176 176
14 -15 11 176 176 176
-15 -14 11 176 176 176
-14 -14 11 176 176 176
-13 -14 11 176 176 176
-12 -14 11 176 176 176
-11 -14 11 176 176 176
-10 -14 11 176 176 176
-9 -14 11 176 176 176
-8 -14 11 176 176 176
-7 -14 11 176 176 176
-6 -14 11 176 176 176
-5 -14 11 176 176 176
-4 -14 11 176 176 176
-3 -14 11 176 176 176
-2 -14 11 176 176 176
-1 -14 11 176 176 176
0 -14 11 176 176 176
1 -14 11 176 176 176
2 -14 11 176 176 176
3 -14 11 176 176 176
4 -14 11 176 176 176
5 -14 11 176 176 176
6 -14 11 176 176 176
7 -14 11 176 176 176
8 -14 11 176 176 176
9 -14 11 176 176 176
10 -14 11 176 176 176
11 -14 11 176 176 176
12 -14 11 176 176 176
13 -14 11 176 176 176
14 -14 11 176 176 176
-15 -13 11 176 176 176
-14 -13 11 176 176 176
-13 -13 11 176 176 176
-12 -13 11 176 176 176
-11 -13 11 176 176 176
-10 -13 11 176 176 176
-9 -13 11 176 176 176
-8 -13 11 176 176 176
-7 -13 11 176 176 176
-6 -13 11 176 176 176
-5 -13 11 176 176 176
-4 -13 11 176 176 176
-3 -13 11 176 176 176
-2 -13 11 176 176 176
-1 -13 11 176 176 176
0 -13 11 176 176 176
1 -13 11 176 176 176
2 -13 11 176 176 176
3 -13 11 176 176 176
4 -13 11 176 176 176
5 -13 11 176 176 176
6 -13 11 176 176 176
7 -13 11 176 176 176
8 -13 11 176 176 176
9 -13 11 176 176 176
10 -13 11 176 176 176
11 -13 11 176 176 176
12 -13 11 176 176 176
13 -13 11 176 176 176
14 -13 11 176 176 176
-15 -12 11 176 176 176
-14 -12 11 176 176 176
-13 -12 11 176 176 176
12 -12 11 176 176 176
13 -12 11 176 176 176
14 -12 11 176 176 176
-15 -11 11 176 176 176
-14 -11 11 176 176 176
-13 -11 11 176 176 176
12 -11 11 176 176 176
13 -11 11 176 176 176
14 -11 11 176 176 176
-15 -10 11 176 176 176
-14 -10 11 176 176 176
-13 -10 11 176 176 176
12 -10 11 176 176 176
13 -10 11 176 176 176
14 -10 11 176 176 176
-15 -9 11 176 176 176
-14 -9 11 176 176 176
-13 -9 11 176 176 176
12 -9 11 176 176 176
13 -9 11 176 176 176
14 -9 11 176 176 176
-15 -8 11 176 176 176
-14 -8 11 176 176 176
-13 -8 11 176 176 176
12 -8 11 176 176 176
13 -8 11 176 176 176
14 -8 11 176 176 176
-15 -7 11 176 176 176
-14 -7 11 176 176 176
-13 -7 11 176 176 176
12 -7 11 176 176 176
13 -7 11 176 176 176
14 -7 11 176 176 176
-15 -6 11 176 176 176
-14 -6 11 176 176 176
-13 -6 11 176 176 176
12 -6 11 176 176 176
13 -6 11 176 176 176
14 -6 11 176 176 176
-15 -5 11 176 176 176
-14 -5 11 176 176 176
-13 -5 11 176 176 176
12 -5 11 176 176 176
13 -5 11 176 176 176
14 -5 11 176 176 176
-15 -4 11 176 176 176
-14 -4 11 176 176 176
-13 -4 11 176 176 176
-12 -4 11 176 176 176
-11 -4 11 176 176 176
-10 -4 11 176 176 176
-9 -4 11 176 176 176
12 -4 11 176 176 176
13 -4 11 176 176 176
14 -4 11 176 176 176
-9 -3 11 176 176 176
12 -3 11 176 176 176
13 -3 11 176 176 176
14 -3 11 176 176 176
-9 -2 11 176 176 176
12 -2 11 176 176 176
13 -2 11 176 176 176
14 -2 11 176 176 176
-9 -1 11 176 176 176
12 -1 11 176 176 176
13 -1 11 176 176 176
14 -1 11 176 176 176
-9 0 11 176 176 176
12 0 11 176 176 176
13 0 11 176 176 176
14 0 11 176 176 176
-9 1 11 176 176 176
12 1 11 176 176 176
13 1 11 176 176 176
14 1 11 176 176 176
-15 2 11 176 176 176
-14 2 11 176 176 176
-13 2 11 176 176 176
-12 2 11 176 176 176
-11 2 11 176 176 176
-10 2 11 176 176 176
-9 2 11 176 176 176
12 2 11 176 176 176
13 2 11 176 176 176
14 2 11 176 176 176
-15 3 11 176 176 176
-14 3 11 176 176 176
-13 3 11 176 176 176
12 3 11 176 176 176
13 3 11 176 176 176
14 3 11 176 176 176
-15 4 11 176 176 176
-14 4 11 176 176 176
-13 4 11 176 176 176
12 4 11 176 176 176
13 4 11 176 176 176
14 4 11 176 176 176
-15 5 11 176 176 176
-14 5 11 176 176 176
-13 5 11 176 176 176
12 5 11 176 176 176
13 5 11 176 176 176
14 5 11 176 176 176
-15 6 11 176 176 176
-14 6 11 176 176 176
-13 6 11 176 176 176
12 6 11 176 176 176
13 6 11 176 176 176
14 6 11 176 176 176
-15 7 11 176 176 176
-14 7 11 176 176 176
-13 7 11 176 176 176
12 7 11 176 176 176
13 7 11 176 176 176
14 7 11 176 176 176
-15 8 11 176 176 176
-14 8 11 176 176 176
-13 8 11 176 176 176
12 8 11 176 176 176
13 8 11 176 176 176
14 8 11 176 176 176
-15 9 11 176 176 176
-14 9 11 176 176 176
-13 9 11 176 176 176
12 9 11 176 176 176
13 9 11 176 176 176
14 9 11 176 176 176
-15 10 11 176 176 176
-14 10 11 176 176 176
-13 10 11 176 176 176
12 10 11 176 176 176
13 10 11 176 176 176
14 10 11 176 176 176
-15 11 11 176 176 176
-14 11 11 176 176 176
-13 11 11 176 176 176
12 11 11 176 176 176
13 11 11 176 176 176
14 11 11 176 176 176
-15 12 11 176 176 176
-14 12 11 176 176 176
-13 12 11 176 176 176
-12 12 11 176 176 176
-11 12 11 176 176 176
-10 12 11 176 176 176
-9 12 11 176 176 176
-8 12 11 176 176 176
-7 12 11 176 176 176
-6 12 11 176 176 176
-5 12 11 176 176 176
-4 12 11 176 176 176
-3 12 11 176 176 176
-2 12 11 176 176 176
-1 12 11 176 176 176
0 12 11 176 176 176
1 12 11 176 176 176
2 12 11 176 176 176
3 12 11 176 176 176
4 12 11 176 176 176
5 12 11 176 176 176
6 12 11 176 176 176
7 12 11 176 176 176
8 12 11 176 176 176
9 12 11 176 176 176
10 12 11 176 176 176
11 12 11 176 176 176
12 12 11 176 176 176
13 12 11 176 176 176
14 12 11 176 176 176
-15 13 11 176 176 176
-14 13 11 176 176 176
-13 13 11 176 176 176
-12 13 11 176 176 176
-11 13 11 176 176 176
-10 13 11 176 176 176
-9 13 11 176 176 176
-8 13 11 176 176 176
-7 13 11 176 176 176
-6 13 11 176 176 176
-5 13 11 176 176 176
-4 13 11 176 176 176
-3 13 11 176 176 176
-2 13 11 176 176 176
-1 13 11 176 176 176
0 13 11 176 176 176
1 13 11 176 176 176
2 13 11 176 176 176
3 13 11 176 176 176
4 13 11 176 176 176
5 13 11 176 176 176
6 13 11 176 176 176
7 13 11 176 176 176
8 13 11 176 176 176
9 13 11 176 176 176
10 13 11 176 176 176
11 13 11 176 176 176
12 13 11 176 176 176
13 13 11 176 176 176
14 13 11 176 176 176
-15 14 11 176 176 176
-14 14 11 176 176 176
-13 14 11 176 176 176
-12 14 11 176 176 176
-11 14 11 176 176 176
-10 14 11 176 176 176
-9 14 11 176 176 176
-8 14 11 176 176 176
-7 14 11 176 176 176
-6 14 11 176 176 176
-5 14 11 176 176 176
-4 14 11 176 176 176
-3 14 11 176 176 176
-2 14 11 176 176 176
-1 14 11 176 176 176
0 14 11 176 176 176
1 14 11 176 176 176
2 14 11 176 176 176
3 14 11 176 176 176
4 14 11 176 176 176
5 14 11 176 176 176
6 14 11 176 176 176
7 14 11 176 176 176
8 14 11 176 176 176
9 14 11 176 176 176
10 14 11 176 176 176
11 14 11 176 176 176
12 14 11 176 176 176
13 14 11 176 176 176
14 14 11 176 176 176
-15 -15 12 176 176 176
-14 -15 12 176 176 176
-13 -15 12 176 176 176
-12 -15 12 176 176 176
-11 -15 12 176 176 176
-10 -15 12 176 176 176
-9 -15 12 176 176 176
-8 -15 12 176 176 176
-7 -15 12 176 176 176
-6 -15 12 176 176 176
-5 -15 12 176 176 176
-4 -15 12 176 176 176
-3 -15 12 176 176 176
-2 -15 12 176 176 176
-1 -15 12 176 176 176
0 -15 12 176 176 176
1 -15 12 176 176 176
2 -15 12 176 176 176
3 -15 12 176 176 176
4 -15 12 176 176 176
5 -15 12 176 176 176
6 -15 12 176 176 176
7 -15 12 176 176 176
8 -15 12 176 176 176
9 -15 12 176 176 176
10 -15 12 176 176 176
11 -15 12 176 176 176
12 -15 12 176 176 176
13 -15 12 176 176 176
14 -15 12 176 176 176
-15 -14 12 176 176 176
-14 -14 12 176 176 176
-13 -14 12 176 176 176
-12 -14 12 176 176 176
-11 -14 12 176 176 176
-10 -14 12 176 176 176
-9 -14 12 176 176 176
-8 -14 12 176 176 176
-7 -14 12 176 176 176
-6 -14 12 176 176 176
-5 -14 12 176 176 176
-4 -14 12 176 176 176
-3 -14 12 176 176 176
-2 -14 12 176 176 176
-1 -14 12 176 176 176
0 -14 12 176 176 176
1 -14 12 176 176 176
2 -14 12 176 176 176
3 -14 12 176 176 176
4 -14 12 176 176 176
5 -14 12 176 176 176
6 -14 12 176 176 176
7 -14 12 176 176 176
8 -14 12 176 176 176
9 -14 12 176 176 176
10 -14 12 176 176 176
11 -14 12 176 176 176
12 -14 12 176 176 176
13 -14 12 176 176 176
14 -14 12 176 176 176
-15 -13 12 176 176 176
-14 -13 12 176 176 176
-13 -13 12 176 176 176
-12 -13 12 176 176 176
-11 -13 12 176 176 176
-10 -13 12 176 176 176
-9 -13 12 176 176 176
-8 -13 12 176 176 176
-7 -13 12 176 176 176
-6 -13 12 176 176 176
-5 -13 12 176 176 176
-4 -13 12 176 176 176
-3 -13 12 176 176 176
-2 -13 12 176 176 176
-1 -13 12 176 176 176
0 -13 12 176 176 176
1 -13 12 176 176 176
2 -13 12 176 176 176
3 -13 12 176 176 176
4 -13 12 176 176 176
5 -13 12 176 176 176
6 -13 12 176 176 176
7 -13 12 176 176 176
8 -13 12 176 176 176
9 -13 12 176 176 176
10 -13 12 176 176 176
11 -13 12 176 176 176
12 -13 12 176 176 176
13 -13 12 176 176 176
14 -13 12 176 176 176
-15 -12 12 176 176 176
-14 -12 12 176 176 176
-13 -12 12 176 176 176
12 -12 12 176 176 176
13 -12 12 176 176 176
14 -12 12 176 176 176
-15 -11 12 176 176 176
-14 -11 12 176 176 176
-13 -11 12 176 176 176
12 -11 12 176 176 176
13 -11 12 176 176 176
14 -11 12 176 176 176
-15 -10 12 176 176 176
-14 -10 12 176 176 176
-13 -10 12 176 176 176
12 -10 12 176 176 176
13 -10 12 176 176 176
14 -10 12 176 176 176
-15 -9 12 176 176 176
-14 -9 12 176 176 176
-13 -9 12 176 176 176
12 -9 12 176 176 176
13 -9 12 176 176 176
14 -9 12 176 176 176
-15 -8 12 176 176 176
-14 -8 12 176 176 176
-13 -8 12 176 176 176
12 -8 12 176 176 176
13 -8 12 176 176 176
14 -8 12 176 176 176
-15 -7 12 176 176 176
-14 -7 12 176 176 176
-13 -7 12 176 176 176
12 -7 12 176 176 176
13 -7 12 176 176 176
14 -7 12 176 176 176
-15 -6 12 176 176 176
-14 -6 12 176 176 176
-13 -6 12 176 176 176
12 -6 12 176 176 176
13 -6 12 176 176 176
14 -6 12 176 176 176
-15 -5 12 176 176 176
-14 -5 12 176 176 176
-13 -5 12 176 176 176
12 -5 12 176 176 176
13 -5 12 176 176 176
14 -5 12 176 176 176
-15 -4 12 176 176 176
-14 -4 12 176 176 176
-13 -4 12 176 176 176
-12 -4 12 176 176 176
-11 -4 12 176 176 176
-10 -4 12 176 176 176
-9 -4 12 176 176 176
12 -4 12 176 176 176
13 -4 12 176 176 176
14 -4 12 176 176 176
-10 -3 12 136 0 0
-9 -3 12 176 176 176
12 -3 12 176 176 176
13 -3 12 176 176 176
14 -3 12 176 176 176
-10 -2 12 136 0 0
-9 -2 12 176 176 176
12 -2 12 176 176 176
13 -2 12 176 176 176
14 -2 12 176 176 176
-10 -1 12 136 0 0
-9 -1 12 176 176 176
12 -1 12 176 176 176
13 -1 12 176 176 176
14 -1 12 176 176 176
-10 0 12 136 0 0
-9 0 12 176 176 176
12 0 12 176 176 176
13 0 12 176 176 176
14 0 12 176 176 176
-10 1 12 136 0 0
-9 1 12 176 176 176
12 1 12 176 176 176
13 1 12 176 176 176
14 1 12 176 176 176
-15 2 12 176 176 176
-14 2 12 176 176 176
-13 2 12 176 176 176
-12 2 12 176 176 176
-11 2 12 176 176 176
-10 2 12 176 176 176
-9 2 12 176 176 176
12 2 12 176 176 176
13 2 12 176 176 176
14 2 12 176 176 176
-15 3 12 176 176 176
-14 3 12 176 176 176
-13 3 12 176 176 176
12 3 12 176 176 176
13 3 12 176 176 176
14 3 12 176 176 176
-15 4 12 176 176 176
-14 4 12 176 176 176
-13 4 12 176 176 176
12 4 12 176 176 176
13 4 12 176 176 176
14 4 12 176 176 176
-15 5 12 176 176 176
-14 5 12 176 176 176
-13 5 12 176 176 176
12 5 12 176 176 176
13 5 12 176 176 176
14 5 12 176 176 176
-15 6 12 176 176 176
-14 6 12 176 176 176
-13 6 12 176 176 176
12 6 12 176 176 176
13 6 12 176 176 176
14 6 12 176 176 176
-15 7 12 176 176 176
-14 7 12 176 176 176
-13 7 12 176 176 176
12 7 12 176 176 176
13 7 12 176 176 176
14 7 12 176 176 176
-15 8 12 176 176 176
-14 8 12 176 176 176
-13 8 12 176 176 176
12 8 12 176 176 176
13 8 12 176 176 176
14 8 12 176 176 176
-15 9 12 176 176 176
-14 9 12 176 176 176
-13 9 12 176 176 176
12 9 12 176 176 176
13 9 12 176 176 176
14 9 12 176 176 176
-15 10 12 176 176 176
-14 10 12 176 176 176
-13 10 12 176 176 176
12 10 12 176 176 176
13 10 12 176 176 176
14 10 12 176 176 176
-15 11 12 176 176 176
-14 11 12 176 176 176
-13 11 12 176 176 176
12 11 12 176 176 176
13 11 12 176 176 176
14 11 12 176 176 176
-15 12 12 176 176 176
-14 12 12 176 176 176
-13 12 12 176 176 176
-12 12 12 176 176 176
-11 12 12 176 176 176
-10 12 12 176 176 176
-9 12 12 176 176 176
-8 12 12 176 176 176
-7 12 12 176 176 176
-6 12 12 176 176 176
-5 12 12 176 176 176
-4 12 12 176 176 176
-3 12 12 176 176 176
-2 12 12 176 176 176
-1 12 12 176 176 176
0 12 12 176 176 176
1 12 12 176 176 176
2 12 12 176 176 176
3 12 12 176 176 176
4 12 12 176 176 176
5 12 12 176 176 176
6 12 12 176 176 176
7 12 12 176 176 176
8 12 12 176 176 176
9 12 12 176 176 176
10 12 12 176 176 176
11 12 12 176 176 176
12 12 12 176 176 176
13 12 12 176 176 176
14 12 12 176 176 176
-15 13 12 176 176 176
-14 13 12 176 176 176
-13 13 12 176 176 176
-12 13 12 176 176 176
-11 13 12 176 176 176
-10 13 12 176 176 176
-9 13 12 176 176 176
-8 13 12 176 176 176
-7 13 12 176 176 176
-6 13 12 176 176 176
-5 13 12 176 176 176
-4 13 12 176 176 176
-3 13 12 176 176 176
-2 13 12 176 176 176
-1 13 12 176 176 176
0 13 12 176 176 176
1 13 12 176 176 176
2 13 12 176 176 176
3 13 12 176 176 176
4 13 12 176 176 176
5 13 12 176 176 176
6 13 12 176 176 176
7 13 12 176 176 176
8 13 12 176 176 176
9 13 12 176 176 176
10 13 12 176 176 176
11 13 12 176 176 176
12 13 12 176 176 176
13 13 12 176 176 176
14 13 12 176 176 176
-15 14 12 176 176 176
-14 14 12 176 176 176
-13 14 12 176 176 176
-12 14 12 176 176 176
-11 14 12 176 176 176
-10 14 12 176 176 176
-9 14 12 176 176 176
-8 14 12 176 176 176
-7 14 12 176 176 176
-6 14 12 176 176 176
-5 14 12 176 176 176
-4 14 12 176 176 176
-3 14 12 176 176 176
-2 14 12 176 176 176
-1 14 12 176 176 176
0 14 12 176 176 176
1 14 12 176 176 176
2 14 12 176 176 176
