ply
format ascii 1.0
comment : MagicaVoxel @ Ephtracy
element vertex 460
property float x
property float y
property float z
property uchar red
property uchar green
property uchar blue
end_header
-5 -5 0 160 132 68
-4 -5 0 160 132 68
-3 -5 0 160 132 68
-2 -5 0 176 60 60
-1 -5 0 192 88 88
0 -5 0 176 60 60
1 -5 0 160 132 68
2 -5 0 160 132 68
3 -5 0 160 132 68
4 -5 0 160 132 68
-5 -4 0 160 132 68
-4 -4 0 160 132 68
-3 -4 0 160 132 68
-2 -4 0 176 60 60
-1 -4 0 192 88 88
0 -4 0 176 60 60
1 -4 0 184 156 88
2 -4 0 184 156 88
3 -4 0 184 156 88
4 -4 0 184 156 88
-5 -3 0 160 132 68
-4 -3 0 160 132 68
-3 -3 0 160 132 68
-2 -3 0 176 60 60
-1 -3 0 192 88 88
0 -3 0 176 60 60
1 -3 0 132 104 48
2 -3 0 132 104 48
3 -3 0 132 104 48
4 -3 0 132 104 48
-5 -2 0 176 60 60
-4 -2 0 176 60 60
-3 -2 0 176 60 60
-2 -2 0 176 60 60
-1 -2 0 192 88 88
0 -2 0 176 60 60
1 -2 0 176 60 60
2 -2 0 176 60 60
3 -2 0 176 60 60
4 -2 0 176 60 60
-5 -1 0 192 88 88
-4 -1 0 192 88 88
-3 -1 0 192 88 88
-2 -1 0 192 88 88
-1 -1 0 192 88 88
0 -1 0 192 88 88
1 -1 0 192 88 88
2 -1 0 192 88 88
3 -1 0 192 88 88
4 -1 0 192 88 88
-5 0 0 176 60 60
-4 0 0 176 60 60
-3 0 0 176 60 60
-2 0 0 176 60 60
-1 0 0 192 88 88
0 0 0 176 60 60
1 0 0 176 60 60
2 0 0 176 60 60
3 0 0 176 60 60
4 0 0 176 60 60
-5 1 0 160 132 68
-4 1 0 160 132 68
-3 1 0 160 132 68
-2 1 0 176 60 60
-1 1 0 192 88 88
0 1 0 176 60 60
1 1 0 160 132 68
2 1 0 160 132 68
3 1 0 160 132 68
4 1 0 160 132 68
-5 2 0 160 132 68
-4 2 0 184 156 88
-3 2 0 184 156 88
-2 2 0 176 60 60
-1 2 0 192 88 88
0 2 0 176 60 60
1 2 0 160 132 68
2 2 0 160 132 68
3 2 0 160 132 68
4 2 0 160 132 68
-5 3 0 132 104 48
-4 3 0 132 104 48
-3 3 0 132 104 48
-2 3 0 176 60 60
-1 3 0 192 88 88
0 3 0 176 60 60
1 3 0 160 132 68
2 3 0 160 132 68
3 3 0 160 132 68
4 3 0 160 132 68
-5 4 0 160 132 68
-4 4 0 160 132 68
-3 4 0 160 132 68
-2 4 0 176 60 60
-1 4 0 192 88 88
0 4 0 176 60 60
1 4 0 160 132 68
2 4 0 160 132 68
3 4 0 160 132 68
4 4 0 160 132 68
-5 -5 1 108 108 108
-4 -5 1 108 108 108
3 -5 1 108 108 108
4 -5 1 108 108 108
-5 -4 1 108 108 108
-4 -4 1 100 72 24
-3 -4 1 100 72 24
2 -4 1 100 72 24
3 -4 1 100 72 24
4 -4 1 108 108 108
-4 -3 1 100 72 24
-3 -3 1 100 72 24
2 -3 1 100 72 24
3 -3 1 100 72 24
-4 2 1 100 72 24
-3 2 1 100 72 24
2 2 1 100 72 24
3 2 1 100 72 24
-5 3 1 108 108 108
-4 3 1 100 72 24
-3 3 1 100 72 24
2 3 1 100 72 24
3 3 1 100 72 24
4 3 1 108 108 108
-5 4 1 108 108 108
-4 4 1 108 108 108
3 4 1 108 108 108
4 4 1 108 108 108
-5 -5 2 144 144 144
-4 -5 2 108 108 108
3 -5 2 108 108 108
4 -5 2 144 144 144
-5 -4 2 108 108 108
-4 -4 2 100 72 24
-3 -4 2 100 72 24
2 -4 2 100 72 24
3 -4 2 100 72 24
4 -4 2 108 108 108
-4 -3 2 100 72 24
-3 -3 2 100 72 24
2 -3 2 100 72 24
3 -3 2 100 72 24
-4 2 2 100 72 24
-3 2 2 100 72 24
2 2 2 100 72 24
3 2 2 100 72 24
-5 3 2 108 108 108
-4 3 2 100 72 24
-3 3 2 100 72 24
2 3 2 100 72 24
3 3 2 100 72 24
4 3 2 108 108 108
-5 4 2 144 144 144
-4 4 2 108 108 108
3 4 2 108 108 108
4 4 2 144 144 144
-5 -5 3 144 144 144
-4 -5 3 108 108 108
3 -5 3 108 108 108
4 -5 3 144 144 144
-5 -4 3 108 108 108
-4 -4 3 100 72 24
-3 -4 3 100 72 24
2 -4 3 100 72 24
3 -4 3 100 72 24
4 -4 3 108 108 108
-4 -3 3 100 72 24
-3 -3 3 100 72 24
2 -3 3 100 72 24
3 -3 3 100 72 24
-4 2 3 100 72 24
-3 2 3 100 72 24
2 2 3 100 72 24
3 2 3 100 72 24
-5 3 3 108 108 108
-4 3 3 100 72 24
-3 3 3 100 72 24
2 3 3 100 72 24
3 3 3 100 72 24
4 3 3 108 108 108
-5 4 3 144 144 144
-4 4 3 108 108 108
3 4 3 108 108 108
4 4 3 144 144 144
-5 -5 4 108 108 108
-4 -5 4 108 108 108
3 -5 4 108 108 108
4 -5 4 108 108 108
-5 -4 4 108 108 108
-4 -4 4 100 72 24
-3 -4 4 100 72 24
2 -4 4 100 72 24
3 -4 4 100 72 24
4 -4 4 108 108 108
-4 -3 4 100 72 24
-3 -3 4 100 72 24
2 -3 4 100 72 24
3 -3 4 100 72 24
-4 2 4 100 72 24
-3 2 4 100 72 24
2 2 4 100 72 24
3 2 4 100 72 24
-5 3 4 108 108 108
-4 3 4 100 72 24
-3 3 4 100 72 24
2 3 4 100 72 24
3 3 4 100 72 24
4 3 4 108 108 108
-5 4 4 108 108 108
-4 4 4 108 108 108
3 4 4 108 108 108
4 4 4 108 108 108
-5 -5 5 144 144 144
-4 -5 5 108 108 108
3 -5 5 108 108 108
4 -5 5 144 144 144
-5 -4 5 108 108 108
-4 -4 5 100 72 24
-3 -4 5 100 72 24
2 -4 5 100 72 24
3 -4 5 100 72 24
4 -4 5 108 108 108
-4 -3 5 100 72 24
-3 -3 5 100 72 24
2 -3 5 100 72 24
3 -3 5 100 72 24
-4 2 5 100 72 24
-3 2 5 100 72 24
2 2 5 100 72 24
3 2 5 100 72 24
-5 3 5 108 108 108
-4 3 5 100 72 24
-3 3 5 100 72 24
2 3 5 100 72 24
3 3 5 100 72 24
4 3 5 108 108 108
-5 4 5 144 144 144
-4 4 5 108 108 108
3 4 5 108 108 108
4 4 5 144 144 144
-5 -5 6 144 144 144
-4 -5 6 108 108 108
3 -5 6 108 108 108
4 -5 6 144 144 144
-5 -4 6 108 108 108
-4 -4 6 100 72 24
-3 -4 6 100 72 24
2 -4 6 100 72 24
3 -4 6 100 72 24
4 -4 6 108 108 108
-5 -3 6 132 104 48
-4 -3 6 100 72 24
-3 -3 6 100 72 24
2 -3 6 100 72 24
3 -3 6 100 72 24
-5 2 6 132 104 48
-4 2 6 100 72 24
-3 2 6 100 72 24
2 2 6 100 72 24
3 2 6 100 72 24
-5 3 6 108 108 108
-4 3 6 100 72 24
-3 3 6 100 72 24
2 3 6 100 72 24
3 3 6 100 72 24
4 3 6 108 108 108
-5 4 6 144 144 144
-4 4 6 108 108 108
-3 4 6 132 104 48
2 4 6 132 104 48
3 4 6 108 108 108
4 4 6 144 144 144
-5 -5 7 144 144 144
-4 -5 7 108 108 108
-3 -5 7 132 104 48
-2 -5 7 132 104 48
1 -5 7 132 104 48
2 -5 7 132 104 48
3 -5 7 108 108 108
4 -5 7 144 144 144
-5 -4 7 108 108 108
-4 -4 7 100 72 24
-3 -4 7 100 72 24
2 -4 7 100 72 24
3 -4 7 100 72 24
4 -4 7 108 108 108
-5 -3 7 132 104 48
-4 -3 7 100 72 24
-3 -3 7 100 72 24
2 -3 7 100 72 24
3 -3 7 100 72 24
4 -3 7 132 104 48
-5 -2 7 132 104 48
4 -2 7 132 104 48
-5 1 7 132 104 48
4 1 7 132 104 48
-5 2 7 132 104 48
-4 2 7 100 72 24
-3 2 7 100 72 24
2 2 7 100 72 24
3 2 7 100 72 24
4 2 7 132 104 48
-5 3 7 108 108 108
-4 3 7 100 72 24
-3 3 7 100 72 24
2 3 7 100 72 24
3 3 7 100 72 24
4 3 7 108 108 108
-5 4 7 144 144 144
-4 4 7 108 108 108
-3 4 7 132 104 48
-2 4 7 132 104 48
1 4 7 132 104 48
2 4 7 132 104 48
3 4 7 108 108 108
4 4 7 144 144 144
-5 -5 8 108 108 108
-4 -5 8 108 108 108
-2 -5 8 132 104 48
-1 -5 8 132 104 48
0 -5 8 132 104 48
1 -5 8 132 104 48
3 -5 8 108 108 108
4 -5 8 108 108 108
-5 -4 8 108 108 108
-4 -4 8 100 72 24
-3 -4 8 100 72 24
2 -4 8 100 72 24
3 -4 8 100 72 24
4 -4 8 108 108 108
-4 -3 8 100 72 24
-3 -3 8 100 72 24
2 -3 8 100 72 24
3 -3 8 100 72 24
-5 -2 8 132 104 48
4 -2 8 132 104 48
-5 -1 8 132 104 48
4 -1 8 132 104 48
-5 0 8 132 104 48
4 0 8 132 104 48
-5 1 8 132 104 48
4 1 8 132 104 48
-4 2 8 100 72 24
-3 2 8 100 72 24
2 2 8 100 72 24
3 2 8 100 72 24
-5 3 8 108 108 108
-4 3 8 100 72 24
-3 3 8 100 72 24
2 3 8 100 72 24
3 3 8 100 72 24
4 3 8 108 108 108
-5 4 8 108 108 108
-4 4 8 108 108 108
-2 4 8 132 104 48
-1 4 8 132 104 48
0 4 8 132 104 48
1 4 8 132 104 48
3 4 8 108 108 108
4 4 8 108 108 108
-5 -5 9 64 64 64
-4 -5 9 64 64 64
-3 -5 9 64 64 64
-2 -5 9 132 104 48
-1 -5 9 132 104 48
0 -5 9 132 104 48
1 -5 9 64 64 64
2 -5 9 64 64 64
3 -5 9 64 64 64
4 -5 9 64 64 64
-5 -4 9 64 64 64
-4 -4 9 64 64 64
-3 -4 9 64 64 64
-2 -4 9 132 104 48
-1 -4 9 132 104 48
0 -4 9 132 104 48
1 -4 9 64 64 64
2 -4 9 64 64 64
3 -4 9 64 64 64
4 -4 9 64 64 64
-5 -3 9 64 64 64
-4 -3 9 64 64 64
-3 -3 9 64 64 64
-2 -3 9 132 104 48
-1 -3 9 132 104 48
0 -3 9 132 104 48
1 -3 9 64 64 64
2 -3 9 64 64 64
3 -3 9 64 64 64
4 -3 9 64 64 64
-5 -2 9 132 104 48
-4 -2 9 132 104 48
-3 -2 9 132 104 48
-2 -2 9 132 104 48
-1 -2 9 132 104 48
0 -2 9 132 104 48
1 -2 9 132 104 48
2 -2 9 132 104 48
3 -2 9 132 104 48
4 -2 9 132 104 48
-5 -1 9 132 104 48
-4 -1 9 132 104 48
-3 -1 9 132 104 48
-2 -1 9 132 104 48
-1 -1 9 132 104 48
0 -1 9 132 104 48
1 -1 9 132 104 48
2 -1 9 132 104 48
3 -1 9 132 104 48
4 -1 9 132 104 48
-5 0 9 132 104 48
-4 0 9 132 104 48
-3 0 9 132 104 48
-2 0 9 132 104 48
-1 0 9 132 104 48
0 0 9 132 104 48
1 0 9 132 104 48
2 0 9 132 104 48
3 0 9 132 104 48
4 0 9 132 104 48
-5 1 9 64 64 64
-4 1 9 64 64 64
-3 1 9 64 64 64
-2 1 9 132 104 48
-1 1 9 132 104 48
0 1 9 132 104 48
1 1 9 64 64 64
2 1 9 64 64 64
3 1 9 64 64 64
4 1 9 64 64 64
-5 2 9 64 64 64
-4 2 9 64 64 64
-3 2 9 64 64 64
-2 2 9 132 104 48
-1 2 9 132 104 48
0 2 9 132 104 48
1 2 9 64 64 64
2 2 9 64 64 64
3 2 9 64 64 64
4 2 9 64 64 64
-5 3 9 64 64 64
-4 3 9 64 64 64
-3 3 9 64 64 64
-2 3 9 132 104 48
-1 3 9 132 104 48
0 3 9 132 104 48
1 3 9 64 64 64
2 3 9 64 64 64
3 3 9 64 64 64
4 3 9 64 64 64
-5 4 9 64 64 64
-4 4 9 64 64 64
-3 4 9 64 64 64
-2 4 9 132 104 48
-1 4 9 132 104 48
0 4 9 132 104 48
1 4 9 64 64 64
2 4 9 64 64 64
3 4 9 64 64 64
4 4 9 64 64 64
