ply
format ascii 1.0
comment : MagicaVoxel @ Ephtracy
element vertex 9596
property float x
property float y
property float z
property uchar red
property uchar green
property uchar blue
end_header
-15 -15 0 144 144 144
-14 -15 0 144 144 144
-13 -15 0 144 144 144
-12 -15 0 144 144 144
-11 -15 0 144 144 144
-10 -15 0 144 144 144
-9 -15 0 144 144 144
-8 -15 0 144 144 144
-7 -15 0 144 144 144
-6 -15 0 144 144 144
-5 -15 0 144 144 144
-4 -15 0 144 144 144
-3 -15 0 144 144 144
-2 -15 0 144 144 144
-1 -15 0 144 144 144
0 -15 0 144 144 144
1 -15 0 144 144 144
2 -15 0 144 144 144
3 -15 0 144 144 144
4 -15 0 144 144 144
5 -15 0 144 144 144
6 -15 0 144 144 144
7 -15 0 144 144 144
8 -15 0 144 144 144
9 -15 0 144 144 144
10 -15 0 144 144 144
11 -15 0 144 144 144
12 -15 0 144 144 144
13 -15 0 144 144 144
14 -15 0 144 144 144
-15 -14 0 144 144 144
-14 -14 0 108 108 108
-13 -14 0 108 108 108
-12 -14 0 108 108 108
-11 -14 0 108 108 108
-10 -14 0 108 108 108
-9 -14 0 108 108 108
-8 -14 0 108 108 108
-7 -14 0 108 108 108
-6 -14 0 108 108 108
-5 -14 0 108 108 108
-4 -14 0 108 108 108
-3 -14 0 108 108 108
-2 -14 0 108 108 108
-1 -14 0 108 108 108
0 -14 0 108 108 108
1 -14 0 108 108 108
2 -14 0 108 108 108
3 -14 0 108 108 108
4 -14 0 108 108 108
5 -14 0 108 108 108
6 -14 0 108 108 108
7 -14 0 108 108 108
8 -14 0 108 108 108
9 -14 0 108 108 108
10 -14 0 108 108 108
11 -14 0 108 108 108
12 -14 0 108 108 108
13 -14 0 108 108 108
14 -14 0 144 144 144
-15 -13 0 144 144 144
-14 -13 0 108 108 108
-13 -13 0 108 108 108
-12 -13 0 108 108 108
-11 -13 0 108 108 108
-10 -13 0 108 108 108
-9 -13 0 108 108 108
-8 -13 0 108 108 108
-7 -13 0 108 108 108
-6 -13 0 108 108 108
-5 -13 0 108 108 108
-4 -13 0 108 108 108
-3 -13 0 108 108 108
-2 -13 0 108 108 108
-1 -13 0 108 108 108
0 -13 0 108 108 108
1 -13 0 108 108 108
2 -13 0 108 108 108
3 -13 0 108 108 108
4 -13 0 108 108 108
5 -13 0 108 108 108
6 -13 0 108 108 108
7 -13 0 108 108 108
8 -13 0 108 108 108
9 -13 0 108 108 108
10 -13 0 108 108 108
11 -13 0 108 108 108
12 -13 0 108 108 108
13 -13 0 108 108 108
14 -13 0 144 144 144
-15 -12 0 144 144 144
-14 -12 0 108 108 108
-13 -12 0 108 108 108
-12 -12 0 68 40 0
-11 -12 0 68 40 0
-10 -12 0 68 40 0
-9 -12 0 68 40 0
-8 -12 0 68 40 0
-7 -12 0 68 40 0
-6 -12 0 68 40 0
-5 -12 0 68 40 0
-4 -12 0 68 40 0
-3 -12 0 68 40 0
-2 -12 0 68 40 0
-1 -12 0 68 40 0
0 -12 0 68 40 0
1 -12 0 68 40 0
2 -12 0 68 40 0
3 -12 0 68 40 0
4 -12 0 68 40 0
5 -12 0 68 40 0
6 -12 0 68 40 0
7 -12 0 68 40 0
8 -12 0 68 40 0
9 -12 0 68 40 0
10 -12 0 68 40 0
11 -12 0 68 40 0
12 -12 0 108 108 108
13 -12 0 108 108 108
14 -12 0 144 144 144
-15 -11 0 144 144 144
-14 -11 0 108 108 108
-13 -11 0 108 108 108
-12 -11 0 68 40 0
-11 -11 0 68 40 0
-10 -11 0 68 40 0
-9 -11 0 68 40 0
-8 -11 0 68 40 0
-7 -11 0 68 40 0
-6 -11 0 68 40 0
-5 -11 0 68 40 0
-4 -11 0 68 40 0
-3 -11 0 68 40 0
-2 -11 0 68 40 0
-1 -11 0 68 40 0
0 -11 0 68 40 0
1 -11 0 68 40 0
2 -11 0 68 40 0
3 -11 0 68 40 0
4 -11 0 68 40 0
5 -11 0 68 40 0
6 -11 0 68 40 0
7 -11 0 68 40 0
8 -11 0 68 40 0
9 -11 0 68 40 0
10 -11 0 68 40 0
11 -11 0 68 40 0
12 -11 0 108 108 108
13 -11 0 108 108 108
14 -11 0 144 144 144
-15 -10 0 144 144 144
-14 -10 0 108 108 108
-13 -10 0 108 108 108
-12 -10 0 68 40 0
-11 -10 0 68 40 0
-10 -10 0 44 48 0
-9 -10 0 44 48 0
-8 -10 0 44 48 0
-7 -10 0 68 40 0
-6 -10 0 68 40 0
-5 -10 0 68 40 0
-4 -10 0 68 40 0
-3 -10 0 44 48 0
-2 -10 0 44 48 0
-1 -10 0 44 48 0
0 -10 0 68 40 0
1 -10 0 68 40 0
2 -10 0 68 40 0
3 -10 0 68 40 0
4 -10 0 68 40 0
5 -10 0 68 40 0
6 -10 0 68 40 0
7 -10 0 68 40 0
8 -10 0 68 40 0
9 -10 0 68 40 0
10 -10 0 68 40 0
11 -10 0 68 40 0
12 -10 0 108 108 108
13 -10 0 108 108 108
14 -10 0 144 144 144
-15 -9 0 144 144 144
-14 -9 0 108 108 108
-13 -9 0 108 108 108
-12 -9 0 68 40 0
-11 -9 0 44 48 0
-10 -9 0 44 48 0
-9 -9 0 44 48 0
-8 -9 0 44 48 0
-7 -9 0 68 40 0
-6 -9 0 68 40 0
-5 -9 0 68 40 0
-4 -9 0 44 48 0
-3 -9 0 44 48 0
-2 -9 0 44 48 0
-1 -9 0 44 48 0
0 -9 0 44 48 0
1 -9 0 68 40 0
2 -9 0 68 40 0
3 -9 0 68 40 0
4 -9 0 68 40 0
5 -9 0 44 48 0
6 -9 0 68 40 0
7 -9 0 68 40 0
8 -9 0 68 40 0
9 -9 0 68 40 0
10 -9 0 68 40 0
11 -9 0 68 40 0
12 -9 0 108 108 108
13 -9 0 108 108 108
14 -9 0 144 144 144
-15 -8 0 144 144 144
-14 -8 0 108 108 108
-13 -8 0 108 108 108
-12 -8 0 68 40 0
-11 -8 0 68 40 0
-10 -8 0 44 48 0
-9 -8 0 44 48 0
-8 -8 0 68 40 0
-7 -8 0 68 40 0
-6 -8 0 68 40 0
-5 -8 0 44 48 0
-4 -8 0 44 48 0
-3 -8 0 44 48 0
-2 -8 0 44 48 0
-1 -8 0 44 48 0
0 -8 0 44 48 0
1 -8 0 44 48 0
2 -8 0 68 40 0
3 -8 0 68 40 0
4 -8 0 68 40 0
5 -8 0 44 48 0
6 -8 0 44 48 0
7 -8 0 44 48 0
8 -8 0 44 48 0
9 -8 0 68 40 0
10 -8 0 68 40 0
11 -8 0 68 40 0
12 -8 0 108 108 108
13 -8 0 108 108 108
14 -8 0 144 144 144
-15 -7 0 144 144 144
-14 -7 0 108 108 108
-13 -7 0 108 108 108
-12 -7 0 68 40 0
-11 -7 0 68 40 0
-10 -7 0 68 40 0
-9 -7 0 44 48 0
-8 -7 0 44 48 0
-7 -7 0 68 40 0
-6 -7 0 68 40 0
-5 -7 0 68 40 0
-4 -7 0 44 48 0
-3 -7 0 44 48 0
-2 -7 0 44 48 0
-1 -7 0 44 48 0
0 -7 0 44 48 0
1 -7 0 68 40 0
2 -7 0 68 40 0
3 -7 0 68 40 0
4 -7 0 44 48 0
5 -7 0 44 48 0
6 -7 0 44 48 0
7 -7 0 44 48 0
8 -7 0 44 48 0
9 -7 0 68 40 0
10 -7 0 68 40 0
11 -7 0 68 40 0
12 -7 0 108 108 108
13 -7 0 108 108 108
14 -7 0 144 144 144
-15 -6 0 144 144 144
-14 -6 0 108 108 108
-13 -6 0 108 108 108
-12 -6 0 68 40 0
-11 -6 0 68 40 0
-10 -6 0 68 40 0
-9 -6 0 44 48 0
-8 -6 0 44 48 0
-7 -6 0 68 40 0
-6 -6 0 32 92 32
-5 -6 0 32 92 32
-4 -6 0 32 92 32
-3 -6 0 32 92 32
-2 -6 0 32 92 32
-1 -6 0 32 92 32
0 -6 0 32 92 32
1 -6 0 32 92 32
2 -6 0 32 92 32
3 -6 0 32 92 32
4 -6 0 32 92 32
5 -6 0 32 92 32
6 -6 0 44 48 0
7 -6 0 44 48 0
8 -6 0 44 48 0
9 -6 0 44 48 0
10 -6 0 68 40 0
11 -6 0 68 40 0
12 -6 0 108 108 108
13 -6 0 108 108 108
14 -6 0 144 144 144
-15 -5 0 144 144 144
-14 -5 0 108 108 108
-13 -5 0 108 108 108
-12 -5 0 68 40 0
-11 -5 0 68 40 0
-10 -5 0 68 40 0
-9 -5 0 44 48 0
-8 -5 0 44 48 0
-7 -5 0 68 40 0
-6 -5 0 32 92 32
-5 -5 0 68 40 0
-4 -5 0 68 40 0
-3 -5 0 44 48 0
-2 -5 0 44 48 0
-1 -5 0 44 48 0
0 -5 0 68 40 0
1 -5 0 68 40 0
2 -5 0 68 40 0
3 -5 0 68 40 0
4 -5 0 44 48 0
5 -5 0 32 92 32
6 -5 0 44 48 0
7 -5 0 44 48 0
8 -5 0 44 48 0
9 -5 0 44 48 0
10 -5 0 68 40 0
11 -5 0 68 40 0
12 -5 0 108 108 108
13 -5 0 108 108 108
14 -5 0 144 144 144
-15 -4 0 144 144 144
-14 -4 0 108 108 108
-13 -4 0 108 108 108
-12 -4 0 68 40 0
-11 -4 0 68 40 0
-10 -4 0 68 40 0
-9 -4 0 68 40 0
-8 -4 0 68 40 0
-7 -4 0 68 40 0
-6 -4 0 32 92 32
-5 -4 0 68 40 0
-4 -4 0 32 92 32
-3 -4 0 32 92 32
-2 -4 0 68 40 0
-1 -4 0 32 92 32
0 -4 0 32 92 32
1 -4 0 68 40 0
2 -4 0 32 92 32
3 -4 0 32 92 32
4 -4 0 68 40 0
5 -4 0 32 92 32
6 -4 0 44 48 0
7 -4 0 44 48 0
8 -4 0 44 48 0
9 -4 0 44 48 0
10 -4 0 68 40 0
11 -4 0 68 40 0
12 -4 0 108 108 108
13 -4 0 108 108 108
14 -4 0 144 144 144
-15 -3 0 144 144 144
-14 -3 0 108 108 108
-13 -3 0 108 108 108
-12 -3 0 68 40 0
-11 -3 0 68 40 0
-10 -3 0 68 40 0
-9 -3 0 68 40 0
-8 -3 0 68 40 0
-7 -3 0 68 40 0
-6 -3 0 32 92 32
-5 -3 0 68 40 0
-4 -3 0 32 92 32
-3 -3 0 32 92 32
-2 -3 0 68 40 0
-1 -3 0 32 92 32
0 -3 0 32 92 32
1 -3 0 68 40 0
2 -3 0 32 92 32
3 -3 0 32 92 32
4 -3 0 68 40 0
5 -3 0 32 92 32
6 -3 0 44 48 0
7 -3 0 44 48 0
8 -3 0 44 48 0
9 -3 0 44 48 0
10 -3 0 68 40 0
11 -3 0 68 40 0
12 -3 0 108 108 108
13 -3 0 108 108 108
14 -3 0 144 144 144
-15 -2 0 144 144 144
-14 -2 0 108 108 108
-13 -2 0 108 108 108
-12 -2 0 68 40 0
-11 -2 0 68 40 0
-10 -2 0 68 40 0
-9 -2 0 68 40 0
-8 -2 0 68 40 0
-7 -2 0 68 40 0
-6 -2 0 32 92 32
-5 -2 0 44 48 0
-4 -2 0 68 40 0
-3 -2 0 68 40 0
-2 -2 0 68 40 0
-1 -2 0 68 40 0
0 -2 0 68 40 0
1 -2 0 68 40 0
2 -2 0 44 48 0
3 -2 0 44 48 0
4 -2 0 44 48 0
5 -2 0 32 92 32
6 -2 0 68 40 0
7 -2 0 68 40 0
8 -2 0 68 40 0
9 -2 0 68 40 0
10 -2 0 68 40 0
11 -2 0 68 40 0
12 -2 0 108 108 108
13 -2 0 108 108 108
14 -2 0 144 144 144
-15 -1 0 144 144 144
-14 -1 0 108 108 108
-13 -1 0 108 108 108
-12 -1 0 68 40 0
-11 -1 0 68 40 0
-10 -1 0 68 40 0
-9 -1 0 68 40 0
-8 -1 0 68 40 0
-7 -1 0 68 40 0
-6 -1 0 32 92 32
-5 -1 0 44 48 0
-4 -1 0 44 48 0
-3 -1 0 68 40 0
-2 -1 0 68 40 0
-1 -1 0 68 40 0
0 -1 0 68 40 0
1 -1 0 44 48 0
2 -1 0 44 48 0
3 -1 0 44 48 0
4 -1 0 44 48 0
5 -1 0 32 92 32
6 -1 0 68 40 0
7 -1 0 68 40 0
8 -1 0 68 40 0
9 -1 0 68 40 0
10 -1 0 68 40 0
11 -1 0 68 40 0
12 -1 0 108 108 108
13 -1 0 108 108 108
14 -1 0 144 144 144
-15 0 0 144 144 144
-14 0 0 108 108 108
-13 0 0 108 108 108
-12 0 0 68 40 0
-11 0 0 68 40 0
-10 0 0 68 40 0
-9 0 0 68 40 0
-8 0 0 68 40 0
-7 0 0 68 40 0
-6 0 0 32 92 32
-5 0 0 68 40 0
-4 0 0 68 40 0
-3 0 0 68 40 0
-2 0 0 68 40 0
-1 0 0 68 40 0
0 0 0 68 40 0
1 0 0 44 48 0
2 0 0 44 48 0
3 0 0 44 48 0
4 0 0 44 48 0
5 0 0 32 92 32
6 0 0 68 40 0
7 0 0 68 40 0
8 0 0 68 40 0
9 0 0 68 40 0
10 0 0 68 40 0
11 0 0 68 40 0
12 0 0 108 108 108
13 0 0 108 108 108
14 0 0 144 144 144
-15 1 0 144 144 144
-14 1 0 108 108 108
-13 1 0 108 108 108
-12 1 0 68 40 0
-11 1 0 68 40 0
-10 1 0 68 40 0
-9 1 0 68 40 0
-8 1 0 68 40 0
-7 1 0 44 48 0
-6 1 0 32 92 32
-5 1 0 68 40 0
-4 1 0 68 40 0
-3 1 0 68 40 0
-2 1 0 68 40 0
-1 1 0 68 40 0
0 1 0 68 40 0
1 1 0 44 48 0
2 1 0 44 48 0
3 1 0 44 48 0
4 1 0 44 48 0
5 1 0 32 92 32
6 1 0 44 48 0
7 1 0 68 40 0
8 1 0 68 40 0
9 1 0 68 40 0
10 1 0 68 40 0
11 1 0 68 40 0
12 1 0 108 108 108
13 1 0 108 108 108
14 1 0 144 144 144
-15 2 0 144 144 144
-14 2 0 108 108 108
-13 2 0 108 108 108
-12 2 0 68 40 0
-11 2 0 68 40 0
-10 2 0 68 40 0
-9 2 0 68 40 0
-8 2 0 68 40 0
-7 2 0 44 48 0
-6 2 0 32 92 32
-5 2 0 68 40 0
-4 2 0 32 92 32
-3 2 0 32 92 32
-2 2 0 68 40 0
-1 2 0 32 92 32
0 2 0 32 92 32
1 2 0 44 48 0
2 2 0 32 92 32
3 2 0 32 92 32
4 2 0 44 48 0
5 2 0 32 92 32
6 2 0 44 48 0
7 2 0 68 40 0
8 2 0 68 40 0
9 2 0 68 40 0
10 2 0 68 40 0
11 2 0 68 40 0
12 2 0 108 108 108
13 2 0 108 108 108
14 2 0 144 144 144
-15 3 0 144 144 144
-14 3 0 108 108 108
-13 3 0 108 108 108
-12 3 0 68 40 0
-11 3 0 68 40 0
-10 3 0 68 40 0
-9 3 0 68 40 0
-8 3 0 68 40 0
-7 3 0 44 48 0
-6 3 0 32 92 32
-5 3 0 68 40 0
-4 3 0 32 92 32
-3 3 0 32 92 32
-2 3 0 68 40 0
-1 3 0 32 92 32
0 3 0 32 92 32
1 3 0 68 40 0
2 3 0 32 92 32
3 3 0 32 92 32
4 3 0 44 48 0
5 3 0 32 92 32
6 3 0 44 48 0
7 3 0 68 40 0
8 3 0 68 40 0
9 3 0 68 40 0
10 3 0 68 40 0
11 3 0 68 40 0
12 3 0 108 108 108
13 3 0 108 108 108
14 3 0 144 144 144
-15 4 0 144 144 144
-14 4 0 108 108 108
-13 4 0 108 108 108
-12 4 0 68 40 0
-11 4 0 68 40 0
-10 4 0 68 40 0
-9 4 0 68 40 0
-8 4 0 44 48 0
-7 4 0 44 48 0
-6 4 0 32 92 32
-5 4 0 68 40 0
-4 4 0 68 40 0
-3 4 0 68 40 0
-2 4 0 68 40 0
-1 4 0 68 40 0
0 4 0 68 40 0
1 4 0 68 40 0
2 4 0 68 40 0
3 4 0 68 40 0
4 4 0 44 48 0
5 4 0 32 92 32
6 4 0 44 48 0
7 4 0 68 40 0
8 4 0 68 40 0
9 4 0 68 40 0
10 4 0 68 40 0
11 4 0 68 40 0
12 4 0 108 108 108
13 4 0 108 108 108
14 4 0 144 144 144
-15 5 0 144 144 144
-14 5 0 108 108 108
-13 5 0 108 108 108
-12 5 0 68 40 0
-11 5 0 68 40 0
-10 5 0 68 40 0
-9 5 0 68 40 0
-8 5 0 44 48 0
-7 5 0 44 48 0
-6 5 0 32 92 32
-5 5 0 32 92 32
-4 5 0 32 92 32
-3 5 0 32 92 32
-2 5 0 32 92 32
-1 5 0 32 92 32
0 5 0 32 92 32
1 5 0 32 92 32
2 5 0 32 92 32
3 5 0 32 92 32
4 5 0 32 92 32
5 5 0 32 92 32
6 5 0 68 40 0
7 5 0 68 40 0
8 5 0 68 40 0
9 5 0 68 40 0
10 5 0 68 40 0
11 5 0 68 40 0
12 5 0 108 108 108
13 5 0 108 108 108
14 5 0 144 144 144
-15 6 0 144 144 144
-14 6 0 108 108 108
-13 6 0 108 108 108
-12 6 0 68 40 0
-11 6 0 68 40 0
-10 6 0 44 48 0
-9 6 0 44 48 0
-8 6 0 44 48 0
-7 6 0 44 48 0
-6 6 0 68 40 0
-5 6 0 68 40 0
-4 6 0 68 40 0
-3 6 0 68 40 0
-2 6 0 68 40 0
-1 6 0 44 48 0
0 6 0 44 48 0
1 6 0 44 48 0
2 6 0 44 48 0
3 6 0 68 40 0
4 6 0 68 40 0
5 6 0 68 40 0
6 6 0 68 40 0
7 6 0 68 40 0
8 6 0 44 48 0
9 6 0 44 48 0
10 6 0 68 40 0
11 6 0 68 40 0
12 6 0 108 108 108
13 6 0 108 108 108
14 6 0 144 144 144
-15 7 0 144 144 144
-14 7 0 108 108 108
-13 7 0 108 108 108
-12 7 0 68 40 0
-11 7 0 68 40 0
-10 7 0 44 48 0
-9 7 0 44 48 0
-8 7 0 44 48 0
-7 7 0 44 48 0
-6 7 0 44 48 0
-5 7 0 44 48 0
-4 7 0 68 40 0
-3 7 0 68 40 0
-2 7 0 44 48 0
-1 7 0 44 48 0
0 7 0 44 48 0
1 7 0 44 48 0
2 7 0 44 48 0
3 7 0 68 40 0
4 7 0 68 40 0
5 7 0 68 40 0
6 7 0 68 40 0
7 7 0 44 48 0
8 7 0 44 48 0
9 7 0 44 48 0
10 7 0 68 40 0
11 7 0 68 40 0
12 7 0 108 108 108
13 7 0 108 108 108
14 7 0 144 144 144
-15 8 0 144 144 144
-14 8 0 108 108 108
-13 8 0 108 108 108
-12 8 0 68 40 0
-11 8 0 68 40 0
-10 8 0 44 48 0
-9 8 0 44 48 0
-8 8 0 44 48 0
-7 8 0 44 48 0
-6 8 0 44 48 0
-5 8 0 44 48 0
-4 8 0 68 40 0
-3 8 0 68 40 0
-2 8 0 68 40 0
-1 8 0 44 48 0
0 8 0 44 48 0
1 8 0 68 40 0
2 8 0 68 40 0
3 8 0 68 40 0
4 8 0 68 40 0
5 8 0 68 40 0
6 8 0 68 40 0
7 8 0 44 48 0
8 8 0 44 48 0
9 8 0 44 48 0
10 8 0 68 40 0
11 8 0 68 40 0
12 8 0 108 108 108
13 8 0 108 108 108
14 8 0 144 144 144
-15 9 0 144 144 144
-14 9 0 108 108 108
-13 9 0 108 108 108
-12 9 0 68 40 0
-11 9 0 68 40 0
-10 9 0 68 40 0
-9 9 0 68 40 0
-8 9 0 68 40 0
-7 9 0 44 48 0
-6 9 0 44 48 0
-5 9 0 44 48 0
-4 9 0 68 40 0
-3 9 0 68 40 0
-2 9 0 68 40 0
-1 9 0 44 48 0
0 9 0 68 40 0
1 9 0 68 40 0
2 9 0 68 40 0
3 9 0 68 40 0
4 9 0 68 40 0
5 9 0 68 40 0
6 9 0 68 40 0
7 9 0 68 40 0
8 9 0 68 40 0
9 9 0 68 40 0
10 9 0 68 40 0
11 9 0 68 40 0
12 9 0 108 108 108
13 9 0 108 108 108
14 9 0 144 144 144
-15 10 0 144 144 144
-14 10 0 108 108 108
-13 10 0 108 108 108
-12 10 0 68 40 0
-11 10 0 68 40 0
-10 10 0 68 40 0
-9 10 0 68 40 0
-8 10 0 68 40 0
-7 10 0 68 40 0
-6 10 0 68 40 0
-5 10 0 68 40 0
-4 10 0 68 40 0
-3 10 0 68 40 0
-2 10 0 68 40 0
-1 10 0 68 40 0
0 10 0 68 40 0
1 10 0 68 40 0
2 10 0 68 40 0
3 10 0 68 40 0
4 10 0 68 40 0
5 10 0 68 40 0
6 10 0 68 40 0
7 10 0 68 40 0
8 10 0 68 40 0
9 10 0 68 40 0
10 10 0 68 40 0
11 10 0 68 40 0
12 10 0 108 108 108
13 10 0 108 108 108
14 10 0 144 144 144
-15 11 0 144 144 144
-14 11 0 108 108 108
-13 11 0 108 108 108
-12 11 0 68 40 0
-11 11 0 68 40 0
-10 11 0 68 40 0
-9 11 0 68 40 0
-8 11 0 68 40 0
-7 11 0 68 40 0
-6 11 0 68 40 0
-5 11 0 68 40 0
-4 11 0 68 40 0
-3 11 0 68 40 0
-2 11 0 68 40 0
-1 11 0 68 40 0
0 11 0 68 40 0
1 11 0 68 40 0
2 11 0 68 40 0
3 11 0 68 40 0
4 11 0 68 40 0
5 11 0 68 40 0
6 11 0 68 40 0
7 11 0 68 40 0
8 11 0 68 40 0
9 11 0 68 40 0
10 11 0 68 40 0
11 11 0 68 40 0
12 11 0 108 108 108
13 11 0 108 108 108
14 11 0 144 144 144
-15 12 0 144 144 144
-14 12 0 108 108 108
-13 12 0 108 108 108
-12 12 0 108 108 108
-11 12 0 108 108 108
-10 12 0 108 108 108
-9 12 0 108 108 108
-8 12 0 108 108 108
-7 12 0 108 108 108
-6 12 0 108 108 108
-5 12 0 108 108 108
-4 12 0 108 108 108
-3 12 0 108 108 108
-2 12 0 108 108 108
-1 12 0 108 108 108
0 12 0 108 108 108
1 12 0 108 108 108
2 12 0 108 108 108
3 12 0 108 108 108
4 12 0 108 108 108
5 12 0 108 108 108
6 12 0 108 108 108
7 12 0 108 108 108
8 12 0 108 108 108
9 12 0 108 108 108
10 12 0 108 108 108
11 12 0 108 108 108
12 12 0 108 108 108
13 12 0 108 108 108
14 12 0 144 144 144
-15 13 0 144 144 144
-14 13 0 108 108 108
-13 13 0 108 108 108
-12 13 0 108 108 108
-11 13 0 108 108 108
-10 13 0 108 108 108
-9 13 0 108 108 108
-8 13 0 108 108 108
-7 13 0 108 108 108
-6 13 0 108 108 108
-5 13 0 108 108 108
-4 13 0 108 108 108
-3 13 0 108 108 108
-2 13 0 108 108 108
-1 13 0 108 108 108
0 13 0 108 108 108
1 13 0 108 108 108
2 13 0 108 108 108
3 13 0 108 108 108
4 13 0 108 108 108
5 13 0 108 108 108
6 13 0 108 108 108
7 13 0 108 108 108
8 13 0 108 108 108
9 13 0 108 108 108
10 13 0 108 108 108
11 13 0 108 108 108
12 13 0 108 108 108
13 13 0 108 108 108
14 13 0 144 144 144
-15 14 0 144 144 144
-14 14 0 144 144 144
-13 14 0 144 144 144
-12 14 0 144 144 144
-11 14 0 144 144 144
-10 14 0 144 144 144
-9 14 0 144 144 144
-8 14 0 144 144 144
-7 14 0 144 144 144
-6 14 0 144 144 144
-5 14 0 144 144 144
-4 14 0 144 144 144
-3 14 0 144 144 144
-2 14 0 144 144 144
-1 14 0 144 144 144
0 14 0 144 144 144
1 14 0 144 144 144
2 14 0 144 144 144
3 14 0 144 144 144
4 14 0 144 144 144
5 14 0 144 144 144
6 14 0 144 144 144
7 14 0 144 144 144
8 14 0 144 144 144
9 14 0 144 144 144
10 14 0 144 144 144
11 14 0 144 144 144
12 14 0 144 144 144
13 14 0 144 144 144
14 14 0 144 144 144
-15 -15 1 144 144 144
-14 -15 1 144 144 144
-13 -15 1 144 144 144
-12 -15 1 144 144 144
-11 -15 1 144 144 144
-10 -15 1 144 144 144
-9 -15 1 144 144 144
-8 -15 1 144 144 144
-7 -15 1 144 144 144
-6 -15 1 144 144 144
-5 -15 1 144 144 144
-4 -15 1 144 144 144
-3 -15 1 144 144 144
-2 -15 1 144 144 144
-1 -15 1 144 144 144
0 -15 1 144 144 144
1 -15 1 144 144 144
2 -15 1 144 144 144
3 -15 1 144 144 144
4 -15 1 144 144 144
5 -15 1 144 144 144
6 -15 1 144 144 144
7 -15 1 144 144 144
8 -15 1 144 144 144
9 -15 1 144 144 144
10 -15 1 144 144 144
11 -15 1 144 144 144
12 -15 1 144 144 144
13 -15 1 144 144 144
14 -15 1 144 144 144
-15 -14 1 144 144 144
-14 -14 1 108 108 108
-13 -14 1 108 108 108
-12 -14 1 108 108 108
-11 -14 1 108 108 108
-10 -14 1 108 108 108
-9 -14 1 108 108 108
-8 -14 1 108 108 108
-7 -14 1 108 108 108
-6 -14 1 108 108 108
-5 -14 1 108 108 108
-4 -14 1 108 108 108
-3 -14 1 108 108 108
-2 -14 1 108 108 108
-1 -14 1 108 108 108
0 -14 1 108 108 108
1 -14 1 108 108 108
2 -14 1 108 108 108
3 -14 1 108 108 108
4 -14 1 108 108 108
5 -14 1 108 108 108
6 -14 1 108 108 108
7 -14 1 108 108 108
8 -14 1 108 108 108
9 -14 1 108 108 108
10 -14 1 108 108 108
11 -14 1 108 108 108
12 -14 1 108 108 108
13 -14 1 108 108 108
14 -14 1 144 144 144
-15 -13 1 144 144 144
-14 -13 1 108 108 108
-13 -13 1 108 108 108
-12 -13 1 52 92 28
-11 -13 1 52 92 28
-10 -13 1 52 92 28
-9 -13 1 52 92 28
-8 -13 1 52 92 28
-7 -13 1 52 92 28
-6 -13 1 52 92 28
-5 -13 1 52 92 28
-4 -13 1 52 92 28
-3 -13 1 52 92 28
-2 -13 1 52 92 28
-1 -13 1 52 92 28
0 -13 1 52 92 28
1 -13 1 52 92 28
2 -13 1 52 92 28
3 -13 1 108 108 108
4 -13 1 108 108 108
5 -13 1 108 108 108
6 -13 1 108 108 108
7 -13 1 108 108 108
8 -13 1 108 108 108
9 -13 1 108 108 108
10 -13 1 108 108 108
11 -13 1 108 108 108
12 -13 1 108 108 108
13 -13 1 108 108 108
14 -13 1 144 144 144
-15 -12 1 144 144 144
-14 -12 1 108 108 108
-13 -12 1 108 108 108
-12 -12 1 52 92 28
-11 -12 1 52 92 28
-10 -12 1 52 92 28
-9 -12 1 52 92 28
-8 -12 1 52 92 28
-7 -12 1 52 92 28
-6 -12 1 52 92 28
-5 -12 1 52 92 28
-4 -12 1 52 92 28
-3 -12 1 52 92 28
-2 -12 1 52 92 28
-1 -12 1 52 92 28
0 -12 1 52 92 28
12 -12 1 108 108 108
13 -12 1 108 108 108
14 -12 1 144 144 144
-15 -11 1 144 144 144
-14 -11 1 108 108 108
-13 -11 1 108 108 108
-12 -11 1 52 92 28
-11 -11 1 52 92 28
-10 -11 1 52 92 28
-9 -11 1 52 92 28
-8 -11 1 52 92 28
-7 -11 1 52 92 28
-6 -11 1 52 92 28
12 -11 1 108 108 108
13 -11 1 108 108 108
14 -11 1 144 144 144
-15 -10 1 144 144 144
-14 -10 1 108 108 108
-13 -10 1 108 108 108
-12 -10 1 52 92 28
-11 -10 1 52 92 28
-10 -10 1 52 92 28
-9 -10 1 52 92 28
-8 -10 1 52 92 28
-7 -10 1 52 92 28
12 -10 1 52 92 28
13 -10 1 108 108 108
14 -10 1 144 144 144
-15 -9 1 144 144 144
-14 -9 1 108 108 108
-13 -9 1 108 108 108
-12 -9 1 52 92 28
-11 -9 1 52 92 28
-10 -9 1 52 92 28
-9 -9 1 52 92 28
-8 -9 1 52 92 28
-7 -9 1 52 92 28
12 -9 1 52 92 28
13 -9 1 108 108 108
14 -9 1 144 144 144
-15 -8 1 144 144 144
-14 -8 1 108 108 108
-13 -8 1 108 108 108
-12 -8 1 52 92 28
-11 -8 1 52 92 28
11 -8 1 52 92 28
12 -8 1 52 92 28
13 -8 1 108 108 108
14 -8 1 144 144 144
-15 -7 1 144 144 144
-14 -7 1 108 108 108
-13 -7 1 108 108 108
-12 -7 1 52 92 28
-11 -7 1 52 92 28
11 -7 1 52 92 28
12 -7 1 52 92 28
13 -7 1 108 108 108
14 -7 1 144 144 144
-15 -6 1 144 144 144
-14 -6 1 108 108 108
-13 -6 1 108 108 108
-12 -6 1 52 92 28
-11 -6 1 52 92 28
10 -6 1 52 92 28
11 -6 1 52 92 28
12 -6 1 52 92 28
13 -6 1 108 108 108
14 -6 1 144 144 144
-15 -5 1 144 144 144
-14 -5 1 108 108 108
-13 -5 1 108 108 108
10 -5 1 52 92 28
11 -5 1 52 92 28
12 -5 1 52 92 28
13 -5 1 108 108 108
14 -5 1 144 144 144
-15 -4 1 144 144 144
-14 -4 1 108 108 108
-13 -4 1 108 108 108
-12 -4 1 108 108 108
-11 -4 1 108 108 108
-10 -4 1 108 108 108
10 -4 1 52 92 28
11 -4 1 52 92 28
12 -4 1 52 92 28
13 -4 1 108 108 108
14 -4 1 144 144 144
-15 -3 1 144 144 144
-14 -3 1 108 108 108
-13 -3 1 108 108 108
-12 -3 1 108 108 108
-11 -3 1 108 108 108
-10 -3 1 108 108 108
10 -3 1 52 92 28
11 -3 1 52 92 28
12 -3 1 52 92 28
13 -3 1 108 108 108
14 -3 1 144 144 144
-15 -2 1 144 144 144
-14 -2 1 108 108 108
-13 -2 1 108 108 108
-12 -2 1 108 108 108
-11 -2 1 108 108 108
-10 -2 1 108 108 108
10 -2 1 52 92 28
11 -2 1 52 92 28
12 -2 1 52 92 28
13 -2 1 108 108 108
14 -2 1 144 144 144
-15 -1 1 144 144 144
-14 -1 1 108 108 108
-13 -1 1 108 108 108
-12 -1 1 108 108 108
-11 -1 1 108 108 108
-10 -1 1 108 108 108
10 -1 1 52 92 28
11 -1 1 52 92 28
12 -1 1 52 92 28
13 -1 1 108 108 108
14 -1 1 144 144 144
-15 0 1 144 144 144
-14 0 1 108 108 108
-13 0 1 108 108 108
-12 0 1 108 108 108
-11 0 1 108 108 108
-10 0 1 108 108 108
10 0 1 52 92 28
11 0 1 52 92 28
12 0 1 52 92 28
13 0 1 108 108 108
14 0 1 144 144 144
-15 1 1 144 144 144
-14 1 1 108 108 108
-13 1 1 108 108 108
-12 1 1 108 108 108
-11 1 1 108 108 108
-10 1 1 108 108 108
10 1 1 52 92 28
11 1 1 52 92 28
12 1 1 52 92 28
13 1 1 108 108 108
14 1 1 144 144 144
-15 2 1 144 144 144
-14 2 1 108 108 108
-13 2 1 108 108 108
-12 2 1 108 108 108
-11 2 1 108 108 108
-10 2 1 108 108 108
10 2 1 52 92 28
11 2 1 52 92 28
12 2 1 52 92 28
13 2 1 108 108 108
14 2 1 144 144 144
-15 3 1 144 144 144
-14 3 1 108 108 108
-13 3 1 108 108 108
-12 3 1 108 108 108
-11 3 1 108 108 108
-10 3 1 108 108 108
10 3 1 52 92 28
11 3 1 52 92 28
12 3 1 52 92 28
13 3 1 108 108 108
14 3 1 144 144 144
-15 4 1 144 144 144
-14 4 1 108 108 108
-13 4 1 108 108 108
10 4 1 52 92 28
11 4 1 52 92 28
12 4 1 52 92 28
13 4 1 108 108 108
14 4 1 144 144 144
-15 5 1 144 144 144
-14 5 1 108 108 108
-13 5 1 108 108 108
-12 5 1 52 92 28
9 5 1 52 92 28
10 5 1 52 92 28
11 5 1 52 92 28
12 5 1 52 92 28
13 5 1 108 108 108
14 5 1 144 144 144
-15 6 1 144 144 144
-14 6 1 108 108 108
-13 6 1 108 108 108
-12 6 1 52 92 28
9 6 1 52 92 28
10 6 1 52 92 28
11 6 1 52 92 28
12 6 1 52 92 28
13 6 1 108 108 108
14 6 1 144 144 144
-15 7 1 144 144 144
-14 7 1 108 108 108
-13 7 1 108 108 108
-12 7 1 52 92 28
-11 7 1 52 92 28
9 7 1 52 92 28
10 7 1 52 92 28
11 7 1 52 92 28
12 7 1 52 92 28
13 7 1 108 108 108
14 7 1 144 144 144
-15 8 1 144 144 144
-14 8 1 108 108 108
-13 8 1 108 108 108
-12 8 1 52 92 28
-11 8 1 52 92 28
9 8 1 52 92 28
10 8 1 52 92 28
11 8 1 52 92 28
12 8 1 52 92 28
13 8 1 108 108 108
14 8 1 144 144 144
-15 9 1 144 144 144
-14 9 1 108 108 108
-13 9 1 108 108 108
-12 9 1 52 92 28
-11 9 1 52 92 28
-10 9 1 52 92 28
-9 9 1 52 92 28
-8 9 1 52 92 28
5 9 1 52 92 28
6 9 1 52 92 28
7 9 1 52 92 28
8 9 1 52 92 28
9 9 1 52 92 28
10 9 1 52 92 28
11 9 1 52 92 28
12 9 1 52 92 28
13 9 1 108 108 108
14 9 1 144 144 144
-15 10 1 144 144 144
-14 10 1 108 108 108
-13 10 1 108 108 108
-12 10 1 52 92 28
-11 10 1 52 92 28
-10 10 1 52 92 28
-9 10 1 52 92 28
-8 10 1 52 92 28
-7 10 1 52 92 28
4 10 1 52 92 28
5 10 1 52 92 28
6 10 1 52 92 28
7 10 1 52 92 28
8 10 1 52 92 28
9 10 1 52 92 28
10 10 1 52 92 28
11 10 1 52 92 28
12 10 1 52 92 28
13 10 1 108 108 108
14 10 1 144 144 144
-15 11 1 144 144 144
-14 11 1 108 108 108
-13 11 1 108 108 108
-12 11 1 52 92 28
-11 11 1 52 92 28
-10 11 1 52 92 28
-9 11 1 52 92 28
-8 11 1 52 92 28
-7 11 1 52 92 28
-6 11 1 52 92 28
-5 11 1 52 92 28
-4 11 1 52 92 28
-3 11 1 52 92 28
-2 11 1 52 92 28
2 11 1 52 92 28
3 11 1 52 92 28
4 11 1 52 92 28
5 11 1 52 92 28
6 11 1 52 92 28
7 11 1 52 92 28
8 11 1 52 92 28
9 11 1 52 92 28
10 11 1 52 92 28
11 11 1 52 92 28
12 11 1 52 92 28
13 11 1 108 108 108
14 11 1 144 144 144
-15 12 1 144 144 144
-14 12 1 108 108 108
-13 12 1 108 108 108
-12 12 1 52 92 28
-11 12 1 52 92 28
-10 12 1 52 92 28
-9 12 1 52 92 28
-8 12 1 52 92 28
-7 12 1 52 92 28
-6 12 1 52 92 28
-5 12 1 52 92 28
-4 12 1 52 92 28
-3 12 1 52 92 28
-2 12 1 52 92 28
-1 12 1 52 92 28
0 12 1 52 92 28
1 12 1 52 92 28
2 12 1 52 92 28
3 12 1 52 92 28
4 12 1 52 92 28
5 12 1 52 92 28
6 12 1 52 92 28
7 12 1 52 92 28
8 12 1 52 92 28
9 12 1 52 92 28
10 12 1 52 92 28
11 12 1 52 92 28
12 12 1 52 92 28
13 12 1 108 108 108
14 12 1 144 144 144
-15 13 1 144 144 144
-14 13 1 108 108 108
-13 13 1 108 108 108
-12 13 1 108 108 108
-11 13 1 108 108 108
-10 13 1 108 108 108
-9 13 1 108 108 108
-8 13 1 108 108 108
-7 13 1 108 108 108
-6 13 1 108 108 108
-5 13 1 108 108 108
-4 13 1 108 108 108
-3 13 1 108 108 108
-2 13 1 108 108 108
-1 13 1 108 108 108
0 13 1 108 108 108
1 13 1 108 108 108
2 13 1 108 108 108
3 13 1 108 108 108
4 13 1 108 108 108
5 13 1 108 108 108
6 13 1 108 108 108
7 13 1 108 108 108
8 13 1 108 108 108
9 13 1 108 108 108
10 13 1 108 108 108
11 13 1 108 108 108
12 13 1 108 108 108
13 13 1 108 108 108
14 13 1 144 144 144
-15 14 1 144 144 144
-14 14 1 144 144 144
-13 14 1 144 144 144
-12 14 1 144 144 144
-11 14 1 144 144 144
-10 14 1 144 144 144
-9 14 1 144 144 144
-8 14 1 144 144 144
-7 14 1 144 144 144
-6 14 1 144 144 144
-5 14 1 144 144 144
-4 14 1 144 144 144
-3 14 1 144 144 144
-2 14 1 144 144 144
-1 14 1 144 144 144
0 14 1 144 144 144
1 14 1 144 144 144
2 14 1 144 144 144
3 14 1 144 144 144
4 14 1 144 144 144
5 14 1 144 144 144
6 14 1 144 144 144
7 14 1 144 144 144
8 14 1 144 144 144
9 14 1 144 144 144
10 14 1 144 144 144
11 14 1 144 144 144
12 14 1 144 144 144
13 14 1 144 144 144
14 14 1 144 144 144
-15 -15 2 144 144 144
-14 -15 2 144 144 144
-13 -15 2 144 144 144
-12 -15 2 144 144 144
-11 -15 2 144 144 144
-10 -15 2 144 144 144
-9 -15 2 144 144 144
-8 -15 2 144 144 144
-7 -15 2 144 144 144
-6 -15 2 144 144 144
-5 -15 2 144 144 144
-4 -15 2 144 144 144
-3 -15 2 144 144 144
-2 -15 2 144 144 144
-1 -15 2 144 144 144
0 -15 2 144 144 144
1 -15 2 144 144 144
2 -15 2 144 144 144
3 -15 2 144 144 144
4 -15 2 144 144 144
5 -15 2 144 144 144
6 -15 2 144 144 144
7 -15 2 144 144 144
8 -15 2 144 144 144
9 -15 2 144 144 144
10 -15 2 144 144 144
11 -15 2 144 144 144
12 -15 2 144 144 144
13 -15 2 144 144 144
14 -15 2 144 144 144
-15 -14 2 144 144 144
-14 -14 2 108 108 108
-13 -14 2 108 108 108
-12 -14 2 108 108 108
-11 -14 2 108 108 108
-10 -14 2 108 108 108
-9 -14 2 108 108 108
-8 -14 2 108 108 108
-7 -14 2 108 108 108
-6 -14 2 108 108 108
-5 -14 2 108 108 108
-4 -14 2 108 108 108
-3 -14 2 108 108 108
-2 -14 2 108 108 108
-1 -14 2 108 108 108
0 -14 2 108 108 108
1 -14 2 108 108 108
2 -14 2 108 108 108
3 -14 2 108 108 108
4 -14 2 108 108 108
5 -14 2 108 108 108
6 -14 2 108 108 108
7 -14 2 108 108 108
8 -14 2 108 108 108
9 -14 2 108 108 108
10 -14 2 108 108 108
11 -14 2 108 108 108
12 -14 2 108 108 108
13 -14 2 108 108 108
14 -14 2 144 144 144
-15 -13 2 144 144 144
-14 -13 2 108 108 108
-13 -13 2 108 108 108
-12 -13 2 52 92 28
-11 -13 2 52 92 28
-10 -13 2 52 92 28
-9 -13 2 52 92 28
-8 -13 2 52 92 28
-7 -13 2 52 92 28
-6 -13 2 52 92 28
-5 -13 2 52 92 28
-4 -13 2 52 92 28
-3 -13 2 52 92 28
-2 -13 2 52 92 28
-1 -13 2 52 92 28
0 -13 2 52 92 28
1 -13 2 52 92 28
2 -13 2 52 92 28
3 -13 2 52 92 28
4 -13 2 108 108 108
5 -13 2 108 108 108
6 -13 2 108 108 108
7 -13 2 108 108 108
8 -13 2 108 108 108
9 -13 2 108 108 108
10 -13 2 108 108 108
11 -13 2 108 108 108
12 -13 2 108 108 108
13 -13 2 108 108 108
14 -13 2 144 144 144
-15 -12 2 144 144 144
-14 -12 2 108 108 108
-13 -12 2 108 108 108
-12 -12 2 52 92 28
-11 -12 2 52 92 28
-10 -12 2 52 92 28
-9 -12 2 52 92 28
-8 -12 2 52 92 28
-7 -12 2 52 92 28
-6 -12 2 52 92 28
-5 -12 2 52 92 28
-4 -12 2 52 92 28
1 -12 2 52 92 28
2 -12 2 52 92 28
12 -12 2 108 108 108
13 -12 2 108 108 108
14 -12 2 144 144 144
-15 -11 2 144 144 144
-14 -11 2 108 108 108
-13 -11 2 108 108 108
-12 -11 2 52 92 28
-11 -11 2 52 92 28
-10 -11 2 52 92 28
-9 -11 2 52 92 28
12 -11 2 108 108 108
13 -11 2 108 108 108
14 -11 2 144 144 144
-15 -10 2 144 144 144
-14 -10 2 108 108 108
-13 -10 2 108 108 108
-12 -10 2 52 92 28
-11 -10 2 52 92 28
12 -10 2 108 108 108
13 -10 2 108 108 108
14 -10 2 144 144 144
-15 -9 2 144 144 144
-14 -9 2 108 108 108
-13 -9 2 108 108 108
-12 -9 2 52 92 28
12 -9 2 108 108 108
13 -9 2 108 108 108
14 -9 2 144 144 144
-15 -8 2 144 144 144
-14 -8 2 108 108 108
-13 -8 2 108 108 108
12 -8 2 108 108 108
13 -8 2 108 108 108
14 -8 2 144 144 144
-15 -7 2 144 144 144
-14 -7 2 108 108 108
-13 -7 2 108 108 108
12 -7 2 108 108 108
13 -7 2 108 108 108
14 -7 2 144 144 144
-15 -6 2 144 144 144
-14 -6 2 108 108 108
-13 -6 2 108 108 108
12 -6 2 52 92 28
13 -6 2 108 108 108
14 -6 2 144 144 144
-15 -5 2 144 144 144
-14 -5 2 108 108 108
-13 -5 2 108 108 108
12 -5 2 52 92 28
13 -5 2 108 108 108
14 -5 2 144 144 144
-15 -4 2 144 144 144
-14 -4 2 108 108 108
-13 -4 2 108 108 108
-12 -4 2 108 108 108
-11 -4 2 108 108 108
-10 -4 2 108 108 108
12 -4 2 52 92 28
13 -4 2 108 108 108
14 -4 2 144 144 144
-15 -3 2 144 144 144
-14 -3 2 108 108 108
-13 -3 2 108 108 108
-12 -3 2 108 108 108
-11 -3 2 108 108 108
11 -3 2 52 92 28
12 -3 2 52 92 28
13 -3 2 108 108 108
14 -3 2 144 144 144
-15 -2 2 144 144 144
-14 -2 2 108 108 108
-13 -2 2 108 108 108
-12 -2 2 108 108 108
-11 -2 2 108 108 108
11 -2 2 52 92 28
12 -2 2 52 92 28
13 -2 2 108 108 108
14 -2 2 144 144 144
-15 -1 2 144 144 144
-14 -1 2 108 108 108
-13 -1 2 108 108 108
-12 -1 2 108 108 108
-11 -1 2 108 108 108
10 -1 2 52 92 28
11 -1 2 52 92 28
12 -1 2 52 92 28
13 -1 2 108 108 108
14 -1 2 144 144 144
-15 0 2 144 144 144
-14 0 2 108 108 108
-13 0 2 108 108 108
-12 0 2 108 108 108
-11 0 2 108 108 108
10 0 2 52 92 28
11 0 2 52 92 28
12 0 2 52 92 28
13 0 2 108 108 108
14 0 2 144 144 144
-15 1 2 144 144 144
-14 1 2 108 108 108
-13 1 2 108 108 108
-12 1 2 108 108 108
-11 1 2 108 108 108
10 1 2 52 92 28
11 1 2 52 92 28
12 1 2 52 92 28
13 1 2 108 108 108
14 1 2 144 144 144
-15 2 2 144 144 144
-14 2 2 108 108 108
-13 2 2 108 108 108
-12 2 2 108 108 108
-11 2 2 108 108 108
11 2 2 52 92 28
12 2 2 52 92 28
13 2 2 108 108 108
14 2 2 144 144 144
-15 3 2 144 144 144
-14 3 2 108 108 108
-13 3 2 108 108 108
-12 3 2 108 108 108
-11 3 2 108 108 108
-10 3 2 108 108 108
11 3 2 52 92 28
12 3 2 52 92 28
13 3 2 108 108 108
14 3 2 144 144 144
-15 4 2 144 144 144
-14 4 2 108 108 108
-13 4 2 108 108 108
11 4 2 52 92 28
12 4 2 52 92 28
13 4 2 108 108 108
14 4 2 144 144 144
-15 5 2 144 144 144
-14 5 2 108 108 108
-13 5 2 108 108 108
10 5 2 52 92 28
11 5 2 52 92 28
12 5 2 52 92 28
13 5 2 108 108 108
14 5 2 144 144 144
-15 6 2 144 144 144
-14 6 2 108 108 108
-13 6 2 108 108 108
10 6 2 52 92 28
11 6 2 52 92 28
12 6 2 52 92 28
13 6 2 108 108 108
14 6 2 144 144 144
-15 7 2 144 144 144
-14 7 2 108 108 108
-13 7 2 108 108 108
10 7 2 52 92 28
11 7 2 52 92 28
12 7 2 52 92 28
13 7 2 108 108 108
14 7 2 144 144 144
-15 8 2 144 144 144
-14 8 2 108 108 108
-13 8 2 108 108 108
-12 8 2 52 92 28
10 8 2 52 92 28
11 8 2 52 92 28
12 8 2 52 92 28
13 8 2 108 108 108
14 8 2 144 144 144
-15 9 2 144 144 144
-14 9 2 108 108 108
-13 9 2 108 108 108
-12 9 2 52 92 28
9 9 2 52 92 28
10 9 2 52 92 28
11 9 2 52 92 28
12 9 2 52 92 28
13 9 2 108 108 108
14 9 2 144 144 144
-15 10 2 144 144 144
-14 10 2 108 108 108
-13 10 2 108 108 108
-12 10 2 52 92 28
-11 10 2 52 92 28
-10 10 2 52 92 28
7 10 2 52 92 28
8 10 2 52 92 28
9 10 2 52 92 28
10 10 2 52 92 28
11 10 2 52 92 28
12 10 2 52 92 28
13 10 2 108 108 108
14 10 2 144 144 144
-15 11 2 144 144 144
-14 11 2 108 108 108
-13 11 2 108 108 108
-12 11 2 52 92 28
-11 11 2 52 92 28
-10 11 2 52 92 28
-9 11 2 52 92 28
-8 11 2 52 92 28
-7 11 2 52 92 28
-6 11 2 52 92 28
4 11 2 52 92 28
5 11 2 52 92 28
6 11 2 52 92 28
7 11 2 52 92 28
8 11 2 52 92 28
9 11 2 52 92 28
10 11 2 52 92 28
11 11 2 52 92 28
12 11 2 52 92 28
13 11 2 108 108 108
14 11 2 144 144 144
-15 12 2 144 144 144
-14 12 2 108 108 108
-13 12 2 108 108 108
-12 12 2 52 92 28
-11 12 2 52 92 28
-10 12 2 52 92 28
-9 12 2 52 92 28
-8 12 2 52 92 28
-7 12 2 52 92 28
-6 12 2 52 92 28
-5 12 2 52 92 28
-4 12 2 108 108 108
-3 12 2 108 108 108
-2 12 2 108 108 108
-1 12 2 108 108 108
0 12 2 108 108 108
1 12 2 108 108 108
2 12 2 108 108 108
3 12 2 52 92 28
4 12 2 52 92 28
5 12 2 52 92 28
6 12 2 52 92 28
7 12 2 52 92 28
8 12 2 52 92 28
9 12 2 52 92 28
10 12 2 52 92 28
11 12 2 52 92 28
12 12 2 52 92 28
13 12 2 108 108 108
14 12 2 144 144 144
-15 13 2 144 144 144
-14 13 2 108 108 108
-13 13 2 108 108 108
-12 13 2 108 108 108
-11 13 2 108 108 108
-10 13 2 108 108 108
-9 13 2 108 108 108
-8 13 2 108 108 108
-7 13 2 108 108 108
-6 13 2 108 108 108
-5 13 2 108 108 108
-4 13 2 108 108 108
-3 13 2 108 108 108
-2 13 2 108 108 108
-1 13 2 108 108 108
0 13 2 108 108 108
1 13 2 108 108 108
2 13 2 108 108 108
3 13 2 108 108 108
4 13 2 108 108 108
5 13 2 108 108 108
6 13 2 108 108 108
7 13 2 108 108 108
8 13 2 108 108 108
9 13 2 108 108 108
10 13 2 108 108 108
11 13 2 108 108 108
12 13 2 108 108 108
13 13 2 108 108 108
14 13 2 144 144 144
-15 14 2 144 144 144
-14 14 2 144 144 144
-13 14 2 144 144 144
-12 14 2 144 144 144
-11 14 2 144 144 144
-10 14 2 144 144 144
-9 14 2 144 144 144
-8 14 2 144 144 144
-7 14 2 144 144 144
-6 14 2 144 144 144
-5 14 2 144 144 144
-4 14 2 144 144 144
-3 14 2 144 144 144
-2 14 2 144 144 144
-1 14 2 144 144 144
0 14 2 144 144 144
1 14 2 144 144 144
2 14 2 144 144 144
3 14 2 144 144 144
4 14 2 144 144 144
5 14 2 144 144 144
6 14 2 144 144 144
7 14 2 144 144 144
8 14 2 144 144 144
9 14 2 144 144 144
10 14 2 144 144 144
11 14 2 144 144 144
12 14 2 144 144 144
13 14 2 144 144 144
14 14 2 144 144 144
-15 -15 3 144 144 144
-14 -15 3 144 144 144
-13 -15 3 144 144 144
-12 -15 3 144 144 144
-11 -15 3 144 144 144
-10 -15 3 144 144 144
-9 -15 3 144 144 144
-8 -15 3 144 144 144
-7 -15 3 144 144 144
-6 -15 3 144 144 144
-5 -15 3 144 144 144
-4 -15 3 144 144 144
-3 -15 3 144 144 144
-2 -15 3 144 144 144
-1 -15 3 144 144 144
0 -15 3 144 144 144
1 -15 3 144 144 144
2 -15 3 144 144 144
3 -15 3 144 144 144
4 -15 3 144 144 144
5 -15 3 144 144 144
6 -15 3 144 144 144
7 -15 3 144 144 144
8 -15 3 144 144 144
9 -15 3 144 144 144
10 -15 3 144 144 144
11 -15 3 144 144 144
12 -15 3 144 144 144
13 -15 3 144 144 144
14 -15 3 144 144 144
-15 -14 3 144 144 144
-14 -14 3 108 108 108
-13 -14 3 108 108 108
-12 -14 3 108 108 108
-11 -14 3 108 108 108
-10 -14 3 108 108 108
-9 -14 3 108 108 108
-8 -14 3 108 108 108
-7 -14 3 108 108 108
-6 -14 3 108 108 108
-5 -14 3 108 108 108
-4 -14 3 108 108 108
-3 -14 3 108 108 108
-2 -14 3 108 108 108
-1 -14 3 108 108 108
0 -14 3 108 108 108
1 -14 3 108 108 108
2 -14 3 108 108 108
3 -14 3 108 108 108
4 -14 3 108 108 108
5 -14 3 108 108 108
6 -14 3 108 108 108
7 -14 3 108 108 108
8 -14 3 108 108 108
9 -14 3 108 108 108
10 -14 3 108 108 108
11 -14 3 108 108 108
12 -14 3 108 108 108
13 -14 3 108 108 108
14 -14 3 144 144 144
-15 -13 3 144 144 144
-14 -13 3 108 108 108
-13 -13 3 108 108 108
-12 -13 3 52 92 28
-11 -13 3 52 92 28
-10 -13 3 52 92 28
-9 -13 3 52 92 28
-8 -13 3 52 92 28
-7 -13 3 52 92 28
-6 -13 3 52 92 28
-5 -13 3 52 92 28
-4 -13 3 52 92 28
-3 -13 3 108 108 108
-2 -13 3 108 108 108
-1 -13 3 108 108 108
0 -13 3 108 108 108
1 -13 3 52 92 28
2 -13 3 52 92 28
3 -13 3 52 92 28
4 -13 3 52 92 28
5 -13 3 108 108 108
6 -13 3 108 108 108
7 -13 3 108 108 108
8 -13 3 108 108 108
9 -13 3 108 108 108
10 -13 3 108 108 108
11 -13 3 108 108 108
12 -13 3 108 108 108
13 -13 3 108 108 108
14 -13 3 144 144 144
-15 -12 3 144 144 144
-14 -12 3 108 108 108
-13 -12 3 108 108 108
-12 -12 3 52 92 28
-11 -12 3 52 92 28
-10 -12 3 52 92 28
-9 -12 3 52 92 28
-8 -12 3 52 92 28
3 -12 3 52 92 28
12 -12 3 108 108 108
13 -12 3 108 108 108
14 -12 3 144 144 144
-15 -11 3 144 144 144
-14 -11 3 108 108 108
-13 -11 3 108 108 108
-12 -11 3 52 92 28
-11 -11 3 52 92 28
12 -11 3 108 108 108
13 -11 3 108 108 108
14 -11 3 144 144 144
-15 -10 3 144 144 144
-14 -10 3 108 108 108
-13 -10 3 108 108 108
-12 -10 3 52 92 28
12 -10 3 108 108 108
13 -10 3 108 108 108
14 -10 3 144 144 144
-15 -9 3 144 144 144
-14 -9 3 108 108 108
-13 -9 3 108 108 108
12 -9 3 108 108 108
13 -9 3 108 108 108
14 -9 3 144 144 144
-15 -8 3 144 144 144
-14 -8 3 108 108 108
-13 -8 3 108 108 108
12 -8 3 108 108 108
13 -8 3 108 108 108
14 -8 3 144 144 144
-15 -7 3 144 144 144
-14 -7 3 108 108 108
-13 -7 3 108 108 108
12 -7 3 108 108 108
13 -7 3 108 108 108
14 -7 3 144 144 144
-15 -6 3 144 144 144
-14 -6 3 108 108 108
-13 -6 3 108 108 108
12 -6 3 108 108 108
13 -6 3 108 108 108
14 -6 3 144 144 144
-15 -5 3 144 144 144
-14 -5 3 108 108 108
-13 -5 3 108 108 108
12 -5 3 108 108 108
13 -5 3 108 108 108
14 -5 3 144 144 144
-15 -4 3 144 144 144
-14 -4 3 108 108 108
-13 -4 3 108 108 108
-12 -4 3 108 108 108
-11 -4 3 108 108 108
-10 -4 3 108 108 108
12 -4 3 108 108 108
13 -4 3 108 108 108
14 -4 3 144 144 144
-15 -3 3 144 144 144
-14 -3 3 108 108 108
-13 -3 3 108 108 108
-12 -3 3 108 108 108
12 -3 3 52 92 28
13 -3 3 108 108 108
14 -3 3 144 144 144
-15 -2 3 144 144 144
-14 -2 3 108 108 108
-13 -2 3 108 108 108
-12 -2 3 108 108 108
12 -2 3 52 92 28
13 -2 3 108 108 108
14 -2 3 144 144 144
-15 -1 3 144 144 144
-14 -1 3 108 108 108
-13 -1 3 108 108 108
-12 -1 3 108 108 108
12 -1 3 52 92 28
13 -1 3 108 108 108
14 -1 3 144 144 144
-15 0 3 144 144 144
-14 0 3 108 108 108
-13 0 3 108 108 108
-12 0 3 108 108 108
11 0 3 52 92 28
12 0 3 52 92 28
13 0 3 108 108 108
14 0 3 144 144 144
-15 1 3 144 144 144
-14 1 3 108 108 108
-13 1 3 108 108 108
-12 1 3 108 108 108
11 1 3 52 92 28
12 1 3 52 92 28
13 1 3 108 108 108
14 1 3 144 144 144
-15 2 3 144 144 144
-14 2 3 108 108 108
-13 2 3 108 108 108
-12 2 3 108 108 108
11 2 3 52 92 28
12 2 3 52 92 28
13 2 3 108 108 108
14 2 3 144 144 144
-15 3 3 144 144 144
-14 3 3 108 108 108
-13 3 3 108 108 108
-12 3 3 108 108 108
-11 3 3 108 108 108
-10 3 3 108 108 108
11 3 3 52 92 28
12 3 3 52 92 28
13 3 3 108 108 108
14 3 3 144 144 144
-15 4 3 144 144 144
-14 4 3 108 108 108
-13 4 3 108 108 108
11 4 3 52 92 28
12 4 3 52 92 28
13 4 3 108 108 108
14 4 3 144 144 144
-15 5 3 144 144 144
-14 5 3 108 108 108
-13 5 3 108 108 108
11 5 3 52 92 28
12 5 3 52 92 28
13 5 3 108 108 108
14 5 3 144 144 144
-15 6 3 144 144 144
-14 6 3 108 108 108
-13 6 3 108 108 108
10 6 3 52 92 28
11 6 3 52 92 28
12 6 3 52 92 28
13 6 3 108 108 108
14 6 3 144 144 144
-15 7 3 144 144 144
-14 7 3 108 108 108
-13 7 3 108 108 108
10 7 3 52 92 28
11 7 3 52 92 28
12 7 3 52 92 28
13 7 3 108 108 108
14 7 3 144 144 144
-15 8 3 144 144 144
-14 8 3 108 108 108
-13 8 3 108 108 108
10 8 3 52 92 28
11 8 3 52 92 28
12 8 3 52 92 28
13 8 3 108 108 108
14 8 3 144 144 144
-15 9 3 144 144 144
-14 9 3 108 108 108
-13 9 3 108 108 108
10 9 3 52 92 28
11 9 3 52 92 28
12 9 3 52 92 28
13 9 3 108 108 108
14 9 3 144 144 144
-15 10 3 144 144 144
-14 10 3 108 108 108
-13 10 3 108 108 108
-12 10 3 52 92 28
10 10 3 52 92 28
11 10 3 52 92 28
12 10 3 52 92 28
13 10 3 108 108 108
14 10 3 144 144 144
-15 11 3 144 144 144
-14 11 3 108 108 108
-13 11 3 108 108 108
-12 11 3 52 92 28
-11 11 3 52 92 28
-10 11 3 52 92 28
-9 11 3 52 92 28
8 11 3 52 92 28
9 11 3 52 92 28
10 11 3 52 92 28
11 11 3 52 92 28
12 11 3 52 92 28
13 11 3 108 108 108
14 11 3 144 144 144
-15 12 3 144 144 144
-14 12 3 108 108 108
-13 12 3 108 108 108
-12 12 3 52 92 28
-11 12 3 52 92 28
-10 12 3 52 92 28
-9 12 3 52 92 28
-8 12 3 52 92 28
-7 12 3 108 108 108
-6 12 3 108 108 108
-5 12 3 108 108 108
-4 12 3 108 108 108
-3 12 3 108 108 108
-2 12 3 108 108 108
-1 12 3 108 108 108
0 12 3 108 108 108
1 12 3 108 108 108
2 12 3 108 108 108
3 12 3 52 92 28
4 12 3 52 92 28
5 12 3 52 92 28
6 12 3 52 92 28
7 12 3 52 92 28
8 12 3 52 92 28
9 12 3 52 92 28
10 12 3 52 92 28
11 12 3 52 92 28
12 12 3 52 92 28
13 12 3 108 108 108
14 12 3 144 144 144
-15 13 3 144 144 144
-14 13 3 108 108 108
-13 13 3 108 108 108
-12 13 3 108 108 108
-11 13 3 108 108 108
-10 13 3 108 108 108
-9 13 3 108 108 108
-8 13 3 108 108 108
-7 13 3 108 108 108
-6 13 3 108 108 108
-5 13 3 108 108 108
-4 13 3 108 108 108
-3 13 3 108 108 108
-2 13 3 108 108 108
-1 13 3 108 108 108
0 13 3 108 108 108
1 13 3 108 108 108
2 13 3 108 108 108
3 13 3 108 108 108
4 13 3 108 108 108
5 13 3 108 108 108
6 13 3 108 108 108
7 13 3 108 108 108
8 13 3 108 108 108
9 13 3 108 108 108
10 13 3 108 108 108
11 13 3 108 108 108
12 13 3 108 108 108
13 13 3 108 108 108
14 13 3 144 144 144
-15 14 3 144 144 144
-14 14 3 144 144 144
-13 14 3 144 144 144
-12 14 3 144 144 144
-11 14 3 144 144 144
-10 14 3 144 144 144
-9 14 3 144 144 144
-8 14 3 144 144 144
-7 14 3 144 144 144
-6 14 3 144 144 144
-5 14 3 144 144 144
-4 14 3 144 144 144
-3 14 3 144 144 144
-2 14 3 144 144 144
-1 14 3 144 144 144
0 14 3 144 144 144
1 14 3 144 144 144
2 14 3 144 144 144
3 14 3 144 144 144
4 14 3 144 144 144
5 14 3 144 144 144
6 14 3 144 144 144
7 14 3 144 144 144
8 14 3 144 144 144
9 14 3 144 144 144
10 14 3 144 144 144
11 14 3 144 144 144
12 14 3 144 144 144
13 14 3 144 144 144
14 14 3 144 144 144
-15 -15 4 144 144 144
-14 -15 4 144 144 144
-13 -15 4 144 144 144
-12 -15 4 144 144 144
-11 -15 4 144 144 144
-10 -15 4 144 144 144
-9 -15 4 144 144 144
-8 -15 4 144 144 144
-7 -15 4 144 144 144
-6 -15 4 144 144 144
-5 -15 4 144 144 144
-4 -15 4 144 144 144
-3 -15 4 144 144 144
-2 -15 4 144 144 144
-1 -15 4 144 144 144
0 -15 4 144 144 144
1 -15 4 144 144 144
2 -15 4 144 144 144
3 -15 4 144 144 144
4 -15 4 144 144 144
5 -15 4 144 144 144
6 -15 4 144 144 144
7 -15 4 144 144 144
8 -15 4 144 144 144
9 -15 4 144 144 144
10 -15 4 144 144 144
11 -15 4 144 144 144
12 -15 4 144 144 144
13 -15 4 144 144 144
14 -15 4 144 144 144
-15 -14 4 144 144 144
-14 -14 4 108 108 108
-13 -14 4 108 108 108
-12 -14 4 108 108 108
-11 -14 4 108 108 108
-10 -14 4 108 108 108
-9 -14 4 108 108 108
-8 -14 4 108 108 108
-7 -14 4 108 108 108
-6 -14 4 108 108 108
-5 -14 4 108 108 108
-4 -14 4 108 108 108
-3 -14 4 108 108 108
-2 -14 4 108 108 108
-1 -14 4 108 108 108
0 -14 4 108 108 108
1 -14 4 108 108 108
2 -14 4 108 108 108
3 -14 4 108 108 108
4 -14 4 108 108 108
5 -14 4 108 108 108
6 -14 4 108 108 108
7 -14 4 108 108 108
8 -14 4 108 108 108
9 -14 4 108 108 108
10 -14 4 108 108 108
11 -14 4 108 108 108
12 -14 4 108 108 108
13 -14 4 108 108 108
14 -14 4 144 144 144
-15 -13 4 144 144 144
-14 -13 4 108 108 108
-13 -13 4 108 108 108
-12 -13 4 52 92 28
-11 -13 4 52 92 28
-10 -13 4 52 92 28
-9 -13 4 52 92 28
-8 -13 4 52 92 28
-7 -13 4 108 108 108
-6 -13 4 108 108 108
-5 -13 4 108 108 108
-4 -13 4 108 108 108
-3 -13 4 108 108 108
-2 -13 4 108 108 108
-1 -13 4 108 108 108
0 -13 4 108 108 108
1 -13 4 108 108 108
2 -13 4 108 108 108
3 -13 4 52 92 28
4 -13 4 52 92 28
5 -13 4 52 92 28
6 -13 4 108 108 108
7 -13 4 108 108 108
8 -13 4 108 108 108
9 -13 4 108 108 108
10 -13 4 108 108 108
11 -13 4 108 108 108
12 -13 4 108 108 108
13 -13 4 108 108 108
14 -13 4 144 144 144
-15 -12 4 144 144 144
-14 -12 4 108 108 108
-13 -12 4 108 108 108
-12 -12 4 52 92 28
-11 -12 4 52 92 28
4 -12 4 52 92 28
12 -12 4 108 108 108
13 -12 4 108 108 108
14 -12 4 144 144 144
-15 -11 4 144 144 144
-14 -11 4 108 108 108
-13 -11 4 108 108 108
-12 -11 4 52 92 28
12 -11 4 108 108 108
13 -11 4 108 108 108
14 -11 4 144 144 144
-15 -10 4 144 144 144
-14 -10 4 108 108 108
-13 -10 4 108 108 108
12 -10 4 108 108 108
13 -10 4 108 108 108
14 -10 4 144 144 144
-15 -9 4 144 144 144
-14 -9 4 108 108 108
-13 -9 4 108 108 108
12 -9 4 108 108 108
13 -9 4 108 108 108
14 -9 4 144 144 144
-15 -8 4 144 144 144
-14 -8 4 108 108 108
-13 -8 4 108 108 108
12 -8 4 108 108 108
13 -8 4 108 108 108
14 -8 4 144 144 144
-15 -7 4 144 144 144
-14 -7 4 108 108 108
-13 -7 4 108 108 108
12 -7 4 108 108 108
13 -7 4 108 108 108
14 -7 4 144 144 144
-15 -6 4 144 144 144
-14 -6 4 108 108 108
-13 -6 4 108 108 108
12 -6 4 108 108 108
13 -6 4 108 108 108
14 -6 4 144 144 144
-15 -5 4 144 144 144
-14 -5 4 108 108 108
-13 -5 4 108 108 108
12 -5 4 108 108 108
13 -5 4 108 108 108
14 -5 4 144 144 144
-15 -4 4 144 144 144
-14 -4 4 108 108 108
-13 -4 4 108 108 108
-12 -4 4 108 108 108
-11 -4 4 108 108 108
-10 -4 4 108 108 108
12 -4 4 108 108 108
13 -4 4 108 108 108
14 -4 4 144 144 144
-15 -3 4 144 144 144
-14 -3 4 108 108 108
-13 -3 4 108 108 108
12 -3 4 108 108 108
13 -3 4 108 108 108
14 -3 4 144 144 144
-15 -2 4 144 144 144
-14 -2 4 108 108 108
-13 -2 4 108 108 108
12 -2 4 108 108 108
13 -2 4 108 108 108
14 -2 4 144 144 144
-15 -1 4 144 144 144
-14 -1 4 108 108 108
-13 -1 4 108 108 108
12 -1 4 108 108 108
13 -1 4 108 108 108
14 -1 4 144 144 144
-15 0 4 144 144 144
-14 0 4 108 108 108
-13 0 4 108 108 108
12 0 4 108 108 108
13 0 4 108 108 108
14 0 4 144 144 144
-15 1 4 144 144 144
-14 1 4 108 108 108
-13 1 4 108 108 108
12 1 4 108 108 108
13 1 4 108 108 108
14 1 4 144 144 144
-15 2 4 144 144 144
-14 2 4 108 108 108
-13 2 4 108 108 108
12 2 4 52 92 28
13 2 4 108 108 108
14 2 4 144 144 144
-15 3 4 144 144 144
-14 3 4 108 108 108
-13 3 4 108 108 108
-12 3 4 108 108 108
-11 3 4 108 108 108
-10 3 4 108 108 108
11 3 4 52 92 28
12 3 4 52 92 28
13 3 4 108 108 108
14 3 4 144 144 144
-15 4 4 144 144 144
-14 4 4 108 108 108
-13 4 4 108 108 108
11 4 4 52 92 28
12 4 4 52 92 28
13 4 4 108 108 108
14 4 4 144 144 144
-15 5 4 144 144 144
-14 5 4 108 108 108
-13 5 4 108 108 108
11 5 4 52 92 28
12 5 4 52 92 28
13 5 4 108 108 108
14 5 4 144 144 144
-15 6 4 144 144 144
-14 6 4 108 108 108
-13 6 4 108 108 108
12 6 4 52 92 28
13 6 4 108 108 108
14 6 4 144 144 144
-15 7 4 144 144 144
-14 7 4 108 108 108
-13 7 4 108 108 108
12 7 4 52 92 28
13 7 4 108 108 108
14 7 4 144 144 144
-15 8 4 144 144 144
-14 8 4 108 108 108
-13 8 4 108 108 108
11 8 4 52 92 28
12 8 4 52 92 28
13 8 4 108 108 108
14 8 4 144 144 144
-15 9 4 144 144 144
-14 9 4 108 108 108
-13 9 4 108 108 108
11 9 4 52 92 28
12 9 4 52 92 28
13 9 4 108 108 108
14 9 4 144 144 144
-15 10 4 144 144 144
-14 10 4 108 108 108
-13 10 4 108 108 108
-12 10 4 52 92 28
11 10 4 52 92 28
12 10 4 52 92 28
13 10 4 108 108 108
14 10 4 144 144 144
-15 11 4 144 144 144
-14 11 4 108 108 108
-13 11 4 108 108 108
-12 11 4 52 92 28
-11 11 4 52 92 28
9 11 4 52 92 28
10 11 4 52 92 28
11 11 4 52 92 28
12 11 4 52 92 28
13 11 4 108 108 108
14 11 4 144 144 144
-15 12 4 144 144 144
-14 12 4 108 108 108
-13 12 4 108 108 108
-12 12 4 52 92 28
-11 12 4 52 92 28
-10 12 4 52 92 28
-9 12 4 52 92 28
-8 12 4 108 108 108
-7 12 4 108 108 108
-6 12 4 108 108 108
-5 12 4 108 108 108
-4 12 4 108 108 108
-3 12 4 108 108 108
-2 12 4 108 108 108
-1 12 4 108 108 108
0 12 4 108 108 108
1 12 4 108 108 108
2 12 4 108 108 108
3 12 4 108 108 108
4 12 4 108 108 108
5 12 4 108 108 108
6 12 4 108 108 108
7 12 4 52 92 28
8 12 4 52 92 28
9 12 4 52 92 28
10 12 4 52 92 28
11 12 4 52 92 28
12 12 4 52 92 28
13 12 4 108 108 108
14 12 4 144 144 144
-15 13 4 144 144 144
-14 13 4 108 108 108
-13 13 4 108 108 108
-12 13 4 108 108 108
-11 13 4 108 108 108
-10 13 4 108 108 108
-9 13 4 108 108 108
-8 13 4 108 108 108
-7 13 4 108 108 108
-6 13 4 108 108 108
-5 13 4 108 108 108
-4 13 4 108 108 108
-3 13 4 108 108 108
-2 13 4 108 108 108
-1 13 4 108 108 108
0 13 4 108 108 108
1 13 4 108 108 108
2 13 4 108 108 108
3 13 4 108 108 108
4 13 4 108 108 108
5 13 4 108 108 108
6 13 4 108 108 108
7 13 4 108 108 108
8 13 4 108 108 108
9 13 4 108 108 108
10 13 4 108 108 108
11 13 4 108 108 108
12 13 4 108 108 108
13 13 4 108 108 108
14 13 4 144 144 144
-15 14 4 144 144 144
-14 14 4 144 144 144
-13 14 4 144 144 144
-12 14 4 144 144 144
-11 14 4 144 144 144
-10 14 4 144 144 144
-9 14 4 144 144 144
-8 14 4 144 144 144
-7 14 4 144 144 144
-6 14 4 144 144 144
-5 14 4 144 144 144
-4 14 4 144 144 144
-3 14 4 144 144 144
-2 14 4 144 144 144
-1 14 4 144 144 144
0 14 4 144 144 144
1 14 4 144 144 144
2 14 4 144 144 144
3 14 4 144 144 144
4 14 4 144 144 144
5 14 4 144 144 144
6 14 4 144 144 144
7 14 4 144 144 144
8 14 4 144 144 144
9 14 4 144 144 144
10 14 4 144 144 144
11 14 4 144 144 144
12 14 4 144 144 144
13 14 4 144 144 144
14 14 4 144 144 144
-15 -15 5 144 144 144
-14 -15 5 144 144 144
-13 -15 5 144 144 144
-12 -15 5 144 144 144
-11 -15 5 144 144 144
-10 -15 5 144 144 144
-9 -15 5 144 144 144
-8 -15 5 144 144 144
-7 -15 5 144 144 144
-6 -15 5 144 144 144
-5 -15 5 144 144 144
-4 -15 5 144 144 144
-3 -15 5 144 144 144
-2 -15 5 144 144 144
-1 -15 5 144 144 144
0 -15 5 144 144 144
1 -15 5 144 144 144
2 -15 5 144 144 144
3 -15 5 144 144 144
4 -15 5 144 144 144
5 -15 5 144 144 144
6 -15 5 144 144 144
7 -15 5 144 144 144
8 -15 5 144 144 144
9 -15 5 144 144 144
10 -15 5 144 144 144
11 -15 5 144 144 144
12 -15 5 144 144 144
13 -15 5 144 144 144
14 -15 5 144 144 144
-15 -14 5 144 144 144
-14 -14 5 108 108 108
-13 -14 5 108 108 108
-12 -14 5 108 108 108
-11 -14 5 108 108 108
-10 -14 5 108 108 108
-9 -14 5 108 108 108
-8 -14 5 108 108 108
-7 -14 5 108 108 108
-6 -14 5 108 108 108
-5 -14 5 108 108 108
-4 -14 5 108 108 108
-3 -14 5 108 108 108
-2 -14 5 108 108 108
-1 -14 5 108 108 108
0 -14 5 108 108 108
1 -14 5 108 108 108
2 -14 5 108 108 108
3 -14 5 108 108 108
4 -14 5 108 108 108
5 -14 5 108 108 108
6 -14 5 108 108 108
7 -14 5 108 108 108
8 -14 5 108 108 108
9 -14 5 108 108 108
10 -14 5 108 108 108
11 -14 5 108 108 108
12 -14 5 108 108 108
13 -14 5 108 108 108
14 -14 5 144 144 144
-15 -13 5 144 144 144
-14 -13 5 108 108 108
-13 -13 5 108 108 108
-12 -13 5 52 92 28
-11 -13 5 52 92 28
-10 -13 5 108 108 108
-9 -13 5 108 108 108
-8 -13 5 108 108 108
-7 -13 5 108 108 108
-6 -13 5 108 108 108
-5 -13 5 108 108 108
-4 -13 5 108 108 108
-3 -13 5 108 108 108
-2 -13 5 108 108 108
-1 -13 5 108 108 108
0 -13 5 108 108 108
1 -13 5 108 108 108
2 -13 5 108 108 108
3 -13 5 52 92 28
4 -13 5 52 92 28
5 -13 5 52 92 28
6 -13 5 108 108 108
7 -13 5 108 108 108
8 -13 5 108 108 108
9 -13 5 108 108 108
10 -13 5 108 108 108
11 -13 5 108 108 108
12 -13 5 108 108 108
13 -13 5 108 108 108
14 -13 5 144 144 144
-15 -12 5 144 144 144
-14 -12 5 108 108 108
-13 -12 5 108 108 108
-12 -12 5 52 92 28
-11 -12 5 52 92 28
4 -12 5 52 92 28
12 -12 5 108 108 108
13 -12 5 108 108 108
14 -12 5 144 144 144
-15 -11 5 144 144 144
-14 -11 5 108 108 108
-13 -11 5 108 108 108
12 -11 5 52 92 28
13 -11 5 108 108 108
14 -11 5 144 144 144
-15 -10 5 144 144 144
-14 -10 5 108 108 108
-13 -10 5 108 108 108
12 -10 5 52 92 28
13 -10 5 108 108 108
14 -10 5 144 144 144
-15 -9 5 144 144 144
-14 -9 5 108 108 108
-13 -9 5 108 108 108
12 -9 5 52 92 28
13 -9 5 108 108 108
14 -9 5 144 144 144
-15 -8 5 144 144 144
-14 -8 5 108 108 108
-13 -8 5 108 108 108
12 -8 5 52 92 28
13 -8 5 108 108 108
14 -8 5 144 144 144
-15 -7 5 144 144 144
-14 -7 5 108 108 108
-13 -7 5 108 108 108
12 -7 5 52 92 28
13 -7 5 108 108 108
14 -7 5 144 144 144
-15 -6 5 144 144 144
-14 -6 5 108 108 108
-13 -6 5 108 108 108
12 -6 5 108 108 108
13 -6 5 108 108 108
14 -6 5 144 144 144
-15 -5 5 144 144 144
-14 -5 5 108 108 108
-13 -5 5 108 108 108
12 -5 5 108 108 108
13 -5 5 108 108 108
14 -5 5 144 144 144
-15 -4 5 144 144 144
-14 -4 5 108 108 108
-13 -4 5 108 108 108
-12 -4 5 108 108 108
-11 -4 5 108 108 108
-10 -4 5 108 108 108
12 -4 5 108 108 108
13 -4 5 108 108 108
14 -4 5 144 144 144
-15 -3 5 144 144 144
-14 -3 5 108 108 108
-13 -3 5 108 108 108
12 -3 5 108 108 108
13 -3 5 108 108 108
14 -3 5 144 144 144
-15 -2 5 144 144 144
-14 -2 5 108 108 108
-13 -2 5 108 108 108
12 -2 5 108 108 108
13 -2 5 108 108 108
14 -2 5 144 144 144
-15 -1 5 144 144 144
-14 -1 5 108 108 108
-13 -1 5 108 108 108
12 -1 5 108 108 108
13 -1 5 108 108 108
14 -1 5 144 144 144
-15 0 5 144 144 144
-14 0 5 108 108 108
-13 0 5 108 108 108
12 0 5 108 108 108
13 0 5 108 108 108
14 0 5 144 144 144
-15 1 5 144 144 144
-14 1 5 108 108 108
-13 1 5 108 108 108
12 1 5 108 108 108
13 1 5 108 108 108
14 1 5 144 144 144
-15 2 5 144 144 144
-14 2 5 108 108 108
-13 2 5 108 108 108
12 2 5 52 92 28
13 2 5 108 108 108
14 2 5 144 144 144
-15 3 5 144 144 144
-14 3 5 108 108 108
-13 3 5 108 108 108
-12 3 5 108 108 108
-11 3 5 108 108 108
-10 3 5 108 108 108
11 3 5 52 92 28
12 3 5 52 92 28
13 3 5 108 108 108
14 3 5 144 144 144
-15 4 5 144 144 144
-14 4 5 108 108 108
-13 4 5 108 108 108
12 4 5 52 92 28
13 4 5 108 108 108
14 4 5 144 144 144
-15 5 5 144 144 144
-14 5 5 108 108 108
-13 5 5 108 108 108
12 5 5 108 108 108
13 5 5 108 108 108
14 5 5 144 144 144
-15 6 5 144 144 144
-14 6 5 108 108 108
-13 6 5 108 108 108
12 6 5 108 108 108
13 6 5 108 108 108
14 6 5 144 144 144
-15 7 5 144 144 144
-14 7 5 108 108 108
-13 7 5 108 108 108
12 7 5 108 108 108
13 7 5 108 108 108
14 7 5 144 144 144
-15 8 5 144 144 144
-14 8 5 108 108 108
-13 8 5 108 108 108
12 8 5 108 108 108
13 8 5 108 108 108
14 8 5 144 144 144
-15 9 5 144 144 144
-14 9 5 108 108 108
-13 9 5 108 108 108
12 9 5 108 108 108
13 9 5 108 108 108
14 9 5 144 144 144
-15 10 5 144 144 144
-14 10 5 108 108 108
-13 10 5 108 108 108
11 10 5 52 92 28
12 10 5 52 92 28
13 10 5 108 108 108
14 10 5 144 144 144
-15 11 5 144 144 144
-14 11 5 108 108 108
-13 11 5 108 108 108
-12 11 5 52 92 28
-11 11 5 52 92 28
10 11 5 52 92 28
11 11 5 52 92 28
12 11 5 52 92 28
13 11 5 108 108 108
14 11 5 144 144 144
-15 12 5 144 144 144
-14 12 5 108 108 108
-13 12 5 108 108 108
-12 12 5 52 92 28
-11 12 5 52 92 28
-10 12 5 52 92 28
-9 12 5 108 108 108
-8 12 5 108 108 108
-7 12 5 108 108 108
-6 12 5 108 108 108
-5 12 5 108 108 108
-4 12 5 108 108 108
-3 12 5 108 108 108
-2 12 5 108 108 108
-1 12 5 108 108 108
0 12 5 108 108 108
1 12 5 108 108 108
2 12 5 108 108 108
3 12 5 108 108 108
4 12 5 108 108 108
5 12 5 108 108 108
6 12 5 108 108 108
7 12 5 108 108 108
8 12 5 52 92 28
9 12 5 52 92 28
10 12 5 52 92 28
11 12 5 52 92 28
12 12 5 52 92 28
13 12 5 108 108 108
14 12 5 144 144 144
-15 13 5 144 144 144
-14 13 5 108 108 108
-13 13 5 108 108 108
-12 13 5 108 108 108
-11 13 5 108 108 108
-10 13 5 108 108 108
-9 13 5 108 108 108
-8 13 5 108 108 108
-7 13 5 108 108 108
-6 13 5 108 108 108
-5 13 5 108 108 108
-4 13 5 108 108 108
-3 13 5 108 108 108
-2 13 5 108 108 108
-1 13 5 108 108 108
0 13 5 108 108 108
1 13 5 108 108 108
2 13 5 108 108 108
3 13 5 108 108 108
4 13 5 108 108 108
5 13 5 108 108 108
6 13 5 108 108 108
7 13 5 108 108 108
8 13 5 108 108 108
9 13 5 108 108 108
10 13 5 108 108 108
11 13 5 108 108 108
12 13 5 108 108 108
13 13 5 108 108 108
14 13 5 144 144 144
-15 14 5 144 144 144
-14 14 5 144 144 144
-13 14 5 144 144 144
-12 14 5 144 144 144
-11 14 5 144 144 144
-10 14 5 144 144 144
-9 14 5 144 144 144
-8 14 5 144 144 144
-7 14 5 144 144 144
-6 14 5 144 144 144
-5 14 5 144 144 144
-4 14 5 144 144 144
-3 14 5 144 144 144
-2 14 5 144 144 144
-1 14 5 144 144 144
0 14 5 144 144 144
1 14 5 144 144 144
2 14 5 144 144 144
3 14 5 144 144 144
4 14 5 144 144 144
5 14 5 144 144 144
6 14 5 144 144 144
7 14 5 144 144 144
8 14 5 144 144 144
9 14 5 144 144 144
10 14 5 144 144 144
11 14 5 144 144 144
12 14 5 144 144 144
13 14 5 144 144 144
14 14 5 144 144 144
-15 -15 6 144 144 144
-14 -15 6 144 144 144
-13 -15 6 144 144 144
-12 -15 6 144 144 144
-11 -15 6 144 144 144
-10 -15 6 144 144 144
-9 -15 6 144 144 144
-8 -15 6 144 144 144
-7 -15 6 144 144 144
-6 -15 6 144 144 144
-5 -15 6 144 144 144
-4 -15 6 144 144 144
-3 -15 6 144 144 144
-2 -15 6 144 144 144
-1 -15 6 144 144 144
0 -15 6 144 144 144
1 -15 6 144 144 144
2 -15 6 144 144 144
3 -15 6 144 144 144
4 -15 6 144 144 144
5 -15 6 144 144 144
6 -15 6 144 144 144
7 -15 6 144 144 144
8 -15 6 144 144 144
9 -15 6 144 144 144
10 -15 6 144 144 144
11 -15 6 144 144 144
12 -15 6 144 144 144
13 -15 6 144 144 144
14 -15 6 144 144 144
-15 -14 6 144 144 144
-14 -14 6 108 108 108
-13 -14 6 108 108 108
-12 -14 6 108 108 108
-11 -14 6 108 108 108
-10 -14 6 108 108 108
-9 -14 6 108 108 108
-8 -14 6 108 108 108
-7 -14 6 108 108 108
-6 -14 6 108 108 108
-5 -14 6 108 108 108
-4 -14 6 108 108 108
-3 -14 6 108 108 108
-2 -14 6 108 108 108
-1 -14 6 108 108 108
0 -14 6 108 108 108
1 -14 6 108 108 108
2 -14 6 108 108 108
3 -14 6 108 108 108
4 -14 6 108 108 108
5 -14 6 108 108 108
6 -14 6 108 108 108
7 -14 6 108 108 108
8 -14 6 108 108 108
9 -14 6 108 108 108
10 -14 6 108 108 108
11 -14 6 108 108 108
12 -14 6 108 108 108
13 -14 6 108 108 108
14 -14 6 144 144 144
-15 -13 6 144 144 144
-14 -13 6 108 108 108
-13 -13 6 108 108 108
-12 -13 6 52 92 28
-11 -13 6 52 92 28
-10 -13 6 108 108 108
-9 -13 6 108 108 108
-8 -13 6 108 108 108
-7 -13 6 108 108 108
-6 -13 6 108 108 108
-5 -13 6 108 108 108
-4 -13 6 108 108 108
-3 -13 6 108 108 108
-2 -13 6 108 108 108
-1 -13 6 108 108 108
0 -13 6 108 108 108
1 -13 6 108 108 108
2 -13 6 108 108 108
3 -13 6 108 108 108
4 -13 6 52 92 28
5 -13 6 52 92 28
6 -13 6 52 92 28
7 -13 6 108 108 108
8 -13 6 108 108 108
9 -13 6 108 108 108
10 -13 6 52 92 28
11 -13 6 52 92 28
12 -13 6 108 108 108
13 -13 6 108 108 108
14 -13 6 144 144 144
-15 -12 6 144 144 144
-14 -12 6 108 108 108
-13 -12 6 108 108 108
-12 -12 6 52 92 28
5 -12 6 52 92 28
12 -12 6 52 92 28
13 -12 6 108 108 108
14 -12 6 144 144 144
-15 -11 6 144 144 144
-14 -11 6 108 108 108
-13 -11 6 108 108 108
11 -11 6 52 92 28
12 -11 6 52 92 28
13 -11 6 108 108 108
14 -11 6 144 144 144
-15 -10 6 144 144 144
-14 -10 6 108 108 108
-13 -10 6 108 108 108
11 -10 6 52 92 28
12 -10 6 52 92 28
13 -10 6 108 108 108
14 -10 6 144 144 144
-15 -9 6 144 144 144
-14 -9 6 108 108 108
-13 -9 6 108 108 108
11 -9 6 52 92 28
12 -9 6 52 92 28
13 -9 6 108 108 108
14 -9 6 144 144 144
-15 -8 6 144 144 144
-14 -8 6 108 108 108
-13 -8 6 108 108 108
11 -8 6 52 92 28
12 -8 6 52 92 28
13 -8 6 108 108 108
14 -8 6 144 144 144
-15 -7 6 144 144 144
-14 -7 6 108 108 108
-13 -7 6 108 108 108
11 -7 6 52 92 28
12 -7 6 52 92 28
13 -7 6 108 108 108
14 -7 6 144 144 144
-15 -6 6 144 144 144
-14 -6 6 108 108 108
-13 -6 6 108 108 108
12 -6 6 52 92 28
13 -6 6 108 108 108
14 -6 6 144 144 144
-15 -5 6 144 144 144
-14 -5 6 108 108 108
-13 -5 6 108 108 108
12 -5 6 52 92 28
13 -5 6 108 108 108
14 -5 6 144 144 144
-15 -4 6 144 144 144
-14 -4 6 108 108 108
-13 -4 6 108 108 108
-12 -4 6 108 108 108
-11 -4 6 108 108 108
-10 -4 6 108 108 108
12 -4 6 108 108 108
13 -4 6 108 108 108
14 -4 6 144 144 144
-15 -3 6 144 144 144
-14 -3 6 108 108 108
-13 -3 6 108 108 108
12 -3 6 108 108 108
13 -3 6 108 108 108
14 -3 6 144 144 144
-15 -2 6 144 144 144
-14 -2 6 108 108 108
-13 -2 6 108 108 108
12 -2 6 108 108 108
13 -2 6 108 108 108
14 -2 6 144 144 144
-15 -1 6 144 144 144
-14 -1 6 108 108 108
-13 -1 6 108 108 108
12 -1 6 108 108 108
13 -1 6 108 108 108
14 -1 6 144 144 144
-15 0 6 144 144 144
-14 0 6 108 108 108
-13 0 6 108 108 108
12 0 6 108 108 108
13 0 6 108 108 108
14 0 6 144 144 144
-15 1 6 144 144 144
-14 1 6 108 108 108
-13 1 6 108 108 108
12 1 6 108 108 108
13 1 6 108 108 108
14 1 6 144 144 144
-15 2 6 144 144 144
-14 2 6 108 108 108
-13 2 6 108 108 108
12 2 6 52 92 28
13 2 6 108 108 108
14 2 6 144 144 144
-15 3 6 144 144 144
-14 3 6 108 108 108
-13 3 6 108 108 108
-12 3 6 108 108 108
-11 3 6 108 108 108
-10 3 6 108 108 108
11 3 6 52 92 28
12 3 6 52 92 28
13 3 6 108 108 108
14 3 6 144 144 144
-15 4 6 144 144 144
-14 4 6 108 108 108
-13 4 6 108 108 108
12 4 6 52 92 28
13 4 6 108 108 108
14 4 6 144 144 144
-15 5 6 144 144 144
-14 5 6 108 108 108
-13 5 6 108 108 108
12 5 6 108 108 108
13 5 6 108 108 108
14 5 6 144 144 144
-15 6 6 144 144 144
-14 6 6 108 108 108
-13 6 6 108 108 108
12 6 6 108 108 108
13 6 6 108 108 108
14 6 6 144 144 144
-15 7 6 144 144 144
-14 7 6 108 108 108
-13 7 6 108 108 108
12 7 6 108 108 108
13 7 6 108 108 108
14 7 6 144 144 144
-15 8 6 144 144 144
-14 8 6 108 108 108
-13 8 6 108 108 108
12 8 6 108 108 108
13 8 6 108 108 108
14 8 6 144 144 144
-15 9 6 144 144 144
-14 9 6 108 108 108
-13 9 6 108 108 108
12 9 6 108 108 108
13 9 6 108 108 108
14 9 6 144 144 144
-15 10 6 144 144 144
-14 10 6 108 108 108
-13 10 6 108 108 108
12 10 6 52 92 28
13 10 6 108 108 108
14 10 6 144 144 144
-15 11 6 144 144 144
-14 11 6 108 108 108
-13 11 6 108 108 108
-12 11 6 52 92 28
-11 11 6 52 92 28
10 11 6 52 92 28
11 11 6 52 92 28
12 11 6 52 92 28
13 11 6 108 108 108
14 11 6 144 144 144
-15 12 6 144 144 144
-14 12 6 108 108 108
-13 12 6 108 108 108
-12 12 6 52 92 28
-11 12 6 52 92 28
-10 12 6 52 92 28
-9 12 6 108 108 108
-8 12 6 108 108 108
-7 12 6 108 108 108
-6 12 6 108 108 108
-5 12 6 108 108 108
-4 12 6 108 108 108
-3 12 6 108 108 108
-2 12 6 108 108 108
-1 12 6 108 108 108
0 12 6 108 108 108
1 12 6 108 108 108
2 12 6 108 108 108
3 12 6 108 108 108
4 12 6 108 108 108
5 12 6 108 108 108
6 12 6 108 108 108
7 12 6 108 108 108
8 12 6 108 108 108
9 12 6 52 92 28
10 12 6 52 92 28
11 12 6 52 92 28
12 12 6 52 92 28
13 12 6 108 108 108
14 12 6 144 144 144
-15 13 6 144 144 144
-14 13 6 108 108 108
-13 13 6 108 108 108
-12 13 6 108 108 108
-11 13 6 108 108 108
-10 13 6 108 108 108
-9 13 6 108 108 108
-8 13 6 108 108 108
-7 13 6 108 108 108
-6 13 6 108 108 108
-5 13 6 108 108 108
-4 13 6 108 108 108
-3 13 6 108 108 108
-2 13 6 108 108 108
-1 13 6 108 108 108
0 13 6 108 108 108
1 13 6 108 108 108
2 13 6 108 108 108
3 13 6 108 108 108
4 13 6 108 108 108
5 13 6 108 108 108
6 13 6 108 108 108
7 13 6 108 108 108
8 13 6 108 108 108
9 13 6 108 108 108
10 13 6 108 108 108
11 13 6 108 108 108
12 13 6 108 108 108
13 13 6 108 108 108
14 13 6 144 144 144
-15 14 6 144 144 144
-14 14 6 144 144 144
-13 14 6 144 144 144
-12 14 6 144 144 144
-11 14 6 144 144 144
-10 14 6 144 144 144
-9 14 6 144 144 144
-8 14 6 144 144 144
-7 14 6 144 144 144
-6 14 6 144 144 144
-5 14 6 144 144 144
-4 14 6 144 144 144
-3 14 6 144 144 144
-2 14 6 144 144 144
-1 14 6 144 144 144
0 14 6 144 144 144
1 14 6 144 144 144
2 14 6 144 144 144
3 14 6 144 144 144
4 14 6 144 144 144
5 14 6 144 144 144
6 14 6 144 144 144
7 14 6 144 144 144
8 14 6 144 144 144
9 14 6 144 144 144
10 14 6 144 144 144
11 14 6 144 144 144
12 14 6 144 144 144
13 14 6 144 144 144
14 14 6 144 144 144
-15 -15 7 144 144 144
-14 -15 7 144 144 144
-13 -15 7 144 144 144
-12 -15 7 144 144 144
-11 -15 7 144 144 144
-10 -15 7 144 144 144
-9 -15 7 144 144 144
-8 -15 7 144 144 144
-7 -15 7 144 144 144
-6 -15 7 144 144 144
-5 -15 7 144 144 144
-4 -15 7 144 144 144
-3 -15 7 144 144 144
-2 -15 7 144 144 144
-1 -15 7 144 144 144
0 -15 7 144 144 144
1 -15 7 144 144 144
2 -15 7 144 144 144
3 -15 7 144 144 144
4 -15 7 144 144 144
5 -15 7 144 144 144
6 -15 7 144 144 144
7 -15 7 144 144 144
8 -15 7 144 144 144
9 -15 7 144 144 144
10 -15 7 144 144 144
11 -15 7 144 144 144
12 -15 7 144 144 144
13 -15 7 144 144 144
14 -15 7 144 144 144
-15 -14 7 144 144 144
-14 -14 7 108 108 108
-13 -14 7 108 108 108
-12 -14 7 108 108 108
-11 -14 7 108 108 108
-10 -14 7 108 108 108
-9 -14 7 108 108 108
-8 -14 7 108 108 108
-7 -14 7 108 108 108
-6 -14 7 108 108 108
-5 -14 7 108 108 108
-4 -14 7 108 108 108
-3 -14 7 108 108 108
-2 -14 7 108 108 108
-1 -14 7 108 108 108
0 -14 7 108 108 108
1 -14 7 108 108 108
2 -14 7 108 108 108
3 -14 7 108 108 108
4 -14 7 108 108 108
5 -14 7 108 108 108
6 -14 7 108 108 108
7 -14 7 108 108 108
8 -14 7 108 108 108
9 -14 7 108 108 108
10 -14 7 108 108 108
11 -14 7 108 108 108
12 -14 7 108 108 108
13 -14 7 108 108 108
14 -14 7 144 144 144
-15 -13 7 144 144 144
-14 -13 7 108 108 108
-13 -13 7 108 108 108
-12 -13 7 52 92 28
-11 -13 7 52 92 28
-10 -13 7 108 108 108
-9 -13 7 108 108 108
-8 -13 7 108 108 108
-7 -13 7 108 108 108
-6 -13 7 108 108 108
-5 -13 7 108 108 108
-4 -13 7 108 108 108
-3 -13 7 108 108 108
-2 -13 7 108 108 108
-1 -13 7 108 108 108
0 -13 7 108 108 108
1 -13 7 108 108 108
2 -13 7 108 108 108
3 -13 7 108 108 108
4 -13 7 52 92 28
5 -13 7 52 92 28
6 -13 7 52 92 28
7 -13 7 108 108 108
8 -13 7 108 108 108
9 -13 7 52 92 28
10 -13 7 52 92 28
11 -13 7 52 92 28
12 -13 7 108 108 108
13 -13 7 108 108 108
14 -13 7 144 144 144
-15 -12 7 144 144 144
-14 -12 7 108 108 108
-13 -12 7 108 108 108
-12 -12 7 52 92 28
5 -12 7 52 92 28
10 -12 7 52 92 28
11 -12 7 52 92 28
12 -12 7 52 92 28
13 -12 7 108 108 108
14 -12 7 144 144 144
-15 -11 7 144 144 144
-14 -11 7 108 108 108
-13 -11 7 108 108 108
12 -11 7 52 92 28
13 -11 7 108 108 108
14 -11 7 144 144 144
-15 -10 7 144 144 144
-14 -10 7 108 108 108
-13 -10 7 108 108 108
12 -10 7 52 92 28
13 -10 7 108 108 108
14 -10 7 144 144 144
-15 -9 7 144 144 144
-14 -9 7 108 108 108
-13 -9 7 108 108 108
12 -9 7 52 92 28
13 -9 7 108 108 108
14 -9 7 144 144 144
-15 -8 7 144 144 144
-14 -8 7 108 108 108
-13 -8 7 108 108 108
12 -8 7 52 92 28
13 -8 7 108 108 108
14 -8 7 144 144 144
-15 -7 7 144 144 144
-14 -7 7 108 108 108
-13 -7 7 108 108 108
12 -7 7 52 92 28
13 -7 7 108 108 108
14 -7 7 144 144 144
-15 -6 7 144 144 144
-14 -6 7 108 108 108
-13 -6 7 108 108 108
11 -6 7 52 92 28
12 -6 7 52 92 28
13 -6 7 108 108 108
14 -6 7 144 144 144
-15 -5 7 144 144 144
-14 -5 7 108 108 108
-13 -5 7 108 108 108
11 -5 7 52 92 28
12 -5 7 52 92 28
13 -5 7 108 108 108
14 -5 7 144 144 144
-15 -4 7 144 144 144
-14 -4 7 108 108 108
-13 -4 7 108 108 108
-12 -4 7 108 108 108
-11 -4 7 108 108 108
-10 -4 7 108 108 108
-9 -4 7 108 108 108
12 -4 7 52 92 28
13 -4 7 108 108 108
14 -4 7 144 144 144
-15 -3 7 144 144 144
-14 -3 7 108 108 108
-13 -3 7 108 108 108
-9 -3 7 108 108 108
12 -3 7 108 108 108
13 -3 7 108 108 108
14 -3 7 144 144 144
-15 -2 7 144 144 144
-14 -2 7 108 108 108
-13 -2 7 108 108 108
-9 -2 7 108 108 108
12 -2 7 108 108 108
13 -2 7 108 108 108
14 -2 7 144 144 144
-15 -1 7 144 144 144
-14 -1 7 108 108 108
-13 -1 7 108 108 108
-9 -1 7 108 108 108
12 -1 7 108 108 108
13 -1 7 108 108 108
14 -1 7 144 144 144
-15 0 7 144 144 144
-14 0 7 108 108 108
-13 0 7 108 108 108
-9 0 7 108 108 108
12 0 7 108 108 108
13 0 7 108 108 108
14 0 7 144 144 144
-15 1 7 144 144 144
-14 1 7 108 108 108
-13 1 7 108 108 108
-9 1 7 108 108 108
12 1 7 52 92 28
13 1 7 108 108 108
14 1 7 144 144 144
-15 2 7 144 144 144
-14 2 7 108 108 108
-13 2 7 108 108 108
-9 2 7 108 108 108
11 2 7 52 92 28
12 2 7 52 92 28
13 2 7 108 108 108
14 2 7 144 144 144
-15 3 7 144 144 144
-14 3 7 108 108 108
-13 3 7 108 108 108
-12 3 7 108 108 108
-11 3 7 108 108 108
-10 3 7 108 108 108
-9 3 7 108 108 108
11 3 7 52 92 28
12 3 7 52 92 28
13 3 7 108 108 108
14 3 7 144 144 144
-15 4 7 144 144 144
-14 4 7 108 108 108
-13 4 7 108 108 108
12 4 7 52 92 28
13 4 7 108 108 108
14 4 7 144 144 144
-15 5 7 144 144 144
-14 5 7 108 108 108
-13 5 7 108 108 108
12 5 7 108 108 108
13 5 7 108 108 108
14 5 7 144 144 144
-15 6 7 144 144 144
-14 6 7 108 108 108
-13 6 7 108 108 108
12 6 7 108 108 108
13 6 7 108 108 108
14 6 7 144 144 144
-15 7 7 144 144 144
-14 7 7 108 108 108
-13 7 7 108 108 108
12 7 7 108 108 108
13 7 7 108 108 108
14 7 7 144 144 144
-15 8 7 144 144 144
-14 8 7 108 108 108
-13 8 7 108 108 108
12 8 7 108 108 108
13 8 7 108 108 108
14 8 7 144 144 144
-15 9 7 144 144 144
-14 9 7 108 108 108
-13 9 7 108 108 108
12 9 7 108 108 108
13 9 7 108 108 108
14 9 7 144 144 144
-15 10 7 144 144 144
-14 10 7 108 108 108
-13 10 7 108 108 108
12 10 7 52 92 28
13 10 7 108 108 108
14 10 7 144 144 144
-15 11 7 144 144 144
-14 11 7 108 108 108
-13 11 7 108 108 108
-12 11 7 52 92 28
10 11 7 52 92 28
11 11 7 52 92 28
12 11 7 52 92 28
13 11 7 108 108 108
14 11 7 144 144 144
-15 12 7 144 144 144
-14 12 7 108 108 108
-13 12 7 108 108 108
-12 12 7 52 92 28
-11 12 7 52 92 28
-10 12 7 108 108 108
-9 12 7 108 108 108
-8 12 7 108 108 108
-7 12 7 108 108 108
-6 12 7 108 108 108
-5 12 7 108 108 108
-4 12 7 108 108 108
-3 12 7 108 108 108
-2 12 7 108 108 108
-1 12 7 108 108 108
0 12 7 108 108 108
1 12 7 52 92 28
2 12 7 52 92 28
3 12 7 52 92 28
4 12 7 108 108 108
5 12 7 108 108 108
6 12 7 108 108 108
7 12 7 108 108 108
8 12 7 108 108 108
9 12 7 52 92 28
10 12 7 52 92 28
11 12 7 52 92 28
12 12 7 52 92 28
13 12 7 108 108 108
14 12 7 144 144 144
-15 13 7 144 144 144
-14 13 7 108 108 108
-13 13 7 108 108 108
-12 13 7 108 108 108
-11 13 7 108 108 108
-10 13 7 108 108 108
-9 13 7 108 108 108
-8 13 7 108 108 108
-7 13 7 108 108 108
-6 13 7 108 108 108
-5 13 7 108 108 108
-4 13 7 108 108 108
-3 13 7 108 108 108
-2 13 7 108 108 108
-1 13 7 108 108 108
0 13 7 108 108 108
1 13 7 108 108 108
2 13 7 108 108 108
3 13 7 108 108 108
4 13 7 108 108 108
5 13 7 108 108 108
6 13 7 108 108 108
7 13 7 108 108 108
8 13 7 108 108 108
9 13 7 108 108 108
10 13 7 108 108 108
11 13 7 108 108 108
12 13 7 108 108 108
13 13 7 108 108 108
14 13 7 144 144 144
-15 14 7 144 144 144
-14 14 7 144 144 144
-13 14 7 144 144 144
-12 14 7 144 144 144
-11 14 7 144 144 144
-10 14 7 144 144 144
-9 14 7 144 144 144
-8 14 7 144 144 144
-7 14 7 144 144 144
-6 14 7 144 144 144
-5 14 7 144 144 144
-4 14 7 144 144 144
-3 14 7 144 144 144
-2 14 7 144 144 144
-1 14 7 144 144 144
0 14 7 144 144 144
1 14 7 144 144 144
2 14 7 144 144 144
3 14 7 144 144 144
4 14 7 144 144 144
5 14 7 144 144 144
6 14 7 144 144 144
7 14 7 144 144 144
8 14 7 144 144 144
9 14 7 144 144 144
10 14 7 144 144 144
11 14 7 144 144 144
12 14 7 144 144 144
13 14 7 144 144 144
14 14 7 144 144 144
-15 -15 8 144 144 144
-14 -15 8 144 144 144
-13 -15 8 144 144 144
-12 -15 8 144 144 144
-11 -15 8 144 144 144
-10 -15 8 144 144 144
-9 -15 8 144 144 144
-8 -15 8 144 144 144
-7 -15 8 144 144 144
-6 -15 8 144 144 144
-5 -15 8 144 144 144
-4 -15 8 144 144 144
-3 -15 8 144 144 144
-2 -15 8 144 144 144
-1 -15 8 144 144 144
0 -15 8 144 144 144
1 -15 8 144 144 144
2 -15 8 144 144 144
3 -15 8 144 144 144
4 -15 8 144 144 144
5 -15 8 144 144 144
6 -15 8 144 144 144
7 -15 8 144 144 144
8 -15 8 144 144 144
9 -15 8 144 144 144
10 -15 8 144 144 144
11 -15 8 144 144 144
12 -15 8 144 144 144
13 -15 8 144 144 144
14 -15 8 144 144 144
-15 -14 8 144 144 144
-14 -14 8 108 108 108
-13 -14 8 108 108 108
-12 -14 8 108 108 108
-11 -14 8 108 108 108
-10 -14 8 108 108 108
-9 -14 8 108 108 108
-8 -14 8 108 108 108
-7 -14 8 108 108 108
-6 -14 8 108 108 108
-5 -14 8 108 108 108
-4 -14 8 108 108 108
-3 -14 8 108 108 108
-2 -14 8 108 108 108
-1 -14 8 108 108 108
0 -14 8 108 108 108
1 -14 8 108 108 108
2 -14 8 108 108 108
3 -14 8 108 108 108
4 -14 8 108 108 108
5 -14 8 108 108 108
6 -14 8 108 108 108
7 -14 8 108 108 108
8 -14 8 108 108 108
9 -14 8 108 108 108
10 -14 8 108 108 108
11 -14 8 108 108 108
12 -14 8 108 108 108
13 -14 8 108 108 108
14 -14 8 144 144 144
-15 -13 8 144 144 144
-14 -13 8 108 108 108
-13 -13 8 108 108 108
-12 -13 8 52 92 28
-11 -13 8 52 92 28
-10 -13 8 108 108 108
-9 -13 8 108 108 108
-8 -13 8 108 108 108
-7 -13 8 108 108 108
-6 -13 8 108 108 108
-5 -13 8 108 108 108
-4 -13 8 108 108 108
-3 -13 8 108 108 108
-2 -13 8 108 108 108
-1 -13 8 108 108 108
0 -13 8 108 108 108
1 -13 8 108 108 108
2 -13 8 108 108 108
3 -13 8 108 108 108
4 -13 8 108 108 108
5 -13 8 52 92 28
6 -13 8 52 92 28
7 -13 8 108 108 108
8 -13 8 52 92 28
9 -13 8 52 92 28
10 -13 8 52 92 28
11 -13 8 52 92 28
12 -13 8 108 108 108
13 -13 8 108 108 108
14 -13 8 144 144 144
-15 -12 8 144 144 144
-14 -12 8 108 108 108
-13 -12 8 108 108 108
-12 -12 8 52 92 28
6 -12 8 52 92 28
9 -12 8 52 92 28
12 -12 8 52 92 28
13 -12 8 108 108 108
14 -12 8 144 144 144
-15 -11 8 144 144 144
-14 -11 8 108 108 108
-13 -11 8 108 108 108
12 -11 8 108 108 108
13 -11 8 108 108 108
14 -11 8 144 144 144
-15 -10 8 144 144 144
-14 -10 8 108 108 108
-13 -10 8 108 108 108
12 -10 8 108 108 108
13 -10 8 108 108 108
14 -10 8 144 144 144
-15 -9 8 144 144 144
-14 -9 8 108 108 108
-13 -9 8 108 108 108
12 -9 8 108 108 108
13 -9 8 108 108 108
14 -9 8 144 144 144
-15 -8 8 144 144 144
-14 -8 8 108 108 108
-13 -8 8 108 108 108
12 -8 8 108 108 108
13 -8 8 108 108 108
14 -8 8 144 144 144
-15 -7 8 144 144 144
-14 -7 8 108 108 108
-13 -7 8 108 108 108
12 -7 8 108 108 108
13 -7 8 108 108 108
14 -7 8 144 144 144
-15 -6 8 144 144 144
-14 -6 8 108 108 108
-13 -6 8 108 108 108
12 -6 8 52 92 28
13 -6 8 108 108 108
14 -6 8 144 144 144
-15 -5 8 144 144 144
-14 -5 8 108 108 108
-13 -5 8 108 108 108
12 -5 8 52 92 28
13 -5 8 108 108 108
14 -5 8 144 144 144
-15 -4 8 144 144 144
-14 -4 8 108 108 108
-13 -4 8 108 108 108
-12 -4 8 108 108 108
-11 -4 8 108 108 108
-10 -4 8 108 108 108
-9 -4 8 108 108 108
11 -4 8 52 92 28
12 -4 8 52 92 28
13 -4 8 108 108 108
14 -4 8 144 144 144
-15 -3 8 144 144 144
-14 -3 8 108 108 108
-13 -3 8 108 108 108
-9 -3 8 108 108 108
12 -3 8 52 92 28
13 -3 8 108 108 108
14 -3 8 144 144 144
-15 -2 8 144 144 144
-14 -2 8 108 108 108
-13 -2 8 108 108 108
-9 -2 8 108 108 108
12 -2 8 108 108 108
13 -2 8 108 108 108
14 -2 8 144 144 144
-15 -1 8 144 144 144
-14 -1 8 108 108 108
-13 -1 8 108 108 108
-9 -1 8 108 108 108
12 -1 8 108 108 108
13 -1 8 108 108 108
14 -1 8 144 144 144
-15 0 8 144 144 144
-14 0 8 108 108 108
-13 0 8 108 108 108
-9 0 8 108 108 108
12 0 8 108 108 108
13 0 8 108 108 108
14 0 8 144 144 144
-15 1 8 144 144 144
-14 1 8 108 108 108
-13 1 8 108 108 108
-9 1 8 108 108 108
12 1 8 52 92 28
13 1 8 108 108 108
14 1 8 144 144 144
-15 2 8 144 144 144
-14 2 8 108 108 108
-13 2 8 108 108 108
-9 2 8 108 108 108
11 2 8 52 92 28
12 2 8 52 92 28
13 2 8 108 108 108
14 2 8 144 144 144
-15 3 8 144 144 144
-14 3 8 108 108 108
-13 3 8 108 108 108
-12 3 8 108 108 108
-11 3 8 108 108 108
-10 3 8 108 108 108
-9 3 8 108 108 108
12 3 8 52 92 28
13 3 8 108 108 108
14 3 8 144 144 144
-15 4 8 144 144 144
-14 4 8 108 108 108
-13 4 8 108 108 108
12 4 8 108 108 108
13 4 8 108 108 108
14 4 8 144 144 144
-15 5 8 144 144 144
-14 5 8 108 108 108
-13 5 8 108 108 108
12 5 8 108 108 108
13 5 8 108 108 108
14 5 8 144 144 144
-15 6 8 144 144 144
-14 6 8 108 108 108
-13 6 8 108 108 108
12 6 8 108 108 108
13 6 8 108 108 108
14 6 8 144 144 144
-15 7 8 144 144 144
-14 7 8 108 108 108
-13 7 8 108 108 108
12 7 8 108 108 108
13 7 8 108 108 108
14 7 8 144 144 144
-15 8 8 144 144 144
-14 8 8 108 108 108
-13 8 8 108 108 108
12 8 8 108 108 108
13 8 8 108 108 108
14 8 8 144 144 144
-15 9 8 144 144 144
-14 9 8 108 108 108
-13 9 8 108 108 108
12 9 8 108 108 108
13 9 8 108 108 108
14 9 8 144 144 144
-15 10 8 144 144 144
-14 10 8 108 108 108
-13 10 8 108 108 108
12 10 8 52 92 28
13 10 8 108 108 108
14 10 8 144 144 144
-15 11 8 144 144 144
-14 11 8 108 108 108
-13 11 8 108 108 108
-12 11 8 52 92 28
1 11 8 52 92 28
2 11 8 52 92 28
3 11 8 52 92 28
11 11 8 52 92 28
12 11 8 52 92 28
13 11 8 108 108 108
14 11 8 144 144 144
-15 12 8 144 144 144
-14 12 8 108 108 108
-13 12 8 108 108 108
-12 12 8 52 92 28
-11 12 8 108 108 108
-10 12 8 108 108 108
-9 12 8 108 108 108
-8 12 8 108 108 108
-7 12 8 108 108 108
-6 12 8 108 108 108
-5 12 8 108 108 108
-4 12 8 108 108 108
-3 12 8 108 108 108
-2 12 8 108 108 108
-1 12 8 52 92 28
0 12 8 52 92 28
1 12 8 52 92 28
2 12 8 52 92 28
3 12 8 52 92 28
4 12 8 52 92 28
5 12 8 52 92 28
6 12 8 108 108 108
7 12 8 108 108 108
8 12 8 108 108 108
9 12 8 52 92 28
10 12 8 52 92 28
11 12 8 52 92 28
12 12 8 52 92 28
13 12 8 108 108 108
14 12 8 144 144 144
-15 13 8 144 144 144
-14 13 8 108 108 108
-13 13 8 108 108 108
-12 13 8 108 108 108
-11 13 8 108 108 108
-10 13 8 108 108 108
-9 13 8 108 108 108
-8 13 8 108 108 108
-7 13 8 108 108 108
-6 13 8 108 108 108
-5 13 8 108 108 108
-4 13 8 108 108 108
-3 13 8 108 108 108
-2 13 8 108 108 108
-1 13 8 108 108 108
0 13 8 108 108 108
1 13 8 108 108 108
2 13 8 108 108 108
3 13 8 108 108 108
4 13 8 108 108 108
5 13 8 108 108 108
6 13 8 108 108 108
7 13 8 108 108 108
8 13 8 108 108 108
9 13 8 108 108 108
10 13 8 108 108 108
11 13 8 108 108 108
12 13 8 108 108 108
13 13 8 108 108 108
14 13 8 144 144 144
-15 14 8 144 144 144
-14 14 8 144 144 144
-13 14 8 144 144 144
-12 14 8 144 144 144
-11 14 8 144 144 144
-10 14 8 144 144 144
-9 14 8 144 144 144
-8 14 8 144 144 144
-7 14 8 144 144 144
-6 14 8 144 144 144
-5 14 8 144 144 144
-4 14 8 144 144 144
-3 14 8 144 144 144
-2 14 8 144 144 144
-1 14 8 144 144 144
0 14 8 144 144 144
1 14 8 144 144 144
2 14 8 144 144 144
3 14 8 144 144 144
4 14 8 144 144 144
5 14 8 144 144 144
6 14 8 144 144 144
7 14 8 144 144 144
8 14 8 144 144 144
9 14 8 144 144 144
10 14 8 144 144 144
11 14 8 144 144 144
12 14 8 144 144 144
13 14 8 144 144 144
14 14 8 144 144 144
-15 -15 9 144 144 144
-14 -15 9 144 144 144
-13 -15 9 144 144 144
-12 -15 9 144 144 144
-11 -15 9 144 144 144
-10 -15 9 144 144 144
-9 -15 9 144 144 144
-8 -15 9 144 144 144
-7 -15 9 144 144 144
-6 -15 9 144 144 144
-5 -15 9 144 144 144
-4 -15 9 144 144 144
-3 -15 9 144 144 144
-2 -15 9 144 144 144
-1 -15 9 144 144 144
0 -15 9 144 144 144
1 -15 9 144 144 144
2 -15 9 144 144 144
3 -15 9 144 144 144
4 -15 9 144 144 144
5 -15 9 144 144 144
6 -15 9 144 144 144
7 -15 9 144 144 144
8 -15 9 144 144 144
9 -15 9 144 144 144
10 -15 9 144 144 144
11 -15 9 144 144 144
12 -15 9 144 144 144
13 -15 9 144 144 144
14 -15 9 144 144 144
-15 -14 9 144 144 144
-14 -14 9 108 108 108
-13 -14 9 108 108 108
-12 -14 9 108 108 108
-11 -14 9 108 108 108
-10 -14 9 108 108 108
-9 -14 9 108 108 108
-8 -14 9 108 108 108
-7 -14 9 108 108 108
-6 -14 9 108 108 108
-5 -14 9 108 108 108
-4 -14 9 108 108 108
-3 -14 9 108 108 108
-2 -14 9 108 108 108
-1 -14 9 108 108 108
0 -14 9 108 108 108
1 -14 9 108 108 108
2 -14 9 108 108 108
3 -14 9 108 108 108
4 -14 9 108 108 108
5 -14 9 108 108 108
6 -14 9 108 108 108
7 -14 9 108 108 108
8 -14 9 108 108 108
9 -14 9 108 108 108
10 -14 9 108 108 108
11 -14 9 108 108 108
12 -14 9 108 108 108
13 -14 9 108 108 108
14 -14 9 144 144 144
-15 -13 9 144 144 144
-14 -13 9 108 108 108
-13 -13 9 108 108 108
-12 -13 9 52 92 28
-11 -13 9 52 92 28
-10 -13 9 108 108 108
-9 -13 9 108 108 108
-8 -13 9 108 108 108
-7 -13 9 108 108 108
-6 -13 9 108 108 108
-5 -13 9 108 108 108
-4 -13 9 108 108 108
-3 -13 9 108 108 108
-2 -13 9 108 108 108
-1 -13 9 108 108 108
0 -13 9 108 108 108
1 -13 9 108 108 108
2 -13 9 108 108 108
3 -13 9 108 108 108
4 -13 9 108 108 108
5 -13 9 52 92 28
6 -13 9 52 92 28
7 -13 9 52 92 28
8 -13 9 52 92 28
9 -13 9 52 92 28
10 -13 9 108 108 108
11 -13 9 108 108 108
12 -13 9 108 108 108
13 -13 9 108 108 108
14 -13 9 144 144 144
-15 -12 9 144 144 144
-14 -12 9 108 108 108
-13 -12 9 108 108 108
-12 -12 9 52 92 28
6 -12 9 52 92 28
8 -12 9 52 92 28
12 -12 9 108 108 108
13 -12 9 108 108 108
14 -12 9 144 144 144
-15 -11 9 144 144 144
-14 -11 9 108 108 108
-13 -11 9 108 108 108
12 -11 9 108 108 108
13 -11 9 108 108 108
14 -11 9 144 144 144
-15 -10 9 144 144 144
-14 -10 9 108 108 108
-13 -10 9 108 108 108
12 -10 9 108 108 108
13 -10 9 108 108 108
14 -10 9 144 144 144
-15 -9 9 144 144 144
-14 -9 9 108 108 108
-13 -9 9 108 108 108
12 -9 9 108 108 108
13 -9 9 108 108 108
14 -9 9 144 144 144
-15 -8 9 144 144 144
-14 -8 9 108 108 108
-13 -8 9 108 108 108
12 -8 9 108 108 108
13 -8 9 108 108 108
14 -8 9 144 144 144
-15 -7 9 144 144 144
-14 -7 9 108 108 108
-13 -7 9 108 108 108
12 -7 9 108 108 108
13 -7 9 108 108 108
14 -7 9 144 144 144
-15 -6 9 144 144 144
-14 -6 9 108 108 108
-13 -6 9 108 108 108
12 -6 9 108 108 108
13 -6 9 108 108 108
14 -6 9 144 144 144
-15 -5 9 144 144 144
-14 -5 9 108 108 108
-13 -5 9 108 108 108
12 -5 9 108 108 108
13 -5 9 108 108 108
14 -5 9 144 144 144
-15 -4 9 144 144 144
-14 -4 9 108 108 108
-13 -4 9 108 108 108
-12 -4 9 108 108 108
-11 -4 9 108 108 108
-10 -4 9 108 108 108
-9 -4 9 108 108 108
12 -4 9 52 92 28
13 -4 9 108 108 108
14 -4 9 144 144 144
-15 -3 9 144 144 144
-14 -3 9 108 108 108
-13 -3 9 108 108 108
-9 -3 9 108 108 108
11 -3 9 52 92 28
12 -3 9 52 92 28
13 -3 9 108 108 108
14 -3 9 144 144 144
-15 -2 9 144 144 144
-14 -2 9 108 108 108
-13 -2 9 108 108 108
-9 -2 9 108 108 108
12 -2 9 52 92 28
13 -2 9 108 108 108
14 -2 9 144 144 144
-15 -1 9 144 144 144
-14 -1 9 108 108 108
-13 -1 9 108 108 108
-9 -1 9 108 108 108
12 -1 9 108 108 108
13 -1 9 108 108 108
14 -1 9 144 144 144
-15 0 9 144 144 144
-14 0 9 108 108 108
-13 0 9 108 108 108
-9 0 9 108 108 108
12 0 9 108 108 108
13 0 9 108 108 108
14 0 9 144 144 144
-15 1 9 144 144 144
-14 1 9 108 108 108
-13 1 9 108 108 108
-9 1 9 108 108 108
12 1 9 52 92 28
13 1 9 108 108 108
14 1 9 144 144 144
-15 2 9 144 144 144
-14 2 9 108 108 108
-13 2 9 108 108 108
-9 2 9 108 108 108
11 2 9 52 92 28
12 2 9 52 92 28
13 2 9 108 108 108
14 2 9 144 144 144
-15 3 9 144 144 144
-14 3 9 108 108 108
-13 3 9 108 108 108
-12 3 9 108 108 108
-11 3 9 108 108 108
-10 3 9 108 108 108
-9 3 9 108 108 108
12 3 9 52 92 28
13 3 9 108 108 108
14 3 9 144 144 144
-15 4 9 144 144 144
-14 4 9 108 108 108
-13 4 9 108 108 108
12 4 9 108 108 108
13 4 9 108 108 108
14 4 9 144 144 144
-15 5 9 144 144 144
-14 5 9 108 108 108
-13 5 9 108 108 108
12 5 9 108 108 108
13 5 9 108 108 108
14 5 9 144 144 144
-15 6 9 144 144 144
-14 6 9 108 108 108
-13 6 9 108 108 108
-7 6 9 52 92 28
12 6 9 108 108 108
13 6 9 108 108 108
14 6 9 144 144 144
-15 7 9 144 144 144
-14 7 9 108 108 108
-13 7 9 108 108 108
12 7 9 108 108 108
13 7 9 108 108 108
14 7 9 144 144 144
-15 8 9 144 144 144
-14 8 9 108 108 108
-13 8 9 108 108 108
12 8 9 108 108 108
13 8 9 108 108 108
14 8 9 144 144 144
-15 9 9 144 144 144
-14 9 9 108 108 108
-13 9 9 108 108 108
12 9 9 108 108 108
13 9 9 108 108 108
14 9 9 144 144 144
-15 10 9 144 144 144
-14 10 9 108 108 108
-13 10 9 108 108 108
12 10 9 52 92 28
13 10 9 108 108 108
14 10 9 144 144 144
-15 11 9 144 144 144
-14 11 9 108 108 108
-13 11 9 108 108 108
-12 11 9 52 92 28
-1 11 9 52 92 28
0 11 9 52 92 28
4 11 9 52 92 28
5 11 9 52 92 28
11 11 9 52 92 28
12 11 9 52 92 28
13 11 9 108 108 108
14 11 9 144 144 144
-15 12 9 144 144 144
-14 12 9 108 108 108
-13 12 9 108 108 108
-12 12 9 52 92 28
-11 12 9 108 108 108
-10 12 9 108 108 108
-9 12 9 108 108 108
-8 12 9 108 108 108
-7 12 9 108 108 108
-6 12 9 108 108 108
-5 12 9 108 108 108
-4 12 9 108 108 108
-3 12 9 108 108 108
-2 12 9 52 92 28
-1 12 9 52 92 28
0 12 9 52 92 28
1 12 9 52 92 28
2 12 9 52 92 28
3 12 9 52 92 28
4 12 9 52 92 28
5 12 9 52 92 28
6 12 9 52 92 28
7 12 9 108 108 108
8 12 9 108 108 108
9 12 9 108 108 108
10 12 9 52 92 28
11 12 9 52 92 28
12 12 9 52 92 28
13 12 9 108 108 108
14 12 9 144 144 144
-15 13 9 144 144 144
-14 13 9 108 108 108
-13 13 9 108 108 108
-12 13 9 108 108 108
-11 13 9 108 108 108
-10 13 9 108 108 108
-9 13 9 108 108 108
-8 13 9 108 108 108
-7 13 9 108 108 108
-6 13 9 108 108 108
-5 13 9 108 108 108
-4 13 9 108 108 108
-3 13 9 108 108 108
-2 13 9 108 108 108
-1 13 9 108 108 108
0 13 9 108 108 108
1 13 9 108 108 108
2 13 9 108 108 108
3 13 9 108 108 108
4 13 9 108 108 108
5 13 9 108 108 108
6 13 9 108 108 108
7 13 9 108 108 108
8 13 9 108 108 108
9 13 9 108 108 108
10 13 9 108 108 108
11 13 9 108 108 108
12 13 9 108 108 108
13 13 9 108 108 108
14 13 9 144 144 144
-15 14 9 144 144 144
-14 14 9 144 144 144
-13 14 9 144 144 144
-12 14 9 144 144 144
-11 14 9 144 144 144
-10 14 9 144 144 144
-9 14 9 144 144 144
-8 14 9 144 144 144
-7 14 9 144 144 144
-6 14 9 144 144 144
-5 14 9 144 144 144
-4 14 9 144 144 144
-3 14 9 144 144 144
-2 14 9 144 144 144
-1 14 9 144 144 144
0 14 9 144 144 144
1 14 9 144 144 144
2 14 9 144 144 144
3 14 9 144 144 144
4 14 9 144 144 144
5 14 9 144 144 144
6 14 9 144 144 144
7 14 9 144 144 144
8 14 9 144 144 144
9 14 9 144 144 144
10 14 9 144 144 144
11 14 9 144 144 144
12 14 9 144 144 144
13 14 9 144 144 144
14 14 9 144 144 144
-15 -15 10 144 144 144
-14 -15 10 144 144 144
-13 -15 10 144 144 144
-12 -15 10 144 144 144
-11 -15 10 144 144 144
-10 -15 10 144 144 144
-9 -15 10 144 144 144
-8 -15 10 144 144 144
-7 -15 10 144 144 144
-6 -15 10 144 144 144
-5 -15 10 144 144 144
-4 -15 10 144 144 144
-3 -15 10 144 144 144
-2 -15 10 144 144 144
-1 -15 10 144 144 144
0 -15 10 144 144 144
1 -15 10 144 144 144
2 -15 10 144 144 144
3 -15 10 144 144 144
4 -15 10 144 144 144
5 -15 10 144 144 144
6 -15 10 144 144 144
7 -15 10 144 144 144
8 -15 10 144 144 144
9 -15 10 144 144 144
10 -15 10 144 144 144
11 -15 10 144 144 144
12 -15 10 144 144 144
13 -15 10 144 144 144
14 -15 10 144 144 144
-15 -14 10 144 144 144
-14 -14 10 108 108 108
-13 -14 10 108 108 108
-12 -14 10 108 108 108
-11 -14 10 108 108 108
-10 -14 10 108 108 108
-9 -14 10 108 108 108
-8 -14 10 108 108 108
-7 -14 10 108 108 108
-6 -14 10 108 108 108
-5 -14 10 108 108 108
-4 -14 10 108 108 108
-3 -14 10 108 108 108
-2 -14 10 108 108 108
-1 -14 10 108 108 108
0 -14 10 108 108 108
1 -14 10 108 108 108
2 -14 10 108 108 108
3 -14 10 108 108 108
4 -14 10 108 108 108
5 -14 10 108 108 108
6 -14 10 108 108 108
7 -14 10 108 108 108
8 -14 10 108 108 108
9 -14 10 108 108 108
10 -14 10 108 108 108
11 -14 10 108 108 108
12 -14 10 108 108 108
13 -14 10 108 108 108
14 -14 10 144 144 144
-15 -13 10 144 144 144
-14 -13 10 108 108 108
-13 -13 10 108 108 108
-12 -13 10 52 92 28
-11 -13 10 52 92 28
-10 -13 10 108 108 108
-9 -13 10 108 108 108
-8 -13 10 108 108 108
-7 -13 10 108 108 108
-6 -13 10 108 108 108
-5 -13 10 108 108 108
-4 -13 10 108 108 108
-3 -13 10 108 108 108
-2 -13 10 108 108 108
-1 -13 10 108 108 108
0 -13 10 108 108 108
1 -13 10 108 108 108
2 -13 10 108 108 108
3 -13 10 108 108 108
4 -13 10 108 108 108
5 -13 10 108 108 108
6 -13 10 52 92 28
7 -13 10 52 92 28
8 -13 10 52 92 28
9 -13 10 108 108 108
10 -13 10 108 108 108
11 -13 10 108 108 108
12 -13 10 108 108 108
13 -13 10 108 108 108
14 -13 10 144 144 144
-15 -12 10 144 144 144
-14 -12 10 108 108 108
-13 -12 10 108 108 108
-12 -12 10 52 92 28
7 -12 10 52 92 28
12 -12 10 108 108 108
13 -12 10 108 108 108
14 -12 10 144 144 144
-15 -11 10 144 144 144
-14 -11 10 108 108 108
-13 -11 10 108 108 108
12 -11 10 108 108 108
13 -11 10 108 108 108
14 -11 10 144 144 144
-15 -10 10 144 144 144
-14 -10 10 108 108 108
-13 -10 10 108 108 108
12 -10 10 108 108 108
13 -10 10 108 108 108
14 -10 10 144 144 144
-15 -9 10 144 144 144
-14 -9 10 108 108 108
-13 -9 10 108 108 108
12 -9 10 108 108 108
13 -9 10 108 108 108
14 -9 10 144 144 144
-15 -8 10 144 144 144
-14 -8 10 108 108 108
-13 -8 10 108 108 108
12 -8 10 108 108 108
13 -8 10 108 108 108
14 -8 10 144 144 144
-15 -7 10 144 144 144
-14 -7 10 108 108 108
-13 -7 10 108 108 108
12 -7 10 108 108 108
13 -7 10 108 108 108
14 -7 10 144 144 144
-15 -6 10 144 144 144
-14 -6 10 108 108 108
-13 -6 10 108 108 108
-3 -6 10 52 92 28
12 -6 10 108 108 108
13 -6 10 108 108 108
14 -6 10 144 144 144
-15 -5 10 144 144 144
-14 -5 10 108 108 108
-13 -5 10 108 108 108
12 -5 10 108 108 108
13 -5 10 108 108 108
14 -5 10 144 144 144
-15 -4 10 144 144 144
-14 -4 10 108 108 108
-13 -4 10 108 108 108
-12 -4 10 108 108 108
-11 -4 10 108 108 108
-10 -4 10 108 108 108
-9 -4 10 108 108 108
12 -4 10 52 92 28
13 -4 10 108 108 108
14 -4 10 144 144 144
-15 -3 10 144 144 144
-14 -3 10 108 108 108
-9 -3 10 108 108 108
11 -3 10 52 92 28
12 -3 10 52 92 28
13 -3 10 108 108 108
14 -3 10 144 144 144
-15 -2 10 144 144 144
-14 -2 10 108 108 108
-9 -2 10 108 108 108
12 -2 10 52 92 28
13 -2 10 108 108 108
14 -2 10 144 144 144
-15 -1 10 144 144 144
-14 -1 10 108 108 108
-9 -1 10 108 108 108
12 -1 10 108 108 108
13 -1 10 108 108 108
14 -1 10 144 144 144
-15 0 10 144 144 144
-14 0 10 108 108 108
-9 0 10 108 108 108
12 0 10 108 108 108
13 0 10 108 108 108
14 0 10 144 144 144
-15 1 10 144 144 144
-14 1 10 108 108 108
-9 1 10 108 108 108
12 1 10 52 92 28
13 1 10 108 108 108
14 1 10 144 144 144
-15 2 10 144 144 144
-14 2 10 108 108 108
-9 2 10 108 108 108
11 2 10 52 92 28
12 2 10 52 92 28
13 2 10 108 108 108
14 2 10 144 144 144
-15 3 10 144 144 144
-14 3 10 108 108 108
-13 3 10 108 108 108
-12 3 10 108 108 108
-11 3 10 108 108 108
-10 3 10 108 108 108
-9 3 10 108 108 108
12 3 10 52 92 28
13 3 10 108 108 108
14 3 10 144 144 144
-15 4 10 144 144 144
-14 4 10 108 108 108
-13 4 10 108 108 108
5 4 10 52 92 28
12 4 10 108 108 108
13 4 10 108 108 108
14 4 10 144 144 144
-15 5 10 144 144 144
-14 5 10 108 108 108
-13 5 10 108 108 108
12 5 10 108 108 108
13 5 10 108 108 108
14 5 10 144 144 144
-15 6 10 144 144 144
-14 6 10 108 108 108
-13 6 10 108 108 108
-7 6 10 52 92 28
12 6 10 108 108 108
13 6 10 108 108 108
14 6 10 144 144 144
-15 7 10 144 144 144
-14 7 10 108 108 108
-13 7 10 108 108 108
12 7 10 108 108 108
13 7 10 108 108 108
14 7 10 144 144 144
-15 8 10 144 144 144
-14 8 10 108 108 108
-13 8 10 108 108 108
12 8 10 108 108 108
13 8 10 108 108 108
14 8 10 144 144 144
-15 9 10 144 144 144
-14 9 10 108 108 108
-13 9 10 108 108 108
12 9 10 108 108 108
13 9 10 108 108 108
14 9 10 144 144 144
-15 10 10 144 144 144
-14 10 10 108 108 108
-13 10 10 108 108 108
12 10 10 52 92 28
13 10 10 108 108 108
14 10 10 144 144 144
-15 11 10 144 144 144
-14 11 10 108 108 108
-13 11 10 108 108 108
-12 11 10 52 92 28
-2 11 10 52 92 28
6 11 10 52 92 28
11 11 10 52 92 28
12 11 10 52 92 28
13 11 10 108 108 108
14 11 10 144 144 144
-15 12 10 144 144 144
-14 12 10 108 108 108
-13 12 10 108 108 108
-12 12 10 52 92 28
-11 12 10 52 92 28
-10 12 10 108 108 108
-9 12 10 108 108 108
-8 12 10 108 108 108
-7 12 10 108 108 108
-6 12 10 108 108 108
-5 12 10 108 108 108
-4 12 10 108 108 108
-3 12 10 52 92 28
-2 12 10 52 92 28
-1 12 10 52 92 28
0 12 10 52 92 28
1 12 10 108 108 108
2 12 10 108 108 108
3 12 10 108 108 108
4 12 10 52 92 28
5 12 10 52 92 28
6 12 10 52 92 28
7 12 10 52 92 28
8 12 10 108 108 108
9 12 10 108 108 108
10 12 10 52 92 28
11 12 10 52 92 28
12 12 10 52 92 28
13 12 10 108 108 108
14 12 10 144 144 144
-15 13 10 144 144 144
-14 13 10 108 108 108
-13 13 10 108 108 108
-12 13 10 108 108 108
-11 13 10 108 108 108
-10 13 10 108 108 108
-9 13 10 108 108 108
-8 13 10 108 108 108
-7 13 10 108 108 108
-6 13 10 108 108 108
-5 13 10 108 108 108
-4 13 10 108 108 108
-3 13 10 108 108 108
-2 13 10 108 108 108
-1 13 10 108 108 108
0 13 10 108 108 108
1 13 10 108 108 108
2 13 10 108 108 108
3 13 10 108 108 108
4 13 10 108 108 108
5 13 10 108 108 108
6 13 10 108 108 108
7 13 10 108 108 108
8 13 10 108 108 108
9 13 10 108 108 108
10 13 10 108 108 108
11 13 10 108 108 108
12 13 10 108 108 108
13 13 10 108 108 108
14 13 10 144 144 144
-15 14 10 144 144 144
-14 14 10 144 144 144
-13 14 10 144 144 144
-12 14 10 144 144 144
-11 14 10 144 144 144
-10 14 10 144 144 144
-9 14 10 144 144 144
-8 14 10 144 144 144
-7 14 10 144 144 144
-6 14 10 144 144 144
-5 14 10 144 144 144
-4 14 10 144 144 144
-3 14 10 144 144 144
-2 14 10 144 144 144
-1 14 10 144 144 144
0 14 10 144 144 144
1 14 10 144 144 144
2 14 10 144 144 144
3 14 10 144 144 144
4 14 10 144 144 144
5 14 10 144 144 144
6 14 10 144 144 144
7 14 10 144 144 144
8 14 10 144 144 144
9 14 10 144 144 144
10 14 10 144 144 144
11 14 10 144 144 144
12 14 10 144 144 144
13 14 10 144 144 144
14 14 10 144 144 144
-15 -15 11 144 144 144
-14 -15 11 144 144 144
-13 -15 11 144 144 144
-12 -15 11 144 144 144
-11 -15 11 144 144 144
-10 -15 11 144 144 144
-9 -15 11 144 144 144
-8 -15 11 144 144 144
-7 -15 11 144 144 144
-6 -15 11 144 144 144
-5 -15 11 144 144 144
-4 -15 11 144 144 144
-3 -15 11 144 144 144
-2 -15 11 144 144 144
-1 -15 11 144 144 144
0 -15 11 144 144 144
1 -15 11 144 144 144
2 -15 11 144 144 144
3 -15 11 144 144 144
4 -15 11 144 144 144
5 -15 11 144 144 144
6 -15 11 144 144 144
7 -15 11 144 144 144
8 -15 11 144 144 144
9 -15 11 144 144 144
10 -15 11 144 144 144
11 -15 11 144 144 144
12 -15 11 144 144 144
13 -15 11 144 144 144
14 -15 11 144 144 144
-15 -14 11 144 144 144
-14 -14 11 108 108 108
-13 -14 11 108 108 108
-12 -14 11 108 108 108
-11 -14 11 108 108 108
-10 -14 11 108 108 108
-9 -14 11 108 108 108
-8 -14 11 108 108 108
-7 -14 11 108 108 108
-6 -14 11 108 108 108
-5 -14 11 108 108 108
-4 -14 11 108 108 108
-3 -14 11 108 108 108
-2 -14 11 108 108 108
-1 -14 11 108 108 108
0 -14 11 108 108 108
1 -14 11 108 108 108
2 -14 11 108 108 108
3 -14 11 108 108 108
4 -14 11 108 108 108
5 -14 11 108 108 108
6 -14 11 108 108 108
7 -14 11 108 108 108
8 -14 11 108 108 108
9 -14 11 108 108 108
10 -14 11 108 108 108
11 -14 11 108 108 108
12 -14 11 108 108 108
13 -14 11 108 108 108
14 -14 11 144 144 144
-15 -13 11 144 144 144
-14 -13 11 108 108 108
-13 -13 11 108 108 108
-12 -13 11 52 92 28
-11 -13 11 52 92 28
-10 -13 11 108 108 108
-9 -13 11 108 108 108
-8 -13 11 108 108 108
-7 -13 11 108 108 108
-6 -13 11 108 108 108
-5 -13 11 108 108 108
-4 -13 11 108 108 108
-3 -13 11 108 108 108
-2 -13 11 108 108 108
-1 -13 11 108 108 108
0 -13 11 108 108 108
1 -13 11 108 108 108
2 -13 11 108 108 108
3 -13 11 108 108 108
4 -13 11 108 108 108
5 -13 11 108 108 108
6 -13 11 52 92 28
7 -13 11 52 92 28
8 -13 11 52 92 28
9 -13 11 108 108 108
10 -13 11 108 108 108
11 -13 11 108 108 108
12 -13 11 108 108 108
13 -13 11 108 108 108
14 -13 11 144 144 144
-15 -12 11 144 144 144
-14 -12 11 108 108 108
-13 -12 11 108 108 108
-12 -12 11 52 92 28
7 -12 11 52 92 28
12 -12 11 108 108 108
13 -12 11 108 108 108
14 -12 11 144 144 144
-15 -11 11 144 144 144
-14 -11 11 108 108 108
-13 -11 11 108 108 108
-12 -11 11 52 92 28
12 -11 11 108 108 108
13 -11 11 108 108 108
14 -11 11 144 144 144
-15 -10 11 144 144 144
-14 -10 11 108 108 108
-13 -10 11 108 108 108
12 -10 11 108 108 108
13 -10 11 108 108 108
14 -10 11 144 144 144
-15 -9 11 144 144 144
-14 -9 11 108 108 108
-13 -9 11 108 108 108
12 -9 11 108 108 108
13 -9 11 108 108 108
14 -9 11 144 144 144
-15 -8 11 144 144 144
-14 -8 11 108 108 108
-13 -8 11 108 108 108
12 -8 11 108 108 108
13 -8 11 108 108 108
14 -8 11 144 144 144
-15 -7 11 144 144 144
-14 -7 11 108 108 108
-13 -7 11 108 108 108
12 -7 11 108 108 108
13 -7 11 108 108 108
14 -7 11 144 144 144
-15 -6 11 144 144 144
-14 -6 11 108 108 108
-13 -6 11 108 108 108
-3 -6 11 52 92 28
12 -6 11 108 108 108
13 -6 11 108 108 108
14 -6 11 144 144 144
-15 -5 11 144 144 144
-14 -5 11 108 108 108
-13 -5 11 108 108 108
12 -5 11 108 108 108
13 -5 11 108 108 108
14 -5 11 144 144 144
-15 -4 11 144 144 144
-14 -4 11 108 108 108
-13 -4 11 108 108 108
-12 -4 11 108 108 108
-11 -4 11 108 108 108
-10 -4 11 108 108 108
-9 -4 11 108 108 108
12 -4 11 52 92 28
13 -4 11 108 108 108
14 -4 11 144 144 144
-9 -3 11 108 108 108
11 -3 11 52 92 28
12 -3 11 52 92 28
13 -3 11 108 108 108
14 -3 11 144 144 144
-9 -2 11 108 108 108
12 -2 11 52 92 28
13 -2 11 108 108 108
14 -2 11 144 144 144
-9 -1 11 108 108 108
12 -1 11 108 108 108
13 -1 11 108 108 108
14 -1 11 144 144 144
-9 0 11 108 108 108
12 0 11 108 108 108
13 0 11 108 108 108
14 0 11 144 144 144
-9 1 11 108 108 108
12 1 11 52 92 28
13 1 11 108 108 108
14 1 11 144 144 144
-9 2 11 108 108 108
11 2 11 52 92 28
12 2 11 52 92 28
13 2 11 108 108 108
14 2 11 144 144 144
-15 3 11 144 144 144
-14 3 11 108 108 108
-13 3 11 108 108 108
-12 3 11 108 108 108
-11 3 11 108 108 108
-10 3 11 108 108 108
-9 3 11 108 108 108
12 3 11 52 92 28
13 3 11 108 108 108
14 3 11 144 144 144
-15 4 11 144 144 144
-14 4 11 108 108 108
-13 4 11 108 108 108
5 4 11 52 92 28
12 4 11 108 108 108
13 4 11 108 108 108
14 4 11 144 144 144
-15 5 11 144 144 144
-14 5 11 108 108 108
-13 5 11 108 108 108
12 5 11 108 108 108
13 5 11 108 108 108
14 5 11 144 144 144
-15 6 11 144 144 144
-14 6 11 108 108 108
-13 6 11 108 108 108
-7 6 11 52 92 28
12 6 11 108 108 108
13 6 11 108 108 108
14 6 11 144 144 144
-15 7 11 144 144 144
-14 7 11 108 108 108
-13 7 11 108 108 108
12 7 11 108 108 108
13 7 11 108 108 108
14 7 11 144 144 144
-15 8 11 144 144 144
-14 8 11 108 108 108
-13 8 11 108 108 108
12 8 11 108 108 108
13 8 11 108 108 108
14 8 11 144 144 144
-15 9 11 144 144 144
-14 9 11 108 108 108
-13 9 11 108 108 108
12 9 11 108 108 108
13 9 11 108 108 108
14 9 11 144 144 144
-15 10 11 144 144 144
-14 10 11 108 108 108
-13 10 11 108 108 108
12 10 11 52 92 28
13 10 11 108 108 108
14 10 11 144 144 144
-15 11 11 144 144 144
-14 11 11 108 108 108
-13 11 11 108 108 108
-12 11 11 52 92 28
-3 11 11 52 92 28
7 11 11 52 92 28
11 11 11 52 92 28
12 11 11 52 92 28
13 11 11 108 108 108
14 11 11 144 144 144
-15 12 11 144 144 144
-14 12 11 108 108 108
-13 12 11 108 108 108
-12 12 11 52 92 28
-11 12 11 52 92 28
-10 12 11 108 108 108
-9 12 11 108 108 108
-8 12 11 108 108 108
-7 12 11 108 108 108
-6 12 11 108 108 108
-5 12 11 108 108 108
-4 12 11 52 92 28
-3 12 11 52 92 28
-2 12 11 52 92 28
-1 12 11 108 108 108
0 12 11 108 108 108
1 12 11 108 108 108
2 12 11 108 108 108
3 12 11 108 108 108
4 12 11 108 108 108
5 12 11 108 108 108
6 12 11 52 92 28
7 12 11 52 92 28
8 12 11 52 92 28
9 12 11 108 108 108
10 12 11 52 92 28
11 12 11 52 92 28
12 12 11 52 92 28
13 12 11 108 108 108
14 12 11 144 144 144
-15 13 11 144 144 144
-14 13 11 108 108 108
-13 13 11 108 108 108
-12 13 11 108 108 108
-11 13 11 108 108 108
-10 13 11 108 108 108
-9 13 11 108 108 108
-8 13 11 108 108 108
-7 13 11 108 108 108
-6 13 11 108 108 108
-5 13 11 108 108 108
-4 13 11 108 108 108
-3 13 11 108 108 108
-2 13 11 108 108 108
-1 13 11 108 108 108
0 13 11 108 108 108
1 13 11 108 108 108
2 13 11 108 108 108
3 13 11 108 108 108
4 13 11 108 108 108
5 13 11 108 108 108
6 13 11 108 108 108
7 13 11 108 108 108
8 13 11 108 108 108
9 13 11 108 108 108
10 13 11 108 108 108
11 13 11 108 108 108
12 13 11 108 108 108
13 13 11 108 108 108
14 13 11 144 144 144
-15 14 11 144 144 144
-14 14 11 144 144 144
-13 14 11 144 144 144
-12 14 11 144 144 144
-11 14 11 144 144 144
-10 14 11 144 144 144
-9 14 11 144 144 144
-8 14 11 144 144 144
-7 14 11 144 144 144
-6 14 11 144 144 144
-5 14 11 144 144 144
-4 14 11 144 144 144
-3 14 11 144 144 144
-2 14 11 144 144 144
-1 14 11 144 144 144
0 14 11 144 144 144
1 14 11 144 144 144
2 14 11 144 144 144
3 14 11 144 144 144
4 14 11 144 144 144
5 14 11 144 144 144
6 14 11 144 144 144
7 14 11 144 144 144
8 14 11 144 144 144
9 14 11 144 144 144
10 14 11 144 144 144
11 14 11 144 144 144
12 14 11 144 144 144
13 14 11 144 144 144
14 14 11 144 144 144
-15 -15 12 144 144 144
-14 -15 12 144 144 144
-13 -15 12 144 144 144
-12 -15 12 144 144 144
-11 -15 12 144 144 144
-10 -15 12 144 144 144
-9 -15 12 144 144 144
-8 -15 12 144 144 144
-7 -15 12 144 144 144
-6 -15 12 144 144 144
-5 -15 12 144 144 144
-4 -15 12 144 144 144
-3 -15 12 144 144 144
-2 -15 12 144 144 144
-1 -15 12 144 144 144
0 -15 12 144 144 144
1 -15 12 144 144 144
2 -15 12 144 144 144
3 -15 12 144 144 144
4 -15 12 144 144 144
5 -15 12 144 144 144
6 -15 12 144 144 144
7 -15 12 144 144 144
8 -15 12 144 144 144
9 -15 12 144 144 144
10 -15 12 144 144 144
11 -15 12 144 144 144
12 -15 12 144 144 144
13 -15 12 144 144 144
14 -15 12 144 144 144
-15 -14 12 144 144 144
-14 -14 12 108 108 108
-13 -14 12 108 108 108
-12 -14 12 108 108 108
-11 -14 12 108 108 108
-10 -14 12 108 108 108
-9 -14 12 108 108 108
-8 -14 12 108 108 108
-7 -14 12 108 108 108
-6 -14 12 108 108 108
-5 -14 12 108 108 108
-4 -14 12 108 108 108
-3 -14 12 108 108 108
-2 -14 12 108 108 108
-1 -14 12 108 108 108
0 -14 12 108 108 108
1 -14 12 108 108 108
2 -14 12 108 108 108
3 -14 12 108 108 108
4 -14 12 108 108 108
5 -14 12 108 108 108
6 -14 12 108 108 108
7 -14 12 108 108 108
8 -14 12 108 108 108
9 -14 12 108 108 108
10 -14 12 108 108 108
11 -14 12 108 108 108
12 -14 12 108 108 108
13 -14 12 108 108 108
14 -14 12 144 144 144
-15 -13 12 144 144 144
-14 -13 12 108 108 108
-13 -13 12 108 108 108
-12 -13 12 52 92 28
-11 -13 12 52 92 28
-10 -13 12 52 92 28
-9 -13 12 108 108 108
-8 -13 12 108 108 108
-7 -13 12 108 108 108
-6 -13 12 108 108 108
-5 -13 12 108 108 108
-4 -13 12 108 108 108
-3 -13 12 108 108 108
-2 -13 12 108 108 108
-1 -13 12 108 108 108
0 -13 12 108 108 108
1 -13 12 108 108 108
2 -13 12 108 108 108
3 -13 12 108 108 108
4 -13 12 108 108 108
5 -13 12 108 108 108
6 -13 12 52 92 28
7 -13 12 52 92 28
8 -13 12 52 92 28
9 -13 12 108 108 108
10 -13 12 108 108 108
11 -13 12 108 108 108
12 -13 12 108 108 108
13 -13 12 108 108 108
14 -13 12 144 144 144
-15 -12 12 144 144 144
-14 -12 12 108 108 108
-13 -12 12 108 108 108
-12 -12 12 52 92 28
7 -12 12 52 92 28
12 -12 12 108 108 108
13 -12 12 108 108 108
14 -12 12 144 144 144
-15 -11 12 144 144 144
-14 -11 12 108 108 108
-13 -11 12 108 108 108
-12 -11 12 52 92 28
12 -11 12 108 108 108
13 -11 12 108 108 108
14 -11 12 144 144 144
-15 -10 12 144 144 144
-14 -10 12 108 108 108
-13 -10 12 108 108 108
12 -10 12 108 108 108
13 -10 12 108 108 108
14 -10 12 144 144 144
-15 -9 12 144 144 144
-14 -9 12 108 108 108
-13 -9 12 108 108 108
12 -9 12 108 108 108
13 -9 12 108 108 108
14 -9 12 144 144 144
-15 -8 12 144 144 144
-14 -8 12 108 108 108
-13 -8 12 108 108 108
12 -8 12 108 108 108
13 -8 12 108 108 108
14 -8 12 144 144 144
-15 -7 12 144 144 144
-14 -7 12 108 108 108
-13 -7 12 108 108 108
12 -7 12 108 108 108
13 -7 12 108 108 108
14 -7 12 144 144 144
-15 -6 12 144 144 144
-14 -6 12 108 108 108
-13 -6 12 108 108 108
-3 -6 12 52 92 28
12 -6 12 108 108 108
13 -6 12 108 108 108
14 -6 12 144 144 144
-15 -5 12 144 144 144
-14 -5 12 108 108 108
-13 -5 12 108 108 108
12 -5 12 108 108 108
13 -5 12 108 108 108
14 -5 12 144 144 144
-15 -4 12 144 144 144
-14 -4 12 108 108 108
-13 -4 12 108 108 108
-12 -4 12 108 108 108
-11 -4 12 108 108 108
-10 -4 12 108 108 108
-9 -4 12 108 108 108
12 -4 12 108 108 108
13 -4 12 108 108 108
14 -4 12 144 144 144
-9 -3 12 108 108 108
12 -3 12 52 92 28
13 -3 12 108 108 108
14 -3 12 144 144 144
-9 -2 12 108 108 108
5 -2 12 52 92 28
11 -2 12 52 92 28
12 -2 12 52 92 28
13 -2 12 108 108 108
14 -2 12 144 144 144
-9 -1 12 108 108 108
12 -1 12 108 108 108
13 -1 12 108 108 108
14 -1 12 144 144 144
-9 0 12 108 108 108
12 0 12 52 92 28
13 0 12 108 108 108
14 0 12 144 144 144
-9 1 12 108 108 108
11 1 12 52 92 28
12 1 12 52 92 28
13 1 12 108 108 108
14 1 12 144 144 144
-9 2 12 108 108 108
11 2 12 52 92 28
12 2 12 52 92 28
13 2 12 108 108 108
14 2 12 144 144 144
-15 3 12 144 144 144
-14 3 12 108 108 108
-13 3 12 108 108 108
-12 3 12 108 108 108
-11 3 12 108 108 108
-10 3 12 108 108 108
-9 3 12 108 108 108
12 3 12 52 92 28
13 3 12 108 108 108
14 3 12 144 144 144
-15 4 12 144 144 144
-14 4 12 108 108 108
-13 4 12 108 108 108
5 4 12 52 92 28
12 4 12 108 108 108
13 4 12 108 108 108
14 4 12 144 144 144
-15 5 12 144 144 144
-14 5 12 108 108 108
-13 5 12 108 108 108
12 5 12 108 108 108
13 5 12 108 108 108
14 5 12 144 144 144
-15 6 12 144 144 144
-14 6 12 108 108 108
-13 6 12 108 108 108
-7 6 12 52 92 28
-6 6 12 52 92 28
12 6 12 108 108 108
13 6 12 108 108 108
14 6 12 144 144 144
-15 7 12 144 144 144
-14 7 12 108 108 108
-13 7 12 108 108 108
-7 7 12 52 92 28
12 7 12 108 108 108
13 7 12 108 108 108
