ply
format ascii 1.0
comment : MagicaVoxel @ Ephtracy
element vertex 1376
property float x
property float y
property float z
property uchar red
property uchar green
property uchar blue
end_header
-10 -10 0 238 238 238
-9 -10 0 238 238 238
-8 -10 0 17 17 17
-7 -10 0 238 238 238
-6 -10 0 17 17 17
-5 -10 0 238 238 238
-4 -10 0 17 17 17
-3 -10 0 238 238 238
-2 -10 0 238 238 238
-1 -10 0 238 238 238
0 -10 0 238 238 238
1 -10 0 238 238 238
2 -10 0 238 238 238
3 -10 0 238 238 238
4 -10 0 238 238 238
5 -10 0 238 238 238
6 -10 0 238 238 238
7 -10 0 238 238 238
8 -10 0 238 238 238
9 -10 0 238 238 238
-10 -9 0 238 238 238
-9 -9 0 17 17 17
-8 -9 0 238 238 238
-7 -9 0 17 17 17
-6 -9 0 238 238 238
-5 -9 0 17 17 17
-4 -9 0 238 238 238
-3 -9 0 17 17 17
-2 -9 0 238 238 238
-1 -9 0 17 17 17
0 -9 0 238 238 238
1 -9 0 17 17 17
2 -9 0 238 238 238
3 -9 0 17 17 17
4 -9 0 238 238 238
5 -9 0 17 17 17
6 -9 0 238 238 238
7 -9 0 17 17 17
8 -9 0 238 238 238
9 -9 0 136 136 136
-10 -8 0 17 17 17
-9 -8 0 238 238 238
-8 -8 0 17 17 17
-7 -8 0 238 238 238
-6 -8 0 17 17 17
-5 -8 0 238 238 238
-4 -8 0 17 17 17
-3 -8 0 238 238 238
-2 -8 0 17 17 17
-1 -8 0 238 238 238
0 -8 0 17 17 17
1 -8 0 238 238 238
2 -8 0 17 17 17
3 -8 0 238 238 238
4 -8 0 17 17 17
5 -8 0 238 238 238
6 -8 0 17 17 17
7 -8 0 238 238 238
8 -8 0 17 17 17
9 -8 0 136 136 136
-10 -7 0 238 238 238
-9 -7 0 17 17 17
-8 -7 0 238 238 238
-7 -7 0 17 17 17
-6 -7 0 238 238 238
-5 -7 0 17 17 17
-4 -7 0 238 238 238
-3 -7 0 17 17 17
-2 -7 0 238 238 238
-1 -7 0 17 17 17
0 -7 0 238 238 238
1 -7 0 17 17 17
2 -7 0 238 238 238
3 -7 0 17 17 17
4 -7 0 238 238 238
5 -7 0 17 17 17
6 -7 0 238 238 238
7 -7 0 17 17 17
8 -7 0 238 238 238
9 -7 0 136 136 136
-10 -6 0 17 17 17
-9 -6 0 238 238 238
-8 -6 0 17 17 17
-7 -6 0 238 238 238
-6 -6 0 17 17 17
-5 -6 0 238 238 238
-4 -6 0 17 17 17
-3 -6 0 238 238 238
-2 -6 0 17 17 17
-1 -6 0 238 238 238
0 -6 0 17 17 17
1 -6 0 238 238 238
2 -6 0 17 17 17
3 -6 0 238 238 238
4 -6 0 17 17 17
5 -6 0 238 238 238
6 -6 0 17 17 17
7 -6 0 255 204 153
8 -6 0 17 17 17
9 -6 0 136 136 136
-10 -5 0 238 238 238
-9 -5 0 17 17 17
-8 -5 0 238 238 238
-7 -5 0 17 17 17
-6 -5 0 238 238 238
-5 -5 0 17 17 17
-4 -5 0 238 238 238
-3 -5 0 17 17 17
-2 -5 0 238 238 238
-1 -5 0 17 17 17
0 -5 0 238 238 238
1 -5 0 17 17 17
2 -5 0 238 238 238
3 -5 0 17 17 17
4 -5 0 238 238 238
5 -5 0 17 17 17
6 -5 0 238 238 238
7 -5 0 17 17 17
8 -5 0 238 238 238
9 -5 0 238 238 238
-10 -4 0 17 17 17
-9 -4 0 238 238 238
-8 -4 0 17 17 17
-7 -4 0 238 238 238
-6 -4 0 17 17 17
-5 -4 0 238 238 238
-4 -4 0 17 17 17
-3 -4 0 238 238 238
-2 -4 0 17 17 17
-1 -4 0 238 238 238
0 -4 0 17 17 17
1 -4 0 238 238 238
2 -4 0 17 17 17
3 -4 0 238 238 238
4 -4 0 17 17 17
5 -4 0 238 238 238
6 -4 0 17 17 17
7 -4 0 238 238 238
8 -4 0 17 17 17
9 -4 0 238 238 238
-10 -3 0 238 238 238
-9 -3 0 17 17 17
-8 -3 0 238 238 238
-7 -3 0 17 17 17
-6 -3 0 238 238 238
-5 -3 0 17 17 17
-4 -3 0 238 238 238
-3 -3 0 17 17 17
-2 -3 0 238 238 238
-1 -3 0 17 17 17
0 -3 0 238 238 238
1 -3 0 17 17 17
2 -3 0 238 238 238
3 -3 0 17 17 17
4 -3 0 238 238 238
5 -3 0 17 17 17
6 -3 0 238 238 238
7 -3 0 17 17 17
8 -3 0 238 238 238
9 -3 0 238 238 238
-10 -2 0 238 238 238
-9 -2 0 238 238 238
-8 -2 0 17 17 17
-7 -2 0 238 238 238
-6 -2 0 17 17 17
-5 -2 0 238 238 238
-4 -2 0 17 17 17
-3 -2 0 238 238 238
-2 -2 0 17 17 17
-1 -2 0 238 238 238
0 -2 0 17 17 17
1 -2 0 238 238 238
2 -2 0 17 17 17
3 -2 0 238 238 238
4 -2 0 17 17 17
5 -2 0 238 238 238
6 -2 0 17 17 17
7 -2 0 238 238 238
8 -2 0 17 17 17
9 -2 0 238 238 238
-10 -1 0 238 238 238
-9 -1 0 17 17 17
-8 -1 0 238 238 238
-7 -1 0 17 17 17
-6 -1 0 238 238 238
-5 -1 0 17 17 17
-4 -1 0 238 238 238
-3 -1 0 17 17 17
-2 -1 0 238 238 238
-1 -1 0 17 17 17
0 -1 0 238 238 238
1 -1 0 17 17 17
2 -1 0 238 238 238
3 -1 0 17 17 17
4 -1 0 238 238 238
5 -1 0 17 17 17
6 -1 0 238 238 238
7 -1 0 17 17 17
8 -1 0 238 238 238
9 -1 0 238 238 238
-10 0 0 238 238 238
-9 0 0 238 238 238
-8 0 0 17 17 17
-7 0 0 238 238 238
-6 0 0 17 17 17
-5 0 0 238 238 238
-4 0 0 17 17 17
-3 0 0 238 238 238
-2 0 0 17 17 17
-1 0 0 238 238 238
0 0 0 17 17 17
1 0 0 238 238 238
2 0 0 17 17 17
3 0 0 238 238 238
4 0 0 17 17 17
5 0 0 238 238 238
6 0 0 17 17 17
7 0 0 238 238 238
8 0 0 17 17 17
9 0 0 238 238 238
-10 1 0 238 238 238
-9 1 0 17 17 17
-8 1 0 238 238 238
-7 1 0 17 17 17
-6 1 0 238 238 238
-5 1 0 17 17 17
-4 1 0 238 238 238
-3 1 0 17 17 17
-2 1 0 238 238 238
-1 1 0 17 17 17
0 1 0 238 238 238
1 1 0 17 17 17
2 1 0 238 238 238
3 1 0 17 17 17
4 1 0 238 238 238
5 1 0 17 17 17
6 1 0 238 238 238
7 1 0 17 17 17
8 1 0 238 238 238
9 1 0 238 238 238
-10 2 0 238 238 238
-9 2 0 238 238 238
-8 2 0 17 17 17
-7 2 0 238 238 238
-6 2 0 17 17 17
-5 2 0 238 238 238
-4 2 0 17 17 17
-3 2 0 238 238 238
-2 2 0 17 17 17
-1 2 0 238 238 238
0 2 0 17 17 17
1 2 0 238 238 238
2 2 0 17 17 17
3 2 0 238 238 238
4 2 0 17 17 17
5 2 0 238 238 238
6 2 0 17 17 17
7 2 0 238 238 238
8 2 0 17 17 17
9 2 0 238 238 238
-10 3 0 238 238 238
-9 3 0 17 17 17
-8 3 0 238 238 238
-7 3 0 17 17 17
-6 3 0 238 238 238
-5 3 0 17 17 17
-4 3 0 238 238 238
-3 3 0 17 17 17
-2 3 0 238 238 238
-1 3 0 17 17 17
0 3 0 238 238 238
1 3 0 17 17 17
2 3 0 238 238 238
3 3 0 17 17 17
4 3 0 238 238 238
5 3 0 17 17 17
6 3 0 238 238 238
7 3 0 17 17 17
8 3 0 238 238 238
9 3 0 17 17 17
-10 4 0 238 238 238
-9 4 0 238 238 238
-8 4 0 17 17 17
-7 4 0 238 238 238
-6 4 0 17 17 17
-5 4 0 238 238 238
-4 4 0 17 17 17
-3 4 0 238 238 238
-2 4 0 17 17 17
-1 4 0 238 238 238
0 4 0 17 17 17
1 4 0 238 238 238
2 4 0 17 17 17
3 4 0 238 238 238
4 4 0 17 17 17
5 4 0 238 238 238
6 4 0 17 17 17
7 4 0 238 238 238
8 4 0 17 17 17
9 4 0 238 238 238
-10 5 0 238 238 238
-9 5 0 17 17 17
-8 5 0 238 238 238
-7 5 0 17 17 17
-6 5 0 238 238 238
-5 5 0 17 17 17
-4 5 0 238 238 238
-3 5 0 17 17 17
-2 5 0 238 238 238
-1 5 0 17 17 17
0 5 0 238 238 238
1 5 0 17 17 17
2 5 0 238 238 238
3 5 0 17 17 17
4 5 0 238 238 238
5 5 0 17 17 17
6 5 0 238 238 238
7 5 0 17 17 17
8 5 0 238 238 238
9 5 0 17 17 17
-10 6 0 238 238 238
-9 6 0 238 238 238
-8 6 0 17 17 17
-7 6 0 238 238 238
-6 6 0 17 17 17
-5 6 0 238 238 238
-4 6 0 17 17 17
-3 6 0 238 238 238
-2 6 0 17 17 17
-1 6 0 238 238 238
0 6 0 17 17 17
1 6 0 238 238 238
2 6 0 17 17 17
3 6 0 238 238 238
4 6 0 17 17 17
5 6 0 238 238 238
6 6 0 17 17 17
7 6 0 238 238 238
8 6 0 17 17 17
9 6 0 238 238 238
-10 7 0 238 238 238
-9 7 0 17 17 17
-8 7 0 238 238 238
-7 7 0 17 17 17
-6 7 0 238 238 238
-5 7 0 17 17 17
-4 7 0 238 238 238
-3 7 0 17 17 17
-2 7 0 238 238 238
-1 7 0 17 17 17
0 7 0 238 238 238
1 7 0 17 17 17
2 7 0 238 238 238
3 7 0 17 17 17
4 7 0 238 238 238
5 7 0 17 17 17
6 7 0 238 238 238
7 7 0 17 17 17
8 7 0 238 238 238
9 7 0 17 17 17
-10 8 0 238 238 238
-9 8 0 238 238 238
-8 8 0 17 17 17
-7 8 0 238 238 238
-6 8 0 17 17 17
-5 8 0 238 238 238
-4 8 0 17 17 17
-3 8 0 238 238 238
-2 8 0 17 17 17
-1 8 0 238 238 238
0 8 0 17 17 17
1 8 0 238 238 238
2 8 0 17 17 17
3 8 0 238 238 238
4 8 0 17 17 17
5 8 0 238 238 238
6 8 0 17 17 17
7 8 0 238 238 238
8 8 0 17 17 17
9 8 0 238 238 238
-10 9 0 238 238 238
-9 9 0 238 238 238
-8 9 0 238 238 238
-7 9 0 238 238 238
-6 9 0 238 238 238
-5 9 0 238 238 238
-4 9 0 238 238 238
-3 9 0 238 238 238
-2 9 0 238 238 238
-1 9 0 238 238 238
0 9 0 238 238 238
1 9 0 238 238 238
2 9 0 238 238 238
3 9 0 17 17 17
4 9 0 238 238 238
5 9 0 17 17 17
6 9 0 238 238 238
7 9 0 17 17 17
8 9 0 238 238 238
9 9 0 238 238 238
-10 -10 1 136 136 136
-9 -10 1 136 136 136
-3 -10 1 136 136 136
-2 -10 1 136 136 136
-1 -10 1 136 136 136
0 -10 1 136 136 136
1 -10 1 136 136 136
2 -10 1 136 136 136
3 -10 1 136 136 136
4 -10 1 136 136 136
5 -10 1 136 136 136
6 -10 1 136 136 136
7 -10 1 136 136 136
8 -10 1 136 136 136
9 -10 1 136 136 136
-10 -9 1 136 136 136
6 -9 1 204 0 51
7 -9 1 204 0 51
8 -9 1 204 0 51
9 -9 1 136 136 136
6 -8 1 204 0 51
7 -8 1 204 0 51
8 -8 1 204 0 51
9 -8 1 136 136 136
9 -7 1 136 136 136
7 -6 1 255 204 153
9 -6 1 136 136 136
9 -5 1 136 136 136
6 -4 1 204 0 51
7 -4 1 204 0 51
8 -4 1 204 0 51
9 -4 1 136 136 136
-10 -3 1 136 136 136
6 -3 1 204 0 51
7 -3 1 204 0 51
8 -3 1 204 0 51
9 -3 1 136 136 136
-10 -2 1 136 136 136
9 -2 1 136 136 136
-10 -1 1 136 136 136
9 -1 1 136 136 136
-10 0 1 136 136 136
9 0 1 136 136 136
-10 1 1 136 136 136
9 1 1 136 136 136
-10 2 1 136 136 136
-9 2 1 204 0 0
-8 2 1 204 0 0
-7 2 1 204 0 0
9 2 1 136 136 136
-10 3 1 136 136 136
-9 3 1 204 0 0
-8 3 1 204 0 0
-7 3 1 204 0 0
-10 4 1 136 136 136
-10 5 1 136 136 136
-8 5 1 255 204 153
-10 6 1 136 136 136
-10 7 1 136 136 136
-9 7 1 204 0 0
-8 7 1 204 0 0
-7 7 1 204 0 0
-10 8 1 136 136 136
-9 8 1 204 0 0
-8 8 1 204 0 0
-7 8 1 204 0 0
9 8 1 136 136 136
-10 9 1 136 136 136
-9 9 1 136 136 136
-8 9 1 136 136 136
-7 9 1 136 136 136
-6 9 1 136 136 136
-5 9 1 136 136 136
-4 9 1 136 136 136
-3 9 1 136 136 136
-2 9 1 136 136 136
-1 9 1 136 136 136
0 9 1 136 136 136
1 9 1 136 136 136
2 9 1 136 136 136
8 9 1 136 136 136
9 9 1 136 136 136
-10 -10 2 136 136 136
-9 -10 2 136 136 136
-3 -10 2 136 136 136
-2 -10 2 136 136 136
-1 -10 2 136 136 136
0 -10 2 136 136 136
1 -10 2 136 136 136
2 -10 2 136 136 136
3 -10 2 136 136 136
4 -10 2 136 136 136
5 -10 2 136 136 136
6 -10 2 136 136 136
7 -10 2 136 136 136
8 -10 2 136 136 136
9 -10 2 136 136 136
-10 -9 2 136 136 136
6 -9 2 204 0 51
7 -9 2 204 0 51
8 -9 2 204 0 51
9 -9 2 136 136 136
9 -8 2 136 136 136
6 -7 2 255 204 153
7 -7 2 255 204 153
8 -7 2 255 204 153
9 -7 2 136 136 136
6 -6 2 255 204 153
7 -6 2 255 204 153
8 -6 2 255 204 153
9 -6 2 136 136 136
6 -5 2 255 204 153
7 -5 2 255 204 153
8 -5 2 255 204 153
9 -5 2 136 136 136
9 -4 2 136 136 136
-10 -3 2 136 136 136
6 -3 2 204 0 51
7 -3 2 204 0 51
8 -3 2 204 0 51
9 -3 2 136 136 136
-10 -2 2 136 136 136
9 -2 2 136 136 136
-10 -1 2 136 136 136
9 -1 2 136 136 136
-10 0 2 136 136 136
9 0 2 136 136 136
-10 1 2 136 136 136
9 1 2 136 136 136
-10 2 2 136 136 136
-9 2 2 204 0 0
-8 2 2 204 0 0
-7 2 2 204 0 0
9 2 2 136 136 136
-10 3 2 136 136 136
-10 4 2 136 136 136
-9 4 2 255 204 153
-8 4 2 255 204 153
-7 4 2 255 204 153
-10 5 2 136 136 136
-9 5 2 255 204 153
-8 5 2 255 204 153
-7 5 2 255 204 153
-10 6 2 136 136 136
-9 6 2 255 204 153
-8 6 2 255 204 153
-7 6 2 255 204 153
-10 7 2 136 136 136
-10 8 2 136 136 136
-9 8 2 204 0 0
-8 8 2 204 0 0
-7 8 2 204 0 0
9 8 2 136 136 136
-10 9 2 136 136 136
-9 9 2 136 136 136
-8 9 2 136 136 136
-7 9 2 136 136 136
-6 9 2 136 136 136
-5 9 2 136 136 136
-4 9 2 136 136 136
-3 9 2 136 136 136
-2 9 2 136 136 136
-1 9 2 136 136 136
0 9 2 136 136 136
1 9 2 136 136 136
2 9 2 136 136 136
8 9 2 136 136 136
9 9 2 136 136 136
-10 -10 3 136 136 136
-9 -10 3 136 136 136
-3 -10 3 136 136 136
-2 -10 3 136 136 136
-1 -10 3 136 136 136
0 -10 3 136 136 136
1 -10 3 136 136 136
2 -10 3 136 136 136
3 -10 3 136 136 136
4 -10 3 136 136 136
5 -10 3 136 136 136
6 -10 3 136 136 136
7 -10 3 136 136 136
8 -10 3 136 136 136
9 -10 3 136 136 136
-10 -9 3 136 136 136
6 -9 3 204 0 51
7 -9 3 204 0 51
8 -9 3 204 0 51
9 -9 3 136 136 136
9 -8 3 136 136 136
9 -7 3 136 136 136
9 -6 3 136 136 136
9 -5 3 136 136 136
9 -4 3 136 136 136
-10 -3 3 136 136 136
6 -3 3 204 0 51
7 -3 3 204 0 51
8 -3 3 204 0 51
9 -3 3 136 136 136
-10 -2 3 136 136 136
9 -2 3 136 136 136
-10 -1 3 136 136 136
9 -1 3 136 136 136
-10 0 3 136 136 136
9 0 3 136 136 136
-10 1 3 136 136 136
9 1 3 136 136 136
-10 2 3 136 136 136
-9 2 3 204 0 0
-8 2 3 204 0 0
-7 2 3 204 0 0
9 2 3 136 136 136
-10 3 3 136 136 136
-10 4 3 136 136 136
-10 5 3 136 136 136
-10 6 3 136 136 136
-10 7 3 136 136 136
-10 8 3 136 136 136
-9 8 3 204 0 0
-8 8 3 204 0 0
-7 8 3 204 0 0
9 8 3 136 136 136
-10 9 3 136 136 136
-9 9 3 136 136 136
-8 9 3 136 136 136
-7 9 3 136 136 136
-6 9 3 136 136 136
-5 9 3 136 136 136
-4 9 3 136 136 136
-3 9 3 136 136 136
-2 9 3 136 136 136
-1 9 3 136 136 136
0 9 3 136 136 136
1 9 3 136 136 136
2 9 3 136 136 136
8 9 3 136 136 136
9 9 3 136 136 136
-10 -10 4 136 136 136
-9 -10 4 136 136 136
-3 -10 4 136 136 136
-2 -10 4 136 136 136
-1 -10 4 136 136 136
0 -10 4 136 136 136
1 -10 4 136 136 136
2 -10 4 136 136 136
3 -10 4 136 136 136
4 -10 4 136 136 136
5 -10 4 136 136 136
6 -10 4 136 136 136
7 -10 4 136 136 136
8 -10 4 136 136 136
9 -10 4 136 136 136
-10 -9 4 136 136 136
9 -9 4 136 136 136
9 -8 4 136 136 136
9 -7 4 136 136 136
9 -6 4 136 136 136
9 -5 4 136 136 136
9 -4 4 136 136 136
-10 -3 4 136 136 136
9 -3 4 136 136 136
-10 -2 4 136 136 136
9 -2 4 136 136 136
-10 -1 4 136 136 136
9 -1 4 136 136 136
-10 0 4 136 136 136
9 0 4 136 136 136
-10 1 4 136 136 136
9 1 4 136 136 136
-10 2 4 136 136 136
9 2 4 136 136 136
-10 3 4 136 136 136
-10 4 4 136 136 136
-10 5 4 136 136 136
-10 6 4 136 136 136
-10 7 4 136 136 136
-10 8 4 136 136 136
9 8 4 136 136 136
-10 9 4 136 136 136
-9 9 4 136 136 136
-8 9 4 136 136 136
-7 9 4 136 136 136
-6 9 4 136 136 136
-5 9 4 136 136 136
-4 9 4 136 136 136
-3 9 4 136 136 136
-2 9 4 136 136 136
-1 9 4 136 136 136
0 9 4 136 136 136
1 9 4 136 136 136
2 9 4 136 136 136
8 9 4 136 136 136
9 9 4 136 136 136
-10 -10 5 136 136 136
-9 -10 5 136 136 136
-3 -10 5 136 136 136
-2 -10 5 136 136 136
-1 -10 5 136 136 136
0 -10 5 136 136 136
1 -10 5 136 136 136
2 -10 5 136 136 136
3 -10 5 136 136 136
4 -10 5 136 136 136
5 -10 5 136 136 136
6 -10 5 136 136 136
7 -10 5 136 136 136
8 -10 5 136 136 136
9 -10 5 136 136 136
-10 -9 5 136 136 136
9 -9 5 136 136 136
9 -8 5 136 136 136
9 -7 5 136 136 136
9 -6 5 136 136 136
9 -5 5 136 136 136
9 -4 5 136 136 136
-10 -3 5 136 136 136
9 -3 5 136 136 136
-10 -2 5 136 136 136
9 -2 5 136 136 136
-10 -1 5 136 136 136
9 -1 5 136 136 136
-10 0 5 136 136 136
9 0 5 136 136 136
-10 1 5 136 136 136
9 1 5 136 136 136
-10 2 5 136 136 136
9 2 5 136 136 136
-10 3 5 136 136 136
-10 4 5 136 136 136
-10 5 5 136 136 136
-10 6 5 136 136 136
-10 7 5 136 136 136
-10 8 5 136 136 136
9 8 5 136 136 136
-10 9 5 136 136 136
-9 9 5 136 136 136
-8 9 5 136 136 136
-7 9 5 136 136 136
-6 9 5 136 136 136
-5 9 5 136 136 136
-4 9 5 136 136 136
-3 9 5 136 136 136
-2 9 5 136 136 136
-1 9 5 136 136 136
0 9 5 136 136 136
1 9 5 136 136 136
2 9 5 136 136 136
8 9 5 136 136 136
9 9 5 136 136 136
-10 -10 6 136 136 136
-9 -10 6 136 136 136
-8 -10 6 136 136 136
-7 -10 6 136 136 136
-6 -10 6 136 136 136
-5 -10 6 136 136 136
-4 -10 6 136 136 136
-3 -10 6 136 136 136
-2 -10 6 136 136 136
-1 -10 6 136 136 136
0 -10 6 136 136 136
1 -10 6 136 136 136
2 -10 6 136 136 136
3 -10 6 136 136 136
4 -10 6 136 136 136
5 -10 6 136 136 136
6 -10 6 136 136 136
7 -10 6 136 136 136
8 -10 6 136 136 136
9 -10 6 136 136 136
-10 -9 6 136 136 136
9 -9 6 136 136 136
-10 -8 6 136 136 136
9 -8 6 136 136 136
-10 -7 6 136 136 136
9 -7 6 136 136 136
-10 -6 6 136 136 136
9 -6 6 136 136 136
-10 -5 6 136 136 136
9 -5 6 136 136 136
-10 -4 6 136 136 136
9 -4 6 136 136 136
-10 -3 6 136 136 136
9 -3 6 136 136 136
-10 -2 6 136 136 136
9 -2 6 136 136 136
-10 -1 6 136 136 136
9 -1 6 136 136 136
-10 0 6 136 136 136
9 0 6 136 136 136
-10 1 6 136 136 136
9 1 6 136 136 136
-10 2 6 136 136 136
9 2 6 136 136 136
-10 3 6 136 136 136
9 3 6 136 136 136
-10 4 6 136 136 136
9 4 6 136 136 136
-10 5 6 136 136 136
9 5 6 136 136 136
-10 6 6 136 136 136
9 6 6 136 136 136
-10 7 6 136 136 136
9 7 6 136 136 136
-10 8 6 136 136 136
9 8 6 136 136 136
-10 9 6 136 136 136
-9 9 6 136 136 136
-8 9 6 136 136 136
-7 9 6 136 136 136
-6 9 6 136 136 136
-5 9 6 136 136 136
-4 9 6 136 136 136
-3 9 6 136 136 136
-2 9 6 136 136 136
-1 9 6 136 136 136
0 9 6 136 136 136
1 9 6 136 136 136
2 9 6 136 136 136
3 9 6 136 136 136
4 9 6 136 136 136
5 9 6 136 136 136
6 9 6 136 136 136
7 9 6 136 136 136
8 9 6 136 136 136
9 9 6 136 136 136
-10 -10 7 136 136 136
-9 -10 7 136 136 136
-8 -10 7 136 136 136
-7 -10 7 136 136 136
-6 -10 7 136 136 136
-5 -10 7 136 136 136
-4 -10 7 136 136 136
-3 -10 7 136 136 136
-2 -10 7 136 136 136
-1 -10 7 136 136 136
0 -10 7 136 136 136
1 -10 7 136 136 136
2 -10 7 136 136 136
3 -10 7 136 136 136
4 -10 7 136 136 136
5 -10 7 136 136 136
6 -10 7 136 136 136
7 -10 7 136 136 136
8 -10 7 136 136 136
9 -10 7 136 136 136
-10 -9 7 136 136 136
9 -9 7 136 136 136
-10 -8 7 136 136 136
9 -8 7 136 136 136
-10 -7 7 136 136 136
9 -7 7 136 136 136
-10 -6 7 136 136 136
9 -6 7 136 136 136
-10 -5 7 136 136 136
9 -5 7 136 136 136
-10 -4 7 136 136 136
9 -4 7 136 136 136
-10 -3 7 136 136 136
9 -3 7 136 136 136
-10 -2 7 136 136 136
9 -2 7 136 136 136
-10 -1 7 136 136 136
9 -1 7 136 136 136
-10 0 7 136 136 136
9 0 7 136 136 136
-10 1 7 136 136 136
9 1 7 136 136 136
-10 2 7 136 136 136
9 2 7 136 136 136
-10 3 7 136 136 136
9 3 7 136 136 136
-10 4 7 136 136 136
9 4 7 136 136 136
-10 5 7 136 136 136
9 5 7 136 136 136
-10 6 7 136 136 136
9 6 7 136 136 136
-10 7 7 136 136 136
9 7 7 136 136 136
-10 8 7 136 136 136
9 8 7 136 136 136
-10 9 7 136 136 136
-9 9 7 136 136 136
-8 9 7 136 136 136
-7 9 7 136 136 136
-6 9 7 136 136 136
-5 9 7 136 136 136
-4 9 7 136 136 136
-3 9 7 136 136 136
-2 9 7 136 136 136
-1 9 7 136 136 136
0 9 7 136 136 136
1 9 7 136 136 136
2 9 7 136 136 136
3 9 7 136 136 136
4 9 7 136 136 136
5 9 7 136 136 136
6 9 7 136 136 136
7 9 7 136 136 136
8 9 7 136 136 136
9 9 7 136 136 136
-10 -10 8 136 136 136
-9 -10 8 136 136 136
-8 -10 8 136 136 136
-7 -10 8 136 136 136
-6 -10 8 136 136 136
-5 -10 8 136 136 136
-4 -10 8 136 136 136
-3 -10 8 136 136 136
-2 -10 8 136 136 136
-1 -10 8 136 136 136
0 -10 8 136 136 136
1 -10 8 136 136 136
2 -10 8 136 136 136
3 -10 8 136 136 136
4 -10 8 136 136 136
5 -10 8 136 136 136
6 -10 8 136 136 136
7 -10 8 136 136 136
8 -10 8 136 136 136
9 -10 8 136 136 136
-10 -9 8 136 136 136
9 -9 8 136 136 136
-10 -8 8 136 136 136
9 -8 8 136 136 136
-10 -7 8 136 136 136
9 -7 8 136 136 136
-10 -6 8 136 136 136
9 -6 8 136 136 136
-10 -5 8 136 136 136
9 -5 8 136 136 136
-10 -4 8 136 136 136
9 -4 8 136 136 136
-10 -3 8 136 136 136
9 -3 8 136 136 136
-10 -2 8 136 136 136
9 -2 8 136 136 136
-10 -1 8 136 136 136
9 -1 8 136 136 136
-10 0 8 136 136 136
9 0 8 136 136 136
-10 1 8 136 136 136
9 1 8 136 136 136
-10 2 8 136 136 136
9 2 8 136 136 136
-10 3 8 136 136 136
9 3 8 136 136 136
-10 4 8 136 136 136
9 4 8 136 136 136
-10 5 8 136 136 136
9 5 8 136 136 136
-10 6 8 136 136 136
9 6 8 136 136 136
-10 7 8 136 136 136
9 7 8 136 136 136
-10 8 8 136 136 136
9 8 8 136 136 136
-10 9 8 136 136 136
-9 9 8 136 136 136
-8 9 8 136 136 136
-7 9 8 136 136 136
-6 9 8 136 136 136
-5 9 8 136 136 136
-4 9 8 136 136 136
-3 9 8 136 136 136
-2 9 8 136 136 136
-1 9 8 136 136 136
0 9 8 136 136 136
1 9 8 136 136 136
2 9 8 136 136 136
3 9 8 136 136 136
4 9 8 136 136 136
5 9 8 136 136 136
6 9 8 136 136 136
7 9 8 136 136 136
8 9 8 136 136 136
9 9 8 136 136 136
-10 -10 9 136 136 136
-9 -10 9 136 136 136
-8 -10 9 136 136 136
-7 -10 9 136 136 136
-6 -10 9 136 136 136
-5 -10 9 136 136 136
-4 -10 9 136 136 136
-3 -10 9 136 136 136
-2 -10 9 136 136 136
-1 -10 9 136 136 136
0 -10 9 136 136 136
1 -10 9 136 136 136
2 -10 9 136 136 136
3 -10 9 136 136 136
4 -10 9 136 136 136
5 -10 9 136 136 136
6 -10 9 136 136 136
7 -10 9 136 136 136
8 -10 9 136 136 136
9 -10 9 136 136 136
-10 -9 9 136 136 136
-9 -9 9 187 187 187
-8 -9 9 187 187 187
-7 -9 9 187 187 187
-6 -9 9 187 187 187
-5 -9 9 187 187 187
-4 -9 9 187 187 187
-3 -9 9 187 187 187
-2 -9 9 187 187 187
-1 -9 9 187 187 187
0 -9 9 187 187 187
1 -9 9 187 187 187
2 -9 9 187 187 187
3 -9 9 187 187 187
4 -9 9 187 187 187
5 -9 9 187 187 187
6 -9 9 187 187 187
7 -9 9 187 187 187
8 -9 9 187 187 187
9 -9 9 136 136 136
-10 -8 9 136 136 136
-9 -8 9 187 187 187
-8 -8 9 187 187 187
-7 -8 9 187 187 187
-6 -8 9 187 187 187
-5 -8 9 187 187 187
-4 -8 9 187 187 187
-3 -8 9 187 187 187
-2 -8 9 187 187 187
-1 -8 9 187 187 187
0 -8 9 187 187 187
1 -8 9 187 187 187
2 -8 9 187 187 187
3 -8 9 187 187 187
4 -8 9 187 187 187
5 -8 9 187 187 187
6 -8 9 187 187 187
7 -8 9 187 187 187
8 -8 9 187 187 187
9 -8 9 136 136 136
-10 -7 9 136 136 136
-9 -7 9 187 187 187
-8 -7 9 187 187 187
-7 -7 9 187 187 187
-6 -7 9 187 187 187
-5 -7 9 187 187 187
-4 -7 9 187 187 187
-3 -7 9 187 187 187
-2 -7 9 187 187 187
-1 -7 9 187 187 187
0 -7 9 187 187 187
1 -7 9 187 187 187
2 -7 9 187 187 187
3 -7 9 187 187 187
4 -7 9 187 187 187
5 -7 9 187 187 187
6 -7 9 187 187 187
7 -7 9 187 187 187
8 -7 9 187 187 187
9 -7 9 136 136 136
-10 -6 9 136 136 136
-9 -6 9 187 187 187
-8 -6 9 187 187 187
-7 -6 9 187 187 187
-6 -6 9 187 187 187
-5 -6 9 187 187 187
-4 -6 9 187 187 187
-3 -6 9 187 187 187
-2 -6 9 187 187 187
-1 -6 9 187 187 187
0 -6 9 187 187 187
1 -6 9 187 187 187
2 -6 9 187 187 187
3 -6 9 187 187 187
4 -6 9 187 187 187
5 -6 9 187 187 187
6 -6 9 187 187 187
7 -6 9 187 187 187
8 -6 9 187 187 187
9 -6 9 136 136 136
-10 -5 9 136 136 136
-9 -5 9 187 187 187
-8 -5 9 187 187 187
-7 -5 9 187 187 187
-6 -5 9 187 187 187
-5 -5 9 187 187 187
-4 -5 9 187 187 187
-3 -5 9 187 187 187
-2 -5 9 187 187 187
-1 -5 9 187 187 187
0 -5 9 187 187 187
1 -5 9 187 187 187
2 -5 9 187 187 187
3 -5 9 187 187 187
4 -5 9 187 187 187
5 -5 9 187 187 187
6 -5 9 187 187 187
7 -5 9 187 187 187
8 -5 9 187 187 187
9 -5 9 136 136 136
-10 -4 9 136 136 136
-9 -4 9 187 187 187
-8 -4 9 187 187 187
-7 -4 9 187 187 187
-6 -4 9 187 187 187
-5 -4 9 187 187 187
-4 -4 9 187 187 187
-3 -4 9 187 187 187
-2 -4 9 187 187 187
-1 -4 9 187 187 187
0 -4 9 187 187 187
1 -4 9 187 187 187
2 -4 9 187 187 187
3 -4 9 187 187 187
4 -4 9 187 187 187
5 -4 9 187 187 187
6 -4 9 187 187 187
7 -4 9 187 187 187
8 -4 9 187 187 187
9 -4 9 136 136 136
-10 -3 9 136 136 136
-9 -3 9 187 187 187
-8 -3 9 187 187 187
-7 -3 9 187 187 187
-6 -3 9 187 187 187
-5 -3 9 187 187 187
-4 -3 9 187 187 187
-3 -3 9 187 187 187
-2 -3 9 187 187 187
-1 -3 9 187 187 187
0 -3 9 187 187 187
1 -3 9 187 187 187
2 -3 9 187 187 187
3 -3 9 187 187 187
4 -3 9 187 187 187
5 -3 9 187 187 187
6 -3 9 187 187 187
7 -3 9 187 187 187
8 -3 9 187 187 187
9 -3 9 136 136 136
-10 -2 9 136 136 136
-9 -2 9 187 187 187
-8 -2 9 187 187 187
-7 -2 9 187 187 187
-6 -2 9 187 187 187
-5 -2 9 187 187 187
-4 -2 9 187 187 187
-3 -2 9 187 187 187
-2 -2 9 187 187 187
-1 -2 9 187 187 187
0 -2 9 187 187 187
1 -2 9 187 187 187
2 -2 9 187 187 187
3 -2 9 187 187 187
4 -2 9 187 187 187
5 -2 9 187 187 187
6 -2 9 187 187 187
7 -2 9 187 187 187
8 -2 9 187 187 187
9 -2 9 136 136 136
-10 -1 9 136 136 136
-9 -1 9 187 187 187
-8 -1 9 187 187 187
-7 -1 9 187 187 187
-6 -1 9 187 187 187
-5 -1 9 187 187 187
-4 -1 9 187 187 187
-3 -1 9 187 187 187
-2 -1 9 187 187 187
-1 -1 9 187 187 187
0 -1 9 187 187 187
1 -1 9 187 187 187
2 -1 9 187 187 187
3 -1 9 187 187 187
4 -1 9 187 187 187
5 -1 9 187 187 187
6 -1 9 187 187 187
7 -1 9 187 187 187
8 -1 9 187 187 187
9 -1 9 136 136 136
-10 0 9 136 136 136
-9 0 9 187 187 187
-8 0 9 187 187 187
-7 0 9 187 187 187
-6 0 9 187 187 187
-5 0 9 187 187 187
-4 0 9 187 187 187
-3 0 9 187 187 187
-2 0 9 187 187 187
-1 0 9 187 187 187
0 0 9 187 187 187
1 0 9 187 187 187
2 0 9 187 187 187
3 0 9 187 187 187
4 0 9 187 187 187
5 0 9 187 187 187
6 0 9 187 187 187
7 0 9 187 187 187
8 0 9 187 187 187
9 0 9 136 136 136
-10 1 9 136 136 136
-9 1 9 187 187 187
-8 1 9 187 187 187
-7 1 9 187 187 187
-6 1 9 187 187 187
-5 1 9 187 187 187
-4 1 9 187 187 187
-3 1 9 187 187 187
-2 1 9 187 187 187
-1 1 9 187 187 187
0 1 9 187 187 187
1 1 9 187 187 187
2 1 9 187 187 187
3 1 9 187 187 187
4 1 9 187 187 187
5 1 9 187 187 187
6 1 9 187 187 187
7 1 9 187 187 187
8 1 9 187 187 187
9 1 9 136 136 136
-10 2 9 136 136 136
-9 2 9 187 187 187
-8 2 9 187 187 187
-7 2 9 187 187 187
-6 2 9 187 187 187
-5 2 9 187 187 187
-4 2 9 187 187 187
-3 2 9 187 187 187
-2 2 9 187 187 187
-1 2 9 187 187 187
0 2 9 187 187 187
1 2 9 187 187 187
2 2 9 187 187 187
3 2 9 187 187 187
4 2 9 187 187 187
5 2 9 187 187 187
6 2 9 187 187 187
7 2 9 187 187 187
8 2 9 187 187 187
9 2 9 136 136 136
-10 3 9 136 136 136
-9 3 9 187 187 187
-8 3 9 187 187 187
-7 3 9 187 187 187
-6 3 9 187 187 187
-5 3 9 187 187 187
-4 3 9 187 187 187
-3 3 9 187 187 187
-2 3 9 187 187 187
-1 3 9 187 187 187
0 3 9 187 187 187
1 3 9 187 187 187
2 3 9 187 187 187
3 3 9 187 187 187
4 3 9 187 187 187
5 3 9 187 187 187
6 3 9 187 187 187
7 3 9 187 187 187
8 3 9 187 187 187
9 3 9 136 136 136
-10 4 9 136 136 136
-9 4 9 187 187 187
-8 4 9 187 187 187
-7 4 9 187 187 187
-6 4 9 187 187 187
-5 4 9 187 187 187
-4 4 9 187 187 187
-3 4 9 187 187 187
-2 4 9 187 187 187
-1 4 9 187 187 187
0 4 9 187 187 187
1 4 9 187 187 187
2 4 9 187 187 187
3 4 9 187 187 187
4 4 9 187 187 187
5 4 9 187 187 187
6 4 9 187 187 187
7 4 9 187 187 187
8 4 9 187 187 187
9 4 9 136 136 136
-10 5 9 136 136 136
-9 5 9 187 187 187
-8 5 9 187 187 187
-7 5 9 187 187 187
-6 5 9 187 187 187
-5 5 9 187 187 187
-4 5 9 187 187 187
-3 5 9 187 187 187
-2 5 9 187 187 187
-1 5 9 187 187 187
0 5 9 187 187 187
1 5 9 187 187 187
2 5 9 187 187 187
3 5 9 187 187 187
4 5 9 187 187 187
5 5 9 187 187 187
6 5 9 187 187 187
7 5 9 187 187 187
8 5 9 187 187 187
9 5 9 136 136 136
-10 6 9 136 136 136
-9 6 9 187 187 187
-8 6 9 187 187 187
-7 6 9 187 187 187
-6 6 9 187 187 187
-5 6 9 187 187 187
-4 6 9 187 187 187
-3 6 9 187 187 187
-2 6 9 187 187 187
-1 6 9 187 187 187
0 6 9 187 187 187
1 6 9 187 187 187
2 6 9 187 187 187
3 6 9 187 187 187
4 6 9 187 187 187
5 6 9 187 187 187
6 6 9 187 187 187
7 6 9 187 187 187
8 6 9 187 187 187
9 6 9 136 136 136
-10 7 9 136 136 136
-9 7 9 187 187 187
-8 7 9 187 187 187
-7 7 9 187 187 187
-6 7 9 187 187 187
-5 7 9 187 187 187
-4 7 9 187 187 187
-3 7 9 187 187 187
-2 7 9 187 187 187
-1 7 9 187 187 187
0 7 9 187 187 187
1 7 9 187 187 187
2 7 9 187 187 187
3 7 9 187 187 187
4 7 9 187 187 187
5 7 9 187 187 187
6 7 9 187 187 187
7 7 9 187 187 187
8 7 9 187 187 187
9 7 9 136 136 136
-10 8 9 136 136 136
-9 8 9 187 187 187
-8 8 9 187 187 187
-7 8 9 187 187 187
-6 8 9 187 187 187
-5 8 9 187 187 187
-4 8 9 187 187 187
-3 8 9 187 187 187
-2 8 9 187 187 187
-1 8 9 187 187 187
0 8 9 187 187 187
1 8 9 187 187 187
2 8 9 187 187 187
3 8 9 187 187 187
4 8 9 187 187 187
5 8 9 187 187 187
6 8 9 187 187 187
7 8 9 187 187 187
8 8 9 187 187 187
9 8 9 136 136 136
-10 9 9 136 136 136
-9 9 9 136 136 136
-8 9 9 136 136 136
-7 9 9 136 136 136
-6 9 9 136 136 136
-5 9 9 136 136 136
-4 9 9 136 136 136
-3 9 9 136 136 136
-2 9 9 136 136 136
-1 9 9 136 136 136
0 9 9 136 136 136
1 9 9 136 136 136
2 9 9 136 136 136
3 9 9 136 136 136
4 9 9 136 136 136
5 9 9 136 136 136
6 9 9 136 136 136
7 9 9 136 136 136
8 9 9 136 136 136
9 9 9 136 136 136
