ply
format ascii 1.0
comment : MagicaVoxel @ Ephtracy
element vertex 772
property float x
property float y
property float z
property uchar red
property uchar green
property uchar blue
end_header
-5 -10 0 136 136 136
-4 -10 0 136 136 136
-3 -10 0 136 136 136
-2 -10 0 136 136 136
-1 -10 0 136 136 136
0 -10 0 136 136 136
1 -10 0 136 136 136
2 -10 0 136 136 136
3 -10 0 136 136 136
4 -10 0 136 136 136
-5 -9 0 136 136 136
-4 -9 0 136 136 136
-3 -9 0 136 136 136
-2 -9 0 136 136 136
-1 -9 0 136 136 136
0 -9 0 136 136 136
1 -9 0 136 136 136
2 -9 0 136 136 136
3 -9 0 136 136 136
4 -9 0 136 136 136
-5 -8 0 136 136 136
-4 -8 0 136 136 136
-3 -8 0 136 136 136
-2 -8 0 136 136 136
-1 -8 0 136 136 136
0 -8 0 136 136 136
1 -8 0 136 136 136
2 -8 0 136 136 136
3 -8 0 136 136 136
4 -8 0 136 136 136
-5 -7 0 136 136 136
-4 -7 0 136 136 136
-3 -7 0 136 136 136
-2 -7 0 136 136 136
-1 -7 0 136 136 136
0 -7 0 136 136 136
1 -7 0 136 136 136
2 -7 0 136 136 136
3 -7 0 136 136 136
4 -7 0 136 136 136
-5 -6 0 136 136 136
-4 -6 0 136 136 136
-3 -6 0 136 136 136
-2 -6 0 136 136 136
-1 -6 0 136 136 136
0 -6 0 136 136 136
1 -6 0 136 136 136
2 -6 0 136 136 136
3 -6 0 136 136 136
4 -6 0 136 136 136
-5 -5 0 136 136 136
-4 -5 0 136 136 136
-3 -5 0 136 136 136
-2 -5 0 136 136 136
-1 -5 0 136 136 136
0 -5 0 136 136 136
1 -5 0 136 136 136
2 -5 0 136 136 136
3 -5 0 136 136 136
4 -5 0 136 136 136
-5 -4 0 136 136 136
-4 -4 0 136 136 136
-3 -4 0 136 136 136
-2 -4 0 136 136 136
-1 -4 0 136 136 136
0 -4 0 136 136 136
1 -4 0 136 136 136
2 -4 0 136 136 136
3 -4 0 136 136 136
4 -4 0 136 136 136
-5 -3 0 136 136 136
-4 -3 0 136 136 136
-3 -3 0 136 136 136
-2 -3 0 136 136 136
-1 -3 0 136 136 136
0 -3 0 136 136 136
1 -3 0 136 136 136
2 -3 0 136 136 136
3 -3 0 136 136 136
4 -3 0 136 136 136
-5 -2 0 136 136 136
-4 -2 0 136 136 136
-3 -2 0 136 136 136
-2 -2 0 136 136 136
-1 -2 0 136 136 136
0 -2 0 136 136 136
1 -2 0 136 136 136
2 -2 0 136 136 136
3 -2 0 136 136 136
4 -2 0 136 136 136
-5 -1 0 136 136 136
-4 -1 0 136 136 136
-3 -1 0 136 136 136
-2 -1 0 136 136 136
-1 -1 0 136 136 136
0 -1 0 136 136 136
1 -1 0 136 136 136
2 -1 0 136 136 136
3 -1 0 136 136 136
4 -1 0 136 136 136
-5 0 0 136 136 136
-4 0 0 136 136 136
-3 0 0 136 136 136
-2 0 0 136 136 136
-1 0 0 136 136 136
0 0 0 136 136 136
1 0 0 136 136 136
2 0 0 136 136 136
3 0 0 136 136 136
4 0 0 136 136 136
-5 1 0 136 136 136
-4 1 0 136 136 136
-3 1 0 136 136 136
-2 1 0 136 136 136
-1 1 0 136 136 136
0 1 0 136 136 136
1 1 0 136 136 136
2 1 0 136 136 136
3 1 0 136 136 136
4 1 0 136 136 136
-5 2 0 136 136 136
-4 2 0 136 136 136
-3 2 0 136 136 136
-2 2 0 136 136 136
-1 2 0 136 136 136
0 2 0 136 136 136
1 2 0 136 136 136
2 2 0 136 136 136
3 2 0 136 136 136
4 2 0 136 136 136
-5 3 0 136 136 136
-4 3 0 136 136 136
-3 3 0 136 136 136
-2 3 0 136 136 136
-1 3 0 136 136 136
0 3 0 136 136 136
1 3 0 136 136 136
2 3 0 136 136 136
3 3 0 136 136 136
4 3 0 136 136 136
-5 4 0 136 136 136
-4 4 0 136 136 136
-3 4 0 136 136 136
-2 4 0 136 136 136
-1 4 0 136 136 136
0 4 0 136 136 136
1 4 0 136 136 136
2 4 0 136 136 136
3 4 0 136 136 136
4 4 0 136 136 136
-5 5 0 136 136 136
-4 5 0 136 136 136
-3 5 0 136 136 136
-2 5 0 136 136 136
-1 5 0 136 136 136
0 5 0 136 136 136
1 5 0 136 136 136
2 5 0 136 136 136
3 5 0 136 136 136
4 5 0 136 136 136
-5 6 0 136 136 136
-4 6 0 136 136 136
-3 6 0 136 136 136
-2 6 0 136 136 136
-1 6 0 136 136 136
0 6 0 136 136 136
1 6 0 136 136 136
2 6 0 136 136 136
3 6 0 136 136 136
4 6 0 136 136 136
-5 7 0 136 136 136
-4 7 0 136 136 136
-3 7 0 136 136 136
-2 7 0 136 136 136
-1 7 0 136 136 136
0 7 0 136 136 136
1 7 0 136 136 136
2 7 0 136 136 136
3 7 0 136 136 136
4 7 0 136 136 136
-5 8 0 136 136 136
-4 8 0 136 136 136
-3 8 0 136 136 136
-2 8 0 136 136 136
-1 8 0 136 136 136
0 8 0 136 136 136
1 8 0 136 136 136
2 8 0 136 136 136
3 8 0 136 136 136
4 8 0 136 136 136
-5 9 0 136 136 136
-4 9 0 136 136 136
-3 9 0 136 136 136
-2 9 0 136 136 136
-1 9 0 136 136 136
0 9 0 136 136 136
1 9 0 136 136 136
2 9 0 136 136 136
3 9 0 136 136 136
4 9 0 136 136 136
-5 -10 1 136 136 136
-4 -10 1 68 68 68
3 -10 1 68 68 68
4 -10 1 136 136 136
-5 -9 1 136 136 136
-4 -9 1 102 51 0
-3 -9 1 102 51 0
-2 -9 1 102 51 0
-1 -9 1 102 51 0
0 -9 1 102 51 0
1 -9 1 102 51 0
2 -9 1 102 51 0
3 -9 1 102 51 0
4 -9 1 136 136 136
-5 -8 1 119 119 119
4 -8 1 119 119 119
-5 -7 1 136 136 136
4 -7 1 136 136 136
-5 -6 1 136 136 136
4 -6 1 136 136 136
-5 -5 1 136 136 136
4 -5 1 136 136 136
-5 -4 1 136 136 136
4 -4 1 136 136 136
-5 -3 1 136 136 136
4 -3 1 136 136 136
-5 -2 1 136 136 136
4 -2 1 136 136 136
-5 -1 1 119 119 119
4 -1 1 119 119 119
-5 0 1 136 136 136
4 0 1 136 136 136
-5 1 1 136 136 136
4 1 1 136 136 136
-5 2 1 136 136 136
4 2 1 136 136 136
-5 3 1 136 136 136
4 3 1 136 136 136
-5 4 1 136 136 136
4 4 1 136 136 136
-5 5 1 136 136 136
4 5 1 136 136 136
-5 6 1 136 136 136
4 6 1 136 136 136
-5 7 1 136 136 136
4 7 1 136 136 136
-5 8 1 136 136 136
-4 8 1 102 51 0
-3 8 1 102 51 0
-2 8 1 102 51 0
-1 8 1 102 51 0
0 8 1 102 51 0
1 8 1 102 51 0
2 8 1 102 51 0
3 8 1 102 51 0
4 8 1 136 136 136
-5 9 1 136 136 136
-4 9 1 68 68 68
3 9 1 68 68 68
4 9 1 136 136 136
-5 -10 2 136 136 136
-4 -10 2 68 68 68
3 -10 2 68 68 68
4 -10 2 136 136 136
-5 -9 2 136 136 136
-2 -9 2 102 51 0
1 -9 2 102 51 0
4 -9 2 136 136 136
-5 -8 2 119 119 119
4 -8 2 119 119 119
-5 -7 2 136 136 136
4 -7 2 136 136 136
-5 -6 2 136 136 136
4 -6 2 136 136 136
-5 -5 2 136 136 136
4 -5 2 136 136 136
-5 -4 2 136 136 136
4 -4 2 136 136 136
-5 -3 2 136 136 136
4 -3 2 136 136 136
-5 -2 2 136 136 136
4 -2 2 136 136 136
-5 -1 2 119 119 119
4 -1 2 119 119 119
-5 0 2 136 136 136
4 0 2 136 136 136
-5 1 2 136 136 136
4 1 2 136 136 136
-5 2 2 136 136 136
4 2 2 136 136 136
-5 3 2 136 136 136
4 3 2 136 136 136
-5 4 2 136 136 136
4 4 2 136 136 136
-5 5 2 136 136 136
4 5 2 136 136 136
-5 6 2 136 136 136
4 6 2 136 136 136
-5 7 2 136 136 136
4 7 2 136 136 136
-5 8 2 136 136 136
-2 8 2 102 51 0
1 8 2 102 51 0
4 8 2 136 136 136
-5 9 2 136 136 136
-4 9 2 68 68 68
3 9 2 68 68 68
4 9 2 136 136 136
-5 -10 3 136 136 136
-4 -10 3 68 68 68
3 -10 3 68 68 68
4 -10 3 136 136 136
-5 -9 3 119 119 119
4 -9 3 119 119 119
-5 -8 3 119 119 119
4 -8 3 119 119 119
-5 -7 3 119 119 119
4 -7 3 119 119 119
-5 -6 3 119 119 119
4 -6 3 119 119 119
-5 -5 3 119 119 119
4 -5 3 119 119 119
-5 -4 3 119 119 119
4 -4 3 119 119 119
-5 -3 3 119 119 119
4 -3 3 119 119 119
-5 -2 3 119 119 119
4 -2 3 119 119 119
-5 -1 3 119 119 119
4 -1 3 119 119 119
-5 0 3 119 119 119
4 0 3 119 119 119
-5 1 3 119 119 119
4 1 3 119 119 119
-5 2 3 119 119 119
4 2 3 119 119 119
-5 3 3 119 119 119
4 3 3 119 119 119
-5 4 3 119 119 119
4 4 3 119 119 119
-5 5 3 119 119 119
4 5 3 119 119 119
-5 6 3 119 119 119
4 6 3 119 119 119
-5 7 3 119 119 119
4 7 3 119 119 119
-5 8 3 119 119 119
4 8 3 119 119 119
-5 9 3 136 136 136
-4 9 3 68 68 68
3 9 3 68 68 68
4 9 3 136 136 136
-5 -10 4 136 136 136
-4 -10 4 68 68 68
3 -10 4 68 68 68
4 -10 4 136 136 136
-5 -9 4 136 136 136
4 -9 4 136 136 136
-5 -8 4 136 136 136
4 -8 4 136 136 136
-5 -7 4 136 136 136
4 -7 4 136 136 136
-5 -6 4 136 136 136
4 -6 4 136 136 136
-5 -5 4 136 136 136
4 -5 4 136 136 136
-5 -4 4 136 136 136
4 -4 4 136 136 136
-5 -3 4 136 136 136
4 -3 4 136 136 136
-5 -2 4 136 136 136
4 -2 4 136 136 136
-5 -1 4 136 136 136
4 -1 4 136 136 136
-5 0 4 136 136 136
4 0 4 136 136 136
-5 1 4 136 136 136
4 1 4 136 136 136
-5 2 4 136 136 136
4 2 4 136 136 136
-5 3 4 136 136 136
4 3 4 136 136 136
-5 4 4 119 119 119
4 4 4 119 119 119
-5 5 4 136 136 136
4 5 4 136 136 136
-5 6 4 136 136 136
4 6 4 136 136 136
-5 7 4 136 136 136
4 7 4 136 136 136
-5 8 4 136 136 136
4 8 4 136 136 136
-5 9 4 136 136 136
-4 9 4 68 68 68
3 9 4 68 68 68
4 9 4 136 136 136
-5 -10 5 136 136 136
-4 -10 5 68 68 68
3 -10 5 68 68 68
4 -10 5 136 136 136
-5 -9 5 136 136 136
4 -9 5 136 136 136
-5 -8 5 136 136 136
4 -8 5 136 136 136
-5 -7 5 136 136 136
4 -7 5 136 136 136
-5 -6 5 136 136 136
4 -6 5 136 136 136
-5 -5 5 136 136 136
4 -5 5 136 136 136
-5 -4 5 136 136 136
4 -4 5 136 136 136
-5 -3 5 136 136 136
4 -3 5 136 136 136
-5 -2 5 136 136 136
4 -2 5 136 136 136
-5 -1 5 136 136 136
4 -1 5 136 136 136
-5 0 5 136 136 136
4 0 5 136 136 136
-5 1 5 136 136 136
4 1 5 136 136 136
-5 2 5 136 136 136
4 2 5 136 136 136
-5 3 5 136 136 136
4 3 5 136 136 136
-5 4 5 119 119 119
4 4 5 119 119 119
-5 5 5 136 136 136
4 5 5 136 136 136
-5 6 5 136 136 136
4 6 5 136 136 136
-5 7 5 136 136 136
4 7 5 136 136 136
-5 8 5 136 136 136
4 8 5 136 136 136
-5 9 5 136 136 136
-4 9 5 68 68 68
3 9 5 68 68 68
4 9 5 136 136 136
-5 -10 6 136 136 136
-4 -10 6 68 68 68
3 -10 6 68 68 68
4 -10 6 136 136 136
-5 -9 6 119 119 119
4 -9 6 119 119 119
-5 -8 6 119 119 119
4 -8 6 119 119 119
-5 -7 6 119 119 119
4 -7 6 119 119 119
-5 -6 6 119 119 119
4 -6 6 119 119 119
-5 -5 6 119 119 119
4 -5 6 119 119 119
-5 -4 6 119 119 119
4 -4 6 119 119 119
-5 -3 6 119 119 119
4 -3 6 119 119 119
-5 -2 6 119 119 119
4 -2 6 119 119 119
-5 -1 6 119 119 119
4 -1 6 119 119 119
-5 0 6 119 119 119
4 0 6 119 119 119
-5 1 6 119 119 119
4 1 6 119 119 119
-5 2 6 119 119 119
4 2 6 119 119 119
-5 3 6 119 119 119
4 3 6 119 119 119
-5 4 6 119 119 119
4 4 6 119 119 119
-5 5 6 119 119 119
4 5 6 119 119 119
-5 6 6 119 119 119
4 6 6 119 119 119
-5 7 6 119 119 119
4 7 6 119 119 119
-5 8 6 119 119 119
4 8 6 119 119 119
-5 9 6 136 136 136
-4 9 6 68 68 68
3 9 6 68 68 68
4 9 6 136 136 136
-5 -10 7 136 136 136
-4 -10 7 68 68 68
3 -10 7 68 68 68
4 -10 7 136 136 136
-5 -9 7 136 136 136
4 -9 7 136 136 136
-5 -8 7 136 136 136
4 -8 7 136 136 136
-5 -7 7 136 136 136
4 -7 7 136 136 136
-5 -6 7 136 136 136
4 -6 7 136 136 136
-5 -5 7 136 136 136
4 -5 7 136 136 136
-5 -4 7 119 119 119
4 -4 7 119 119 119
-5 -3 7 136 136 136
4 -3 7 136 136 136
-5 -2 7 136 136 136
4 -2 7 136 136 136
-5 -1 7 136 136 136
4 -1 7 136 136 136
-5 0 7 136 136 136
4 0 7 136 136 136
-5 1 7 136 136 136
4 1 7 136 136 136
-5 2 7 136 136 136
4 2 7 136 136 136
-5 3 7 136 136 136
4 3 7 136 136 136
-5 4 7 136 136 136
4 4 7 136 136 136
-5 5 7 136 136 136
4 5 7 136 136 136
-5 6 7 136 136 136
4 6 7 136 136 136
-5 7 7 136 136 136
4 7 7 136 136 136
-5 8 7 136 136 136
4 8 7 136 136 136
-5 9 7 136 136 136
-4 9 7 68 68 68
3 9 7 68 68 68
4 9 7 136 136 136
-5 -10 8 136 136 136
-4 -10 8 68 68 68
3 -10 8 68 68 68
4 -10 8 136 136 136
-5 -9 8 136 136 136
4 -9 8 136 136 136
-5 -8 8 136 136 136
4 -8 8 136 136 136
-5 -7 8 136 136 136
4 -7 8 136 136 136
-5 -6 8 136 136 136
4 -6 8 136 136 136
-5 -5 8 136 136 136
4 -5 8 136 136 136
-5 -4 8 119 119 119
4 -4 8 119 119 119
-5 -3 8 136 136 136
4 -3 8 136 136 136
-5 -2 8 136 136 136
4 -2 8 136 136 136
-5 -1 8 136 136 136
4 -1 8 136 136 136
-5 0 8 136 136 136
4 0 8 136 136 136
-5 1 8 136 136 136
4 1 8 136 136 136
-5 2 8 136 136 136
4 2 8 136 136 136
-5 3 8 136 136 136
4 3 8 136 136 136
-5 4 8 136 136 136
4 4 8 136 136 136
-5 5 8 136 136 136
4 5 8 136 136 136
-5 6 8 136 136 136
4 6 8 136 136 136
-5 7 8 136 136 136
4 7 8 136 136 136
-5 8 8 136 136 136
4 8 8 136 136 136
-5 9 8 136 136 136
-4 9 8 68 68 68
3 9 8 68 68 68
4 9 8 136 136 136
-5 -10 9 136 136 136
-4 -10 9 68 68 68
-3 -10 9 119 119 119
-2 -10 9 119 119 119
-1 -10 9 119 119 119
0 -10 9 119 119 119
1 -10 9 119 119 119
2 -10 9 119 119 119
3 -10 9 68 68 68
4 -10 9 136 136 136
-5 -9 9 119 119 119
-4 -9 9 119 119 119
-3 -9 9 119 119 119
-2 -9 9 119 119 119
-1 -9 9 119 119 119
0 -9 9 119 119 119
1 -9 9 119 119 119
2 -9 9 119 119 119
3 -9 9 119 119 119
4 -9 9 119 119 119
-5 -8 9 119 119 119
-4 -8 9 119 119 119
-3 -8 9 119 119 119
-2 -8 9 119 119 119
-1 -8 9 119 119 119
0 -8 9 119 119 119
1 -8 9 119 119 119
2 -8 9 119 119 119
3 -8 9 119 119 119
4 -8 9 119 119 119
-5 -7 9 119 119 119
-4 -7 9 119 119 119
-3 -7 9 119 119 119
-2 -7 9 119 119 119
-1 -7 9 119 119 119
0 -7 9 119 119 119
1 -7 9 119 119 119
2 -7 9 119 119 119
3 -7 9 119 119 119
4 -7 9 119 119 119
-5 -6 9 119 119 119
-4 -6 9 119 119 119
-3 -6 9 119 119 119
-2 -6 9 119 119 119
-1 -6 9 119 119 119
0 -6 9 119 119 119
1 -6 9 119 119 119
2 -6 9 119 119 119
3 -6 9 119 119 119
4 -6 9 119 119 119
-5 -5 9 119 119 119
-4 -5 9 119 119 119
-3 -5 9 119 119 119
-2 -5 9 119 119 119
-1 -5 9 119 119 119
0 -5 9 119 119 119
1 -5 9 119 119 119
2 -5 9 119 119 119
3 -5 9 119 119 119
4 -5 9 119 119 119
-5 -4 9 119 119 119
-4 -4 9 119 119 119
-3 -4 9 119 119 119
-2 -4 9 119 119 119
-1 -4 9 119 119 119
0 -4 9 119 119 119
1 -4 9 119 119 119
2 -4 9 119 119 119
3 -4 9 119 119 119
4 -4 9 119 119 119
-5 -3 9 119 119 119
-4 -3 9 119 119 119
-3 -3 9 119 119 119
-2 -3 9 119 119 119
-1 -3 9 119 119 119
0 -3 9 119 119 119
1 -3 9 119 119 119
2 -3 9 119 119 119
3 -3 9 119 119 119
4 -3 9 119 119 119
-5 -2 9 119 119 119
-4 -2 9 119 119 119
-3 -2 9 119 119 119
-2 -2 9 119 119 119
-1 -2 9 119 119 119
0 -2 9 119 119 119
1 -2 9 119 119 119
2 -2 9 119 119 119
3 -2 9 119 119 119
4 -2 9 119 119 119
-5 -1 9 119 119 119
-4 -1 9 119 119 119
-3 -1 9 119 119 119
-2 -1 9 119 119 119
-1 -1 9 119 119 119
0 -1 9 119 119 119
1 -1 9 119 119 119
2 -1 9 119 119 119
3 -1 9 119 119 119
4 -1 9 119 119 119
-5 0 9 119 119 119
-4 0 9 119 119 119
-3 0 9 119 119 119
-2 0 9 119 119 119
-1 0 9 119 119 119
0 0 9 119 119 119
1 0 9 119 119 119
2 0 9 119 119 119
3 0 9 119 119 119
4 0 9 119 119 119
-5 1 9 119 119 119
-4 1 9 119 119 119
-3 1 9 119 119 119
-2 1 9 119 119 119
-1 1 9 119 119 119
0 1 9 119 119 119
1 1 9 119 119 119
2 1 9 119 119 119
3 1 9 119 119 119
4 1 9 119 119 119
-5 2 9 119 119 119
-4 2 9 119 119 119
-3 2 9 119 119 119
-2 2 9 119 119 119
-1 2 9 119 119 119
0 2 9 119 119 119
1 2 9 119 119 119
2 2 9 119 119 119
3 2 9 119 119 119
4 2 9 119 119 119
-5 3 9 119 119 119
-4 3 9 119 119 119
-3 3 9 119 119 119
-2 3 9 119 119 119
-1 3 9 119 119 119
0 3 9 119 119 119
1 3 9 119 119 119
2 3 9 119 119 119
3 3 9 119 119 119
4 3 9 119 119 119
-5 4 9 119 119 119
-4 4 9 119 119 119
-3 4 9 119 119 119
-2 4 9 119 119 119
-1 4 9 119 119 119
0 4 9 119 119 119
1 4 9 119 119 119
2 4 9 119 119 119
3 4 9 119 119 119
4 4 9 119 119 119
-5 5 9 119 119 119
-4 5 9 119 119 119
-3 5 9 119 119 119
-2 5 9 119 119 119
-1 5 9 119 119 119
0 5 9 119 119 119
1 5 9 119 119 119
2 5 9 119 119 119
3 5 9 119 119 119
4 5 9 119 119 119
-5 6 9 119 119 119
-4 6 9 119 119 119
-3 6 9 119 119 119
-2 6 9 119 119 119
-1 6 9 119 119 119
0 6 9 119 119 119
1 6 9 119 119 119
2 6 9 119 119 119
3 6 9 119 119 119
4 6 9 119 119 119
-5 7 9 119 119 119
-4 7 9 119 119 119
-3 7 9 119 119 119
-2 7 9 119 119 119
-1 7 9 119 119 119
0 7 9 119 119 119
1 7 9 119 119 119
2 7 9 119 119 119
3 7 9 119 119 119
4 7 9 119 119 119
-5 8 9 119 119 119
-4 8 9 119 119 119
-3 8 9 119 119 119
-2 8 9 119 119 119
-1 8 9 119 119 119
0 8 9 119 119 119
1 8 9 119 119 119
2 8 9 119 119 119
3 8 9 119 119 119
4 8 9 119 119 119
-5 9 9 136 136 136
-4 9 9 68 68 68
-3 9 9 119 119 119
-2 9 9 119 119 119
-1 9 9 119 119 119
0 9 9 119 119 119
1 9 9 119 119 119
2 9 9 119 119 119
3 9 9 68 68 68
4 9 9 136 136 136
