ply
format ascii 1.0
comment : MagicaVoxel @ Ephtracy
element vertex 1734
property float x
property float y
property float z
property uchar red
property uchar green
property uchar blue
end_header
-10 -10 0 100 72 24
-9 -10 0 100 72 24
-8 -10 0 100 72 24
-7 -10 0 100 72 24
-6 -10 0 100 72 24
-5 -10 0 100 72 24
-4 -10 0 100 72 24
-3 -10 0 100 72 24
-2 -10 0 100 72 24
-1 -10 0 100 72 24
0 -10 0 100 72 24
1 -10 0 100 72 24
2 -10 0 100 72 24
3 -10 0 100 72 24
4 -10 0 100 72 24
5 -10 0 100 72 24
6 -10 0 100 72 24
7 -10 0 100 72 24
8 -10 0 100 72 24
9 -10 0 100 72 24
-10 -9 0 100 72 24
-9 -9 0 100 72 24
-8 -9 0 100 72 24
-7 -9 0 100 72 24
-6 -9 0 160 132 68
-5 -9 0 132 104 48
-4 -9 0 100 72 24
-3 -9 0 160 132 68
-2 -9 0 132 104 48
-1 -9 0 100 72 24
0 -9 0 160 132 68
1 -9 0 132 104 48
2 -9 0 100 72 24
3 -9 0 160 132 68
4 -9 0 132 104 48
5 -9 0 100 72 24
6 -9 0 160 132 68
7 -9 0 132 104 48
8 -9 0 100 72 24
9 -9 0 100 72 24
-10 -8 0 100 72 24
-9 -8 0 160 132 68
-8 -8 0 160 132 68
-7 -8 0 100 72 24
-6 -8 0 160 132 68
-5 -8 0 132 104 48
-4 -8 0 100 72 24
-3 -8 0 160 132 68
-2 -8 0 132 104 48
-1 -8 0 100 72 24
0 -8 0 160 132 68
1 -8 0 132 104 48
2 -8 0 100 72 24
3 -8 0 160 132 68
4 -8 0 132 104 48
5 -8 0 100 72 24
6 -8 0 160 132 68
7 -8 0 132 104 48
8 -8 0 100 72 24
9 -8 0 100 72 24
-10 -7 0 100 72 24
-9 -7 0 160 132 68
-8 -7 0 132 104 48
-7 -7 0 100 72 24
-6 -7 0 160 132 68
-5 -7 0 132 104 48
-4 -7 0 100 72 24
-3 -7 0 100 72 24
-2 -7 0 100 72 24
-1 -7 0 100 72 24
0 -7 0 160 132 68
1 -7 0 132 104 48
2 -7 0 100 72 24
3 -7 0 100 72 24
4 -7 0 100 72 24
5 -7 0 100 72 24
6 -7 0 160 132 68
7 -7 0 132 104 48
8 -7 0 100 72 24
9 -7 0 100 72 24
-10 -6 0 100 72 24
-9 -6 0 160 132 68
-8 -6 0 132 104 48
-7 -6 0 100 72 24
-6 -6 0 160 132 68
-5 -6 0 132 104 48
-4 -6 0 100 72 24
-3 -6 0 160 132 68
-2 -6 0 160 132 68
-1 -6 0 100 72 24
0 -6 0 160 132 68
1 -6 0 132 104 48
2 -6 0 100 72 24
3 -6 0 160 132 68
4 -6 0 160 132 68
5 -6 0 100 72 24
6 -6 0 160 132 68
7 -6 0 132 104 48
8 -6 0 100 72 24
9 -6 0 100 72 24
-10 -5 0 100 72 24
-9 -5 0 160 132 68
-8 -5 0 132 104 48
-7 -5 0 100 72 24
-6 -5 0 160 132 68
-5 -5 0 132 104 48
-4 -5 0 100 72 24
-3 -5 0 160 132 68
-2 -5 0 132 104 48
-1 -5 0 100 72 24
0 -5 0 160 132 68
1 -5 0 132 104 48
2 -5 0 100 72 24
3 -5 0 160 132 68
4 -5 0 132 104 48
5 -5 0 100 72 24
6 -5 0 160 132 68
7 -5 0 132 104 48
8 -5 0 100 72 24
9 -5 0 100 72 24
-10 -4 0 100 72 24
-9 -4 0 160 132 68
-8 -4 0 132 104 48
-7 -4 0 100 72 24
-6 -4 0 100 72 24
-5 -4 0 100 72 24
-4 -4 0 100 72 24
-3 -4 0 160 132 68
-2 -4 0 132 104 48
-1 -4 0 100 72 24
0 -4 0 160 132 68
1 -4 0 132 104 48
2 -4 0 100 72 24
3 -4 0 160 132 68
4 -4 0 132 104 48
5 -4 0 100 72 24
6 -4 0 100 72 24
7 -4 0 100 72 24
8 -4 0 100 72 24
9 -4 0 100 72 24
-10 -3 0 100 72 24
-9 -3 0 160 132 68
-8 -3 0 132 104 48
-7 -3 0 100 72 24
-6 -3 0 160 132 68
-5 -3 0 160 132 68
-4 -3 0 100 72 24
-3 -3 0 160 132 68
-2 -3 0 132 104 48
-1 -3 0 100 72 24
0 -3 0 100 72 24
1 -3 0 100 72 24
2 -3 0 100 72 24
3 -3 0 160 132 68
4 -3 0 132 104 48
5 -3 0 100 72 24
6 -3 0 160 132 68
7 -3 0 160 132 68
8 -3 0 100 72 24
9 -3 0 100 72 24
-10 -2 0 100 72 24
-9 -2 0 160 132 68
-8 -2 0 132 104 48
-7 -2 0 100 72 24
-6 -2 0 160 132 68
-5 -2 0 132 104 48
-4 -2 0 100 72 24
-3 -2 0 160 132 68
-2 -2 0 132 104 48
-1 -2 0 100 72 24
0 -2 0 160 132 68
1 -2 0 160 132 68
2 -2 0 100 72 24
3 -2 0 160 132 68
4 -2 0 132 104 48
5 -2 0 100 72 24
6 -2 0 160 132 68
7 -2 0 132 104 48
8 -2 0 100 72 24
9 -2 0 100 72 24
-10 -1 0 100 72 24
-9 -1 0 160 132 68
-8 -1 0 132 104 48
-7 -1 0 100 72 24
-6 -1 0 160 132 68
-5 -1 0 132 104 48
-4 -1 0 100 72 24
-3 -1 0 160 132 68
-2 -1 0 132 104 48
-1 -1 0 100 72 24
0 -1 0 160 132 68
1 -1 0 132 104 48
2 -1 0 100 72 24
3 -1 0 160 132 68
4 -1 0 132 104 48
5 -1 0 100 72 24
6 -1 0 160 132 68
7 -1 0 132 104 48
8 -1 0 100 72 24
9 -1 0 100 72 24
-10 0 0 100 72 24
-9 0 0 160 132 68
-8 0 0 132 104 48
-7 0 0 100 72 24
-6 0 0 160 132 68
-5 0 0 132 104 48
-4 0 0 100 72 24
-3 0 0 160 132 68
-2 0 0 132 104 48
-1 0 0 100 72 24
0 0 0 160 132 68
1 0 0 132 104 48
2 0 0 100 72 24
3 0 0 160 132 68
4 0 0 132 104 48
5 0 0 100 72 24
6 0 0 160 132 68
7 0 0 132 104 48
8 0 0 100 72 24
9 0 0 100 72 24
-10 1 0 100 72 24
-9 1 0 100 72 24
-8 1 0 100 72 24
-7 1 0 100 72 24
-6 1 0 160 132 68
-5 1 0 132 104 48
-4 1 0 100 72 24
-3 1 0 160 132 68
-2 1 0 132 104 48
-1 1 0 100 72 24
0 1 0 160 132 68
1 1 0 132 104 48
2 1 0 100 72 24
3 1 0 160 132 68
4 1 0 132 104 48
5 1 0 100 72 24
6 1 0 160 132 68
7 1 0 132 104 48
8 1 0 100 72 24
9 1 0 100 72 24
-10 2 0 100 72 24
-9 2 0 160 132 68
-8 2 0 160 132 68
-7 2 0 100 72 24
-6 2 0 160 132 68
-5 2 0 132 104 48
-4 2 0 100 72 24
-3 2 0 160 132 68
-2 2 0 132 104 48
-1 2 0 100 72 24
0 2 0 160 132 68
1 2 0 132 104 48
2 2 0 100 72 24
3 2 0 160 132 68
4 2 0 132 104 48
5 2 0 100 72 24
6 2 0 160 132 68
7 2 0 132 104 48
8 2 0 100 72 24
9 2 0 100 72 24
-10 3 0 100 72 24
-9 3 0 160 132 68
-8 3 0 132 104 48
-7 3 0 100 72 24
-6 3 0 160 132 68
-5 3 0 132 104 48
-4 3 0 100 72 24
-3 3 0 100 72 24
-2 3 0 100 72 24
-1 3 0 100 72 24
0 3 0 160 132 68
1 3 0 132 104 48
2 3 0 100 72 24
3 3 0 100 72 24
4 3 0 100 72 24
5 3 0 100 72 24
6 3 0 160 132 68
7 3 0 132 104 48
8 3 0 100 72 24
9 3 0 100 72 24
-10 4 0 100 72 24
-9 4 0 160 132 68
-8 4 0 132 104 48
-7 4 0 100 72 24
-6 4 0 160 132 68
-5 4 0 132 104 48
-4 4 0 100 72 24
-3 4 0 160 132 68
-2 4 0 160 132 68
-1 4 0 100 72 24
0 4 0 160 132 68
1 4 0 132 104 48
2 4 0 100 72 24
3 4 0 160 132 68
4 4 0 160 132 68
5 4 0 100 72 24
6 4 0 160 132 68
7 4 0 132 104 48
8 4 0 100 72 24
9 4 0 100 72 24
-10 5 0 100 72 24
-9 5 0 160 132 68
-8 5 0 132 104 48
-7 5 0 100 72 24
-6 5 0 160 132 68
-5 5 0 132 104 48
-4 5 0 100 72 24
-3 5 0 160 132 68
-2 5 0 132 104 48
-1 5 0 100 72 24
0 5 0 160 132 68
1 5 0 132 104 48
2 5 0 100 72 24
3 5 0 160 132 68
4 5 0 132 104 48
5 5 0 100 72 24
6 5 0 160 132 68
7 5 0 132 104 48
8 5 0 100 72 24
9 5 0 100 72 24
-10 6 0 100 72 24
-9 6 0 160 132 68
-8 6 0 132 104 48
-7 6 0 100 72 24
-6 6 0 100 72 24
-5 6 0 100 72 24
-4 6 0 100 72 24
-3 6 0 160 132 68
-2 6 0 132 104 48
-1 6 0 100 72 24
0 6 0 160 132 68
1 6 0 132 104 48
2 6 0 100 72 24
3 6 0 160 132 68
4 6 0 132 104 48
5 6 0 100 72 24
6 6 0 100 72 24
7 6 0 100 72 24
8 6 0 100 72 24
9 6 0 100 72 24
-10 7 0 100 72 24
-9 7 0 160 132 68
-8 7 0 132 104 48
-7 7 0 100 72 24
-6 7 0 160 132 68
-5 7 0 160 132 68
-4 7 0 100 72 24
-3 7 0 160 132 68
-2 7 0 132 104 48
-1 7 0 100 72 24
0 7 0 100 72 24
1 7 0 100 72 24
2 7 0 100 72 24
3 7 0 160 132 68
4 7 0 132 104 48
5 7 0 100 72 24
6 7 0 160 132 68
7 7 0 160 132 68
8 7 0 100 72 24
9 7 0 100 72 24
-10 8 0 100 72 24
-9 8 0 160 132 68
-8 8 0 132 104 48
-7 8 0 100 72 24
-6 8 0 160 132 68
-5 8 0 132 104 48
-4 8 0 100 72 24
-3 8 0 160 132 68
-2 8 0 132 104 48
-1 8 0 100 72 24
0 8 0 160 132 68
1 8 0 160 132 68
2 8 0 100 72 24
3 8 0 160 132 68
4 8 0 132 104 48
5 8 0 100 72 24
6 8 0 160 132 68
7 8 0 132 104 48
8 8 0 100 72 24
9 8 0 100 72 24
-10 9 0 100 72 24
-9 9 0 100 72 24
-8 9 0 100 72 24
-7 9 0 100 72 24
-6 9 0 100 72 24
-5 9 0 100 72 24
-4 9 0 100 72 24
-3 9 0 100 72 24
-2 9 0 100 72 24
-1 9 0 100 72 24
0 9 0 100 72 24
1 9 0 100 72 24
2 9 0 100 72 24
3 9 0 100 72 24
4 9 0 100 72 24
5 9 0 100 72 24
6 9 0 100 72 24
7 9 0 100 72 24
8 9 0 100 72 24
9 9 0 100 72 24
-10 -10 1 64 64 64
-9 -10 1 64 64 64
-8 -10 1 64 64 64
-7 -10 1 64 64 64
-6 -10 1 64 64 64
-5 -10 1 64 64 64
-4 -10 1 64 64 64
-3 -10 1 64 64 64
-2 -10 1 68 40 0
1 -10 1 68 40 0
2 -10 1 64 64 64
3 -10 1 64 64 64
4 -10 1 64 64 64
5 -10 1 64 64 64
6 -10 1 64 64 64
7 -10 1 64 64 64
8 -10 1 64 64 64
9 -10 1 64 64 64
-10 -9 1 64 64 64
-9 -9 1 68 40 0
-8 -9 1 68 40 0
7 -9 1 68 40 0
8 -9 1 68 40 0
9 -9 1 64 64 64
-10 -8 1 64 64 64
-9 -8 1 68 40 0
-8 -8 1 68 40 0
7 -8 1 68 40 0
8 -8 1 68 40 0
9 -8 1 64 64 64
-10 -7 1 64 64 64
9 -7 1 64 64 64
-10 -6 1 64 64 64
9 -6 1 64 64 64
-10 -5 1 64 64 64
9 -5 1 64 64 64
-10 -4 1 64 64 64
9 -4 1 64 64 64
-10 -3 1 64 64 64
9 -3 1 64 64 64
-10 -2 1 64 64 64
9 -2 1 64 64 64
-10 -1 1 64 64 64
9 -1 1 64 64 64
-10 0 1 64 64 64
9 0 1 64 64 64
-10 1 1 64 64 64
9 1 1 64 64 64
-10 2 1 64 64 64
9 2 1 64 64 64
-10 3 1 64 64 64
9 3 1 64 64 64
-10 4 1 64 64 64
9 4 1 64 64 64
-10 5 1 64 64 64
9 5 1 64 64 64
-10 6 1 64 64 64
9 6 1 64 64 64
-10 7 1 64 64 64
-9 7 1 68 40 0
-8 7 1 68 40 0
7 7 1 68 40 0
8 7 1 68 40 0
9 7 1 64 64 64
-10 8 1 64 64 64
-9 8 1 68 40 0
-8 8 1 68 40 0
7 8 1 68 40 0
8 8 1 68 40 0
9 8 1 64 64 64
-10 9 1 64 64 64
-9 9 1 64 64 64
-8 9 1 64 64 64
-7 9 1 64 64 64
-6 9 1 64 64 64
-5 9 1 64 64 64
-4 9 1 64 64 64
-3 9 1 64 64 64
-2 9 1 64 64 64
-1 9 1 64 64 64
0 9 1 64 64 64
1 9 1 64 64 64
2 9 1 64 64 64
3 9 1 64 64 64
4 9 1 64 64 64
5 9 1 64 64 64
6 9 1 64 64 64
7 9 1 64 64 64
8 9 1 64 64 64
9 9 1 64 64 64
-10 -10 2 144 144 144
-9 -10 2 144 144 144
-8 -10 2 144 144 144
-7 -10 2 144 144 144
-6 -10 2 144 144 144
-5 -10 2 64 64 64
-4 -10 2 144 144 144
-3 -10 2 144 144 144
-2 -10 2 68 40 0
1 -10 2 68 40 0
2 -10 2 144 144 144
3 -10 2 144 144 144
4 -10 2 144 144 144
5 -10 2 64 64 64
6 -10 2 144 144 144
7 -10 2 144 144 144
8 -10 2 144 144 144
9 -10 2 144 144 144
-10 -9 2 144 144 144
-9 -9 2 68 40 0
-8 -9 2 68 40 0
7 -9 2 68 40 0
8 -9 2 68 40 0
9 -9 2 144 144 144
-10 -8 2 144 144 144
-9 -8 2 68 40 0
-8 -8 2 68 40 0
7 -8 2 68 40 0
8 -8 2 68 40 0
9 -8 2 144 144 144
-10 -7 2 144 144 144
9 -7 2 144 144 144
-10 -6 2 64 64 64
9 -6 2 144 144 144
-10 -5 2 144 144 144
9 -5 2 64 64 64
-10 -4 2 144 144 144
9 -4 2 144 144 144
-10 -3 2 144 144 144
9 -3 2 144 144 144
-10 -2 2 144 144 144
9 -2 2 144 144 144
-10 -1 2 144 144 144
9 -1 2 144 144 144
-10 0 2 144 144 144
9 0 2 144 144 144
-10 1 2 144 144 144
9 1 2 144 144 144
-10 2 2 144 144 144
9 2 2 144 144 144
-10 3 2 144 144 144
9 3 2 144 144 144
-10 4 2 64 64 64
9 4 2 144 144 144
-10 5 2 144 144 144
9 5 2 64 64 64
-10 6 2 144 144 144
9 6 2 144 144 144
-10 7 2 144 144 144
-9 7 2 68 40 0
-8 7 2 68 40 0
7 7 2 68 40 0
8 7 2 68 40 0
9 7 2 144 144 144
-10 8 2 144 144 144
-9 8 2 68 40 0
-8 8 2 68 40 0
7 8 2 68 40 0
8 8 2 68 40 0
9 8 2 144 144 144
-10 9 2 144 144 144
-9 9 2 144 144 144
-8 9 2 144 144 144
-7 9 2 144 144 144
-6 9 2 64 64 64
-5 9 2 144 144 144
-4 9 2 144 144 144
-3 9 2 144 144 144
-2 9 2 144 144 144
-1 9 2 144 144 144
0 9 2 144 144 144
1 9 2 144 144 144
2 9 2 144 144 144
3 9 2 144 144 144
4 9 2 64 64 64
5 9 2 144 144 144
6 9 2 144 144 144
7 9 2 144 144 144
8 9 2 144 144 144
9 9 2 144 144 144
-10 -10 3 108 108 108
-9 -10 3 108 108 108
-8 -10 3 108 108 108
-7 -10 3 108 108 108
-6 -10 3 108 108 108
-5 -10 3 64 64 64
-4 -10 3 144 144 144
-3 -10 3 108 108 108
-2 -10 3 68 40 0
1 -10 3 68 40 0
2 -10 3 108 108 108
3 -10 3 108 108 108
4 -10 3 108 108 108
5 -10 3 64 64 64
6 -10 3 144 144 144
7 -10 3 108 108 108
8 -10 3 108 108 108
9 -10 3 108 108 108
-10 -9 3 108 108 108
-9 -9 3 68 40 0
-8 -9 3 68 40 0
7 -9 3 68 40 0
8 -9 3 68 40 0
9 -9 3 108 108 108
-10 -8 3 108 108 108
-9 -8 3 68 40 0
-8 -8 3 68 40 0
7 -8 3 68 40 0
8 -8 3 68 40 0
9 -8 3 108 108 108
-10 -7 3 144 144 144
9 -7 3 108 108 108
-10 -6 3 64 64 64
9 -6 3 108 108 108
-10 -5 3 108 108 108
9 -5 3 64 64 64
-10 -4 3 108 108 108
9 -4 3 144 144 144
-10 -3 3 108 108 108
9 -3 3 108 108 108
-10 -2 3 108 108 108
9 -2 3 108 108 108
-10 -1 3 108 108 108
9 -1 3 108 108 108
-10 0 3 108 108 108
9 0 3 108 108 108
-10 1 3 108 108 108
9 1 3 108 108 108
-10 2 3 108 108 108
9 2 3 108 108 108
-10 3 3 144 144 144
9 3 3 108 108 108
-10 4 3 64 64 64
9 4 3 108 108 108
-10 5 3 108 108 108
9 5 3 64 64 64
-10 6 3 108 108 108
9 6 3 144 144 144
-10 7 3 108 108 108
-9 7 3 68 40 0
-8 7 3 68 40 0
7 7 3 68 40 0
8 7 3 68 40 0
9 7 3 108 108 108
-10 8 3 108 108 108
-9 8 3 68 40 0
-8 8 3 68 40 0
7 8 3 68 40 0
8 8 3 68 40 0
9 8 3 108 108 108
-10 9 3 108 108 108
-9 9 3 108 108 108
-8 9 3 108 108 108
-7 9 3 144 144 144
-6 9 3 64 64 64
-5 9 3 108 108 108
-4 9 3 108 108 108
-3 9 3 108 108 108
-2 9 3 108 108 108
-1 9 3 108 108 108
0 9 3 108 108 108
1 9 3 108 108 108
2 9 3 108 108 108
3 9 3 144 144 144
4 9 3 64 64 64
5 9 3 108 108 108
6 9 3 108 108 108
7 9 3 108 108 108
8 9 3 108 108 108
9 9 3 108 108 108
-10 -10 4 64 64 64
-9 -10 4 64 64 64
-8 -10 4 64 64 64
-7 -10 4 64 64 64
-6 -10 4 64 64 64
-5 -10 4 64 64 64
-4 -10 4 64 64 64
-3 -10 4 64 64 64
-2 -10 4 68 40 0
-1 -10 4 68 40 0
0 -10 4 68 40 0
1 -10 4 68 40 0
2 -10 4 64 64 64
3 -10 4 64 64 64
4 -10 4 64 64 64
5 -10 4 64 64 64
6 -10 4 64 64 64
7 -10 4 64 64 64
8 -10 4 64 64 64
9 -10 4 64 64 64
-10 -9 4 64 64 64
-9 -9 4 68 40 0
-8 -9 4 68 40 0
7 -9 4 68 40 0
8 -9 4 68 40 0
9 -9 4 64 64 64
-10 -8 4 64 64 64
-9 -8 4 68 40 0
-8 -8 4 68 40 0
7 -8 4 68 40 0
8 -8 4 68 40 0
9 -8 4 64 64 64
-10 -7 4 64 64 64
9 -7 4 64 64 64
-10 -6 4 64 64 64
9 -6 4 64 64 64
-10 -5 4 64 64 64
9 -5 4 64 64 64
-10 -4 4 64 64 64
9 -4 4 64 64 64
-10 -3 4 64 64 64
9 -3 4 64 64 64
-10 -2 4 64 64 64
9 -2 4 64 64 64
-10 -1 4 64 64 64
9 -1 4 64 64 64
-10 0 4 64 64 64
9 0 4 64 64 64
-10 1 4 64 64 64
9 1 4 64 64 64
-10 2 4 64 64 64
9 2 4 64 64 64
-10 3 4 64 64 64
9 3 4 64 64 64
-10 4 4 64 64 64
9 4 4 64 64 64
-10 5 4 64 64 64
9 5 4 64 64 64
-10 6 4 64 64 64
9 6 4 64 64 64
-10 7 4 64 64 64
-9 7 4 68 40 0
-8 7 4 68 40 0
7 7 4 68 40 0
8 7 4 68 40 0
9 7 4 64 64 64
-10 8 4 64 64 64
-9 8 4 68 40 0
-8 8 4 68 40 0
7 8 4 68 40 0
8 8 4 68 40 0
9 8 4 64 64 64
-10 9 4 64 64 64
-9 9 4 64 64 64
-8 9 4 64 64 64
-7 9 4 64 64 64
-6 9 4 64 64 64
-5 9 4 64 64 64
-4 9 4 64 64 64
-3 9 4 64 64 64
-2 9 4 64 64 64
-1 9 4 64 64 64
0 9 4 64 64 64
1 9 4 64 64 64
2 9 4 64 64 64
3 9 4 64 64 64
4 9 4 64 64 64
5 9 4 64 64 64
6 9 4 64 64 64
7 9 4 64 64 64
8 9 4 64 64 64
9 9 4 64 64 64
-10 -10 5 144 144 144
-9 -10 5 144 144 144
-8 -10 5 64 64 64
-7 -10 5 144 144 144
-6 -10 5 144 144 144
-5 -10 5 144 144 144
-4 -10 5 144 144 144
-3 -10 5 144 144 144
-2 -10 5 144 144 144
-1 -10 5 144 144 144
0 -10 5 144 144 144
1 -10 5 144 144 144
2 -10 5 64 64 64
3 -10 5 144 144 144
4 -10 5 144 144 144
5 -10 5 144 144 144
6 -10 5 144 144 144
7 -10 5 144 144 144
8 -10 5 144 144 144
9 -10 5 144 144 144
-10 -9 5 144 144 144
-9 -9 5 68 40 0
-8 -9 5 68 40 0
7 -9 5 68 40 0
8 -9 5 68 40 0
9 -9 5 144 144 144
-10 -8 5 144 144 144
-9 -8 5 68 40 0
-8 -8 5 68 40 0
7 -8 5 68 40 0
8 -8 5 68 40 0
9 -8 5 64 64 64
-10 -7 5 144 144 144
9 -7 5 144 144 144
-10 -6 5 144 144 144
9 -6 5 144 144 144
-10 -5 5 144 144 144
9 -5 5 144 144 144
-10 -4 5 144 144 144
9 -4 5 144 144 144
-10 -3 5 64 64 64
9 -3 5 144 144 144
-10 -2 5 144 144 144
9 -2 5 144 144 144
-10 -1 5 144 144 144
9 -1 5 144 144 144
-10 0 5 144 144 144
9 0 5 144 144 144
-10 1 5 144 144 144
9 1 5 144 144 144
-10 2 5 144 144 144
9 2 5 64 64 64
-10 3 5 144 144 144
9 3 5 144 144 144
-10 4 5 144 144 144
9 4 5 144 144 144
-10 5 5 144 144 144
9 5 5 144 144 144
-10 6 5 144 144 144
9 6 5 144 144 144
-10 7 5 64 64 64
-9 7 5 68 40 0
-8 7 5 68 40 0
7 7 5 68 40 0
8 7 5 68 40 0
9 7 5 144 144 144
-10 8 5 144 144 144
-9 8 5 68 40 0
-8 8 5 68 40 0
7 8 5 68 40 0
8 8 5 68 40 0
9 8 5 144 144 144
-10 9 5 144 144 144
-9 9 5 144 144 144
-8 9 5 144 144 144
-7 9 5 144 144 144
-6 9 5 144 144 144
-5 9 5 144 144 144
-4 9 5 144 144 144
-3 9 5 64 64 64
-2 9 5 144 144 144
-1 9 5 144 144 144
0 9 5 144 144 144
1 9 5 144 144 144
2 9 5 144 144 144
3 9 5 144 144 144
4 9 5 144 144 144
5 9 5 144 144 144
6 9 5 144 144 144
7 9 5 64 64 64
8 9 5 144 144 144
9 9 5 144 144 144
-10 -10 6 108 108 108
-9 -10 6 108 108 108
-8 -10 6 64 64 64
-7 -10 6 144 144 144
-6 -10 6 108 108 108
-5 -10 6 108 108 108
-4 -10 6 108 108 108
-3 -10 6 108 108 108
-2 -10 6 108 108 108
-1 -10 6 108 108 108
0 -10 6 108 108 108
1 -10 6 108 108 108
2 -10 6 64 64 64
3 -10 6 144 144 144
4 -10 6 108 108 108
5 -10 6 108 108 108
6 -10 6 108 108 108
7 -10 6 108 108 108
8 -10 6 108 108 108
9 -10 6 108 108 108
-10 -9 6 108 108 108
-9 -9 6 68 40 0
-8 -9 6 68 40 0
-7 -9 6 100 72 24
-6 -9 6 100 72 24
-5 -9 6 100 72 24
-4 -9 6 100 72 24
-3 -9 6 100 72 24
-2 -9 6 100 72 24
-1 -9 6 100 72 24
0 -9 6 100 72 24
1 -9 6 100 72 24
2 -9 6 100 72 24
3 -9 6 100 72 24
4 -9 6 100 72 24
5 -9 6 100 72 24
6 -9 6 100 72 24
7 -9 6 68 40 0
8 -9 6 68 40 0
9 -9 6 108 108 108
-10 -8 6 108 108 108
-9 -8 6 68 40 0
-8 -8 6 68 40 0
7 -8 6 68 40 0
8 -8 6 68 40 0
9 -8 6 64 64 64
-10 -7 6 108 108 108
-9 -7 6 100 72 24
8 -7 6 100 72 24
9 -7 6 144 144 144
-10 -6 6 108 108 108
-9 -6 6 100 72 24
8 -6 6 100 72 24
9 -6 6 108 108 108
-10 -5 6 108 108 108
-9 -5 6 100 72 24
8 -5 6 100 72 24
9 -5 6 108 108 108
-10 -4 6 144 144 144
-9 -4 6 100 72 24
8 -4 6 100 72 24
9 -4 6 108 108 108
-10 -3 6 64 64 64
-9 -3 6 100 72 24
8 -3 6 100 72 24
9 -3 6 108 108 108
-10 -2 6 108 108 108
-9 -2 6 100 72 24
8 -2 6 100 72 24
9 -2 6 108 108 108
-10 -1 6 108 108 108
-9 -1 6 100 72 24
8 -1 6 100 72 24
9 -1 6 108 108 108
-10 0 6 108 108 108
-9 0 6 100 72 24
8 0 6 100 72 24
9 0 6 108 108 108
-10 1 6 108 108 108
-9 1 6 100 72 24
8 1 6 100 72 24
9 1 6 108 108 108
-10 2 6 108 108 108
-9 2 6 100 72 24
8 2 6 100 72 24
9 2 6 64 64 64
-10 3 6 108 108 108
-9 3 6 100 72 24
8 3 6 100 72 24
9 3 6 144 144 144
-10 4 6 108 108 108
-9 4 6 100 72 24
8 4 6 100 72 24
9 4 6 108 108 108
-10 5 6 108 108 108
-9 5 6 100 72 24
8 5 6 100 72 24
9 5 6 108 108 108
-10 6 6 144 144 144
-9 6 6 100 72 24
8 6 6 100 72 24
9 6 6 108 108 108
-10 7 6 64 64 64
-9 7 6 68 40 0
-8 7 6 68 40 0
7 7 6 68 40 0
8 7 6 68 40 0
9 7 6 108 108 108
-10 8 6 108 108 108
-9 8 6 68 40 0
-8 8 6 68 40 0
-7 8 6 100 72 24
-6 8 6 100 72 24
-5 8 6 100 72 24
-4 8 6 100 72 24
-3 8 6 100 72 24
-2 8 6 100 72 24
-1 8 6 100 72 24
0 8 6 100 72 24
1 8 6 100 72 24
2 8 6 100 72 24
3 8 6 100 72 24
4 8 6 100 72 24
5 8 6 100 72 24
6 8 6 100 72 24
7 8 6 68 40 0
8 8 6 68 40 0
9 8 6 108 108 108
-10 9 6 108 108 108
-9 9 6 108 108 108
-8 9 6 108 108 108
-7 9 6 108 108 108
-6 9 6 108 108 108
-5 9 6 108 108 108
-4 9 6 144 144 144
-3 9 6 64 64 64
-2 9 6 108 108 108
-1 9 6 108 108 108
0 9 6 108 108 108
1 9 6 108 108 108
2 9 6 108 108 108
3 9 6 108 108 108
4 9 6 108 108 108
5 9 6 108 108 108
6 9 6 144 144 144
7 9 6 64 64 64
8 9 6 108 108 108
9 9 6 108 108 108
-10 -10 7 64 64 64
-9 -10 7 64 64 64
-8 -10 7 64 64 64
-7 -10 7 64 64 64
-6 -10 7 64 64 64
-5 -10 7 64 64 64
-4 -10 7 64 64 64
-3 -10 7 64 64 64
-2 -10 7 64 64 64
-1 -10 7 64 64 64
0 -10 7 64 64 64
1 -10 7 64 64 64
2 -10 7 64 64 64
3 -10 7 64 64 64
4 -10 7 64 64 64
5 -10 7 64 64 64
6 -10 7 64 64 64
7 -10 7 64 64 64
8 -10 7 64 64 64
9 -10 7 64 64 64
-10 -9 7 64 64 64
-9 -9 7 68 40 0
-8 -9 7 68 40 0
-7 -9 7 100 72 24
-6 -9 7 100 72 24
-5 -9 7 100 72 24
-4 -9 7 100 72 24
-3 -9 7 100 72 24
-2 -9 7 100 72 24
-1 -9 7 100 72 24
0 -9 7 100 72 24
1 -9 7 100 72 24
2 -9 7 100 72 24
3 -9 7 100 72 24
4 -9 7 100 72 24
5 -9 7 100 72 24
6 -9 7 100 72 24
7 -9 7 68 40 0
8 -9 7 68 40 0
9 -9 7 64 64 64
-10 -8 7 64 64 64
-9 -8 7 68 40 0
-8 -8 7 68 40 0
7 -8 7 68 40 0
8 -8 7 68 40 0
9 -8 7 64 64 64
-10 -7 7 64 64 64
-9 -7 7 100 72 24
8 -7 7 100 72 24
9 -7 7 64 64 64
-10 -6 7 64 64 64
-9 -6 7 100 72 24
8 -6 7 100 72 24
9 -6 7 64 64 64
-10 -5 7 64 64 64
-9 -5 7 100 72 24
8 -5 7 100 72 24
9 -5 7 64 64 64
-10 -4 7 64 64 64
-9 -4 7 100 72 24
8 -4 7 100 72 24
9 -4 7 64 64 64
-10 -3 7 64 64 64
-9 -3 7 100 72 24
8 -3 7 100 72 24
9 -3 7 64 64 64
-10 -2 7 64 64 64
-9 -2 7 100 72 24
8 -2 7 100 72 24
9 -2 7 64 64 64
-10 -1 7 64 64 64
-9 -1 7 100 72 24
8 -1 7 100 72 24
9 -1 7 64 64 64
-10 0 7 64 64 64
-9 0 7 100 72 24
8 0 7 100 72 24
9 0 7 64 64 64
-10 1 7 64 64 64
-9 1 7 100 72 24
8 1 7 100 72 24
9 1 7 64 64 64
-10 2 7 64 64 64
-9 2 7 100 72 24
8 2 7 100 72 24
9 2 7 64 64 64
-10 3 7 64 64 64
-9 3 7 100 72 24
8 3 7 100 72 24
9 3 7 64 64 64
-10 4 7 64 64 64
-9 4 7 100 72 24
8 4 7 100 72 24
9 4 7 64 64 64
-10 5 7 64 64 64
-9 5 7 100 72 24
8 5 7 100 72 24
9 5 7 64 64 64
-10 6 7 64 64 64
-9 6 7 100 72 24
8 6 7 100 72 24
9 6 7 64 64 64
-10 7 7 64 64 64
-9 7 7 68 40 0
-8 7 7 68 40 0
7 7 7 68 40 0
8 7 7 68 40 0
9 7 7 64 64 64
-10 8 7 64 64 64
-9 8 7 68 40 0
-8 8 7 68 40 0
-7 8 7 100 72 24
-6 8 7 100 72 24
-5 8 7 100 72 24
-4 8 7 100 72 24
-3 8 7 100 72 24
-2 8 7 100 72 24
-1 8 7 100 72 24
0 8 7 100 72 24
1 8 7 100 72 24
2 8 7 100 72 24
3 8 7 100 72 24
4 8 7 100 72 24
5 8 7 100 72 24
6 8 7 100 72 24
7 8 7 68 40 0
8 8 7 68 40 0
9 8 7 64 64 64
-10 9 7 64 64 64
-9 9 7 64 64 64
-8 9 7 64 64 64
-7 9 7 64 64 64
-6 9 7 64 64 64
-5 9 7 64 64 64
-4 9 7 64 64 64
-3 9 7 64 64 64
-2 9 7 64 64 64
-1 9 7 64 64 64
0 9 7 64 64 64
1 9 7 64 64 64
2 9 7 64 64 64
3 9 7 64 64 64
4 9 7 64 64 64
5 9 7 64 64 64
6 9 7 64 64 64
7 9 7 64 64 64
8 9 7 64 64 64
9 9 7 64 64 64
-10 -10 8 144 144 144
-9 -10 8 144 144 144
-8 -10 8 144 144 144
-7 -10 8 144 144 144
-6 -10 8 144 144 144
-5 -10 8 144 144 144
-4 -10 8 64 64 64
-3 -10 8 144 144 144
-2 -10 8 144 144 144
-1 -10 8 144 144 144
0 -10 8 144 144 144
1 -10 8 144 144 144
2 -10 8 144 144 144
3 -10 8 144 144 144
4 -10 8 144 144 144
5 -10 8 144 144 144
6 -10 8 64 64 64
7 -10 8 144 144 144
8 -10 8 144 144 144
9 -10 8 144 144 144
-10 -9 8 144 144 144
-9 -9 8 68 40 0
-8 -9 8 68 40 0
7 -9 8 68 40 0
8 -9 8 68 40 0
9 -9 8 144 144 144
-10 -8 8 144 144 144
-9 -8 8 68 40 0
-8 -8 8 68 40 0
7 -8 8 68 40 0
8 -8 8 68 40 0
9 -8 8 144 144 144
-10 -7 8 64 64 64
9 -7 8 144 144 144
-10 -6 8 144 144 144
9 -6 8 144 144 144
-10 -5 8 144 144 144
9 -5 8 144 144 144
-10 -4 8 144 144 144
9 -4 8 64 64 64
-10 -3 8 144 144 144
9 -3 8 144 144 144
-10 -2 8 144 144 144
9 -2 8 144 144 144
-10 -1 8 144 144 144
9 -1 8 144 144 144
-10 0 8 144 144 144
9 0 8 144 144 144
-10 1 8 144 144 144
9 1 8 144 144 144
-10 2 8 144 144 144
9 2 8 144 144 144
-10 3 8 64 64 64
9 3 8 144 144 144
-10 4 8 144 144 144
9 4 8 144 144 144
-10 5 8 144 144 144
9 5 8 144 144 144
-10 6 8 144 144 144
9 6 8 64 64 64
-10 7 8 144 144 144
-9 7 8 68 40 0
-8 7 8 68 40 0
7 7 8 68 40 0
8 7 8 68 40 0
9 7 8 144 144 144
-10 8 8 144 144 144
-9 8 8 68 40 0
-8 8 8 68 40 0
7 8 8 68 40 0
8 8 8 68 40 0
9 8 8 144 144 144
-10 9 8 144 144 144
-9 9 8 144 144 144
-8 9 8 144 144 144
-7 9 8 64 64 64
-6 9 8 144 144 144
-5 9 8 144 144 144
-4 9 8 144 144 144
-3 9 8 144 144 144
-2 9 8 144 144 144
-1 9 8 144 144 144
0 9 8 144 144 144
1 9 8 144 144 144
2 9 8 144 144 144
3 9 8 64 64 64
4 9 8 144 144 144
5 9 8 144 144 144
6 9 8 144 144 144
7 9 8 144 144 144
8 9 8 144 144 144
9 9 8 144 144 144
-10 -10 9 108 108 108
-9 -10 9 108 108 108
-8 -10 9 108 108 108
-7 -10 9 108 108 108
-6 -10 9 108 108 108
-5 -10 9 108 108 108
-4 -10 9 64 64 64
-3 -10 9 144 144 144
-2 -10 9 108 108 108
-1 -10 9 108 108 108
0 -10 9 108 108 108
1 -10 9 108 108 108
2 -10 9 108 108 108
3 -10 9 108 108 108
4 -10 9 108 108 108
5 -10 9 108 108 108
6 -10 9 64 64 64
7 -10 9 144 144 144
8 -10 9 108 108 108
9 -10 9 108 108 108
-10 -9 9 108 108 108
-9 -9 9 68 40 0
-8 -9 9 68 40 0
7 -9 9 68 40 0
8 -9 9 68 40 0
9 -9 9 108 108 108
-10 -8 9 144 144 144
-9 -8 9 68 40 0
-8 -8 9 68 40 0
7 -8 9 68 40 0
8 -8 9 68 40 0
9 -8 9 108 108 108
-10 -7 9 64 64 64
9 -7 9 108 108 108
-10 -6 9 108 108 108
9 -6 9 108 108 108
-10 -5 9 108 108 108
9 -5 9 108 108 108
-10 -4 9 108 108 108
9 -4 9 64 64 64
-10 -3 9 108 108 108
9 -3 9 144 144 144
-10 -2 9 108 108 108
9 -2 9 108 108 108
-10 -1 9 108 108 108
9 -1 9 108 108 108
-10 0 9 108 108 108
9 0 9 108 108 108
-10 1 9 108 108 108
9 1 9 108 108 108
-10 2 9 144 144 144
9 2 9 108 108 108
-10 3 9 64 64 64
9 3 9 108 108 108
-10 4 9 108 108 108
9 4 9 108 108 108
-10 5 9 108 108 108
9 5 9 108 108 108
-10 6 9 108 108 108
9 6 9 64 64 64
-10 7 9 108 108 108
-9 7 9 68 40 0
-8 7 9 68 40 0
7 7 9 68 40 0
8 7 9 68 40 0
9 7 9 144 144 144
-10 8 9 108 108 108
-9 8 9 68 40 0
-8 8 9 68 40 0
7 8 9 68 40 0
8 8 9 68 40 0
9 8 9 108 108 108
-10 9 9 108 108 108
-9 9 9 108 108 108
-8 9 9 144 144 144
-7 9 9 64 64 64
-6 9 9 108 108 108
-5 9 9 108 108 108
-4 9 9 108 108 108
-3 9 9 108 108 108
-2 9 9 108 108 108
-1 9 9 108 108 108
0 9 9 108 108 108
1 9 9 108 108 108
2 9 9 144 144 144
3 9 9 64 64 64
4 9 9 108 108 108
5 9 9 108 108 108
6 9 9 108 108 108
7 9 9 108 108 108
8 9 9 108 108 108
9 9 9 108 108 108
-10 -10 10 64 64 64
-9 -10 10 64 64 64
-8 -10 10 64 64 64
-7 -10 10 64 64 64
-6 -10 10 64 64 64
-5 -10 10 64 64 64
-4 -10 10 64 64 64
-3 -10 10 64 64 64
-2 -10 10 64 64 64
-1 -10 10 64 64 64
0 -10 10 64 64 64
1 -10 10 64 64 64
2 -10 10 64 64 64
3 -10 10 64 64 64
4 -10 10 64 64 64
5 -10 10 64 64 64
6 -10 10 64 64 64
7 -10 10 64 64 64
8 -10 10 64 64 64
9 -10 10 64 64 64
-10 -9 10 64 64 64
-9 -9 10 64 64 64
-8 -9 10 64 64 64
-7 -9 10 64 64 64
-6 -9 10 64 64 64
-5 -9 10 64 64 64
-4 -9 10 64 64 64
-3 -9 10 64 64 64
-2 -9 10 64 64 64
-1 -9 10 64 64 64
0 -9 10 64 64 64
1 -9 10 64 64 64
2 -9 10 64 64 64
3 -9 10 64 64 64
4 -9 10 64 64 64
5 -9 10 64 64 64
6 -9 10 64 64 64
7 -9 10 64 64 64
8 -9 10 64 64 64
9 -9 10 64 64 64
-10 -8 10 64 64 64
-9 -8 10 64 64 64
-8 -8 10 64 64 64
-7 -8 10 64 64 64
-6 -8 10 64 64 64
-5 -8 10 64 64 64
-4 -8 10 64 64 64
-3 -8 10 64 64 64
-2 -8 10 64 64 64
-1 -8 10 64 64 64
0 -8 10 64 64 64
1 -8 10 64 64 64
2 -8 10 64 64 64
3 -8 10 64 64 64
4 -8 10 64 64 64
5 -8 10 64 64 64
6 -8 10 64 64 64
7 -8 10 64 64 64
8 -8 10 64 64 64
9 -8 10 64 64 64
-10 -7 10 64 64 64
-9 -7 10 64 64 64
-8 -7 10 64 64 64
-7 -7 10 64 64 64
-6 -7 10 64 64 64
-5 -7 10 64 64 64
-4 -7 10 64 64 64
-3 -7 10 64 64 64
-2 -7 10 64 64 64
-1 -7 10 64 64 64
0 -7 10 64 64 64
1 -7 10 64 64 64
2 -7 10 64 64 64
3 -7 10 64 64 64
4 -7 10 64 64 64
5 -7 10 64 64 64
6 -7 10 64 64 64
7 -7 10 64 64 64
8 -7 10 64 64 64
9 -7 10 64 64 64
-10 -6 10 64 64 64
-9 -6 10 64 64 64
-8 -6 10 64 64 64
-7 -6 10 64 64 64
-6 -6 10 64 64 64
-5 -6 10 64 64 64
-4 -6 10 64 64 64
-3 -6 10 64 64 64
-2 -6 10 64 64 64
-1 -6 10 64 64 64
0 -6 10 64 64 64
1 -6 10 64 64 64
2 -6 10 64 64 64
3 -6 10 64 64 64
4 -6 10 64 64 64
5 -6 10 64 64 64
6 -6 10 64 64 64
7 -6 10 64 64 64
8 -6 10 64 64 64
9 -6 10 64 64 64
-10 -5 10 64 64 64
-9 -5 10 64 64 64
-8 -5 10 64 64 64
-7 -5 10 64 64 64
-6 -5 10 64 64 64
-5 -5 10 64 64 64
-4 -5 10 64 64 64
-3 -5 10 64 64 64
-2 -5 10 64 64 64
-1 -5 10 64 64 64
0 -5 10 64 64 64
1 -5 10 64 64 64
2 -5 10 64 64 64
3 -5 10 64 64 64
4 -5 10 64 64 64
5 -5 10 64 64 64
6 -5 10 64 64 64
7 -5 10 64 64 64
8 -5 10 64 64 64
9 -5 10 64 64 64
-10 -4 10 64 64 64
-9 -4 10 64 64 64
-8 -4 10 64 64 64
-7 -4 10 64 64 64
-6 -4 10 64 64 64
-5 -4 10 64 64 64
-4 -4 10 64 64 64
-3 -4 10 64 64 64
-2 -4 10 64 64 64
-1 -4 10 64 64 64
0 -4 10 64 64 64
1 -4 10 64 64 64
2 -4 10 64 64 64
3 -4 10 64 64 64
4 -4 10 64 64 64
5 -4 10 64 64 64
6 -4 10 64 64 64
7 -4 10 64 64 64
8 -4 10 64 64 64
9 -4 10 64 64 64
-10 -3 10 64 64 64
-9 -3 10 64 64 64
-8 -3 10 64 64 64
-7 -3 10 64 64 64
-6 -3 10 64 64 64
-5 -3 10 64 64 64
-4 -3 10 64 64 64
-3 -3 10 64 64 64
-2 -3 10 64 64 64
-1 -3 10 64 64 64
0 -3 10 64 64 64
1 -3 10 64 64 64
2 -3 10 64 64 64
3 -3 10 64 64 64
4 -3 10 64 64 64
5 -3 10 64 64 64
6 -3 10 64 64 64
7 -3 10 64 64 64
8 -3 10 64 64 64
9 -3 10 64 64 64
-10 -2 10 64 64 64
-9 -2 10 64 64 64
-8 -2 10 64 64 64
-7 -2 10 64 64 64
-6 -2 10 64 64 64
-5 -2 10 64 64 64
-4 -2 10 64 64 64
-3 -2 10 64 64 64
-2 -2 10 64 64 64
-1 -2 10 64 64 64
0 -2 10 64 64 64
1 -2 10 64 64 64
2 -2 10 64 64 64
3 -2 10 64 64 64
4 -2 10 64 64 64
5 -2 10 64 64 64
6 -2 10 64 64 64
7 -2 10 64 64 64
8 -2 10 64 64 64
9 -2 10 64 64 64
-10 -1 10 64 64 64
-9 -1 10 64 64 64
-8 -1 10 64 64 64
-7 -1 10 64 64 64
-6 -1 10 64 64 64
-5 -1 10 64 64 64
-4 -1 10 64 64 64
-3 -1 10 64 64 64
-2 -1 10 64 64 64
-1 -1 10 64 64 64
0 -1 10 64 64 64
1 -1 10 64 64 64
2 -1 10 64 64 64
3 -1 10 64 64 64
4 -1 10 64 64 64
5 -1 10 64 64 64
6 -1 10 64 64 64
7 -1 10 64 64 64
8 -1 10 64 64 64
9 -1 10 64 64 64
-10 0 10 64 64 64
-9 0 10 64 64 64
-8 0 10 64 64 64
-7 0 10 64 64 64
-6 0 10 64 64 64
-5 0 10 64 64 64
-4 0 10 64 64 64
-3 0 10 64 64 64
-2 0 10 64 64 64
-1 0 10 64 64 64
0 0 10 64 64 64
1 0 10 64 64 64
2 0 10 64 64 64
3 0 10 64 64 64
4 0 10 64 64 64
5 0 10 64 64 64
6 0 10 64 64 64
7 0 10 64 64 64
8 0 10 64 64 64
9 0 10 64 64 64
-10 1 10 64 64 64
-9 1 10 64 64 64
-8 1 10 64 64 64
-7 1 10 64 64 64
-6 1 10 64 64 64
-5 1 10 64 64 64
-4 1 10 64 64 64
-3 1 10 64 64 64
-2 1 10 64 64 64
-1 1 10 64 64 64
0 1 10 64 64 64
1 1 10 64 64 64
2 1 10 64 64 64
3 1 10 64 64 64
4 1 10 64 64 64
5 1 10 64 64 64
6 1 10 64 64 64
7 1 10 64 64 64
8 1 10 64 64 64
9 1 10 64 64 64
-10 2 10 64 64 64
-9 2 10 64 64 64
-8 2 10 64 64 64
-7 2 10 64 64 64
-6 2 10 64 64 64
-5 2 10 64 64 64
-4 2 10 64 64 64
-3 2 10 64 64 64
-2 2 10 64 64 64
-1 2 10 64 64 64
0 2 10 64 64 64
1 2 10 64 64 64
2 2 10 64 64 64
3 2 10 64 64 64
4 2 10 64 64 64
5 2 10 64 64 64
6 2 10 64 64 64
7 2 10 64 64 64
8 2 10 64 64 64
9 2 10 64 64 64
-10 3 10 64 64 64
-9 3 10 64 64 64
-8 3 10 64 64 64
-7 3 10 64 64 64
-6 3 10 64 64 64
-5 3 10 64 64 64
-4 3 10 64 64 64
-3 3 10 64 64 64
-2 3 10 64 64 64
-1 3 10 64 64 64
0 3 10 64 64 64
1 3 10 64 64 64
2 3 10 64 64 64
3 3 10 64 64 64
4 3 10 64 64 64
5 3 10 64 64 64
6 3 10 64 64 64
7 3 10 64 64 64
8 3 10 64 64 64
9 3 10 64 64 64
-10 4 10 64 64 64
-9 4 10 64 64 64
-8 4 10 64 64 64
-7 4 10 64 64 64
-6 4 10 64 64 64
-5 4 10 64 64 64
-4 4 10 64 64 64
-3 4 10 64 64 64
-2 4 10 64 64 64
-1 4 10 64 64 64
0 4 10 64 64 64
1 4 10 64 64 64
2 4 10 64 64 64
3 4 10 64 64 64
4 4 10 64 64 64
5 4 10 64 64 64
6 4 10 64 64 64
7 4 10 64 64 64
8 4 10 64 64 64
9 4 10 64 64 64
-10 5 10 64 64 64
-9 5 10 64 64 64
-8 5 10 64 64 64
-7 5 10 64 64 64
-6 5 10 64 64 64
-5 5 10 64 64 64
-4 5 10 64 64 64
-3 5 10 64 64 64
-2 5 10 64 64 64
-1 5 10 64 64 64
0 5 10 64 64 64
1 5 10 64 64 64
2 5 10 64 64 64
3 5 10 64 64 64
4 5 10 64 64 64
5 5 10 64 64 64
6 5 10 64 64 64
7 5 10 64 64 64
8 5 10 64 64 64
9 5 10 64 64 64
-10 6 10 64 64 64
-9 6 10 64 64 64
-8 6 10 64 64 64
-7 6 10 64 64 64
-6 6 10 64 64 64
-5 6 10 64 64 64
-4 6 10 64 64 64
-3 6 10 64 64 64
-2 6 10 64 64 64
-1 6 10 64 64 64
0 6 10 64 64 64
1 6 10 64 64 64
2 6 10 64 64 64
3 6 10 64 64 64
4 6 10 64 64 64
5 6 10 64 64 64
6 6 10 64 64 64
7 6 10 64 64 64
8 6 10 64 64 64
9 6 10 64 64 64
-10 7 10 64 64 64
-9 7 10 64 64 64
-8 7 10 64 64 64
-7 7 10 64 64 64
-6 7 10 64 64 64
-5 7 10 64 64 64
-4 7 10 64 64 64
-3 7 10 64 64 64
-2 7 10 64 64 64
-1 7 10 64 64 64
0 7 10 64 64 64
1 7 10 64 64 64
2 7 10 64 64 64
3 7 10 64 64 64
4 7 10 64 64 64
5 7 10 64 64 64
6 7 10 64 64 64
7 7 10 64 64 64
8 7 10 64 64 64
9 7 10 64 64 64
-10 8 10 64 64 64
-9 8 10 64 64 64
-8 8 10 64 64 64
-7 8 10 64 64 64
-6 8 10 64 64 64
-5 8 10 64 64 64
-4 8 10 64 64 64
-3 8 10 64 64 64
-2 8 10 64 64 64
-1 8 10 64 64 64
0 8 10 64 64 64
1 8 10 64 64 64
2 8 10 64 64 64
3 8 10 64 64 64
4 8 10 64 64 64
5 8 10 64 64 64
6 8 10 64 64 64
7 8 10 64 64 64
8 8 10 64 64 64
9 8 10 64 64 64
-10 9 10 64 64 64
-9 9 10 64 64 64
-8 9 10 64 64 64
-7 9 10 64 64 64
-6 9 10 64 64 64
-5 9 10 64 64 64
-4 9 10 64 64 64
-3 9 10 64 64 64
-2 9 10 64 64 64
-1 9 10 64 64 64
0 9 10 64 64 64
1 9 10 64 64 64
2 9 10 64 64 64
3 9 10 64 64 64
4 9 10 64 64 64
5 9 10 64 64 64
6 9 10 64 64 64
7 9 10 64 64 64
8 9 10 64 64 64
9 9 10 64 64 64
