ply
format ascii 1.0
comment : MagicaVoxel @ Ephtracy
element vertex 446
property float x
property float y
property float z
property uchar red
property uchar green
property uchar blue
end_header
-5 -5 0 136 136 136
-4 -5 0 136 136 136
-3 -5 0 136 136 136
-2 -5 0 136 136 136
-1 -5 0 136 136 136
0 -5 0 136 136 136
1 -5 0 136 136 136
2 -5 0 136 136 136
3 -5 0 136 136 136
4 -5 0 136 136 136
-5 -4 0 136 136 136
-4 -4 0 136 136 136
-3 -4 0 136 136 136
-2 -4 0 136 136 136
-1 -4 0 136 136 136
0 -4 0 136 136 136
1 -4 0 136 136 136
2 -4 0 136 136 136
3 -4 0 136 136 136
4 -4 0 136 136 136
-5 -3 0 153 102 0
-4 -3 0 136 136 136
-3 -3 0 136 136 136
-2 -3 0 136 136 136
-1 -3 0 136 136 136
0 -3 0 136 136 136
1 -3 0 136 136 136
2 -3 0 136 136 136
3 -3 0 136 136 136
4 -3 0 136 136 136
-5 -2 0 153 102 0
-4 -2 0 136 136 136
-3 -2 0 136 136 136
-2 -2 0 136 136 136
-1 -2 0 136 136 136
0 -2 0 136 136 136
1 -2 0 136 136 136
2 -2 0 136 136 136
3 -2 0 136 136 136
4 -2 0 136 136 136
-5 -1 0 153 102 0
-4 -1 0 136 136 136
-3 -1 0 136 136 136
-2 -1 0 136 136 136
-1 -1 0 136 136 136
0 -1 0 136 136 136
1 -1 0 136 136 136
2 -1 0 136 136 136
3 -1 0 136 136 136
4 -1 0 136 136 136
-5 0 0 153 102 0
-4 0 0 136 136 136
-3 0 0 136 136 136
-2 0 0 136 136 136
-1 0 0 136 136 136
0 0 0 136 136 136
1 0 0 136 136 136
2 0 0 136 136 136
3 0 0 136 136 136
4 0 0 136 136 136
-5 1 0 153 102 0
-4 1 0 136 136 136
-3 1 0 136 136 136
-2 1 0 136 136 136
-1 1 0 136 136 136
0 1 0 136 136 136
1 1 0 136 136 136
2 1 0 136 136 136
3 1 0 136 136 136
4 1 0 136 136 136
-5 2 0 153 102 0
-4 2 0 136 136 136
-3 2 0 136 136 136
-2 2 0 136 136 136
-1 2 0 136 136 136
0 2 0 136 136 136
1 2 0 136 136 136
2 2 0 136 136 136
3 2 0 136 136 136
4 2 0 136 136 136
-5 3 0 136 136 136
-4 3 0 136 136 136
-3 3 0 136 136 136
-2 3 0 136 136 136
-1 3 0 136 136 136
0 3 0 136 136 136
1 3 0 136 136 136
2 3 0 136 136 136
3 3 0 136 136 136
4 3 0 136 136 136
-5 4 0 136 136 136
-4 4 0 136 136 136
-3 4 0 136 136 136
-2 4 0 136 136 136
-1 4 0 136 136 136
0 4 0 136 136 136
1 4 0 136 136 136
2 4 0 136 136 136
3 4 0 136 136 136
4 4 0 136 136 136
-5 -5 1 136 136 136
-4 -5 1 136 136 136
-3 -5 1 136 136 136
-2 -5 1 136 136 136
-1 -5 1 136 136 136
0 -5 1 136 136 136
1 -5 1 136 136 136
2 -5 1 136 136 136
3 -5 1 136 136 136
4 -5 1 136 136 136
-5 -4 1 153 102 0
4 -4 1 136 136 136
4 -3 1 136 136 136
4 -2 1 136 136 136
4 -1 1 136 136 136
4 0 1 136 136 136
4 1 1 136 136 136
4 2 1 136 136 136
-5 3 1 153 102 0
4 3 1 136 136 136
-5 4 1 136 136 136
-4 4 1 136 136 136
-3 4 1 136 136 136
-2 4 1 136 136 136
-1 4 1 136 136 136
0 4 1 136 136 136
1 4 1 136 136 136
2 4 1 136 136 136
3 4 1 136 136 136
4 4 1 136 136 136
-5 -5 2 136 136 136
-4 -5 2 136 136 136
-3 -5 2 136 136 136
-2 -5 2 136 136 136
-1 -5 2 136 136 136
0 -5 2 136 136 136
1 -5 2 136 136 136
2 -5 2 136 136 136
3 -5 2 136 136 136
4 -5 2 136 136 136
-5 -4 2 153 102 0
4 -4 2 136 136 136
4 -3 2 136 136 136
4 -2 2 136 136 136
4 -1 2 136 136 136
4 0 2 136 136 136
4 1 2 136 136 136
4 2 2 136 136 136
-5 3 2 153 102 0
4 3 2 136 136 136
-5 4 2 136 136 136
-4 4 2 136 136 136
-3 4 2 136 136 136
-2 4 2 136 136 136
-1 4 2 136 136 136
0 4 2 136 136 136
1 4 2 136 136 136
2 4 2 136 136 136
3 4 2 136 136 136
4 4 2 136 136 136
-5 -5 3 136 136 136
-4 -5 3 136 136 136
-3 -5 3 136 136 136
-2 -5 3 136 136 136
-1 -5 3 136 136 136
0 -5 3 136 136 136
1 -5 3 136 136 136
2 -5 3 136 136 136
3 -5 3 136 136 136
4 -5 3 136 136 136
-5 -4 3 153 102 0
4 -4 3 136 136 136
4 -3 3 136 136 136
4 -2 3 136 136 136
4 -1 3 136 136 136
4 0 3 136 136 136
4 1 3 136 136 136
4 2 3 136 136 136
-5 3 3 153 102 0
4 3 3 136 136 136
-5 4 3 136 136 136
-4 4 3 136 136 136
-3 4 3 136 136 136
-2 4 3 136 136 136
-1 4 3 136 136 136
0 4 3 136 136 136
1 4 3 136 136 136
2 4 3 136 136 136
3 4 3 136 136 136
4 4 3 136 136 136
-5 -5 4 136 136 136
-4 -5 4 136 136 136
-3 -5 4 136 136 136
-2 -5 4 136 136 136
-1 -5 4 136 136 136
0 -5 4 136 136 136
1 -5 4 136 136 136
2 -5 4 136 136 136
3 -5 4 136 136 136
4 -5 4 136 136 136
-5 -4 4 153 102 0
4 -4 4 136 136 136
4 -3 4 136 136 136
4 -2 4 136 136 136
4 -1 4 136 136 136
4 0 4 136 136 136
4 1 4 136 136 136
4 2 4 136 136 136
-5 3 4 153 102 0
4 3 4 136 136 136
-5 4 4 136 136 136
-4 4 4 136 136 136
-3 4 4 136 136 136
-2 4 4 136 136 136
-1 4 4 136 136 136
0 4 4 136 136 136
1 4 4 136 136 136
2 4 4 136 136 136
3 4 4 136 136 136
4 4 4 136 136 136
-5 -5 5 136 136 136
-4 -5 5 136 136 136
-3 -5 5 136 136 136
-2 -5 5 136 136 136
-1 -5 5 136 136 136
0 -5 5 136 136 136
1 -5 5 136 136 136
2 -5 5 136 136 136
3 -5 5 136 136 136
4 -5 5 136 136 136
-5 -4 5 153 102 0
4 -4 5 136 136 136
4 -3 5 136 136 136
4 -2 5 136 136 136
4 -1 5 136 136 136
4 0 5 136 136 136
4 1 5 136 136 136
4 2 5 136 136 136
-5 3 5 153 102 0
4 3 5 136 136 136
-5 4 5 136 136 136
-4 4 5 136 136 136
-3 4 5 136 136 136
-2 4 5 136 136 136
-1 4 5 136 136 136
0 4 5 136 136 136
1 4 5 136 136 136
2 4 5 136 136 136
3 4 5 136 136 136
4 4 5 136 136 136
-5 -5 6 136 136 136
-4 -5 6 136 136 136
-3 -5 6 136 136 136
-2 -5 6 136 136 136
-1 -5 6 136 136 136
0 -5 6 136 136 136
1 -5 6 136 136 136
2 -5 6 136 136 136
3 -5 6 136 136 136
4 -5 6 136 136 136
-5 -4 6 153 102 0
4 -4 6 136 136 136
4 -3 6 136 136 136
4 -2 6 136 136 136
4 -1 6 136 136 136
4 0 6 136 136 136
4 1 6 136 136 136
4 2 6 136 136 136
-5 3 6 153 102 0
4 3 6 136 136 136
-5 4 6 136 136 136
-4 4 6 136 136 136
-3 4 6 136 136 136
-2 4 6 136 136 136
-1 4 6 136 136 136
0 4 6 136 136 136
1 4 6 136 136 136
2 4 6 136 136 136
3 4 6 136 136 136
4 4 6 136 136 136
-5 -5 7 136 136 136
-4 -5 7 136 136 136
-3 -5 7 136 136 136
-2 -5 7 136 136 136
-1 -5 7 136 136 136
0 -5 7 136 136 136
1 -5 7 136 136 136
2 -5 7 136 136 136
3 -5 7 136 136 136
4 -5 7 136 136 136
-5 -4 7 153 102 0
4 -4 7 136 136 136
4 -3 7 136 136 136
4 -2 7 136 136 136
4 -1 7 136 136 136
4 0 7 136 136 136
4 1 7 136 136 136
4 2 7 136 136 136
-5 3 7 153 102 0
4 3 7 136 136 136
-5 4 7 136 136 136
-4 4 7 136 136 136
-3 4 7 136 136 136
-2 4 7 136 136 136
-1 4 7 136 136 136
0 4 7 136 136 136
1 4 7 136 136 136
2 4 7 136 136 136
3 4 7 136 136 136
4 4 7 136 136 136
-5 -5 8 136 136 136
-4 -5 8 136 136 136
-3 -5 8 136 136 136
-2 -5 8 136 136 136
-1 -5 8 136 136 136
0 -5 8 136 136 136
1 -5 8 136 136 136
2 -5 8 136 136 136
3 -5 8 136 136 136
4 -5 8 136 136 136
-5 -4 8 153 102 0
4 -4 8 136 136 136
-5 -3 8 153 102 0
4 -3 8 136 136 136
-5 -2 8 153 102 0
4 -2 8 136 136 136
-5 -1 8 153 102 0
4 -1 8 136 136 136
-5 0 8 153 102 0
4 0 8 136 136 136
-5 1 8 153 102 0
4 1 8 136 136 136
-5 2 8 153 102 0
4 2 8 136 136 136
-5 3 8 153 102 0
4 3 8 136 136 136
-5 4 8 136 136 136
-4 4 8 136 136 136
-3 4 8 136 136 136
-2 4 8 136 136 136
-1 4 8 136 136 136
0 4 8 136 136 136
1 4 8 136 136 136
2 4 8 136 136 136
3 4 8 136 136 136
4 4 8 136 136 136
-5 -5 9 136 136 136
-4 -5 9 136 136 136
-3 -5 9 136 136 136
-2 -5 9 136 136 136
-1 -5 9 136 136 136
0 -5 9 136 136 136
1 -5 9 136 136 136
2 -5 9 136 136 136
3 -5 9 136 136 136
4 -5 9 136 136 136
-5 -4 9 136 136 136
-4 -4 9 136 136 136
-3 -4 9 136 136 136
-2 -4 9 136 136 136
-1 -4 9 136 136 136
0 -4 9 136 136 136
1 -4 9 136 136 136
2 -4 9 136 136 136
3 -4 9 136 136 136
4 -4 9 136 136 136
-5 -3 9 136 136 136
-4 -3 9 136 136 136
-3 -3 9 136 136 136
-2 -3 9 136 136 136
-1 -3 9 136 136 136
0 -3 9 136 136 136
1 -3 9 136 136 136
2 -3 9 136 136 136
3 -3 9 136 136 136
4 -3 9 136 136 136
-5 -2 9 136 136 136
-4 -2 9 136 136 136
-3 -2 9 136 136 136
-2 -2 9 136 136 136
-1 -2 9 136 136 136
0 -2 9 136 136 136
1 -2 9 136 136 136
2 -2 9 136 136 136
3 -2 9 136 136 136
4 -2 9 136 136 136
-5 -1 9 136 136 136
-4 -1 9 136 136 136
-3 -1 9 136 136 136
-2 -1 9 136 136 136
-1 -1 9 136 136 136
0 -1 9 136 136 136
1 -1 9 136 136 136
2 -1 9 136 136 136
3 -1 9 136 136 136
4 -1 9 136 136 136
-5 0 9 136 136 136
-4 0 9 136 136 136
-3 0 9 136 136 136
-2 0 9 136 136 136
-1 0 9 136 136 136
0 0 9 136 136 136
1 0 9 136 136 136
2 0 9 136 136 136
3 0 9 136 136 136
4 0 9 136 136 136
-5 1 9 136 136 136
-4 1 9 136 136 136
-3 1 9 136 136 136
-2 1 9 136 136 136
-1 1 9 136 136 136
0 1 9 136 136 136
1 1 9 136 136 136
2 1 9 136 136 136
3 1 9 136 136 136
4 1 9 136 136 136
-5 2 9 136 136 136
-4 2 9 136 136 136
-3 2 9 136 136 136
-2 2 9 136 136 136
-1 2 9 136 136 136
0 2 9 136 136 136
1 2 9 136 136 136
2 2 9 136 136 136
3 2 9 136 136 136
4 2 9 136 136 136
-5 3 9 136 136 136
-4 3 9 136 136 136
-3 3 9 136 136 136
-2 3 9 136 136 136
-1 3 9 136 136 136
0 3 9 136 136 136
1 3 9 136 136 136
2 3 9 136 136 136
3 3 9 136 136 136
4 3 9 136 136 136
-5 4 9 136 136 136
-4 4 9 136 136 136
-3 4 9 136 136 136
-2 4 9 136 136 136
-1 4 9 136 136 136
0 4 9 136 136 136
1 4 9 136 136 136
2 4 9 136 136 136
3 4 9 136 136 136
4 4 9 136 136 136
