ply
format ascii 1.0
comment : MagicaVoxel @ Ephtracy
element vertex 1880
property float x
property float y
property float z
property uchar red
property uchar green
property uchar blue
end_header
-10 -5 0 136 136 136
-9 -5 0 136 136 136
-8 -5 0 136 136 136
-7 -5 0 136 136 136
-6 -5 0 136 136 136
-5 -5 0 136 136 136
-4 -5 0 136 136 136
-3 -5 0 136 136 136
-2 -5 0 136 136 136
-1 -5 0 136 136 136
0 -5 0 136 136 136
1 -5 0 136 136 136
2 -5 0 136 136 136
3 -5 0 136 136 136
4 -5 0 136 136 136
5 -5 0 136 136 136
6 -5 0 136 136 136
7 -5 0 136 136 136
8 -5 0 136 136 136
9 -5 0 136 136 136
-10 -4 0 136 136 136
-9 -4 0 136 136 136
-8 -4 0 136 136 136
-7 -4 0 136 136 136
-6 -4 0 136 136 136
-5 -4 0 136 136 136
-4 -4 0 136 136 136
-3 -4 0 85 85 85
-2 -4 0 136 136 136
-1 -4 0 85 85 85
0 -4 0 136 136 136
1 -4 0 85 85 85
2 -4 0 136 136 136
3 -4 0 85 85 85
4 -4 0 136 136 136
5 -4 0 85 85 85
6 -4 0 136 136 136
7 -4 0 136 136 136
8 -4 0 136 136 136
9 -4 0 136 136 136
-10 -3 0 136 136 136
-9 -3 0 136 136 136
-8 -3 0 136 136 136
-7 -3 0 136 136 136
-6 -3 0 136 136 136
-5 -3 0 136 136 136
-4 -3 0 136 136 136
-3 -3 0 85 85 85
-2 -3 0 136 136 136
-1 -3 0 85 85 85
0 -3 0 136 136 136
1 -3 0 85 85 85
2 -3 0 136 136 136
3 -3 0 85 85 85
4 -3 0 136 136 136
5 -3 0 85 85 85
6 -3 0 136 136 136
7 -3 0 136 136 136
8 -3 0 136 136 136
9 -3 0 136 136 136
-10 -2 0 136 136 136
-9 -2 0 136 136 136
-8 -2 0 136 136 136
-7 -2 0 136 136 136
-6 -2 0 136 136 136
-5 -2 0 136 136 136
-4 -2 0 136 136 136
-3 -2 0 85 85 85
-2 -2 0 136 136 136
-1 -2 0 85 85 85
0 -2 0 136 136 136
1 -2 0 85 85 85
2 -2 0 136 136 136
3 -2 0 85 85 85
4 -2 0 136 136 136
5 -2 0 85 85 85
6 -2 0 136 136 136
7 -2 0 136 136 136
8 -2 0 136 136 136
9 -2 0 136 136 136
-10 -1 0 136 136 136
-9 -1 0 136 136 136
-8 -1 0 136 136 136
-7 -1 0 136 136 136
-6 -1 0 136 136 136
-5 -1 0 136 136 136
-4 -1 0 136 136 136
-3 -1 0 85 85 85
-2 -1 0 136 136 136
-1 -1 0 85 85 85
0 -1 0 136 136 136
1 -1 0 85 85 85
2 -1 0 136 136 136
3 -1 0 85 85 85
4 -1 0 136 136 136
5 -1 0 85 85 85
6 -1 0 136 136 136
7 -1 0 136 136 136
8 -1 0 136 136 136
9 -1 0 136 136 136
-10 0 0 136 136 136
-9 0 0 136 136 136
-8 0 0 136 136 136
-7 0 0 136 136 136
-6 0 0 136 136 136
-5 0 0 136 136 136
-4 0 0 136 136 136
-3 0 0 85 85 85
-2 0 0 136 136 136
-1 0 0 85 85 85
0 0 0 136 136 136
1 0 0 85 85 85
2 0 0 136 136 136
3 0 0 85 85 85
4 0 0 136 136 136
5 0 0 85 85 85
6 0 0 136 136 136
7 0 0 136 136 136
8 0 0 136 136 136
9 0 0 136 136 136
-10 1 0 136 136 136
-9 1 0 136 136 136
-8 1 0 136 136 136
-7 1 0 136 136 136
-6 1 0 136 136 136
-5 1 0 136 136 136
-4 1 0 136 136 136
-3 1 0 85 85 85
-2 1 0 136 136 136
-1 1 0 85 85 85
0 1 0 136 136 136
1 1 0 85 85 85
2 1 0 136 136 136
3 1 0 85 85 85
4 1 0 136 136 136
5 1 0 85 85 85
6 1 0 136 136 136
7 1 0 136 136 136
8 1 0 136 136 136
9 1 0 136 136 136
-10 2 0 136 136 136
-9 2 0 136 136 136
-8 2 0 136 136 136
-7 2 0 136 136 136
-6 2 0 136 136 136
-5 2 0 136 136 136
-4 2 0 136 136 136
-3 2 0 85 85 85
-2 2 0 136 136 136
-1 2 0 85 85 85
0 2 0 136 136 136
1 2 0 85 85 85
2 2 0 136 136 136
3 2 0 85 85 85
4 2 0 136 136 136
5 2 0 85 85 85
6 2 0 136 136 136
7 2 0 136 136 136
8 2 0 136 136 136
9 2 0 136 136 136
-10 3 0 136 136 136
-9 3 0 136 136 136
-8 3 0 136 136 136
-7 3 0 136 136 136
-6 3 0 136 136 136
-5 3 0 136 136 136
-4 3 0 136 136 136
-3 3 0 85 85 85
-2 3 0 136 136 136
-1 3 0 85 85 85
0 3 0 136 136 136
1 3 0 85 85 85
2 3 0 136 136 136
3 3 0 85 85 85
4 3 0 136 136 136
5 3 0 85 85 85
6 3 0 136 136 136
7 3 0 136 136 136
8 3 0 136 136 136
9 3 0 136 136 136
-10 4 0 136 136 136
-9 4 0 136 136 136
-8 4 0 136 136 136
-7 4 0 136 136 136
-6 4 0 136 136 136
-5 4 0 136 136 136
-4 4 0 136 136 136
-3 4 0 85 85 85
-2 4 0 136 136 136
-1 4 0 85 85 85
0 4 0 136 136 136
1 4 0 85 85 85
2 4 0 136 136 136
3 4 0 85 85 85
4 4 0 136 136 136
5 4 0 85 85 85
6 4 0 136 136 136
7 4 0 136 136 136
8 4 0 136 136 136
9 4 0 136 136 136
-10 -5 1 136 136 136
-9 -5 1 136 136 136
-8 -5 1 136 136 136
-7 -5 1 136 136 136
-6 -5 1 136 136 136
-5 -5 1 136 136 136
-4 -5 1 136 136 136
-3 -5 1 85 85 85
-2 -5 1 136 136 136
-1 -5 1 85 85 85
0 -5 1 136 136 136
1 -5 1 85 85 85
2 -5 1 136 136 136
3 -5 1 85 85 85
4 -5 1 136 136 136
5 -5 1 85 85 85
6 -5 1 136 136 136
7 -5 1 136 136 136
8 -5 1 136 136 136
9 -5 1 136 136 136
-3 -4 1 85 85 85
-2 -4 1 136 136 136
-1 -4 1 85 85 85
0 -4 1 136 136 136
1 -4 1 85 85 85
2 -4 1 136 136 136
3 -4 1 85 85 85
4 -4 1 136 136 136
5 -4 1 85 85 85
6 -4 1 136 136 136
7 -4 1 136 136 136
8 -4 1 136 136 136
9 -4 1 136 136 136
-3 -3 1 85 85 85
-2 -3 1 136 136 136
-1 -3 1 85 85 85
0 -3 1 136 136 136
1 -3 1 85 85 85
2 -3 1 136 136 136
3 -3 1 85 85 85
4 -3 1 136 136 136
5 -3 1 85 85 85
6 -3 1 136 136 136
7 -3 1 136 136 136
8 -3 1 136 136 136
9 -3 1 136 136 136
-3 -2 1 85 85 85
-2 -2 1 136 136 136
-1 -2 1 85 85 85
0 -2 1 136 136 136
1 -2 1 85 85 85
2 -2 1 136 136 136
3 -2 1 85 85 85
4 -2 1 136 136 136
5 -2 1 85 85 85
6 -2 1 136 136 136
7 -2 1 136 136 136
8 -2 1 136 136 136
9 -2 1 136 136 136
-3 -1 1 85 85 85
-2 -1 1 136 136 136
-1 -1 1 85 85 85
0 -1 1 136 136 136
1 -1 1 85 85 85
2 -1 1 136 136 136
3 -1 1 85 85 85
4 -1 1 136 136 136
5 -1 1 85 85 85
6 -1 1 136 136 136
7 -1 1 136 136 136
8 -1 1 136 136 136
9 -1 1 136 136 136
-3 0 1 85 85 85
-2 0 1 136 136 136
-1 0 1 85 85 85
0 0 1 136 136 136
1 0 1 85 85 85
2 0 1 136 136 136
3 0 1 85 85 85
4 0 1 136 136 136
5 0 1 85 85 85
6 0 1 136 136 136
7 0 1 136 136 136
8 0 1 136 136 136
9 0 1 136 136 136
-3 1 1 85 85 85
-2 1 1 136 136 136
-1 1 1 85 85 85
0 1 1 136 136 136
1 1 1 85 85 85
2 1 1 136 136 136
3 1 1 85 85 85
4 1 1 136 136 136
5 1 1 85 85 85
6 1 1 136 136 136
7 1 1 136 136 136
8 1 1 136 136 136
9 1 1 136 136 136
-3 2 1 85 85 85
-2 2 1 136 136 136
-1 2 1 85 85 85
0 2 1 136 136 136
1 2 1 85 85 85
2 2 1 136 136 136
3 2 1 85 85 85
4 2 1 136 136 136
5 2 1 85 85 85
6 2 1 136 136 136
7 2 1 136 136 136
8 2 1 136 136 136
9 2 1 136 136 136
-3 3 1 85 85 85
-2 3 1 136 136 136
-1 3 1 85 85 85
0 3 1 136 136 136
1 3 1 85 85 85
2 3 1 136 136 136
3 3 1 85 85 85
4 3 1 136 136 136
5 3 1 85 85 85
6 3 1 136 136 136
7 3 1 136 136 136
8 3 1 136 136 136
9 3 1 136 136 136
-10 4 1 136 136 136
-9 4 1 136 136 136
-8 4 1 136 136 136
-7 4 1 136 136 136
-6 4 1 136 136 136
-5 4 1 136 136 136
-4 4 1 136 136 136
-3 4 1 85 85 85
-2 4 1 136 136 136
-1 4 1 85 85 85
0 4 1 136 136 136
1 4 1 85 85 85
2 4 1 136 136 136
3 4 1 85 85 85
4 4 1 136 136 136
5 4 1 85 85 85
6 4 1 136 136 136
7 4 1 136 136 136
8 4 1 136 136 136
9 4 1 136 136 136
-10 -5 2 136 136 136
-9 -5 2 136 136 136
-8 -5 2 136 136 136
-7 -5 2 136 136 136
-6 -5 2 136 136 136
-5 -5 2 136 136 136
-4 -5 2 136 136 136
-3 -5 2 136 136 136
-2 -5 2 136 136 136
-1 -5 2 85 85 85
0 -5 2 136 136 136
1 -5 2 85 85 85
2 -5 2 136 136 136
3 -5 2 85 85 85
4 -5 2 136 136 136
5 -5 2 85 85 85
6 -5 2 136 136 136
7 -5 2 136 136 136
8 -5 2 136 136 136
9 -5 2 136 136 136
-2 -4 2 136 136 136
-1 -4 2 85 85 85
0 -4 2 136 136 136
1 -4 2 85 85 85
2 -4 2 136 136 136
3 -4 2 85 85 85
4 -4 2 136 136 136
5 -4 2 85 85 85
6 -4 2 136 136 136
7 -4 2 136 136 136
8 -4 2 136 136 136
9 -4 2 136 136 136
-2 -3 2 136 136 136
-1 -3 2 85 85 85
0 -3 2 136 136 136
1 -3 2 85 85 85
2 -3 2 136 136 136
3 -3 2 85 85 85
4 -3 2 136 136 136
5 -3 2 85 85 85
6 -3 2 136 136 136
7 -3 2 136 136 136
8 -3 2 136 136 136
9 -3 2 136 136 136
-2 -2 2 136 136 136
-1 -2 2 85 85 85
0 -2 2 136 136 136
1 -2 2 85 85 85
2 -2 2 136 136 136
3 -2 2 85 85 85
4 -2 2 136 136 136
5 -2 2 85 85 85
6 -2 2 136 136 136
7 -2 2 136 136 136
8 -2 2 136 136 136
9 -2 2 136 136 136
-2 -1 2 136 136 136
-1 -1 2 85 85 85
0 -1 2 136 136 136
1 -1 2 85 85 85
2 -1 2 136 136 136
3 -1 2 85 85 85
4 -1 2 136 136 136
5 -1 2 85 85 85
6 -1 2 136 136 136
7 -1 2 136 136 136
8 -1 2 136 136 136
9 -1 2 136 136 136
-2 0 2 136 136 136
-1 0 2 85 85 85
0 0 2 136 136 136
1 0 2 85 85 85
2 0 2 136 136 136
3 0 2 85 85 85
4 0 2 136 136 136
5 0 2 85 85 85
6 0 2 136 136 136
7 0 2 136 136 136
8 0 2 136 136 136
9 0 2 136 136 136
-2 1 2 136 136 136
-1 1 2 85 85 85
0 1 2 136 136 136
1 1 2 85 85 85
2 1 2 136 136 136
3 1 2 85 85 85
4 1 2 136 136 136
5 1 2 85 85 85
6 1 2 136 136 136
7 1 2 136 136 136
8 1 2 136 136 136
9 1 2 136 136 136
-2 2 2 136 136 136
-1 2 2 85 85 85
0 2 2 136 136 136
1 2 2 85 85 85
2 2 2 136 136 136
3 2 2 85 85 85
4 2 2 136 136 136
5 2 2 85 85 85
6 2 2 136 136 136
7 2 2 136 136 136
8 2 2 136 136 136
9 2 2 136 136 136
-2 3 2 136 136 136
-1 3 2 85 85 85
0 3 2 136 136 136
1 3 2 85 85 85
2 3 2 136 136 136
3 3 2 85 85 85
4 3 2 136 136 136
5 3 2 85 85 85
6 3 2 136 136 136
7 3 2 136 136 136
8 3 2 136 136 136
9 3 2 136 136 136
-10 4 2 136 136 136
-9 4 2 136 136 136
-8 4 2 136 136 136
-7 4 2 136 136 136
-6 4 2 136 136 136
-5 4 2 136 136 136
-4 4 2 136 136 136
-3 4 2 136 136 136
-2 4 2 136 136 136
-1 4 2 85 85 85
0 4 2 136 136 136
1 4 2 85 85 85
2 4 2 136 136 136
3 4 2 85 85 85
4 4 2 136 136 136
5 4 2 85 85 85
6 4 2 136 136 136
7 4 2 136 136 136
8 4 2 136 136 136
9 4 2 136 136 136
-10 -5 3 136 136 136
-9 -5 3 136 136 136
-8 -5 3 136 136 136
-7 -5 3 136 136 136
-6 -5 3 136 136 136
-5 -5 3 136 136 136
-4 -5 3 136 136 136
-3 -5 3 136 136 136
-2 -5 3 136 136 136
-1 -5 3 85 85 85
0 -5 3 136 136 136
1 -5 3 85 85 85
2 -5 3 136 136 136
3 -5 3 85 85 85
4 -5 3 136 136 136
5 -5 3 85 85 85
6 -5 3 136 136 136
7 -5 3 136 136 136
8 -5 3 136 136 136
9 -5 3 136 136 136
-1 -4 3 85 85 85
0 -4 3 136 136 136
1 -4 3 85 85 85
2 -4 3 136 136 136
3 -4 3 85 85 85
4 -4 3 136 136 136
5 -4 3 85 85 85
6 -4 3 136 136 136
7 -4 3 136 136 136
8 -4 3 136 136 136
9 -4 3 136 136 136
-1 -3 3 85 85 85
0 -3 3 136 136 136
1 -3 3 85 85 85
2 -3 3 136 136 136
3 -3 3 85 85 85
4 -3 3 136 136 136
5 -3 3 85 85 85
6 -3 3 136 136 136
7 -3 3 136 136 136
8 -3 3 136 136 136
9 -3 3 136 136 136
-1 -2 3 85 85 85
0 -2 3 136 136 136
1 -2 3 85 85 85
2 -2 3 136 136 136
3 -2 3 85 85 85
4 -2 3 136 136 136
5 -2 3 85 85 85
6 -2 3 136 136 136
7 -2 3 136 136 136
8 -2 3 136 136 136
9 -2 3 136 136 136
-1 -1 3 85 85 85
0 -1 3 136 136 136
1 -1 3 85 85 85
2 -1 3 136 136 136
3 -1 3 85 85 85
4 -1 3 136 136 136
5 -1 3 85 85 85
6 -1 3 136 136 136
7 -1 3 136 136 136
8 -1 3 136 136 136
9 -1 3 136 136 136
-1 0 3 85 85 85
0 0 3 136 136 136
1 0 3 85 85 85
2 0 3 136 136 136
3 0 3 85 85 85
4 0 3 136 136 136
5 0 3 85 85 85
6 0 3 136 136 136
7 0 3 136 136 136
8 0 3 136 136 136
9 0 3 136 136 136
-1 1 3 85 85 85
0 1 3 136 136 136
1 1 3 85 85 85
2 1 3 136 136 136
3 1 3 85 85 85
4 1 3 136 136 136
5 1 3 85 85 85
6 1 3 136 136 136
7 1 3 136 136 136
8 1 3 136 136 136
9 1 3 136 136 136
-1 2 3 85 85 85
0 2 3 136 136 136
1 2 3 85 85 85
2 2 3 136 136 136
3 2 3 85 85 85
4 2 3 136 136 136
5 2 3 85 85 85
6 2 3 136 136 136
7 2 3 136 136 136
8 2 3 136 136 136
9 2 3 136 136 136
-1 3 3 85 85 85
0 3 3 136 136 136
1 3 3 85 85 85
2 3 3 136 136 136
3 3 3 85 85 85
4 3 3 136 136 136
5 3 3 85 85 85
6 3 3 136 136 136
7 3 3 136 136 136
8 3 3 136 136 136
9 3 3 136 136 136
-10 4 3 136 136 136
-9 4 3 136 136 136
-8 4 3 136 136 136
-7 4 3 136 136 136
-6 4 3 136 136 136
-5 4 3 136 136 136
-4 4 3 136 136 136
-3 4 3 136 136 136
-2 4 3 136 136 136
-1 4 3 85 85 85
0 4 3 136 136 136
1 4 3 85 85 85
2 4 3 136 136 136
3 4 3 85 85 85
4 4 3 136 136 136
5 4 3 85 85 85
6 4 3 136 136 136
7 4 3 136 136 136
8 4 3 136 136 136
9 4 3 136 136 136
-10 -5 4 136 136 136
-9 -5 4 136 136 136
-8 -5 4 136 136 136
-7 -5 4 136 136 136
-6 -5 4 136 136 136
-5 -5 4 136 136 136
-4 -5 4 136 136 136
-3 -5 4 136 136 136
-2 -5 4 136 136 136
-1 -5 4 136 136 136
0 -5 4 136 136 136
1 -5 4 85 85 85
2 -5 4 136 136 136
3 -5 4 85 85 85
4 -5 4 136 136 136
5 -5 4 85 85 85
6 -5 4 136 136 136
7 -5 4 136 136 136
8 -5 4 136 136 136
9 -5 4 136 136 136
0 -4 4 136 136 136
1 -4 4 85 85 85
2 -4 4 136 136 136
3 -4 4 85 85 85
4 -4 4 136 136 136
5 -4 4 85 85 85
6 -4 4 136 136 136
7 -4 4 136 136 136
8 -4 4 136 136 136
9 -4 4 136 136 136
0 -3 4 136 136 136
1 -3 4 85 85 85
2 -3 4 136 136 136
3 -3 4 85 85 85
4 -3 4 136 136 136
5 -3 4 85 85 85
6 -3 4 136 136 136
7 -3 4 136 136 136
8 -3 4 136 136 136
9 -3 4 136 136 136
0 -2 4 136 136 136
1 -2 4 85 85 85
2 -2 4 136 136 136
3 -2 4 85 85 85
4 -2 4 136 136 136
5 -2 4 85 85 85
6 -2 4 136 136 136
7 -2 4 136 136 136
8 -2 4 136 136 136
9 -2 4 136 136 136
0 -1 4 136 136 136
1 -1 4 85 85 85
2 -1 4 136 136 136
3 -1 4 85 85 85
4 -1 4 136 136 136
5 -1 4 85 85 85
6 -1 4 136 136 136
7 -1 4 136 136 136
8 -1 4 136 136 136
9 -1 4 136 136 136
0 0 4 136 136 136
1 0 4 85 85 85
2 0 4 136 136 136
3 0 4 85 85 85
4 0 4 136 136 136
5 0 4 85 85 85
6 0 4 136 136 136
7 0 4 136 136 136
8 0 4 136 136 136
9 0 4 136 136 136
0 1 4 136 136 136
1 1 4 85 85 85
2 1 4 136 136 136
3 1 4 85 85 85
4 1 4 136 136 136
5 1 4 85 85 85
6 1 4 136 136 136
7 1 4 136 136 136
8 1 4 136 136 136
9 1 4 136 136 136
0 2 4 136 136 136
1 2 4 85 85 85
2 2 4 136 136 136
3 2 4 85 85 85
4 2 4 136 136 136
5 2 4 85 85 85
6 2 4 136 136 136
7 2 4 136 136 136
8 2 4 136 136 136
9 2 4 136 136 136
0 3 4 136 136 136
1 3 4 85 85 85
2 3 4 136 136 136
3 3 4 85 85 85
4 3 4 136 136 136
5 3 4 85 85 85
6 3 4 136 136 136
7 3 4 136 136 136
8 3 4 136 136 136
9 3 4 136 136 136
-10 4 4 136 136 136
-9 4 4 136 136 136
-8 4 4 136 136 136
-7 4 4 136 136 136
-6 4 4 136 136 136
-5 4 4 136 136 136
-4 4 4 136 136 136
-3 4 4 136 136 136
-2 4 4 136 136 136
-1 4 4 136 136 136
0 4 4 136 136 136
1 4 4 85 85 85
2 4 4 136 136 136
3 4 4 85 85 85
4 4 4 136 136 136
5 4 4 85 85 85
6 4 4 136 136 136
7 4 4 136 136 136
8 4 4 136 136 136
9 4 4 136 136 136
-10 -5 5 136 136 136
-9 -5 5 136 136 136
-8 -5 5 136 136 136
-7 -5 5 136 136 136
-6 -5 5 136 136 136
-5 -5 5 136 136 136
-4 -5 5 136 136 136
-3 -5 5 136 136 136
-2 -5 5 136 136 136
-1 -5 5 136 136 136
0 -5 5 136 136 136
1 -5 5 85 85 85
2 -5 5 136 136 136
3 -5 5 85 85 85
4 -5 5 136 136 136
5 -5 5 85 85 85
6 -5 5 136 136 136
7 -5 5 136 136 136
8 -5 5 136 136 136
9 -5 5 136 136 136
1 -4 5 85 85 85
2 -4 5 136 136 136
3 -4 5 85 85 85
4 -4 5 136 136 136
5 -4 5 85 85 85
6 -4 5 136 136 136
7 -4 5 136 136 136
8 -4 5 136 136 136
9 -4 5 136 136 136
1 -3 5 85 85 85
2 -3 5 136 136 136
3 -3 5 85 85 85
4 -3 5 136 136 136
5 -3 5 85 85 85
6 -3 5 136 136 136
7 -3 5 136 136 136
8 -3 5 136 136 136
9 -3 5 136 136 136
1 -2 5 85 85 85
2 -2 5 136 136 136
3 -2 5 85 85 85
4 -2 5 136 136 136
5 -2 5 85 85 85
6 -2 5 136 136 136
7 -2 5 136 136 136
8 -2 5 136 136 136
9 -2 5 136 136 136
1 -1 5 85 85 85
2 -1 5 136 136 136
3 -1 5 85 85 85
4 -1 5 136 136 136
5 -1 5 85 85 85
6 -1 5 136 136 136
7 -1 5 136 136 136
8 -1 5 136 136 136
9 -1 5 136 136 136
1 0 5 85 85 85
2 0 5 136 136 136
3 0 5 85 85 85
4 0 5 136 136 136
5 0 5 85 85 85
6 0 5 136 136 136
7 0 5 136 136 136
8 0 5 136 136 136
9 0 5 136 136 136
1 1 5 85 85 85
2 1 5 136 136 136
3 1 5 85 85 85
4 1 5 136 136 136
5 1 5 85 85 85
6 1 5 136 136 136
7 1 5 136 136 136
8 1 5 136 136 136
9 1 5 136 136 136
1 2 5 85 85 85
2 2 5 136 136 136
3 2 5 85 85 85
4 2 5 136 136 136
5 2 5 85 85 85
6 2 5 136 136 136
7 2 5 136 136 136
8 2 5 136 136 136
9 2 5 136 136 136
1 3 5 85 85 85
2 3 5 136 136 136
3 3 5 85 85 85
4 3 5 136 136 136
5 3 5 85 85 85
6 3 5 136 136 136
7 3 5 136 136 136
8 3 5 136 136 136
9 3 5 136 136 136
-10 4 5 136 136 136
-9 4 5 136 136 136
-8 4 5 136 136 136
-7 4 5 136 136 136
-6 4 5 136 136 136
-5 4 5 136 136 136
-4 4 5 136 136 136
-3 4 5 136 136 136
-2 4 5 136 136 136
-1 4 5 136 136 136
0 4 5 136 136 136
1 4 5 85 85 85
2 4 5 136 136 136
3 4 5 85 85 85
4 4 5 136 136 136
5 4 5 85 85 85
6 4 5 136 136 136
7 4 5 136 136 136
8 4 5 136 136 136
9 4 5 136 136 136
-10 -5 6 136 136 136
-9 -5 6 136 136 136
-8 -5 6 136 136 136
-7 -5 6 136 136 136
-6 -5 6 136 136 136
-5 -5 6 136 136 136
-4 -5 6 136 136 136
-3 -5 6 136 136 136
-2 -5 6 136 136 136
-1 -5 6 136 136 136
0 -5 6 136 136 136
1 -5 6 136 136 136
2 -5 6 136 136 136
3 -5 6 85 85 85
4 -5 6 136 136 136
5 -5 6 85 85 85
6 -5 6 136 136 136
7 -5 6 136 136 136
8 -5 6 136 136 136
9 -5 6 136 136 136
2 -4 6 136 136 136
3 -4 6 85 85 85
4 -4 6 136 136 136
5 -4 6 85 85 85
6 -4 6 136 136 136
7 -4 6 136 136 136
8 -4 6 136 136 136
9 -4 6 136 136 136
2 -3 6 136 136 136
3 -3 6 85 85 85
4 -3 6 136 136 136
5 -3 6 85 85 85
6 -3 6 136 136 136
7 -3 6 136 136 136
8 -3 6 136 136 136
9 -3 6 136 136 136
2 -2 6 136 136 136
3 -2 6 85 85 85
4 -2 6 136 136 136
5 -2 6 85 85 85
6 -2 6 136 136 136
7 -2 6 136 136 136
8 -2 6 136 136 136
9 -2 6 136 136 136
2 -1 6 136 136 136
3 -1 6 85 85 85
4 -1 6 136 136 136
5 -1 6 85 85 85
6 -1 6 136 136 136
7 -1 6 136 136 136
8 -1 6 136 136 136
9 -1 6 136 136 136
2 0 6 136 136 136
3 0 6 85 85 85
4 0 6 136 136 136
5 0 6 85 85 85
6 0 6 136 136 136
7 0 6 136 136 136
8 0 6 136 136 136
9 0 6 136 136 136
2 1 6 136 136 136
3 1 6 85 85 85
4 1 6 136 136 136
5 1 6 85 85 85
6 1 6 136 136 136
7 1 6 136 136 136
8 1 6 136 136 136
9 1 6 136 136 136
2 2 6 136 136 136
3 2 6 85 85 85
4 2 6 136 136 136
5 2 6 85 85 85
6 2 6 136 136 136
7 2 6 136 136 136
8 2 6 136 136 136
9 2 6 136 136 136
2 3 6 136 136 136
3 3 6 85 85 85
4 3 6 136 136 136
5 3 6 85 85 85
6 3 6 136 136 136
7 3 6 136 136 136
8 3 6 136 136 136
9 3 6 136 136 136
-10 4 6 136 136 136
-9 4 6 136 136 136
-8 4 6 136 136 136
-7 4 6 136 136 136
-6 4 6 136 136 136
-5 4 6 136 136 136
-4 4 6 136 136 136
-3 4 6 136 136 136
-2 4 6 136 136 136
-1 4 6 136 136 136
0 4 6 136 136 136
1 4 6 136 136 136
2 4 6 136 136 136
3 4 6 85 85 85
4 4 6 136 136 136
5 4 6 85 85 85
6 4 6 136 136 136
7 4 6 136 136 136
8 4 6 136 136 136
9 4 6 136 136 136
-10 -5 7 136 136 136
-9 -5 7 136 136 136
-8 -5 7 136 136 136
-7 -5 7 136 136 136
-6 -5 7 136 136 136
-5 -5 7 136 136 136
-4 -5 7 136 136 136
-3 -5 7 136 136 136
-2 -5 7 136 136 136
-1 -5 7 136 136 136
0 -5 7 136 136 136
1 -5 7 136 136 136
2 -5 7 136 136 136
3 -5 7 85 85 85
4 -5 7 136 136 136
5 -5 7 85 85 85
6 -5 7 136 136 136
7 -5 7 136 136 136
8 -5 7 136 136 136
9 -5 7 136 136 136
3 -4 7 85 85 85
4 -4 7 136 136 136
5 -4 7 85 85 85
6 -4 7 136 136 136
7 -4 7 136 136 136
8 -4 7 136 136 136
9 -4 7 136 136 136
3 -3 7 85 85 85
4 -3 7 136 136 136
5 -3 7 85 85 85
6 -3 7 136 136 136
7 -3 7 136 136 136
8 -3 7 136 136 136
9 -3 7 136 136 136
3 -2 7 85 85 85
4 -2 7 136 136 136
5 -2 7 85 85 85
6 -2 7 136 136 136
7 -2 7 136 136 136
8 -2 7 136 136 136
9 -2 7 136 136 136
3 -1 7 85 85 85
4 -1 7 136 136 136
5 -1 7 85 85 85
6 -1 7 136 136 136
7 -1 7 136 136 136
8 -1 7 136 136 136
9 -1 7 136 136 136
3 0 7 85 85 85
4 0 7 136 136 136
5 0 7 85 85 85
6 0 7 136 136 136
7 0 7 136 136 136
8 0 7 136 136 136
9 0 7 136 136 136
3 1 7 85 85 85
4 1 7 136 136 136
5 1 7 85 85 85
6 1 7 136 136 136
7 1 7 136 136 136
8 1 7 136 136 136
9 1 7 136 136 136
3 2 7 85 85 85
4 2 7 136 136 136
5 2 7 85 85 85
6 2 7 136 136 136
7 2 7 136 136 136
8 2 7 136 136 136
9 2 7 136 136 136
3 3 7 85 85 85
4 3 7 136 136 136
5 3 7 85 85 85
6 3 7 136 136 136
7 3 7 136 136 136
8 3 7 136 136 136
9 3 7 136 136 136
-10 4 7 136 136 136
-9 4 7 136 136 136
-8 4 7 136 136 136
-7 4 7 136 136 136
-6 4 7 136 136 136
-5 4 7 136 136 136
-4 4 7 136 136 136
-3 4 7 136 136 136
-2 4 7 136 136 136
-1 4 7 136 136 136
0 4 7 136 136 136
1 4 7 136 136 136
2 4 7 136 136 136
3 4 7 85 85 85
4 4 7 136 136 136
5 4 7 85 85 85
6 4 7 136 136 136
7 4 7 136 136 136
8 4 7 136 136 136
9 4 7 136 136 136
-10 -5 8 136 136 136
-9 -5 8 136 136 136
-8 -5 8 136 136 136
-7 -5 8 136 136 136
-6 -5 8 136 136 136
-5 -5 8 136 136 136
-4 -5 8 136 136 136
-3 -5 8 136 136 136
-2 -5 8 136 136 136
-1 -5 8 136 136 136
0 -5 8 136 136 136
1 -5 8 136 136 136
2 -5 8 136 136 136
3 -5 8 136 136 136
4 -5 8 136 136 136
5 -5 8 85 85 85
6 -5 8 136 136 136
7 -5 8 136 136 136
8 -5 8 136 136 136
9 -5 8 136 136 136
4 -4 8 136 136 136
5 -4 8 85 85 85
6 -4 8 136 136 136
7 -4 8 136 136 136
8 -4 8 136 136 136
9 -4 8 136 136 136
4 -3 8 136 136 136
5 -3 8 85 85 85
6 -3 8 136 136 136
7 -3 8 136 136 136
8 -3 8 136 136 136
9 -3 8 136 136 136
4 -2 8 136 136 136
5 -2 8 85 85 85
6 -2 8 136 136 136
7 -2 8 136 136 136
8 -2 8 136 136 136
9 -2 8 136 136 136
4 -1 8 136 136 136
5 -1 8 85 85 85
6 -1 8 136 136 136
7 -1 8 136 136 136
8 -1 8 136 136 136
9 -1 8 136 136 136
4 0 8 136 136 136
5 0 8 85 85 85
6 0 8 136 136 136
7 0 8 136 136 136
8 0 8 136 136 136
9 0 8 136 136 136
4 1 8 136 136 136
5 1 8 85 85 85
6 1 8 136 136 136
7 1 8 136 136 136
8 1 8 136 136 136
9 1 8 136 136 136
4 2 8 136 136 136
5 2 8 85 85 85
6 2 8 136 136 136
7 2 8 136 136 136
8 2 8 136 136 136
9 2 8 136 136 136
4 3 8 136 136 136
5 3 8 85 85 85
6 3 8 136 136 136
7 3 8 136 136 136
8 3 8 136 136 136
9 3 8 136 136 136
-10 4 8 136 136 136
-9 4 8 136 136 136
-8 4 8 136 136 136
-7 4 8 136 136 136
-6 4 8 136 136 136
-5 4 8 136 136 136
-4 4 8 136 136 136
-3 4 8 136 136 136
-2 4 8 136 136 136
-1 4 8 136 136 136
0 4 8 136 136 136
1 4 8 136 136 136
2 4 8 136 136 136
3 4 8 136 136 136
4 4 8 136 136 136
5 4 8 85 85 85
6 4 8 136 136 136
7 4 8 136 136 136
8 4 8 136 136 136
9 4 8 136 136 136
-10 -5 9 136 136 136
-9 -5 9 136 136 136
-8 -5 9 136 136 136
-7 -5 9 136 136 136
-6 -5 9 136 136 136
-5 -5 9 136 136 136
-4 -5 9 136 136 136
-3 -5 9 136 136 136
-2 -5 9 136 136 136
-1 -5 9 136 136 136
0 -5 9 136 136 136
1 -5 9 136 136 136
2 -5 9 136 136 136
3 -5 9 136 136 136
4 -5 9 136 136 136
5 -5 9 85 85 85
6 -5 9 136 136 136
7 -5 9 136 136 136
8 -5 9 136 136 136
9 -5 9 136 136 136
-10 -4 9 136 136 136
5 -4 9 85 85 85
6 -4 9 136 136 136
7 -4 9 136 136 136
8 -4 9 136 136 136
9 -4 9 136 136 136
-10 -3 9 136 136 136
5 -3 9 85 85 85
6 -3 9 136 136 136
7 -3 9 136 136 136
8 -3 9 136 136 136
9 -3 9 136 136 136
-10 -2 9 136 136 136
5 -2 9 85 85 85
6 -2 9 136 136 136
7 -2 9 136 136 136
8 -2 9 136 136 136
9 -2 9 136 136 136
-10 -1 9 136 136 136
5 -1 9 85 85 85
6 -1 9 136 136 136
7 -1 9 136 136 136
8 -1 9 136 136 136
9 -1 9 136 136 136
-10 0 9 136 136 136
5 0 9 85 85 85
6 0 9 136 136 136
7 0 9 136 136 136
8 0 9 136 136 136
9 0 9 136 136 136
-10 1 9 136 136 136
5 1 9 85 85 85
6 1 9 136 136 136
7 1 9 136 136 136
8 1 9 136 136 136
9 1 9 136 136 136
-10 2 9 136 136 136
5 2 9 85 85 85
6 2 9 136 136 136
7 2 9 136 136 136
8 2 9 136 136 136
9 2 9 136 136 136
-10 3 9 136 136 136
5 3 9 85 85 85
6 3 9 136 136 136
7 3 9 136 136 136
8 3 9 136 136 136
9 3 9 136 136 136
-10 4 9 136 136 136
-9 4 9 136 136 136
-8 4 9 136 136 136
-7 4 9 136 136 136
-6 4 9 136 136 136
-5 4 9 136 136 136
-4 4 9 136 136 136
-3 4 9 136 136 136
-2 4 9 136 136 136
-1 4 9 136 136 136
0 4 9 136 136 136
1 4 9 136 136 136
2 4 9 136 136 136
3 4 9 136 136 136
4 4 9 136 136 136
5 4 9 85 85 85
6 4 9 136 136 136
7 4 9 136 136 136
8 4 9 136 136 136
9 4 9 136 136 136
-10 -5 10 136 136 136
-9 -5 10 136 136 136
-8 -5 10 136 136 136
-7 -5 10 136 136 136
-6 -5 10 136 136 136
-5 -5 10 136 136 136
-4 -5 10 136 136 136
-3 -5 10 136 136 136
-2 -5 10 136 136 136
-1 -5 10 136 136 136
0 -5 10 136 136 136
1 -5 10 136 136 136
2 -5 10 136 136 136
3 -5 10 136 136 136
4 -5 10 136 136 136
5 -5 10 136 136 136
6 -5 10 136 136 136
7 -5 10 136 136 136
8 -5 10 136 136 136
9 -5 10 136 136 136
-10 -4 10 136 136 136
6 -4 10 136 136 136
7 -4 10 136 136 136
8 -4 10 136 136 136
9 -4 10 136 136 136
-10 -3 10 136 136 136
6 -3 10 136 136 136
7 -3 10 136 136 136
8 -3 10 136 136 136
9 -3 10 136 136 136
-10 -2 10 136 136 136
6 -2 10 136 136 136
7 -2 10 136 136 136
8 -2 10 136 136 136
9 -2 10 136 136 136
-10 -1 10 136 136 136
6 -1 10 136 136 136
7 -1 10 136 136 136
8 -1 10 136 136 136
9 -1 10 136 136 136
-10 0 10 136 136 136
6 0 10 136 136 136
7 0 10 136 136 136
8 0 10 136 136 136
9 0 10 136 136 136
-10 1 10 136 136 136
6 1 10 136 136 136
7 1 10 136 136 136
8 1 10 136 136 136
9 1 10 136 136 136
-10 2 10 136 136 136
6 2 10 136 136 136
7 2 10 136 136 136
8 2 10 136 136 136
9 2 10 136 136 136
-10 3 10 136 136 136
6 3 10 136 136 136
7 3 10 136 136 136
8 3 10 136 136 136
9 3 10 136 136 136
-10 4 10 136 136 136
-9 4 10 136 136 136
-8 4 10 136 136 136
-7 4 10 136 136 136
-6 4 10 136 136 136
-5 4 10 136 136 136
-4 4 10 136 136 136
-3 4 10 136 136 136
-2 4 10 136 136 136
-1 4 10 136 136 136
0 4 10 136 136 136
1 4 10 136 136 136
2 4 10 136 136 136
3 4 10 136 136 136
4 4 10 136 136 136
5 4 10 136 136 136
6 4 10 136 136 136
7 4 10 136 136 136
8 4 10 136 136 136
9 4 10 136 136 136
-10 -5 11 136 136 136
-9 -5 11 136 136 136
-8 -5 11 136 136 136
-7 -5 11 136 136 136
-6 -5 11 136 136 136
-5 -5 11 136 136 136
-4 -5 11 136 136 136
-3 -5 11 136 136 136
-2 -5 11 136 136 136
-1 -5 11 136 136 136
0 -5 11 136 136 136
1 -5 11 136 136 136
2 -5 11 136 136 136
3 -5 11 136 136 136
4 -5 11 136 136 136
5 -5 11 136 136 136
6 -5 11 136 136 136
7 -5 11 136 136 136
8 -5 11 136 136 136
9 -5 11 136 136 136
-10 -4 11 136 136 136
-10 -3 11 136 136 136
-10 -2 11 136 136 136
-10 -1 11 136 136 136
-10 0 11 136 136 136
-10 1 11 136 136 136
-10 2 11 136 136 136
-10 3 11 136 136 136
-10 4 11 136 136 136
-9 4 11 136 136 136
-8 4 11 136 136 136
-7 4 11 136 136 136
-6 4 11 136 136 136
-5 4 11 136 136 136
-4 4 11 136 136 136
-3 4 11 136 136 136
-2 4 11 136 136 136
-1 4 11 136 136 136
0 4 11 136 136 136
1 4 11 136 136 136
2 4 11 136 136 136
3 4 11 136 136 136
4 4 11 136 136 136
5 4 11 136 136 136
6 4 11 136 136 136
7 4 11 136 136 136
8 4 11 136 136 136
9 4 11 136 136 136
-10 -5 12 136 136 136
-9 -5 12 136 136 136
-8 -5 12 136 136 136
-7 -5 12 136 136 136
-6 -5 12 136 136 136
-5 -5 12 136 136 136
-4 -5 12 136 136 136
-3 -5 12 136 136 136
-2 -5 12 136 136 136
-1 -5 12 136 136 136
0 -5 12 136 136 136
1 -5 12 136 136 136
2 -5 12 136 136 136
3 -5 12 136 136 136
4 -5 12 136 136 136
5 -5 12 136 136 136
6 -5 12 136 136 136
7 -5 12 136 136 136
8 -5 12 136 136 136
9 -5 12 136 136 136
-10 -4 12 136 136 136
-10 -3 12 136 136 136
-10 -2 12 136 136 136
-10 -1 12 136 136 136
-10 0 12 136 136 136
-10 1 12 136 136 136
-10 2 12 136 136 136
-10 3 12 136 136 136
-10 4 12 136 136 136
-9 4 12 136 136 136
-8 4 12 136 136 136
-7 4 12 136 136 136
-6 4 12 136 136 136
-5 4 12 136 136 136
-4 4 12 136 136 136
-3 4 12 136 136 136
-2 4 12 136 136 136
-1 4 12 136 136 136
0 4 12 136 136 136
1 4 12 136 136 136
2 4 12 136 136 136
3 4 12 136 136 136
4 4 12 136 136 136
5 4 12 136 136 136
6 4 12 136 136 136
7 4 12 136 136 136
8 4 12 136 136 136
9 4 12 136 136 136
-10 -5 13 136 136 136
-9 -5 13 136 136 136
-8 -5 13 136 136 136
-7 -5 13 136 136 136
-6 -5 13 136 136 136
-5 -5 13 136 136 136
-4 -5 13 136 136 136
-3 -5 13 136 136 136
-2 -5 13 136 136 136
-1 -5 13 136 136 136
0 -5 13 136 136 136
1 -5 13 136 136 136
2 -5 13 136 136 136
3 -5 13 136 136 136
4 -5 13 136 136 136
5 -5 13 136 136 136
6 -5 13 136 136 136
7 -5 13 136 136 136
8 -5 13 136 136 136
9 -5 13 136 136 136
-10 -4 13 136 136 136
-10 -3 13 136 136 136
-10 -2 13 136 136 136
-10 -1 13 136 136 136
-10 0 13 136 136 136
-10 1 13 136 136 136
-10 2 13 136 136 136
-10 3 13 136 136 136
-10 4 13 136 136 136
-9 4 13 136 136 136
-8 4 13 136 136 136
-7 4 13 136 136 136
-6 4 13 136 136 136
-5 4 13 136 136 136
-4 4 13 136 136 136
-3 4 13 136 136 136
-2 4 13 136 136 136
-1 4 13 136 136 136
0 4 13 136 136 136
1 4 13 136 136 136
2 4 13 136 136 136
3 4 13 136 136 136
4 4 13 136 136 136
5 4 13 136 136 136
6 4 13 136 136 136
7 4 13 136 136 136
8 4 13 136 136 136
9 4 13 136 136 136
-10 -5 14 136 136 136
-9 -5 14 136 136 136
-8 -5 14 136 136 136
-7 -5 14 136 136 136
-6 -5 14 136 136 136
-5 -5 14 136 136 136
-4 -5 14 136 136 136
-3 -5 14 136 136 136
-2 -5 14 136 136 136
-1 -5 14 136 136 136
0 -5 14 136 136 136
1 -5 14 136 136 136
2 -5 14 136 136 136
3 -5 14 136 136 136
4 -5 14 136 136 136
5 -5 14 136 136 136
6 -5 14 136 136 136
7 -5 14 136 136 136
8 -5 14 136 136 136
9 -5 14 136 136 136
-10 -4 14 136 136 136
-10 -3 14 136 136 136
-10 -2 14 136 136 136
-10 -1 14 136 136 136
-10 0 14 136 136 136
-10 1 14 136 136 136
-10 2 14 136 136 136
-10 3 14 136 136 136
-10 4 14 136 136 136
-9 4 14 136 136 136
-8 4 14 136 136 136
-7 4 14 136 136 136
-6 4 14 136 136 136
-5 4 14 136 136 136
-4 4 14 136 136 136
-3 4 14 136 136 136
-2 4 14 136 136 136
-1 4 14 136 136 136
0 4 14 136 136 136
1 4 14 136 136 136
2 4 14 136 136 136
3 4 14 136 136 136
4 4 14 136 136 136
5 4 14 136 136 136
6 4 14 136 136 136
7 4 14 136 136 136
8 4 14 136 136 136
9 4 14 136 136 136
-10 -5 15 136 136 136
-9 -5 15 136 136 136
-8 -5 15 136 136 136
-7 -5 15 136 136 136
-6 -5 15 136 136 136
-5 -5 15 136 136 136
-4 -5 15 136 136 136
-3 -5 15 136 136 136
-2 -5 15 136 136 136
-1 -5 15 136 136 136
0 -5 15 136 136 136
1 -5 15 136 136 136
2 -5 15 136 136 136
3 -5 15 136 136 136
4 -5 15 136 136 136
5 -5 15 136 136 136
6 -5 15 136 136 136
7 -5 15 136 136 136
8 -5 15 136 136 136
9 -5 15 136 136 136
-10 -4 15 136 136 136
-10 -3 15 136 136 136
-10 -2 15 136 136 136
-10 -1 15 136 136 136
-10 0 15 136 136 136
-10 1 15 136 136 136
-10 2 15 136 136 136
-10 3 15 136 136 136
-10 4 15 136 136 136
-9 4 15 136 136 136
-8 4 15 136 136 136
-7 4 15 136 136 136
-6 4 15 136 136 136
-5 4 15 136 136 136
-4 4 15 136 136 136
-3 4 15 136 136 136
-2 4 15 136 136 136
-1 4 15 136 136 136
0 4 15 136 136 136
1 4 15 136 136 136
2 4 15 136 136 136
3 4 15 136 136 136
4 4 15 136 136 136
5 4 15 136 136 136
6 4 15 136 136 136
7 4 15 136 136 136
8 4 15 136 136 136
9 4 15 136 136 136
-10 -5 16 136 136 136
-9 -5 16 136 136 136
-8 -5 16 136 136 136
-7 -5 16 136 136 136
-6 -5 16 136 136 136
-5 -5 16 136 136 136
-4 -5 16 136 136 136
-3 -5 16 136 136 136
-2 -5 16 136 136 136
-1 -5 16 136 136 136
0 -5 16 136 136 136
1 -5 16 136 136 136
2 -5 16 136 136 136
3 -5 16 136 136 136
4 -5 16 136 136 136
5 -5 16 136 136 136
6 -5 16 136 136 136
7 -5 16 136 136 136
8 -5 16 136 136 136
9 -5 16 136 136 136
-10 -4 16 136 136 136
-10 -3 16 136 136 136
-10 -2 16 136 136 136
-10 -1 16 136 136 136
-10 0 16 136 136 136
-10 1 16 136 136 136
-10 2 16 136 136 136
-10 3 16 136 136 136
-10 4 16 136 136 136
-9 4 16 136 136 136
-8 4 16 136 136 136
-7 4 16 136 136 136
-6 4 16 136 136 136
-5 4 16 136 136 136
-4 4 16 136 136 136
-3 4 16 136 136 136
-2 4 16 136 136 136
-1 4 16 136 136 136
0 4 16 136 136 136
1 4 16 136 136 136
2 4 16 136 136 136
3 4 16 136 136 136
4 4 16 136 136 136
5 4 16 136 136 136
6 4 16 136 136 136
7 4 16 136 136 136
8 4 16 136 136 136
9 4 16 136 136 136
-10 -5 17 136 136 136
-9 -5 17 136 136 136
-8 -5 17 136 136 136
-7 -5 17 136 136 136
-6 -5 17 136 136 136
-5 -5 17 136 136 136
-4 -5 17 136 136 136
-3 -5 17 136 136 136
-2 -5 17 136 136 136
-1 -5 17 136 136 136
0 -5 17 136 136 136
1 -5 17 136 136 136
2 -5 17 136 136 136
3 -5 17 136 136 136
4 -5 17 136 136 136
5 -5 17 136 136 136
6 -5 17 136 136 136
7 -5 17 136 136 136
8 -5 17 136 136 136
9 -5 17 136 136 136
-10 -4 17 136 136 136
-10 -3 17 136 136 136
-10 -2 17 136 136 136
-10 -1 17 136 136 136
-10 0 17 136 136 136
-10 1 17 136 136 136
-10 2 17 136 136 136
-10 3 17 136 136 136
-10 4 17 136 136 136
-9 4 17 136 136 136
-8 4 17 136 136 136
-7 4 17 136 136 136
-6 4 17 136 136 136
-5 4 17 136 136 136
-4 4 17 136 136 136
-3 4 17 136 136 136
-2 4 17 136 136 136
-1 4 17 136 136 136
0 4 17 136 136 136
1 4 17 136 136 136
2 4 17 136 136 136
3 4 17 136 136 136
4 4 17 136 136 136
5 4 17 136 136 136
6 4 17 136 136 136
7 4 17 136 136 136
8 4 17 136 136 136
9 4 17 136 136 136
-10 -5 18 136 136 136
-9 -5 18 136 136 136
-8 -5 18 136 136 136
-7 -5 18 136 136 136
-6 -5 18 136 136 136
-5 -5 18 136 136 136
-4 -5 18 136 136 136
-3 -5 18 136 136 136
-2 -5 18 136 136 136
-1 -5 18 136 136 136
0 -5 18 136 136 136
1 -5 18 136 136 136
2 -5 18 136 136 136
3 -5 18 136 136 136
4 -5 18 136 136 136
5 -5 18 136 136 136
6 -5 18 136 136 136
7 -5 18 136 136 136
8 -5 18 136 136 136
9 -5 18 136 136 136
-10 -4 18 136 136 136
-10 -3 18 136 136 136
-10 -2 18 136 136 136
-10 -1 18 136 136 136
-10 0 18 136 136 136
-10 1 18 136 136 136
-10 2 18 136 136 136
-10 3 18 136 136 136
-10 4 18 136 136 136
-9 4 18 136 136 136
-8 4 18 136 136 136
-7 4 18 136 136 136
-6 4 18 136 136 136
-5 4 18 136 136 136
-4 4 18 136 136 136
-3 4 18 136 136 136
-2 4 18 136 136 136
-1 4 18 136 136 136
0 4 18 136 136 136
1 4 18 136 136 136
2 4 18 136 136 136
3 4 18 136 136 136
4 4 18 136 136 136
5 4 18 136 136 136
6 4 18 136 136 136
7 4 18 136 136 136
8 4 18 136 136 136
9 4 18 136 136 136
-10 -5 19 136 136 136
-9 -5 19 136 136 136
-8 -5 19 136 136 136
-7 -5 19 136 136 136
-6 -5 19 136 136 136
-5 -5 19 136 136 136
-4 -5 19 136 136 136
-3 -5 19 136 136 136
-2 -5 19 136 136 136
-1 -5 19 136 136 136
0 -5 19 136 136 136
1 -5 19 136 136 136
2 -5 19 136 136 136
3 -5 19 136 136 136
4 -5 19 136 136 136
5 -5 19 136 136 136
6 -5 19 136 136 136
7 -5 19 136 136 136
8 -5 19 136 136 136
9 -5 19 136 136 136
-10 -4 19 136 136 136
-9 -4 19 136 136 136
-8 -4 19 136 136 136
-7 -4 19 136 136 136
-6 -4 19 136 136 136
-5 -4 19 136 136 136
-4 -4 19 136 136 136
-3 -4 19 136 136 136
-2 -4 19 136 136 136
-1 -4 19 136 136 136
0 -4 19 136 136 136
1 -4 19 136 136 136
2 -4 19 136 136 136
3 -4 19 136 136 136
4 -4 19 136 136 136
5 -4 19 136 136 136
6 -4 19 136 136 136
7 -4 19 136 136 136
8 -4 19 136 136 136
9 -4 19 136 136 136
-10 -3 19 136 136 136
-9 -3 19 136 136 136
-8 -3 19 136 136 136
-7 -3 19 136 136 136
-6 -3 19 136 136 136
-5 -3 19 136 136 136
-4 -3 19 136 136 136
-3 -3 19 136 136 136
-2 -3 19 136 136 136
-1 -3 19 136 136 136
0 -3 19 136 136 136
1 -3 19 136 136 136
2 -3 19 136 136 136
3 -3 19 136 136 136
4 -3 19 136 136 136
5 -3 19 136 136 136
6 -3 19 136 136 136
7 -3 19 136 136 136
8 -3 19 136 136 136
9 -3 19 136 136 136
-10 -2 19 136 136 136
-9 -2 19 136 136 136
-8 -2 19 136 136 136
-7 -2 19 136 136 136
-6 -2 19 136 136 136
-5 -2 19 136 136 136
-4 -2 19 136 136 136
-3 -2 19 136 136 136
-2 -2 19 136 136 136
-1 -2 19 136 136 136
0 -2 19 136 136 136
1 -2 19 136 136 136
2 -2 19 136 136 136
3 -2 19 136 136 136
4 -2 19 136 136 136
5 -2 19 136 136 136
6 -2 19 136 136 136
7 -2 19 136 136 136
8 -2 19 136 136 136
9 -2 19 136 136 136
-10 -1 19 136 136 136
-9 -1 19 136 136 136
-8 -1 19 136 136 136
-7 -1 19 136 136 136
-6 -1 19 136 136 136
-5 -1 19 136 136 136
-4 -1 19 136 136 136
-3 -1 19 136 136 136
-2 -1 19 136 136 136
-1 -1 19 136 136 136
0 -1 19 136 136 136
1 -1 19 136 136 136
2 -1 19 136 136 136
3 -1 19 136 136 136
4 -1 19 136 136 136
5 -1 19 136 136 136
6 -1 19 136 136 136
7 -1 19 136 136 136
8 -1 19 136 136 136
9 -1 19 136 136 136
-10 0 19 136 136 136
-9 0 19 136 136 136
-8 0 19 136 136 136
-7 0 19 136 136 136
-6 0 19 136 136 136
-5 0 19 136 136 136
-4 0 19 136 136 136
-3 0 19 136 136 136
-2 0 19 136 136 136
-1 0 19 136 136 136
0 0 19 136 136 136
1 0 19 136 136 136
2 0 19 136 136 136
3 0 19 136 136 136
4 0 19 136 136 136
5 0 19 136 136 136
6 0 19 136 136 136
7 0 19 136 136 136
8 0 19 136 136 136
9 0 19 136 136 136
-10 1 19 136 136 136
-9 1 19 136 136 136
-8 1 19 136 136 136
-7 1 19 136 136 136
-6 1 19 136 136 136
-5 1 19 136 136 136
-4 1 19 136 136 136
-3 1 19 136 136 136
-2 1 19 136 136 136
-1 1 19 136 136 136
0 1 19 136 136 136
1 1 19 136 136 136
2 1 19 136 136 136
3 1 19 136 136 136
4 1 19 136 136 136
5 1 19 136 136 136
6 1 19 136 136 136
7 1 19 136 136 136
8 1 19 136 136 136
9 1 19 136 136 136
-10 2 19 136 136 136
-9 2 19 136 136 136
-8 2 19 136 136 136
-7 2 19 136 136 136
-6 2 19 136 136 136
-5 2 19 136 136 136
-4 2 19 136 136 136
-3 2 19 136 136 136
-2 2 19 136 136 136
-1 2 19 136 136 136
0 2 19 136 136 136
1 2 19 136 136 136
2 2 19 136 136 136
3 2 19 136 136 136
4 2 19 136 136 136
5 2 19 136 136 136
6 2 19 136 136 136
7 2 19 136 136 136
8 2 19 136 136 136
9 2 19 136 136 136
-10 3 19 136 136 136
-9 3 19 136 136 136
-8 3 19 136 136 136
-7 3 19 136 136 136
-6 3 19 136 136 136
-5 3 19 136 136 136
-4 3 19 136 136 136
-3 3 19 136 136 136
-2 3 19 136 136 136
-1 3 19 136 136 136
0 3 19 136 136 136
1 3 19 136 136 136
2 3 19 136 136 136
3 3 19 136 136 136
4 3 19 136 136 136
5 3 19 136 136 136
6 3 19 136 136 136
7 3 19 136 136 136
8 3 19 136 136 136
9 3 19 136 136 136
-10 4 19 136 136 136
-9 4 19 136 136 136
-8 4 19 136 136 136
-7 4 19 136 136 136
-6 4 19 136 136 136
-5 4 19 136 136 136
-4 4 19 136 136 136
-3 4 19 136 136 136
-2 4 19 136 136 136
-1 4 19 136 136 136
0 4 19 136 136 136
1 4 19 136 136 136
2 4 19 136 136 136
3 4 19 136 136 136
4 4 19 136 136 136
5 4 19 136 136 136
6 4 19 136 136 136
7 4 19 136 136 136
8 4 19 136 136 136
9 4 19 136 136 136
