ply
format ascii 1.0
comment : MagicaVoxel @ Ephtracy
element vertex 500
property float x
property float y
property float z
property uchar red
property uchar green
property uchar blue
end_header
-5 -5 0 160 132 68
-4 -5 0 160 132 68
-3 -5 0 160 132 68
-2 -5 0 176 60 60
-1 -5 0 192 88 88
0 -5 0 176 60 60
1 -5 0 160 132 68
2 -5 0 160 132 68
3 -5 0 160 132 68
4 -5 0 160 132 68
-5 -4 0 160 132 68
-4 -4 0 160 132 68
-3 -4 0 160 132 68
-2 -4 0 176 60 60
-1 -4 0 192 88 88
0 -4 0 176 60 60
1 -4 0 184 156 88
2 -4 0 184 156 88
3 -4 0 184 156 88
4 -4 0 184 156 88
-5 -3 0 160 132 68
-4 -3 0 160 132 68
-3 -3 0 160 132 68
-2 -3 0 176 60 60
-1 -3 0 192 88 88
0 -3 0 176 60 60
1 -3 0 132 104 48
2 -3 0 132 104 48
3 -3 0 132 104 48
4 -3 0 132 104 48
-5 -2 0 160 132 68
-4 -2 0 160 132 68
-3 -2 0 160 132 68
-2 -2 0 176 60 60
-1 -2 0 192 88 88
0 -2 0 176 60 60
1 -2 0 160 132 68
2 -2 0 160 132 68
3 -2 0 160 132 68
4 -2 0 160 132 68
-5 -1 0 160 132 68
-4 -1 0 160 132 68
-3 -1 0 160 132 68
-2 -1 0 176 60 60
-1 -1 0 192 88 88
0 -1 0 176 60 60
1 -1 0 160 132 68
2 -1 0 160 132 68
3 -1 0 160 132 68
4 -1 0 160 132 68
-5 0 0 160 132 68
-4 0 0 160 132 68
-3 0 0 160 132 68
-2 0 0 176 60 60
-1 0 0 192 88 88
0 0 0 176 60 60
1 0 0 160 132 68
2 0 0 160 132 68
3 0 0 160 132 68
4 0 0 160 132 68
-5 1 0 160 132 68
-4 1 0 160 132 68
-3 1 0 160 132 68
-2 1 0 176 60 60
-1 1 0 192 88 88
0 1 0 176 60 60
1 1 0 160 132 68
2 1 0 160 132 68
3 1 0 160 132 68
4 1 0 160 132 68
-5 2 0 160 132 68
-4 2 0 184 156 88
-3 2 0 184 156 88
-2 2 0 176 60 60
-1 2 0 192 88 88
0 2 0 176 60 60
1 2 0 160 132 68
2 2 0 160 132 68
3 2 0 160 132 68
4 2 0 160 132 68
-5 3 0 132 104 48
-4 3 0 132 104 48
-3 3 0 132 104 48
-2 3 0 176 60 60
-1 3 0 192 88 88
0 3 0 176 60 60
1 3 0 160 132 68
2 3 0 160 132 68
3 3 0 160 132 68
4 3 0 160 132 68
-5 4 0 160 132 68
-4 4 0 160 132 68
-3 4 0 160 132 68
-2 4 0 176 60 60
-1 4 0 192 88 88
0 4 0 176 60 60
1 4 0 160 132 68
2 4 0 160 132 68
3 4 0 160 132 68
4 4 0 160 132 68
-5 -5 1 108 108 108
4 -5 1 108 108 108
-5 -4 1 108 108 108
4 -4 1 108 108 108
-5 -3 1 108 108 108
4 -3 1 108 108 108
-5 -2 1 108 108 108
4 -2 1 108 108 108
-5 -1 1 108 108 108
-4 -1 1 100 72 24
-3 -1 1 100 72 24
2 -1 1 100 72 24
3 -1 1 100 72 24
4 -1 1 108 108 108
-5 0 1 108 108 108
-4 0 1 100 72 24
-3 0 1 100 72 24
2 0 1 100 72 24
3 0 1 100 72 24
4 0 1 108 108 108
-5 1 1 108 108 108
4 1 1 108 108 108
-5 2 1 108 108 108
4 2 1 108 108 108
-5 3 1 108 108 108
4 3 1 108 108 108
-5 4 1 108 108 108
-4 4 1 108 108 108
-3 4 1 108 108 108
-2 4 1 108 108 108
-1 4 1 108 108 108
0 4 1 108 108 108
1 4 1 108 108 108
2 4 1 108 108 108
3 4 1 108 108 108
4 4 1 108 108 108
-5 -5 2 144 144 144
4 -5 2 144 144 144
-5 -4 2 144 144 144
4 -4 2 144 144 144
-5 -3 2 144 144 144
4 -3 2 108 108 108
-5 -2 2 144 144 144
4 -2 2 144 144 144
-5 -1 2 144 144 144
-4 -1 2 100 72 24
-3 -1 2 100 72 24
2 -1 2 100 72 24
3 -1 2 100 72 24
4 -1 2 144 144 144
-5 0 2 144 144 144
-4 0 2 100 72 24
-3 0 2 100 72 24
2 0 2 100 72 24
3 0 2 100 72 24
4 0 2 144 144 144
-5 1 2 144 144 144
4 1 2 144 144 144
-5 2 2 108 108 108
4 2 2 144 144 144
-5 3 2 144 144 144
4 3 2 144 144 144
-5 4 2 144 144 144
-4 4 2 144 144 144
-3 4 2 144 144 144
-2 4 2 144 144 144
-1 4 2 144 144 144
0 4 2 108 108 108
1 4 2 144 144 144
2 4 2 144 144 144
3 4 2 144 144 144
4 4 2 144 144 144
-5 -5 3 144 144 144
4 -5 3 144 144 144
-5 -4 3 144 144 144
4 -4 3 144 144 144
-5 -3 3 144 144 144
4 -3 3 108 108 108
-5 -2 3 144 144 144
4 -2 3 144 144 144
-5 -1 3 144 144 144
-4 -1 3 100 72 24
-3 -1 3 100 72 24
2 -1 3 100 72 24
3 -1 3 100 72 24
4 -1 3 144 144 144
-5 0 3 144 144 144
-4 0 3 100 72 24
-3 0 3 100 72 24
2 0 3 100 72 24
3 0 3 100 72 24
4 0 3 144 144 144
-5 1 3 144 144 144
4 1 3 144 144 144
-5 2 3 108 108 108
4 2 3 144 144 144
-5 3 3 144 144 144
4 3 3 144 144 144
-5 4 3 144 144 144
-4 4 3 144 144 144
-3 4 3 144 144 144
-2 4 3 144 144 144
-1 4 3 144 144 144
0 4 3 108 108 108
1 4 3 144 144 144
2 4 3 144 144 144
3 4 3 144 144 144
4 4 3 144 144 144
-5 -5 4 108 108 108
4 -5 4 108 108 108
-5 -4 4 108 108 108
4 -4 4 108 108 108
-5 -3 4 108 108 108
4 -3 4 108 108 108
-5 -2 4 108 108 108
4 -2 4 108 108 108
-5 -1 4 108 108 108
-4 -1 4 100 72 24
-3 -1 4 100 72 24
2 -1 4 100 72 24
3 -1 4 100 72 24
4 -1 4 108 108 108
-5 0 4 108 108 108
-4 0 4 100 72 24
-3 0 4 100 72 24
2 0 4 100 72 24
3 0 4 100 72 24
4 0 4 108 108 108
-5 1 4 108 108 108
4 1 4 108 108 108
-5 2 4 108 108 108
4 2 4 108 108 108
-5 3 4 108 108 108
4 3 4 108 108 108
-5 4 4 108 108 108
-4 4 4 108 108 108
-3 4 4 108 108 108
-2 4 4 108 108 108
-1 4 4 108 108 108
0 4 4 108 108 108
1 4 4 108 108 108
2 4 4 108 108 108
3 4 4 108 108 108
4 4 4 108 108 108
-5 -5 5 144 144 144
4 -5 5 144 144 144
-5 -4 5 144 144 144
4 -4 5 144 144 144
-5 -3 5 108 108 108
4 -3 5 144 144 144
-5 -2 5 144 144 144
-4 -2 5 132 104 48
3 -2 5 132 104 48
4 -2 5 144 144 144
-5 -1 5 144 144 144
-4 -1 5 100 72 24
-3 -1 5 100 72 24
2 -1 5 100 72 24
3 -1 5 100 72 24
4 -1 5 144 144 144
-5 0 5 144 144 144
-4 0 5 100 72 24
-3 0 5 100 72 24
2 0 5 100 72 24
3 0 5 100 72 24
4 0 5 144 144 144
-5 1 5 144 144 144
4 1 5 144 144 144
-5 2 5 144 144 144
4 2 5 144 144 144
-5 3 5 144 144 144
4 3 5 108 108 108
-5 4 5 144 144 144
-4 4 5 144 144 144
-3 4 5 108 108 108
-2 4 5 144 144 144
-1 4 5 144 144 144
0 4 5 144 144 144
1 4 5 144 144 144
2 4 5 144 144 144
3 4 5 144 144 144
4 4 5 144 144 144
-5 -5 6 144 144 144
4 -5 6 144 144 144
-5 -4 6 144 144 144
-4 -4 6 132 104 48
3 -4 6 132 104 48
4 -4 6 144 144 144
-5 -3 6 108 108 108
-4 -3 6 132 104 48
3 -3 6 132 104 48
4 -3 6 144 144 144
-5 -2 6 144 144 144
-4 -2 6 132 104 48
3 -2 6 132 104 48
4 -2 6 144 144 144
-5 -1 6 144 144 144
-4 -1 6 100 72 24
-3 -1 6 100 72 24
2 -1 6 100 72 24
3 -1 6 100 72 24
4 -1 6 144 144 144
-5 0 6 144 144 144
-4 0 6 100 72 24
-3 0 6 100 72 24
2 0 6 100 72 24
3 0 6 100 72 24
4 0 6 144 144 144
-5 1 6 144 144 144
4 1 6 144 144 144
-5 2 6 144 144 144
4 2 6 144 144 144
-5 3 6 144 144 144
4 3 6 108 108 108
-5 4 6 144 144 144
-4 4 6 144 144 144
-3 4 6 108 108 108
-2 4 6 144 144 144
-1 4 6 144 144 144
0 4 6 144 144 144
1 4 6 144 144 144
2 4 6 144 144 144
3 4 6 144 144 144
4 4 6 144 144 144
-5 -5 7 108 108 108
-4 -5 7 132 104 48
3 -5 7 132 104 48
4 -5 7 108 108 108
-5 -4 7 108 108 108
-4 -4 7 132 104 48
3 -4 7 132 104 48
4 -4 7 108 108 108
-5 -3 7 108 108 108
4 -3 7 108 108 108
-5 -2 7 108 108 108
4 -2 7 108 108 108
-5 -1 7 108 108 108
-4 -1 7 100 72 24
-3 -1 7 100 72 24
2 -1 7 100 72 24
3 -1 7 100 72 24
4 -1 7 108 108 108
-5 0 7 108 108 108
-4 0 7 100 72 24
-3 0 7 100 72 24
2 0 7 100 72 24
3 0 7 100 72 24
4 0 7 108 108 108
-5 1 7 108 108 108
4 1 7 108 108 108
-5 2 7 108 108 108
4 2 7 108 108 108
-5 3 7 108 108 108
4 3 7 108 108 108
-5 4 7 108 108 108
-4 4 7 108 108 108
-3 4 7 108 108 108
-2 4 7 108 108 108
-1 4 7 108 108 108
0 4 7 108 108 108
1 4 7 108 108 108
2 4 7 108 108 108
3 4 7 108 108 108
4 4 7 108 108 108
-5 -5 8 144 144 144
4 -5 8 144 144 144
-5 -4 8 144 144 144
4 -4 8 144 144 144
-5 -3 8 144 144 144
4 -3 8 144 144 144
-5 -2 8 144 144 144
4 -2 8 144 144 144
-5 -1 8 144 144 144
-4 -1 8 100 72 24
-3 -1 8 100 72 24
2 -1 8 100 72 24
3 -1 8 100 72 24
4 -1 8 144 144 144
-5 0 8 108 108 108
-4 0 8 100 72 24
-3 0 8 100 72 24
2 0 8 100 72 24
3 0 8 100 72 24
4 0 8 144 144 144
-5 1 8 144 144 144
4 1 8 108 108 108
-5 2 8 144 144 144
4 2 8 144 144 144
-5 3 8 144 144 144
4 3 8 144 144 144
-5 4 8 144 144 144
-4 4 8 144 144 144
-3 4 8 144 144 144
-2 4 8 144 144 144
-1 4 8 144 144 144
0 4 8 144 144 144
1 4 8 108 108 108
2 4 8 144 144 144
3 4 8 144 144 144
4 4 8 144 144 144
-5 -5 9 108 108 108
-4 -5 9 108 108 108
-3 -5 9 108 108 108
-2 -5 9 108 108 108
-1 -5 9 108 108 108
0 -5 9 108 108 108
1 -5 9 108 108 108
2 -5 9 108 108 108
3 -5 9 108 108 108
4 -5 9 108 108 108
-5 -4 9 108 108 108
-4 -4 9 108 108 108
-3 -4 9 108 108 108
-2 -4 9 108 108 108
-1 -4 9 108 108 108
0 -4 9 108 108 108
1 -4 9 108 108 108
2 -4 9 108 108 108
3 -4 9 108 108 108
4 -4 9 108 108 108
-5 -3 9 108 108 108
-4 -3 9 108 108 108
-3 -3 9 108 108 108
-2 -3 9 108 108 108
-1 -3 9 108 108 108
0 -3 9 108 108 108
1 -3 9 108 108 108
2 -3 9 108 108 108
3 -3 9 108 108 108
4 -3 9 108 108 108
-5 -2 9 64 64 64
-4 -2 9 64 64 64
-3 -2 9 64 64 64
-2 -2 9 64 64 64
-1 -2 9 108 108 108
0 -2 9 108 108 108
1 -2 9 108 108 108
2 -2 9 64 64 64
3 -2 9 64 64 64
4 -2 9 64 64 64
-5 -1 9 64 64 64
-4 -1 9 64 64 64
-3 -1 9 64 64 64
-2 -1 9 64 64 64
-1 -1 9 108 108 108
0 -1 9 108 108 108
1 -1 9 108 108 108
2 -1 9 64 64 64
3 -1 9 64 64 64
4 -1 9 64 64 64
-5 0 9 64 64 64
-4 0 9 64 64 64
-3 0 9 64 64 64
-2 0 9 64 64 64
-1 0 9 108 108 108
0 0 9 108 108 108
1 0 9 108 108 108
2 0 9 64 64 64
3 0 9 64 64 64
4 0 9 64 64 64
-5 1 9 64 64 64
-4 1 9 64 64 64
-3 1 9 64 64 64
-2 1 9 64 64 64
-1 1 9 108 108 108
0 1 9 108 108 108
1 1 9 108 108 108
2 1 9 64 64 64
3 1 9 64 64 64
4 1 9 64 64 64
-5 2 9 108 108 108
-4 2 9 108 108 108
-3 2 9 108 108 108
-2 2 9 108 108 108
-1 2 9 108 108 108
0 2 9 108 108 108
1 2 9 108 108 108
2 2 9 108 108 108
3 2 9 108 108 108
4 2 9 108 108 108
-5 3 9 108 108 108
-4 3 9 108 108 108
-3 3 9 108 108 108
-2 3 9 108 108 108
-1 3 9 108 108 108
0 3 9 108 108 108
1 3 9 108 108 108
2 3 9 108 108 108
3 3 9 108 108 108
4 3 9 108 108 108
-5 4 9 108 108 108
-4 4 9 108 108 108
-3 4 9 108 108 108
-2 4 9 108 108 108
-1 4 9 108 108 108
0 4 9 108 108 108
1 4 9 108 108 108
2 4 9 108 108 108
3 4 9 108 108 108
4 4 9 108 108 108
