ply
format ascii 1.0
comment : MagicaVoxel @ Ephtracy
element vertex 9910
property float x
property float y
property float z
property uchar red
property uchar green
property uchar blue
end_header
-15 -15 0 144 144 144
-14 -15 0 144 144 144
-13 -15 0 144 144 144
-12 -15 0 144 144 144
-11 -15 0 144 144 144
-10 -15 0 144 144 144
-9 -15 0 144 144 144
-8 -15 0 144 144 144
-7 -15 0 144 144 144
-6 -15 0 144 144 144
-5 -15 0 144 144 144
-4 -15 0 144 144 144
-3 -15 0 144 144 144
-2 -15 0 144 144 144
-1 -15 0 144 144 144
0 -15 0 144 144 144
1 -15 0 144 144 144
2 -15 0 144 144 144
3 -15 0 144 144 144
4 -15 0 144 144 144
5 -15 0 144 144 144
6 -15 0 144 144 144
7 -15 0 144 144 144
8 -15 0 144 144 144
9 -15 0 144 144 144
10 -15 0 144 144 144
11 -15 0 144 144 144
12 -15 0 144 144 144
13 -15 0 144 144 144
14 -15 0 144 144 144
-15 -14 0 144 144 144
-14 -14 0 108 108 108
-13 -14 0 108 108 108
-12 -14 0 108 108 108
-11 -14 0 108 108 108
-10 -14 0 108 108 108
-9 -14 0 108 108 108
-8 -14 0 108 108 108
-7 -14 0 108 108 108
-6 -14 0 108 108 108
-5 -14 0 108 108 108
-4 -14 0 108 108 108
-3 -14 0 108 108 108
-2 -14 0 108 108 108
-1 -14 0 108 108 108
0 -14 0 108 108 108
1 -14 0 108 108 108
2 -14 0 108 108 108
3 -14 0 108 108 108
4 -14 0 108 108 108
5 -14 0 108 108 108
6 -14 0 108 108 108
7 -14 0 108 108 108
8 -14 0 108 108 108
9 -14 0 108 108 108
10 -14 0 108 108 108
11 -14 0 108 108 108
12 -14 0 108 108 108
13 -14 0 108 108 108
14 -14 0 144 144 144
-15 -13 0 144 144 144
-14 -13 0 108 108 108
-13 -13 0 108 108 108
-12 -13 0 108 108 108
-11 -13 0 108 108 108
-10 -13 0 108 108 108
-9 -13 0 108 108 108
-8 -13 0 108 108 108
-7 -13 0 108 108 108
-6 -13 0 108 108 108
-5 -13 0 108 108 108
-4 -13 0 108 108 108
-3 -13 0 108 108 108
-2 -13 0 108 108 108
-1 -13 0 108 108 108
0 -13 0 108 108 108
1 -13 0 108 108 108
2 -13 0 108 108 108
3 -13 0 108 108 108
4 -13 0 108 108 108
5 -13 0 108 108 108
6 -13 0 108 108 108
7 -13 0 108 108 108
8 -13 0 108 108 108
9 -13 0 108 108 108
10 -13 0 108 108 108
11 -13 0 108 108 108
12 -13 0 108 108 108
13 -13 0 108 108 108
14 -13 0 144 144 144
-15 -12 0 144 144 144
-14 -12 0 108 108 108
-13 -12 0 108 108 108
-12 -12 0 108 108 108
-11 -12 0 108 108 108
-10 -12 0 108 108 108
-9 -12 0 108 108 108
-8 -12 0 108 108 108
-7 -12 0 108 108 108
-6 -12 0 108 108 108
-5 -12 0 108 108 108
-4 -12 0 108 108 108
-3 -12 0 108 108 108
-2 -12 0 108 108 108
-1 -12 0 108 108 108
0 -12 0 108 108 108
1 -12 0 108 108 108
2 -12 0 108 108 108
3 -12 0 108 108 108
4 -12 0 108 108 108
5 -12 0 108 108 108
6 -12 0 108 108 108
7 -12 0 108 108 108
8 -12 0 108 108 108
9 -12 0 108 108 108
10 -12 0 108 108 108
11 -12 0 108 108 108
12 -12 0 108 108 108
13 -12 0 108 108 108
14 -12 0 144 144 144
-15 -11 0 144 144 144
-14 -11 0 108 108 108
-13 -11 0 108 108 108
-12 -11 0 108 108 108
-11 -11 0 108 108 108
-10 -11 0 108 108 108
-9 -11 0 108 108 108
-8 -11 0 108 108 108
-7 -11 0 108 108 108
-6 -11 0 108 108 108
-5 -11 0 108 108 108
-4 -11 0 108 108 108
-3 -11 0 108 108 108
-2 -11 0 108 108 108
-1 -11 0 108 108 108
0 -11 0 108 108 108
1 -11 0 108 108 108
2 -11 0 108 108 108
3 -11 0 108 108 108
4 -11 0 108 108 108
5 -11 0 108 108 108
6 -11 0 108 108 108
7 -11 0 108 108 108
8 -11 0 108 108 108
9 -11 0 108 108 108
10 -11 0 108 108 108
11 -11 0 108 108 108
12 -11 0 108 108 108
13 -11 0 108 108 108
14 -11 0 144 144 144
-15 -10 0 144 144 144
-14 -10 0 108 108 108
-13 -10 0 108 108 108
-12 -10 0 108 108 108
-11 -10 0 108 108 108
-10 -10 0 108 108 108
-9 -10 0 108 108 108
-8 -10 0 108 108 108
-7 -10 0 108 108 108
-6 -10 0 108 108 108
-5 -10 0 108 108 108
-4 -10 0 108 108 108
-3 -10 0 108 108 108
-2 -10 0 108 108 108
-1 -10 0 108 108 108
0 -10 0 108 108 108
1 -10 0 108 108 108
2 -10 0 108 108 108
3 -10 0 108 108 108
4 -10 0 108 108 108
5 -10 0 108 108 108
6 -10 0 108 108 108
7 -10 0 108 108 108
8 -10 0 108 108 108
9 -10 0 108 108 108
10 -10 0 108 108 108
11 -10 0 108 108 108
12 -10 0 108 108 108
13 -10 0 108 108 108
14 -10 0 144 144 144
-15 -9 0 144 144 144
-14 -9 0 108 108 108
-13 -9 0 108 108 108
-12 -9 0 108 108 108
-11 -9 0 108 108 108
-10 -9 0 108 108 108
-9 -9 0 108 108 108
-8 -9 0 108 108 108
-7 -9 0 108 108 108
-6 -9 0 108 108 108
-5 -9 0 108 108 108
-4 -9 0 108 108 108
-3 -9 0 108 108 108
-2 -9 0 108 108 108
-1 -9 0 108 108 108
0 -9 0 108 108 108
1 -9 0 108 108 108
2 -9 0 108 108 108
3 -9 0 108 108 108
4 -9 0 108 108 108
5 -9 0 108 108 108
6 -9 0 108 108 108
7 -9 0 108 108 108
8 -9 0 108 108 108
9 -9 0 108 108 108
10 -9 0 108 108 108
11 -9 0 108 108 108
12 -9 0 108 108 108
13 -9 0 108 108 108
14 -9 0 144 144 144
-15 -8 0 144 144 144
-14 -8 0 108 108 108
-13 -8 0 108 108 108
-12 -8 0 108 108 108
-11 -8 0 108 108 108
-10 -8 0 108 108 108
-9 -8 0 108 108 108
-8 -8 0 108 108 108
-7 -8 0 108 108 108
-6 -8 0 108 108 108
-5 -8 0 108 108 108
-4 -8 0 108 108 108
-3 -8 0 108 108 108
-2 -8 0 108 108 108
-1 -8 0 108 108 108
0 -8 0 108 108 108
1 -8 0 108 108 108
2 -8 0 108 108 108
3 -8 0 108 108 108
4 -8 0 108 108 108
5 -8 0 108 108 108
6 -8 0 108 108 108
7 -8 0 108 108 108
8 -8 0 108 108 108
9 -8 0 108 108 108
10 -8 0 108 108 108
11 -8 0 108 108 108
12 -8 0 108 108 108
13 -8 0 108 108 108
14 -8 0 144 144 144
-15 -7 0 144 144 144
-14 -7 0 108 108 108
-13 -7 0 108 108 108
-12 -7 0 108 108 108
-11 -7 0 108 108 108
-10 -7 0 108 108 108
-9 -7 0 108 108 108
-8 -7 0 108 108 108
-7 -7 0 108 108 108
-6 -7 0 108 108 108
-5 -7 0 108 108 108
-4 -7 0 108 108 108
-3 -7 0 108 108 108
-2 -7 0 108 108 108
-1 -7 0 108 108 108
0 -7 0 108 108 108
1 -7 0 108 108 108
2 -7 0 108 108 108
3 -7 0 108 108 108
4 -7 0 108 108 108
5 -7 0 108 108 108
6 -7 0 108 108 108
7 -7 0 108 108 108
8 -7 0 108 108 108
9 -7 0 108 108 108
10 -7 0 108 108 108
11 -7 0 108 108 108
12 -7 0 108 108 108
13 -7 0 108 108 108
14 -7 0 144 144 144
-15 -6 0 144 144 144
-14 -6 0 108 108 108
-13 -6 0 108 108 108
-12 -6 0 108 108 108
-11 -6 0 108 108 108
-10 -6 0 108 108 108
-9 -6 0 108 108 108
-8 -6 0 108 108 108
-7 -6 0 108 108 108
-6 -6 0 64 64 64
-5 -6 0 64 64 64
-4 -6 0 64 64 64
-3 -6 0 64 64 64
-2 -6 0 64 64 64
-1 -6 0 64 64 64
0 -6 0 64 64 64
1 -6 0 64 64 64
2 -6 0 64 64 64
3 -6 0 64 64 64
4 -6 0 64 64 64
5 -6 0 64 64 64
6 -6 0 108 108 108
7 -6 0 108 108 108
8 -6 0 108 108 108
9 -6 0 108 108 108
10 -6 0 108 108 108
11 -6 0 108 108 108
12 -6 0 108 108 108
13 -6 0 108 108 108
14 -6 0 144 144 144
-15 -5 0 144 144 144
-14 -5 0 108 108 108
-13 -5 0 108 108 108
-12 -5 0 108 108 108
-11 -5 0 108 108 108
-10 -5 0 108 108 108
-9 -5 0 108 108 108
-8 -5 0 108 108 108
-7 -5 0 108 108 108
-6 -5 0 64 64 64
-5 -5 0 108 108 108
-4 -5 0 108 108 108
-3 -5 0 108 108 108
-2 -5 0 108 108 108
-1 -5 0 108 108 108
0 -5 0 108 108 108
1 -5 0 108 108 108
2 -5 0 108 108 108
3 -5 0 108 108 108
4 -5 0 108 108 108
5 -5 0 64 64 64
6 -5 0 108 108 108
7 -5 0 108 108 108
8 -5 0 108 108 108
9 -5 0 108 108 108
10 -5 0 108 108 108
11 -5 0 108 108 108
12 -5 0 108 108 108
13 -5 0 108 108 108
14 -5 0 144 144 144
-15 -4 0 144 144 144
-14 -4 0 108 108 108
-13 -4 0 108 108 108
-12 -4 0 108 108 108
-11 -4 0 108 108 108
-10 -4 0 108 108 108
-9 -4 0 108 108 108
-8 -4 0 108 108 108
-7 -4 0 108 108 108
-6 -4 0 64 64 64
-5 -4 0 108 108 108
-4 -4 0 64 64 64
-3 -4 0 64 64 64
-2 -4 0 108 108 108
-1 -4 0 64 64 64
0 -4 0 64 64 64
1 -4 0 108 108 108
2 -4 0 64 64 64
3 -4 0 64 64 64
4 -4 0 108 108 108
5 -4 0 64 64 64
6 -4 0 108 108 108
7 -4 0 108 108 108
8 -4 0 108 108 108
9 -4 0 108 108 108
10 -4 0 108 108 108
11 -4 0 108 108 108
12 -4 0 108 108 108
13 -4 0 108 108 108
14 -4 0 144 144 144
-15 -3 0 144 144 144
-14 -3 0 108 108 108
-13 -3 0 108 108 108
-12 -3 0 108 108 108
-11 -3 0 108 108 108
-10 -3 0 108 108 108
-9 -3 0 108 108 108
-8 -3 0 108 108 108
-7 -3 0 108 108 108
-6 -3 0 64 64 64
-5 -3 0 108 108 108
-4 -3 0 64 64 64
-3 -3 0 64 64 64
-2 -3 0 108 108 108
-1 -3 0 64 64 64
0 -3 0 64 64 64
1 -3 0 108 108 108
2 -3 0 64 64 64
3 -3 0 64 64 64
4 -3 0 108 108 108
5 -3 0 64 64 64
6 -3 0 108 108 108
7 -3 0 108 108 108
8 -3 0 108 108 108
9 -3 0 108 108 108
10 -3 0 108 108 108
11 -3 0 108 108 108
12 -3 0 108 108 108
13 -3 0 108 108 108
14 -3 0 144 144 144
-15 -2 0 144 144 144
-14 -2 0 108 108 108
-13 -2 0 108 108 108
-12 -2 0 108 108 108
-11 -2 0 108 108 108
-10 -2 0 108 108 108
-9 -2 0 108 108 108
-8 -2 0 108 108 108
-7 -2 0 108 108 108
-6 -2 0 64 64 64
-5 -2 0 108 108 108
-4 -2 0 108 108 108
-3 -2 0 108 108 108
-2 -2 0 108 108 108
-1 -2 0 108 108 108
0 -2 0 108 108 108
1 -2 0 108 108 108
2 -2 0 108 108 108
3 -2 0 108 108 108
4 -2 0 108 108 108
5 -2 0 64 64 64
6 -2 0 108 108 108
7 -2 0 108 108 108
8 -2 0 108 108 108
9 -2 0 108 108 108
10 -2 0 108 108 108
11 -2 0 108 108 108
12 -2 0 108 108 108
13 -2 0 108 108 108
14 -2 0 144 144 144
-15 -1 0 144 144 144
-14 -1 0 108 108 108
-13 -1 0 108 108 108
-12 -1 0 108 108 108
-11 -1 0 108 108 108
-10 -1 0 108 108 108
-9 -1 0 108 108 108
-8 -1 0 108 108 108
-7 -1 0 108 108 108
-6 -1 0 64 64 64
-5 -1 0 108 108 108
-4 -1 0 108 108 108
-3 -1 0 108 108 108
-2 -1 0 108 108 108
-1 -1 0 108 108 108
0 -1 0 108 108 108
1 -1 0 108 108 108
2 -1 0 108 108 108
3 -1 0 108 108 108
4 -1 0 108 108 108
5 -1 0 64 64 64
6 -1 0 108 108 108
7 -1 0 108 108 108
8 -1 0 108 108 108
9 -1 0 108 108 108
10 -1 0 108 108 108
11 -1 0 108 108 108
12 -1 0 108 108 108
13 -1 0 108 108 108
14 -1 0 144 144 144
-15 0 0 144 144 144
-14 0 0 108 108 108
-13 0 0 108 108 108
-12 0 0 108 108 108
-11 0 0 108 108 108
-10 0 0 108 108 108
-9 0 0 108 108 108
-8 0 0 108 108 108
-7 0 0 108 108 108
-6 0 0 64 64 64
-5 0 0 108 108 108
-4 0 0 108 108 108
-3 0 0 108 108 108
-2 0 0 108 108 108
-1 0 0 108 108 108
0 0 0 108 108 108
1 0 0 108 108 108
2 0 0 108 108 108
3 0 0 108 108 108
4 0 0 108 108 108
5 0 0 64 64 64
6 0 0 108 108 108
7 0 0 108 108 108
8 0 0 108 108 108
9 0 0 108 108 108
10 0 0 108 108 108
11 0 0 108 108 108
12 0 0 108 108 108
13 0 0 108 108 108
14 0 0 144 144 144
-15 1 0 144 144 144
-14 1 0 108 108 108
-13 1 0 108 108 108
-12 1 0 108 108 108
-11 1 0 108 108 108
-10 1 0 108 108 108
-9 1 0 108 108 108
-8 1 0 108 108 108
-7 1 0 108 108 108
-6 1 0 64 64 64
-5 1 0 108 108 108
-4 1 0 108 108 108
-3 1 0 108 108 108
-2 1 0 108 108 108
-1 1 0 108 108 108
0 1 0 108 108 108
1 1 0 108 108 108
2 1 0 108 108 108
3 1 0 108 108 108
4 1 0 108 108 108
5 1 0 64 64 64
6 1 0 108 108 108
7 1 0 108 108 108
8 1 0 108 108 108
9 1 0 108 108 108
10 1 0 108 108 108
11 1 0 108 108 108
12 1 0 108 108 108
13 1 0 108 108 108
14 1 0 144 144 144
-15 2 0 144 144 144
-14 2 0 108 108 108
-13 2 0 108 108 108
-12 2 0 108 108 108
-11 2 0 108 108 108
-10 2 0 108 108 108
-9 2 0 108 108 108
-8 2 0 108 108 108
-7 2 0 108 108 108
-6 2 0 64 64 64
-5 2 0 108 108 108
-4 2 0 64 64 64
-3 2 0 64 64 64
-2 2 0 108 108 108
-1 2 0 64 64 64
0 2 0 64 64 64
1 2 0 108 108 108
2 2 0 64 64 64
3 2 0 64 64 64
4 2 0 108 108 108
5 2 0 64 64 64
6 2 0 108 108 108
7 2 0 108 108 108
8 2 0 108 108 108
9 2 0 108 108 108
10 2 0 108 108 108
11 2 0 108 108 108
12 2 0 108 108 108
13 2 0 108 108 108
14 2 0 144 144 144
-15 3 0 144 144 144
-14 3 0 108 108 108
-13 3 0 108 108 108
-12 3 0 108 108 108
-11 3 0 108 108 108
-10 3 0 108 108 108
-9 3 0 108 108 108
-8 3 0 108 108 108
-7 3 0 108 108 108
-6 3 0 64 64 64
-5 3 0 108 108 108
-4 3 0 64 64 64
-3 3 0 64 64 64
-2 3 0 108 108 108
-1 3 0 64 64 64
0 3 0 64 64 64
1 3 0 108 108 108
2 3 0 64 64 64
3 3 0 64 64 64
4 3 0 108 108 108
5 3 0 64 64 64
6 3 0 108 108 108
7 3 0 108 108 108
8 3 0 108 108 108
9 3 0 108 108 108
10 3 0 108 108 108
11 3 0 108 108 108
12 3 0 108 108 108
13 3 0 108 108 108
14 3 0 144 144 144
-15 4 0 144 144 144
-14 4 0 108 108 108
-13 4 0 108 108 108
-12 4 0 108 108 108
-11 4 0 108 108 108
-10 4 0 108 108 108
-9 4 0 108 108 108
-8 4 0 108 108 108
-7 4 0 108 108 108
-6 4 0 64 64 64
-5 4 0 108 108 108
-4 4 0 108 108 108
-3 4 0 108 108 108
-2 4 0 108 108 108
-1 4 0 108 108 108
0 4 0 108 108 108
1 4 0 108 108 108
2 4 0 108 108 108
3 4 0 108 108 108
4 4 0 108 108 108
5 4 0 64 64 64
6 4 0 108 108 108
7 4 0 108 108 108
8 4 0 108 108 108
9 4 0 108 108 108
10 4 0 108 108 108
11 4 0 108 108 108
12 4 0 108 108 108
13 4 0 108 108 108
14 4 0 144 144 144
-15 5 0 144 144 144
-14 5 0 108 108 108
-13 5 0 108 108 108
-12 5 0 108 108 108
-11 5 0 108 108 108
-10 5 0 108 108 108
-9 5 0 108 108 108
-8 5 0 108 108 108
-7 5 0 108 108 108
-6 5 0 64 64 64
-5 5 0 64 64 64
-4 5 0 64 64 64
-3 5 0 64 64 64
-2 5 0 64 64 64
-1 5 0 64 64 64
0 5 0 64 64 64
1 5 0 64 64 64
2 5 0 64 64 64
3 5 0 64 64 64
4 5 0 64 64 64
5 5 0 64 64 64
6 5 0 108 108 108
7 5 0 108 108 108
8 5 0 108 108 108
9 5 0 108 108 108
10 5 0 108 108 108
11 5 0 108 108 108
12 5 0 108 108 108
13 5 0 108 108 108
14 5 0 144 144 144
-15 6 0 144 144 144
-14 6 0 108 108 108
-13 6 0 108 108 108
-12 6 0 108 108 108
-11 6 0 108 108 108
-10 6 0 108 108 108
-9 6 0 108 108 108
-8 6 0 108 108 108
-7 6 0 108 108 108
-6 6 0 108 108 108
-5 6 0 108 108 108
-4 6 0 108 108 108
-3 6 0 108 108 108
-2 6 0 108 108 108
-1 6 0 108 108 108
0 6 0 108 108 108
1 6 0 108 108 108
2 6 0 108 108 108
3 6 0 108 108 108
4 6 0 108 108 108
5 6 0 108 108 108
6 6 0 108 108 108
7 6 0 108 108 108
8 6 0 108 108 108
9 6 0 108 108 108
10 6 0 108 108 108
11 6 0 108 108 108
12 6 0 108 108 108
13 6 0 108 108 108
14 6 0 144 144 144
-15 7 0 144 144 144
-14 7 0 108 108 108
-13 7 0 108 108 108
-12 7 0 108 108 108
-11 7 0 108 108 108
-10 7 0 108 108 108
-9 7 0 108 108 108
-8 7 0 108 108 108
-7 7 0 108 108 108
-6 7 0 108 108 108
-5 7 0 108 108 108
-4 7 0 108 108 108
-3 7 0 108 108 108
-2 7 0 108 108 108
-1 7 0 108 108 108
0 7 0 108 108 108
1 7 0 108 108 108
2 7 0 108 108 108
3 7 0 108 108 108
4 7 0 108 108 108
5 7 0 108 108 108
6 7 0 108 108 108
7 7 0 108 108 108
8 7 0 108 108 108
9 7 0 108 108 108
10 7 0 108 108 108
11 7 0 108 108 108
12 7 0 108 108 108
13 7 0 108 108 108
14 7 0 144 144 144
-15 8 0 144 144 144
-14 8 0 108 108 108
-13 8 0 108 108 108
-12 8 0 108 108 108
-11 8 0 108 108 108
-10 8 0 108 108 108
-9 8 0 108 108 108
-8 8 0 108 108 108
-7 8 0 108 108 108
-6 8 0 108 108 108
-5 8 0 108 108 108
-4 8 0 108 108 108
-3 8 0 108 108 108
-2 8 0 108 108 108
-1 8 0 108 108 108
0 8 0 108 108 108
1 8 0 108 108 108
2 8 0 108 108 108
3 8 0 108 108 108
4 8 0 108 108 108
5 8 0 108 108 108
6 8 0 108 108 108
7 8 0 108 108 108
8 8 0 108 108 108
9 8 0 108 108 108
10 8 0 108 108 108
11 8 0 108 108 108
12 8 0 108 108 108
13 8 0 108 108 108
14 8 0 144 144 144
-15 9 0 144 144 144
-14 9 0 108 108 108
-13 9 0 108 108 108
-12 9 0 108 108 108
-11 9 0 108 108 108
-10 9 0 108 108 108
-9 9 0 108 108 108
-8 9 0 108 108 108
-7 9 0 108 108 108
-6 9 0 108 108 108
-5 9 0 108 108 108
-4 9 0 108 108 108
-3 9 0 108 108 108
-2 9 0 108 108 108
-1 9 0 108 108 108
0 9 0 108 108 108
1 9 0 108 108 108
2 9 0 108 108 108
3 9 0 108 108 108
4 9 0 108 108 108
5 9 0 108 108 108
6 9 0 108 108 108
7 9 0 108 108 108
8 9 0 108 108 108
9 9 0 108 108 108
10 9 0 108 108 108
11 9 0 108 108 108
12 9 0 108 108 108
13 9 0 108 108 108
14 9 0 144 144 144
-15 10 0 144 144 144
-14 10 0 108 108 108
-13 10 0 108 108 108
-12 10 0 108 108 108
-11 10 0 108 108 108
-10 10 0 108 108 108
-9 10 0 108 108 108
-8 10 0 108 108 108
-7 10 0 108 108 108
-6 10 0 108 108 108
-5 10 0 108 108 108
-4 10 0 108 108 108
-3 10 0 108 108 108
-2 10 0 108 108 108
-1 10 0 108 108 108
0 10 0 108 108 108
1 10 0 108 108 108
2 10 0 108 108 108
3 10 0 108 108 108
4 10 0 108 108 108
5 10 0 108 108 108
6 10 0 108 108 108
7 10 0 108 108 108
8 10 0 108 108 108
9 10 0 108 108 108
10 10 0 108 108 108
11 10 0 108 108 108
12 10 0 108 108 108
13 10 0 108 108 108
14 10 0 144 144 144
-15 11 0 144 144 144
-14 11 0 108 108 108
-13 11 0 108 108 108
-12 11 0 108 108 108
-11 11 0 108 108 108
-10 11 0 108 108 108
-9 11 0 108 108 108
-8 11 0 108 108 108
-7 11 0 108 108 108
-6 11 0 108 108 108
-5 11 0 108 108 108
-4 11 0 108 108 108
-3 11 0 108 108 108
-2 11 0 108 108 108
-1 11 0 108 108 108
0 11 0 108 108 108
1 11 0 108 108 108
2 11 0 108 108 108
3 11 0 108 108 108
4 11 0 108 108 108
5 11 0 108 108 108
6 11 0 108 108 108
7 11 0 108 108 108
8 11 0 108 108 108
9 11 0 108 108 108
10 11 0 108 108 108
11 11 0 108 108 108
12 11 0 108 108 108
13 11 0 108 108 108
14 11 0 144 144 144
-15 12 0 144 144 144
-14 12 0 108 108 108
-13 12 0 108 108 108
-12 12 0 108 108 108
-11 12 0 108 108 108
-10 12 0 108 108 108
-9 12 0 108 108 108
-8 12 0 108 108 108
-7 12 0 108 108 108
-6 12 0 108 108 108
-5 12 0 108 108 108
-4 12 0 108 108 108
-3 12 0 108 108 108
-2 12 0 108 108 108
-1 12 0 108 108 108
0 12 0 108 108 108
1 12 0 108 108 108
2 12 0 108 108 108
3 12 0 108 108 108
4 12 0 108 108 108
5 12 0 108 108 108
6 12 0 108 108 108
7 12 0 108 108 108
8 12 0 108 108 108
9 12 0 108 108 108
10 12 0 108 108 108
11 12 0 108 108 108
12 12 0 108 108 108
13 12 0 108 108 108
14 12 0 144 144 144
-15 13 0 144 144 144
-14 13 0 108 108 108
-13 13 0 108 108 108
-12 13 0 108 108 108
-11 13 0 108 108 108
-10 13 0 108 108 108
-9 13 0 108 108 108
-8 13 0 108 108 108
-7 13 0 108 108 108
-6 13 0 108 108 108
-5 13 0 108 108 108
-4 13 0 108 108 108
-3 13 0 108 108 108
-2 13 0 108 108 108
-1 13 0 108 108 108
0 13 0 108 108 108
1 13 0 108 108 108
2 13 0 108 108 108
3 13 0 108 108 108
4 13 0 108 108 108
5 13 0 108 108 108
6 13 0 108 108 108
7 13 0 108 108 108
8 13 0 108 108 108
9 13 0 108 108 108
10 13 0 108 108 108
11 13 0 108 108 108
12 13 0 108 108 108
13 13 0 108 108 108
14 13 0 144 144 144
-15 14 0 144 144 144
-14 14 0 144 144 144
-13 14 0 144 144 144
-12 14 0 144 144 144
-11 14 0 144 144 144
-10 14 0 144 144 144
-9 14 0 144 144 144
-8 14 0 144 144 144
-7 14 0 144 144 144
-6 14 0 144 144 144
-5 14 0 144 144 144
-4 14 0 144 144 144
-3 14 0 144 144 144
-2 14 0 144 144 144
-1 14 0 144 144 144
0 14 0 144 144 144
1 14 0 144 144 144
2 14 0 144 144 144
3 14 0 144 144 144
4 14 0 144 144 144
5 14 0 144 144 144
6 14 0 144 144 144
7 14 0 144 144 144
8 14 0 144 144 144
9 14 0 144 144 144
10 14 0 144 144 144
11 14 0 144 144 144
12 14 0 144 144 144
13 14 0 144 144 144
14 14 0 144 144 144
-15 -15 1 144 144 144
-14 -15 1 144 144 144
-13 -15 1 144 144 144
-12 -15 1 144 144 144
-11 -15 1 144 144 144
-10 -15 1 144 144 144
-9 -15 1 144 144 144
-8 -15 1 144 144 144
-7 -15 1 144 144 144
-6 -15 1 144 144 144
-5 -15 1 144 144 144
-4 -15 1 144 144 144
-3 -15 1 144 144 144
-2 -15 1 144 144 144
-1 -15 1 144 144 144
0 -15 1 144 144 144
1 -15 1 144 144 144
2 -15 1 144 144 144
3 -15 1 144 144 144
4 -15 1 144 144 144
5 -15 1 144 144 144
6 -15 1 144 144 144
7 -15 1 144 144 144
8 -15 1 144 144 144
9 -15 1 144 144 144
10 -15 1 144 144 144
11 -15 1 144 144 144
12 -15 1 144 144 144
13 -15 1 144 144 144
14 -15 1 144 144 144
-15 -14 1 144 144 144
-14 -14 1 108 108 108
-13 -14 1 108 108 108
-12 -14 1 108 108 108
-11 -14 1 108 108 108
-10 -14 1 108 108 108
-9 -14 1 108 108 108
-8 -14 1 108 108 108
-7 -14 1 108 108 108
-6 -14 1 108 108 108
-5 -14 1 108 108 108
-4 -14 1 108 108 108
-3 -14 1 108 108 108
-2 -14 1 108 108 108
-1 -14 1 108 108 108
0 -14 1 108 108 108
1 -14 1 108 108 108
2 -14 1 108 108 108
3 -14 1 108 108 108
4 -14 1 108 108 108
5 -14 1 108 108 108
6 -14 1 108 108 108
7 -14 1 108 108 108
8 -14 1 108 108 108
9 -14 1 108 108 108
10 -14 1 108 108 108
11 -14 1 108 108 108
12 -14 1 108 108 108
13 -14 1 108 108 108
14 -14 1 144 144 144
-15 -13 1 144 144 144
-14 -13 1 108 108 108
-13 -13 1 108 108 108
-12 -13 1 108 108 108
-11 -13 1 108 108 108
-10 -13 1 108 108 108
-9 -13 1 108 108 108
-8 -13 1 108 108 108
-7 -13 1 108 108 108
-6 -13 1 108 108 108
-5 -13 1 108 108 108
-4 -13 1 108 108 108
-3 -13 1 108 108 108
-2 -13 1 108 108 108
-1 -13 1 108 108 108
0 -13 1 108 108 108
1 -13 1 108 108 108
2 -13 1 108 108 108
3 -13 1 108 108 108
4 -13 1 108 108 108
5 -13 1 108 108 108
6 -13 1 108 108 108
7 -13 1 108 108 108
8 -13 1 108 108 108
9 -13 1 108 108 108
10 -13 1 108 108 108
11 -13 1 108 108 108
12 -13 1 108 108 108
13 -13 1 108 108 108
14 -13 1 144 144 144
-15 -12 1 144 144 144
-14 -12 1 108 108 108
-13 -12 1 108 108 108
-12 -12 1 64 64 64
-11 -12 1 64 64 64
-1 -12 1 64 64 64
0 -12 1 64 64 64
10 -12 1 64 64 64
11 -12 1 64 64 64
12 -12 1 108 108 108
13 -12 1 108 108 108
14 -12 1 144 144 144
-15 -11 1 144 144 144
-14 -11 1 108 108 108
-13 -11 1 108 108 108
-12 -11 1 64 64 64
-11 -11 1 64 64 64
-1 -11 1 64 64 64
0 -11 1 64 64 64
10 -11 1 64 64 64
11 -11 1 64 64 64
12 -11 1 108 108 108
13 -11 1 108 108 108
14 -11 1 144 144 144
-15 -10 1 144 144 144
-14 -10 1 108 108 108
-13 -10 1 108 108 108
12 -10 1 108 108 108
13 -10 1 108 108 108
14 -10 1 144 144 144
-15 -9 1 144 144 144
-14 -9 1 108 108 108
-13 -9 1 108 108 108
12 -9 1 108 108 108
13 -9 1 108 108 108
14 -9 1 144 144 144
-15 -8 1 144 144 144
-14 -8 1 108 108 108
-13 -8 1 108 108 108
12 -8 1 108 108 108
13 -8 1 108 108 108
14 -8 1 144 144 144
-15 -7 1 144 144 144
-14 -7 1 108 108 108
-13 -7 1 108 108 108
12 -7 1 108 108 108
13 -7 1 108 108 108
14 -7 1 144 144 144
-15 -6 1 144 144 144
-14 -6 1 108 108 108
-13 -6 1 108 108 108
-12 -6 1 64 64 64
-11 -6 1 64 64 64
12 -6 1 108 108 108
13 -6 1 108 108 108
14 -6 1 144 144 144
-15 -5 1 144 144 144
-14 -5 1 108 108 108
-13 -5 1 108 108 108
-12 -5 1 64 64 64
-11 -5 1 64 64 64
12 -5 1 108 108 108
13 -5 1 108 108 108
14 -5 1 144 144 144
-15 -4 1 144 144 144
-14 -4 1 108 108 108
-13 -4 1 108 108 108
-12 -4 1 108 108 108
-11 -4 1 108 108 108
-10 -4 1 108 108 108
12 -4 1 108 108 108
13 -4 1 108 108 108
14 -4 1 144 144 144
-15 -3 1 144 144 144
-14 -3 1 108 108 108
-13 -3 1 108 108 108
-12 -3 1 108 108 108
-11 -3 1 108 108 108
-10 -3 1 108 108 108
12 -3 1 108 108 108
13 -3 1 108 108 108
14 -3 1 144 144 144
-15 -2 1 144 144 144
-14 -2 1 108 108 108
-13 -2 1 108 108 108
-12 -2 1 108 108 108
-11 -2 1 108 108 108
-10 -2 1 108 108 108
12 -2 1 108 108 108
13 -2 1 108 108 108
14 -2 1 144 144 144
-15 -1 1 144 144 144
-14 -1 1 108 108 108
-13 -1 1 108 108 108
-12 -1 1 108 108 108
-11 -1 1 108 108 108
-10 -1 1 108 108 108
10 -1 1 64 64 64
11 -1 1 64 64 64
12 -1 1 108 108 108
13 -1 1 108 108 108
14 -1 1 144 144 144
-15 0 1 144 144 144
-14 0 1 108 108 108
-13 0 1 108 108 108
-12 0 1 108 108 108
-11 0 1 108 108 108
-10 0 1 108 108 108
10 0 1 64 64 64
11 0 1 64 64 64
12 0 1 108 108 108
13 0 1 108 108 108
14 0 1 144 144 144
-15 1 1 144 144 144
-14 1 1 108 108 108
-13 1 1 108 108 108
-12 1 1 108 108 108
-11 1 1 108 108 108
-10 1 1 108 108 108
12 1 1 108 108 108
13 1 1 108 108 108
14 1 1 144 144 144
-15 2 1 144 144 144
-14 2 1 108 108 108
-13 2 1 108 108 108
-12 2 1 108 108 108
-11 2 1 108 108 108
-10 2 1 108 108 108
12 2 1 108 108 108
13 2 1 108 108 108
14 2 1 144 144 144
-15 3 1 144 144 144
-14 3 1 108 108 108
-13 3 1 108 108 108
-12 3 1 108 108 108
-11 3 1 108 108 108
-10 3 1 108 108 108
12 3 1 108 108 108
13 3 1 108 108 108
14 3 1 144 144 144
-15 4 1 144 144 144
-14 4 1 108 108 108
-13 4 1 108 108 108
-12 4 1 64 64 64
-11 4 1 64 64 64
12 4 1 108 108 108
13 4 1 108 108 108
14 4 1 144 144 144
-15 5 1 144 144 144
-14 5 1 108 108 108
-13 5 1 108 108 108
-12 5 1 64 64 64
-11 5 1 64 64 64
12 5 1 108 108 108
13 5 1 108 108 108
14 5 1 144 144 144
-15 6 1 144 144 144
-14 6 1 108 108 108
-13 6 1 108 108 108
12 6 1 108 108 108
13 6 1 108 108 108
14 6 1 144 144 144
-15 7 1 144 144 144
-14 7 1 108 108 108
-13 7 1 108 108 108
12 7 1 108 108 108
13 7 1 108 108 108
14 7 1 144 144 144
-15 8 1 144 144 144
-14 8 1 108 108 108
-13 8 1 108 108 108
12 8 1 108 108 108
13 8 1 108 108 108
14 8 1 144 144 144
-15 9 1 144 144 144
-14 9 1 108 108 108
-13 9 1 108 108 108
12 9 1 108 108 108
13 9 1 108 108 108
14 9 1 144 144 144
-15 10 1 144 144 144
-14 10 1 108 108 108
-13 10 1 108 108 108
-12 10 1 64 64 64
-11 10 1 64 64 64
-1 10 1 64 64 64
0 10 1 64 64 64
10 10 1 64 64 64
11 10 1 64 64 64
12 10 1 108 108 108
13 10 1 108 108 108
14 10 1 144 144 144
-15 11 1 144 144 144
-14 11 1 108 108 108
-13 11 1 108 108 108
-12 11 1 64 64 64
-11 11 1 64 64 64
-1 11 1 64 64 64
0 11 1 64 64 64
10 11 1 64 64 64
11 11 1 64 64 64
12 11 1 108 108 108
13 11 1 108 108 108
14 11 1 144 144 144
-15 12 1 144 144 144
-14 12 1 108 108 108
-13 12 1 108 108 108
-12 12 1 108 108 108
-11 12 1 108 108 108
-10 12 1 108 108 108
-9 12 1 108 108 108
-8 12 1 108 108 108
-7 12 1 108 108 108
-6 12 1 108 108 108
-5 12 1 108 108 108
-4 12 1 108 108 108
-3 12 1 108 108 108
-2 12 1 108 108 108
-1 12 1 108 108 108
0 12 1 108 108 108
1 12 1 108 108 108
2 12 1 108 108 108
3 12 1 108 108 108
4 12 1 108 108 108
5 12 1 108 108 108
6 12 1 108 108 108
7 12 1 108 108 108
8 12 1 108 108 108
9 12 1 108 108 108
10 12 1 108 108 108
11 12 1 108 108 108
12 12 1 108 108 108
13 12 1 108 108 108
14 12 1 144 144 144
-15 13 1 144 144 144
-14 13 1 108 108 108
-13 13 1 108 108 108
-12 13 1 108 108 108
-11 13 1 108 108 108
-10 13 1 108 108 108
-9 13 1 108 108 108
-8 13 1 108 108 108
-7 13 1 108 108 108
-6 13 1 108 108 108
-5 13 1 108 108 108
-4 13 1 108 108 108
-3 13 1 108 108 108
-2 13 1 108 108 108
-1 13 1 108 108 108
0 13 1 108 108 108
1 13 1 108 108 108
2 13 1 108 108 108
3 13 1 108 108 108
4 13 1 108 108 108
5 13 1 108 108 108
6 13 1 108 108 108
7 13 1 108 108 108
8 13 1 108 108 108
9 13 1 108 108 108
10 13 1 108 108 108
11 13 1 108 108 108
12 13 1 108 108 108
13 13 1 108 108 108
14 13 1 144 144 144
-15 14 1 144 144 144
-14 14 1 144 144 144
-13 14 1 144 144 144
-12 14 1 144 144 144
-11 14 1 144 144 144
-10 14 1 144 144 144
-9 14 1 144 144 144
-8 14 1 144 144 144
-7 14 1 144 144 144
-6 14 1 144 144 144
-5 14 1 144 144 144
-4 14 1 144 144 144
-3 14 1 144 144 144
-2 14 1 144 144 144
-1 14 1 144 144 144
0 14 1 144 144 144
1 14 1 144 144 144
2 14 1 144 144 144
3 14 1 144 144 144
4 14 1 144 144 144
5 14 1 144 144 144
6 14 1 144 144 144
7 14 1 144 144 144
8 14 1 144 144 144
9 14 1 144 144 144
10 14 1 144 144 144
11 14 1 144 144 144
12 14 1 144 144 144
13 14 1 144 144 144
14 14 1 144 144 144
-15 -15 2 144 144 144
-14 -15 2 144 144 144
-13 -15 2 144 144 144
-12 -15 2 144 144 144
-11 -15 2 144 144 144
-10 -15 2 144 144 144
-9 -15 2 144 144 144
-8 -15 2 144 144 144
-7 -15 2 144 144 144
-6 -15 2 144 144 144
-5 -15 2 144 144 144
-4 -15 2 144 144 144
-3 -15 2 144 144 144
-2 -15 2 144 144 144
-1 -15 2 144 144 144
0 -15 2 144 144 144
1 -15 2 144 144 144
2 -15 2 144 144 144
3 -15 2 144 144 144
4 -15 2 144 144 144
5 -15 2 144 144 144
6 -15 2 144 144 144
7 -15 2 144 144 144
8 -15 2 144 144 144
9 -15 2 144 144 144
10 -15 2 144 144 144
11 -15 2 144 144 144
12 -15 2 144 144 144
13 -15 2 144 144 144
14 -15 2 144 144 144
-15 -14 2 144 144 144
-14 -14 2 108 108 108
-13 -14 2 108 108 108
-12 -14 2 108 108 108
-11 -14 2 108 108 108
-10 -14 2 108 108 108
-9 -14 2 108 108 108
-8 -14 2 108 108 108
-7 -14 2 108 108 108
-6 -14 2 108 108 108
-5 -14 2 108 108 108
-4 -14 2 108 108 108
-3 -14 2 108 108 108
-2 -14 2 108 108 108
-1 -14 2 108 108 108
0 -14 2 108 108 108
1 -14 2 108 108 108
2 -14 2 108 108 108
3 -14 2 108 108 108
4 -14 2 108 108 108
5 -14 2 108 108 108
6 -14 2 108 108 108
7 -14 2 108 108 108
8 -14 2 108 108 108
9 -14 2 108 108 108
10 -14 2 108 108 108
11 -14 2 108 108 108
12 -14 2 108 108 108
13 -14 2 108 108 108
14 -14 2 144 144 144
-15 -13 2 144 144 144
-14 -13 2 108 108 108
-13 -13 2 108 108 108
-12 -13 2 108 108 108
-11 -13 2 108 108 108
-10 -13 2 108 108 108
-9 -13 2 108 108 108
-8 -13 2 108 108 108
-7 -13 2 108 108 108
-6 -13 2 108 108 108
-5 -13 2 108 108 108
-4 -13 2 108 108 108
-3 -13 2 108 108 108
-2 -13 2 108 108 108
-1 -13 2 108 108 108
0 -13 2 108 108 108
1 -13 2 108 108 108
2 -13 2 108 108 108
3 -13 2 108 108 108
4 -13 2 108 108 108
5 -13 2 108 108 108
6 -13 2 108 108 108
7 -13 2 108 108 108
8 -13 2 108 108 108
9 -13 2 108 108 108
10 -13 2 108 108 108
11 -13 2 108 108 108
12 -13 2 108 108 108
13 -13 2 108 108 108
14 -13 2 144 144 144
-15 -12 2 144 144 144
-14 -12 2 108 108 108
-13 -12 2 108 108 108
-12 -12 2 64 64 64
-11 -12 2 64 64 64
-1 -12 2 64 64 64
0 -12 2 64 64 64
10 -12 2 64 64 64
11 -12 2 64 64 64
12 -12 2 108 108 108
13 -12 2 108 108 108
14 -12 2 144 144 144
-15 -11 2 144 144 144
-14 -11 2 108 108 108
-13 -11 2 108 108 108
-12 -11 2 64 64 64
-11 -11 2 64 64 64
-1 -11 2 64 64 64
0 -11 2 64 64 64
10 -11 2 64 64 64
11 -11 2 64 64 64
12 -11 2 108 108 108
13 -11 2 108 108 108
14 -11 2 144 144 144
-15 -10 2 144 144 144
-14 -10 2 108 108 108
-13 -10 2 108 108 108
12 -10 2 108 108 108
13 -10 2 108 108 108
14 -10 2 144 144 144
-15 -9 2 144 144 144
-14 -9 2 108 108 108
-13 -9 2 108 108 108
12 -9 2 108 108 108
13 -9 2 108 108 108
14 -9 2 144 144 144
-15 -8 2 144 144 144
-14 -8 2 108 108 108
-13 -8 2 108 108 108
12 -8 2 108 108 108
13 -8 2 108 108 108
14 -8 2 144 144 144
-15 -7 2 144 144 144
-14 -7 2 108 108 108
-13 -7 2 108 108 108
12 -7 2 108 108 108
13 -7 2 108 108 108
14 -7 2 144 144 144
-15 -6 2 144 144 144
-14 -6 2 108 108 108
-13 -6 2 108 108 108
-12 -6 2 64 64 64
-11 -6 2 64 64 64
12 -6 2 108 108 108
13 -6 2 108 108 108
14 -6 2 144 144 144
-15 -5 2 144 144 144
-14 -5 2 108 108 108
-13 -5 2 108 108 108
-12 -5 2 64 64 64
-11 -5 2 64 64 64
12 -5 2 108 108 108
13 -5 2 108 108 108
14 -5 2 144 144 144
-15 -4 2 144 144 144
-14 -4 2 108 108 108
-13 -4 2 108 108 108
-12 -4 2 108 108 108
-11 -4 2 108 108 108
-10 -4 2 108 108 108
12 -4 2 108 108 108
13 -4 2 108 108 108
14 -4 2 144 144 144
-15 -3 2 144 144 144
-14 -3 2 108 108 108
-13 -3 2 108 108 108
-12 -3 2 108 108 108
-11 -3 2 108 108 108
12 -3 2 108 108 108
13 -3 2 108 108 108
14 -3 2 144 144 144
-15 -2 2 144 144 144
-14 -2 2 108 108 108
-13 -2 2 108 108 108
-12 -2 2 108 108 108
-11 -2 2 108 108 108
12 -2 2 108 108 108
13 -2 2 108 108 108
14 -2 2 144 144 144
-15 -1 2 144 144 144
-14 -1 2 108 108 108
-13 -1 2 108 108 108
-12 -1 2 108 108 108
-11 -1 2 108 108 108
10 -1 2 64 64 64
11 -1 2 64 64 64
12 -1 2 108 108 108
13 -1 2 108 108 108
14 -1 2 144 144 144
-15 0 2 144 144 144
-14 0 2 108 108 108
-13 0 2 108 108 108
-12 0 2 108 108 108
-11 0 2 108 108 108
10 0 2 64 64 64
11 0 2 64 64 64
12 0 2 108 108 108
13 0 2 108 108 108
14 0 2 144 144 144
-15 1 2 144 144 144
-14 1 2 108 108 108
-13 1 2 108 108 108
-12 1 2 108 108 108
-11 1 2 108 108 108
12 1 2 108 108 108
13 1 2 108 108 108
14 1 2 144 144 144
-15 2 2 144 144 144
-14 2 2 108 108 108
-13 2 2 108 108 108
-12 2 2 108 108 108
-11 2 2 108 108 108
12 2 2 108 108 108
13 2 2 108 108 108
14 2 2 144 144 144
-15 3 2 144 144 144
-14 3 2 108 108 108
-13 3 2 108 108 108
-12 3 2 108 108 108
-11 3 2 108 108 108
-10 3 2 108 108 108
12 3 2 108 108 108
13 3 2 108 108 108
14 3 2 144 144 144
-15 4 2 144 144 144
-14 4 2 108 108 108
-13 4 2 108 108 108
-12 4 2 64 64 64
-11 4 2 64 64 64
12 4 2 108 108 108
13 4 2 108 108 108
14 4 2 144 144 144
-15 5 2 144 144 144
-14 5 2 108 108 108
-13 5 2 108 108 108
-12 5 2 64 64 64
-11 5 2 64 64 64
12 5 2 108 108 108
13 5 2 108 108 108
14 5 2 144 144 144
-15 6 2 144 144 144
-14 6 2 108 108 108
-13 6 2 108 108 108
12 6 2 108 108 108
13 6 2 108 108 108
14 6 2 144 144 144
-15 7 2 144 144 144
-14 7 2 108 108 108
-13 7 2 108 108 108
12 7 2 108 108 108
13 7 2 108 108 108
14 7 2 144 144 144
-15 8 2 144 144 144
-14 8 2 108 108 108
-13 8 2 108 108 108
12 8 2 108 108 108
13 8 2 108 108 108
14 8 2 144 144 144
-15 9 2 144 144 144
-14 9 2 108 108 108
-13 9 2 108 108 108
12 9 2 108 108 108
13 9 2 108 108 108
14 9 2 144 144 144
-15 10 2 144 144 144
-14 10 2 108 108 108
-13 10 2 108 108 108
-12 10 2 64 64 64
-11 10 2 64 64 64
-1 10 2 64 64 64
0 10 2 64 64 64
10 10 2 64 64 64
11 10 2 64 64 64
12 10 2 108 108 108
13 10 2 108 108 108
14 10 2 144 144 144
-15 11 2 144 144 144
-14 11 2 108 108 108
-13 11 2 108 108 108
-12 11 2 64 64 64
-11 11 2 64 64 64
-1 11 2 64 64 64
0 11 2 64 64 64
10 11 2 64 64 64
11 11 2 64 64 64
12 11 2 108 108 108
13 11 2 108 108 108
14 11 2 144 144 144
-15 12 2 144 144 144
-14 12 2 108 108 108
-13 12 2 108 108 108
-12 12 2 108 108 108
-11 12 2 108 108 108
-10 12 2 108 108 108
-9 12 2 108 108 108
-8 12 2 108 108 108
-7 12 2 108 108 108
-6 12 2 108 108 108
-5 12 2 108 108 108
-4 12 2 108 108 108
-3 12 2 108 108 108
-2 12 2 108 108 108
-1 12 2 108 108 108
0 12 2 108 108 108
1 12 2 108 108 108
2 12 2 108 108 108
3 12 2 108 108 108
4 12 2 108 108 108
5 12 2 108 108 108
6 12 2 108 108 108
7 12 2 108 108 108
8 12 2 108 108 108
9 12 2 108 108 108
10 12 2 108 108 108
11 12 2 108 108 108
12 12 2 108 108 108
13 12 2 108 108 108
14 12 2 144 144 144
-15 13 2 144 144 144
-14 13 2 108 108 108
-13 13 2 108 108 108
-12 13 2 108 108 108
-11 13 2 108 108 108
-10 13 2 108 108 108
-9 13 2 108 108 108
-8 13 2 108 108 108
-7 13 2 108 108 108
-6 13 2 108 108 108
-5 13 2 108 108 108
-4 13 2 108 108 108
-3 13 2 108 108 108
-2 13 2 108 108 108
-1 13 2 108 108 108
0 13 2 108 108 108
1 13 2 108 108 108
2 13 2 108 108 108
3 13 2 108 108 108
4 13 2 108 108 108
5 13 2 108 108 108
6 13 2 108 108 108
7 13 2 108 108 108
8 13 2 108 108 108
9 13 2 108 108 108
10 13 2 108 108 108
11 13 2 108 108 108
12 13 2 108 108 108
13 13 2 108 108 108
14 13 2 144 144 144
-15 14 2 144 144 144
-14 14 2 144 144 144
-13 14 2 144 144 144
-12 14 2 144 144 144
-11 14 2 144 144 144
-10 14 2 144 144 144
-9 14 2 144 144 144
-8 14 2 144 144 144
-7 14 2 144 144 144
-6 14 2 144 144 144
-5 14 2 144 144 144
-4 14 2 144 144 144
-3 14 2 144 144 144
-2 14 2 144 144 144
-1 14 2 144 144 144
0 14 2 144 144 144
1 14 2 144 144 144
2 14 2 144 144 144
3 14 2 144 144 144
4 14 2 144 144 144
5 14 2 144 144 144
6 14 2 144 144 144
7 14 2 144 144 144
8 14 2 144 144 144
9 14 2 144 144 144
10 14 2 144 144 144
11 14 2 144 144 144
12 14 2 144 144 144
13 14 2 144 144 144
14 14 2 144 144 144
-15 -15 3 144 144 144
-14 -15 3 144 144 144
-13 -15 3 144 144 144
-12 -15 3 144 144 144
-11 -15 3 144 144 144
-10 -15 3 144 144 144
-9 -15 3 144 144 144
-8 -15 3 144 144 144
-7 -15 3 144 144 144
-6 -15 3 144 144 144
-5 -15 3 144 144 144
-4 -15 3 144 144 144
-3 -15 3 144 144 144
-2 -15 3 144 144 144
-1 -15 3 144 144 144
0 -15 3 144 144 144
1 -15 3 144 144 144
2 -15 3 144 144 144
3 -15 3 144 144 144
4 -15 3 144 144 144
5 -15 3 144 144 144
6 -15 3 144 144 144
7 -15 3 144 144 144
8 -15 3 144 144 144
9 -15 3 144 144 144
10 -15 3 144 144 144
11 -15 3 144 144 144
12 -15 3 144 144 144
13 -15 3 144 144 144
14 -15 3 144 144 144
-15 -14 3 144 144 144
-14 -14 3 108 108 108
-13 -14 3 108 108 108
-12 -14 3 108 108 108
-11 -14 3 108 108 108
-10 -14 3 108 108 108
-9 -14 3 108 108 108
-8 -14 3 108 108 108
-7 -14 3 108 108 108
-6 -14 3 108 108 108
-5 -14 3 108 108 108
-4 -14 3 108 108 108
-3 -14 3 108 108 108
-2 -14 3 108 108 108
-1 -14 3 108 108 108
0 -14 3 108 108 108
1 -14 3 108 108 108
2 -14 3 108 108 108
3 -14 3 108 108 108
4 -14 3 108 108 108
5 -14 3 108 108 108
6 -14 3 108 108 108
7 -14 3 108 108 108
8 -14 3 108 108 108
9 -14 3 108 108 108
10 -14 3 108 108 108
11 -14 3 108 108 108
12 -14 3 108 108 108
13 -14 3 108 108 108
14 -14 3 144 144 144
-15 -13 3 144 144 144
-14 -13 3 108 108 108
-13 -13 3 108 108 108
-12 -13 3 108 108 108
-11 -13 3 108 108 108
-10 -13 3 108 108 108
-9 -13 3 108 108 108
-8 -13 3 108 108 108
-7 -13 3 108 108 108
-6 -13 3 108 108 108
-5 -13 3 108 108 108
-4 -13 3 108 108 108
-3 -13 3 108 108 108
-2 -13 3 108 108 108
-1 -13 3 108 108 108
0 -13 3 108 108 108
1 -13 3 108 108 108
2 -13 3 108 108 108
3 -13 3 108 108 108
4 -13 3 108 108 108
5 -13 3 108 108 108
6 -13 3 108 108 108
7 -13 3 108 108 108
8 -13 3 108 108 108
9 -13 3 108 108 108
10 -13 3 108 108 108
11 -13 3 108 108 108
12 -13 3 108 108 108
13 -13 3 108 108 108
14 -13 3 144 144 144
-15 -12 3 144 144 144
-14 -12 3 108 108 108
-13 -12 3 108 108 108
-12 -12 3 64 64 64
-11 -12 3 64 64 64
-1 -12 3 64 64 64
0 -12 3 64 64 64
10 -12 3 64 64 64
11 -12 3 64 64 64
12 -12 3 108 108 108
13 -12 3 108 108 108
14 -12 3 144 144 144
-15 -11 3 144 144 144
-14 -11 3 108 108 108
-13 -11 3 108 108 108
-12 -11 3 64 64 64
-11 -11 3 64 64 64
-1 -11 3 64 64 64
0 -11 3 64 64 64
10 -11 3 64 64 64
11 -11 3 64 64 64
12 -11 3 108 108 108
13 -11 3 108 108 108
14 -11 3 144 144 144
-15 -10 3 144 144 144
-14 -10 3 108 108 108
-13 -10 3 108 108 108
12 -10 3 108 108 108
13 -10 3 108 108 108
14 -10 3 144 144 144
-15 -9 3 144 144 144
-14 -9 3 108 108 108
-13 -9 3 108 108 108
12 -9 3 108 108 108
13 -9 3 108 108 108
14 -9 3 144 144 144
-15 -8 3 144 144 144
-14 -8 3 108 108 108
-13 -8 3 108 108 108
12 -8 3 108 108 108
13 -8 3 108 108 108
14 -8 3 144 144 144
-15 -7 3 144 144 144
-14 -7 3 108 108 108
-13 -7 3 108 108 108
12 -7 3 108 108 108
13 -7 3 108 108 108
14 -7 3 144 144 144
-15 -6 3 144 144 144
-14 -6 3 108 108 108
-13 -6 3 108 108 108
-12 -6 3 64 64 64
-11 -6 3 64 64 64
12 -6 3 108 108 108
13 -6 3 108 108 108
14 -6 3 144 144 144
-15 -5 3 144 144 144
-14 -5 3 108 108 108
-13 -5 3 108 108 108
-12 -5 3 64 64 64
-11 -5 3 64 64 64
12 -5 3 108 108 108
13 -5 3 108 108 108
14 -5 3 144 144 144
-15 -4 3 144 144 144
-14 -4 3 108 108 108
-13 -4 3 108 108 108
-12 -4 3 108 108 108
-11 -4 3 108 108 108
-10 -4 3 108 108 108
12 -4 3 108 108 108
13 -4 3 108 108 108
14 -4 3 144 144 144
-15 -3 3 144 144 144
-14 -3 3 108 108 108
-13 -3 3 108 108 108
-12 -3 3 108 108 108
12 -3 3 108 108 108
13 -3 3 108 108 108
14 -3 3 144 144 144
-15 -2 3 144 144 144
-14 -2 3 108 108 108
-13 -2 3 108 108 108
-12 -2 3 108 108 108
12 -2 3 108 108 108
13 -2 3 108 108 108
14 -2 3 144 144 144
-15 -1 3 144 144 144
-14 -1 3 108 108 108
-13 -1 3 108 108 108
-12 -1 3 108 108 108
10 -1 3 64 64 64
11 -1 3 64 64 64
12 -1 3 108 108 108
13 -1 3 108 108 108
14 -1 3 144 144 144
-15 0 3 144 144 144
-14 0 3 108 108 108
-13 0 3 108 108 108
-12 0 3 108 108 108
10 0 3 64 64 64
11 0 3 64 64 64
12 0 3 108 108 108
13 0 3 108 108 108
14 0 3 144 144 144
-15 1 3 144 144 144
-14 1 3 108 108 108
-13 1 3 108 108 108
-12 1 3 108 108 108
12 1 3 108 108 108
13 1 3 108 108 108
14 1 3 144 144 144
-15 2 3 144 144 144
-14 2 3 108 108 108
-13 2 3 108 108 108
-12 2 3 108 108 108
12 2 3 108 108 108
13 2 3 108 108 108
14 2 3 144 144 144
-15 3 3 144 144 144
-14 3 3 108 108 108
-13 3 3 108 108 108
-12 3 3 108 108 108
-11 3 3 108 108 108
-10 3 3 108 108 108
12 3 3 108 108 108
13 3 3 108 108 108
14 3 3 144 144 144
-15 4 3 144 144 144
-14 4 3 108 108 108
-13 4 3 108 108 108
-12 4 3 64 64 64
-11 4 3 64 64 64
12 4 3 108 108 108
13 4 3 108 108 108
14 4 3 144 144 144
-15 5 3 144 144 144
-14 5 3 108 108 108
-13 5 3 108 108 108
-12 5 3 64 64 64
-11 5 3 64 64 64
12 5 3 108 108 108
13 5 3 108 108 108
14 5 3 144 144 144
-15 6 3 144 144 144
-14 6 3 108 108 108
-13 6 3 108 108 108
12 6 3 108 108 108
13 6 3 108 108 108
14 6 3 144 144 144
-15 7 3 144 144 144
-14 7 3 108 108 108
-13 7 3 108 108 108
12 7 3 108 108 108
13 7 3 108 108 108
14 7 3 144 144 144
-15 8 3 144 144 144
-14 8 3 108 108 108
-13 8 3 108 108 108
12 8 3 108 108 108
13 8 3 108 108 108
14 8 3 144 144 144
-15 9 3 144 144 144
-14 9 3 108 108 108
-13 9 3 108 108 108
12 9 3 108 108 108
13 9 3 108 108 108
14 9 3 144 144 144
-15 10 3 144 144 144
-14 10 3 108 108 108
-13 10 3 108 108 108
-12 10 3 64 64 64
-11 10 3 64 64 64
-1 10 3 64 64 64
0 10 3 64 64 64
10 10 3 64 64 64
11 10 3 64 64 64
12 10 3 108 108 108
13 10 3 108 108 108
14 10 3 144 144 144
-15 11 3 144 144 144
-14 11 3 108 108 108
-13 11 3 108 108 108
-12 11 3 64 64 64
-11 11 3 64 64 64
-1 11 3 64 64 64
0 11 3 64 64 64
10 11 3 64 64 64
11 11 3 64 64 64
12 11 3 108 108 108
13 11 3 108 108 108
14 11 3 144 144 144
-15 12 3 144 144 144
-14 12 3 108 108 108
-13 12 3 108 108 108
-12 12 3 108 108 108
-11 12 3 108 108 108
-10 12 3 108 108 108
-9 12 3 108 108 108
-8 12 3 108 108 108
-7 12 3 108 108 108
-6 12 3 108 108 108
-5 12 3 108 108 108
-4 12 3 108 108 108
-3 12 3 108 108 108
-2 12 3 108 108 108
-1 12 3 108 108 108
0 12 3 108 108 108
1 12 3 108 108 108
2 12 3 108 108 108
3 12 3 108 108 108
4 12 3 108 108 108
5 12 3 108 108 108
6 12 3 108 108 108
7 12 3 108 108 108
8 12 3 108 108 108
9 12 3 108 108 108
10 12 3 108 108 108
11 12 3 108 108 108
12 12 3 108 108 108
13 12 3 108 108 108
14 12 3 144 144 144
-15 13 3 144 144 144
-14 13 3 108 108 108
-13 13 3 108 108 108
-12 13 3 108 108 108
-11 13 3 108 108 108
-10 13 3 108 108 108
-9 13 3 108 108 108
-8 13 3 108 108 108
-7 13 3 108 108 108
-6 13 3 108 108 108
-5 13 3 108 108 108
-4 13 3 108 108 108
-3 13 3 108 108 108
-2 13 3 108 108 108
-1 13 3 108 108 108
0 13 3 108 108 108
1 13 3 108 108 108
2 13 3 108 108 108
3 13 3 108 108 108
4 13 3 108 108 108
5 13 3 108 108 108
6 13 3 108 108 108
7 13 3 108 108 108
8 13 3 108 108 108
9 13 3 108 108 108
10 13 3 108 108 108
11 13 3 108 108 108
12 13 3 108 108 108
13 13 3 108 108 108
14 13 3 144 144 144
-15 14 3 144 144 144
-14 14 3 144 144 144
-13 14 3 144 144 144
-12 14 3 144 144 144
-11 14 3 144 144 144
-10 14 3 144 144 144
-9 14 3 144 144 144
-8 14 3 144 144 144
-7 14 3 144 144 144
-6 14 3 144 144 144
-5 14 3 144 144 144
-4 14 3 144 144 144
-3 14 3 144 144 144
-2 14 3 144 144 144
-1 14 3 144 144 144
0 14 3 144 144 144
1 14 3 144 144 144
2 14 3 144 144 144
3 14 3 144 144 144
4 14 3 144 144 144
5 14 3 144 144 144
6 14 3 144 144 144
7 14 3 144 144 144
8 14 3 144 144 144
9 14 3 144 144 144
10 14 3 144 144 144
11 14 3 144 144 144
12 14 3 144 144 144
13 14 3 144 144 144
14 14 3 144 144 144
-15 -15 4 144 144 144
-14 -15 4 144 144 144
-13 -15 4 144 144 144
-12 -15 4 144 144 144
-11 -15 4 144 144 144
-10 -15 4 144 144 144
-9 -15 4 144 144 144
-8 -15 4 144 144 144
-7 -15 4 144 144 144
-6 -15 4 144 144 144
-5 -15 4 144 144 144
-4 -15 4 144 144 144
-3 -15 4 144 144 144
-2 -15 4 144 144 144
-1 -15 4 144 144 144
0 -15 4 144 144 144
1 -15 4 144 144 144
2 -15 4 144 144 144
3 -15 4 144 144 144
4 -15 4 144 144 144
5 -15 4 144 144 144
6 -15 4 144 144 144
7 -15 4 144 144 144
8 -15 4 144 144 144
9 -15 4 144 144 144
10 -15 4 144 144 144
11 -15 4 144 144 144
12 -15 4 144 144 144
13 -15 4 144 144 144
14 -15 4 144 144 144
-15 -14 4 144 144 144
-14 -14 4 108 108 108
-13 -14 4 108 108 108
-12 -14 4 108 108 108
-11 -14 4 108 108 108
-10 -14 4 108 108 108
-9 -14 4 108 108 108
-8 -14 4 108 108 108
-7 -14 4 108 108 108
-6 -14 4 108 108 108
-5 -14 4 108 108 108
-4 -14 4 108 108 108
-3 -14 4 108 108 108
-2 -14 4 108 108 108
-1 -14 4 108 108 108
0 -14 4 108 108 108
1 -14 4 108 108 108
2 -14 4 108 108 108
3 -14 4 108 108 108
4 -14 4 108 108 108
5 -14 4 108 108 108
6 -14 4 108 108 108
7 -14 4 108 108 108
8 -14 4 108 108 108
9 -14 4 108 108 108
10 -14 4 108 108 108
11 -14 4 108 108 108
12 -14 4 108 108 108
13 -14 4 108 108 108
14 -14 4 144 144 144
-15 -13 4 144 144 144
-14 -13 4 108 108 108
-13 -13 4 108 108 108
-12 -13 4 108 108 108
-11 -13 4 108 108 108
-10 -13 4 108 108 108
-9 -13 4 108 108 108
-8 -13 4 108 108 108
-7 -13 4 108 108 108
-6 -13 4 108 108 108
-5 -13 4 108 108 108
-4 -13 4 108 108 108
-3 -13 4 108 108 108
-2 -13 4 108 108 108
-1 -13 4 108 108 108
0 -13 4 108 108 108
1 -13 4 108 108 108
2 -13 4 108 108 108
3 -13 4 108 108 108
4 -13 4 108 108 108
5 -13 4 108 108 108
6 -13 4 108 108 108
7 -13 4 108 108 108
8 -13 4 108 108 108
9 -13 4 108 108 108
10 -13 4 108 108 108
11 -13 4 108 108 108
12 -13 4 108 108 108
13 -13 4 108 108 108
14 -13 4 144 144 144
-15 -12 4 144 144 144
-14 -12 4 108 108 108
-13 -12 4 108 108 108
-12 -12 4 64 64 64
-11 -12 4 64 64 64
-6 -12 4 156 32 32
-1 -12 4 64 64 64
0 -12 4 64 64 64
5 -12 4 156 32 32
10 -12 4 64 64 64
11 -12 4 64 64 64
12 -12 4 108 108 108
13 -12 4 108 108 108
14 -12 4 144 144 144
-15 -11 4 144 144 144
-14 -11 4 108 108 108
-13 -11 4 108 108 108
-12 -11 4 64 64 64
-11 -11 4 64 64 64
-1 -11 4 64 64 64
0 -11 4 64 64 64
10 -11 4 64 64 64
11 -11 4 64 64 64
12 -11 4 108 108 108
13 -11 4 108 108 108
14 -11 4 144 144 144
-15 -10 4 144 144 144
-14 -10 4 108 108 108
-13 -10 4 108 108 108
12 -10 4 108 108 108
13 -10 4 108 108 108
14 -10 4 144 144 144
-15 -9 4 144 144 144
-14 -9 4 108 108 108
-13 -9 4 108 108 108
12 -9 4 108 108 108
13 -9 4 108 108 108
14 -9 4 144 144 144
-15 -8 4 144 144 144
-14 -8 4 108 108 108
-13 -8 4 108 108 108
12 -8 4 108 108 108
13 -8 4 108 108 108
14 -8 4 144 144 144
-15 -7 4 144 144 144
-14 -7 4 108 108 108
-13 -7 4 108 108 108
12 -7 4 108 108 108
13 -7 4 108 108 108
14 -7 4 144 144 144
-15 -6 4 144 144 144
-14 -6 4 108 108 108
-13 -6 4 108 108 108
-12 -6 4 64 64 64
-11 -6 4 64 64 64
11 -6 4 156 32 32
12 -6 4 108 108 108
13 -6 4 108 108 108
14 -6 4 144 144 144
-15 -5 4 144 144 144
-14 -5 4 108 108 108
-13 -5 4 108 108 108
-12 -5 4 64 64 64
-11 -5 4 64 64 64
12 -5 4 108 108 108
13 -5 4 108 108 108
14 -5 4 144 144 144
-15 -4 4 144 144 144
-14 -4 4 108 108 108
-13 -4 4 108 108 108
-12 -4 4 108 108 108
-11 -4 4 108 108 108
-10 -4 4 108 108 108
12 -4 4 108 108 108
13 -4 4 108 108 108
14 -4 4 144 144 144
-15 -3 4 144 144 144
-14 -3 4 108 108 108
-13 -3 4 108 108 108
12 -3 4 108 108 108
13 -3 4 108 108 108
14 -3 4 144 144 144
-15 -2 4 144 144 144
-14 -2 4 108 108 108
-13 -2 4 108 108 108
12 -2 4 108 108 108
13 -2 4 108 108 108
14 -2 4 144 144 144
-15 -1 4 144 144 144
-14 -1 4 108 108 108
-13 -1 4 108 108 108
10 -1 4 64 64 64
11 -1 4 64 64 64
12 -1 4 108 108 108
13 -1 4 108 108 108
14 -1 4 144 144 144
-15 0 4 144 144 144
-14 0 4 108 108 108
-13 0 4 108 108 108
10 0 4 64 64 64
11 0 4 64 64 64
12 0 4 108 108 108
13 0 4 108 108 108
14 0 4 144 144 144
-15 1 4 144 144 144
-14 1 4 108 108 108
-13 1 4 108 108 108
12 1 4 108 108 108
13 1 4 108 108 108
14 1 4 144 144 144
-15 2 4 144 144 144
-14 2 4 108 108 108
-13 2 4 108 108 108
12 2 4 108 108 108
13 2 4 108 108 108
14 2 4 144 144 144
-15 3 4 144 144 144
-14 3 4 108 108 108
-13 3 4 108 108 108
-12 3 4 108 108 108
-11 3 4 108 108 108
-10 3 4 108 108 108
12 3 4 108 108 108
13 3 4 108 108 108
14 3 4 144 144 144
-15 4 4 144 144 144
-14 4 4 108 108 108
-13 4 4 108 108 108
-12 4 4 64 64 64
-11 4 4 64 64 64
12 4 4 108 108 108
13 4 4 108 108 108
14 4 4 144 144 144
-15 5 4 144 144 144
-14 5 4 108 108 108
-13 5 4 108 108 108
-12 5 4 64 64 64
-11 5 4 64 64 64
11 5 4 156 32 32
12 5 4 108 108 108
13 5 4 108 108 108
14 5 4 144 144 144
-15 6 4 144 144 144
-14 6 4 108 108 108
-13 6 4 108 108 108
12 6 4 108 108 108
13 6 4 108 108 108
14 6 4 144 144 144
-15 7 4 144 144 144
-14 7 4 108 108 108
-13 7 4 108 108 108
12 7 4 108 108 108
13 7 4 108 108 108
14 7 4 144 144 144
-15 8 4 144 144 144
-14 8 4 108 108 108
-13 8 4 108 108 108
12 8 4 108 108 108
13 8 4 108 108 108
14 8 4 144 144 144
-15 9 4 144 144 144
-14 9 4 108 108 108
-13 9 4 108 108 108
12 9 4 108 108 108
13 9 4 108 108 108
14 9 4 144 144 144
-15 10 4 144 144 144
-14 10 4 108 108 108
-13 10 4 108 108 108
-12 10 4 64 64 64
-11 10 4 64 64 64
-1 10 4 64 64 64
0 10 4 64 64 64
10 10 4 64 64 64
11 10 4 64 64 64
12 10 4 108 108 108
13 10 4 108 108 108
14 10 4 144 144 144
-15 11 4 144 144 144
-14 11 4 108 108 108
-13 11 4 108 108 108
-12 11 4 64 64 64
-11 11 4 64 64 64
-6 11 4 156 32 32
-1 11 4 64 64 64
0 11 4 64 64 64
5 11 4 156 32 32
10 11 4 64 64 64
11 11 4 64 64 64
12 11 4 108 108 108
13 11 4 108 108 108
14 11 4 144 144 144
-15 12 4 144 144 144
-14 12 4 108 108 108
-13 12 4 108 108 108
-12 12 4 108 108 108
-11 12 4 108 108 108
-10 12 4 108 108 108
-9 12 4 108 108 108
-8 12 4 108 108 108
-7 12 4 108 108 108
-6 12 4 108 108 108
-5 12 4 108 108 108
-4 12 4 108 108 108
-3 12 4 108 108 108
-2 12 4 108 108 108
-1 12 4 108 108 108
0 12 4 108 108 108
1 12 4 108 108 108
2 12 4 108 108 108
3 12 4 108 108 108
4 12 4 108 108 108
5 12 4 108 108 108
6 12 4 108 108 108
7 12 4 108 108 108
8 12 4 108 108 108
9 12 4 108 108 108
10 12 4 108 108 108
11 12 4 108 108 108
12 12 4 108 108 108
13 12 4 108 108 108
14 12 4 144 144 144
-15 13 4 144 144 144
-14 13 4 108 108 108
-13 13 4 108 108 108
-12 13 4 108 108 108
-11 13 4 108 108 108
-10 13 4 108 108 108
-9 13 4 108 108 108
-8 13 4 108 108 108
-7 13 4 108 108 108
-6 13 4 108 108 108
-5 13 4 108 108 108
-4 13 4 108 108 108
-3 13 4 108 108 108
-2 13 4 108 108 108
-1 13 4 108 108 108
0 13 4 108 108 108
1 13 4 108 108 108
2 13 4 108 108 108
3 13 4 108 108 108
4 13 4 108 108 108
5 13 4 108 108 108
6 13 4 108 108 108
7 13 4 108 108 108
8 13 4 108 108 108
9 13 4 108 108 108
10 13 4 108 108 108
11 13 4 108 108 108
12 13 4 108 108 108
13 13 4 108 108 108
14 13 4 144 144 144
-15 14 4 144 144 144
-14 14 4 144 144 144
-13 14 4 144 144 144
-12 14 4 144 144 144
-11 14 4 144 144 144
-10 14 4 144 144 144
-9 14 4 144 144 144
-8 14 4 144 144 144
-7 14 4 144 144 144
-6 14 4 144 144 144
-5 14 4 144 144 144
-4 14 4 144 144 144
-3 14 4 144 144 144
-2 14 4 144 144 144
-1 14 4 144 144 144
0 14 4 144 144 144
1 14 4 144 144 144
2 14 4 144 144 144
3 14 4 144 144 144
4 14 4 144 144 144
5 14 4 144 144 144
6 14 4 144 144 144
7 14 4 144 144 144
8 14 4 144 144 144
9 14 4 144 144 144
10 14 4 144 144 144
11 14 4 144 144 144
12 14 4 144 144 144
13 14 4 144 144 144
14 14 4 144 144 144
-15 -15 5 144 144 144
-14 -15 5 144 144 144
-13 -15 5 144 144 144
-12 -15 5 144 144 144
-11 -15 5 144 144 144
-10 -15 5 144 144 144
-9 -15 5 144 144 144
-8 -15 5 144 144 144
-7 -15 5 144 144 144
-6 -15 5 144 144 144
-5 -15 5 144 144 144
-4 -15 5 144 144 144
-3 -15 5 144 144 144
-2 -15 5 144 144 144
-1 -15 5 144 144 144
0 -15 5 144 144 144
1 -15 5 144 144 144
2 -15 5 144 144 144
3 -15 5 144 144 144
4 -15 5 144 144 144
5 -15 5 144 144 144
6 -15 5 144 144 144
7 -15 5 144 144 144
8 -15 5 144 144 144
9 -15 5 144 144 144
10 -15 5 144 144 144
11 -15 5 144 144 144
12 -15 5 144 144 144
13 -15 5 144 144 144
14 -15 5 144 144 144
-15 -14 5 144 144 144
-14 -14 5 108 108 108
-13 -14 5 108 108 108
-12 -14 5 108 108 108
-11 -14 5 108 108 108
-10 -14 5 108 108 108
-9 -14 5 108 108 108
-8 -14 5 108 108 108
-7 -14 5 108 108 108
-6 -14 5 108 108 108
-5 -14 5 108 108 108
-4 -14 5 108 108 108
-3 -14 5 108 108 108
-2 -14 5 108 108 108
-1 -14 5 108 108 108
0 -14 5 108 108 108
1 -14 5 108 108 108
2 -14 5 108 108 108
3 -14 5 108 108 108
4 -14 5 108 108 108
5 -14 5 108 108 108
6 -14 5 108 108 108
7 -14 5 108 108 108
8 -14 5 108 108 108
9 -14 5 108 108 108
10 -14 5 108 108 108
11 -14 5 108 108 108
12 -14 5 108 108 108
13 -14 5 108 108 108
14 -14 5 144 144 144
-15 -13 5 144 144 144
-14 -13 5 108 108 108
-13 -13 5 108 108 108
-12 -13 5 108 108 108
-11 -13 5 108 108 108
-10 -13 5 108 108 108
-9 -13 5 108 108 108
-8 -13 5 108 108 108
-7 -13 5 108 108 108
-6 -13 5 108 108 108
-5 -13 5 108 108 108
-4 -13 5 108 108 108
-3 -13 5 108 108 108
-2 -13 5 108 108 108
-1 -13 5 108 108 108
0 -13 5 108 108 108
1 -13 5 108 108 108
2 -13 5 108 108 108
3 -13 5 108 108 108
4 -13 5 108 108 108
5 -13 5 108 108 108
6 -13 5 108 108 108
7 -13 5 108 108 108
8 -13 5 108 108 108
9 -13 5 108 108 108
10 -13 5 108 108 108
11 -13 5 108 108 108
12 -13 5 108 108 108
13 -13 5 108 108 108
14 -13 5 144 144 144
-15 -12 5 144 144 144
-14 -12 5 108 108 108
-13 -12 5 108 108 108
-12 -12 5 64 64 64
-11 -12 5 64 64 64
-7 -12 5 156 32 32
-6 -12 5 156 32 32
-5 -12 5 156 32 32
-1 -12 5 64 64 64
0 -12 5 64 64 64
4 -12 5 156 32 32
5 -12 5 156 32 32
6 -12 5 156 32 32
10 -12 5 64 64 64
11 -12 5 64 64 64
12 -12 5 108 108 108
13 -12 5 108 108 108
14 -12 5 144 144 144
-15 -11 5 144 144 144
-14 -11 5 108 108 108
-13 -11 5 108 108 108
-12 -11 5 64 64 64
-11 -11 5 64 64 64
-1 -11 5 64 64 64
0 -11 5 64 64 64
10 -11 5 64 64 64
11 -11 5 64 64 64
12 -11 5 108 108 108
13 -11 5 108 108 108
14 -11 5 144 144 144
-15 -10 5 144 144 144
-14 -10 5 108 108 108
-13 -10 5 108 108 108
12 -10 5 108 108 108
13 -10 5 108 108 108
14 -10 5 144 144 144
-15 -9 5 144 144 144
-14 -9 5 108 108 108
-13 -9 5 108 108 108
12 -9 5 108 108 108
13 -9 5 108 108 108
14 -9 5 144 144 144
-15 -8 5 144 144 144
-14 -8 5 108 108 108
-13 -8 5 108 108 108
12 -8 5 108 108 108
13 -8 5 108 108 108
14 -8 5 144 144 144
-15 -7 5 144 144 144
-14 -7 5 108 108 108
-13 -7 5 108 108 108
11 -7 5 156 32 32
12 -7 5 108 108 108
13 -7 5 108 108 108
14 -7 5 144 144 144
-15 -6 5 144 144 144
-14 -6 5 108 108 108
-13 -6 5 108 108 108
-12 -6 5 64 64 64
-11 -6 5 64 64 64
11 -6 5 156 32 32
12 -6 5 108 108 108
13 -6 5 108 108 108
14 -6 5 144 144 144
-15 -5 5 144 144 144
-14 -5 5 108 108 108
-13 -5 5 108 108 108
-12 -5 5 64 64 64
-11 -5 5 64 64 64
11 -5 5 156 32 32
12 -5 5 108 108 108
13 -5 5 108 108 108
14 -5 5 144 144 144
-15 -4 5 144 144 144
-14 -4 5 108 108 108
-13 -4 5 108 108 108
-12 -4 5 108 108 108
-11 -4 5 108 108 108
-10 -4 5 108 108 108
12 -4 5 108 108 108
13 -4 5 108 108 108
14 -4 5 144 144 144
-15 -3 5 144 144 144
-14 -3 5 108 108 108
-13 -3 5 108 108 108
12 -3 5 108 108 108
13 -3 5 108 108 108
14 -3 5 144 144 144
-15 -2 5 144 144 144
-14 -2 5 108 108 108
-13 -2 5 108 108 108
12 -2 5 108 108 108
13 -2 5 108 108 108
14 -2 5 144 144 144
-15 -1 5 144 144 144
-14 -1 5 108 108 108
-13 -1 5 108 108 108
10 -1 5 64 64 64
11 -1 5 64 64 64
12 -1 5 108 108 108
13 -1 5 108 108 108
14 -1 5 144 144 144
-15 0 5 144 144 144
-14 0 5 108 108 108
-13 0 5 108 108 108
10 0 5 64 64 64
11 0 5 64 64 64
12 0 5 108 108 108
13 0 5 108 108 108
14 0 5 144 144 144
-15 1 5 144 144 144
-14 1 5 108 108 108
-13 1 5 108 108 108
12 1 5 108 108 108
13 1 5 108 108 108
14 1 5 144 144 144
-15 2 5 144 144 144
-14 2 5 108 108 108
-13 2 5 108 108 108
12 2 5 108 108 108
13 2 5 108 108 108
14 2 5 144 144 144
-15 3 5 144 144 144
-14 3 5 108 108 108
-13 3 5 108 108 108
-12 3 5 108 108 108
-11 3 5 108 108 108
-10 3 5 108 108 108
12 3 5 108 108 108
13 3 5 108 108 108
14 3 5 144 144 144
-15 4 5 144 144 144
-14 4 5 108 108 108
-13 4 5 108 108 108
-12 4 5 64 64 64
-11 4 5 64 64 64
11 4 5 156 32 32
12 4 5 108 108 108
13 4 5 108 108 108
14 4 5 144 144 144
-15 5 5 144 144 144
-14 5 5 108 108 108
-13 5 5 108 108 108
-12 5 5 64 64 64
-11 5 5 64 64 64
11 5 5 156 32 32
12 5 5 108 108 108
13 5 5 108 108 108
14 5 5 144 144 144
-15 6 5 144 144 144
-14 6 5 108 108 108
-13 6 5 108 108 108
11 6 5 156 32 32
12 6 5 108 108 108
13 6 5 108 108 108
14 6 5 144 144 144
-15 7 5 144 144 144
-14 7 5 108 108 108
-13 7 5 108 108 108
12 7 5 108 108 108
13 7 5 108 108 108
14 7 5 144 144 144
-15 8 5 144 144 144
-14 8 5 108 108 108
-13 8 5 108 108 108
12 8 5 108 108 108
13 8 5 108 108 108
14 8 5 144 144 144
-15 9 5 144 144 144
-14 9 5 108 108 108
-13 9 5 108 108 108
12 9 5 108 108 108
13 9 5 108 108 108
14 9 5 144 144 144
-15 10 5 144 144 144
-14 10 5 108 108 108
-13 10 5 108 108 108
-12 10 5 64 64 64
-11 10 5 64 64 64
-1 10 5 64 64 64
0 10 5 64 64 64
10 10 5 64 64 64
11 10 5 64 64 64
12 10 5 108 108 108
13 10 5 108 108 108
14 10 5 144 144 144
-15 11 5 144 144 144
-14 11 5 108 108 108
-13 11 5 108 108 108
-12 11 5 64 64 64
-11 11 5 64 64 64
-7 11 5 156 32 32
-6 11 5 156 32 32
-5 11 5 156 32 32
-1 11 5 64 64 64
0 11 5 64 64 64
4 11 5 156 32 32
5 11 5 156 32 32
6 11 5 156 32 32
10 11 5 64 64 64
11 11 5 64 64 64
12 11 5 108 108 108
13 11 5 108 108 108
14 11 5 144 144 144
-15 12 5 144 144 144
-14 12 5 108 108 108
-13 12 5 108 108 108
-12 12 5 108 108 108
-11 12 5 108 108 108
-10 12 5 108 108 108
-9 12 5 108 108 108
-8 12 5 108 108 108
-7 12 5 108 108 108
-6 12 5 108 108 108
-5 12 5 108 108 108
-4 12 5 108 108 108
-3 12 5 108 108 108
-2 12 5 108 108 108
-1 12 5 108 108 108
0 12 5 108 108 108
1 12 5 108 108 108
2 12 5 108 108 108
3 12 5 108 108 108
4 12 5 108 108 108
5 12 5 108 108 108
6 12 5 108 108 108
7 12 5 108 108 108
8 12 5 108 108 108
9 12 5 108 108 108
10 12 5 108 108 108
11 12 5 108 108 108
12 12 5 108 108 108
13 12 5 108 108 108
14 12 5 144 144 144
-15 13 5 144 144 144
-14 13 5 108 108 108
-13 13 5 108 108 108
-12 13 5 108 108 108
-11 13 5 108 108 108
-10 13 5 108 108 108
-9 13 5 108 108 108
-8 13 5 108 108 108
-7 13 5 108 108 108
-6 13 5 108 108 108
-5 13 5 108 108 108
-4 13 5 108 108 108
-3 13 5 108 108 108
-2 13 5 108 108 108
-1 13 5 108 108 108
0 13 5 108 108 108
1 13 5 108 108 108
2 13 5 108 108 108
3 13 5 108 108 108
4 13 5 108 108 108
5 13 5 108 108 108
6 13 5 108 108 108
7 13 5 108 108 108
8 13 5 108 108 108
9 13 5 108 108 108
10 13 5 108 108 108
11 13 5 108 108 108
12 13 5 108 108 108
13 13 5 108 108 108
14 13 5 144 144 144
-15 14 5 144 144 144
-14 14 5 144 144 144
-13 14 5 144 144 144
-12 14 5 144 144 144
-11 14 5 144 144 144
-10 14 5 144 144 144
-9 14 5 144 144 144
-8 14 5 144 144 144
-7 14 5 144 144 144
-6 14 5 144 144 144
-5 14 5 144 144 144
-4 14 5 144 144 144
-3 14 5 144 144 144
-2 14 5 144 144 144
-1 14 5 144 144 144
0 14 5 144 144 144
1 14 5 144 144 144
2 14 5 144 144 144
3 14 5 144 144 144
4 14 5 144 144 144
5 14 5 144 144 144
6 14 5 144 144 144
7 14 5 144 144 144
8 14 5 144 144 144
9 14 5 144 144 144
10 14 5 144 144 144
11 14 5 144 144 144
12 14 5 144 144 144
13 14 5 144 144 144
14 14 5 144 144 144
-15 -15 6 144 144 144
-14 -15 6 144 144 144
-13 -15 6 144 144 144
-12 -15 6 144 144 144
-11 -15 6 144 144 144
-10 -15 6 144 144 144
-9 -15 6 144 144 144
-8 -15 6 144 144 144
-7 -15 6 144 144 144
-6 -15 6 144 144 144
-5 -15 6 144 144 144
-4 -15 6 144 144 144
-3 -15 6 144 144 144
-2 -15 6 144 144 144
-1 -15 6 144 144 144
0 -15 6 144 144 144
1 -15 6 144 144 144
2 -15 6 144 144 144
3 -15 6 144 144 144
4 -15 6 144 144 144
5 -15 6 144 144 144
6 -15 6 144 144 144
7 -15 6 144 144 144
8 -15 6 144 144 144
9 -15 6 144 144 144
10 -15 6 144 144 144
11 -15 6 144 144 144
12 -15 6 144 144 144
13 -15 6 144 144 144
14 -15 6 144 144 144
-15 -14 6 144 144 144
-14 -14 6 108 108 108
-13 -14 6 108 108 108
-12 -14 6 108 108 108
-11 -14 6 108 108 108
-10 -14 6 108 108 108
-9 -14 6 108 108 108
-8 -14 6 108 108 108
-7 -14 6 108 108 108
-6 -14 6 108 108 108
-5 -14 6 108 108 108
-4 -14 6 108 108 108
-3 -14 6 108 108 108
-2 -14 6 108 108 108
-1 -14 6 108 108 108
0 -14 6 108 108 108
1 -14 6 108 108 108
2 -14 6 108 108 108
3 -14 6 108 108 108
4 -14 6 108 108 108
5 -14 6 108 108 108
6 -14 6 108 108 108
7 -14 6 108 108 108
8 -14 6 108 108 108
9 -14 6 108 108 108
10 -14 6 108 108 108
11 -14 6 108 108 108
12 -14 6 108 108 108
13 -14 6 108 108 108
14 -14 6 144 144 144
-15 -13 6 144 144 144
-14 -13 6 108 108 108
-13 -13 6 108 108 108
-12 -13 6 108 108 108
-11 -13 6 108 108 108
-10 -13 6 108 108 108
-9 -13 6 108 108 108
-8 -13 6 108 108 108
-7 -13 6 108 108 108
-6 -13 6 108 108 108
-5 -13 6 108 108 108
-4 -13 6 108 108 108
-3 -13 6 108 108 108
-2 -13 6 108 108 108
-1 -13 6 108 108 108
0 -13 6 108 108 108
1 -13 6 108 108 108
2 -13 6 108 108 108
3 -13 6 108 108 108
4 -13 6 108 108 108
5 -13 6 108 108 108
6 -13 6 108 108 108
7 -13 6 108 108 108
8 -13 6 108 108 108
9 -13 6 108 108 108
10 -13 6 108 108 108
11 -13 6 108 108 108
12 -13 6 108 108 108
13 -13 6 108 108 108
14 -13 6 144 144 144
-15 -12 6 144 144 144
-14 -12 6 108 108 108
-13 -12 6 108 108 108
-12 -12 6 64 64 64
-11 -12 6 64 64 64
-8 -12 6 156 32 32
-7 -12 6 156 32 32
-6 -12 6 176 60 60
-5 -12 6 156 32 32
-4 -12 6 156 32 32
-1 -12 6 64 64 64
0 -12 6 64 64 64
3 -12 6 156 32 32
4 -12 6 156 32 32
5 -12 6 176 60 60
6 -12 6 156 32 32
7 -12 6 156 32 32
10 -12 6 64 64 64
11 -12 6 64 64 64
12 -12 6 108 108 108
13 -12 6 108 108 108
14 -12 6 144 144 144
-15 -11 6 144 144 144
-14 -11 6 108 108 108
-13 -11 6 108 108 108
-12 -11 6 64 64 64
-11 -11 6 64 64 64
-1 -11 6 64 64 64
0 -11 6 64 64 64
10 -11 6 64 64 64
11 -11 6 64 64 64
12 -11 6 108 108 108
13 -11 6 108 108 108
14 -11 6 144 144 144
-15 -10 6 144 144 144
-14 -10 6 108 108 108
-13 -10 6 108 108 108
12 -10 6 108 108 108
13 -10 6 108 108 108
14 -10 6 144 144 144
-15 -9 6 144 144 144
-14 -9 6 108 108 108
-13 -9 6 108 108 108
12 -9 6 108 108 108
13 -9 6 108 108 108
14 -9 6 144 144 144
-15 -8 6 144 144 144
-14 -8 6 108 108 108
-13 -8 6 108 108 108
11 -8 6 156 32 32
12 -8 6 108 108 108
13 -8 6 108 108 108
14 -8 6 144 144 144
-15 -7 6 144 144 144
-14 -7 6 108 108 108
-13 -7 6 108 108 108
11 -7 6 156 32 32
12 -7 6 108 108 108
13 -7 6 108 108 108
14 -7 6 144 144 144
-15 -6 6 144 144 144
-14 -6 6 108 108 108
-13 -6 6 108 108 108
-12 -6 6 64 64 64
-11 -6 6 64 64 64
11 -6 6 176 60 60
12 -6 6 108 108 108
13 -6 6 108 108 108
14 -6 6 144 144 144
-15 -5 6 144 144 144
-14 -5 6 108 108 108
-13 -5 6 108 108 108
-12 -5 6 64 64 64
-11 -5 6 64 64 64
11 -5 6 156 32 32
12 -5 6 108 108 108
13 -5 6 108 108 108
14 -5 6 144 144 144
-15 -4 6 144 144 144
-14 -4 6 108 108 108
-13 -4 6 108 108 108
-12 -4 6 108 108 108
-11 -4 6 108 108 108
-10 -4 6 108 108 108
11 -4 6 156 32 32
12 -4 6 108 108 108
13 -4 6 108 108 108
14 -4 6 144 144 144
-15 -3 6 144 144 144
-14 -3 6 108 108 108
-13 -3 6 108 108 108
12 -3 6 108 108 108
13 -3 6 108 108 108
14 -3 6 144 144 144
-15 -2 6 144 144 144
-14 -2 6 108 108 108
-13 -2 6 108 108 108
12 -2 6 108 108 108
13 -2 6 108 108 108
14 -2 6 144 144 144
-15 -1 6 144 144 144
-14 -1 6 108 108 108
-13 -1 6 108 108 108
10 -1 6 64 64 64
11 -1 6 64 64 64
12 -1 6 108 108 108
13 -1 6 108 108 108
14 -1 6 144 144 144
-15 0 6 144 144 144
-14 0 6 108 108 108
-13 0 6 108 108 108
10 0 6 64 64 64
11 0 6 64 64 64
12 0 6 108 108 108
13 0 6 108 108 108
14 0 6 144 144 144
-15 1 6 144 144 144
-14 1 6 108 108 108
-13 1 6 108 108 108
12 1 6 108 108 108
13 1 6 108 108 108
14 1 6 144 144 144
-15 2 6 144 144 144
-14 2 6 108 108 108
-13 2 6 108 108 108
12 2 6 108 108 108
13 2 6 108 108 108
14 2 6 144 144 144
-15 3 6 144 144 144
-14 3 6 108 108 108
-13 3 6 108 108 108
-12 3 6 108 108 108
-11 3 6 108 108 108
-10 3 6 108 108 108
11 3 6 156 32 32
12 3 6 108 108 108
13 3 6 108 108 108
14 3 6 144 144 144
-15 4 6 144 144 144
-14 4 6 108 108 108
-13 4 6 108 108 108
-12 4 6 64 64 64
-11 4 6 64 64 64
11 4 6 156 32 32
12 4 6 108 108 108
13 4 6 108 108 108
14 4 6 144 144 144
-15 5 6 144 144 144
-14 5 6 108 108 108
-13 5 6 108 108 108
-12 5 6 64 64 64
-11 5 6 64 64 64
11 5 6 176 60 60
12 5 6 108 108 108
13 5 6 108 108 108
14 5 6 144 144 144
-15 6 6 144 144 144
-14 6 6 108 108 108
-13 6 6 108 108 108
11 6 6 156 32 32
12 6 6 108 108 108
13 6 6 108 108 108
14 6 6 144 144 144
-15 7 6 144 144 144
-14 7 6 108 108 108
-13 7 6 108 108 108
11 7 6 156 32 32
12 7 6 108 108 108
13 7 6 108 108 108
14 7 6 144 144 144
-15 8 6 144 144 144
-14 8 6 108 108 108
-13 8 6 108 108 108
12 8 6 108 108 108
13 8 6 108 108 108
14 8 6 144 144 144
-15 9 6 144 144 144
-14 9 6 108 108 108
-13 9 6 108 108 108
12 9 6 108 108 108
13 9 6 108 108 108
14 9 6 144 144 144
-15 10 6 144 144 144
-14 10 6 108 108 108
-13 10 6 108 108 108
-12 10 6 64 64 64
-11 10 6 64 64 64
-1 10 6 64 64 64
0 10 6 64 64 64
10 10 6 64 64 64
11 10 6 64 64 64
12 10 6 108 108 108
13 10 6 108 108 108
14 10 6 144 144 144
-15 11 6 144 144 144
-14 11 6 108 108 108
-13 11 6 108 108 108
-12 11 6 64 64 64
-11 11 6 64 64 64
-8 11 6 156 32 32
-7 11 6 156 32 32
-6 11 6 176 60 60
-5 11 6 156 32 32
-4 11 6 156 32 32
-1 11 6 64 64 64
0 11 6 64 64 64
3 11 6 156 32 32
4 11 6 156 32 32
5 11 6 176 60 60
6 11 6 156 32 32
7 11 6 156 32 32
10 11 6 64 64 64
11 11 6 64 64 64
12 11 6 108 108 108
13 11 6 108 108 108
14 11 6 144 144 144
-15 12 6 144 144 144
-14 12 6 108 108 108
-13 12 6 108 108 108
-12 12 6 108 108 108
-11 12 6 108 108 108
-10 12 6 108 108 108
-9 12 6 108 108 108
-8 12 6 108 108 108
-7 12 6 108 108 108
-6 12 6 108 108 108
-5 12 6 108 108 108
-4 12 6 108 108 108
-3 12 6 108 108 108
-2 12 6 108 108 108
-1 12 6 108 108 108
0 12 6 108 108 108
1 12 6 108 108 108
2 12 6 108 108 108
3 12 6 108 108 108
4 12 6 108 108 108
5 12 6 108 108 108
6 12 6 108 108 108
7 12 6 108 108 108
8 12 6 108 108 108
9 12 6 108 108 108
10 12 6 108 108 108
11 12 6 108 108 108
12 12 6 108 108 108
13 12 6 108 108 108
14 12 6 144 144 144
-15 13 6 144 144 144
-14 13 6 108 108 108
-13 13 6 108 108 108
-12 13 6 108 108 108
-11 13 6 108 108 108
-10 13 6 108 108 108
-9 13 6 108 108 108
-8 13 6 108 108 108
-7 13 6 108 108 108
-6 13 6 108 108 108
-5 13 6 108 108 108
-4 13 6 108 108 108
-3 13 6 108 108 108
-2 13 6 108 108 108
-1 13 6 108 108 108
0 13 6 108 108 108
1 13 6 108 108 108
2 13 6 108 108 108
3 13 6 108 108 108
4 13 6 108 108 108
5 13 6 108 108 108
6 13 6 108 108 108
7 13 6 108 108 108
8 13 6 108 108 108
9 13 6 108 108 108
10 13 6 108 108 108
11 13 6 108 108 108
12 13 6 108 108 108
13 13 6 108 108 108
14 13 6 144 144 144
-15 14 6 144 144 144
-14 14 6 144 144 144
-13 14 6 144 144 144
-12 14 6 144 144 144
-11 14 6 144 144 144
-10 14 6 144 144 144
-9 14 6 144 144 144
-8 14 6 144 144 144
-7 14 6 144 144 144
-6 14 6 144 144 144
-5 14 6 144 144 144
-4 14 6 144 144 144
-3 14 6 144 144 144
-2 14 6 144 144 144
-1 14 6 144 144 144
0 14 6 144 144 144
1 14 6 144 144 144
2 14 6 144 144 144
3 14 6 144 144 144
4 14 6 144 144 144
5 14 6 144 144 144
6 14 6 144 144 144
7 14 6 144 144 144
8 14 6 144 144 144
9 14 6 144 144 144
10 14 6 144 144 144
11 14 6 144 144 144
12 14 6 144 144 144
13 14 6 144 144 144
14 14 6 144 144 144
-15 -15 7 144 144 144
-14 -15 7 144 144 144
-13 -15 7 144 144 144
-12 -15 7 144 144 144
-11 -15 7 144 144 144
-10 -15 7 144 144 144
-9 -15 7 144 144 144
-8 -15 7 144 144 144
-7 -15 7 144 144 144
-6 -15 7 144 144 144
-5 -15 7 144 144 144
-4 -15 7 144 144 144
-3 -15 7 144 144 144
-2 -15 7 144 144 144
-1 -15 7 144 144 144
0 -15 7 144 144 144
1 -15 7 144 144 144
2 -15 7 144 144 144
3 -15 7 144 144 144
4 -15 7 144 144 144
5 -15 7 144 144 144
6 -15 7 144 144 144
7 -15 7 144 144 144
8 -15 7 144 144 144
9 -15 7 144 144 144
10 -15 7 144 144 144
11 -15 7 144 144 144
12 -15 7 144 144 144
13 -15 7 144 144 144
14 -15 7 144 144 144
-15 -14 7 144 144 144
-14 -14 7 108 108 108
-13 -14 7 108 108 108
-12 -14 7 108 108 108
-11 -14 7 108 108 108
-10 -14 7 108 108 108
-9 -14 7 108 108 108
-8 -14 7 108 108 108
-7 -14 7 108 108 108
-6 -14 7 108 108 108
-5 -14 7 108 108 108
-4 -14 7 108 108 108
-3 -14 7 108 108 108
-2 -14 7 108 108 108
-1 -14 7 108 108 108
0 -14 7 108 108 108
1 -14 7 108 108 108
2 -14 7 108 108 108
3 -14 7 108 108 108
4 -14 7 108 108 108
5 -14 7 108 108 108
6 -14 7 108 108 108
7 -14 7 108 108 108
8 -14 7 108 108 108
9 -14 7 108 108 108
10 -14 7 108 108 108
11 -14 7 108 108 108
12 -14 7 108 108 108
13 -14 7 108 108 108
14 -14 7 144 144 144
-15 -13 7 144 144 144
-14 -13 7 108 108 108
-13 -13 7 108 108 108
-12 -13 7 108 108 108
-11 -13 7 108 108 108
-10 -13 7 108 108 108
-9 -13 7 108 108 108
-8 -13 7 108 108 108
-7 -13 7 108 108 108
-6 -13 7 108 108 108
-5 -13 7 108 108 108
-4 -13 7 108 108 108
-3 -13 7 108 108 108
-2 -13 7 108 108 108
-1 -13 7 108 108 108
0 -13 7 108 108 108
1 -13 7 108 108 108
2 -13 7 108 108 108
3 -13 7 108 108 108
4 -13 7 108 108 108
5 -13 7 108 108 108
6 -13 7 108 108 108
7 -13 7 108 108 108
8 -13 7 108 108 108
9 -13 7 108 108 108
10 -13 7 108 108 108
11 -13 7 108 108 108
12 -13 7 108 108 108
13 -13 7 108 108 108
14 -13 7 144 144 144
-15 -12 7 144 144 144
-14 -12 7 108 108 108
-13 -12 7 108 108 108
-12 -12 7 64 64 64
-11 -12 7 64 64 64
-8 -12 7 156 32 32
-7 -12 7 176 60 60
-6 -12 7 176 60 60
-5 -12 7 176 60 60
-4 -12 7 156 32 32
-1 -12 7 64 64 64
0 -12 7 64 64 64
3 -12 7 156 32 32
4 -12 7 176 60 60
5 -12 7 176 60 60
6 -12 7 176 60 60
7 -12 7 156 32 32
10 -12 7 64 64 64
11 -12 7 64 64 64
12 -12 7 108 108 108
13 -12 7 108 108 108
14 -12 7 144 144 144
-15 -11 7 144 144 144
-14 -11 7 108 108 108
-13 -11 7 108 108 108
-12 -11 7 64 64 64
-11 -11 7 64 64 64
-1 -11 7 64 64 64
0 -11 7 64 64 64
10 -11 7 64 64 64
11 -11 7 64 64 64
12 -11 7 108 108 108
13 -11 7 108 108 108
14 -11 7 144 144 144
-15 -10 7 144 144 144
-14 -10 7 108 108 108
-13 -10 7 108 108 108
12 -10 7 108 108 108
13 -10 7 108 108 108
14 -10 7 144 144 144
-15 -9 7 144 144 144
-14 -9 7 108 108 108
-13 -9 7 108 108 108
12 -9 7 108 108 108
13 -9 7 108 108 108
14 -9 7 144 144 144
-15 -8 7 144 144 144
-14 -8 7 108 108 108
-13 -8 7 108 108 108
11 -8 7 156 32 32
12 -8 7 108 108 108
13 -8 7 108 108 108
14 -8 7 144 144 144
-15 -7 7 144 144 144
-14 -7 7 108 108 108
-13 -7 7 108 108 108
11 -7 7 176 60 60
12 -7 7 108 108 108
13 -7 7 108 108 108
14 -7 7 144 144 144
-15 -6 7 144 144 144
-14 -6 7 108 108 108
-13 -6 7 108 108 108
-12 -6 7 64 64 64
-11 -6 7 64 64 64
11 -6 7 176 60 60
12 -6 7 108 108 108
13 -6 7 108 108 108
14 -6 7 144 144 144
-15 -5 7 144 144 144
-14 -5 7 108 108 108
-13 -5 7 108 108 108
-12 -5 7 64 64 64
-11 -5 7 64 64 64
11 -5 7 176 60 60
12 -5 7 108 108 108
13 -5 7 108 108 108
14 -5 7 144 144 144
-15 -4 7 144 144 144
-14 -4 7 108 108 108
-13 -4 7 108 108 108
-12 -4 7 108 108 108
-11 -4 7 108 108 108
-10 -4 7 108 108 108
-9 -4 7 108 108 108
11 -4 7 156 32 32
12 -4 7 108 108 108
13 -4 7 108 108 108
14 -4 7 144 144 144
-15 -3 7 144 144 144
-14 -3 7 108 108 108
-13 -3 7 108 108 108
-9 -3 7 108 108 108
12 -3 7 108 108 108
13 -3 7 108 108 108
14 -3 7 144 144 144
-15 -2 7 144 144 144
-14 -2 7 108 108 108
-13 -2 7 108 108 108
-9 -2 7 108 108 108
12 -2 7 108 108 108
13 -2 7 108 108 108
14 -2 7 144 144 144
-15 -1 7 144 144 144
-14 -1 7 108 108 108
-13 -1 7 108 108 108
-9 -1 7 108 108 108
10 -1 7 64 64 64
11 -1 7 64 64 64
12 -1 7 108 108 108
13 -1 7 108 108 108
14 -1 7 144 144 144
-15 0 7 144 144 144
-14 0 7 108 108 108
-13 0 7 108 108 108
-9 0 7 108 108 108
10 0 7 64 64 64
11 0 7 64 64 64
12 0 7 108 108 108
13 0 7 108 108 108
14 0 7 144 144 144
-15 1 7 144 144 144
-14 1 7 108 108 108
-13 1 7 108 108 108
-9 1 7 108 108 108
12 1 7 108 108 108
13 1 7 108 108 108
14 1 7 144 144 144
-15 2 7 144 144 144
-14 2 7 108 108 108
-13 2 7 108 108 108
-9 2 7 108 108 108
12 2 7 108 108 108
13 2 7 108 108 108
14 2 7 144 144 144
-15 3 7 144 144 144
-14 3 7 108 108 108
-13 3 7 108 108 108
-12 3 7 108 108 108
-11 3 7 108 108 108
-10 3 7 108 108 108
-9 3 7 108 108 108
11 3 7 156 32 32
12 3 7 108 108 108
13 3 7 108 108 108
14 3 7 144 144 144
-15 4 7 144 144 144
-14 4 7 108 108 108
-13 4 7 108 108 108
-12 4 7 64 64 64
-11 4 7 64 64 64
11 4 7 176 60 60
12 4 7 108 108 108
13 4 7 108 108 108
14 4 7 144 144 144
-15 5 7 144 144 144
-14 5 7 108 108 108
-13 5 7 108 108 108
-12 5 7 64 64 64
-11 5 7 64 64 64
11 5 7 176 60 60
12 5 7 108 108 108
13 5 7 108 108 108
14 5 7 144 144 144
-15 6 7 144 144 144
-14 6 7 108 108 108
-13 6 7 108 108 108
11 6 7 176 60 60
12 6 7 108 108 108
13 6 7 108 108 108
14 6 7 144 144 144
-15 7 7 144 144 144
-14 7 7 108 108 108
-13 7 7 108 108 108
11 7 7 156 32 32
12 7 7 108 108 108
13 7 7 108 108 108
14 7 7 144 144 144
-15 8 7 144 144 144
-14 8 7 108 108 108
-13 8 7 108 108 108
12 8 7 108 108 108
13 8 7 108 108 108
14 8 7 144 144 144
-15 9 7 144 144 144
-14 9 7 108 108 108
-13 9 7 108 108 108
12 9 7 108 108 108
13 9 7 108 108 108
14 9 7 144 144 144
-15 10 7 144 144 144
-14 10 7 108 108 108
-13 10 7 108 108 108
-12 10 7 64 64 64
-11 10 7 64 64 64
-1 10 7 64 64 64
0 10 7 64 64 64
10 10 7 64 64 64
11 10 7 64 64 64
12 10 7 108 108 108
13 10 7 108 108 108
14 10 7 144 144 144
-15 11 7 144 144 144
-14 11 7 108 108 108
-13 11 7 108 108 108
-12 11 7 64 64 64
-11 11 7 64 64 64
-8 11 7 156 32 32
-7 11 7 176 60 60
-6 11 7 176 60 60
-5 11 7 176 60 60
-4 11 7 156 32 32
-1 11 7 64 64 64
0 11 7 64 64 64
3 11 7 156 32 32
4 11 7 176 60 60
5 11 7 176 60 60
6 11 7 176 60 60
7 11 7 156 32 32
10 11 7 64 64 64
11 11 7 64 64 64
12 11 7 108 108 108
13 11 7 108 108 108
14 11 7 144 144 144
-15 12 7 144 144 144
-14 12 7 108 108 108
-13 12 7 108 108 108
-12 12 7 108 108 108
-11 12 7 108 108 108
-10 12 7 108 108 108
-9 12 7 108 108 108
-8 12 7 108 108 108
-7 12 7 108 108 108
-6 12 7 108 108 108
-5 12 7 108 108 108
-4 12 7 108 108 108
-3 12 7 108 108 108
-2 12 7 108 108 108
-1 12 7 108 108 108
0 12 7 108 108 108
1 12 7 108 108 108
2 12 7 108 108 108
3 12 7 108 108 108
4 12 7 108 108 108
5 12 7 108 108 108
6 12 7 108 108 108
7 12 7 108 108 108
8 12 7 108 108 108
9 12 7 108 108 108
10 12 7 108 108 108
11 12 7 108 108 108
12 12 7 108 108 108
13 12 7 108 108 108
14 12 7 144 144 144
-15 13 7 144 144 144
-14 13 7 108 108 108
-13 13 7 108 108 108
-12 13 7 108 108 108
-11 13 7 108 108 108
-10 13 7 108 108 108
-9 13 7 108 108 108
-8 13 7 108 108 108
-7 13 7 108 108 108
-6 13 7 108 108 108
-5 13 7 108 108 108
-4 13 7 108 108 108
-3 13 7 108 108 108
-2 13 7 108 108 108
-1 13 7 108 108 108
0 13 7 108 108 108
1 13 7 108 108 108
2 13 7 108 108 108
3 13 7 108 108 108
4 13 7 108 108 108
5 13 7 108 108 108
6 13 7 108 108 108
7 13 7 108 108 108
8 13 7 108 108 108
9 13 7 108 108 108
10 13 7 108 108 108
11 13 7 108 108 108
12 13 7 108 108 108
13 13 7 108 108 108
14 13 7 144 144 144
-15 14 7 144 144 144
-14 14 7 144 144 144
-13 14 7 144 144 144
-12 14 7 144 144 144
-11 14 7 144 144 144
-10 14 7 144 144 144
-9 14 7 144 144 144
-8 14 7 144 144 144
-7 14 7 144 144 144
-6 14 7 144 144 144
-5 14 7 144 144 144
-4 14 7 144 144 144
-3 14 7 144 144 144
-2 14 7 144 144 144
-1 14 7 144 144 144
0 14 7 144 144 144
1 14 7 144 144 144
2 14 7 144 144 144
3 14 7 144 144 144
4 14 7 144 144 144
5 14 7 144 144 144
6 14 7 144 144 144
7 14 7 144 144 144
8 14 7 144 144 144
9 14 7 144 144 144
10 14 7 144 144 144
11 14 7 144 144 144
12 14 7 144 144 144
13 14 7 144 144 144
14 14 7 144 144 144
-15 -15 8 144 144 144
-14 -15 8 144 144 144
-13 -15 8 144 144 144
-12 -15 8 144 144 144
-11 -15 8 144 144 144
-10 -15 8 144 144 144
-9 -15 8 144 144 144
-8 -15 8 144 144 144
-7 -15 8 144 144 144
-6 -15 8 144 144 144
-5 -15 8 144 144 144
-4 -15 8 144 144 144
-3 -15 8 144 144 144
-2 -15 8 144 144 144
-1 -15 8 144 144 144
0 -15 8 144 144 144
1 -15 8 144 144 144
2 -15 8 144 144 144
3 -15 8 144 144 144
4 -15 8 144 144 144
5 -15 8 144 144 144
6 -15 8 144 144 144
7 -15 8 144 144 144
8 -15 8 144 144 144
9 -15 8 144 144 144
10 -15 8 144 144 144
11 -15 8 144 144 144
12 -15 8 144 144 144
13 -15 8 144 144 144
14 -15 8 144 144 144
-15 -14 8 144 144 144
-14 -14 8 108 108 108
-13 -14 8 108 108 108
-12 -14 8 108 108 108
-11 -14 8 108 108 108
-10 -14 8 108 108 108
-9 -14 8 108 108 108
-8 -14 8 108 108 108
-7 -14 8 108 108 108
-6 -14 8 108 108 108
-5 -14 8 108 108 108
-4 -14 8 108 108 108
-3 -14 8 108 108 108
-2 -14 8 108 108 108
-1 -14 8 108 108 108
0 -14 8 108 108 108
1 -14 8 108 108 108
2 -14 8 108 108 108
3 -14 8 108 108 108
4 -14 8 108 108 108
5 -14 8 108 108 108
6 -14 8 108 108 108
7 -14 8 108 108 108
8 -14 8 108 108 108
9 -14 8 108 108 108
10 -14 8 108 108 108
11 -14 8 108 108 108
12 -14 8 108 108 108
13 -14 8 108 108 108
14 -14 8 144 144 144
-15 -13 8 144 144 144
-14 -13 8 108 108 108
-13 -13 8 108 108 108
-12 -13 8 108 108 108
-11 -13 8 108 108 108
-10 -13 8 108 108 108
-9 -13 8 108 108 108
-8 -13 8 108 108 108
-7 -13 8 108 108 108
-6 -13 8 108 108 108
-5 -13 8 108 108 108
-4 -13 8 108 108 108
-3 -13 8 108 108 108
-2 -13 8 108 108 108
-1 -13 8 108 108 108
0 -13 8 108 108 108
1 -13 8 108 108 108
2 -13 8 108 108 108
3 -13 8 108 108 108
4 -13 8 108 108 108
5 -13 8 108 108 108
6 -13 8 108 108 108
7 -13 8 108 108 108
8 -13 8 108 108 108
9 -13 8 108 108 108
10 -13 8 108 108 108
11 -13 8 108 108 108
12 -13 8 108 108 108
13 -13 8 108 108 108
14 -13 8 144 144 144
-15 -12 8 144 144 144
-14 -12 8 108 108 108
-13 -12 8 108 108 108
-12 -12 8 64 64 64
-11 -12 8 64 64 64
-8 -12 8 156 32 32
-7 -12 8 176 60 60
-6 -12 8 176 60 60
-5 -12 8 176 60 60
-4 -12 8 156 32 32
-1 -12 8 64 64 64
0 -12 8 64 64 64
3 -12 8 156 32 32
4 -12 8 176 60 60
5 -12 8 176 60 60
6 -12 8 176 60 60
7 -12 8 156 32 32
10 -12 8 64 64 64
11 -12 8 64 64 64
12 -12 8 108 108 108
13 -12 8 108 108 108
14 -12 8 144 144 144
-15 -11 8 144 144 144
-14 -11 8 108 108 108
-13 -11 8 108 108 108
-12 -11 8 64 64 64
-11 -11 8 64 64 64
-1 -11 8 64 64 64
0 -11 8 64 64 64
10 -11 8 64 64 64
11 -11 8 64 64 64
12 -11 8 108 108 108
13 -11 8 108 108 108
14 -11 8 144 144 144
-15 -10 8 144 144 144
-14 -10 8 108 108 108
-13 -10 8 108 108 108
12 -10 8 108 108 108
13 -10 8 108 108 108
14 -10 8 144 144 144
-15 -9 8 144 144 144
-14 -9 8 108 108 108
-13 -9 8 108 108 108
12 -9 8 108 108 108
13 -9 8 108 108 108
14 -9 8 144 144 144
-15 -8 8 144 144 144
-14 -8 8 108 108 108
-13 -8 8 108 108 108
11 -8 8 156 32 32
12 -8 8 108 108 108
13 -8 8 108 108 108
14 -8 8 144 144 144
-15 -7 8 144 144 144
-14 -7 8 108 108 108
-13 -7 8 108 108 108
11 -7 8 176 60 60
12 -7 8 108 108 108
13 -7 8 108 108 108
14 -7 8 144 144 144
-15 -6 8 144 144 144
-14 -6 8 108 108 108
-13 -6 8 108 108 108
-12 -6 8 64 64 64
-11 -6 8 64 64 64
11 -6 8 176 60 60
12 -6 8 108 108 108
13 -6 8 108 108 108
14 -6 8 144 144 144
-15 -5 8 144 144 144
-14 -5 8 108 108 108
-13 -5 8 108 108 108
-12 -5 8 64 64 64
-11 -5 8 64 64 64
11 -5 8 176 60 60
12 -5 8 108 108 108
13 -5 8 108 108 108
14 -5 8 144 144 144
-15 -4 8 144 144 144
-14 -4 8 108 108 108
-13 -4 8 108 108 108
-12 -4 8 108 108 108
-11 -4 8 108 108 108
-10 -4 8 108 108 108
-9 -4 8 108 108 108
11 -4 8 156 32 32
12 -4 8 108 108 108
13 -4 8 108 108 108
14 -4 8 144 144 144
-15 -3 8 144 144 144
-14 -3 8 108 108 108
-13 -3 8 108 108 108
-9 -3 8 108 108 108
12 -3 8 108 108 108
13 -3 8 108 108 108
14 -3 8 144 144 144
-15 -2 8 144 144 144
-14 -2 8 108 108 108
-13 -2 8 108 108 108
-9 -2 8 108 108 108
12 -2 8 108 108 108
13 -2 8 108 108 108
14 -2 8 144 144 144
-15 -1 8 144 144 144
-14 -1 8 108 108 108
-13 -1 8 108 108 108
-9 -1 8 108 108 108
10 -1 8 64 64 64
11 -1 8 64 64 64
12 -1 8 108 108 108
13 -1 8 108 108 108
14 -1 8 144 144 144
-15 0 8 144 144 144
-14 0 8 108 108 108
-13 0 8 108 108 108
-9 0 8 108 108 108
10 0 8 64 64 64
11 0 8 64 64 64
12 0 8 108 108 108
13 0 8 108 108 108
14 0 8 144 144 144
-15 1 8 144 144 144
-14 1 8 108 108 108
-13 1 8 108 108 108
-9 1 8 108 108 108
12 1 8 108 108 108
13 1 8 108 108 108
14 1 8 144 144 144
-15 2 8 144 144 144
-14 2 8 108 108 108
-13 2 8 108 108 108
-9 2 8 108 108 108
12 2 8 108 108 108
13 2 8 108 108 108
14 2 8 144 144 144
-15 3 8 144 144 144
-14 3 8 108 108 108
-13 3 8 108 108 108
-12 3 8 108 108 108
-11 3 8 108 108 108
-10 3 8 108 108 108
-9 3 8 108 108 108
11 3 8 156 32 32
12 3 8 108 108 108
13 3 8 108 108 108
14 3 8 144 144 144
-15 4 8 144 144 144
-14 4 8 108 108 108
-13 4 8 108 108 108
-12 4 8 64 64 64
-11 4 8 64 64 64
11 4 8 176 60 60
12 4 8 108 108 108
13 4 8 108 108 108
14 4 8 144 144 144
-15 5 8 144 144 144
-14 5 8 108 108 108
-13 5 8 108 108 108
-12 5 8 64 64 64
-11 5 8 64 64 64
11 5 8 176 60 60
12 5 8 108 108 108
13 5 8 108 108 108
14 5 8 144 144 144
-15 6 8 144 144 144
-14 6 8 108 108 108
-13 6 8 108 108 108
11 6 8 176 60 60
12 6 8 108 108 108
13 6 8 108 108 108
14 6 8 144 144 144
-15 7 8 144 144 144
-14 7 8 108 108 108
-13 7 8 108 108 108
11 7 8 156 32 32
12 7 8 108 108 108
13 7 8 108 108 108
14 7 8 144 144 144
-15 8 8 144 144 144
-14 8 8 108 108 108
-13 8 8 108 108 108
12 8 8 108 108 108
13 8 8 108 108 108
14 8 8 144 144 144
-15 9 8 144 144 144
-14 9 8 108 108 108
-13 9 8 108 108 108
12 9 8 108 108 108
13 9 8 108 108 108
14 9 8 144 144 144
-15 10 8 144 144 144
-14 10 8 108 108 108
-13 10 8 108 108 108
-12 10 8 64 64 64
-11 10 8 64 64 64
-1 10 8 64 64 64
0 10 8 64 64 64
10 10 8 64 64 64
11 10 8 64 64 64
12 10 8 108 108 108
13 10 8 108 108 108
14 10 8 144 144 144
-15 11 8 144 144 144
-14 11 8 108 108 108
-13 11 8 108 108 108
-12 11 8 64 64 64
-11 11 8 64 64 64
-8 11 8 156 32 32
-7 11 8 176 60 60
-6 11 8 176 60 60
-5 11 8 176 60 60
-4 11 8 156 32 32
-1 11 8 64 64 64
0 11 8 64 64 64
3 11 8 156 32 32
4 11 8 176 60 60
5 11 8 176 60 60
6 11 8 176 60 60
7 11 8 156 32 32
10 11 8 64 64 64
11 11 8 64 64 64
12 11 8 108 108 108
13 11 8 108 108 108
14 11 8 144 144 144
-15 12 8 144 144 144
-14 12 8 108 108 108
-13 12 8 108 108 108
-12 12 8 108 108 108
-11 12 8 108 108 108
-10 12 8 108 108 108
-9 12 8 108 108 108
-8 12 8 108 108 108
-7 12 8 108 108 108
-6 12 8 108 108 108
-5 12 8 108 108 108
-4 12 8 108 108 108
-3 12 8 108 108 108
-2 12 8 108 108 108
-1 12 8 108 108 108
0 12 8 108 108 108
1 12 8 108 108 108
2 12 8 108 108 108
3 12 8 108 108 108
4 12 8 108 108 108
5 12 8 108 108 108
6 12 8 108 108 108
7 12 8 108 108 108
8 12 8 108 108 108
9 12 8 108 108 108
10 12 8 108 108 108
11 12 8 108 108 108
12 12 8 108 108 108
13 12 8 108 108 108
14 12 8 144 144 144
-15 13 8 144 144 144
-14 13 8 108 108 108
-13 13 8 108 108 108
-12 13 8 108 108 108
-11 13 8 108 108 108
-10 13 8 108 108 108
-9 13 8 108 108 108
-8 13 8 108 108 108
-7 13 8 108 108 108
-6 13 8 108 108 108
-5 13 8 108 108 108
-4 13 8 108 108 108
-3 13 8 108 108 108
-2 13 8 108 108 108
-1 13 8 108 108 108
0 13 8 108 108 108
1 13 8 108 108 108
2 13 8 108 108 108
3 13 8 108 108 108
4 13 8 108 108 108
5 13 8 108 108 108
6 13 8 108 108 108
7 13 8 108 108 108
8 13 8 108 108 108
9 13 8 108 108 108
10 13 8 108 108 108
11 13 8 108 108 108
12 13 8 108 108 108
13 13 8 108 108 108
14 13 8 144 144 144
-15 14 8 144 144 144
-14 14 8 144 144 144
-13 14 8 144 144 144
-12 14 8 144 144 144
-11 14 8 144 144 144
-10 14 8 144 144 144
-9 14 8 144 144 144
-8 14 8 144 144 144
-7 14 8 144 144 144
-6 14 8 144 144 144
-5 14 8 144 144 144
-4 14 8 144 144 144
-3 14 8 144 144 144
-2 14 8 144 144 144
-1 14 8 144 144 144
0 14 8 144 144 144
1 14 8 144 144 144
2 14 8 144 144 144
3 14 8 144 144 144
4 14 8 144 144 144
5 14 8 144 144 144
6 14 8 144 144 144
7 14 8 144 144 144
8 14 8 144 144 144
9 14 8 144 144 144
10 14 8 144 144 144
11 14 8 144 144 144
12 14 8 144 144 144
13 14 8 144 144 144
14 14 8 144 144 144
-15 -15 9 144 144 144
-14 -15 9 144 144 144
-13 -15 9 144 144 144
-12 -15 9 144 144 144
-11 -15 9 144 144 144
-10 -15 9 144 144 144
-9 -15 9 144 144 144
-8 -15 9 144 144 144
-7 -15 9 144 144 144
-6 -15 9 144 144 144
-5 -15 9 144 144 144
-4 -15 9 144 144 144
-3 -15 9 144 144 144
-2 -15 9 144 144 144
-1 -15 9 144 144 144
0 -15 9 144 144 144
1 -15 9 144 144 144
2 -15 9 144 144 144
3 -15 9 144 144 144
4 -15 9 144 144 144
5 -15 9 144 144 144
6 -15 9 144 144 144
7 -15 9 144 144 144
8 -15 9 144 144 144
9 -15 9 144 144 144
10 -15 9 144 144 144
11 -15 9 144 144 144
12 -15 9 144 144 144
13 -15 9 144 144 144
14 -15 9 144 144 144
-15 -14 9 144 144 144
-14 -14 9 108 108 108
-13 -14 9 108 108 108
-12 -14 9 108 108 108
-11 -14 9 108 108 108
-10 -14 9 108 108 108
-9 -14 9 108 108 108
-8 -14 9 108 108 108
-7 -14 9 108 108 108
-6 -14 9 108 108 108
-5 -14 9 108 108 108
-4 -14 9 108 108 108
-3 -14 9 108 108 108
-2 -14 9 108 108 108
-1 -14 9 108 108 108
0 -14 9 108 108 108
1 -14 9 108 108 108
2 -14 9 108 108 108
3 -14 9 108 108 108
4 -14 9 108 108 108
5 -14 9 108 108 108
6 -14 9 108 108 108
7 -14 9 108 108 108
8 -14 9 108 108 108
9 -14 9 108 108 108
10 -14 9 108 108 108
11 -14 9 108 108 108
12 -14 9 108 108 108
13 -14 9 108 108 108
14 -14 9 144 144 144
-15 -13 9 144 144 144
-14 -13 9 108 108 108
-13 -13 9 108 108 108
-12 -13 9 108 108 108
-11 -13 9 108 108 108
-10 -13 9 108 108 108
-9 -13 9 108 108 108
-8 -13 9 108 108 108
-7 -13 9 108 108 108
-6 -13 9 108 108 108
-5 -13 9 108 108 108
-4 -13 9 108 108 108
-3 -13 9 108 108 108
-2 -13 9 108 108 108
-1 -13 9 108 108 108
0 -13 9 108 108 108
1 -13 9 108 108 108
2 -13 9 108 108 108
3 -13 9 108 108 108
4 -13 9 108 108 108
5 -13 9 108 108 108
6 -13 9 108 108 108
7 -13 9 108 108 108
8 -13 9 108 108 108
9 -13 9 108 108 108
10 -13 9 108 108 108
11 -13 9 108 108 108
12 -13 9 108 108 108
13 -13 9 108 108 108
14 -13 9 144 144 144
-15 -12 9 144 144 144
-14 -12 9 108 108 108
-13 -12 9 108 108 108
-12 -12 9 64 64 64
-11 -12 9 64 64 64
-8 -12 9 156 32 32
-7 -12 9 176 60 60
-6 -12 9 176 60 60
-5 -12 9 176 60 60
-4 -12 9 156 32 32
-1 -12 9 64 64 64
0 -12 9 64 64 64
3 -12 9 156 32 32
4 -12 9 176 60 60
5 -12 9 176 60 60
6 -12 9 176 60 60
7 -12 9 156 32 32
10 -12 9 64 64 64
11 -12 9 64 64 64
12 -12 9 108 108 108
13 -12 9 108 108 108
14 -12 9 144 144 144
-15 -11 9 144 144 144
-14 -11 9 108 108 108
-13 -11 9 108 108 108
-12 -11 9 64 64 64
-11 -11 9 64 64 64
-1 -11 9 64 64 64
0 -11 9 64 64 64
10 -11 9 64 64 64
11 -11 9 64 64 64
12 -11 9 108 108 108
13 -11 9 108 108 108
14 -11 9 144 144 144
-15 -10 9 144 144 144
-14 -10 9 108 108 108
-13 -10 9 108 108 108
12 -10 9 108 108 108
13 -10 9 108 108 108
14 -10 9 144 144 144
-15 -9 9 144 144 144
-14 -9 9 108 108 108
-13 -9 9 108 108 108
12 -9 9 108 108 108
13 -9 9 108 108 108
14 -9 9 144 144 144
-15 -8 9 144 144 144
-14 -8 9 108 108 108
-13 -8 9 108 108 108
11 -8 9 156 32 32
12 -8 9 108 108 108
13 -8 9 108 108 108
14 -8 9 144 144 144
-15 -7 9 144 144 144
-14 -7 9 108 108 108
-13 -7 9 108 108 108
11 -7 9 176 60 60
12 -7 9 108 108 108
13 -7 9 108 108 108
14 -7 9 144 144 144
-15 -6 9 144 144 144
-14 -6 9 108 108 108
-13 -6 9 108 108 108
-12 -6 9 64 64 64
-11 -6 9 64 64 64
11 -6 9 176 60 60
12 -6 9 108 108 108
13 -6 9 108 108 108
14 -6 9 144 144 144
-15 -5 9 144 144 144
-14 -5 9 108 108 108
-13 -5 9 108 108 108
-12 -5 9 64 64 64
-11 -5 9 64 64 64
11 -5 9 176 60 60
12 -5 9 108 108 108
13 -5 9 108 108 108
14 -5 9 144 144 144
-15 -4 9 144 144 144
-14 -4 9 108 108 108
-13 -4 9 108 108 108
-12 -4 9 108 108 108
-11 -4 9 108 108 108
-10 -4 9 108 108 108
-9 -4 9 108 108 108
11 -4 9 156 32 32
12 -4 9 108 108 108
13 -4 9 108 108 108
14 -4 9 144 144 144
-15 -3 9 144 144 144
-14 -3 9 108 108 108
-13 -3 9 108 108 108
-9 -3 9 108 108 108
12 -3 9 108 108 108
13 -3 9 108 108 108
14 -3 9 144 144 144
-15 -2 9 144 144 144
-14 -2 9 108 108 108
-13 -2 9 108 108 108
-9 -2 9 108 108 108
12 -2 9 108 108 108
13 -2 9 108 108 108
14 -2 9 144 144 144
-15 -1 9 144 144 144
-14 -1 9 108 108 108
-13 -1 9 108 108 108
-9 -1 9 108 108 108
10 -1 9 64 64 64
11 -1 9 64 64 64
12 -1 9 108 108 108
13 -1 9 108 108 108
14 -1 9 144 144 144
-15 0 9 144 144 144
-14 0 9 108 108 108
-13 0 9 108 108 108
-9 0 9 108 108 108
10 0 9 64 64 64
11 0 9 64 64 64
12 0 9 108 108 108
13 0 9 108 108 108
14 0 9 144 144 144
-15 1 9 144 144 144
-14 1 9 108 108 108
-13 1 9 108 108 108
-9 1 9 108 108 108
12 1 9 108 108 108
13 1 9 108 108 108
14 1 9 144 144 144
-15 2 9 144 144 144
-14 2 9 108 108 108
-13 2 9 108 108 108
-9 2 9 108 108 108
12 2 9 108 108 108
13 2 9 108 108 108
14 2 9 144 144 144
-15 3 9 144 144 144
-14 3 9 108 108 108
-13 3 9 108 108 108
-12 3 9 108 108 108
-11 3 9 108 108 108
-10 3 9 108 108 108
-9 3 9 108 108 108
11 3 9 156 32 32
12 3 9 108 108 108
13 3 9 108 108 108
14 3 9 144 144 144
-15 4 9 144 144 144
-14 4 9 108 108 108
-13 4 9 108 108 108
-12 4 9 64 64 64
-11 4 9 64 64 64
11 4 9 176 60 60
12 4 9 108 108 108
13 4 9 108 108 108
14 4 9 144 144 144
-15 5 9 144 144 144
-14 5 9 108 108 108
-13 5 9 108 108 108
-12 5 9 64 64 64
-11 5 9 64 64 64
11 5 9 176 60 60
12 5 9 108 108 108
13 5 9 108 108 108
14 5 9 144 144 144
-15 6 9 144 144 144
-14 6 9 108 108 108
-13 6 9 108 108 108
11 6 9 176 60 60
12 6 9 108 108 108
13 6 9 108 108 108
14 6 9 144 144 144
-15 7 9 144 144 144
-14 7 9 108 108 108
-13 7 9 108 108 108
11 7 9 156 32 32
12 7 9 108 108 108
13 7 9 108 108 108
14 7 9 144 144 144
-15 8 9 144 144 144
-14 8 9 108 108 108
-13 8 9 108 108 108
12 8 9 108 108 108
13 8 9 108 108 108
14 8 9 144 144 144
-15 9 9 144 144 144
-14 9 9 108 108 108
-13 9 9 108 108 108
12 9 9 108 108 108
13 9 9 108 108 108
14 9 9 144 144 144
-15 10 9 144 144 144
-14 10 9 108 108 108
-13 10 9 108 108 108
-12 10 9 64 64 64
-11 10 9 64 64 64
-1 10 9 64 64 64
0 10 9 64 64 64
10 10 9 64 64 64
11 10 9 64 64 64
12 10 9 108 108 108
13 10 9 108 108 108
14 10 9 144 144 144
-15 11 9 144 144 144
-14 11 9 108 108 108
-13 11 9 108 108 108
-12 11 9 64 64 64
-11 11 9 64 64 64
-8 11 9 156 32 32
-7 11 9 176 60 60
-6 11 9 176 60 60
-5 11 9 176 60 60
-4 11 9 156 32 32
-1 11 9 64 64 64
0 11 9 64 64 64
3 11 9 156 32 32
4 11 9 176 60 60
5 11 9 176 60 60
6 11 9 176 60 60
7 11 9 156 32 32
10 11 9 64 64 64
11 11 9 64 64 64
12 11 9 108 108 108
13 11 9 108 108 108
14 11 9 144 144 144
-15 12 9 144 144 144
-14 12 9 108 108 108
-13 12 9 108 108 108
-12 12 9 108 108 108
-11 12 9 108 108 108
-10 12 9 108 108 108
-9 12 9 108 108 108
-8 12 9 108 108 108
-7 12 9 108 108 108
-6 12 9 108 108 108
-5 12 9 108 108 108
-4 12 9 108 108 108
-3 12 9 108 108 108
-2 12 9 108 108 108
-1 12 9 108 108 108
0 12 9 108 108 108
1 12 9 108 108 108
2 12 9 108 108 108
3 12 9 108 108 108
4 12 9 108 108 108
5 12 9 108 108 108
6 12 9 108 108 108
7 12 9 108 108 108
8 12 9 108 108 108
9 12 9 108 108 108
10 12 9 108 108 108
11 12 9 108 108 108
12 12 9 108 108 108
13 12 9 108 108 108
14 12 9 144 144 144
-15 13 9 144 144 144
-14 13 9 108 108 108
-13 13 9 108 108 108
-12 13 9 108 108 108
-11 13 9 108 108 108
-10 13 9 108 108 108
-9 13 9 108 108 108
-8 13 9 108 108 108
-7 13 9 108 108 108
-6 13 9 108 108 108
-5 13 9 108 108 108
-4 13 9 108 108 108
-3 13 9 108 108 108
-2 13 9 108 108 108
-1 13 9 108 108 108
0 13 9 108 108 108
1 13 9 108 108 108
2 13 9 108 108 108
3 13 9 108 108 108
4 13 9 108 108 108
5 13 9 108 108 108
6 13 9 108 108 108
7 13 9 108 108 108
8 13 9 108 108 108
9 13 9 108 108 108
10 13 9 108 108 108
11 13 9 108 108 108
12 13 9 108 108 108
13 13 9 108 108 108
14 13 9 144 144 144
-15 14 9 144 144 144
-14 14 9 144 144 144
-13 14 9 144 144 144
-12 14 9 144 144 144
-11 14 9 144 144 144
-10 14 9 144 144 144
-9 14 9 144 144 144
-8 14 9 144 144 144
-7 14 9 144 144 144
-6 14 9 144 144 144
-5 14 9 144 144 144
-4 14 9 144 144 144
-3 14 9 144 144 144
-2 14 9 144 144 144
-1 14 9 144 144 144
0 14 9 144 144 144
1 14 9 144 144 144
2 14 9 144 144 144
3 14 9 144 144 144
4 14 9 144 144 144
5 14 9 144 144 144
6 14 9 144 144 144
7 14 9 144 144 144
8 14 9 144 144 144
9 14 9 144 144 144
10 14 9 144 144 144
11 14 9 144 144 144
12 14 9 144 144 144
13 14 9 144 144 144
14 14 9 144 144 144
-15 -15 10 144 144 144
-14 -15 10 144 144 144
-13 -15 10 144 144 144
-12 -15 10 144 144 144
-11 -15 10 144 144 144
-10 -15 10 144 144 144
-9 -15 10 144 144 144
-8 -15 10 144 144 144
-7 -15 10 144 144 144
-6 -15 10 144 144 144
-5 -15 10 144 144 144
-4 -15 10 144 144 144
-3 -15 10 144 144 144
-2 -15 10 144 144 144
-1 -15 10 144 144 144
0 -15 10 144 144 144
1 -15 10 144 144 144
2 -15 10 144 144 144
3 -15 10 144 144 144
4 -15 10 144 144 144
5 -15 10 144 144 144
6 -15 10 144 144 144
7 -15 10 144 144 144
8 -15 10 144 144 144
9 -15 10 144 144 144
10 -15 10 144 144 144
11 -15 10 144 144 144
12 -15 10 144 144 144
13 -15 10 144 144 144
14 -15 10 144 144 144
-15 -14 10 144 144 144
-14 -14 10 108 108 108
-13 -14 10 108 108 108
-12 -14 10 108 108 108
-11 -14 10 108 108 108
-10 -14 10 108 108 108
-9 -14 10 108 108 108
-8 -14 10 108 108 108
-7 -14 10 108 108 108
-6 -14 10 108 108 108
-5 -14 10 108 108 108
-4 -14 10 108 108 108
-3 -14 10 108 108 108
-2 -14 10 108 108 108
-1 -14 10 108 108 108
0 -14 10 108 108 108
1 -14 10 108 108 108
2 -14 10 108 108 108
3 -14 10 108 108 108
4 -14 10 108 108 108
5 -14 10 108 108 108
6 -14 10 108 108 108
7 -14 10 108 108 108
8 -14 10 108 108 108
9 -14 10 108 108 108
10 -14 10 108 108 108
11 -14 10 108 108 108
12 -14 10 108 108 108
13 -14 10 108 108 108
14 -14 10 144 144 144
-15 -13 10 144 144 144
-14 -13 10 108 108 108
-13 -13 10 108 108 108
-12 -13 10 108 108 108
-11 -13 10 108 108 108
-10 -13 10 108 108 108
-9 -13 10 108 108 108
-8 -13 10 108 108 108
-7 -13 10 108 108 108
-6 -13 10 108 108 108
-5 -13 10 108 108 108
-4 -13 10 108 108 108
-3 -13 10 108 108 108
-2 -13 10 108 108 108
-1 -13 10 108 108 108
0 -13 10 108 108 108
1 -13 10 108 108 108
2 -13 10 108 108 108
3 -13 10 108 108 108
4 -13 10 108 108 108
5 -13 10 108 108 108
6 -13 10 108 108 108
7 -13 10 108 108 108
8 -13 10 108 108 108
9 -13 10 108 108 108
10 -13 10 108 108 108
11 -13 10 108 108 108
12 -13 10 108 108 108
13 -13 10 108 108 108
14 -13 10 144 144 144
-15 -12 10 144 144 144
-14 -12 10 108 108 108
-13 -12 10 108 108 108
-12 -12 10 64 64 64
-11 -12 10 64 64 64
-8 -12 10 156 32 32
-7 -12 10 156 32 32
-6 -12 10 156 32 32
-5 -12 10 156 32 32
-4 -12 10 156 32 32
-1 -12 10 64 64 64
0 -12 10 64 64 64
3 -12 10 156 32 32
4 -12 10 156 32 32
5 -12 10 156 32 32
6 -12 10 156 32 32
7 -12 10 156 32 32
10 -12 10 64 64 64
11 -12 10 64 64 64
12 -12 10 108 108 108
13 -12 10 108 108 108
14 -12 10 144 144 144
-15 -11 10 144 144 144
-14 -11 10 108 108 108
-13 -11 10 108 108 108
-12 -11 10 64 64 64
-11 -11 10 64 64 64
-1 -11 10 64 64 64
0 -11 10 64 64 64
10 -11 10 64 64 64
11 -11 10 64 64 64
12 -11 10 108 108 108
13 -11 10 108 108 108
14 -11 10 144 144 144
-15 -10 10 144 144 144
-14 -10 10 108 108 108
-13 -10 10 108 108 108
12 -10 10 108 108 108
13 -10 10 108 108 108
14 -10 10 144 144 144
-15 -9 10 144 144 144
-14 -9 10 108 108 108
-13 -9 10 108 108 108
12 -9 10 108 108 108
13 -9 10 108 108 108
14 -9 10 144 144 144
-15 -8 10 144 144 144
-14 -8 10 108 108 108
-13 -8 10 108 108 108
11 -8 10 156 32 32
12 -8 10 108 108 108
13 -8 10 108 108 108
14 -8 10 144 144 144
-15 -7 10 144 144 144
-14 -7 10 108 108 108
-13 -7 10 108 108 108
11 -7 10 156 32 32
12 -7 10 108 108 108
13 -7 10 108 108 108
14 -7 10 144 144 144
-15 -6 10 144 144 144
-14 -6 10 108 108 108
-13 -6 10 108 108 108
-12 -6 10 64 64 64
-11 -6 10 64 64 64
11 -6 10 156 32 32
12 -6 10 108 108 108
13 -6 10 108 108 108
14 -6 10 144 144 144
-15 -5 10 144 144 144
-14 -5 10 108 108 108
-13 -5 10 108 108 108
-12 -5 10 64 64 64
-11 -5 10 64 64 64
11 -5 10 156 32 32
12 -5 10 108 108 108
13 -5 10 108 108 108
14 -5 10 144 144 144
-15 -4 10 156 32 32
-14 -4 10 108 108 108
-13 -4 10 108 108 108
-12 -4 10 108 108 108
-11 -4 10 108 108 108
-10 -4 10 108 108 108
-9 -4 10 108 108 108
11 -4 10 156 32 32
12 -4 10 108 108 108
13 -4 10 108 108 108
14 -4 10 144 144 144
-15 -3 10 156 32 32
-14 -3 10 108 108 108
-9 -3 10 108 108 108
12 -3 10 108 108 108
13 -3 10 108 108 108
14 -3 10 144 144 144
-15 -2 10 156 32 32
-14 -2 10 108 108 108
-9 -2 10 108 108 108
12 -2 10 108 108 108
13 -2 10 108 108 108
14 -2 10 144 144 144
-15 -1 10 156 32 32
-14 -1 10 108 108 108
-9 -1 10 108 108 108
10 -1 10 64 64 64
11 -1 10 64 64 64
12 -1 10 108 108 108
13 -1 10 108 108 108
14 -1 10 144 144 144
-15 0 10 156 32 32
-14 0 10 108 108 108
-9 0 10 108 108 108
10 0 10 64 64 64
11 0 10 64 64 64
12 0 10 108 108 108
13 0 10 108 108 108
14 0 10 144 144 144
-15 1 10 156 32 32
-14 1 10 108 108 108
-9 1 10 108 108 108
12 1 10 108 108 108
13 1 10 108 108 108
14 1 10 144 144 144
-15 2 10 156 32 32
-14 2 10 108 108 108
-9 2 10 108 108 108
12 2 10 108 108 108
13 2 10 108 108 108
14 2 10 144 144 144
-15 3 10 156 32 32
-14 3 10 108 108 108
-13 3 10 108 108 108
-12 3 10 108 108 108
-11 3 10 108 108 108
-10 3 10 108 108 108
-9 3 10 108 108 108
11 3 10 156 32 32
12 3 10 108 108 108
13 3 10 108 108 108
14 3 10 144 144 144
-15 4 10 144 144 144
-14 4 10 108 108 108
-13 4 10 108 108 108
-12 4 10 64 64 64
-11 4 10 64 64 64
11 4 10 156 32 32
12 4 10 108 108 108
13 4 10 108 108 108
14 4 10 144 144 144
-15 5 10 144 144 144
-14 5 10 108 108 108
-13 5 10 108 108 108
-12 5 10 64 64 64
-11 5 10 64 64 64
11 5 10 156 32 32
12 5 10 108 108 108
13 5 10 108 108 108
14 5 10 144 144 144
-15 6 10 144 144 144
-14 6 10 108 108 108
-13 6 10 108 108 108
11 6 10 156 32 32
12 6 10 108 108 108
13 6 10 108 108 108
14 6 10 144 144 144
-15 7 10 144 144 144
-14 7 10 108 108 108
-13 7 10 108 108 108
11 7 10 156 32 32
12 7 10 108 108 108
13 7 10 108 108 108
14 7 10 144 144 144
-15 8 10 144 144 144
-14 8 10 108 108 108
-13 8 10 108 108 108
12 8 10 108 108 108
13 8 10 108 108 108
14 8 10 144 144 144
-15 9 10 144 144 144
-14 9 10 108 108 108
-13 9 10 108 108 108
12 9 10 108 108 108
13 9 10 108 108 108
14 9 10 144 144 144
-15 10 10 144 144 144
-14 10 10 108 108 108
-13 10 10 108 108 108
-12 10 10 64 64 64
-11 10 10 64 64 64
-1 10 10 64 64 64
0 10 10 64 64 64
10 10 10 64 64 64
11 10 10 64 64 64
12 10 10 108 108 108
13 10 10 108 108 108
14 10 10 144 144 144
-15 11 10 144 144 144
-14 11 10 108 108 108
-13 11 10 108 108 108
-12 11 10 64 64 64
-11 11 10 64 64 64
-8 11 10 156 32 32
-7 11 10 156 32 32
-6 11 10 156 32 32
-5 11 10 156 32 32
-4 11 10 156 32 32
-1 11 10 64 64 64
0 11 10 64 64 64
3 11 10 156 32 32
4 11 10 156 32 32
5 11 10 156 32 32
6 11 10 156 32 32
7 11 10 156 32 32
10 11 10 64 64 64
11 11 10 64 64 64
12 11 10 108 108 108
13 11 10 108 108 108
14 11 10 144 144 144
-15 12 10 144 144 144
-14 12 10 108 108 108
-13 12 10 108 108 108
-12 12 10 108 108 108
-11 12 10 108 108 108
-10 12 10 108 108 108
-9 12 10 108 108 108
-8 12 10 108 108 108
-7 12 10 108 108 108
-6 12 10 108 108 108
-5 12 10 108 108 108
-4 12 10 108 108 108
-3 12 10 108 108 108
-2 12 10 108 108 108
-1 12 10 108 108 108
0 12 10 108 108 108
1 12 10 108 108 108
2 12 10 108 108 108
3 12 10 108 108 108
4 12 10 108 108 108
5 12 10 108 108 108
6 12 10 108 108 108
7 12 10 108 108 108
8 12 10 108 108 108
9 12 10 108 108 108
10 12 10 108 108 108
11 12 10 108 108 108
12 12 10 108 108 108
13 12 10 108 108 108
14 12 10 144 144 144
-15 13 10 144 144 144
-14 13 10 108 108 108
-13 13 10 108 108 108
-12 13 10 108 108 108
-11 13 10 108 108 108
-10 13 10 108 108 108
-9 13 10 108 108 108
-8 13 10 108 108 108
-7 13 10 108 108 108
-6 13 10 108 108 108
-5 13 10 108 108 108
-4 13 10 108 108 108
-3 13 10 108 108 108
-2 13 10 108 108 108
-1 13 10 108 108 108
0 13 10 108 108 108
1 13 10 108 108 108
2 13 10 108 108 108
3 13 10 108 108 108
4 13 10 108 108 108
5 13 10 108 108 108
6 13 10 108 108 108
7 13 10 108 108 108
8 13 10 108 108 108
9 13 10 108 108 108
10 13 10 108 108 108
11 13 10 108 108 108
12 13 10 108 108 108
13 13 10 108 108 108
14 13 10 144 144 144
-15 14 10 144 144 144
-14 14 10 144 144 144
-13 14 10 144 144 144
-12 14 10 144 144 144
-11 14 10 144 144 144
-10 14 10 144 144 144
-9 14 10 144 144 144
-8 14 10 144 144 144
-7 14 10 144 144 144
-6 14 10 144 144 144
-5 14 10 144 144 144
-4 14 10 144 144 144
-3 14 10 144 144 144
-2 14 10 144 144 144
-1 14 10 144 144 144
0 14 10 144 144 144
1 14 10 144 144 144
2 14 10 144 144 144
3 14 10 144 144 144
4 14 10 144 144 144
5 14 10 144 144 144
6 14 10 144 144 144
7 14 10 144 144 144
8 14 10 144 144 144
9 14 10 144 144 144
10 14 10 144 144 144
11 14 10 144 144 144
12 14 10 144 144 144
13 14 10 144 144 144
14 14 10 144 144 144
-15 -15 11 144 144 144
-14 -15 11 144 144 144
-13 -15 11 144 144 144
-12 -15 11 144 144 144
-11 -15 11 144 144 144
-10 -15 11 144 144 144
-9 -15 11 144 144 144
-8 -15 11 144 144 144
-7 -15 11 144 144 144
-6 -15 11 144 144 144
-5 -15 11 144 144 144
-4 -15 11 144 144 144
-3 -15 11 144 144 144
-2 -15 11 144 144 144
-1 -15 11 144 144 144
0 -15 11 144 144 144
1 -15 11 144 144 144
2 -15 11 144 144 144
3 -15 11 144 144 144
4 -15 11 144 144 144
5 -15 11 144 144 144
6 -15 11 144 144 144
7 -15 11 144 144 144
8 -15 11 144 144 144
9 -15 11 144 144 144
10 -15 11 144 144 144
11 -15 11 144 144 144
12 -15 11 144 144 144
13 -15 11 144 144 144
14 -15 11 144 144 144
-15 -14 11 144 144 144
-14 -14 11 108 108 108
-13 -14 11 108 108 108
-12 -14 11 108 108 108
-11 -14 11 108 108 108
-10 -14 11 108 108 108
-9 -14 11 108 108 108
-8 -14 11 108 108 108
-7 -14 11 108 108 108
-6 -14 11 108 108 108
-5 -14 11 108 108 108
-4 -14 11 108 108 108
-3 -14 11 108 108 108
-2 -14 11 108 108 108
-1 -14 11 108 108 108
0 -14 11 108 108 108
1 -14 11 108 108 108
2 -14 11 108 108 108
3 -14 11 108 108 108
4 -14 11 108 108 108
5 -14 11 108 108 108
6 -14 11 108 108 108
7 -14 11 108 108 108
8 -14 11 108 108 108
9 -14 11 108 108 108
10 -14 11 108 108 108
11 -14 11 108 108 108
12 -14 11 108 108 108
13 -14 11 108 108 108
14 -14 11 144 144 144
-15 -13 11 144 144 144
-14 -13 11 108 108 108
-13 -13 11 108 108 108
-12 -13 11 108 108 108
-11 -13 11 108 108 108
-10 -13 11 108 108 108
-9 -13 11 108 108 108
-8 -13 11 108 108 108
-7 -13 11 108 108 108
-6 -13 11 108 108 108
-5 -13 11 108 108 108
-4 -13 11 108 108 108
-3 -13 11 108 108 108
-2 -13 11 108 108 108
-1 -13 11 108 108 108
0 -13 11 108 108 108
1 -13 11 108 108 108
2 -13 11 108 108 108
3 -13 11 108 108 108
4 -13 11 108 108 108
5 -13 11 108 108 108
6 -13 11 108 108 108
7 -13 11 108 108 108
8 -13 11 108 108 108
9 -13 11 108 108 108
10 -13 11 108 108 108
11 -13 11 108 108 108
12 -13 11 108 108 108
13 -13 11 108 108 108
14 -13 11 144 144 144
-15 -12 11 144 144 144
-14 -12 11 108 108 108
-13 -12 11 108 108 108
-12 -12 11 64 64 64
-11 -12 11 64 64 64
-8 -12 11 100 72 24
-7 -12 11 100 72 24
-6 -12 11 100 72 24
-5 -12 11 100 72 24
-4 -12 11 100 72 24
-1 -12 11 64 64 64
0 -12 11 64 64 64
3 -12 11 100 72 24
4 -12 11 100 72 24
5 -12 11 100 72 24
6 -12 11 100 72 24
7 -12 11 100 72 24
10 -12 11 64 64 64
11 -12 11 64 64 64
12 -12 11 108 108 108
13 -12 11 108 108 108
14 -12 11 144 144 144
-15 -11 11 144 144 144
-14 -11 11 108 108 108
-13 -11 11 108 108 108
-12 -11 11 64 64 64
-11 -11 11 64 64 64
-1 -11 11 64 64 64
0 -11 11 64 64 64
10 -11 11 64 64 64
11 -11 11 64 64 64
12 -11 11 108 108 108
13 -11 11 108 108 108
14 -11 11 144 144 144
-15 -10 11 144 144 144
-14 -10 11 108 108 108
-13 -10 11 108 108 108
12 -10 11 108 108 108
13 -10 11 108 108 108
14 -10 11 144 144 144
-15 -9 11 144 144 144
-14 -9 11 108 108 108
-13 -9 11 108 108 108
12 -9 11 108 108 108
13 -9 11 108 108 108
14 -9 11 144 144 144
-15 -8 11 144 144 144
-14 -8 11 108 108 108
-13 -8 11 108 108 108
11 -8 11 100 72 24
12 -8 11 108 108 108
13 -8 11 108 108 108
14 -8 11 144 144 144
-15 -7 11 144 144 144
-14 -7 11 108 108 108
-13 -7 11 108 108 108
11 -7 11 100 72 24
12 -7 11 108 108 108
13 -7 11 108 108 108
14 -7 11 144 144 144
-15 -6 11 144 144 144
-14 -6 11 108 108 108
-13 -6 11 108 108 108
-12 -6 11 64 64 64
-11 -6 11 64 64 64
11 -6 11 100 72 24
12 -6 11 108 108 108
13 -6 11 108 108 108
14 -6 11 144 144 144
-15 -5 11 144 144 144
-14 -5 11 108 108 108
-13 -5 11 108 108 108
-12 -5 11 64 64 64
-11 -5 11 64 64 64
11 -5 11 100 72 24
12 -5 11 108 108 108
13 -5 11 108 108 108
14 -5 11 144 144 144
-15 -4 11 156 32 32
-14 -4 11 108 108 108
-13 -4 11 108 108 108
-12 -4 11 108 108 108
-11 -4 11 108 108 108
-10 -4 11 108 108 108
-9 -4 11 108 108 108
11 -4 11 100 72 24
12 -4 11 108 108 108
13 -4 11 108 108 108
14 -4 11 144 144 144
-9 -3 11 108 108 108
12 -3 11 108 108 108
13 -3 11 108 108 108
14 -3 11 144 144 144
-9 -2 11 108 108 108
12 -2 11 108 108 108
13 -2 11 108 108 108
14 -2 11 144 144 144
-9 -1 11 108 108 108
10 -1 11 64 64 64
11 -1 11 64 64 64
12 -1 11 108 108 108
13 -1 11 108 108 108
14 -1 11 144 144 144
-9 0 11 108 108 108
10 0 11 64 64 64
11 0 11 64 64 64
12 0 11 108 108 108
13 0 11 108 108 108
14 0 11 144 144 144
