ply
format ascii 1.0
comment : MagicaVoxel @ Ephtracy
element vertex 1640
property float x
property float y
property float z
property uchar red
property uchar green
property uchar blue
end_header
-10 -10 0 160 132 68
-9 -10 0 160 132 68
-8 -10 0 160 132 68
-7 -10 0 160 132 68
-6 -10 0 160 132 68
-5 -10 0 160 132 68
-4 -10 0 160 132 68
-3 -10 0 160 132 68
-2 -10 0 160 132 68
-1 -10 0 160 132 68
0 -10 0 160 132 68
1 -10 0 160 132 68
2 -10 0 160 132 68
3 -10 0 160 132 68
4 -10 0 160 132 68
5 -10 0 132 104 48
6 -10 0 160 132 68
7 -10 0 160 132 68
8 -10 0 160 132 68
9 -10 0 160 132 68
-10 -9 0 160 132 68
-9 -9 0 160 132 68
-8 -9 0 160 132 68
-7 -9 0 160 132 68
-6 -9 0 160 132 68
-5 -9 0 160 132 68
-4 -9 0 160 132 68
-3 -9 0 160 132 68
-2 -9 0 160 132 68
-1 -9 0 160 132 68
0 -9 0 160 132 68
1 -9 0 160 132 68
2 -9 0 160 132 68
3 -9 0 160 132 68
4 -9 0 184 156 88
5 -9 0 132 104 48
6 -9 0 160 132 68
7 -9 0 160 132 68
8 -9 0 160 132 68
9 -9 0 160 132 68
-10 -8 0 160 132 68
-9 -8 0 160 132 68
-8 -8 0 160 132 68
-7 -8 0 160 132 68
-6 -8 0 160 132 68
-5 -8 0 160 132 68
-4 -8 0 160 132 68
-3 -8 0 160 132 68
-2 -8 0 160 132 68
-1 -8 0 160 132 68
0 -8 0 160 132 68
1 -8 0 160 132 68
2 -8 0 184 156 88
3 -8 0 184 156 88
4 -8 0 184 156 88
5 -8 0 132 104 48
6 -8 0 160 132 68
7 -8 0 160 132 68
8 -8 0 160 132 68
9 -8 0 160 132 68
-10 -7 0 132 104 48
-9 -7 0 132 104 48
-8 -7 0 132 104 48
-7 -7 0 132 104 48
-6 -7 0 132 104 48
-5 -7 0 132 104 48
-4 -7 0 132 104 48
-3 -7 0 132 104 48
-2 -7 0 132 104 48
-1 -7 0 132 104 48
0 -7 0 132 104 48
1 -7 0 132 104 48
2 -7 0 132 104 48
3 -7 0 132 104 48
4 -7 0 132 104 48
5 -7 0 132 104 48
6 -7 0 132 104 48
7 -7 0 132 104 48
8 -7 0 132 104 48
9 -7 0 132 104 48
-10 -6 0 160 132 68
-9 -6 0 160 132 68
-8 -6 0 160 132 68
-7 -6 0 132 104 48
-6 -6 0 160 132 68
-5 -6 0 160 132 68
-4 -6 0 160 132 68
-3 -6 0 160 132 68
-2 -6 0 160 132 68
-1 -6 0 160 132 68
0 -6 0 160 132 68
1 -6 0 160 132 68
2 -6 0 160 132 68
3 -6 0 160 132 68
4 -6 0 160 132 68
5 -6 0 160 132 68
6 -6 0 160 132 68
7 -6 0 132 104 48
8 -6 0 160 132 68
9 -6 0 160 132 68
-10 -5 0 160 132 68
-9 -5 0 160 132 68
-8 -5 0 184 156 88
-7 -5 0 132 104 48
-6 -5 0 160 132 68
-5 -5 0 160 132 68
-4 -5 0 160 132 68
-3 -5 0 160 132 68
-2 -5 0 160 132 68
-1 -5 0 160 132 68
0 -5 0 160 132 68
1 -5 0 160 132 68
2 -5 0 160 132 68
3 -5 0 160 132 68
4 -5 0 160 132 68
5 -5 0 160 132 68
6 -5 0 184 156 88
7 -5 0 132 104 48
8 -5 0 160 132 68
9 -5 0 160 132 68
-10 -4 0 184 156 88
-9 -4 0 184 156 88
-8 -4 0 184 156 88
-7 -4 0 132 104 48
-6 -4 0 160 132 68
-5 -4 0 160 132 68
-4 -4 0 160 132 68
-3 -4 0 160 132 68
-2 -4 0 160 132 68
-1 -4 0 160 132 68
0 -4 0 160 132 68
1 -4 0 160 132 68
2 -4 0 160 132 68
3 -4 0 160 132 68
4 -4 0 184 156 88
5 -4 0 184 156 88
6 -4 0 184 156 88
7 -4 0 132 104 48
8 -4 0 160 132 68
9 -4 0 160 132 68
-10 -3 0 132 104 48
-9 -3 0 132 104 48
-8 -3 0 132 104 48
-7 -3 0 132 104 48
-6 -3 0 132 104 48
-5 -3 0 132 104 48
-4 -3 0 132 104 48
-3 -3 0 132 104 48
-2 -3 0 132 104 48
-1 -3 0 132 104 48
0 -3 0 132 104 48
1 -3 0 132 104 48
2 -3 0 132 104 48
3 -3 0 132 104 48
4 -3 0 132 104 48
5 -3 0 132 104 48
6 -3 0 132 104 48
7 -3 0 132 104 48
8 -3 0 132 104 48
9 -3 0 132 104 48
-10 -2 0 160 132 68
-9 -2 0 160 132 68
-8 -2 0 160 132 68
-7 -2 0 160 132 68
-6 -2 0 160 132 68
-5 -2 0 160 132 68
-4 -2 0 160 132 68
-3 -2 0 160 132 68
-2 -2 0 160 132 68
-1 -2 0 160 132 68
0 -2 0 160 132 68
1 -2 0 132 104 48
2 -2 0 160 132 68
3 -2 0 160 132 68
4 -2 0 160 132 68
5 -2 0 160 132 68
6 -2 0 160 132 68
7 -2 0 160 132 68
8 -2 0 160 132 68
9 -2 0 160 132 68
-10 -1 0 160 132 68
-9 -1 0 160 132 68
-8 -1 0 160 132 68
-7 -1 0 160 132 68
-6 -1 0 160 132 68
-5 -1 0 160 132 68
-4 -1 0 160 132 68
-3 -1 0 160 132 68
-2 -1 0 160 132 68
-1 -1 0 160 132 68
0 -1 0 184 156 88
1 -1 0 132 104 48
2 -1 0 160 132 68
3 -1 0 160 132 68
4 -1 0 160 132 68
5 -1 0 160 132 68
6 -1 0 160 132 68
7 -1 0 160 132 68
8 -1 0 160 132 68
9 -1 0 160 132 68
-10 0 0 160 132 68
-9 0 0 160 132 68
-8 0 0 160 132 68
-7 0 0 160 132 68
-6 0 0 160 132 68
-5 0 0 160 132 68
-4 0 0 160 132 68
-3 0 0 160 132 68
-2 0 0 184 156 88
-1 0 0 184 156 88
0 0 0 184 156 88
1 0 0 132 104 48
2 0 0 160 132 68
3 0 0 160 132 68
4 0 0 160 132 68
5 0 0 160 132 68
6 0 0 160 132 68
7 0 0 160 132 68
8 0 0 160 132 68
9 0 0 160 132 68
-10 1 0 132 104 48
-9 1 0 132 104 48
-8 1 0 132 104 48
-7 1 0 132 104 48
-6 1 0 132 104 48
-5 1 0 132 104 48
-4 1 0 132 104 48
-3 1 0 132 104 48
-2 1 0 132 104 48
-1 1 0 132 104 48
0 1 0 132 104 48
1 1 0 132 104 48
2 1 0 132 104 48
3 1 0 132 104 48
4 1 0 132 104 48
5 1 0 132 104 48
6 1 0 132 104 48
7 1 0 132 104 48
8 1 0 132 104 48
9 1 0 132 104 48
-10 2 0 160 132 68
-9 2 0 160 132 68
-8 2 0 160 132 68
-7 2 0 160 132 68
-6 2 0 160 132 68
-5 2 0 160 132 68
-4 2 0 160 132 68
-3 2 0 132 104 48
-2 2 0 160 132 68
-1 2 0 160 132 68
0 2 0 160 132 68
1 2 0 160 132 68
2 2 0 160 132 68
3 2 0 160 132 68
4 2 0 160 132 68
5 2 0 160 132 68
6 2 0 160 132 68
7 2 0 132 104 48
8 2 0 160 132 68
9 2 0 160 132 68
-10 3 0 160 132 68
-9 3 0 160 132 68
-8 3 0 160 132 68
-7 3 0 160 132 68
-6 3 0 160 132 68
-5 3 0 160 132 68
-4 3 0 160 132 68
-3 3 0 132 104 48
-2 3 0 160 132 68
-1 3 0 160 132 68
0 3 0 160 132 68
1 3 0 160 132 68
2 3 0 160 132 68
3 3 0 160 132 68
4 3 0 160 132 68
5 3 0 160 132 68
6 3 0 184 156 88
7 3 0 132 104 48
8 3 0 160 132 68
9 3 0 160 132 68
-10 4 0 160 132 68
-9 4 0 160 132 68
-8 4 0 160 132 68
-7 4 0 160 132 68
-6 4 0 160 132 68
-5 4 0 160 132 68
-4 4 0 160 132 68
-3 4 0 132 104 48
-2 4 0 160 132 68
-1 4 0 160 132 68
0 4 0 160 132 68
1 4 0 160 132 68
2 4 0 160 132 68
3 4 0 160 132 68
4 4 0 184 156 88
5 4 0 184 156 88
6 4 0 184 156 88
7 4 0 132 104 48
8 4 0 160 132 68
9 4 0 160 132 68
-10 5 0 132 104 48
-9 5 0 132 104 48
-8 5 0 132 104 48
-7 5 0 132 104 48
-6 5 0 132 104 48
-5 5 0 132 104 48
-4 5 0 132 104 48
-3 5 0 132 104 48
-2 5 0 132 104 48
-1 5 0 132 104 48
0 5 0 132 104 48
1 5 0 132 104 48
2 5 0 132 104 48
3 5 0 132 104 48
4 5 0 132 104 48
5 5 0 132 104 48
6 5 0 132 104 48
7 5 0 132 104 48
8 5 0 132 104 48
9 5 0 132 104 48
-10 6 0 160 132 68
-9 6 0 132 104 48
-8 6 0 160 132 68
-7 6 0 160 132 68
-6 6 0 160 132 68
-5 6 0 160 132 68
-4 6 0 160 132 68
-3 6 0 160 132 68
-2 6 0 160 132 68
-1 6 0 160 132 68
0 6 0 160 132 68
1 6 0 160 132 68
2 6 0 160 132 68
3 6 0 160 132 68
4 6 0 132 104 48
5 6 0 160 132 68
6 6 0 160 132 68
7 6 0 160 132 68
8 6 0 160 132 68
9 6 0 160 132 68
-10 7 0 160 132 68
-9 7 0 132 104 48
-8 7 0 160 132 68
-7 7 0 160 132 68
-6 7 0 160 132 68
-5 7 0 160 132 68
-4 7 0 160 132 68
-3 7 0 160 132 68
-2 7 0 160 132 68
-1 7 0 160 132 68
0 7 0 160 132 68
1 7 0 160 132 68
2 7 0 160 132 68
3 7 0 184 156 88
4 7 0 132 104 48
5 7 0 160 132 68
6 7 0 160 132 68
7 7 0 160 132 68
8 7 0 160 132 68
9 7 0 160 132 68
-10 8 0 184 156 88
-9 8 0 132 104 48
-8 8 0 160 132 68
-7 8 0 160 132 68
-6 8 0 160 132 68
-5 8 0 160 132 68
-4 8 0 160 132 68
-3 8 0 160 132 68
-2 8 0 160 132 68
-1 8 0 160 132 68
0 8 0 160 132 68
1 8 0 184 156 88
2 8 0 184 156 88
3 8 0 184 156 88
4 8 0 132 104 48
5 8 0 160 132 68
6 8 0 160 132 68
7 8 0 160 132 68
8 8 0 184 156 88
9 8 0 184 156 88
-10 9 0 132 104 48
-9 9 0 132 104 48
-8 9 0 132 104 48
-7 9 0 132 104 48
-6 9 0 132 104 48
-5 9 0 132 104 48
-4 9 0 132 104 48
-3 9 0 132 104 48
-2 9 0 132 104 48
-1 9 0 132 104 48
0 9 0 132 104 48
1 9 0 132 104 48
2 9 0 132 104 48
3 9 0 132 104 48
4 9 0 132 104 48
5 9 0 132 104 48
6 9 0 132 104 48
7 9 0 132 104 48
8 9 0 132 104 48
9 9 0 132 104 48
-10 -10 1 144 144 144
-9 -10 1 144 144 144
-8 -10 1 144 144 144
-7 -10 1 144 144 144
-6 -10 1 108 108 108
-5 -10 1 144 144 144
-4 -10 1 144 144 144
-3 -10 1 144 144 144
-2 -10 1 144 144 144
-1 -10 1 144 144 144
0 -10 1 144 144 144
1 -10 1 144 144 144
2 -10 1 132 104 48
7 -10 1 132 104 48
8 -10 1 144 144 144
9 -10 1 144 144 144
-10 -9 1 144 144 144
9 -9 1 144 144 144
-10 -8 1 144 144 144
9 -8 1 144 144 144
-10 -7 1 144 144 144
9 -7 1 144 144 144
-10 -6 1 144 144 144
-6 -6 1 144 144 144
-5 -6 1 144 144 144
4 -6 1 144 144 144
5 -6 1 144 144 144
9 -6 1 144 144 144
-10 -5 1 144 144 144
-6 -5 1 144 144 144
-5 -5 1 144 144 144
4 -5 1 144 144 144
5 -5 1 144 144 144
9 -5 1 144 144 144
-10 -4 1 108 108 108
9 -4 1 108 108 108
-10 -3 1 144 144 144
9 -3 1 144 144 144
-10 -2 1 144 144 144
9 -2 1 144 144 144
-10 -1 1 144 144 144
9 -1 1 144 144 144
-10 0 1 144 144 144
9 0 1 144 144 144
-10 1 1 144 144 144
9 1 1 144 144 144
-10 2 1 144 144 144
9 2 1 144 144 144
-10 3 1 144 144 144
9 3 1 144 144 144
-10 4 1 144 144 144
-6 4 1 144 144 144
-5 4 1 144 144 144
4 4 1 144 144 144
5 4 1 144 144 144
9 4 1 144 144 144
-10 5 1 144 144 144
-6 5 1 144 144 144
-5 5 1 144 144 144
4 5 1 144 144 144
5 5 1 144 144 144
9 5 1 144 144 144
-10 6 1 108 108 108
9 6 1 108 108 108
-10 7 1 144 144 144
9 7 1 144 144 144
-10 8 1 144 144 144
9 8 1 144 144 144
-10 9 1 144 144 144
-9 9 1 144 144 144
-8 9 1 132 104 48
-3 9 1 132 104 48
-2 9 1 144 144 144
-1 9 1 144 144 144
0 9 1 144 144 144
1 9 1 144 144 144
2 9 1 144 144 144
3 9 1 144 144 144
4 9 1 108 108 108
5 9 1 144 144 144
6 9 1 144 144 144
7 9 1 144 144 144
8 9 1 144 144 144
9 9 1 144 144 144
-10 -10 2 144 144 144
-9 -10 2 144 144 144
-8 -10 2 144 144 144
-7 -10 2 144 144 144
-6 -10 2 108 108 108
-5 -10 2 144 144 144
-4 -10 2 144 144 144
-3 -10 2 144 144 144
-2 -10 2 144 144 144
-1 -10 2 144 144 144
0 -10 2 144 144 144
1 -10 2 144 144 144
2 -10 2 132 104 48
7 -10 2 132 104 48
8 -10 2 144 144 144
9 -10 2 144 144 144
-10 -9 2 144 144 144
9 -9 2 144 144 144
-10 -8 2 144 144 144
9 -8 2 144 144 144
-10 -7 2 144 144 144
9 -7 2 144 144 144
-10 -6 2 144 144 144
-6 -6 2 144 144 144
-5 -6 2 144 144 144
4 -6 2 144 144 144
5 -6 2 144 144 144
9 -6 2 144 144 144
-10 -5 2 144 144 144
-6 -5 2 144 144 144
-5 -5 2 144 144 144
4 -5 2 144 144 144
5 -5 2 144 144 144
9 -5 2 144 144 144
-10 -4 2 108 108 108
9 -4 2 108 108 108
-10 -3 2 144 144 144
9 -3 2 144 144 144
-10 -2 2 144 144 144
9 -2 2 144 144 144
-10 -1 2 144 144 144
9 -1 2 144 144 144
-10 0 2 144 144 144
9 0 2 144 144 144
-10 1 2 144 144 144
9 1 2 144 144 144
-10 2 2 144 144 144
9 2 2 144 144 144
-10 3 2 144 144 144
9 3 2 144 144 144
-10 4 2 144 144 144
-6 4 2 144 144 144
-5 4 2 144 144 144
4 4 2 144 144 144
5 4 2 144 144 144
9 4 2 144 144 144
-10 5 2 144 144 144
-6 5 2 144 144 144
-5 5 2 144 144 144
4 5 2 144 144 144
5 5 2 144 144 144
9 5 2 144 144 144
-10 6 2 108 108 108
9 6 2 108 108 108
-10 7 2 144 144 144
9 7 2 144 144 144
-10 8 2 144 144 144
9 8 2 144 144 144
-10 9 2 144 144 144
-9 9 2 144 144 144
-8 9 2 132 104 48
-3 9 2 132 104 48
-2 9 2 144 144 144
-1 9 2 144 144 144
0 9 2 144 144 144
1 9 2 144 144 144
2 9 2 144 144 144
3 9 2 144 144 144
4 9 2 108 108 108
5 9 2 144 144 144
6 9 2 144 144 144
7 9 2 144 144 144
8 9 2 144 144 144
9 9 2 144 144 144
-10 -10 3 108 108 108
-9 -10 3 108 108 108
-8 -10 3 108 108 108
-7 -10 3 108 108 108
-6 -10 3 108 108 108
-5 -10 3 108 108 108
-4 -10 3 108 108 108
-3 -10 3 108 108 108
-2 -10 3 108 108 108
-1 -10 3 108 108 108
0 -10 3 108 108 108
1 -10 3 108 108 108
2 -10 3 132 104 48
7 -10 3 132 104 48
8 -10 3 108 108 108
9 -10 3 108 108 108
-10 -9 3 108 108 108
9 -9 3 108 108 108
-10 -8 3 108 108 108
9 -8 3 108 108 108
-10 -7 3 108 108 108
9 -7 3 108 108 108
-10 -6 3 108 108 108
-6 -6 3 144 144 144
-5 -6 3 144 144 144
4 -6 3 144 144 144
5 -6 3 144 144 144
9 -6 3 108 108 108
-10 -5 3 108 108 108
-6 -5 3 144 144 144
-5 -5 3 144 144 144
4 -5 3 144 144 144
5 -5 3 144 144 144
9 -5 3 108 108 108
-10 -4 3 108 108 108
9 -4 3 108 108 108
-10 -3 3 108 108 108
9 -3 3 108 108 108
-10 -2 3 108 108 108
9 -2 3 108 108 108
-10 -1 3 108 108 108
9 -1 3 108 108 108
-10 0 3 108 108 108
9 0 3 108 108 108
-10 1 3 108 108 108
9 1 3 108 108 108
-10 2 3 108 108 108
9 2 3 108 108 108
-10 3 3 108 108 108
9 3 3 108 108 108
-10 4 3 108 108 108
-6 4 3 144 144 144
-5 4 3 144 144 144
4 4 3 144 144 144
5 4 3 144 144 144
9 4 3 108 108 108
-10 5 3 108 108 108
-6 5 3 144 144 144
-5 5 3 144 144 144
4 5 3 144 144 144
5 5 3 144 144 144
9 5 3 108 108 108
-10 6 3 108 108 108
9 6 3 108 108 108
-10 7 3 108 108 108
9 7 3 108 108 108
-10 8 3 108 108 108
9 8 3 108 108 108
-10 9 3 108 108 108
-9 9 3 108 108 108
-8 9 3 132 104 48
-3 9 3 132 104 48
-2 9 3 108 108 108
-1 9 3 108 108 108
0 9 3 108 108 108
1 9 3 108 108 108
2 9 3 108 108 108
3 9 3 108 108 108
4 9 3 108 108 108
5 9 3 108 108 108
6 9 3 108 108 108
7 9 3 108 108 108
8 9 3 108 108 108
9 9 3 108 108 108
-10 -10 4 144 144 144
-9 -10 4 144 144 144
-8 -10 4 144 144 144
-7 -10 4 144 144 144
-6 -10 4 144 144 144
-5 -10 4 144 144 144
-4 -10 4 108 108 108
-3 -10 4 144 144 144
-2 -10 4 144 144 144
-1 -10 4 144 144 144
0 -10 4 144 144 144
1 -10 4 144 144 144
2 -10 4 132 104 48
7 -10 4 132 104 48
8 -10 4 144 144 144
9 -10 4 144 144 144
-10 -9 4 144 144 144
9 -9 4 144 144 144
-10 -8 4 144 144 144
9 -8 4 144 144 144
-10 -7 4 108 108 108
9 -7 4 108 108 108
-10 -6 4 144 144 144
-6 -6 4 144 144 144
-5 -6 4 144 144 144
4 -6 4 144 144 144
5 -6 4 144 144 144
9 -6 4 144 144 144
-10 -5 4 144 144 144
-6 -5 4 144 144 144
-5 -5 4 144 144 144
4 -5 4 144 144 144
5 -5 4 144 144 144
9 -5 4 144 144 144
-10 -4 4 144 144 144
9 -4 4 144 144 144
-10 -3 4 144 144 144
9 -3 4 144 144 144
-10 -2 4 144 144 144
9 -2 4 144 144 144
-10 -1 4 144 144 144
9 -1 4 144 144 144
-10 0 4 144 144 144
9 0 4 144 144 144
-10 1 4 144 144 144
9 1 4 144 144 144
-10 2 4 144 144 144
9 2 4 144 144 144
-10 3 4 108 108 108
9 3 4 144 144 144
-10 4 4 144 144 144
-6 4 4 144 144 144
-5 4 4 144 144 144
4 4 4 144 144 144
5 4 4 144 144 144
9 4 4 108 108 108
-10 5 4 144 144 144
-6 5 4 144 144 144
-5 5 4 144 144 144
4 5 4 144 144 144
5 5 4 144 144 144
9 5 4 144 144 144
-10 6 4 144 144 144
9 6 4 144 144 144
-10 7 4 144 144 144
9 7 4 144 144 144
-10 8 4 144 144 144
9 8 4 144 144 144
-10 9 4 144 144 144
-9 9 4 144 144 144
-8 9 4 132 104 48
-3 9 4 132 104 48
-2 9 4 144 144 144
-1 9 4 144 144 144
0 9 4 144 144 144
1 9 4 144 144 144
2 9 4 108 108 108
3 9 4 144 144 144
4 9 4 144 144 144
5 9 4 144 144 144
6 9 4 144 144 144
7 9 4 144 144 144
8 9 4 144 144 144
9 9 4 144 144 144
-10 -10 5 144 144 144
-9 -10 5 144 144 144
-8 -10 5 144 144 144
-7 -10 5 144 144 144
-6 -10 5 144 144 144
-5 -10 5 144 144 144
-4 -10 5 108 108 108
-3 -10 5 144 144 144
-2 -10 5 144 144 144
-1 -10 5 144 144 144
0 -10 5 144 144 144
1 -10 5 144 144 144
2 -10 5 132 104 48
7 -10 5 132 104 48
8 -10 5 144 144 144
9 -10 5 144 144 144
-10 -9 5 144 144 144
9 -9 5 144 144 144
-10 -8 5 144 144 144
9 -8 5 144 144 144
-10 -7 5 108 108 108
9 -7 5 108 108 108
-10 -6 5 144 144 144
-6 -6 5 144 144 144
-5 -6 5 144 144 144
4 -6 5 144 144 144
5 -6 5 144 144 144
9 -6 5 144 144 144
-10 -5 5 144 144 144
-6 -5 5 144 144 144
-5 -5 5 144 144 144
4 -5 5 144 144 144
5 -5 5 144 144 144
9 -5 5 144 144 144
-10 -4 5 144 144 144
9 -4 5 144 144 144
-10 -3 5 144 144 144
9 -3 5 144 144 144
-10 -2 5 144 144 144
9 -2 5 144 144 144
-10 -1 5 144 144 144
9 -1 5 144 144 144
-10 0 5 144 144 144
9 0 5 144 144 144
-10 1 5 144 144 144
9 1 5 144 144 144
-10 2 5 144 144 144
9 2 5 144 144 144
-10 3 5 108 108 108
9 3 5 144 144 144
-10 4 5 144 144 144
-6 4 5 144 144 144
-5 4 5 144 144 144
4 4 5 144 144 144
5 4 5 144 144 144
9 4 5 108 108 108
-10 5 5 144 144 144
-6 5 5 144 144 144
-5 5 5 144 144 144
4 5 5 144 144 144
5 5 5 144 144 144
9 5 5 144 144 144
-10 6 5 144 144 144
9 6 5 144 144 144
-10 7 5 144 144 144
9 7 5 144 144 144
-10 8 5 144 144 144
9 8 5 144 144 144
-10 9 5 144 144 144
-9 9 5 144 144 144
-8 9 5 132 104 48
-3 9 5 132 104 48
-2 9 5 144 144 144
-1 9 5 144 144 144
0 9 5 144 144 144
1 9 5 144 144 144
2 9 5 108 108 108
3 9 5 144 144 144
4 9 5 144 144 144
5 9 5 144 144 144
6 9 5 144 144 144
7 9 5 144 144 144
8 9 5 144 144 144
9 9 5 144 144 144
-10 -10 6 108 108 108
-9 -10 6 108 108 108
-8 -10 6 108 108 108
-7 -10 6 108 108 108
-6 -10 6 108 108 108
-5 -10 6 108 108 108
-4 -10 6 108 108 108
-3 -10 6 108 108 108
-2 -10 6 108 108 108
-1 -10 6 108 108 108
0 -10 6 108 108 108
1 -10 6 108 108 108
2 -10 6 132 104 48
3 -10 6 132 104 48
4 -10 6 132 104 48
5 -10 6 132 104 48
6 -10 6 132 104 48
7 -10 6 132 104 48
8 -10 6 108 108 108
9 -10 6 108 108 108
-10 -9 6 108 108 108
9 -9 6 108 108 108
-10 -8 6 108 108 108
9 -8 6 108 108 108
-10 -7 6 108 108 108
9 -7 6 108 108 108
-10 -6 6 108 108 108
-6 -6 6 144 144 144
-5 -6 6 144 144 144
-4 -6 6 108 108 108
3 -6 6 108 108 108
4 -6 6 144 144 144
5 -6 6 144 144 144
9 -6 6 108 108 108
-10 -5 6 108 108 108
-6 -5 6 144 144 144
-5 -5 6 144 144 144
-4 -5 6 108 108 108
3 -5 6 108 108 108
4 -5 6 144 144 144
5 -5 6 144 144 144
9 -5 6 108 108 108
-10 -4 6 108 108 108
-6 -4 6 108 108 108
-5 -4 6 108 108 108
4 -4 6 108 108 108
5 -4 6 108 108 108
9 -4 6 108 108 108
-10 -3 6 108 108 108
9 -3 6 108 108 108
-10 -2 6 108 108 108
9 -2 6 108 108 108
-10 -1 6 108 108 108
9 -1 6 108 108 108
-10 0 6 108 108 108
9 0 6 108 108 108
-10 1 6 108 108 108
9 1 6 108 108 108
-10 2 6 108 108 108
9 2 6 108 108 108
-10 3 6 108 108 108
-6 3 6 108 108 108
-5 3 6 108 108 108
4 3 6 108 108 108
5 3 6 108 108 108
9 3 6 108 108 108
-10 4 6 108 108 108
-6 4 6 144 144 144
-5 4 6 144 144 144
-4 4 6 108 108 108
3 4 6 108 108 108
4 4 6 144 144 144
5 4 6 144 144 144
9 4 6 108 108 108
-10 5 6 108 108 108
-6 5 6 144 144 144
-5 5 6 144 144 144
-4 5 6 108 108 108
3 5 6 108 108 108
4 5 6 144 144 144
5 5 6 144 144 144
9 5 6 108 108 108
-10 6 6 108 108 108
9 6 6 108 108 108
-10 7 6 108 108 108
9 7 6 108 108 108
-10 8 6 108 108 108
9 8 6 108 108 108
-10 9 6 108 108 108
-9 9 6 108 108 108
-8 9 6 132 104 48
-7 9 6 132 104 48
-6 9 6 132 104 48
-5 9 6 132 104 48
-4 9 6 132 104 48
-3 9 6 132 104 48
-2 9 6 108 108 108
-1 9 6 108 108 108
0 9 6 108 108 108
1 9 6 108 108 108
2 9 6 108 108 108
3 9 6 108 108 108
4 9 6 108 108 108
5 9 6 108 108 108
6 9 6 108 108 108
7 9 6 108 108 108
8 9 6 108 108 108
9 9 6 108 108 108
-10 -10 7 144 144 144
-9 -10 7 144 144 144
-8 -10 7 144 144 144
-7 -10 7 108 108 108
-6 -10 7 144 144 144
-5 -10 7 144 144 144
-4 -10 7 144 144 144
-3 -10 7 144 144 144
-2 -10 7 144 144 144
-1 -10 7 144 144 144
0 -10 7 144 144 144
1 -10 7 108 108 108
2 -10 7 144 144 144
3 -10 7 144 144 144
4 -10 7 144 144 144
5 -10 7 144 144 144
6 -10 7 144 144 144
7 -10 7 108 108 108
8 -10 7 144 144 144
9 -10 7 144 144 144
-10 -9 7 144 144 144
9 -9 7 144 144 144
-10 -8 7 144 144 144
9 -8 7 144 144 144
-10 -7 7 144 144 144
9 -7 7 144 144 144
-10 -6 7 144 144 144
-6 -6 7 144 144 144
-5 -6 7 144 144 144
-4 -6 7 108 108 108
-3 -6 7 108 108 108
2 -6 7 108 108 108
3 -6 7 108 108 108
4 -6 7 144 144 144
5 -6 7 144 144 144
9 -6 7 144 144 144
-10 -5 7 108 108 108
-6 -5 7 144 144 144
-5 -5 7 144 144 144
-4 -5 7 108 108 108
-3 -5 7 108 108 108
2 -5 7 108 108 108
3 -5 7 108 108 108
4 -5 7 144 144 144
5 -5 7 144 144 144
9 -5 7 144 144 144
-10 -4 7 144 144 144
-6 -4 7 108 108 108
-5 -4 7 108 108 108
4 -4 7 108 108 108
5 -4 7 108 108 108
9 -4 7 144 144 144
-10 -3 7 144 144 144
-6 -3 7 108 108 108
-5 -3 7 108 108 108
4 -3 7 108 108 108
5 -3 7 108 108 108
9 -3 7 144 144 144
-10 -2 7 144 144 144
9 -2 7 144 144 144
-10 -1 7 144 144 144
9 -1 7 108 108 108
-10 0 7 144 144 144
9 0 7 144 144 144
-10 1 7 144 144 144
9 1 7 144 144 144
-10 2 7 144 144 144
-6 2 7 108 108 108
-5 2 7 108 108 108
4 2 7 108 108 108
5 2 7 108 108 108
9 2 7 144 144 144
-10 3 7 144 144 144
-6 3 7 108 108 108
-5 3 7 108 108 108
4 3 7 108 108 108
5 3 7 108 108 108
9 3 7 144 144 144
-10 4 7 144 144 144
-6 4 7 144 144 144
-5 4 7 144 144 144
-4 4 7 108 108 108
-3 4 7 108 108 108
2 4 7 108 108 108
3 4 7 108 108 108
4 4 7 144 144 144
5 4 7 144 144 144
9 4 7 144 144 144
-10 5 7 108 108 108
-6 5 7 144 144 144
-5 5 7 144 144 144
-4 5 7 108 108 108
-3 5 7 108 108 108
2 5 7 108 108 108
3 5 7 108 108 108
4 5 7 144 144 144
5 5 7 144 144 144
9 5 7 144 144 144
-10 6 7 144 144 144
9 6 7 144 144 144
-10 7 7 144 144 144
9 7 7 108 108 108
-10 8 7 144 144 144
9 8 7 144 144 144
-10 9 7 144 144 144
-9 9 7 144 144 144
-8 9 7 144 144 144
-7 9 7 144 144 144
-6 9 7 144 144 144
-5 9 7 144 144 144
-4 9 7 144 144 144
-3 9 7 144 144 144
-2 9 7 144 144 144
-1 9 7 108 108 108
0 9 7 144 144 144
1 9 7 144 144 144
2 9 7 144 144 144
3 9 7 144 144 144
4 9 7 144 144 144
5 9 7 144 144 144
6 9 7 144 144 144
7 9 7 108 108 108
8 9 7 144 144 144
9 9 7 144 144 144
-10 -10 8 144 144 144
-9 -10 8 144 144 144
-8 -10 8 144 144 144
-7 -10 8 108 108 108
-6 -10 8 144 144 144
-5 -10 8 144 144 144
-4 -10 8 144 144 144
-3 -10 8 144 144 144
-2 -10 8 144 144 144
-1 -10 8 144 144 144
0 -10 8 144 144 144
1 -10 8 108 108 108
2 -10 8 144 144 144
3 -10 8 144 144 144
4 -10 8 144 144 144
5 -10 8 144 144 144
6 -10 8 144 144 144
7 -10 8 108 108 108
8 -10 8 144 144 144
9 -10 8 144 144 144
-10 -9 8 144 144 144
9 -9 8 144 144 144
-10 -8 8 144 144 144
9 -8 8 144 144 144
-10 -7 8 144 144 144
-7 -7 8 108 108 108
-6 -7 8 108 108 108
-5 -7 8 108 108 108
-4 -7 8 108 108 108
3 -7 8 108 108 108
4 -7 8 108 108 108
5 -7 8 108 108 108
6 -7 8 108 108 108
9 -7 8 144 144 144
-10 -6 8 144 144 144
-7 -6 8 108 108 108
-6 -6 8 144 144 144
-5 -6 8 144 144 144
-4 -6 8 108 108 108
-3 -6 8 108 108 108
-2 -6 8 108 108 108
-1 -6 8 108 108 108
0 -6 8 108 108 108
1 -6 8 108 108 108
2 -6 8 108 108 108
3 -6 8 108 108 108
4 -6 8 144 144 144
5 -6 8 144 144 144
6 -6 8 108 108 108
9 -6 8 144 144 144
-10 -5 8 108 108 108
-7 -5 8 108 108 108
-6 -5 8 144 144 144
-5 -5 8 144 144 144
-4 -5 8 108 108 108
-3 -5 8 108 108 108
-2 -5 8 108 108 108
-1 -5 8 108 108 108
0 -5 8 108 108 108
1 -5 8 108 108 108
2 -5 8 108 108 108
3 -5 8 108 108 108
4 -5 8 144 144 144
5 -5 8 144 144 144
6 -5 8 108 108 108
9 -5 8 144 144 144
-10 -4 8 144 144 144
-7 -4 8 108 108 108
-6 -4 8 108 108 108
-5 -4 8 108 108 108
-4 -4 8 108 108 108
3 -4 8 108 108 108
4 -4 8 108 108 108
5 -4 8 108 108 108
6 -4 8 108 108 108
9 -4 8 144 144 144
-10 -3 8 144 144 144
-6 -3 8 108 108 108
-5 -3 8 108 108 108
4 -3 8 108 108 108
5 -3 8 108 108 108
9 -3 8 144 144 144
-10 -2 8 144 144 144
-6 -2 8 108 108 108
-5 -2 8 108 108 108
4 -2 8 108 108 108
5 -2 8 108 108 108
9 -2 8 144 144 144
-10 -1 8 144 144 144
-6 -1 8 108 108 108
-5 -1 8 108 108 108
4 -1 8 108 108 108
5 -1 8 108 108 108
9 -1 8 108 108 108
-10 0 8 144 144 144
-6 0 8 108 108 108
-5 0 8 108 108 108
4 0 8 108 108 108
5 0 8 108 108 108
9 0 8 144 144 144
-10 1 8 144 144 144
-6 1 8 108 108 108
-5 1 8 108 108 108
4 1 8 108 108 108
5 1 8 108 108 108
9 1 8 144 144 144
-10 2 8 144 144 144
-6 2 8 108 108 108
-5 2 8 108 108 108
4 2 8 108 108 108
5 2 8 108 108 108
9 2 8 144 144 144
-10 3 8 144 144 144
-7 3 8 108 108 108
-6 3 8 108 108 108
-5 3 8 108 108 108
-4 3 8 108 108 108
3 3 8 108 108 108
4 3 8 108 108 108
5 3 8 108 108 108
6 3 8 108 108 108
9 3 8 144 144 144
-10 4 8 144 144 144
-7 4 8 108 108 108
-6 4 8 144 144 144
-5 4 8 144 144 144
-4 4 8 108 108 108
-3 4 8 108 108 108
-2 4 8 108 108 108
-1 4 8 108 108 108
0 4 8 108 108 108
1 4 8 108 108 108
2 4 8 108 108 108
3 4 8 108 108 108
4 4 8 144 144 144
5 4 8 144 144 144
6 4 8 108 108 108
9 4 8 144 144 144
-10 5 8 108 108 108
-7 5 8 108 108 108
-6 5 8 144 144 144
-5 5 8 144 144 144
-4 5 8 108 108 108
-3 5 8 108 108 108
-2 5 8 108 108 108
-1 5 8 108 108 108
0 5 8 108 108 108
1 5 8 108 108 108
2 5 8 108 108 108
3 5 8 108 108 108
4 5 8 144 144 144
5 5 8 144 144 144
6 5 8 108 108 108
9 5 8 144 144 144
-10 6 8 144 144 144
-7 6 8 108 108 108
-6 6 8 108 108 108
-5 6 8 108 108 108
-4 6 8 108 108 108
3 6 8 108 108 108
4 6 8 108 108 108
5 6 8 108 108 108
6 6 8 108 108 108
9 6 8 144 144 144
-10 7 8 144 144 144
9 7 8 108 108 108
-10 8 8 144 144 144
9 8 8 144 144 144
-10 9 8 144 144 144
-9 9 8 144 144 144
-8 9 8 144 144 144
-7 9 8 144 144 144
-6 9 8 144 144 144
-5 9 8 144 144 144
-4 9 8 144 144 144
-3 9 8 144 144 144
-2 9 8 144 144 144
-1 9 8 108 108 108
0 9 8 144 144 144
1 9 8 144 144 144
2 9 8 144 144 144
3 9 8 144 144 144
4 9 8 144 144 144
5 9 8 144 144 144
6 9 8 144 144 144
7 9 8 108 108 108
8 9 8 144 144 144
9 9 8 144 144 144
-10 -10 9 108 108 108
-9 -10 9 108 108 108
-8 -10 9 108 108 108
-7 -10 9 108 108 108
-6 -10 9 108 108 108
-5 -10 9 108 108 108
-4 -10 9 108 108 108
-3 -10 9 108 108 108
-2 -10 9 108 108 108
-1 -10 9 108 108 108
0 -10 9 108 108 108
1 -10 9 108 108 108
2 -10 9 108 108 108
3 -10 9 108 108 108
4 -10 9 108 108 108
5 -10 9 108 108 108
6 -10 9 108 108 108
7 -10 9 108 108 108
8 -10 9 108 108 108
9 -10 9 108 108 108
-10 -9 9 108 108 108
-9 -9 9 144 144 144
-8 -9 9 144 144 144
-7 -9 9 144 144 144
-6 -9 9 144 144 144
-5 -9 9 144 144 144
-4 -9 9 144 144 144
-3 -9 9 144 144 144
-2 -9 9 144 144 144
-1 -9 9 144 144 144
0 -9 9 144 144 144
1 -9 9 144 144 144
2 -9 9 144 144 144
3 -9 9 144 144 144
4 -9 9 144 144 144
5 -9 9 144 144 144
6 -9 9 144 144 144
7 -9 9 144 144 144
8 -9 9 144 144 144
9 -9 9 108 108 108
-10 -8 9 108 108 108
-9 -8 9 144 144 144
-8 -8 9 144 144 144
-7 -8 9 144 144 144
-6 -8 9 144 144 144
-5 -8 9 144 144 144
-4 -8 9 144 144 144
-3 -8 9 144 144 144
-2 -8 9 144 144 144
-1 -8 9 144 144 144
0 -8 9 144 144 144
1 -8 9 144 144 144
2 -8 9 144 144 144
3 -8 9 144 144 144
4 -8 9 144 144 144
5 -8 9 144 144 144
6 -8 9 144 144 144
7 -8 9 144 144 144
8 -8 9 144 144 144
9 -8 9 108 108 108
-10 -7 9 108 108 108
-9 -7 9 144 144 144
-8 -7 9 144 144 144
-7 -7 9 144 144 144
-6 -7 9 144 144 144
-5 -7 9 144 144 144
-4 -7 9 144 144 144
-3 -7 9 144 144 144
-2 -7 9 144 144 144
-1 -7 9 144 144 144
0 -7 9 144 144 144
1 -7 9 144 144 144
2 -7 9 144 144 144
3 -7 9 144 144 144
4 -7 9 144 144 144
5 -7 9 144 144 144
6 -7 9 144 144 144
7 -7 9 144 144 144
8 -7 9 144 144 144
9 -7 9 108 108 108
-10 -6 9 108 108 108
-9 -6 9 144 144 144
-8 -6 9 144 144 144
-7 -6 9 144 144 144
-6 -6 9 144 144 144
-5 -6 9 144 144 144
-4 -6 9 144 144 144
-3 -6 9 144 144 144
-2 -6 9 144 144 144
-1 -6 9 144 144 144
0 -6 9 144 144 144
1 -6 9 144 144 144
2 -6 9 144 144 144
3 -6 9 144 144 144
4 -6 9 144 144 144
5 -6 9 144 144 144
6 -6 9 144 144 144
7 -6 9 144 144 144
8 -6 9 144 144 144
9 -6 9 108 108 108
-10 -5 9 108 108 108
-9 -5 9 144 144 144
-8 -5 9 144 144 144
-7 -5 9 144 144 144
-6 -5 9 144 144 144
-5 -5 9 144 144 144
-4 -5 9 144 144 144
-3 -5 9 144 144 144
-2 -5 9 144 144 144
-1 -5 9 144 144 144
0 -5 9 144 144 144
1 -5 9 144 144 144
2 -5 9 144 144 144
3 -5 9 144 144 144
4 -5 9 144 144 144
5 -5 9 144 144 144
6 -5 9 144 144 144
7 -5 9 144 144 144
8 -5 9 144 144 144
9 -5 9 108 108 108
-10 -4 9 108 108 108
-9 -4 9 144 144 144
-8 -4 9 144 144 144
-7 -4 9 144 144 144
-6 -4 9 144 144 144
-5 -4 9 144 144 144
-4 -4 9 144 144 144
-3 -4 9 144 144 144
-2 -4 9 144 144 144
-1 -4 9 144 144 144
0 -4 9 144 144 144
1 -4 9 144 144 144
2 -4 9 144 144 144
3 -4 9 144 144 144
4 -4 9 144 144 144
5 -4 9 144 144 144
6 -4 9 144 144 144
7 -4 9 144 144 144
8 -4 9 144 144 144
9 -4 9 108 108 108
-10 -3 9 108 108 108
-9 -3 9 144 144 144
-8 -3 9 144 144 144
-7 -3 9 144 144 144
-6 -3 9 144 144 144
-5 -3 9 144 144 144
-4 -3 9 144 144 144
-3 -3 9 144 144 144
-2 -3 9 144 144 144
-1 -3 9 144 144 144
0 -3 9 144 144 144
1 -3 9 144 144 144
2 -3 9 144 144 144
3 -3 9 144 144 144
4 -3 9 144 144 144
5 -3 9 144 144 144
6 -3 9 144 144 144
7 -3 9 144 144 144
8 -3 9 144 144 144
9 -3 9 108 108 108
-10 -2 9 108 108 108
-9 -2 9 144 144 144
-8 -2 9 144 144 144
-7 -2 9 144 144 144
-6 -2 9 144 144 144
-5 -2 9 144 144 144
-4 -2 9 144 144 144
-3 -2 9 144 144 144
-2 -2 9 144 144 144
-1 -2 9 144 144 144
0 -2 9 144 144 144
1 -2 9 144 144 144
2 -2 9 144 144 144
3 -2 9 144 144 144
4 -2 9 144 144 144
5 -2 9 144 144 144
6 -2 9 144 144 144
7 -2 9 144 144 144
8 -2 9 144 144 144
9 -2 9 108 108 108
-10 -1 9 108 108 108
-9 -1 9 144 144 144
-8 -1 9 144 144 144
-7 -1 9 144 144 144
-6 -1 9 144 144 144
-5 -1 9 144 144 144
-4 -1 9 144 144 144
-3 -1 9 144 144 144
-2 -1 9 144 144 144
-1 -1 9 144 144 144
0 -1 9 144 144 144
1 -1 9 144 144 144
2 -1 9 144 144 144
3 -1 9 144 144 144
4 -1 9 144 144 144
5 -1 9 144 144 144
6 -1 9 144 144 144
7 -1 9 144 144 144
8 -1 9 144 144 144
9 -1 9 108 108 108
-10 0 9 108 108 108
-9 0 9 144 144 144
-8 0 9 144 144 144
-7 0 9 144 144 144
-6 0 9 144 144 144
-5 0 9 144 144 144
-4 0 9 144 144 144
-3 0 9 144 144 144
-2 0 9 144 144 144
-1 0 9 144 144 144
0 0 9 144 144 144
1 0 9 144 144 144
2 0 9 144 144 144
3 0 9 144 144 144
4 0 9 144 144 144
5 0 9 144 144 144
6 0 9 144 144 144
7 0 9 144 144 144
8 0 9 144 144 144
9 0 9 108 108 108
-10 1 9 108 108 108
-9 1 9 144 144 144
-8 1 9 144 144 144
-7 1 9 144 144 144
-6 1 9 144 144 144
-5 1 9 144 144 144
-4 1 9 144 144 144
-3 1 9 144 144 144
-2 1 9 144 144 144
-1 1 9 144 144 144
0 1 9 144 144 144
1 1 9 144 144 144
2 1 9 144 144 144
3 1 9 144 144 144
4 1 9 144 144 144
5 1 9 144 144 144
6 1 9 144 144 144
7 1 9 144 144 144
8 1 9 144 144 144
9 1 9 108 108 108
-10 2 9 108 108 108
-9 2 9 144 144 144
-8 2 9 144 144 144
-7 2 9 144 144 144
-6 2 9 144 144 144
-5 2 9 144 144 144
-4 2 9 144 144 144
-3 2 9 144 144 144
-2 2 9 144 144 144
-1 2 9 144 144 144
0 2 9 144 144 144
1 2 9 144 144 144
2 2 9 144 144 144
3 2 9 144 144 144
4 2 9 144 144 144
5 2 9 144 144 144
6 2 9 144 144 144
7 2 9 144 144 144
8 2 9 144 144 144
9 2 9 108 108 108
-10 3 9 108 108 108
-9 3 9 144 144 144
-8 3 9 144 144 144
-7 3 9 144 144 144
-6 3 9 144 144 144
-5 3 9 144 144 144
-4 3 9 144 144 144
-3 3 9 144 144 144
-2 3 9 144 144 144
-1 3 9 144 144 144
0 3 9 144 144 144
1 3 9 144 144 144
2 3 9 144 144 144
3 3 9 144 144 144
4 3 9 144 144 144
5 3 9 144 144 144
6 3 9 144 144 144
7 3 9 144 144 144
8 3 9 144 144 144
9 3 9 108 108 108
-10 4 9 108 108 108
-9 4 9 144 144 144
-8 4 9 144 144 144
-7 4 9 144 144 144
-6 4 9 144 144 144
-5 4 9 144 144 144
-4 4 9 144 144 144
-3 4 9 144 144 144
-2 4 9 144 144 144
-1 4 9 144 144 144
0 4 9 144 144 144
1 4 9 144 144 144
2 4 9 144 144 144
3 4 9 144 144 144
4 4 9 144 144 144
5 4 9 144 144 144
6 4 9 144 144 144
7 4 9 144 144 144
8 4 9 144 144 144
9 4 9 108 108 108
-10 5 9 108 108 108
-9 5 9 144 144 144
-8 5 9 144 144 144
-7 5 9 144 144 144
-6 5 9 144 144 144
-5 5 9 144 144 144
-4 5 9 144 144 144
-3 5 9 144 144 144
-2 5 9 144 144 144
-1 5 9 144 144 144
0 5 9 144 144 144
1 5 9 144 144 144
2 5 9 144 144 144
3 5 9 144 144 144
4 5 9 144 144 144
5 5 9 144 144 144
6 5 9 144 144 144
7 5 9 144 144 144
8 5 9 144 144 144
9 5 9 108 108 108
-10 6 9 108 108 108
-9 6 9 144 144 144
-8 6 9 144 144 144
-7 6 9 144 144 144
-6 6 9 144 144 144
-5 6 9 144 144 144
-4 6 9 144 144 144
-3 6 9 144 144 144
-2 6 9 144 144 144
-1 6 9 144 144 144
0 6 9 144 144 144
1 6 9 144 144 144
2 6 9 144 144 144
3 6 9 144 144 144
4 6 9 144 144 144
5 6 9 144 144 144
6 6 9 144 144 144
7 6 9 144 144 144
8 6 9 144 144 144
9 6 9 108 108 108
-10 7 9 108 108 108
-9 7 9 144 144 144
-8 7 9 144 144 144
-7 7 9 144 144 144
-6 7 9 144 144 144
-5 7 9 144 144 144
-4 7 9 144 144 144
-3 7 9 144 144 144
-2 7 9 144 144 144
-1 7 9 144 144 144
0 7 9 144 144 144
1 7 9 144 144 144
2 7 9 144 144 144
3 7 9 144 144 144
4 7 9 144 144 144
5 7 9 144 144 144
6 7 9 144 144 144
7 7 9 144 144 144
8 7 9 144 144 144
9 7 9 108 108 108
-10 8 9 108 108 108
-9 8 9 144 144 144
-8 8 9 144 144 144
-7 8 9 144 144 144
-6 8 9 144 144 144
-5 8 9 144 144 144
-4 8 9 144 144 144
-3 8 9 144 144 144
-2 8 9 144 144 144
-1 8 9 144 144 144
0 8 9 144 144 144
1 8 9 144 144 144
2 8 9 144 144 144
3 8 9 144 144 144
4 8 9 144 144 144
5 8 9 144 144 144
6 8 9 144 144 144
7 8 9 144 144 144
8 8 9 144 144 144
9 8 9 108 108 108
-10 9 9 108 108 108
-9 9 9 108 108 108
-8 9 9 108 108 108
-7 9 9 108 108 108
-6 9 9 108 108 108
-5 9 9 108 108 108
-4 9 9 108 108 108
-3 9 9 108 108 108
-2 9 9 108 108 108
-1 9 9 108 108 108
0 9 9 108 108 108
1 9 9 108 108 108
2 9 9 108 108 108
3 9 9 108 108 108
4 9 9 108 108 108
5 9 9 108 108 108
6 9 9 108 108 108
7 9 9 108 108 108
8 9 9 108 108 108
9 9 9 108 108 108
