ply
format ascii 1.0
comment : MagicaVoxel @ Ephtracy
element vertex 2659
property float x
property float y
property float z
property uchar red
property uchar green
property uchar blue
end_header
-10 -10 0 160 132 68
-9 -10 0 160 132 68
-8 -10 0 160 132 68
-7 -10 0 160 132 68
-6 -10 0 160 132 68
-5 -10 0 160 132 68
-4 -10 0 160 132 68
-3 -10 0 160 132 68
-2 -10 0 160 132 68
-1 -10 0 160 132 68
0 -10 0 160 132 68
1 -10 0 160 132 68
2 -10 0 160 132 68
3 -10 0 160 132 68
4 -10 0 160 132 68
5 -10 0 132 104 48
6 -10 0 160 132 68
7 -10 0 160 132 68
8 -10 0 160 132 68
9 -10 0 160 132 68
-10 -9 0 160 132 68
-9 -9 0 160 132 68
-8 -9 0 160 132 68
-7 -9 0 160 132 68
-6 -9 0 160 132 68
-5 -9 0 160 132 68
-4 -9 0 160 132 68
-3 -9 0 160 132 68
-2 -9 0 160 132 68
-1 -9 0 160 132 68
0 -9 0 160 132 68
1 -9 0 160 132 68
2 -9 0 160 132 68
3 -9 0 160 132 68
4 -9 0 184 156 88
5 -9 0 132 104 48
6 -9 0 160 132 68
7 -9 0 160 132 68
8 -9 0 160 132 68
9 -9 0 160 132 68
-10 -8 0 160 132 68
-9 -8 0 160 132 68
-8 -8 0 160 132 68
-7 -8 0 160 132 68
-6 -8 0 160 132 68
-5 -8 0 160 132 68
-4 -8 0 160 132 68
-3 -8 0 160 132 68
-2 -8 0 160 132 68
-1 -8 0 160 132 68
0 -8 0 160 132 68
1 -8 0 160 132 68
2 -8 0 184 156 88
3 -8 0 184 156 88
4 -8 0 184 156 88
5 -8 0 132 104 48
6 -8 0 160 132 68
7 -8 0 160 132 68
8 -8 0 160 132 68
9 -8 0 160 132 68
-10 -7 0 132 104 48
-9 -7 0 132 104 48
-8 -7 0 132 104 48
-7 -7 0 132 104 48
-6 -7 0 132 104 48
-5 -7 0 132 104 48
-4 -7 0 132 104 48
-3 -7 0 132 104 48
-2 -7 0 132 104 48
-1 -7 0 132 104 48
0 -7 0 132 104 48
1 -7 0 132 104 48
2 -7 0 132 104 48
3 -7 0 132 104 48
4 -7 0 132 104 48
5 -7 0 132 104 48
6 -7 0 132 104 48
7 -7 0 132 104 48
8 -7 0 132 104 48
9 -7 0 132 104 48
-10 -6 0 160 132 68
-9 -6 0 160 132 68
-8 -6 0 160 132 68
-7 -6 0 132 104 48
-6 -6 0 160 132 68
-5 -6 0 160 132 68
-4 -6 0 160 132 68
-3 -6 0 160 132 68
-2 -6 0 160 132 68
-1 -6 0 160 132 68
0 -6 0 160 132 68
1 -6 0 160 132 68
2 -6 0 160 132 68
3 -6 0 160 132 68
4 -6 0 160 132 68
5 -6 0 160 132 68
6 -6 0 160 132 68
7 -6 0 132 104 48
8 -6 0 160 132 68
9 -6 0 160 132 68
-10 -5 0 160 132 68
-9 -5 0 160 132 68
-8 -5 0 184 156 88
-7 -5 0 132 104 48
-6 -5 0 160 132 68
-5 -5 0 160 132 68
-4 -5 0 160 132 68
-3 -5 0 160 132 68
-2 -5 0 160 132 68
-1 -5 0 160 132 68
0 -5 0 160 132 68
1 -5 0 160 132 68
2 -5 0 160 132 68
3 -5 0 160 132 68
4 -5 0 160 132 68
5 -5 0 160 132 68
6 -5 0 184 156 88
7 -5 0 132 104 48
8 -5 0 160 132 68
9 -5 0 160 132 68
-10 -4 0 184 156 88
-9 -4 0 184 156 88
-8 -4 0 184 156 88
-7 -4 0 132 104 48
-6 -4 0 160 132 68
-5 -4 0 160 132 68
-4 -4 0 160 132 68
-3 -4 0 160 132 68
-2 -4 0 160 132 68
-1 -4 0 160 132 68
0 -4 0 160 132 68
1 -4 0 160 132 68
2 -4 0 160 132 68
3 -4 0 160 132 68
4 -4 0 184 156 88
5 -4 0 184 156 88
6 -4 0 184 156 88
7 -4 0 132 104 48
8 -4 0 160 132 68
9 -4 0 160 132 68
-10 -3 0 132 104 48
-9 -3 0 132 104 48
-8 -3 0 132 104 48
-7 -3 0 132 104 48
-6 -3 0 132 104 48
-5 -3 0 132 104 48
-4 -3 0 132 104 48
-3 -3 0 132 104 48
-2 -3 0 132 104 48
-1 -3 0 132 104 48
0 -3 0 132 104 48
1 -3 0 132 104 48
2 -3 0 132 104 48
3 -3 0 132 104 48
4 -3 0 132 104 48
5 -3 0 132 104 48
6 -3 0 132 104 48
7 -3 0 132 104 48
8 -3 0 132 104 48
9 -3 0 132 104 48
-10 -2 0 160 132 68
-9 -2 0 160 132 68
-8 -2 0 160 132 68
-7 -2 0 160 132 68
-6 -2 0 160 132 68
-5 -2 0 160 132 68
-4 -2 0 160 132 68
-3 -2 0 160 132 68
-2 -2 0 160 132 68
-1 -2 0 160 132 68
0 -2 0 160 132 68
1 -2 0 132 104 48
2 -2 0 160 132 68
3 -2 0 160 132 68
4 -2 0 160 132 68
5 -2 0 160 132 68
6 -2 0 160 132 68
7 -2 0 160 132 68
8 -2 0 160 132 68
9 -2 0 160 132 68
-10 -1 0 160 132 68
-9 -1 0 160 132 68
-8 -1 0 160 132 68
-7 -1 0 160 132 68
-6 -1 0 160 132 68
-5 -1 0 160 132 68
-4 -1 0 160 132 68
-3 -1 0 160 132 68
-2 -1 0 160 132 68
-1 -1 0 160 132 68
0 -1 0 184 156 88
1 -1 0 132 104 48
2 -1 0 160 132 68
3 -1 0 160 132 68
4 -1 0 160 132 68
5 -1 0 160 132 68
6 -1 0 160 132 68
7 -1 0 160 132 68
8 -1 0 160 132 68
9 -1 0 160 132 68
-10 0 0 160 132 68
-9 0 0 160 132 68
-8 0 0 160 132 68
-7 0 0 160 132 68
-6 0 0 160 132 68
-5 0 0 160 132 68
-4 0 0 160 132 68
-3 0 0 160 132 68
-2 0 0 184 156 88
-1 0 0 184 156 88
0 0 0 184 156 88
1 0 0 132 104 48
2 0 0 160 132 68
3 0 0 160 132 68
4 0 0 160 132 68
5 0 0 160 132 68
6 0 0 160 132 68
7 0 0 160 132 68
8 0 0 160 132 68
9 0 0 160 132 68
-10 1 0 132 104 48
-9 1 0 132 104 48
-8 1 0 132 104 48
-7 1 0 132 104 48
-6 1 0 132 104 48
-5 1 0 132 104 48
-4 1 0 132 104 48
-3 1 0 132 104 48
-2 1 0 132 104 48
-1 1 0 132 104 48
0 1 0 132 104 48
1 1 0 132 104 48
2 1 0 132 104 48
3 1 0 132 104 48
4 1 0 132 104 48
5 1 0 132 104 48
6 1 0 132 104 48
7 1 0 132 104 48
8 1 0 132 104 48
9 1 0 132 104 48
-10 2 0 160 132 68
-9 2 0 160 132 68
-8 2 0 160 132 68
-7 2 0 160 132 68
-6 2 0 160 132 68
-5 2 0 160 132 68
-4 2 0 160 132 68
-3 2 0 132 104 48
-2 2 0 160 132 68
-1 2 0 160 132 68
0 2 0 160 132 68
1 2 0 160 132 68
2 2 0 160 132 68
3 2 0 160 132 68
4 2 0 160 132 68
5 2 0 160 132 68
6 2 0 160 132 68
7 2 0 132 104 48
8 2 0 160 132 68
9 2 0 160 132 68
-10 3 0 160 132 68
-9 3 0 160 132 68
-8 3 0 160 132 68
-7 3 0 160 132 68
-6 3 0 160 132 68
-5 3 0 160 132 68
-4 3 0 160 132 68
-3 3 0 132 104 48
-2 3 0 160 132 68
-1 3 0 160 132 68
0 3 0 160 132 68
1 3 0 160 132 68
2 3 0 160 132 68
3 3 0 160 132 68
4 3 0 160 132 68
5 3 0 160 132 68
6 3 0 184 156 88
7 3 0 132 104 48
8 3 0 160 132 68
9 3 0 160 132 68
-10 4 0 160 132 68
-9 4 0 160 132 68
-8 4 0 160 132 68
-7 4 0 160 132 68
-6 4 0 160 132 68
-5 4 0 160 132 68
-4 4 0 160 132 68
-3 4 0 132 104 48
-2 4 0 160 132 68
-1 4 0 160 132 68
0 4 0 160 132 68
1 4 0 160 132 68
2 4 0 160 132 68
3 4 0 160 132 68
4 4 0 184 156 88
5 4 0 184 156 88
6 4 0 184 156 88
7 4 0 132 104 48
8 4 0 160 132 68
9 4 0 160 132 68
-10 5 0 132 104 48
-9 5 0 132 104 48
-8 5 0 132 104 48
-7 5 0 132 104 48
-6 5 0 132 104 48
-5 5 0 132 104 48
-4 5 0 132 104 48
-3 5 0 132 104 48
-2 5 0 132 104 48
-1 5 0 132 104 48
0 5 0 132 104 48
1 5 0 132 104 48
2 5 0 132 104 48
3 5 0 132 104 48
4 5 0 132 104 48
5 5 0 132 104 48
6 5 0 132 104 48
7 5 0 132 104 48
8 5 0 132 104 48
9 5 0 132 104 48
-10 6 0 160 132 68
-9 6 0 132 104 48
-8 6 0 160 132 68
-7 6 0 160 132 68
-6 6 0 160 132 68
-5 6 0 160 132 68
-4 6 0 160 132 68
-3 6 0 160 132 68
-2 6 0 160 132 68
-1 6 0 160 132 68
0 6 0 160 132 68
1 6 0 160 132 68
2 6 0 160 132 68
3 6 0 160 132 68
4 6 0 132 104 48
5 6 0 160 132 68
6 6 0 160 132 68
7 6 0 160 132 68
8 6 0 160 132 68
9 6 0 160 132 68
-10 7 0 160 132 68
-9 7 0 132 104 48
-8 7 0 160 132 68
-7 7 0 160 132 68
-6 7 0 160 132 68
-5 7 0 160 132 68
-4 7 0 160 132 68
-3 7 0 160 132 68
-2 7 0 160 132 68
-1 7 0 160 132 68
0 7 0 160 132 68
1 7 0 160 132 68
2 7 0 160 132 68
3 7 0 184 156 88
4 7 0 132 104 48
5 7 0 160 132 68
6 7 0 160 132 68
7 7 0 160 132 68
8 7 0 160 132 68
9 7 0 160 132 68
-10 8 0 184 156 88
-9 8 0 132 104 48
-8 8 0 160 132 68
-7 8 0 160 132 68
-6 8 0 160 132 68
-5 8 0 160 132 68
-4 8 0 160 132 68
-3 8 0 160 132 68
-2 8 0 160 132 68
-1 8 0 160 132 68
0 8 0 160 132 68
1 8 0 184 156 88
2 8 0 184 156 88
3 8 0 184 156 88
4 8 0 132 104 48
5 8 0 160 132 68
6 8 0 160 132 68
7 8 0 160 132 68
8 8 0 184 156 88
9 8 0 184 156 88
-10 9 0 132 104 48
-9 9 0 132 104 48
-8 9 0 132 104 48
-7 9 0 132 104 48
-6 9 0 132 104 48
-5 9 0 132 104 48
-4 9 0 132 104 48
-3 9 0 132 104 48
-2 9 0 132 104 48
-1 9 0 132 104 48
0 9 0 132 104 48
1 9 0 132 104 48
2 9 0 132 104 48
3 9 0 132 104 48
4 9 0 132 104 48
5 9 0 132 104 48
6 9 0 132 104 48
7 9 0 132 104 48
8 9 0 132 104 48
9 9 0 132 104 48
-10 -10 1 144 144 144
-9 -10 1 144 144 144
-8 -10 1 132 104 48
-3 -10 1 132 104 48
-2 -10 1 144 144 144
-1 -10 1 144 144 144
0 -10 1 144 144 144
1 -10 1 144 144 144
2 -10 1 108 108 108
3 -10 1 144 144 144
4 -10 1 144 144 144
5 -10 1 144 144 144
6 -10 1 144 144 144
7 -10 1 144 144 144
8 -10 1 144 144 144
9 -10 1 144 144 144
-10 -9 1 144 144 144
9 -9 1 144 144 144
-10 -8 1 144 144 144
9 -8 1 144 144 144
-10 -7 1 144 144 144
9 -7 1 144 144 144
-10 -6 1 144 144 144
9 -6 1 144 144 144
-10 -5 1 144 144 144
3 -5 1 108 108 108
4 -5 1 108 108 108
5 -5 1 108 108 108
6 -5 1 108 108 108
9 -5 1 144 144 144
-10 -4 1 108 108 108
3 -4 1 108 108 108
4 -4 1 108 108 108
5 -4 1 108 108 108
6 -4 1 108 108 108
9 -4 1 108 108 108
-10 -3 1 144 144 144
3 -3 1 108 108 108
4 -3 1 108 108 108
5 -3 1 108 108 108
6 -3 1 108 108 108
9 -3 1 144 144 144
-10 -2 1 144 144 144
3 -2 1 108 108 108
4 -2 1 108 108 108
5 -2 1 108 108 108
6 -2 1 108 108 108
9 -2 1 144 144 144
-10 -1 1 144 144 144
3 -1 1 108 108 108
4 -1 1 108 108 108
5 -1 1 108 108 108
6 -1 1 108 108 108
9 -1 1 144 144 144
-10 0 1 144 144 144
3 0 1 108 108 108
4 0 1 108 108 108
5 0 1 108 108 108
6 0 1 108 108 108
9 0 1 144 144 144
-10 1 1 144 144 144
3 1 1 108 108 108
4 1 1 108 108 108
5 1 1 108 108 108
6 1 1 108 108 108
9 1 1 144 144 144
-10 2 1 144 144 144
3 2 1 108 108 108
4 2 1 108 108 108
5 2 1 108 108 108
6 2 1 108 108 108
9 2 1 144 144 144
-10 3 1 144 144 144
2 3 1 132 104 48
3 3 1 108 108 108
4 3 1 132 104 48
5 3 1 160 132 68
6 3 1 160 132 68
7 3 1 132 104 48
9 3 1 144 144 144
-10 4 1 144 144 144
2 4 1 132 104 48
3 4 1 132 104 48
4 4 1 132 104 48
5 4 1 160 132 68
6 4 1 160 132 68
7 4 1 132 104 48
9 4 1 144 144 144
-10 5 1 144 144 144
9 5 1 144 144 144
-10 6 1 108 108 108
9 6 1 108 108 108
-10 7 1 144 144 144
9 7 1 144 144 144
-10 8 1 144 144 144
9 8 1 144 144 144
-10 9 1 144 144 144
-9 9 1 144 144 144
-8 9 1 144 144 144
-7 9 1 144 144 144
-6 9 1 144 144 144
-5 9 1 108 108 108
-4 9 1 144 144 144
-3 9 1 144 144 144
-2 9 1 144 144 144
-1 9 1 144 144 144
0 9 1 144 144 144
1 9 1 144 144 144
2 9 1 132 104 48
7 9 1 132 104 48
8 9 1 144 144 144
9 9 1 144 144 144
-10 -10 2 144 144 144
-9 -10 2 144 144 144
-8 -10 2 132 104 48
-3 -10 2 132 104 48
-2 -10 2 144 144 144
-1 -10 2 144 144 144
0 -10 2 144 144 144
1 -10 2 144 144 144
2 -10 2 108 108 108
3 -10 2 144 144 144
4 -10 2 144 144 144
5 -10 2 144 144 144
6 -10 2 144 144 144
7 -10 2 144 144 144
8 -10 2 144 144 144
9 -10 2 144 144 144
-10 -9 2 144 144 144
9 -9 2 144 144 144
-10 -8 2 144 144 144
9 -8 2 144 144 144
-10 -7 2 144 144 144
9 -7 2 144 144 144
-10 -6 2 144 144 144
9 -6 2 144 144 144
-10 -5 2 144 144 144
3 -5 2 108 108 108
4 -5 2 108 108 108
5 -5 2 108 108 108
6 -5 2 108 108 108
9 -5 2 144 144 144
-10 -4 2 108 108 108
3 -4 2 108 108 108
4 -4 2 108 108 108
5 -4 2 108 108 108
6 -4 2 108 108 108
9 -4 2 108 108 108
-10 -3 2 144 144 144
3 -3 2 108 108 108
4 -3 2 108 108 108
5 -3 2 108 108 108
6 -3 2 108 108 108
9 -3 2 144 144 144
-10 -2 2 144 144 144
3 -2 2 108 108 108
4 -2 2 108 108 108
5 -2 2 108 108 108
6 -2 2 108 108 108
9 -2 2 144 144 144
-10 -1 2 144 144 144
3 -1 2 108 108 108
4 -1 2 108 108 108
5 -1 2 108 108 108
6 -1 2 108 108 108
9 -1 2 144 144 144
-10 0 2 144 144 144
3 0 2 108 108 108
4 0 2 108 108 108
5 0 2 108 108 108
6 0 2 108 108 108
9 0 2 144 144 144
-10 1 2 144 144 144
3 1 2 108 108 108
4 1 2 108 108 108
5 1 2 108 108 108
6 1 2 108 108 108
9 1 2 144 144 144
-10 2 2 144 144 144
2 2 2 132 104 48
3 2 2 108 108 108
4 2 2 132 104 48
5 2 2 108 108 108
6 2 2 108 108 108
7 2 2 132 104 48
9 2 2 144 144 144
-10 3 2 144 144 144
2 3 2 132 104 48
3 3 2 132 104 48
4 3 2 132 104 48
5 3 2 160 132 68
6 3 2 160 132 68
7 3 2 132 104 48
9 3 2 144 144 144
-10 4 2 144 144 144
2 4 2 132 104 48
7 4 2 132 104 48
9 4 2 144 144 144
-10 5 2 144 144 144
9 5 2 144 144 144
-10 6 2 108 108 108
9 6 2 108 108 108
-10 7 2 144 144 144
9 7 2 144 144 144
-10 8 2 144 144 144
9 8 2 144 144 144
-10 9 2 144 144 144
-9 9 2 144 144 144
-8 9 2 144 144 144
-7 9 2 144 144 144
-6 9 2 144 144 144
-5 9 2 108 108 108
-4 9 2 144 144 144
-3 9 2 144 144 144
-2 9 2 144 144 144
-1 9 2 144 144 144
0 9 2 144 144 144
1 9 2 144 144 144
2 9 2 132 104 48
7 9 2 132 104 48
8 9 2 144 144 144
9 9 2 144 144 144
-10 -10 3 108 108 108
-9 -10 3 108 108 108
-8 -10 3 132 104 48
-3 -10 3 132 104 48
-2 -10 3 108 108 108
-1 -10 3 108 108 108
0 -10 3 108 108 108
1 -10 3 108 108 108
2 -10 3 108 108 108
3 -10 3 108 108 108
4 -10 3 108 108 108
5 -10 3 108 108 108
6 -10 3 108 108 108
7 -10 3 108 108 108
8 -10 3 108 108 108
9 -10 3 108 108 108
-10 -9 3 108 108 108
9 -9 3 108 108 108
-10 -8 3 108 108 108
9 -8 3 108 108 108
-10 -7 3 108 108 108
9 -7 3 108 108 108
-10 -6 3 108 108 108
9 -6 3 108 108 108
-10 -5 3 108 108 108
3 -5 3 108 108 108
4 -5 3 108 108 108
5 -5 3 108 108 108
6 -5 3 108 108 108
9 -5 3 108 108 108
-10 -4 3 108 108 108
3 -4 3 108 108 108
4 -4 3 160 132 68
5 -4 3 160 132 68
6 -4 3 108 108 108
9 -4 3 108 108 108
-10 -3 3 108 108 108
3 -3 3 108 108 108
4 -3 3 160 132 68
5 -3 3 160 132 68
6 -3 3 108 108 108
9 -3 3 108 108 108
-10 -2 3 108 108 108
3 -2 3 108 108 108
4 -2 3 160 132 68
5 -2 3 160 132 68
6 -2 3 108 108 108
9 -2 3 108 108 108
-10 -1 3 108 108 108
3 -1 3 108 108 108
4 -1 3 160 132 68
5 -1 3 160 132 68
6 -1 3 108 108 108
9 -1 3 108 108 108
-10 0 3 108 108 108
3 0 3 108 108 108
4 0 3 160 132 68
5 0 3 160 132 68
6 0 3 108 108 108
9 0 3 108 108 108
-10 1 3 108 108 108
2 1 3 132 104 48
3 1 3 132 104 48
4 1 3 160 132 68
5 1 3 160 132 68
6 1 3 160 132 68
7 1 3 132 104 48
9 1 3 108 108 108
-10 2 3 108 108 108
2 2 3 132 104 48
3 2 3 132 104 48
4 2 3 132 104 48
5 2 3 160 132 68
6 2 3 160 132 68
7 2 3 132 104 48
9 2 3 108 108 108
-10 3 3 108 108 108
2 3 3 132 104 48
7 3 3 132 104 48
9 3 3 108 108 108
-10 4 3 108 108 108
2 4 3 132 104 48
7 4 3 132 104 48
9 4 3 108 108 108
-10 5 3 108 108 108
9 5 3 108 108 108
-10 6 3 108 108 108
9 6 3 108 108 108
-10 7 3 108 108 108
9 7 3 108 108 108
-10 8 3 108 108 108
9 8 3 108 108 108
-10 9 3 108 108 108
-9 9 3 108 108 108
-8 9 3 108 108 108
-7 9 3 108 108 108
-6 9 3 108 108 108
-5 9 3 108 108 108
-4 9 3 108 108 108
-3 9 3 108 108 108
-2 9 3 108 108 108
-1 9 3 108 108 108
0 9 3 108 108 108
1 9 3 108 108 108
2 9 3 132 104 48
7 9 3 132 104 48
8 9 3 108 108 108
9 9 3 108 108 108
-10 -10 4 144 144 144
-9 -10 4 144 144 144
-8 -10 4 132 104 48
-3 -10 4 132 104 48
-2 -10 4 144 144 144
-1 -10 4 144 144 144
0 -10 4 144 144 144
1 -10 4 144 144 144
2 -10 4 144 144 144
3 -10 4 144 144 144
4 -10 4 144 144 144
5 -10 4 108 108 108
6 -10 4 144 144 144
7 -10 4 144 144 144
8 -10 4 144 144 144
9 -10 4 144 144 144
-10 -9 4 144 144 144
9 -9 4 144 144 144
-10 -8 4 144 144 144
9 -8 4 144 144 144
-10 -7 4 108 108 108
9 -7 4 108 108 108
-10 -6 4 144 144 144
9 -6 4 144 144 144
-10 -5 4 144 144 144
3 -5 4 108 108 108
4 -5 4 108 108 108
5 -5 4 108 108 108
6 -5 4 108 108 108
9 -5 4 144 144 144
-10 -4 4 144 144 144
3 -4 4 108 108 108
4 -4 4 160 132 68
5 -4 4 160 132 68
6 -4 4 108 108 108
9 -4 4 144 144 144
-10 -3 4 144 144 144
3 -3 4 108 108 108
4 -3 4 160 132 68
5 -3 4 160 132 68
6 -3 4 108 108 108
9 -3 4 144 144 144
-10 -2 4 144 144 144
3 -2 4 108 108 108
4 -2 4 160 132 68
5 -2 4 160 132 68
6 -2 4 108 108 108
9 -2 4 144 144 144
-10 -1 4 144 144 144
3 -1 4 108 108 108
4 -1 4 160 132 68
5 -1 4 160 132 68
6 -1 4 108 108 108
9 -1 4 144 144 144
-10 0 4 144 144 144
2 0 4 132 104 48
3 0 4 132 104 48
4 0 4 160 132 68
5 0 4 160 132 68
6 0 4 160 132 68
7 0 4 132 104 48
9 0 4 144 144 144
-10 1 4 144 144 144
2 1 4 132 104 48
3 1 4 132 104 48
4 1 4 132 104 48
5 1 4 160 132 68
6 1 4 160 132 68
7 1 4 132 104 48
9 1 4 144 144 144
-10 2 4 144 144 144
2 2 4 132 104 48
7 2 4 132 104 48
9 2 4 144 144 144
-10 3 4 108 108 108
2 3 4 132 104 48
7 3 4 132 104 48
9 3 4 144 144 144
-10 4 4 144 144 144
9 4 4 108 108 108
-10 5 4 144 144 144
9 5 4 144 144 144
-10 6 4 144 144 144
9 6 4 144 144 144
-10 7 4 144 144 144
9 7 4 144 144 144
-10 8 4 144 144 144
9 8 4 144 144 144
-10 9 4 144 144 144
-9 9 4 144 144 144
-8 9 4 108 108 108
-7 9 4 144 144 144
-6 9 4 144 144 144
-5 9 4 144 144 144
-4 9 4 144 144 144
-3 9 4 144 144 144
-2 9 4 144 144 144
-1 9 4 144 144 144
0 9 4 144 144 144
1 9 4 144 144 144
2 9 4 132 104 48
7 9 4 132 104 48
8 9 4 144 144 144
9 9 4 144 144 144
-10 -10 5 144 144 144
-9 -10 5 144 144 144
-8 -10 5 132 104 48
-3 -10 5 132 104 48
-2 -10 5 144 144 144
-1 -10 5 144 144 144
0 -10 5 144 144 144
1 -10 5 144 144 144
2 -10 5 144 144 144
3 -10 5 144 144 144
4 -10 5 144 144 144
5 -10 5 108 108 108
6 -10 5 144 144 144
7 -10 5 144 144 144
8 -10 5 144 144 144
9 -10 5 144 144 144
-10 -9 5 144 144 144
9 -9 5 144 144 144
-10 -8 5 144 144 144
9 -8 5 144 144 144
-10 -7 5 108 108 108
9 -7 5 108 108 108
-10 -6 5 144 144 144
9 -6 5 144 144 144
-10 -5 5 144 144 144
3 -5 5 108 108 108
4 -5 5 108 108 108
5 -5 5 108 108 108
6 -5 5 108 108 108
9 -5 5 144 144 144
-10 -4 5 144 144 144
3 -4 5 108 108 108
4 -4 5 160 132 68
5 -4 5 160 132 68
6 -4 5 108 108 108
9 -4 5 144 144 144
-10 -3 5 144 144 144
3 -3 5 108 108 108
4 -3 5 160 132 68
5 -3 5 160 132 68
6 -3 5 108 108 108
9 -3 5 144 144 144
-10 -2 5 144 144 144
3 -2 5 108 108 108
4 -2 5 160 132 68
5 -2 5 160 132 68
6 -2 5 108 108 108
9 -2 5 144 144 144
-10 -1 5 144 144 144
2 -1 5 132 104 48
3 -1 5 132 104 48
4 -1 5 160 132 68
5 -1 5 160 132 68
6 -1 5 108 108 108
7 -1 5 132 104 48
9 -1 5 144 144 144
-10 0 5 144 144 144
2 0 5 132 104 48
3 0 5 132 104 48
4 0 5 132 104 48
5 0 5 160 132 68
6 0 5 160 132 68
7 0 5 132 104 48
9 0 5 144 144 144
-10 1 5 144 144 144
2 1 5 132 104 48
7 1 5 132 104 48
9 1 5 144 144 144
-10 2 5 144 144 144
2 2 5 132 104 48
7 2 5 132 104 48
9 2 5 144 144 144
-10 3 5 108 108 108
9 3 5 144 144 144
-10 4 5 144 144 144
9 4 5 108 108 108
-10 5 5 144 144 144
9 5 5 144 144 144
-10 6 5 144 144 144
9 6 5 144 144 144
-10 7 5 144 144 144
9 7 5 144 144 144
-10 8 5 144 144 144
9 8 5 144 144 144
-10 9 5 144 144 144
-9 9 5 144 144 144
-8 9 5 108 108 108
-7 9 5 144 144 144
-6 9 5 144 144 144
-5 9 5 144 144 144
-4 9 5 144 144 144
-3 9 5 144 144 144
-2 9 5 144 144 144
-1 9 5 144 144 144
0 9 5 144 144 144
1 9 5 144 144 144
2 9 5 132 104 48
7 9 5 132 104 48
8 9 5 144 144 144
9 9 5 144 144 144
-10 -10 6 108 108 108
-9 -10 6 108 108 108
-8 -10 6 132 104 48
-7 -10 6 132 104 48
-6 -10 6 132 104 48
-5 -10 6 132 104 48
-4 -10 6 132 104 48
-3 -10 6 132 104 48
-2 -10 6 108 108 108
-1 -10 6 108 108 108
0 -10 6 108 108 108
1 -10 6 108 108 108
2 -10 6 108 108 108
3 -10 6 108 108 108
4 -10 6 108 108 108
5 -10 6 108 108 108
6 -10 6 108 108 108
7 -10 6 108 108 108
8 -10 6 108 108 108
9 -10 6 108 108 108
-10 -9 6 108 108 108
9 -9 6 108 108 108
-10 -8 6 108 108 108
9 -8 6 108 108 108
-10 -7 6 108 108 108
9 -7 6 108 108 108
-10 -6 6 108 108 108
9 -6 6 108 108 108
-10 -5 6 108 108 108
3 -5 6 108 108 108
4 -5 6 108 108 108
5 -5 6 108 108 108
6 -5 6 108 108 108
9 -5 6 108 108 108
-10 -4 6 108 108 108
3 -4 6 108 108 108
4 -4 6 160 132 68
5 -4 6 160 132 68
6 -4 6 108 108 108
9 -4 6 108 108 108
-10 -3 6 108 108 108
3 -3 6 108 108 108
4 -3 6 160 132 68
5 -3 6 160 132 68
6 -3 6 108 108 108
9 -3 6 108 108 108
-10 -2 6 108 108 108
2 -2 6 132 104 48
3 -2 6 132 104 48
4 -2 6 160 132 68
5 -2 6 160 132 68
6 -2 6 160 132 68
7 -2 6 132 104 48
9 -2 6 108 108 108
-10 -1 6 108 108 108
2 -1 6 132 104 48
3 -1 6 132 104 48
4 -1 6 132 104 48
5 -1 6 160 132 68
6 -1 6 160 132 68
7 -1 6 132 104 48
9 -1 6 108 108 108
-10 0 6 108 108 108
2 0 6 132 104 48
7 0 6 132 104 48
9 0 6 108 108 108
-10 1 6 108 108 108
2 1 6 132 104 48
7 1 6 132 104 48
9 1 6 108 108 108
-10 2 6 108 108 108
9 2 6 108 108 108
-10 3 6 108 108 108
9 3 6 108 108 108
-10 4 6 108 108 108
9 4 6 108 108 108
-10 5 6 108 108 108
9 5 6 108 108 108
-10 6 6 108 108 108
9 6 6 108 108 108
-10 7 6 108 108 108
9 7 6 108 108 108
-10 8 6 108 108 108
9 8 6 108 108 108
-10 9 6 108 108 108
-9 9 6 108 108 108
-8 9 6 108 108 108
-7 9 6 108 108 108
-6 9 6 108 108 108
-5 9 6 108 108 108
-4 9 6 108 108 108
-3 9 6 108 108 108
-2 9 6 108 108 108
-1 9 6 108 108 108
0 9 6 108 108 108
1 9 6 108 108 108
2 9 6 132 104 48
3 9 6 132 104 48
4 9 6 132 104 48
5 9 6 132 104 48
6 9 6 132 104 48
7 9 6 132 104 48
8 9 6 108 108 108
9 9 6 108 108 108
-10 -10 7 144 144 144
-9 -10 7 144 144 144
-8 -10 7 144 144 144
-7 -10 7 108 108 108
-6 -10 7 144 144 144
-5 -10 7 144 144 144
-4 -10 7 144 144 144
-3 -10 7 144 144 144
-2 -10 7 144 144 144
-1 -10 7 144 144 144
0 -10 7 144 144 144
1 -10 7 108 108 108
2 -10 7 144 144 144
3 -10 7 144 144 144
4 -10 7 144 144 144
5 -10 7 144 144 144
6 -10 7 144 144 144
7 -10 7 108 108 108
8 -10 7 144 144 144
9 -10 7 144 144 144
-10 -9 7 144 144 144
9 -9 7 144 144 144
-10 -8 7 144 144 144
9 -8 7 144 144 144
-10 -7 7 144 144 144
9 -7 7 144 144 144
-10 -6 7 144 144 144
9 -6 7 144 144 144
-10 -5 7 108 108 108
3 -5 7 108 108 108
4 -5 7 108 108 108
5 -5 7 108 108 108
6 -5 7 108 108 108
9 -5 7 144 144 144
-10 -4 7 144 144 144
3 -4 7 108 108 108
4 -4 7 160 132 68
5 -4 7 160 132 68
6 -4 7 108 108 108
9 -4 7 144 144 144
-10 -3 7 144 144 144
2 -3 7 132 104 48
3 -3 7 132 104 48
4 -3 7 160 132 68
5 -3 7 160 132 68
6 -3 7 160 132 68
7 -3 7 132 104 48
9 -3 7 144 144 144
-10 -2 7 144 144 144
2 -2 7 132 104 48
3 -2 7 132 104 48
4 -2 7 132 104 48
5 -2 7 160 132 68
6 -2 7 160 132 68
7 -2 7 132 104 48
9 -2 7 144 144 144
-10 -1 7 144 144 144
2 -1 7 132 104 48
7 -1 7 132 104 48
9 -1 7 108 108 108
-10 0 7 144 144 144
2 0 7 132 104 48
7 0 7 132 104 48
9 0 7 144 144 144
-10 1 7 144 144 144
9 1 7 144 144 144
-10 2 7 144 144 144
9 2 7 144 144 144
-10 3 7 144 144 144
9 3 7 144 144 144
-10 4 7 144 144 144
9 4 7 144 144 144
-10 5 7 108 108 108
9 5 7 144 144 144
-10 6 7 144 144 144
9 6 7 144 144 144
-10 7 7 144 144 144
9 7 7 108 108 108
-10 8 7 144 144 144
9 8 7 144 144 144
-10 9 7 144 144 144
-9 9 7 144 144 144
-8 9 7 144 144 144
-7 9 7 144 144 144
-6 9 7 144 144 144
-5 9 7 144 144 144
-4 9 7 144 144 144
-3 9 7 144 144 144
-2 9 7 144 144 144
-1 9 7 108 108 108
0 9 7 144 144 144
1 9 7 144 144 144
2 9 7 144 144 144
3 9 7 144 144 144
4 9 7 144 144 144
5 9 7 144 144 144
6 9 7 144 144 144
7 9 7 108 108 108
8 9 7 144 144 144
9 9 7 144 144 144
-10 -10 8 144 144 144
-9 -10 8 144 144 144
-8 -10 8 144 144 144
-7 -10 8 108 108 108
-6 -10 8 144 144 144
-5 -10 8 144 144 144
-4 -10 8 144 144 144
-3 -10 8 144 144 144
-2 -10 8 144 144 144
-1 -10 8 144 144 144
0 -10 8 144 144 144
1 -10 8 108 108 108
2 -10 8 144 144 144
3 -10 8 144 144 144
4 -10 8 144 144 144
5 -10 8 144 144 144
6 -10 8 144 144 144
7 -10 8 108 108 108
8 -10 8 144 144 144
9 -10 8 144 144 144
-10 -9 8 144 144 144
6 -9 8 132 104 48
7 -9 8 132 104 48
8 -9 8 132 104 48
9 -9 8 144 144 144
-10 -8 8 144 144 144
9 -8 8 144 144 144
-10 -7 8 144 144 144
9 -7 8 144 144 144
-10 -6 8 144 144 144
9 -6 8 144 144 144
-10 -5 8 108 108 108
3 -5 8 108 108 108
4 -5 8 108 108 108
5 -5 8 108 108 108
6 -5 8 108 108 108
9 -5 8 144 144 144
-10 -4 8 144 144 144
2 -4 8 132 104 48
3 -4 8 132 104 48
4 -4 8 160 132 68
5 -4 8 160 132 68
6 -4 8 160 132 68
7 -4 8 132 104 48
9 -4 8 144 144 144
-10 -3 8 144 144 144
2 -3 8 132 104 48
3 -3 8 132 104 48
4 -3 8 132 104 48
5 -3 8 160 132 68
6 -3 8 160 132 68
7 -3 8 132 104 48
9 -3 8 144 144 144
-10 -2 8 144 144 144
2 -2 8 132 104 48
7 -2 8 132 104 48
9 -2 8 144 144 144
-10 -1 8 144 144 144
2 -1 8 132 104 48
7 -1 8 132 104 48
9 -1 8 108 108 108
-10 0 8 144 144 144
9 0 8 144 144 144
-10 1 8 144 144 144
9 1 8 144 144 144
-10 2 8 144 144 144
9 2 8 144 144 144
-10 3 8 144 144 144
9 3 8 144 144 144
-10 4 8 144 144 144
9 4 8 144 144 144
-10 5 8 108 108 108
9 5 8 144 144 144
-10 6 8 144 144 144
9 6 8 144 144 144
-10 7 8 144 144 144
9 7 8 108 108 108
-10 8 8 144 144 144
9 8 8 144 144 144
-10 9 8 144 144 144
-9 9 8 144 144 144
-8 9 8 144 144 144
-7 9 8 144 144 144
-6 9 8 144 144 144
-5 9 8 144 144 144
-4 9 8 144 144 144
-3 9 8 144 144 144
-2 9 8 144 144 144
-1 9 8 108 108 108
0 9 8 144 144 144
1 9 8 144 144 144
2 9 8 144 144 144
3 9 8 144 144 144
4 9 8 144 144 144
5 9 8 144 144 144
6 9 8 144 144 144
7 9 8 108 108 108
8 9 8 144 144 144
9 9 8 144 144 144
-10 -10 9 108 108 108
-9 -10 9 108 108 108
-8 -10 9 108 108 108
-7 -10 9 108 108 108
-6 -10 9 108 108 108
-5 -10 9 108 108 108
-4 -10 9 108 108 108
-3 -10 9 108 108 108
-2 -10 9 108 108 108
-1 -10 9 108 108 108
0 -10 9 108 108 108
1 -10 9 108 108 108
2 -10 9 108 108 108
3 -10 9 108 108 108
4 -10 9 108 108 108
5 -10 9 108 108 108
6 -10 9 108 108 108
7 -10 9 108 108 108
8 -10 9 108 108 108
9 -10 9 108 108 108
-10 -9 9 108 108 108
9 -9 9 108 108 108
-10 -8 9 108 108 108
9 -8 9 108 108 108
-10 -7 9 108 108 108
9 -7 9 108 108 108
-10 -6 9 108 108 108
9 -6 9 108 108 108
-10 -5 9 108 108 108
2 -5 9 132 104 48
3 -5 9 108 108 108
4 -5 9 108 108 108
5 -5 9 108 108 108
6 -5 9 108 108 108
7 -5 9 132 104 48
9 -5 9 108 108 108
-10 -4 9 108 108 108
2 -4 9 132 104 48
3 -4 9 132 104 48
4 -4 9 132 104 48
5 -4 9 160 132 68
6 -4 9 160 132 68
7 -4 9 132 104 48
9 -4 9 108 108 108
-10 -3 9 108 108 108
2 -3 9 132 104 48
7 -3 9 132 104 48
9 -3 9 108 108 108
-10 -2 9 108 108 108
2 -2 9 132 104 48
7 -2 9 132 104 48
9 -2 9 108 108 108
-10 -1 9 108 108 108
9 -1 9 108 108 108
-10 0 9 108 108 108
9 0 9 108 108 108
-10 1 9 108 108 108
9 1 9 108 108 108
-10 2 9 108 108 108
9 2 9 108 108 108
-10 3 9 108 108 108
9 3 9 108 108 108
-10 4 9 108 108 108
9 4 9 108 108 108
-10 5 9 108 108 108
9 5 9 108 108 108
-10 6 9 108 108 108
9 6 9 108 108 108
-10 7 9 108 108 108
9 7 9 108 108 108
-10 8 9 108 108 108
9 8 9 108 108 108
-10 9 9 108 108 108
-9 9 9 108 108 108
-8 9 9 108 108 108
-7 9 9 108 108 108
-6 9 9 108 108 108
-5 9 9 108 108 108
-4 9 9 108 108 108
-3 9 9 108 108 108
-2 9 9 108 108 108
-1 9 9 108 108 108
0 9 9 108 108 108
1 9 9 108 108 108
2 9 9 108 108 108
3 9 9 108 108 108
4 9 9 108 108 108
5 9 9 108 108 108
6 9 9 108 108 108
7 9 9 108 108 108
8 9 9 108 108 108
9 9 9 108 108 108
-10 -10 10 108 108 108
-9 -10 10 108 108 108
-8 -10 10 108 108 108
-7 -10 10 108 108 108
-6 -10 10 108 108 108
-5 -10 10 108 108 108
-4 -10 10 108 108 108
-3 -10 10 108 108 108
-2 -10 10 108 108 108
-1 -10 10 108 108 108
0 -10 10 108 108 108
1 -10 10 108 108 108
2 -10 10 108 108 108
3 -10 10 108 108 108
4 -10 10 108 108 108
5 -10 10 108 108 108
6 -10 10 108 108 108
7 -10 10 108 108 108
8 -10 10 108 108 108
9 -10 10 108 108 108
-10 -9 10 108 108 108
-9 -9 10 132 104 48
-8 -9 10 132 104 48
-7 -9 10 132 104 48
-6 -9 10 132 104 48
-5 -9 10 132 104 48
-4 -9 10 132 104 48
-3 -9 10 132 104 48
-2 -9 10 132 104 48
-1 -9 10 132 104 48
0 -9 10 132 104 48
1 -9 10 132 104 48
2 -9 10 132 104 48
3 -9 10 132 104 48
4 -9 10 132 104 48
5 -9 10 132 104 48
6 -9 10 132 104 48
7 -9 10 132 104 48
8 -9 10 132 104 48
9 -9 10 108 108 108
-10 -8 10 108 108 108
-9 -8 10 132 104 48
-8 -8 10 160 132 68
-7 -8 10 160 132 68
-6 -8 10 160 132 68
-5 -8 10 160 132 68
-4 -8 10 160 132 68
-3 -8 10 160 132 68
-2 -8 10 160 132 68
-1 -8 10 160 132 68
0 -8 10 160 132 68
1 -8 10 160 132 68
2 -8 10 160 132 68
3 -8 10 160 132 68
4 -8 10 160 132 68
5 -8 10 160 132 68
6 -8 10 160 132 68
7 -8 10 160 132 68
8 -8 10 132 104 48
9 -8 10 108 108 108
-10 -7 10 108 108 108
-9 -7 10 132 104 48
-8 -7 10 160 132 68
-7 -7 10 160 132 68
-6 -7 10 160 132 68
-5 -7 10 160 132 68
-4 -7 10 160 132 68
-3 -7 10 160 132 68
-2 -7 10 160 132 68
-1 -7 10 160 132 68
0 -7 10 160 132 68
1 -7 10 160 132 68
2 -7 10 160 132 68
3 -7 10 160 132 68
4 -7 10 160 132 68
5 -7 10 160 132 68
6 -7 10 160 132 68
7 -7 10 160 132 68
8 -7 10 132 104 48
9 -7 10 108 108 108
-10 -6 10 108 108 108
-9 -6 10 132 104 48
-8 -6 10 160 132 68
-7 -6 10 160 132 68
-6 -6 10 160 132 68
-5 -6 10 160 132 68
-4 -6 10 160 132 68
-3 -6 10 160 132 68
-2 -6 10 160 132 68
-1 -6 10 160 132 68
0 -6 10 160 132 68
1 -6 10 132 104 48
2 -6 10 132 104 48
3 -6 10 132 104 48
4 -6 10 132 104 48
5 -6 10 132 104 48
6 -6 10 132 104 48
7 -6 10 132 104 48
8 -6 10 132 104 48
9 -6 10 108 108 108
-10 -5 10 108 108 108
-9 -5 10 132 104 48
-8 -5 10 160 132 68
-7 -5 10 160 132 68
-6 -5 10 160 132 68
-5 -5 10 160 132 68
-4 -5 10 160 132 68
-3 -5 10 160 132 68
-2 -5 10 160 132 68
-1 -5 10 160 132 68
0 -5 10 160 132 68
1 -5 10 132 104 48
2 -5 10 132 104 48
3 -5 10 132 104 48
4 -5 10 132 104 48
5 -5 10 160 132 68
6 -5 10 160 132 68
7 -5 10 132 104 48
9 -5 10 108 108 108
-10 -4 10 108 108 108
-9 -4 10 132 104 48
-8 -4 10 160 132 68
-7 -4 10 160 132 68
-6 -4 10 160 132 68
-5 -4 10 160 132 68
-4 -4 10 160 132 68
-3 -4 10 160 132 68
-2 -4 10 160 132 68
-1 -4 10 160 132 68
0 -4 10 160 132 68
1 -4 10 132 104 48
2 -4 10 132 104 48
7 -4 10 132 104 48
9 -4 10 108 108 108
-10 -3 10 108 108 108
-9 -3 10 132 104 48
-8 -3 10 160 132 68
-7 -3 10 160 132 68
-6 -3 10 160 132 68
-5 -3 10 160 132 68
-4 -3 10 160 132 68
-3 -3 10 160 132 68
-2 -3 10 160 132 68
-1 -3 10 160 132 68
0 -3 10 160 132 68
1 -3 10 132 104 48
2 -3 10 132 104 48
7 -3 10 132 104 48
9 -3 10 108 108 108
-10 -2 10 108 108 108
-9 -2 10 132 104 48
-8 -2 10 160 132 68
-7 -2 10 160 132 68
-6 -2 10 160 132 68
-5 -2 10 160 132 68
-4 -2 10 160 132 68
-3 -2 10 160 132 68
-2 -2 10 160 132 68
-1 -2 10 160 132 68
0 -2 10 160 132 68
1 -2 10 132 104 48
9 -2 10 108 108 108
-10 -1 10 108 108 108
-9 -1 10 132 104 48
-8 -1 10 160 132 68
-7 -1 10 160 132 68
-6 -1 10 160 132 68
-5 -1 10 160 132 68
-4 -1 10 160 132 68
-3 -1 10 160 132 68
-2 -1 10 160 132 68
-1 -1 10 160 132 68
0 -1 10 160 132 68
1 -1 10 132 104 48
9 -1 10 108 108 108
-10 0 10 108 108 108
-9 0 10 132 104 48
-8 0 10 160 132 68
-7 0 10 160 132 68
-6 0 10 160 132 68
-5 0 10 160 132 68
-4 0 10 160 132 68
-3 0 10 160 132 68
-2 0 10 160 132 68
-1 0 10 160 132 68
0 0 10 160 132 68
1 0 10 132 104 48
9 0 10 108 108 108
-10 1 10 108 108 108
-9 1 10 132 104 48
-8 1 10 160 132 68
-7 1 10 160 132 68
-6 1 10 160 132 68
-5 1 10 160 132 68
-4 1 10 160 132 68
-3 1 10 160 132 68
-2 1 10 160 132 68
-1 1 10 160 132 68
0 1 10 160 132 68
1 1 10 132 104 48
9 1 10 108 108 108
-10 2 10 108 108 108
-9 2 10 132 104 48
-8 2 10 132 104 48
-7 2 10 132 104 48
-6 2 10 132 104 48
-5 2 10 132 104 48
-4 2 10 132 104 48
-3 2 10 132 104 48
-2 2 10 132 104 48
-1 2 10 132 104 48
0 2 10 132 104 48
1 2 10 132 104 48
9 2 10 108 108 108
-10 3 10 108 108 108
9 3 10 108 108 108
-10 4 10 108 108 108
9 4 10 108 108 108
-10 5 10 108 108 108
9 5 10 108 108 108
-10 6 10 108 108 108
9 6 10 108 108 108
-10 7 10 108 108 108
9 7 10 108 108 108
-10 8 10 108 108 108
9 8 10 108 108 108
-10 9 10 108 108 108
-9 9 10 108 108 108
-8 9 10 108 108 108
-7 9 10 108 108 108
-6 9 10 108 108 108
-5 9 10 108 108 108
-4 9 10 108 108 108
-3 9 10 108 108 108
-2 9 10 108 108 108
-1 9 10 108 108 108
0 9 10 108 108 108
1 9 10 108 108 108
2 9 10 108 108 108
3 9 10 108 108 108
4 9 10 108 108 108
5 9 10 108 108 108
6 9 10 108 108 108
7 9 10 108 108 108
8 9 10 108 108 108
9 9 10 108 108 108
-10 -10 11 176 176 176
-9 -10 11 176 176 176
-8 -10 11 176 176 176
-7 -10 11 176 176 176
-6 -10 11 176 176 176
-5 -10 11 176 176 176
-4 -10 11 144 144 144
-3 -10 11 176 176 176
-2 -10 11 176 176 176
-1 -10 11 176 176 176
0 -10 11 176 176 176
1 -10 11 176 176 176
2 -10 11 176 176 176
3 -10 11 176 176 176
4 -10 11 176 176 176
5 -10 11 176 176 176
6 -10 11 176 176 176
7 -10 11 176 176 176
8 -10 11 176 176 176
9 -10 11 176 176 176
-10 -9 11 176 176 176
9 -9 11 176 176 176
-10 -8 11 176 176 176
9 -8 11 176 176 176
-10 -7 11 132 104 48
9 -7 11 176 176 176
9 -6 11 176 176 176
1 -5 11 132 104 48
2 -5 11 132 104 48
7 -5 11 132 104 48
9 -5 11 176 176 176
-5 -4 11 132 104 48
-4 -4 11 132 104 48
-3 -4 11 132 104 48
1 -4 11 132 104 48
2 -4 11 132 104 48
7 -4 11 132 104 48
9 -4 11 176 176 176
-5 -3 11 132 104 48
-4 -3 11 132 104 48
-3 -3 11 132 104 48
1 -3 11 132 104 48
9 -3 11 176 176 176
-10 -2 11 132 104 48
-5 -2 11 132 104 48
-4 -2 11 132 104 48
-3 -2 11 132 104 48
1 -2 11 132 104 48
9 -2 11 176 176 176
-10 -1 11 176 176 176
1 -1 11 132 104 48
9 -1 11 176 176 176
-10 0 11 176 176 176
1 0 11 132 104 48
9 0 11 176 176 176
-10 1 11 176 176 176
1 1 11 132 104 48
9 1 11 176 176 176
-10 2 11 176 176 176
-9 2 11 132 104 48
-8 2 11 132 104 48
-7 2 11 132 104 48
-6 2 11 132 104 48
-5 2 11 132 104 48
-4 2 11 132 104 48
-3 2 11 132 104 48
-2 2 11 132 104 48
-1 2 11 132 104 48
0 2 11 132 104 48
1 2 11 132 104 48
9 2 11 176 176 176
-10 3 11 144 144 144
9 3 11 176 176 176
-10 4 11 176 176 176
9 4 11 144 144 144
-10 5 11 176 176 176
9 5 11 176 176 176
-10 6 11 176 176 176
9 6 11 176 176 176
-10 7 11 176 176 176
9 7 11 176 176 176
-10 8 11 176 176 176
9 8 11 176 176 176
-10 9 11 176 176 176
-9 9 11 176 176 176
-8 9 11 176 176 176
-7 9 11 176 176 176
-6 9 11 176 176 176
-5 9 11 144 144 144
-4 9 11 176 176 176
-3 9 11 176 176 176
-2 9 11 176 176 176
-1 9 11 176 176 176
0 9 11 176 176 176
1 9 11 176 176 176
2 9 11 176 176 176
3 9 11 176 176 176
4 9 11 176 176 176
5 9 11 176 176 176
6 9 11 176 176 176
7 9 11 176 176 176
8 9 11 176 176 176
9 9 11 176 176 176
-10 -10 12 176 176 176
-9 -10 12 176 176 176
-8 -10 12 176 176 176
-7 -10 12 176 176 176
-6 -10 12 176 176 176
-5 -10 12 176 176 176
-4 -10 12 144 144 144
-3 -10 12 200 200 200
-2 -10 12 176 176 176
-1 -10 12 176 176 176
0 -10 12 176 176 176
1 -10 12 176 176 176
2 -10 12 176 176 176
3 -10 12 176 176 176
4 -10 12 176 176 176
5 -10 12 176 176 176
6 -10 12 176 176 176
7 -10 12 176 176 176
8 -10 12 176 176 176
9 -10 12 176 176 176
-10 -9 12 176 176 176
9 -9 12 176 176 176
-10 -8 12 176 176 176
9 -8 12 176 176 176
-10 -7 12 132 104 48
9 -7 12 176 176 176
9 -6 12 176 176 176
2 -5 12 132 104 48
7 -5 12 132 104 48
9 -5 12 176 176 176
-5 -4 12 132 104 48
-4 -4 12 132 104 48
-3 -4 12 132 104 48
9 -4 12 176 176 176
-5 -3 12 132 104 48
-4 -3 12 132 104 48
-3 -3 12 132 104 48
9 -3 12 176 176 176
-10 -2 12 132 104 48
-5 -2 12 132 104 48
-4 -2 12 132 104 48
-3 -2 12 132 104 48
9 -2 12 176 176 176
-10 -1 12 176 176 176
9 -1 12 176 176 176
-10 0 12 176 176 176
9 0 12 176 176 176
-10 1 12 176 176 176
9 1 12 176 176 176
-10 2 12 200 200 200
9 2 12 176 176 176
-10 3 12 144 144 144
9 3 12 176 176 176
-10 4 12 176 176 176
9 4 12 144 144 144
-10 5 12 176 176 176
9 5 12 200 200 200
-10 6 12 176 176 176
9 6 12 176 176 176
-10 7 12 176 176 176
9 7 12 176 176 176
-10 8 12 176 176 176
9 8 12 176 176 176
-10 9 12 176 176 176
-9 9 12 176 176 176
-8 9 12 176 176 176
-7 9 12 176 176 176
-6 9 12 200 200 200
-5 9 12 144 144 144
-4 9 12 176 176 176
-3 9 12 176 176 176
-2 9 12 176 176 176
-1 9 12 176 176 176
0 9 12 176 176 176
1 9 12 176 176 176
2 9 12 176 176 176
3 9 12 176 176 176
4 9 12 176 176 176
5 9 12 176 176 176
6 9 12 176 176 176
7 9 12 176 176 176
8 9 12 176 176 176
9 9 12 176 176 176
-10 -10 13 176 176 176
-9 -10 13 176 176 176
-8 -10 13 176 176 176
-7 -10 13 176 176 176
-6 -10 13 176 176 176
-5 -10 13 176 176 176
-4 -10 13 144 144 144
-3 -10 13 200 200 200
-2 -10 13 200 200 200
-1 -10 13 200 200 200
0 -10 13 200 200 200
1 -10 13 176 176 176
2 -10 13 176 176 176
3 -10 13 176 176 176
4 -10 13 176 176 176
5 -10 13 176 176 176
6 -10 13 176 176 176
7 -10 13 176 176 176
8 -10 13 176 176 176
9 -10 13 176 176 176
-10 -9 13 176 176 176
9 -9 13 176 176 176
-10 -8 13 176 176 176
9 -8 13 176 176 176
-10 -7 13 132 104 48
9 -7 13 176 176 176
9 -6 13 176 176 176
9 -5 13 176 176 176
-5 -4 13 132 104 48
-4 -4 13 132 104 48
-3 -4 13 132 104 48
9 -4 13 176 176 176
-5 -3 13 132 104 48
-4 -3 13 132 104 48
-3 -3 13 132 104 48
9 -3 13 176 176 176
-10 -2 13 132 104 48
-5 -2 13 132 104 48
-4 -2 13 132 104 48
-3 -2 13 132 104 48
9 -2 13 176 176 176
-10 -1 13 176 176 176
9 -1 13 176 176 176
-10 0 13 200 200 200
9 0 13 176 176 176
-10 1 13 200 200 200
9 1 13 176 176 176
-10 2 13 200 200 200
9 2 13 176 176 176
-10 3 13 144 144 144
9 3 13 176 176 176
-10 4 13 176 176 176
9 4 13 144 144 144
-10 5 13 176 176 176
9 5 13 200 200 200
-10 6 13 176 176 176
9 6 13 200 200 200
-10 7 13 176 176 176
9 7 13 200 200 200
-10 8 13 176 176 176
9 8 13 176 176 176
-10 9 13 176 176 176
-9 9 13 176 176 176
-8 9 13 200 200 200
-7 9 13 200 200 200
-6 9 13 200 200 200
-5 9 13 144 144 144
-4 9 13 176 176 176
-3 9 13 176 176 176
-2 9 13 176 176 176
-1 9 13 176 176 176
0 9 13 176 176 176
1 9 13 176 176 176
2 9 13 176 176 176
3 9 13 176 176 176
4 9 13 176 176 176
5 9 13 176 176 176
6 9 13 176 176 176
7 9 13 176 176 176
8 9 13 176 176 176
9 9 13 176 176 176
-10 -10 14 144 144 144
-9 -10 14 144 144 144
-8 -10 14 144 144 144
-7 -10 14 144 144 144
-6 -10 14 144 144 144
-5 -10 14 144 144 144
-4 -10 14 144 144 144
-3 -10 14 144 144 144
-2 -10 14 144 144 144
-1 -10 14 144 144 144
0 -10 14 144 144 144
1 -10 14 144 144 144
2 -10 14 144 144 144
3 -10 14 144 144 144
4 -10 14 144 144 144
5 -10 14 144 144 144
6 -10 14 144 144 144
7 -10 14 144 144 144
8 -10 14 144 144 144
9 -10 14 144 144 144
-10 -9 14 144 144 144
9 -9 14 144 144 144
-10 -8 14 144 144 144
9 -8 14 144 144 144
-10 -7 14 132 104 48
9 -7 14 144 144 144
9 -6 14 144 144 144
9 -5 14 144 144 144
-5 -4 14 132 104 48
-4 -4 14 132 104 48
-3 -4 14 132 104 48
9 -4 14 144 144 144
-5 -3 14 132 104 48
-4 -3 14 132 104 48
-3 -3 14 132 104 48
9 -3 14 144 144 144
-10 -2 14 132 104 48
-5 -2 14 132 104 48
-4 -2 14 132 104 48
-3 -2 14 132 104 48
9 -2 14 144 144 144
-10 -1 14 144 144 144
9 -1 14 144 144 144
-10 0 14 144 144 144
9 0 14 144 144 144
-10 1 14 144 144 144
9 1 14 144 144 144
-10 2 14 144 144 144
9 2 14 144 144 144
-10 3 14 144 144 144
9 3 14 144 144 144
-10 4 14 144 144 144
9 4 14 144 144 144
-10 5 14 144 144 144
9 5 14 144 144 144
-10 6 14 144 144 144
9 6 14 144 144 144
-10 7 14 144 144 144
9 7 14 144 144 144
-10 8 14 144 144 144
9 8 14 144 144 144
-10 9 14 144 144 144
-9 9 14 144 144 144
-8 9 14 144 144 144
-7 9 14 144 144 144
-6 9 14 144 144 144
-5 9 14 144 144 144
-4 9 14 144 144 144
-3 9 14 144 144 144
-2 9 14 144 144 144
-1 9 14 144 144 144
0 9 14 144 144 144
1 9 14 144 144 144
2 9 14 144 144 144
3 9 14 144 144 144
4 9 14 144 144 144
5 9 14 144 144 144
6 9 14 144 144 144
7 9 14 144 144 144
8 9 14 144 144 144
9 9 14 144 144 144
-10 -10 15 176 176 176
-9 -10 15 176 176 176
-8 -10 15 176 176 176
-7 -10 15 144 144 144
-6 -10 15 176 176 176
-5 -10 15 176 176 176
-4 -10 15 176 176 176
-3 -10 15 176 176 176
-2 -10 15 176 176 176
-1 -10 15 176 176 176
0 -10 15 176 176 176
1 -10 15 176 176 176
2 -10 15 176 176 176
3 -10 15 176 176 176
4 -10 15 144 144 144
5 -10 15 176 176 176
6 -10 15 176 176 176
7 -10 15 176 176 176
8 -10 15 176 176 176
9 -10 15 176 176 176
-10 -9 15 176 176 176
9 -9 15 176 176 176
-10 -8 15 176 176 176
9 -8 15 176 176 176
-10 -7 15 132 104 48
9 -7 15 176 176 176
9 -6 15 176 176 176
9 -5 15 176 176 176
-5 -4 15 132 104 48
-4 -4 15 132 104 48
-3 -4 15 132 104 48
9 -4 15 144 144 144
-5 -3 15 132 104 48
-4 -3 15 132 104 48
-3 -3 15 132 104 48
9 -3 15 176 176 176
-10 -2 15 132 104 48
-5 -2 15 132 104 48
-4 -2 15 132 104 48
-3 -2 15 132 104 48
9 -2 15 176 176 176
-10 -1 15 176 176 176
9 -1 15 176 176 176
-10 0 15 176 176 176
9 0 15 176 176 176
-10 1 15 176 176 176
9 1 15 176 176 176
-10 2 15 176 176 176
9 2 15 176 176 176
-10 3 15 176 176 176
9 3 15 176 176 176
-10 4 15 176 176 176
9 4 15 176 176 176
-10 5 15 176 176 176
9 5 15 176 176 176
-10 6 15 144 144 144
9 6 15 176 176 176
-10 7 15 176 176 176
9 7 15 176 176 176
-10 8 15 176 176 176
9 8 15 176 176 176
-10 9 15 176 176 176
-9 9 15 176 176 176
-8 9 15 176 176 176
-7 9 15 176 176 176
-6 9 15 176 176 176
-5 9 15 176 176 176
-4 9 15 176 176 176
-3 9 15 176 176 176
-2 9 15 176 176 176
-1 9 15 176 176 176
0 9 15 176 176 176
1 9 15 176 176 176
2 9 15 176 176 176
3 9 15 144 144 144
4 9 15 176 176 176
5 9 15 176 176 176
6 9 15 176 176 176
7 9 15 176 176 176
8 9 15 176 176 176
9 9 15 176 176 176
-10 -10 16 176 176 176
-9 -10 16 176 176 176
-8 -10 16 176 176 176
-7 -10 16 144 144 144
-6 -10 16 200 200 200
-5 -10 16 176 176 176
-4 -10 16 176 176 176
-3 -10 16 176 176 176
-2 -10 16 176 176 176
-1 -10 16 176 176 176
0 -10 16 176 176 176
1 -10 16 176 176 176
2 -10 16 176 176 176
3 -10 16 176 176 176
4 -10 16 144 144 144
5 -10 16 200 200 200
6 -10 16 176 176 176
7 -10 16 176 176 176
8 -10 16 176 176 176
9 -10 16 176 176 176
-10 -9 16 176 176 176
9 -9 16 176 176 176
-10 -8 16 176 176 176
9 -8 16 176 176 176
-10 -7 16 132 104 48
9 -7 16 176 176 176
-10 -6 16 132 104 48
9 -6 16 176 176 176
-10 -5 16 132 104 48
9 -5 16 176 176 176
-10 -4 16 132 104 48
-5 -4 16 132 104 48
-4 -4 16 132 104 48
-3 -4 16 132 104 48
9 -4 16 144 144 144
-10 -3 16 132 104 48
-5 -3 16 132 104 48
-4 -3 16 132 104 48
-3 -3 16 132 104 48
9 -3 16 200 200 200
-10 -2 16 132 104 48
-5 -2 16 132 104 48
-4 -2 16 132 104 48
-3 -2 16 132 104 48
9 -2 16 176 176 176
-10 -1 16 176 176 176
9 -1 16 176 176 176
-10 0 16 176 176 176
9 0 16 176 176 176
-10 1 16 176 176 176
9 1 16 176 176 176
-10 2 16 176 176 176
9 2 16 176 176 176
-10 3 16 176 176 176
9 3 16 176 176 176
-10 4 16 176 176 176
9 4 16 176 176 176
-10 5 16 200 200 200
9 5 16 176 176 176
-10 6 16 144 144 144
9 6 16 176 176 176
-10 7 16 176 176 176
9 7 16 176 176 176
-10 8 16 176 176 176
9 8 16 176 176 176
-10 9 16 176 176 176
-9 9 16 176 176 176
-8 9 16 176 176 176
-7 9 16 176 176 176
-6 9 16 176 176 176
-5 9 16 176 176 176
-4 9 16 176 176 176
-3 9 16 176 176 176
-2 9 16 176 176 176
-1 9 16 176 176 176
0 9 16 176 176 176
1 9 16 176 176 176
2 9 16 200 200 200
3 9 16 144 144 144
4 9 16 176 176 176
5 9 16 176 176 176
6 9 16 176 176 176
7 9 16 176 176 176
8 9 16 176 176 176
9 9 16 176 176 176
-10 -10 17 176 176 176
-9 -10 17 176 176 176
-8 -10 17 176 176 176
-7 -10 17 144 144 144
-6 -10 17 200 200 200
-5 -10 17 200 200 200
-4 -10 17 200 200 200
-3 -10 17 176 176 176
-2 -10 17 176 176 176
-1 -10 17 176 176 176
0 -10 17 176 176 176
1 -10 17 176 176 176
2 -10 17 176 176 176
3 -10 17 176 176 176
4 -10 17 144 144 144
5 -10 17 200 200 200
6 -10 17 200 200 200
7 -10 17 200 200 200
8 -10 17 176 176 176
9 -10 17 176 176 176
-10 -9 17 176 176 176
9 -9 17 176 176 176
-10 -8 17 176 176 176
9 -8 17 176 176 176
-10 -7 17 176 176 176
9 -7 17 176 176 176
-10 -6 17 176 176 176
9 -6 17 176 176 176
-10 -5 17 176 176 176
9 -5 17 176 176 176
-10 -4 17 176 176 176
-5 -4 17 132 104 48
-4 -4 17 132 104 48
-3 -4 17 132 104 48
9 -4 17 144 144 144
-10 -3 17 176 176 176
-5 -3 17 132 104 48
-4 -3 17 132 104 48
-3 -3 17 132 104 48
9 -3 17 200 200 200
-10 -2 17 176 176 176
-5 -2 17 132 104 48
-4 -2 17 132 104 48
-3 -2 17 132 104 48
9 -2 17 200 200 200
-10 -1 17 176 176 176
9 -1 17 200 200 200
-10 0 17 176 176 176
9 0 17 176 176 176
-10 1 17 176 176 176
9 1 17 176 176 176
-10 2 17 176 176 176
9 2 17 176 176 176
-10 3 17 200 200 200
9 3 17 176 176 176
-10 4 17 200 200 200
9 4 17 176 176 176
-10 5 17 200 200 200
9 5 17 176 176 176
-10 6 17 144 144 144
9 6 17 176 176 176
-10 7 17 176 176 176
9 7 17 176 176 176
-10 8 17 176 176 176
9 8 17 176 176 176
-10 9 17 176 176 176
-9 9 17 176 176 176
-8 9 17 176 176 176
-7 9 17 176 176 176
-6 9 17 176 176 176
-5 9 17 176 176 176
-4 9 17 176 176 176
-3 9 17 176 176 176
-2 9 17 176 176 176
-1 9 17 176 176 176
0 9 17 200 200 200
1 9 17 200 200 200
2 9 17 200 200 200
3 9 17 144 144 144
4 9 17 176 176 176
5 9 17 176 176 176
6 9 17 176 176 176
7 9 17 176 176 176
8 9 17 176 176 176
9 9 17 176 176 176
-10 -10 18 144 144 144
-9 -10 18 144 144 144
-8 -10 18 144 144 144
-7 -10 18 144 144 144
-6 -10 18 144 144 144
-5 -10 18 144 144 144
-4 -10 18 144 144 144
-3 -10 18 144 144 144
-2 -10 18 144 144 144
-1 -10 18 144 144 144
0 -10 18 144 144 144
1 -10 18 144 144 144
2 -10 18 144 144 144
3 -10 18 144 144 144
4 -10 18 144 144 144
5 -10 18 144 144 144
6 -10 18 144 144 144
7 -10 18 144 144 144
8 -10 18 144 144 144
9 -10 18 144 144 144
-10 -9 18 144 144 144
9 -9 18 144 144 144
-10 -8 18 144 144 144
9 -8 18 144 144 144
-10 -7 18 144 144 144
9 -7 18 144 144 144
-10 -6 18 144 144 144
9 -6 18 144 144 144
-10 -5 18 144 144 144
9 -5 18 144 144 144
-10 -4 18 144 144 144
-5 -4 18 132 104 48
-4 -4 18 132 104 48
-3 -4 18 132 104 48
9 -4 18 144 144 144
-10 -3 18 144 144 144
-5 -3 18 132 104 48
-4 -3 18 132 104 48
-3 -3 18 132 104 48
9 -3 18 144 144 144
-10 -2 18 144 144 144
-5 -2 18 132 104 48
-4 -2 18 132 104 48
-3 -2 18 132 104 48
9 -2 18 144 144 144
-10 -1 18 144 144 144
9 -1 18 144 144 144
-10 0 18 144 144 144
9 0 18 144 144 144
-10 1 18 144 144 144
9 1 18 144 144 144
-10 2 18 144 144 144
9 2 18 144 144 144
-10 3 18 144 144 144
9 3 18 144 144 144
-10 4 18 144 144 144
9 4 18 144 144 144
-10 5 18 144 144 144
9 5 18 144 144 144
-10 6 18 144 144 144
9 6 18 144 144 144
-10 7 18 144 144 144
9 7 18 144 144 144
-10 8 18 144 144 144
9 8 18 144 144 144
-10 9 18 144 144 144
-9 9 18 144 144 144
-8 9 18 144 144 144
-7 9 18 144 144 144
-6 9 18 144 144 144
-5 9 18 144 144 144
-4 9 18 144 144 144
-3 9 18 144 144 144
-2 9 18 144 144 144
-1 9 18 144 144 144
0 9 18 144 144 144
1 9 18 144 144 144
2 9 18 144 144 144
3 9 18 144 144 144
4 9 18 144 144 144
5 9 18 144 144 144
6 9 18 144 144 144
7 9 18 144 144 144
8 9 18 144 144 144
9 9 18 144 144 144
-10 -10 19 144 144 144
-9 -10 19 144 144 144
-8 -10 19 144 144 144
-7 -10 19 144 144 144
-6 -10 19 144 144 144
-5 -10 19 144 144 144
-4 -10 19 144 144 144
-3 -10 19 144 144 144
-2 -10 19 144 144 144
-1 -10 19 144 144 144
0 -10 19 144 144 144
1 -10 19 144 144 144
2 -10 19 144 144 144
3 -10 19 144 144 144
4 -10 19 144 144 144
5 -10 19 144 144 144
6 -10 19 144 144 144
7 -10 19 144 144 144
8 -10 19 144 144 144
9 -10 19 144 144 144
-10 -9 19 144 144 144
-9 -9 19 144 144 144
-8 -9 19 144 144 144
-7 -9 19 144 144 144
-6 -9 19 144 144 144
-5 -9 19 144 144 144
-4 -9 19 144 144 144
-3 -9 19 144 144 144
-2 -9 19 144 144 144
-1 -9 19 144 144 144
0 -9 19 144 144 144
1 -9 19 144 144 144
2 -9 19 144 144 144
3 -9 19 144 144 144
4 -9 19 144 144 144
5 -9 19 144 144 144
6 -9 19 144 144 144
7 -9 19 144 144 144
8 -9 19 144 144 144
9 -9 19 144 144 144
-10 -8 19 144 144 144
-9 -8 19 144 144 144
-8 -8 19 144 144 144
-7 -8 19 144 144 144
-6 -8 19 144 144 144
-5 -8 19 144 144 144
-4 -8 19 144 144 144
-3 -8 19 144 144 144
-2 -8 19 144 144 144
-1 -8 19 144 144 144
0 -8 19 144 144 144
1 -8 19 144 144 144
2 -8 19 144 144 144
3 -8 19 144 144 144
4 -8 19 144 144 144
5 -8 19 144 144 144
6 -8 19 144 144 144
7 -8 19 144 144 144
8 -8 19 144 144 144
9 -8 19 144 144 144
-10 -7 19 144 144 144
-9 -7 19 144 144 144
-8 -7 19 144 144 144
-7 -7 19 144 144 144
-6 -7 19 144 144 144
-5 -7 19 144 144 144
-4 -7 19 144 144 144
-3 -7 19 144 144 144
-2 -7 19 144 144 144
-1 -7 19 144 144 144
0 -7 19 144 144 144
1 -7 19 144 144 144
2 -7 19 144 144 144
3 -7 19 144 144 144
4 -7 19 144 144 144
5 -7 19 144 144 144
6 -7 19 144 144 144
7 -7 19 144 144 144
8 -7 19 144 144 144
9 -7 19 144 144 144
-10 -6 19 144 144 144
-9 -6 19 144 144 144
-8 -6 19 144 144 144
-7 -6 19 144 144 144
-6 -6 19 144 144 144
-5 -6 19 144 144 144
-4 -6 19 144 144 144
-3 -6 19 144 144 144
-2 -6 19 144 144 144
-1 -6 19 144 144 144
0 -6 19 144 144 144
1 -6 19 144 144 144
2 -6 19 144 144 144
3 -6 19 144 144 144
4 -6 19 144 144 144
5 -6 19 144 144 144
6 -6 19 144 144 144
7 -6 19 144 144 144
8 -6 19 144 144 144
9 -6 19 144 144 144
-10 -5 19 144 144 144
-9 -5 19 144 144 144
-8 -5 19 144 144 144
-7 -5 19 144 144 144
-6 -5 19 144 144 144
-5 -5 19 144 144 144
-4 -5 19 144 144 144
-3 -5 19 144 144 144
-2 -5 19 144 144 144
-1 -5 19 144 144 144
0 -5 19 144 144 144
1 -5 19 144 144 144
2 -5 19 144 144 144
3 -5 19 144 144 144
4 -5 19 144 144 144
5 -5 19 144 144 144
6 -5 19 144 144 144
7 -5 19 144 144 144
8 -5 19 144 144 144
9 -5 19 144 144 144
-10 -4 19 144 144 144
-9 -4 19 144 144 144
-8 -4 19 144 144 144
-7 -4 19 144 144 144
-6 -4 19 144 144 144
-5 -4 19 144 144 144
-4 -4 19 144 144 144
-3 -4 19 144 144 144
-2 -4 19 144 144 144
-1 -4 19 144 144 144
0 -4 19 144 144 144
1 -4 19 144 144 144
2 -4 19 144 144 144
3 -4 19 144 144 144
4 -4 19 144 144 144
5 -4 19 144 144 144
6 -4 19 144 144 144
7 -4 19 144 144 144
8 -4 19 144 144 144
9 -4 19 144 144 144
-10 -3 19 144 144 144
-9 -3 19 144 144 144
-8 -3 19 144 144 144
-7 -3 19 144 144 144
-6 -3 19 144 144 144
-5 -3 19 144 144 144
-4 -3 19 144 144 144
-3 -3 19 144 144 144
-2 -3 19 144 144 144
-1 -3 19 144 144 144
0 -3 19 144 144 144
1 -3 19 144 144 144
2 -3 19 144 144 144
3 -3 19 144 144 144
4 -3 19 144 144 144
5 -3 19 144 144 144
6 -3 19 144 144 144
7 -3 19 144 144 144
8 -3 19 144 144 144
9 -3 19 144 144 144
-10 -2 19 144 144 144
-9 -2 19 144 144 144
-8 -2 19 144 144 144
-7 -2 19 144 144 144
-6 -2 19 144 144 144
-5 -2 19 144 144 144
-4 -2 19 144 144 144
-3 -2 19 144 144 144
-2 -2 19 144 144 144
-1 -2 19 144 144 144
0 -2 19 144 144 144
1 -2 19 144 144 144
2 -2 19 144 144 144
3 -2 19 144 144 144
4 -2 19 144 144 144
5 -2 19 144 144 144
6 -2 19 144 144 144
7 -2 19 144 144 144
8 -2 19 144 144 144
9 -2 19 144 144 144
-10 -1 19 144 144 144
-9 -1 19 144 144 144
-8 -1 19 144 144 144
-7 -1 19 144 144 144
-6 -1 19 144 144 144
-5 -1 19 144 144 144
-4 -1 19 144 144 144
-3 -1 19 144 144 144
-2 -1 19 144 144 144
-1 -1 19 144 144 144
0 -1 19 144 144 144
1 -1 19 144 144 144
2 -1 19 144 144 144
3 -1 19 144 144 144
4 -1 19 144 144 144
5 -1 19 144 144 144
6 -1 19 144 144 144
7 -1 19 144 144 144
8 -1 19 144 144 144
9 -1 19 144 144 144
-10 0 19 144 144 144
-9 0 19 144 144 144
-8 0 19 144 144 144
-7 0 19 144 144 144
-6 0 19 144 144 144
-5 0 19 144 144 144
-4 0 19 144 144 144
-3 0 19 144 144 144
-2 0 19 144 144 144
-1 0 19 144 144 144
0 0 19 144 144 144
1 0 19 144 144 144
2 0 19 144 144 144
3 0 19 144 144 144
4 0 19 144 144 144
5 0 19 144 144 144
6 0 19 144 144 144
7 0 19 144 144 144
8 0 19 144 144 144
9 0 19 144 144 144
-10 1 19 144 144 144
-9 1 19 144 144 144
-8 1 19 144 144 144
-7 1 19 144 144 144
-6 1 19 144 144 144
-5 1 19 144 144 144
-4 1 19 144 144 144
-3 1 19 144 144 144
-2 1 19 144 144 144
-1 1 19 144 144 144
0 1 19 144 144 144
1 1 19 144 144 144
2 1 19 144 144 144
3 1 19 144 144 144
4 1 19 144 144 144
5 1 19 144 144 144
6 1 19 144 144 144
7 1 19 144 144 144
8 1 19 144 144 144
9 1 19 144 144 144
-10 2 19 144 144 144
-9 2 19 144 144 144
-8 2 19 144 144 144
-7 2 19 144 144 144
-6 2 19 144 144 144
-5 2 19 144 144 144
-4 2 19 144 144 144
-3 2 19 144 144 144
-2 2 19 144 144 144
-1 2 19 144 144 144
0 2 19 144 144 144
1 2 19 144 144 144
2 2 19 144 144 144
3 2 19 144 144 144
4 2 19 144 144 144
5 2 19 144 144 144
6 2 19 144 144 144
7 2 19 144 144 144
8 2 19 144 144 144
9 2 19 144 144 144
-10 3 19 144 144 144
-9 3 19 144 144 144
-8 3 19 144 144 144
-7 3 19 144 144 144
-6 3 19 144 144 144
-5 3 19 144 144 144
-4 3 19 144 144 144
-3 3 19 144 144 144
-2 3 19 144 144 144
-1 3 19 144 144 144
0 3 19 144 144 144
1 3 19 144 144 144
2 3 19 144 144 144
3 3 19 144 144 144
4 3 19 144 144 144
5 3 19 144 144 144
6 3 19 144 144 144
7 3 19 144 144 144
8 3 19 144 144 144
9 3 19 144 144 144
-10 4 19 144 144 144
-9 4 19 144 144 144
-8 4 19 144 144 144
-7 4 19 144 144 144
-6 4 19 144 144 144
-5 4 19 144 144 144
-4 4 19 144 144 144
-3 4 19 144 144 144
-2 4 19 144 144 144
-1 4 19 144 144 144
0 4 19 144 144 144
1 4 19 144 144 144
2 4 19 144 144 144
3 4 19 144 144 144
4 4 19 144 144 144
5 4 19 144 144 144
6 4 19 144 144 144
7 4 19 144 144 144
8 4 19 144 144 144
9 4 19 144 144 144
-10 5 19 144 144 144
-9 5 19 144 144 144
-8 5 19 144 144 144
-7 5 19 144 144 144
-6 5 19 144 144 144
-5 5 19 144 144 144
-4 5 19 144 144 144
-3 5 19 144 144 144
-2 5 19 144 144 144
-1 5 19 144 144 144
0 5 19 144 144 144
1 5 19 144 144 144
2 5 19 144 144 144
3 5 19 144 144 144
4 5 19 144 144 144
5 5 19 144 144 144
6 5 19 144 144 144
7 5 19 144 144 144
8 5 19 144 144 144
9 5 19 144 144 144
-10 6 19 144 144 144
-9 6 19 144 144 144
-8 6 19 144 144 144
-7 6 19 144 144 144
-6 6 19 144 144 144
-5 6 19 144 144 144
-4 6 19 144 144 144
-3 6 19 144 144 144
-2 6 19 144 144 144
-1 6 19 144 144 144
0 6 19 144 144 144
1 6 19 144 144 144
2 6 19 144 144 144
3 6 19 144 144 144
4 6 19 144 144 144
5 6 19 144 144 144
6 6 19 144 144 144
7 6 19 144 144 144
8 6 19 144 144 144
9 6 19 144 144 144
-10 7 19 144 144 144
-9 7 19 144 144 144
-8 7 19 144 144 144
-7 7 19 144 144 144
-6 7 19 144 144 144
-5 7 19 144 144 144
-4 7 19 144 144 144
-3 7 19 144 144 144
-2 7 19 144 144 144
-1 7 19 144 144 144
0 7 19 144 144 144
1 7 19 144 144 144
2 7 19 144 144 144
3 7 19 144 144 144
4 7 19 144 144 144
5 7 19 144 144 144
6 7 19 144 144 144
7 7 19 144 144 144
8 7 19 144 144 144
9 7 19 144 144 144
-10 8 19 144 144 144
-9 8 19 144 144 144
-8 8 19 144 144 144
-7 8 19 144 144 144
-6 8 19 144 144 144
-5 8 19 144 144 144
-4 8 19 144 144 144
-3 8 19 144 144 144
-2 8 19 144 144 144
-1 8 19 144 144 144
0 8 19 144 144 144
1 8 19 144 144 144
2 8 19 144 144 144
3 8 19 144 144 144
4 8 19 144 144 144
5 8 19 144 144 144
6 8 19 144 144 144
7 8 19 144 144 144
8 8 19 144 144 144
9 8 19 144 144 144
-10 9 19 144 144 144
-9 9 19 144 144 144
-8 9 19 144 144 144
-7 9 19 144 144 144
-6 9 19 144 144 144
-5 9 19 144 144 144
-4 9 19 144 144 144
-3 9 19 144 144 144
-2 9 19 144 144 144
-1 9 19 144 144 144
0 9 19 144 144 144
1 9 19 144 144 144
2 9 19 144 144 144
3 9 19 144 144 144
4 9 19 144 144 144
5 9 19 144 144 144
6 9 19 144 144 144
7 9 19 144 144 144
8 9 19 144 144 144
9 9 19 144 144 144
