ply
format ascii 1.0
comment : MagicaVoxel @ Ephtracy
element vertex 5480
property float x
property float y
property float z
property uchar red
property uchar green
property uchar blue
end_header
-15 -15 0 132 104 48
-14 -15 0 132 104 48
-13 -15 0 132 104 48
-12 -15 0 132 104 48
-11 -15 0 132 104 48
-10 -15 0 132 104 48
-9 -15 0 132 104 48
-8 -15 0 132 104 48
-7 -15 0 132 104 48
-6 -15 0 132 104 48
-5 -15 0 132 104 48
-4 -15 0 132 104 48
-3 -15 0 132 104 48
-2 -15 0 108 108 108
-1 -15 0 108 108 108
0 -15 0 108 108 108
1 -15 0 108 108 108
2 -15 0 132 104 48
3 -15 0 132 104 48
4 -15 0 132 104 48
5 -15 0 132 104 48
6 -15 0 132 104 48
7 -15 0 132 104 48
8 -15 0 132 104 48
9 -15 0 132 104 48
10 -15 0 132 104 48
11 -15 0 132 104 48
12 -15 0 132 104 48
13 -15 0 132 104 48
14 -15 0 132 104 48
-15 -14 0 132 104 48
-14 -14 0 132 104 48
-13 -14 0 132 104 48
-12 -14 0 132 104 48
-11 -14 0 132 104 48
-10 -14 0 132 104 48
-9 -14 0 132 104 48
-8 -14 0 132 104 48
-7 -14 0 132 104 48
-6 -14 0 132 104 48
-5 -14 0 132 104 48
-4 -14 0 132 104 48
-3 -14 0 132 104 48
-2 -14 0 136 0 0
-1 -14 0 136 0 0
0 -14 0 136 0 0
1 -14 0 136 0 0
2 -14 0 132 104 48
3 -14 0 132 104 48
4 -14 0 132 104 48
5 -14 0 132 104 48
6 -14 0 132 104 48
7 -14 0 132 104 48
8 -14 0 132 104 48
9 -14 0 132 104 48
10 -14 0 132 104 48
11 -14 0 132 104 48
12 -14 0 132 104 48
13 -14 0 132 104 48
14 -14 0 132 104 48
-15 -13 0 132 104 48
-14 -13 0 132 104 48
-13 -13 0 132 104 48
-12 -13 0 132 104 48
-11 -13 0 132 104 48
-10 -13 0 132 104 48
-9 -13 0 132 104 48
-8 -13 0 132 104 48
-7 -13 0 132 104 48
-6 -13 0 132 104 48
-5 -13 0 132 104 48
-4 -13 0 132 104 48
-3 -13 0 132 104 48
-2 -13 0 136 0 0
-1 -13 0 156 32 32
0 -13 0 156 32 32
1 -13 0 136 0 0
2 -13 0 132 104 48
3 -13 0 132 104 48
4 -13 0 132 104 48
5 -13 0 132 104 48
6 -13 0 132 104 48
7 -13 0 132 104 48
8 -13 0 132 104 48
9 -13 0 132 104 48
10 -13 0 132 104 48
11 -13 0 132 104 48
12 -13 0 132 104 48
13 -13 0 132 104 48
14 -13 0 132 104 48
-15 -12 0 132 104 48
-14 -12 0 132 104 48
-13 -12 0 132 104 48
-12 -12 0 132 104 48
-11 -12 0 132 104 48
-10 -12 0 132 104 48
-9 -12 0 132 104 48
-8 -12 0 132 104 48
-7 -12 0 132 104 48
-6 -12 0 132 104 48
-5 -12 0 132 104 48
-4 -12 0 132 104 48
-3 -12 0 132 104 48
-2 -12 0 136 0 0
-1 -12 0 156 32 32
0 -12 0 156 32 32
1 -12 0 136 0 0
2 -12 0 132 104 48
3 -12 0 132 104 48
4 -12 0 132 104 48
5 -12 0 132 104 48
6 -12 0 132 104 48
7 -12 0 132 104 48
8 -12 0 132 104 48
9 -12 0 132 104 48
10 -12 0 132 104 48
11 -12 0 132 104 48
12 -12 0 132 104 48
13 -12 0 132 104 48
14 -12 0 132 104 48
-15 -11 0 132 104 48
-14 -11 0 132 104 48
-13 -11 0 132 104 48
-12 -11 0 132 104 48
-11 -11 0 132 104 48
-10 -11 0 132 104 48
-9 -11 0 132 104 48
-8 -11 0 132 104 48
-7 -11 0 132 104 48
-6 -11 0 132 104 48
-5 -11 0 132 104 48
-4 -11 0 132 104 48
-3 -11 0 132 104 48
-2 -11 0 136 0 0
-1 -11 0 156 32 32
0 -11 0 156 32 32
1 -11 0 136 0 0
2 -11 0 132 104 48
3 -11 0 132 104 48
4 -11 0 132 104 48
5 -11 0 132 104 48
6 -11 0 132 104 48
7 -11 0 132 104 48
8 -11 0 132 104 48
9 -11 0 132 104 48
10 -11 0 132 104 48
11 -11 0 132 104 48
12 -11 0 132 104 48
13 -11 0 132 104 48
14 -11 0 132 104 48
-15 -10 0 132 104 48
-14 -10 0 132 104 48
-13 -10 0 132 104 48
-12 -10 0 132 104 48
-11 -10 0 132 104 48
-10 -10 0 132 104 48
-9 -10 0 132 104 48
-8 -10 0 132 104 48
-7 -10 0 132 104 48
-6 -10 0 132 104 48
-5 -10 0 132 104 48
-4 -10 0 132 104 48
-3 -10 0 132 104 48
-2 -10 0 136 0 0
-1 -10 0 156 32 32
0 -10 0 156 32 32
1 -10 0 136 0 0
2 -10 0 132 104 48
3 -10 0 132 104 48
4 -10 0 132 104 48
5 -10 0 132 104 48
6 -10 0 132 104 48
7 -10 0 132 104 48
8 -10 0 132 104 48
9 -10 0 132 104 48
10 -10 0 132 104 48
11 -10 0 132 104 48
12 -10 0 132 104 48
13 -10 0 132 104 48
14 -10 0 132 104 48
-15 -9 0 132 104 48
-14 -9 0 132 104 48
-13 -9 0 132 104 48
-12 -9 0 132 104 48
-11 -9 0 132 104 48
-10 -9 0 132 104 48
-9 -9 0 132 104 48
-8 -9 0 132 104 48
-7 -9 0 132 104 48
-6 -9 0 132 104 48
-5 -9 0 132 104 48
-4 -9 0 132 104 48
-3 -9 0 132 104 48
-2 -9 0 136 0 0
-1 -9 0 156 32 32
0 -9 0 156 32 32
1 -9 0 136 0 0
2 -9 0 132 104 48
3 -9 0 132 104 48
4 -9 0 132 104 48
5 -9 0 132 104 48
6 -9 0 132 104 48
7 -9 0 132 104 48
8 -9 0 132 104 48
9 -9 0 132 104 48
10 -9 0 132 104 48
11 -9 0 132 104 48
12 -9 0 132 104 48
13 -9 0 132 104 48
14 -9 0 132 104 48
-15 -8 0 132 104 48
-14 -8 0 132 104 48
-13 -8 0 132 104 48
-12 -8 0 132 104 48
-11 -8 0 132 104 48
-10 -8 0 132 104 48
-9 -8 0 132 104 48
-8 -8 0 132 104 48
-7 -8 0 132 104 48
-6 -8 0 132 104 48
-5 -8 0 132 104 48
-4 -8 0 132 104 48
-3 -8 0 132 104 48
-2 -8 0 136 0 0
-1 -8 0 156 32 32
0 -8 0 156 32 32
1 -8 0 136 0 0
2 -8 0 132 104 48
3 -8 0 132 104 48
4 -8 0 132 104 48
5 -8 0 132 104 48
6 -8 0 132 104 48
7 -8 0 132 104 48
8 -8 0 132 104 48
9 -8 0 132 104 48
10 -8 0 132 104 48
11 -8 0 132 104 48
12 -8 0 132 104 48
13 -8 0 132 104 48
14 -8 0 132 104 48
-15 -7 0 132 104 48
-14 -7 0 132 104 48
-13 -7 0 132 104 48
-12 -7 0 132 104 48
-11 -7 0 132 104 48
-10 -7 0 132 104 48
-9 -7 0 132 104 48
-8 -7 0 132 104 48
-7 -7 0 132 104 48
-6 -7 0 132 104 48
-5 -7 0 132 104 48
-4 -7 0 132 104 48
-3 -7 0 132 104 48
-2 -7 0 136 0 0
-1 -7 0 156 32 32
0 -7 0 156 32 32
1 -7 0 136 0 0
2 -7 0 132 104 48
3 -7 0 132 104 48
4 -7 0 132 104 48
5 -7 0 132 104 48
6 -7 0 132 104 48
7 -7 0 132 104 48
8 -7 0 132 104 48
9 -7 0 132 104 48
10 -7 0 132 104 48
11 -7 0 132 104 48
12 -7 0 132 104 48
13 -7 0 132 104 48
14 -7 0 132 104 48
-15 -6 0 132 104 48
-14 -6 0 132 104 48
-13 -6 0 132 104 48
-12 -6 0 132 104 48
-11 -6 0 132 104 48
-10 -6 0 132 104 48
-9 -6 0 132 104 48
-8 -6 0 132 104 48
-7 -6 0 132 104 48
-6 -6 0 132 104 48
-5 -6 0 132 104 48
-4 -6 0 132 104 48
-3 -6 0 132 104 48
-2 -6 0 136 0 0
-1 -6 0 156 32 32
0 -6 0 156 32 32
1 -6 0 136 0 0
2 -6 0 132 104 48
3 -6 0 132 104 48
4 -6 0 132 104 48
5 -6 0 132 104 48
6 -6 0 132 104 48
7 -6 0 132 104 48
8 -6 0 132 104 48
9 -6 0 132 104 48
10 -6 0 132 104 48
11 -6 0 132 104 48
12 -6 0 132 104 48
13 -6 0 132 104 48
14 -6 0 132 104 48
-15 -5 0 132 104 48
-14 -5 0 132 104 48
-13 -5 0 132 104 48
-12 -5 0 132 104 48
-11 -5 0 132 104 48
-10 -5 0 132 104 48
-9 -5 0 132 104 48
-8 -5 0 132 104 48
-7 -5 0 132 104 48
-6 -5 0 132 104 48
-5 -5 0 132 104 48
-4 -5 0 132 104 48
-3 -5 0 132 104 48
-2 -5 0 136 0 0
-1 -5 0 156 32 32
0 -5 0 156 32 32
1 -5 0 136 0 0
2 -5 0 132 104 48
3 -5 0 132 104 48
4 -5 0 132 104 48
5 -5 0 132 104 48
6 -5 0 132 104 48
7 -5 0 132 104 48
8 -5 0 132 104 48
9 -5 0 132 104 48
10 -5 0 132 104 48
11 -5 0 132 104 48
12 -5 0 132 104 48
13 -5 0 132 104 48
14 -5 0 132 104 48
-15 -4 0 132 104 48
-14 -4 0 132 104 48
-13 -4 0 132 104 48
-12 -4 0 132 104 48
-11 -4 0 132 104 48
-10 -4 0 132 104 48
-9 -4 0 132 104 48
-8 -4 0 132 104 48
-7 -4 0 132 104 48
-6 -4 0 132 104 48
-5 -4 0 132 104 48
-4 -4 0 132 104 48
-3 -4 0 132 104 48
-2 -4 0 136 0 0
-1 -4 0 156 32 32
0 -4 0 156 32 32
1 -4 0 136 0 0
2 -4 0 132 104 48
3 -4 0 132 104 48
4 -4 0 132 104 48
5 -4 0 132 104 48
6 -4 0 132 104 48
7 -4 0 132 104 48
8 -4 0 132 104 48
9 -4 0 132 104 48
10 -4 0 132 104 48
11 -4 0 132 104 48
12 -4 0 132 104 48
13 -4 0 132 104 48
14 -4 0 132 104 48
-15 -3 0 132 104 48
-14 -3 0 132 104 48
-13 -3 0 132 104 48
-12 -3 0 132 104 48
-11 -3 0 132 104 48
-10 -3 0 132 104 48
-9 -3 0 132 104 48
-8 -3 0 132 104 48
-7 -3 0 132 104 48
-6 -3 0 132 104 48
-5 -3 0 132 104 48
-4 -3 0 132 104 48
-3 -3 0 132 104 48
-2 -3 0 136 0 0
-1 -3 0 156 32 32
0 -3 0 156 32 32
1 -3 0 136 0 0
2 -3 0 132 104 48
3 -3 0 132 104 48
4 -3 0 132 104 48
5 -3 0 132 104 48
6 -3 0 132 104 48
7 -3 0 132 104 48
8 -3 0 132 104 48
9 -3 0 132 104 48
10 -3 0 132 104 48
11 -3 0 132 104 48
12 -3 0 132 104 48
13 -3 0 132 104 48
14 -3 0 132 104 48
-15 -2 0 108 108 108
-14 -2 0 136 0 0
-13 -2 0 136 0 0
-12 -2 0 136 0 0
-11 -2 0 136 0 0
-10 -2 0 136 0 0
-9 -2 0 136 0 0
-8 -2 0 136 0 0
-7 -2 0 136 0 0
-6 -2 0 136 0 0
-5 -2 0 136 0 0
-4 -2 0 136 0 0
-3 -2 0 136 0 0
-2 -2 0 136 0 0
-1 -2 0 156 32 32
0 -2 0 156 32 32
1 -2 0 136 0 0
2 -2 0 136 0 0
3 -2 0 136 0 0
4 -2 0 136 0 0
5 -2 0 136 0 0
6 -2 0 136 0 0
7 -2 0 136 0 0
8 -2 0 136 0 0
9 -2 0 136 0 0
10 -2 0 136 0 0
11 -2 0 136 0 0
12 -2 0 136 0 0
13 -2 0 136 0 0
14 -2 0 108 108 108
-15 -1 0 108 108 108
-14 -1 0 136 0 0
-13 -1 0 156 32 32
-12 -1 0 156 32 32
-11 -1 0 156 32 32
-10 -1 0 156 32 32
-9 -1 0 156 32 32
-8 -1 0 156 32 32
-7 -1 0 156 32 32
-6 -1 0 156 32 32
-5 -1 0 156 32 32
-4 -1 0 156 32 32
-3 -1 0 156 32 32
-2 -1 0 156 32 32
-1 -1 0 156 32 32
0 -1 0 156 32 32
1 -1 0 156 32 32
2 -1 0 156 32 32
3 -1 0 156 32 32
4 -1 0 156 32 32
5 -1 0 156 32 32
6 -1 0 156 32 32
7 -1 0 156 32 32
8 -1 0 156 32 32
9 -1 0 156 32 32
10 -1 0 156 32 32
11 -1 0 156 32 32
12 -1 0 156 32 32
13 -1 0 136 0 0
14 -1 0 108 108 108
-15 0 0 108 108 108
-14 0 0 136 0 0
-13 0 0 156 32 32
-12 0 0 156 32 32
-11 0 0 156 32 32
-10 0 0 156 32 32
-9 0 0 156 32 32
-8 0 0 156 32 32
-7 0 0 156 32 32
-6 0 0 156 32 32
-5 0 0 156 32 32
-4 0 0 156 32 32
-3 0 0 156 32 32
-2 0 0 156 32 32
-1 0 0 156 32 32
0 0 0 156 32 32
1 0 0 156 32 32
2 0 0 156 32 32
3 0 0 156 32 32
4 0 0 156 32 32
5 0 0 156 32 32
6 0 0 156 32 32
7 0 0 156 32 32
8 0 0 156 32 32
9 0 0 156 32 32
10 0 0 156 32 32
11 0 0 156 32 32
12 0 0 156 32 32
13 0 0 136 0 0
14 0 0 108 108 108
-15 1 0 108 108 108
-14 1 0 136 0 0
-13 1 0 136 0 0
-12 1 0 136 0 0
-11 1 0 136 0 0
-10 1 0 136 0 0
-9 1 0 136 0 0
-8 1 0 136 0 0
-7 1 0 136 0 0
-6 1 0 136 0 0
-5 1 0 136 0 0
-4 1 0 136 0 0
-3 1 0 136 0 0
-2 1 0 136 0 0
-1 1 0 156 32 32
0 1 0 156 32 32
1 1 0 136 0 0
2 1 0 136 0 0
3 1 0 136 0 0
4 1 0 136 0 0
5 1 0 136 0 0
6 1 0 136 0 0
7 1 0 136 0 0
8 1 0 136 0 0
9 1 0 136 0 0
10 1 0 136 0 0
11 1 0 136 0 0
12 1 0 136 0 0
13 1 0 136 0 0
14 1 0 108 108 108
-15 2 0 132 104 48
-14 2 0 132 104 48
-13 2 0 132 104 48
-12 2 0 132 104 48
-11 2 0 132 104 48
-10 2 0 132 104 48
-9 2 0 132 104 48
-8 2 0 132 104 48
-7 2 0 132 104 48
-6 2 0 132 104 48
-5 2 0 132 104 48
-4 2 0 132 104 48
-3 2 0 132 104 48
-2 2 0 136 0 0
-1 2 0 156 32 32
0 2 0 156 32 32
1 2 0 136 0 0
2 2 0 132 104 48
3 2 0 132 104 48
4 2 0 132 104 48
5 2 0 132 104 48
6 2 0 132 104 48
7 2 0 132 104 48
8 2 0 132 104 48
9 2 0 132 104 48
10 2 0 132 104 48
11 2 0 132 104 48
12 2 0 132 104 48
13 2 0 132 104 48
14 2 0 132 104 48
-15 3 0 132 104 48
-14 3 0 132 104 48
-13 3 0 132 104 48
-12 3 0 132 104 48
-11 3 0 132 104 48
-10 3 0 132 104 48
-9 3 0 132 104 48
-8 3 0 132 104 48
-7 3 0 132 104 48
-6 3 0 132 104 48
-5 3 0 132 104 48
-4 3 0 132 104 48
-3 3 0 132 104 48
-2 3 0 136 0 0
-1 3 0 156 32 32
0 3 0 156 32 32
1 3 0 136 0 0
2 3 0 132 104 48
3 3 0 132 104 48
4 3 0 132 104 48
5 3 0 132 104 48
6 3 0 132 104 48
7 3 0 132 104 48
8 3 0 132 104 48
9 3 0 132 104 48
10 3 0 132 104 48
11 3 0 132 104 48
12 3 0 132 104 48
13 3 0 132 104 48
14 3 0 132 104 48
-15 4 0 132 104 48
-14 4 0 132 104 48
-13 4 0 132 104 48
-12 4 0 132 104 48
-11 4 0 132 104 48
-10 4 0 132 104 48
-9 4 0 132 104 48
-8 4 0 132 104 48
-7 4 0 132 104 48
-6 4 0 132 104 48
-5 4 0 132 104 48
-4 4 0 132 104 48
-3 4 0 132 104 48
-2 4 0 136 0 0
-1 4 0 156 32 32
0 4 0 156 32 32
1 4 0 136 0 0
2 4 0 132 104 48
3 4 0 132 104 48
4 4 0 132 104 48
5 4 0 132 104 48
6 4 0 132 104 48
7 4 0 132 104 48
8 4 0 132 104 48
9 4 0 132 104 48
10 4 0 132 104 48
11 4 0 132 104 48
12 4 0 132 104 48
13 4 0 132 104 48
14 4 0 132 104 48
-15 5 0 132 104 48
-14 5 0 132 104 48
-13 5 0 132 104 48
-12 5 0 132 104 48
-11 5 0 132 104 48
-10 5 0 132 104 48
-9 5 0 132 104 48
-8 5 0 132 104 48
-7 5 0 132 104 48
-6 5 0 132 104 48
-5 5 0 132 104 48
-4 5 0 132 104 48
-3 5 0 132 104 48
-2 5 0 136 0 0
-1 5 0 156 32 32
0 5 0 156 32 32
1 5 0 136 0 0
2 5 0 132 104 48
3 5 0 132 104 48
4 5 0 132 104 48
5 5 0 132 104 48
6 5 0 132 104 48
7 5 0 132 104 48
8 5 0 132 104 48
9 5 0 132 104 48
10 5 0 132 104 48
11 5 0 132 104 48
12 5 0 132 104 48
13 5 0 132 104 48
14 5 0 132 104 48
-15 6 0 132 104 48
-14 6 0 132 104 48
-13 6 0 132 104 48
-12 6 0 132 104 48
-11 6 0 132 104 48
-10 6 0 132 104 48
-9 6 0 132 104 48
-8 6 0 132 104 48
-7 6 0 132 104 48
-6 6 0 132 104 48
-5 6 0 132 104 48
-4 6 0 132 104 48
-3 6 0 132 104 48
-2 6 0 136 0 0
-1 6 0 156 32 32
0 6 0 156 32 32
1 6 0 136 0 0
2 6 0 132 104 48
3 6 0 132 104 48
4 6 0 132 104 48
5 6 0 132 104 48
6 6 0 132 104 48
7 6 0 132 104 48
8 6 0 132 104 48
9 6 0 132 104 48
10 6 0 132 104 48
11 6 0 132 104 48
12 6 0 132 104 48
13 6 0 132 104 48
14 6 0 132 104 48
-15 7 0 132 104 48
-14 7 0 132 104 48
-13 7 0 132 104 48
-12 7 0 132 104 48
-11 7 0 132 104 48
-10 7 0 132 104 48
-9 7 0 132 104 48
-8 7 0 132 104 48
-7 7 0 132 104 48
-6 7 0 132 104 48
-5 7 0 132 104 48
-4 7 0 132 104 48
-3 7 0 132 104 48
-2 7 0 136 0 0
-1 7 0 156 32 32
0 7 0 156 32 32
1 7 0 136 0 0
2 7 0 132 104 48
3 7 0 132 104 48
4 7 0 132 104 48
5 7 0 132 104 48
6 7 0 132 104 48
7 7 0 132 104 48
8 7 0 132 104 48
9 7 0 132 104 48
10 7 0 132 104 48
11 7 0 132 104 48
12 7 0 132 104 48
13 7 0 132 104 48
14 7 0 132 104 48
-15 8 0 132 104 48
-14 8 0 132 104 48
-13 8 0 132 104 48
-12 8 0 132 104 48
-11 8 0 132 104 48
-10 8 0 132 104 48
-9 8 0 132 104 48
-8 8 0 132 104 48
-7 8 0 132 104 48
-6 8 0 132 104 48
-5 8 0 132 104 48
-4 8 0 132 104 48
-3 8 0 132 104 48
-2 8 0 136 0 0
-1 8 0 156 32 32
0 8 0 156 32 32
1 8 0 136 0 0
2 8 0 132 104 48
3 8 0 132 104 48
4 8 0 132 104 48
5 8 0 132 104 48
6 8 0 132 104 48
7 8 0 132 104 48
8 8 0 132 104 48
9 8 0 132 104 48
10 8 0 132 104 48
11 8 0 132 104 48
12 8 0 132 104 48
13 8 0 132 104 48
14 8 0 132 104 48
-15 9 0 132 104 48
-14 9 0 132 104 48
-13 9 0 132 104 48
-12 9 0 132 104 48
-11 9 0 132 104 48
-10 9 0 132 104 48
-9 9 0 132 104 48
-8 9 0 132 104 48
-7 9 0 132 104 48
-6 9 0 132 104 48
-5 9 0 132 104 48
-4 9 0 132 104 48
-3 9 0 132 104 48
-2 9 0 136 0 0
-1 9 0 156 32 32
0 9 0 156 32 32
1 9 0 136 0 0
2 9 0 132 104 48
3 9 0 132 104 48
4 9 0 132 104 48
5 9 0 132 104 48
6 9 0 132 104 48
7 9 0 132 104 48
8 9 0 132 104 48
9 9 0 132 104 48
10 9 0 132 104 48
11 9 0 132 104 48
12 9 0 132 104 48
13 9 0 132 104 48
14 9 0 132 104 48
-15 10 0 132 104 48
-14 10 0 132 104 48
-13 10 0 132 104 48
-12 10 0 132 104 48
-11 10 0 132 104 48
-10 10 0 132 104 48
-9 10 0 132 104 48
-8 10 0 132 104 48
-7 10 0 132 104 48
-6 10 0 132 104 48
-5 10 0 132 104 48
-4 10 0 132 104 48
-3 10 0 132 104 48
-2 10 0 136 0 0
-1 10 0 156 32 32
0 10 0 156 32 32
1 10 0 136 0 0
2 10 0 132 104 48
3 10 0 132 104 48
4 10 0 132 104 48
5 10 0 132 104 48
6 10 0 132 104 48
7 10 0 132 104 48
8 10 0 132 104 48
9 10 0 132 104 48
10 10 0 132 104 48
11 10 0 132 104 48
12 10 0 132 104 48
13 10 0 132 104 48
14 10 0 132 104 48
-15 11 0 132 104 48
-14 11 0 132 104 48
-13 11 0 132 104 48
-12 11 0 132 104 48
-11 11 0 132 104 48
-10 11 0 132 104 48
-9 11 0 132 104 48
-8 11 0 132 104 48
-7 11 0 132 104 48
-6 11 0 132 104 48
-5 11 0 132 104 48
-4 11 0 132 104 48
-3 11 0 132 104 48
-2 11 0 136 0 0
-1 11 0 156 32 32
0 11 0 156 32 32
1 11 0 136 0 0
2 11 0 132 104 48
3 11 0 132 104 48
4 11 0 132 104 48
5 11 0 132 104 48
6 11 0 132 104 48
7 11 0 132 104 48
8 11 0 132 104 48
9 11 0 132 104 48
10 11 0 132 104 48
11 11 0 132 104 48
12 11 0 132 104 48
13 11 0 132 104 48
14 11 0 132 104 48
-15 12 0 132 104 48
-14 12 0 132 104 48
-13 12 0 132 104 48
-12 12 0 132 104 48
-11 12 0 132 104 48
-10 12 0 132 104 48
-9 12 0 132 104 48
-8 12 0 132 104 48
-7 12 0 132 104 48
-6 12 0 132 104 48
-5 12 0 132 104 48
-4 12 0 132 104 48
-3 12 0 132 104 48
-2 12 0 136 0 0
-1 12 0 156 32 32
0 12 0 156 32 32
1 12 0 136 0 0
2 12 0 132 104 48
3 12 0 132 104 48
4 12 0 132 104 48
5 12 0 132 104 48
6 12 0 132 104 48
7 12 0 132 104 48
8 12 0 132 104 48
9 12 0 132 104 48
10 12 0 132 104 48
11 12 0 132 104 48
12 12 0 132 104 48
13 12 0 132 104 48
14 12 0 132 104 48
-15 13 0 132 104 48
-14 13 0 132 104 48
-13 13 0 132 104 48
-12 13 0 132 104 48
-11 13 0 132 104 48
-10 13 0 132 104 48
-9 13 0 132 104 48
-8 13 0 132 104 48
-7 13 0 132 104 48
-6 13 0 132 104 48
-5 13 0 132 104 48
-4 13 0 132 104 48
-3 13 0 132 104 48
-2 13 0 136 0 0
-1 13 0 136 0 0
0 13 0 136 0 0
1 13 0 136 0 0
2 13 0 132 104 48
3 13 0 132 104 48
4 13 0 132 104 48
5 13 0 132 104 48
6 13 0 132 104 48
7 13 0 132 104 48
8 13 0 132 104 48
9 13 0 132 104 48
10 13 0 132 104 48
11 13 0 132 104 48
12 13 0 132 104 48
13 13 0 132 104 48
14 13 0 132 104 48
-15 14 0 132 104 48
-14 14 0 132 104 48
-13 14 0 132 104 48
-12 14 0 132 104 48
-11 14 0 132 104 48
-10 14 0 132 104 48
-9 14 0 132 104 48
-8 14 0 132 104 48
-7 14 0 132 104 48
-6 14 0 132 104 48
-5 14 0 132 104 48
-4 14 0 132 104 48
-3 14 0 132 104 48
-2 14 0 108 108 108
-1 14 0 108 108 108
0 14 0 108 108 108
1 14 0 108 108 108
2 14 0 132 104 48
3 14 0 132 104 48
4 14 0 132 104 48
5 14 0 132 104 48
6 14 0 132 104 48
7 14 0 132 104 48
8 14 0 132 104 48
9 14 0 132 104 48
10 14 0 132 104 48
11 14 0 132 104 48
12 14 0 132 104 48
13 14 0 132 104 48
14 14 0 132 104 48
-15 -15 1 68 40 0
-14 -15 1 68 40 0
-13 -15 1 68 40 0
-12 -15 1 68 40 0
-11 -15 1 68 40 0
-10 -15 1 68 40 0
-9 -15 1 68 40 0
-8 -15 1 68 40 0
-7 -15 1 68 40 0
-6 -15 1 68 40 0
-5 -15 1 68 40 0
-4 -15 1 68 40 0
-3 -15 1 68 40 0
2 -15 1 68 40 0
3 -15 1 68 40 0
4 -15 1 68 40 0
5 -15 1 68 40 0
6 -15 1 68 40 0
7 -15 1 68 40 0
8 -15 1 68 40 0
9 -15 1 68 40 0
10 -15 1 68 40 0
11 -15 1 68 40 0
12 -15 1 68 40 0
13 -15 1 68 40 0
14 -15 1 68 40 0
-15 -14 1 68 40 0
14 -14 1 68 40 0
-15 -13 1 68 40 0
14 -13 1 68 40 0
-15 -12 1 68 40 0
14 -12 1 68 40 0
-15 -11 1 68 40 0
14 -11 1 68 40 0
-15 -10 1 68 40 0
-10 -10 1 68 40 0
-9 -10 1 68 40 0
-8 -10 1 68 40 0
-7 -10 1 68 40 0
6 -10 1 68 40 0
7 -10 1 68 40 0
8 -10 1 68 40 0
9 -10 1 68 40 0
14 -10 1 68 40 0
-15 -9 1 68 40 0
-10 -9 1 68 40 0
-9 -9 1 68 40 0
-8 -9 1 68 40 0
-7 -9 1 68 40 0
6 -9 1 68 40 0
7 -9 1 68 40 0
8 -9 1 68 40 0
9 -9 1 68 40 0
14 -9 1 68 40 0
-15 -8 1 68 40 0
-10 -8 1 68 40 0
-9 -8 1 68 40 0
-8 -8 1 68 40 0
-7 -8 1 68 40 0
6 -8 1 68 40 0
7 -8 1 68 40 0
8 -8 1 68 40 0
9 -8 1 68 40 0
14 -8 1 68 40 0
-15 -7 1 68 40 0
-10 -7 1 68 40 0
-9 -7 1 68 40 0
-8 -7 1 68 40 0
-7 -7 1 68 40 0
6 -7 1 68 40 0
7 -7 1 68 40 0
8 -7 1 68 40 0
9 -7 1 68 40 0
14 -7 1 68 40 0
-15 -6 1 68 40 0
14 -6 1 68 40 0
-15 -5 1 68 40 0
14 -5 1 68 40 0
-15 -4 1 68 40 0
14 -4 1 68 40 0
-15 -3 1 68 40 0
14 -3 1 68 40 0
-15 2 1 68 40 0
14 2 1 68 40 0
-15 3 1 68 40 0
14 3 1 68 40 0
-15 4 1 68 40 0
14 4 1 68 40 0
-15 5 1 68 40 0
14 5 1 68 40 0
-15 6 1 68 40 0
-10 6 1 68 40 0
-9 6 1 68 40 0
-8 6 1 68 40 0
-7 6 1 68 40 0
6 6 1 68 40 0
7 6 1 68 40 0
8 6 1 68 40 0
9 6 1 68 40 0
14 6 1 68 40 0
-15 7 1 68 40 0
-10 7 1 68 40 0
-9 7 1 68 40 0
-8 7 1 68 40 0
-7 7 1 68 40 0
6 7 1 68 40 0
7 7 1 68 40 0
8 7 1 68 40 0
9 7 1 68 40 0
14 7 1 68 40 0
-15 8 1 68 40 0
-10 8 1 68 40 0
-9 8 1 68 40 0
-8 8 1 68 40 0
-7 8 1 68 40 0
6 8 1 68 40 0
7 8 1 68 40 0
8 8 1 68 40 0
9 8 1 68 40 0
14 8 1 68 40 0
-15 9 1 68 40 0
-10 9 1 68 40 0
-9 9 1 68 40 0
-8 9 1 68 40 0
-7 9 1 68 40 0
6 9 1 68 40 0
7 9 1 68 40 0
8 9 1 68 40 0
9 9 1 68 40 0
14 9 1 68 40 0
-15 10 1 68 40 0
14 10 1 68 40 0
-15 11 1 68 40 0
14 11 1 68 40 0
-15 12 1 68 40 0
14 12 1 68 40 0
-15 13 1 68 40 0
14 13 1 68 40 0
-15 14 1 68 40 0
-14 14 1 68 40 0
-13 14 1 68 40 0
-12 14 1 68 40 0
-11 14 1 68 40 0
-10 14 1 68 40 0
-9 14 1 68 40 0
-8 14 1 68 40 0
-7 14 1 68 40 0
-6 14 1 68 40 0
-5 14 1 68 40 0
-4 14 1 68 40 0
-3 14 1 68 40 0
2 14 1 68 40 0
3 14 1 68 40 0
4 14 1 68 40 0
5 14 1 68 40 0
6 14 1 68 40 0
7 14 1 68 40 0
8 14 1 68 40 0
9 14 1 68 40 0
10 14 1 68 40 0
11 14 1 68 40 0
12 14 1 68 40 0
13 14 1 68 40 0
14 14 1 68 40 0
-15 -15 2 68 40 0
-14 -15 2 104 136 204
-13 -15 2 104 136 204
-12 -15 2 104 136 204
-11 -15 2 104 136 204
-10 -15 2 104 136 204
-9 -15 2 104 136 204
-8 -15 2 104 136 204
-7 -15 2 104 136 204
-6 -15 2 104 136 204
-5 -15 2 104 136 204
-4 -15 2 104 136 204
-3 -15 2 68 40 0
2 -15 2 68 40 0
3 -15 2 104 136 204
4 -15 2 104 136 204
5 -15 2 104 136 204
6 -15 2 104 136 204
7 -15 2 104 136 204
8 -15 2 104 136 204
9 -15 2 104 136 204
10 -15 2 104 136 204
11 -15 2 104 136 204
12 -15 2 104 136 204
13 -15 2 104 136 204
14 -15 2 68 40 0
-15 -14 2 252 252 104
14 -14 2 252 252 104
-15 -13 2 252 252 104
14 -13 2 252 252 104
-15 -12 2 252 252 104
14 -12 2 252 252 104
-15 -11 2 252 252 104
14 -11 2 252 252 104
-15 -10 2 252 252 104
-10 -10 2 236 236 236
-9 -10 2 236 236 236
-8 -10 2 236 236 236
-7 -10 2 236 236 236
6 -10 2 236 236 236
7 -10 2 236 236 236
8 -10 2 236 236 236
9 -10 2 236 236 236
14 -10 2 252 252 104
-15 -9 2 252 252 104
-10 -9 2 236 236 236
-9 -9 2 236 236 236
-8 -9 2 236 236 236
-7 -9 2 236 236 236
6 -9 2 236 236 236
7 -9 2 236 236 236
8 -9 2 236 236 236
9 -9 2 236 236 236
14 -9 2 252 252 104
-15 -8 2 252 252 104
-10 -8 2 236 236 236
-9 -8 2 236 236 236
-8 -8 2 236 236 236
-7 -8 2 236 236 236
6 -8 2 236 236 236
7 -8 2 236 236 236
8 -8 2 236 236 236
9 -8 2 236 236 236
14 -8 2 252 252 104
-15 -7 2 252 252 104
-10 -7 2 236 236 236
-9 -7 2 236 236 236
-8 -7 2 236 236 236
-7 -7 2 236 236 236
6 -7 2 236 236 236
7 -7 2 236 236 236
8 -7 2 236 236 236
9 -7 2 236 236 236
14 -7 2 252 252 104
-15 -6 2 252 252 104
14 -6 2 252 252 104
-15 -5 2 252 252 104
14 -5 2 252 252 104
-15 -4 2 252 252 104
14 -4 2 252 252 104
-15 -3 2 68 40 0
14 -3 2 68 40 0
-15 2 2 68 40 0
14 2 2 68 40 0
-15 3 2 252 252 104
14 3 2 252 252 104
-15 4 2 252 252 104
14 4 2 252 252 104
-15 5 2 252 252 104
14 5 2 252 252 104
-15 6 2 252 252 104
-10 6 2 236 236 236
-9 6 2 236 236 236
-8 6 2 236 236 236
-7 6 2 236 236 236
6 6 2 236 236 236
7 6 2 236 236 236
8 6 2 236 236 236
9 6 2 236 236 236
14 6 2 252 252 104
-15 7 2 252 252 104
-10 7 2 236 236 236
-9 7 2 236 236 236
-8 7 2 236 236 236
-7 7 2 236 236 236
6 7 2 236 236 236
7 7 2 236 236 236
8 7 2 236 236 236
9 7 2 236 236 236
14 7 2 252 252 104
-15 8 2 252 252 104
-10 8 2 236 236 236
-9 8 2 236 236 236
-8 8 2 236 236 236
-7 8 2 236 236 236
6 8 2 236 236 236
7 8 2 236 236 236
8 8 2 236 236 236
9 8 2 236 236 236
14 8 2 252 252 104
-15 9 2 252 252 104
-10 9 2 236 236 236
-9 9 2 236 236 236
-8 9 2 236 236 236
-7 9 2 236 236 236
6 9 2 236 236 236
7 9 2 236 236 236
8 9 2 236 236 236
9 9 2 236 236 236
14 9 2 252 252 104
-15 10 2 252 252 104
14 10 2 252 252 104
-15 11 2 252 252 104
14 11 2 252 252 104
-15 12 2 252 252 104
14 12 2 252 252 104
-15 13 2 252 252 104
14 13 2 252 252 104
-15 14 2 68 40 0
-14 14 2 104 136 204
-13 14 2 104 136 204
-12 14 2 104 136 204
-11 14 2 104 136 204
-10 14 2 104 136 204
-9 14 2 104 136 204
-8 14 2 104 136 204
-7 14 2 104 136 204
-6 14 2 104 136 204
-5 14 2 104 136 204
-4 14 2 104 136 204
-3 14 2 68 40 0
2 14 2 68 40 0
3 14 2 104 136 204
4 14 2 104 136 204
5 14 2 104 136 204
6 14 2 104 136 204
7 14 2 104 136 204
8 14 2 104 136 204
9 14 2 104 136 204
10 14 2 104 136 204
11 14 2 104 136 204
12 14 2 104 136 204
13 14 2 104 136 204
14 14 2 68 40 0
-15 -15 3 68 40 0
-14 -15 3 104 136 204
-13 -15 3 104 136 204
-12 -15 3 104 136 204
-11 -15 3 104 136 204
-10 -15 3 104 136 204
-9 -15 3 104 136 204
-8 -15 3 104 136 204
-7 -15 3 104 136 204
-6 -15 3 104 136 204
-5 -15 3 104 136 204
-4 -15 3 104 136 204
-3 -15 3 68 40 0
2 -15 3 68 40 0
3 -15 3 104 136 204
4 -15 3 104 136 204
5 -15 3 104 136 204
6 -15 3 104 136 204
7 -15 3 104 136 204
8 -15 3 104 136 204
9 -15 3 104 136 204
10 -15 3 104 136 204
11 -15 3 104 136 204
12 -15 3 104 136 204
13 -15 3 104 136 204
14 -15 3 68 40 0
-15 -14 3 252 252 104
14 -14 3 252 252 104
-15 -13 3 252 252 104
14 -13 3 252 252 104
-15 -12 3 252 252 104
14 -12 3 252 252 104
-15 -11 3 252 252 104
14 -11 3 252 252 104
-15 -10 3 252 252 104
-10 -10 3 236 236 236
-9 -10 3 236 236 236
-8 -10 3 236 236 236
-7 -10 3 236 236 236
6 -10 3 236 236 236
7 -10 3 236 236 236
8 -10 3 236 236 236
9 -10 3 236 236 236
14 -10 3 252 252 104
-15 -9 3 252 252 104
-10 -9 3 236 236 236
-9 -9 3 236 236 236
-8 -9 3 236 236 236
-7 -9 3 236 236 236
6 -9 3 236 236 236
7 -9 3 236 236 236
8 -9 3 236 236 236
9 -9 3 236 236 236
14 -9 3 252 252 104
-15 -8 3 252 252 104
-10 -8 3 236 236 236
-9 -8 3 236 236 236
-8 -8 3 236 236 236
-7 -8 3 236 236 236
6 -8 3 236 236 236
7 -8 3 236 236 236
8 -8 3 236 236 236
9 -8 3 236 236 236
14 -8 3 252 252 104
-15 -7 3 252 252 104
-10 -7 3 236 236 236
-9 -7 3 236 236 236
-8 -7 3 236 236 236
-7 -7 3 236 236 236
6 -7 3 236 236 236
7 -7 3 236 236 236
8 -7 3 236 236 236
9 -7 3 236 236 236
14 -7 3 252 252 104
-15 -6 3 252 252 104
14 -6 3 252 252 104
-15 -5 3 252 252 104
14 -5 3 252 252 104
-15 -4 3 252 252 104
14 -4 3 252 252 104
-15 -3 3 68 40 0
14 -3 3 68 40 0
-15 2 3 68 40 0
14 2 3 68 40 0
-15 3 3 252 252 104
14 3 3 252 252 104
-15 4 3 252 252 104
14 4 3 252 252 104
-15 5 3 252 252 104
14 5 3 252 252 104
-15 6 3 252 252 104
-10 6 3 236 236 236
-9 6 3 236 236 236
-8 6 3 236 236 236
-7 6 3 236 236 236
6 6 3 236 236 236
7 6 3 236 236 236
8 6 3 236 236 236
9 6 3 236 236 236
14 6 3 252 252 104
-15 7 3 252 252 104
-10 7 3 236 236 236
-9 7 3 236 236 236
-8 7 3 236 236 236
-7 7 3 236 236 236
6 7 3 236 236 236
7 7 3 236 236 236
8 7 3 236 236 236
9 7 3 236 236 236
14 7 3 252 252 104
-15 8 3 252 252 104
-10 8 3 236 236 236
-9 8 3 236 236 236
-8 8 3 236 236 236
-7 8 3 236 236 236
6 8 3 236 236 236
7 8 3 236 236 236
8 8 3 236 236 236
9 8 3 236 236 236
14 8 3 252 252 104
-15 9 3 252 252 104
-10 9 3 236 236 236
-9 9 3 236 236 236
-8 9 3 236 236 236
-7 9 3 236 236 236
6 9 3 236 236 236
7 9 3 236 236 236
8 9 3 236 236 236
9 9 3 236 236 236
14 9 3 252 252 104
-15 10 3 252 252 104
14 10 3 252 252 104
-15 11 3 252 252 104
14 11 3 252 252 104
-15 12 3 252 252 104
14 12 3 252 252 104
-15 13 3 252 252 104
14 13 3 252 252 104
-15 14 3 68 40 0
-14 14 3 104 136 204
-13 14 3 104 136 204
-12 14 3 104 136 204
-11 14 3 104 136 204
-10 14 3 104 136 204
-9 14 3 104 136 204
-8 14 3 104 136 204
-7 14 3 104 136 204
-6 14 3 104 136 204
-5 14 3 104 136 204
-4 14 3 104 136 204
-3 14 3 68 40 0
2 14 3 68 40 0
3 14 3 104 136 204
4 14 3 104 136 204
5 14 3 104 136 204
6 14 3 104 136 204
7 14 3 104 136 204
8 14 3 104 136 204
9 14 3 104 136 204
10 14 3 104 136 204
11 14 3 104 136 204
12 14 3 104 136 204
13 14 3 104 136 204
14 14 3 68 40 0
-15 -15 4 68 40 0
-14 -15 4 104 136 204
-13 -15 4 104 136 204
-12 -15 4 104 136 204
-11 -15 4 104 136 204
-10 -15 4 104 136 204
-9 -15 4 104 136 204
-8 -15 4 104 136 204
-7 -15 4 104 136 204
-6 -15 4 104 136 204
-5 -15 4 104 136 204
-4 -15 4 104 136 204
-3 -15 4 68 40 0
2 -15 4 68 40 0
3 -15 4 104 136 204
4 -15 4 104 136 204
5 -15 4 104 136 204
6 -15 4 104 136 204
7 -15 4 104 136 204
8 -15 4 104 136 204
9 -15 4 104 136 204
10 -15 4 104 136 204
11 -15 4 104 136 204
12 -15 4 104 136 204
13 -15 4 104 136 204
14 -15 4 68 40 0
-15 -14 4 252 252 104
14 -14 4 252 252 104
-15 -13 4 252 252 104
14 -13 4 252 252 104
-15 -12 4 252 252 104
14 -12 4 252 252 104
-15 -11 4 252 252 104
14 -11 4 252 252 104
-15 -10 4 252 252 104
-10 -10 4 236 236 236
-9 -10 4 236 236 236
-8 -10 4 236 236 236
-7 -10 4 236 236 236
6 -10 4 236 236 236
7 -10 4 236 236 236
8 -10 4 236 236 236
9 -10 4 236 236 236
14 -10 4 252 252 104
-15 -9 4 252 252 104
-10 -9 4 236 236 236
-9 -9 4 236 236 236
-8 -9 4 236 236 236
-7 -9 4 236 236 236
6 -9 4 236 236 236
7 -9 4 236 236 236
8 -9 4 236 236 236
9 -9 4 236 236 236
14 -9 4 252 252 104
-15 -8 4 252 252 104
-10 -8 4 236 236 236
-9 -8 4 236 236 236
-8 -8 4 236 236 236
-7 -8 4 236 236 236
6 -8 4 236 236 236
7 -8 4 236 236 236
8 -8 4 236 236 236
9 -8 4 236 236 236
14 -8 4 252 252 104
-15 -7 4 252 252 104
-10 -7 4 236 236 236
-9 -7 4 236 236 236
-8 -7 4 236 236 236
-7 -7 4 236 236 236
6 -7 4 236 236 236
7 -7 4 236 236 236
8 -7 4 236 236 236
9 -7 4 236 236 236
14 -7 4 252 252 104
-15 -6 4 252 252 104
14 -6 4 252 252 104
-15 -5 4 252 252 104
14 -5 4 252 252 104
-15 -4 4 252 252 104
14 -4 4 252 252 104
-15 -3 4 68 40 0
14 -3 4 68 40 0
-15 2 4 68 40 0
14 2 4 68 40 0
-15 3 4 252 252 104
14 3 4 252 252 104
-15 4 4 252 252 104
14 4 4 252 252 104
-15 5 4 252 252 104
14 5 4 252 252 104
-15 6 4 252 252 104
-10 6 4 236 236 236
-9 6 4 236 236 236
-8 6 4 236 236 236
-7 6 4 236 236 236
6 6 4 236 236 236
7 6 4 236 236 236
8 6 4 236 236 236
9 6 4 236 236 236
14 6 4 252 252 104
-15 7 4 252 252 104
-10 7 4 236 236 236
-9 7 4 236 236 236
-8 7 4 236 236 236
-7 7 4 236 236 236
6 7 4 236 236 236
7 7 4 236 236 236
8 7 4 236 236 236
9 7 4 236 236 236
14 7 4 252 252 104
-15 8 4 252 252 104
-10 8 4 236 236 236
-9 8 4 236 236 236
-8 8 4 236 236 236
-7 8 4 236 236 236
6 8 4 236 236 236
7 8 4 236 236 236
8 8 4 236 236 236
9 8 4 236 236 236
14 8 4 252 252 104
-15 9 4 252 252 104
-10 9 4 236 236 236
-9 9 4 236 236 236
-8 9 4 236 236 236
-7 9 4 236 236 236
6 9 4 236 236 236
7 9 4 236 236 236
8 9 4 236 236 236
9 9 4 236 236 236
14 9 4 252 252 104
-15 10 4 252 252 104
14 10 4 252 252 104
-15 11 4 252 252 104
14 11 4 252 252 104
-15 12 4 252 252 104
14 12 4 252 252 104
-15 13 4 252 252 104
14 13 4 252 252 104
-15 14 4 68 40 0
-14 14 4 104 136 204
-13 14 4 104 136 204
-12 14 4 104 136 204
-11 14 4 104 136 204
-10 14 4 104 136 204
-9 14 4 104 136 204
-8 14 4 104 136 204
-7 14 4 104 136 204
-6 14 4 104 136 204
-5 14 4 104 136 204
-4 14 4 104 136 204
-3 14 4 68 40 0
2 14 4 68 40 0
3 14 4 104 136 204
4 14 4 104 136 204
5 14 4 104 136 204
6 14 4 104 136 204
7 14 4 104 136 204
8 14 4 104 136 204
9 14 4 104 136 204
10 14 4 104 136 204
11 14 4 104 136 204
12 14 4 104 136 204
13 14 4 104 136 204
14 14 4 68 40 0
-15 -15 5 68 40 0
-14 -15 5 104 136 204
-13 -15 5 104 136 204
-12 -15 5 104 136 204
-11 -15 5 104 136 204
-10 -15 5 104 136 204
-9 -15 5 104 136 204
-8 -15 5 104 136 204
-7 -15 5 104 136 204
-6 -15 5 104 136 204
-5 -15 5 104 136 204
-4 -15 5 104 136 204
-3 -15 5 68 40 0
2 -15 5 68 40 0
3 -15 5 104 136 204
4 -15 5 104 136 204
5 -15 5 104 136 204
6 -15 5 104 136 204
7 -15 5 104 136 204
8 -15 5 104 136 204
9 -15 5 104 136 204
10 -15 5 104 136 204
11 -15 5 104 136 204
12 -15 5 104 136 204
13 -15 5 104 136 204
14 -15 5 68 40 0
-15 -14 5 252 252 104
14 -14 5 252 252 104
-15 -13 5 252 252 104
14 -13 5 252 252 104
-15 -12 5 252 252 104
14 -12 5 252 252 104
-15 -11 5 252 252 104
14 -11 5 252 252 104
-15 -10 5 252 252 104
-10 -10 5 236 236 236
-9 -10 5 236 236 236
-8 -10 5 236 236 236
-7 -10 5 236 236 236
6 -10 5 236 236 236
7 -10 5 236 236 236
8 -10 5 236 236 236
9 -10 5 236 236 236
14 -10 5 252 252 104
-15 -9 5 252 252 104
-10 -9 5 236 236 236
-9 -9 5 236 236 236
-8 -9 5 236 236 236
-7 -9 5 236 236 236
6 -9 5 236 236 236
7 -9 5 236 236 236
8 -9 5 236 236 236
9 -9 5 236 236 236
14 -9 5 252 252 104
-15 -8 5 252 252 104
-10 -8 5 236 236 236
-9 -8 5 236 236 236
-8 -8 5 236 236 236
-7 -8 5 236 236 236
6 -8 5 236 236 236
7 -8 5 236 236 236
8 -8 5 236 236 236
9 -8 5 236 236 236
14 -8 5 252 252 104
-15 -7 5 252 252 104
-10 -7 5 236 236 236
-9 -7 5 236 236 236
-8 -7 5 236 236 236
-7 -7 5 236 236 236
6 -7 5 236 236 236
7 -7 5 236 236 236
8 -7 5 236 236 236
9 -7 5 236 236 236
14 -7 5 252 252 104
-15 -6 5 252 252 104
14 -6 5 252 252 104
-15 -5 5 252 252 104
14 -5 5 252 252 104
-15 -4 5 252 252 104
14 -4 5 252 252 104
-15 -3 5 68 40 0
14 -3 5 68 40 0
-15 2 5 68 40 0
14 2 5 68 40 0
-15 3 5 252 252 104
14 3 5 252 252 104
-15 4 5 252 252 104
14 4 5 252 252 104
-15 5 5 252 252 104
14 5 5 252 252 104
-15 6 5 252 252 104
-10 6 5 236 236 236
-9 6 5 236 236 236
-8 6 5 236 236 236
-7 6 5 236 236 236
6 6 5 236 236 236
7 6 5 236 236 236
8 6 5 236 236 236
9 6 5 236 236 236
14 6 5 252 252 104
-15 7 5 252 252 104
-10 7 5 236 236 236
-9 7 5 236 236 236
-8 7 5 236 236 236
-7 7 5 236 236 236
6 7 5 236 236 236
7 7 5 236 236 236
8 7 5 236 236 236
9 7 5 236 236 236
14 7 5 252 252 104
-15 8 5 252 252 104
-10 8 5 236 236 236
-9 8 5 236 236 236
-8 8 5 236 236 236
-7 8 5 236 236 236
6 8 5 236 236 236
7 8 5 236 236 236
8 8 5 236 236 236
9 8 5 236 236 236
14 8 5 252 252 104
-15 9 5 252 252 104
-10 9 5 236 236 236
-9 9 5 236 236 236
-8 9 5 236 236 236
-7 9 5 236 236 236
6 9 5 236 236 236
7 9 5 236 236 236
8 9 5 236 236 236
9 9 5 236 236 236
14 9 5 252 252 104
-15 10 5 252 252 104
14 10 5 252 252 104
-15 11 5 252 252 104
14 11 5 252 252 104
-15 12 5 252 252 104
14 12 5 252 252 104
-15 13 5 252 252 104
14 13 5 252 252 104
-15 14 5 68 40 0
-14 14 5 104 136 204
-13 14 5 104 136 204
-12 14 5 104 136 204
-11 14 5 104 136 204
-10 14 5 104 136 204
-9 14 5 104 136 204
-8 14 5 104 136 204
-7 14 5 104 136 204
-6 14 5 104 136 204
-5 14 5 104 136 204
-4 14 5 104 136 204
-3 14 5 68 40 0
2 14 5 68 40 0
3 14 5 104 136 204
4 14 5 104 136 204
5 14 5 104 136 204
6 14 5 104 136 204
7 14 5 104 136 204
8 14 5 104 136 204
9 14 5 104 136 204
10 14 5 104 136 204
11 14 5 104 136 204
12 14 5 104 136 204
13 14 5 104 136 204
14 14 5 68 40 0
-15 -15 6 68 40 0
-14 -15 6 104 136 204
-13 -15 6 104 136 204
-12 -15 6 104 136 204
-11 -15 6 104 136 204
-10 -15 6 104 136 204
-9 -15 6 104 136 204
-8 -15 6 104 136 204
-7 -15 6 104 136 204
-6 -15 6 104 136 204
-5 -15 6 104 136 204
-4 -15 6 104 136 204
-3 -15 6 68 40 0
-2 -15 6 68 40 0
-1 -15 6 68 40 0
0 -15 6 68 40 0
1 -15 6 68 40 0
2 -15 6 68 40 0
3 -15 6 104 136 204
4 -15 6 104 136 204
5 -15 6 104 136 204
6 -15 6 104 136 204
7 -15 6 104 136 204
8 -15 6 104 136 204
9 -15 6 104 136 204
10 -15 6 104 136 204
11 -15 6 104 136 204
12 -15 6 104 136 204
13 -15 6 104 136 204
14 -15 6 68 40 0
-15 -14 6 252 252 104
14 -14 6 252 252 104
-15 -13 6 252 252 104
14 -13 6 252 252 104
-15 -12 6 252 252 104
14 -12 6 252 252 104
-15 -11 6 252 252 104
14 -11 6 252 252 104
-15 -10 6 252 252 104
-10 -10 6 236 236 236
-9 -10 6 236 236 236
-8 -10 6 236 236 236
-7 -10 6 236 236 236
6 -10 6 236 236 236
7 -10 6 236 236 236
8 -10 6 236 236 236
9 -10 6 236 236 236
14 -10 6 252 252 104
-15 -9 6 252 252 104
-10 -9 6 236 236 236
-9 -9 6 236 236 236
-8 -9 6 236 236 236
-7 -9 6 236 236 236
6 -9 6 236 236 236
7 -9 6 236 236 236
8 -9 6 236 236 236
9 -9 6 236 236 236
14 -9 6 252 252 104
-15 -8 6 252 252 104
-10 -8 6 236 236 236
-9 -8 6 236 236 236
-8 -8 6 236 236 236
-7 -8 6 236 236 236
6 -8 6 236 236 236
7 -8 6 236 236 236
8 -8 6 236 236 236
9 -8 6 236 236 236
14 -8 6 252 252 104
-15 -7 6 252 252 104
-10 -7 6 236 236 236
-9 -7 6 236 236 236
-8 -7 6 236 236 236
-7 -7 6 236 236 236
6 -7 6 236 236 236
7 -7 6 236 236 236
8 -7 6 236 236 236
9 -7 6 236 236 236
14 -7 6 252 252 104
-15 -6 6 252 252 104
14 -6 6 252 252 104
-15 -5 6 252 252 104
14 -5 6 252 252 104
-15 -4 6 252 252 104
14 -4 6 252 252 104
-15 -3 6 68 40 0
14 -3 6 68 40 0
-15 -2 6 68 40 0
14 -2 6 68 40 0
-15 -1 6 68 40 0
14 -1 6 68 40 0
-15 0 6 68 40 0
14 0 6 68 40 0
-15 1 6 68 40 0
14 1 6 68 40 0
-15 2 6 68 40 0
14 2 6 68 40 0
-15 3 6 252 252 104
14 3 6 252 252 104
-15 4 6 252 252 104
14 4 6 252 252 104
-15 5 6 252 252 104
14 5 6 252 252 104
-15 6 6 252 252 104
-10 6 6 236 236 236
-9 6 6 236 236 236
-8 6 6 236 236 236
-7 6 6 236 236 236
6 6 6 236 236 236
7 6 6 236 236 236
8 6 6 236 236 236
9 6 6 236 236 236
14 6 6 252 252 104
-15 7 6 252 252 104
-10 7 6 236 236 236
-9 7 6 236 236 236
-8 7 6 236 236 236
-7 7 6 236 236 236
6 7 6 236 236 236
7 7 6 236 236 236
8 7 6 236 236 236
9 7 6 236 236 236
14 7 6 252 252 104
-15 8 6 252 252 104
-10 8 6 236 236 236
-9 8 6 236 236 236
-8 8 6 236 236 236
-7 8 6 236 236 236
6 8 6 236 236 236
7 8 6 236 236 236
8 8 6 236 236 236
9 8 6 236 236 236
14 8 6 252 252 104
-15 9 6 252 252 104
-10 9 6 236 236 236
-9 9 6 236 236 236
-8 9 6 236 236 236
-7 9 6 236 236 236
6 9 6 236 236 236
7 9 6 236 236 236
8 9 6 236 236 236
9 9 6 236 236 236
14 9 6 252 252 104
-15 10 6 252 252 104
14 10 6 252 252 104
-15 11 6 252 252 104
14 11 6 252 252 104
-15 12 6 252 252 104
14 12 6 252 252 104
-15 13 6 252 252 104
14 13 6 252 252 104
-15 14 6 68 40 0
-14 14 6 104 136 204
-13 14 6 104 136 204
-12 14 6 104 136 204
-11 14 6 104 136 204
-10 14 6 104 136 204
-9 14 6 104 136 204
-8 14 6 104 136 204
-7 14 6 104 136 204
-6 14 6 104 136 204
-5 14 6 104 136 204
-4 14 6 104 136 204
-3 14 6 68 40 0
-2 14 6 68 40 0
-1 14 6 68 40 0
0 14 6 68 40 0
1 14 6 68 40 0
2 14 6 68 40 0
3 14 6 104 136 204
4 14 6 104 136 204
5 14 6 104 136 204
6 14 6 104 136 204
7 14 6 104 136 204
8 14 6 104 136 204
9 14 6 104 136 204
10 14 6 104 136 204
11 14 6 104 136 204
12 14 6 104 136 204
13 14 6 104 136 204
14 14 6 68 40 0
-15 -15 7 68 40 0
-14 -15 7 104 136 204
-13 -15 7 104 136 204
-12 -15 7 104 136 204
-11 -15 7 104 136 204
-10 -15 7 104 136 204
-9 -15 7 104 136 204
-8 -15 7 104 136 204
-7 -15 7 104 136 204
-6 -15 7 104 136 204
-5 -15 7 104 136 204
-4 -15 7 104 136 204
-3 -15 7 68 40 0
2 -15 7 68 40 0
3 -15 7 104 136 204
4 -15 7 104 136 204
5 -15 7 104 136 204
6 -15 7 104 136 204
7 -15 7 104 136 204
8 -15 7 104 136 204
9 -15 7 104 136 204
10 -15 7 104 136 204
11 -15 7 104 136 204
12 -15 7 104 136 204
13 -15 7 104 136 204
14 -15 7 68 40 0
-15 -14 7 252 252 104
14 -14 7 252 252 104
-15 -13 7 252 252 104
14 -13 7 252 252 104
-15 -12 7 252 252 104
14 -12 7 252 252 104
-15 -11 7 252 252 104
14 -11 7 252 252 104
-15 -10 7 252 252 104
-10 -10 7 236 236 236
-9 -10 7 236 236 236
-8 -10 7 236 236 236
-7 -10 7 236 236 236
6 -10 7 236 236 236
7 -10 7 236 236 236
8 -10 7 236 236 236
9 -10 7 236 236 236
14 -10 7 252 252 104
-15 -9 7 252 252 104
-10 -9 7 236 236 236
-9 -9 7 236 236 236
-8 -9 7 236 236 236
-7 -9 7 236 236 236
6 -9 7 236 236 236
7 -9 7 236 236 236
8 -9 7 236 236 236
9 -9 7 236 236 236
14 -9 7 252 252 104
-15 -8 7 252 252 104
-10 -8 7 236 236 236
-9 -8 7 236 236 236
-8 -8 7 236 236 236
-7 -8 7 236 236 236
6 -8 7 236 236 236
7 -8 7 236 236 236
8 -8 7 236 236 236
9 -8 7 236 236 236
14 -8 7 252 252 104
-15 -7 7 252 252 104
-10 -7 7 236 236 236
-9 -7 7 236 236 236
-8 -7 7 236 236 236
-7 -7 7 236 236 236
6 -7 7 236 236 236
7 -7 7 236 236 236
8 -7 7 236 236 236
9 -7 7 236 236 236
14 -7 7 252 252 104
-15 -6 7 252 252 104
14 -6 7 252 252 104
-15 -5 7 252 252 104
14 -5 7 252 252 104
-15 -4 7 252 252 104
14 -4 7 252 252 104
-15 -3 7 68 40 0
14 -3 7 68 40 0
-15 2 7 68 40 0
14 2 7 68 40 0
-15 3 7 252 252 104
14 3 7 252 252 104
-15 4 7 252 252 104
14 4 7 252 252 104
-15 5 7 252 252 104
14 5 7 252 252 104
-15 6 7 252 252 104
-10 6 7 236 236 236
-9 6 7 236 236 236
-8 6 7 236 236 236
-7 6 7 236 236 236
6 6 7 236 236 236
7 6 7 236 236 236
8 6 7 236 236 236
9 6 7 236 236 236
14 6 7 252 252 104
-15 7 7 252 252 104
-10 7 7 236 236 236
-9 7 7 236 236 236
-8 7 7 236 236 236
-7 7 7 236 236 236
6 7 7 236 236 236
7 7 7 236 236 236
8 7 7 236 236 236
9 7 7 236 236 236
14 7 7 252 252 104
-15 8 7 252 252 104
-10 8 7 236 236 236
-9 8 7 236 236 236
-8 8 7 236 236 236
-7 8 7 236 236 236
6 8 7 236 236 236
7 8 7 236 236 236
8 8 7 236 236 236
9 8 7 236 236 236
14 8 7 252 252 104
-15 9 7 252 252 104
-10 9 7 236 236 236
-9 9 7 236 236 236
-8 9 7 236 236 236
-7 9 7 236 236 236
6 9 7 236 236 236
7 9 7 236 236 236
8 9 7 236 236 236
9 9 7 236 236 236
14 9 7 252 252 104
-15 10 7 252 252 104
14 10 7 252 252 104
-15 11 7 252 252 104
14 11 7 252 252 104
-15 12 7 252 252 104
14 12 7 252 252 104
-15 13 7 252 252 104
14 13 7 252 252 104
-15 14 7 68 40 0
-14 14 7 104 136 204
-13 14 7 104 136 204
-12 14 7 104 136 204
-11 14 7 104 136 204
-10 14 7 104 136 204
-9 14 7 104 136 204
-8 14 7 104 136 204
-7 14 7 104 136 204
-6 14 7 104 136 204
-5 14 7 104 136 204
-4 14 7 104 136 204
-3 14 7 68 40 0
2 14 7 68 40 0
3 14 7 104 136 204
4 14 7 104 136 204
5 14 7 104 136 204
6 14 7 104 136 204
7 14 7 104 136 204
8 14 7 104 136 204
9 14 7 104 136 204
10 14 7 104 136 204
11 14 7 104 136 204
12 14 7 104 136 204
13 14 7 104 136 204
14 14 7 68 40 0
-15 -15 8 68 40 0
-14 -15 8 104 136 204
-13 -15 8 104 136 204
-12 -15 8 104 136 204
-11 -15 8 104 136 204
-10 -15 8 104 136 204
-9 -15 8 104 136 204
-8 -15 8 104 136 204
-7 -15 8 104 136 204
-6 -15 8 104 136 204
-5 -15 8 104 136 204
-4 -15 8 104 136 204
-3 -15 8 68 40 0
2 -15 8 68 40 0
3 -15 8 104 136 204
4 -15 8 104 136 204
5 -15 8 104 136 204
6 -15 8 104 136 204
7 -15 8 104 136 204
8 -15 8 104 136 204
9 -15 8 104 136 204
10 -15 8 104 136 204
11 -15 8 104 136 204
12 -15 8 104 136 204
13 -15 8 104 136 204
14 -15 8 68 40 0
-15 -14 8 252 252 104
14 -14 8 252 252 104
-15 -13 8 252 252 104
14 -13 8 252 252 104
-15 -12 8 252 252 104
14 -12 8 252 252 104
-15 -11 8 252 252 104
14 -11 8 252 252 104
-15 -10 8 252 252 104
-10 -10 8 236 236 236
-9 -10 8 236 236 236
-8 -10 8 236 236 236
-7 -10 8 236 236 236
6 -10 8 236 236 236
7 -10 8 236 236 236
8 -10 8 236 236 236
9 -10 8 236 236 236
14 -10 8 252 252 104
-15 -9 8 252 252 104
-10 -9 8 236 236 236
-9 -9 8 236 236 236
-8 -9 8 236 236 236
-7 -9 8 236 236 236
6 -9 8 236 236 236
7 -9 8 236 236 236
8 -9 8 236 236 236
9 -9 8 236 236 236
14 -9 8 252 252 104
-15 -8 8 252 252 104
-10 -8 8 236 236 236
-9 -8 8 236 236 236
-8 -8 8 236 236 236
-7 -8 8 236 236 236
6 -8 8 236 236 236
7 -8 8 236 236 236
8 -8 8 236 236 236
9 -8 8 236 236 236
14 -8 8 252 252 104
-15 -7 8 252 252 104
-10 -7 8 236 236 236
-9 -7 8 236 236 236
-8 -7 8 236 236 236
-7 -7 8 236 236 236
6 -7 8 236 236 236
7 -7 8 236 236 236
8 -7 8 236 236 236
9 -7 8 236 236 236
14 -7 8 252 252 104
-15 -6 8 252 252 104
14 -6 8 252 252 104
-15 -5 8 252 252 104
14 -5 8 252 252 104
-15 -4 8 252 252 104
14 -4 8 252 252 104
-15 -3 8 68 40 0
14 -3 8 68 40 0
-15 2 8 68 40 0
14 2 8 68 40 0
-15 3 8 252 252 104
14 3 8 252 252 104
-15 4 8 252 252 104
14 4 8 252 252 104
-15 5 8 252 252 104
14 5 8 252 252 104
-15 6 8 252 252 104
-10 6 8 236 236 236
-9 6 8 236 236 236
-8 6 8 236 236 236
-7 6 8 236 236 236
6 6 8 236 236 236
7 6 8 236 236 236
8 6 8 236 236 236
9 6 8 236 236 236
14 6 8 252 252 104
-15 7 8 252 252 104
-10 7 8 236 236 236
-9 7 8 236 236 236
-8 7 8 236 236 236
-7 7 8 236 236 236
6 7 8 236 236 236
7 7 8 236 236 236
8 7 8 236 236 236
9 7 8 236 236 236
14 7 8 252 252 104
-15 8 8 252 252 104
-10 8 8 236 236 236
-9 8 8 236 236 236
-8 8 8 236 236 236
-7 8 8 236 236 236
6 8 8 236 236 236
7 8 8 236 236 236
8 8 8 236 236 236
9 8 8 236 236 236
14 8 8 252 252 104
-15 9 8 252 252 104
-10 9 8 236 236 236
-9 9 8 236 236 236
-8 9 8 236 236 236
-7 9 8 236 236 236
6 9 8 236 236 236
7 9 8 236 236 236
8 9 8 236 236 236
9 9 8 236 236 236
14 9 8 252 252 104
-15 10 8 252 252 104
14 10 8 252 252 104
-15 11 8 252 252 104
14 11 8 252 252 104
-15 12 8 252 252 104
14 12 8 252 252 104
-15 13 8 252 252 104
14 13 8 252 252 104
-15 14 8 68 40 0
-14 14 8 104 136 204
-13 14 8 104 136 204
-12 14 8 104 136 204
-11 14 8 104 136 204
-10 14 8 104 136 204
-9 14 8 104 136 204
-8 14 8 104 136 204
-7 14 8 104 136 204
-6 14 8 104 136 204
-5 14 8 104 136 204
-4 14 8 104 136 204
-3 14 8 68 40 0
2 14 8 68 40 0
3 14 8 104 136 204
4 14 8 104 136 204
5 14 8 104 136 204
6 14 8 104 136 204
7 14 8 104 136 204
8 14 8 104 136 204
9 14 8 104 136 204
10 14 8 104 136 204
11 14 8 104 136 204
12 14 8 104 136 204
13 14 8 104 136 204
14 14 8 68 40 0
-15 -15 9 68 40 0
-14 -15 9 68 40 0
-13 -15 9 68 40 0
-12 -15 9 68 40 0
-11 -15 9 68 40 0
-10 -15 9 68 40 0
-9 -15 9 68 40 0
-8 -15 9 68 40 0
-7 -15 9 68 40 0
-6 -15 9 68 40 0
-5 -15 9 68 40 0
-4 -15 9 68 40 0
-3 -15 9 68 40 0
-2 -15 9 68 40 0
-1 -15 9 68 40 0
0 -15 9 68 40 0
1 -15 9 68 40 0
2 -15 9 68 40 0
3 -15 9 68 40 0
4 -15 9 68 40 0
5 -15 9 68 40 0
6 -15 9 68 40 0
7 -15 9 68 40 0
8 -15 9 68 40 0
9 -15 9 68 40 0
10 -15 9 68 40 0
11 -15 9 68 40 0
12 -15 9 68 40 0
13 -15 9 68 40 0
14 -15 9 68 40 0
-15 -14 9 68 40 0
14 -14 9 68 40 0
-15 -13 9 68 40 0
14 -13 9 68 40 0
-15 -12 9 68 40 0
14 -12 9 68 40 0
-15 -11 9 68 40 0
14 -11 9 68 40 0
-15 -10 9 68 40 0
-10 -10 9 68 40 0
-9 -10 9 68 40 0
-8 -10 9 68 40 0
-7 -10 9 68 40 0
6 -10 9 68 40 0
7 -10 9 68 40 0
8 -10 9 68 40 0
9 -10 9 68 40 0
14 -10 9 68 40 0
-15 -9 9 68 40 0
-10 -9 9 68 40 0
-9 -9 9 68 40 0
-8 -9 9 68 40 0
-7 -9 9 68 40 0
6 -9 9 68 40 0
7 -9 9 68 40 0
8 -9 9 68 40 0
9 -9 9 68 40 0
14 -9 9 68 40 0
-15 -8 9 68 40 0
-10 -8 9 68 40 0
-9 -8 9 68 40 0
-8 -8 9 68 40 0
-7 -8 9 68 40 0
6 -8 9 68 40 0
7 -8 9 68 40 0
8 -8 9 68 40 0
9 -8 9 68 40 0
14 -8 9 68 40 0
-15 -7 9 68 40 0
-10 -7 9 68 40 0
-9 -7 9 68 40 0
-8 -7 9 68 40 0
-7 -7 9 68 40 0
6 -7 9 68 40 0
7 -7 9 68 40 0
8 -7 9 68 40 0
9 -7 9 68 40 0
14 -7 9 68 40 0
-15 -6 9 68 40 0
14 -6 9 68 40 0
-15 -5 9 68 40 0
14 -5 9 68 40 0
-15 -4 9 68 40 0
14 -4 9 68 40 0
-15 -3 9 68 40 0
14 -3 9 68 40 0
-15 -2 9 68 40 0
14 -2 9 68 40 0
-15 -1 9 68 40 0
14 -1 9 68 40 0
-15 0 9 68 40 0
14 0 9 68 40 0
-15 1 9 68 40 0
14 1 9 68 40 0
-15 2 9 68 40 0
14 2 9 68 40 0
-15 3 9 68 40 0
14 3 9 68 40 0
-15 4 9 68 40 0
14 4 9 68 40 0
-15 5 9 68 40 0
14 5 9 68 40 0
-15 6 9 68 40 0
-10 6 9 68 40 0
-9 6 9 68 40 0
-8 6 9 68 40 0
-7 6 9 68 40 0
6 6 9 68 40 0
7 6 9 68 40 0
8 6 9 68 40 0
9 6 9 68 40 0
14 6 9 68 40 0
-15 7 9 68 40 0
-10 7 9 68 40 0
-9 7 9 68 40 0
-8 7 9 68 40 0
-7 7 9 68 40 0
6 7 9 68 40 0
7 7 9 68 40 0
8 7 9 68 40 0
9 7 9 68 40 0
14 7 9 68 40 0
-15 8 9 68 40 0
-10 8 9 68 40 0
-9 8 9 68 40 0
-8 8 9 68 40 0
-7 8 9 68 40 0
6 8 9 68 40 0
7 8 9 68 40 0
8 8 9 68 40 0
9 8 9 68 40 0
14 8 9 68 40 0
-15 9 9 68 40 0
-10 9 9 68 40 0
-9 9 9 68 40 0
-8 9 9 68 40 0
-7 9 9 68 40 0
6 9 9 68 40 0
7 9 9 68 40 0
8 9 9 68 40 0
9 9 9 68 40 0
14 9 9 68 40 0
-15 10 9 68 40 0
14 10 9 68 40 0
-15 11 9 68 40 0
14 11 9 68 40 0
-15 12 9 68 40 0
14 12 9 68 40 0
-15 13 9 68 40 0
14 13 9 68 40 0
-15 14 9 68 40 0
-14 14 9 68 40 0
-13 14 9 68 40 0
-12 14 9 68 40 0
-11 14 9 68 40 0
-10 14 9 68 40 0
-9 14 9 68 40 0
-8 14 9 68 40 0
-7 14 9 68 40 0
-6 14 9 68 40 0
-5 14 9 68 40 0
-4 14 9 68 40 0
-3 14 9 68 40 0
-2 14 9 68 40 0
-1 14 9 68 40 0
0 14 9 68 40 0
1 14 9 68 40 0
2 14 9 68 40 0
3 14 9 68 40 0
4 14 9 68 40 0
5 14 9 68 40 0
6 14 9 68 40 0
7 14 9 68 40 0
8 14 9 68 40 0
9 14 9 68 40 0
10 14 9 68 40 0
11 14 9 68 40 0
12 14 9 68 40 0
13 14 9 68 40 0
14 14 9 68 40 0
-15 -15 10 68 40 0
-14 -15 10 68 40 0
-13 -15 10 68 40 0
-12 -15 10 68 40 0
-11 -15 10 68 40 0
-10 -15 10 68 40 0
-9 -15 10 68 40 0
-8 -15 10 68 40 0
-7 -15 10 68 40 0
-6 -15 10 68 40 0
-5 -15 10 68 40 0
-4 -15 10 68 40 0
-3 -15 10 68 40 0
-2 -15 10 68 40 0
-1 -15 10 68 40 0
0 -15 10 68 40 0
1 -15 10 68 40 0
2 -15 10 68 40 0
3 -15 10 68 40 0
4 -15 10 68 40 0
5 -15 10 68 40 0
6 -15 10 68 40 0
7 -15 10 68 40 0
8 -15 10 68 40 0
9 -15 10 68 40 0
10 -15 10 68 40 0
11 -15 10 68 40 0
12 -15 10 68 40 0
13 -15 10 68 40 0
14 -15 10 68 40 0
-15 -14 10 68 40 0
-14 -14 10 132 104 48
-13 -14 10 132 104 48
-12 -14 10 132 104 48
-11 -14 10 132 104 48
-10 -14 10 132 104 48
-9 -14 10 132 104 48
-8 -14 10 132 104 48
-7 -14 10 132 104 48
-6 -14 10 132 104 48
-5 -14 10 132 104 48
-4 -14 10 132 104 48
-3 -14 10 132 104 48
-2 -14 10 132 104 48
-1 -14 10 132 104 48
0 -14 10 132 104 48
1 -14 10 132 104 48
2 -14 10 132 104 48
3 -14 10 132 104 48
4 -14 10 132 104 48
5 -14 10 132 104 48
6 -14 10 132 104 48
7 -14 10 132 104 48
8 -14 10 132 104 48
9 -14 10 132 104 48
10 -14 10 132 104 48
11 -14 10 132 104 48
12 -14 10 132 104 48
13 -14 10 132 104 48
14 -14 10 68 40 0
-15 -13 10 68 40 0
-14 -13 10 132 104 48
-13 -13 10 132 104 48
-12 -13 10 132 104 48
-11 -13 10 132 104 48
-10 -13 10 132 104 48
-9 -13 10 132 104 48
-8 -13 10 132 104 48
-7 -13 10 132 104 48
-6 -13 10 132 104 48
-5 -13 10 132 104 48
-4 -13 10 132 104 48
-3 -13 10 132 104 48
-2 -13 10 132 104 48
-1 -13 10 132 104 48
0 -13 10 132 104 48
1 -13 10 132 104 48
2 -13 10 132 104 48
3 -13 10 132 104 48
4 -13 10 132 104 48
5 -13 10 132 104 48
6 -13 10 132 104 48
7 -13 10 132 104 48
8 -13 10 132 104 48
9 -13 10 132 104 48
10 -13 10 132 104 48
11 -13 10 132 104 48
12 -13 10 132 104 48
13 -13 10 132 104 48
14 -13 10 68 40 0
-15 -12 10 68 40 0
-14 -12 10 132 104 48
-13 -12 10 132 104 48
-12 -12 10 132 104 48
-11 -12 10 132 104 48
-10 -12 10 132 104 48
-9 -12 10 132 104 48
-8 -12 10 132 104 48
-7 -12 10 132 104 48
-6 -12 10 132 104 48
-5 -12 10 132 104 48
-4 -12 10 132 104 48
-3 -12 10 132 104 48
-2 -12 10 132 104 48
-1 -12 10 132 104 48
0 -12 10 132 104 48
1 -12 10 132 104 48
2 -12 10 132 104 48
3 -12 10 132 104 48
4 -12 10 132 104 48
5 -12 10 132 104 48
6 -12 10 132 104 48
7 -12 10 132 104 48
8 -12 10 132 104 48
9 -12 10 132 104 48
10 -12 10 132 104 48
11 -12 10 132 104 48
12 -12 10 132 104 48
13 -12 10 132 104 48
14 -12 10 68 40 0
-15 -11 10 68 40 0
-14 -11 10 132 104 48
-13 -11 10 132 104 48
-12 -11 10 132 104 48
-11 -11 10 132 104 48
-10 -11 10 132 104 48
-9 -11 10 132 104 48
-8 -11 10 132 104 48
-7 -11 10 132 104 48
-6 -11 10 132 104 48
-5 -11 10 132 104 48
-4 -11 10 132 104 48
-3 -11 10 132 104 48
-2 -11 10 132 104 48
-1 -11 10 132 104 48
0 -11 10 132 104 48
1 -11 10 132 104 48
2 -11 10 132 104 48
3 -11 10 132 104 48
4 -11 10 132 104 48
5 -11 10 132 104 48
6 -11 10 132 104 48
7 -11 10 132 104 48
8 -11 10 132 104 48
9 -11 10 132 104 48
10 -11 10 132 104 48
11 -11 10 132 104 48
12 -11 10 132 104 48
13 -11 10 132 104 48
14 -11 10 68 40 0
-15 -10 10 68 40 0
-14 -10 10 132 104 48
-13 -10 10 132 104 48
-12 -10 10 132 104 48
-11 -10 10 132 104 48
-10 -10 10 132 104 48
-9 -10 10 132 104 48
-8 -10 10 132 104 48
-7 -10 10 132 104 48
-6 -10 10 132 104 48
-5 -10 10 132 104 48
-4 -10 10 132 104 48
-3 -10 10 132 104 48
-2 -10 10 132 104 48
-1 -10 10 132 104 48
0 -10 10 132 104 48
1 -10 10 132 104 48
2 -10 10 132 104 48
3 -10 10 132 104 48
4 -10 10 132 104 48
5 -10 10 132 104 48
6 -10 10 132 104 48
7 -10 10 132 104 48
8 -10 10 132 104 48
9 -10 10 132 104 48
10 -10 10 132 104 48
11 -10 10 132 104 48
12 -10 10 132 104 48
13 -10 10 132 104 48
14 -10 10 68 40 0
-15 -9 10 68 40 0
-14 -9 10 132 104 48
-13 -9 10 132 104 48
-12 -9 10 132 104 48
-11 -9 10 132 104 48
-10 -9 10 132 104 48
-9 -9 10 132 104 48
-8 -9 10 132 104 48
-7 -9 10 132 104 48
-6 -9 10 132 104 48
-5 -9 10 132 104 48
-4 -9 10 132 104 48
-3 -9 10 132 104 48
-2 -9 10 132 104 48
-1 -9 10 132 104 48
0 -9 10 132 104 48
1 -9 10 132 104 48
2 -9 10 132 104 48
3 -9 10 132 104 48
4 -9 10 132 104 48
5 -9 10 132 104 48
6 -9 10 132 104 48
7 -9 10 132 104 48
8 -9 10 132 104 48
9 -9 10 132 104 48
10 -9 10 132 104 48
11 -9 10 132 104 48
12 -9 10 132 104 48
13 -9 10 132 104 48
14 -9 10 68 40 0
-15 -8 10 68 40 0
-14 -8 10 132 104 48
-13 -8 10 132 104 48
-12 -8 10 132 104 48
-11 -8 10 132 104 48
-10 -8 10 132 104 48
-9 -8 10 132 104 48
-8 -8 10 132 104 48
-7 -8 10 132 104 48
-6 -8 10 132 104 48
-5 -8 10 132 104 48
-4 -8 10 132 104 48
-3 -8 10 132 104 48
-2 -8 10 132 104 48
-1 -8 10 132 104 48
0 -8 10 132 104 48
1 -8 10 132 104 48
2 -8 10 132 104 48
3 -8 10 132 104 48
4 -8 10 132 104 48
5 -8 10 132 104 48
6 -8 10 132 104 48
7 -8 10 132 104 48
8 -8 10 132 104 48
9 -8 10 132 104 48
10 -8 10 132 104 48
11 -8 10 132 104 48
12 -8 10 132 104 48
13 -8 10 132 104 48
14 -8 10 68 40 0
-15 -7 10 68 40 0
-14 -7 10 132 104 48
-13 -7 10 132 104 48
-12 -7 10 132 104 48
-11 -7 10 132 104 48
-10 -7 10 132 104 48
-9 -7 10 132 104 48
-8 -7 10 132 104 48
-7 -7 10 132 104 48
-6 -7 10 132 104 48
-5 -7 10 132 104 48
-4 -7 10 132 104 48
-3 -7 10 132 104 48
-2 -7 10 132 104 48
-1 -7 10 132 104 48
0 -7 10 132 104 48
1 -7 10 132 104 48
2 -7 10 132 104 48
3 -7 10 132 104 48
4 -7 10 132 104 48
5 -7 10 132 104 48
6 -7 10 132 104 48
7 -7 10 132 104 48
8 -7 10 132 104 48
9 -7 10 132 104 48
10 -7 10 132 104 48
11 -7 10 132 104 48
12 -7 10 132 104 48
13 -7 10 132 104 48
14 -7 10 68 40 0
-15 -6 10 68 40 0
-14 -6 10 132 104 48
-13 -6 10 132 104 48
-12 -6 10 132 104 48
-11 -6 10 132 104 48
-10 -6 10 132 104 48
-9 -6 10 132 104 48
-8 -6 10 132 104 48
-7 -6 10 132 104 48
-6 -6 10 68 40 0
-5 -6 10 68 40 0
-4 -6 10 68 40 0
-3 -6 10 68 40 0
-2 -6 10 68 40 0
-1 -6 10 68 40 0
0 -6 10 68 40 0
1 -6 10 68 40 0
2 -6 10 68 40 0
3 -6 10 68 40 0
4 -6 10 68 40 0
5 -6 10 68 40 0
6 -6 10 132 104 48
7 -6 10 132 104 48
8 -6 10 132 104 48
9 -6 10 132 104 48
10 -6 10 132 104 48
11 -6 10 132 104 48
12 -6 10 132 104 48
13 -6 10 132 104 48
14 -6 10 68 40 0
-15 -5 10 68 40 0
-14 -5 10 132 104 48
-13 -5 10 132 104 48
-12 -5 10 132 104 48
-11 -5 10 132 104 48
-10 -5 10 132 104 48
-9 -5 10 132 104 48
-8 -5 10 132 104 48
-7 -5 10 132 104 48
-6 -5 10 68 40 0
5 -5 10 68 40 0
6 -5 10 132 104 48
7 -5 10 132 104 48
8 -5 10 132 104 48
9 -5 10 132 104 48
10 -5 10 132 104 48
11 -5 10 132 104 48
12 -5 10 132 104 48
13 -5 10 132 104 48
14 -5 10 68 40 0
-15 -4 10 68 40 0
-14 -4 10 132 104 48
-13 -4 10 132 104 48
-12 -4 10 132 104 48
-11 -4 10 132 104 48
-10 -4 10 132 104 48
-9 -4 10 132 104 48
-8 -4 10 132 104 48
-7 -4 10 132 104 48
-6 -4 10 68 40 0
5 -4 10 68 40 0
6 -4 10 132 104 48
7 -4 10 132 104 48
8 -4 10 132 104 48
9 -4 10 132 104 48
10 -4 10 132 104 48
11 -4 10 132 104 48
12 -4 10 132 104 48
13 -4 10 132 104 48
14 -4 10 68 40 0
-15 -3 10 68 40 0
-14 -3 10 132 104 48
-13 -3 10 132 104 48
-12 -3 10 132 104 48
-11 -3 10 132 104 48
-10 -3 10 132 104 48
-9 -3 10 132 104 48
-8 -3 10 132 104 48
-7 -3 10 132 104 48
-6 -3 10 68 40 0
5 -3 10 68 40 0
6 -3 10 132 104 48
7 -3 10 132 104 48
8 -3 10 132 104 48
9 -3 10 132 104 48
10 -3 10 132 104 48
11 -3 10 132 104 48
12 -3 10 132 104 48
13 -3 10 132 104 48
14 -3 10 68 40 0
-15 -2 10 68 40 0
-14 -2 10 132 104 48
-13 -2 10 132 104 48
-12 -2 10 132 104 48
-11 -2 10 132 104 48
-10 -2 10 132 104 48
-9 -2 10 132 104 48
-8 -2 10 132 104 48
-7 -2 10 132 104 48
-6 -2 10 68 40 0
5 -2 10 68 40 0
6 -2 10 132 104 48
7 -2 10 132 104 48
8 -2 10 132 104 48
9 -2 10 132 104 48
10 -2 10 132 104 48
11 -2 10 132 104 48
12 -2 10 132 104 48
13 -2 10 132 104 48
14 -2 10 68 40 0
-15 -1 10 68 40 0
-14 -1 10 132 104 48
-13 -1 10 132 104 48
-12 -1 10 132 104 48
-11 -1 10 132 104 48
-10 -1 10 132 104 48
-9 -1 10 132 104 48
-8 -1 10 132 104 48
-7 -1 10 132 104 48
-6 -1 10 68 40 0
5 -1 10 68 40 0
6 -1 10 132 104 48
7 -1 10 132 104 48
8 -1 10 132 104 48
9 -1 10 132 104 48
10 -1 10 132 104 48
11 -1 10 132 104 48
12 -1 10 132 104 48
13 -1 10 132 104 48
14 -1 10 68 40 0
-15 0 10 68 40 0
-14 0 10 132 104 48
-13 0 10 132 104 48
-12 0 10 132 104 48
-11 0 10 132 104 48
-10 0 10 132 104 48
-9 0 10 132 104 48
-8 0 10 132 104 48
-7 0 10 132 104 48
-6 0 10 68 40 0
5 0 10 68 40 0
6 0 10 132 104 48
7 0 10 132 104 48
8 0 10 132 104 48
9 0 10 132 104 48
10 0 10 132 104 48
11 0 10 132 104 48
12 0 10 132 104 48
13 0 10 132 104 48
14 0 10 68 40 0
-15 1 10 68 40 0
-14 1 10 132 104 48
-13 1 10 132 104 48
-12 1 10 132 104 48
-11 1 10 132 104 48
-10 1 10 132 104 48
-9 1 10 132 104 48
-8 1 10 132 104 48
-7 1 10 132 104 48
-6 1 10 68 40 0
5 1 10 68 40 0
6 1 10 132 104 48
7 1 10 132 104 48
8 1 10 132 104 48
9 1 10 132 104 48
10 1 10 132 104 48
11 1 10 132 104 48
12 1 10 132 104 48
13 1 10 132 104 48
14 1 10 68 40 0
-15 2 10 68 40 0
-14 2 10 132 104 48
-13 2 10 132 104 48
-12 2 10 132 104 48
-11 2 10 132 104 48
-10 2 10 132 104 48
-9 2 10 132 104 48
-8 2 10 132 104 48
-7 2 10 132 104 48
-6 2 10 68 40 0
5 2 10 68 40 0
6 2 10 132 104 48
7 2 10 132 104 48
8 2 10 132 104 48
9 2 10 132 104 48
10 2 10 132 104 48
11 2 10 132 104 48
12 2 10 132 104 48
13 2 10 132 104 48
14 2 10 68 40 0
-15 3 10 68 40 0
-14 3 10 132 104 48
-13 3 10 132 104 48
-12 3 10 132 104 48
-11 3 10 132 104 48
-10 3 10 132 104 48
-9 3 10 132 104 48
-8 3 10 132 104 48
-7 3 10 132 104 48
-6 3 10 68 40 0
5 3 10 68 40 0
6 3 10 132 104 48
7 3 10 132 104 48
8 3 10 132 104 48
9 3 10 132 104 48
10 3 10 132 104 48
11 3 10 132 104 48
12 3 10 132 104 48
13 3 10 132 104 48
14 3 10 68 40 0
-15 4 10 68 40 0
-14 4 10 132 104 48
-13 4 10 132 104 48
-12 4 10 132 104 48
-11 4 10 132 104 48
-10 4 10 132 104 48
-9 4 10 132 104 48
-8 4 10 132 104 48
-7 4 10 132 104 48
-6 4 10 68 40 0
5 4 10 68 40 0
6 4 10 132 104 48
7 4 10 132 104 48
8 4 10 132 104 48
9 4 10 132 104 48
10 4 10 132 104 48
11 4 10 132 104 48
12 4 10 132 104 48
13 4 10 132 104 48
14 4 10 68 40 0
-15 5 10 68 40 0
-14 5 10 132 104 48
-13 5 10 132 104 48
-12 5 10 132 104 48
-11 5 10 132 104 48
-10 5 10 132 104 48
-9 5 10 132 104 48
-8 5 10 132 104 48
-7 5 10 132 104 48
-6 5 10 68 40 0
-5 5 10 68 40 0
-4 5 10 68 40 0
-3 5 10 68 40 0
-2 5 10 68 40 0
-1 5 10 68 40 0
0 5 10 68 40 0
1 5 10 68 40 0
2 5 10 68 40 0
3 5 10 68 40 0
4 5 10 68 40 0
5 5 10 68 40 0
6 5 10 132 104 48
7 5 10 132 104 48
8 5 10 132 104 48
9 5 10 132 104 48
10 5 10 132 104 48
11 5 10 132 104 48
12 5 10 132 104 48
13 5 10 132 104 48
14 5 10 68 40 0
-15 6 10 68 40 0
-14 6 10 132 104 48
-13 6 10 132 104 48
-12 6 10 132 104 48
-11 6 10 132 104 48
-10 6 10 132 104 48
-9 6 10 132 104 48
-8 6 10 132 104 48
-7 6 10 132 104 48
-6 6 10 132 104 48
-5 6 10 132 104 48
-4 6 10 132 104 48
-3 6 10 132 104 48
-2 6 10 132 104 48
-1 6 10 132 104 48
0 6 10 132 104 48
1 6 10 132 104 48
2 6 10 132 104 48
3 6 10 132 104 48
4 6 10 132 104 48
5 6 10 132 104 48
6 6 10 132 104 48
7 6 10 132 104 48
8 6 10 132 104 48
9 6 10 132 104 48
10 6 10 132 104 48
11 6 10 132 104 48
12 6 10 132 104 48
13 6 10 132 104 48
14 6 10 68 40 0
-15 7 10 68 40 0
-14 7 10 132 104 48
-13 7 10 132 104 48
-12 7 10 132 104 48
-11 7 10 132 104 48
-10 7 10 132 104 48
-9 7 10 132 104 48
-8 7 10 132 104 48
-7 7 10 132 104 48
-6 7 10 132 104 48
-5 7 10 132 104 48
-4 7 10 132 104 48
-3 7 10 132 104 48
-2 7 10 132 104 48
-1 7 10 132 104 48
0 7 10 132 104 48
1 7 10 132 104 48
2 7 10 132 104 48
3 7 10 132 104 48
4 7 10 132 104 48
5 7 10 132 104 48
6 7 10 132 104 48
7 7 10 132 104 48
8 7 10 132 104 48
9 7 10 132 104 48
10 7 10 132 104 48
11 7 10 132 104 48
12 7 10 132 104 48
13 7 10 132 104 48
14 7 10 68 40 0
-15 8 10 68 40 0
-14 8 10 132 104 48
-13 8 10 132 104 48
-12 8 10 132 104 48
-11 8 10 132 104 48
-10 8 10 132 104 48
-9 8 10 132 104 48
-8 8 10 132 104 48
-7 8 10 132 104 48
-6 8 10 132 104 48
-5 8 10 132 104 48
-4 8 10 132 104 48
-3 8 10 132 104 48
-2 8 10 132 104 48
-1 8 10 132 104 48
0 8 10 132 104 48
1 8 10 132 104 48
2 8 10 132 104 48
3 8 10 132 104 48
4 8 10 132 104 48
5 8 10 132 104 48
6 8 10 132 104 48
7 8 10 132 104 48
8 8 10 132 104 48
9 8 10 132 104 48
10 8 10 132 104 48
11 8 10 132 104 48
12 8 10 132 104 48
13 8 10 132 104 48
14 8 10 68 40 0
-15 9 10 68 40 0
-14 9 10 132 104 48
-13 9 10 132 104 48
-12 9 10 132 104 48
-11 9 10 132 104 48
-10 9 10 132 104 48
-9 9 10 132 104 48
-8 9 10 132 104 48
-7 9 10 132 104 48
-6 9 10 132 104 48
-5 9 10 132 104 48
-4 9 10 132 104 48
-3 9 10 132 104 48
-2 9 10 132 104 48
-1 9 10 132 104 48
0 9 10 132 104 48
1 9 10 132 104 48
2 9 10 132 104 48
3 9 10 132 104 48
4 9 10 132 104 48
5 9 10 132 104 48
6 9 10 132 104 48
7 9 10 132 104 48
8 9 10 132 104 48
9 9 10 132 104 48
10 9 10 132 104 48
11 9 10 132 104 48
12 9 10 132 104 48
13 9 10 132 104 48
14 9 10 68 40 0
-15 10 10 68 40 0
-14 10 10 132 104 48
-13 10 10 132 104 48
-12 10 10 132 104 48
-11 10 10 132 104 48
-10 10 10 132 104 48
-9 10 10 132 104 48
-8 10 10 132 104 48
-7 10 10 132 104 48
-6 10 10 132 104 48
-5 10 10 132 104 48
-4 10 10 132 104 48
-3 10 10 132 104 48
-2 10 10 132 104 48
-1 10 10 132 104 48
0 10 10 132 104 48
1 10 10 132 104 48
2 10 10 132 104 48
3 10 10 132 104 48
4 10 10 132 104 48
5 10 10 132 104 48
6 10 10 132 104 48
7 10 10 132 104 48
8 10 10 132 104 48
9 10 10 132 104 48
10 10 10 132 104 48
11 10 10 132 104 48
12 10 10 132 104 48
13 10 10 132 104 48
14 10 10 68 40 0
-15 11 10 68 40 0
-14 11 10 132 104 48
-13 11 10 132 104 48
-12 11 10 132 104 48
-11 11 10 132 104 48
-10 11 10 132 104 48
-9 11 10 132 104 48
-8 11 10 132 104 48
-7 11 10 132 104 48
-6 11 10 132 104 48
-5 11 10 132 104 48
-4 11 10 132 104 48
-3 11 10 132 104 48
-2 11 10 132 104 48
-1 11 10 132 104 48
0 11 10 132 104 48
1 11 10 132 104 48
2 11 10 132 104 48
3 11 10 132 104 48
4 11 10 132 104 48
5 11 10 132 104 48
6 11 10 132 104 48
7 11 10 132 104 48
8 11 10 132 104 48
9 11 10 132 104 48
10 11 10 132 104 48
11 11 10 132 104 48
12 11 10 132 104 48
13 11 10 132 104 48
14 11 10 68 40 0
-15 12 10 68 40 0
-14 12 10 132 104 48
-13 12 10 132 104 48
-12 12 10 132 104 48
-11 12 10 132 104 48
-10 12 10 132 104 48
-9 12 10 132 104 48
-8 12 10 132 104 48
-7 12 10 132 104 48
-6 12 10 132 104 48
-5 12 10 132 104 48
-4 12 10 132 104 48
-3 12 10 132 104 48
-2 12 10 132 104 48
-1 12 10 132 104 48
0 12 10 132 104 48
1 12 10 132 104 48
2 12 10 132 104 48
3 12 10 132 104 48
4 12 10 132 104 48
5 12 10 132 104 48
6 12 10 132 104 48
7 12 10 132 104 48
8 12 10 132 104 48
9 12 10 132 104 48
10 12 10 132 104 48
11 12 10 132 104 48
12 12 10 132 104 48
13 12 10 132 104 48
14 12 10 68 40 0
-15 13 10 68 40 0
-14 13 10 132 104 48
-13 13 10 132 104 48
-12 13 10 132 104 48
-11 13 10 132 104 48
-10 13 10 132 104 48
-9 13 10 132 104 48
-8 13 10 132 104 48
-7 13 10 132 104 48
-6 13 10 132 104 48
-5 13 10 132 104 48
-4 13 10 132 104 48
-3 13 10 132 104 48
-2 13 10 132 104 48
-1 13 10 132 104 48
0 13 10 132 104 48
1 13 10 132 104 48
2 13 10 132 104 48
3 13 10 132 104 48
4 13 10 132 104 48
5 13 10 132 104 48
6 13 10 132 104 48
7 13 10 132 104 48
8 13 10 132 104 48
9 13 10 132 104 48
10 13 10 132 104 48
11 13 10 132 104 48
12 13 10 132 104 48
13 13 10 132 104 48
14 13 10 68 40 0
-15 14 10 68 40 0
-14 14 10 68 40 0
-13 14 10 68 40 0
-12 14 10 68 40 0
-11 14 10 68 40 0
-10 14 10 68 40 0
-9 14 10 68 40 0
-8 14 10 68 40 0
-7 14 10 68 40 0
-6 14 10 68 40 0
-5 14 10 68 40 0
-4 14 10 68 40 0
-3 14 10 68 40 0
-2 14 10 68 40 0
-1 14 10 68 40 0
0 14 10 68 40 0
1 14 10 68 40 0
2 14 10 68 40 0
3 14 10 68 40 0
4 14 10 68 40 0
5 14 10 68 40 0
6 14 10 68 40 0
7 14 10 68 40 0
8 14 10 68 40 0
9 14 10 68 40 0
10 14 10 68 40 0
11 14 10 68 40 0
12 14 10 68 40 0
13 14 10 68 40 0
14 14 10 68 40 0
-15 -15 11 68 40 0
-14 -15 11 68 40 0
-13 -15 11 68 40 0
-12 -15 11 68 40 0
-11 -15 11 68 40 0
-10 -15 11 68 40 0
-9 -15 11 68 40 0
-8 -15 11 68 40 0
-7 -15 11 68 40 0
-6 -15 11 68 40 0
-5 -15 11 68 40 0
-4 -15 11 68 40 0
-3 -15 11 68 40 0
2 -15 11 68 40 0
3 -15 11 68 40 0
4 -15 11 68 40 0
5 -15 11 68 40 0
6 -15 11 68 40 0
7 -15 11 68 40 0
8 -15 11 68 40 0
9 -15 11 68 40 0
10 -15 11 68 40 0
11 -15 11 68 40 0
12 -15 11 68 40 0
13 -15 11 68 40 0
14 -15 11 68 40 0
-15 -14 11 68 40 0
14 -14 11 68 40 0
-15 -13 11 68 40 0
14 -13 11 68 40 0
-15 -12 11 68 40 0
14 -12 11 68 40 0
-15 -11 11 68 40 0
14 -11 11 68 40 0
-15 -10 11 68 40 0
-10 -10 11 68 40 0
-9 -10 11 68 40 0
-8 -10 11 68 40 0
-7 -10 11 68 40 0
6 -10 11 68 40 0
7 -10 11 68 40 0
8 -10 11 68 40 0
9 -10 11 68 40 0
14 -10 11 68 40 0
-15 -9 11 68 40 0
-10 -9 11 68 40 0
-9 -9 11 68 40 0
-8 -9 11 68 40 0
-7 -9 11 68 40 0
6 -9 11 68 40 0
7 -9 11 68 40 0
8 -9 11 68 40 0
9 -9 11 68 40 0
14 -9 11 68 40 0
-15 -8 11 68 40 0
-10 -8 11 68 40 0
-9 -8 11 68 40 0
-8 -8 11 68 40 0
-7 -8 11 68 40 0
6 -8 11 68 40 0
7 -8 11 68 40 0
8 -8 11 68 40 0
9 -8 11 68 40 0
14 -8 11 68 40 0
-15 -7 11 68 40 0
-10 -7 11 68 40 0
-9 -7 11 68 40 0
-8 -7 11 68 40 0
-7 -7 11 68 40 0
6 -7 11 68 40 0
7 -7 11 68 40 0
8 -7 11 68 40 0
9 -7 11 68 40 0
14 -7 11 68 40 0
-15 -6 11 68 40 0
-6 -6 11 68 40 0
-5 -6 11 68 40 0
-4 -6 11 68 40 0
-3 -6 11 68 40 0
-2 -6 11 68 40 0
-1 -6 11 68 40 0
0 -6 11 68 40 0
1 -6 11 68 40 0
2 -6 11 68 40 0
3 -6 11 68 40 0
4 -6 11 68 40 0
5 -6 11 68 40 0
14 -6 11 68 40 0
-15 -5 11 68 40 0
-6 -5 11 68 40 0
5 -5 11 68 40 0
14 -5 11 68 40 0
-15 -4 11 68 40 0
-6 -4 11 68 40 0
5 -4 11 68 40 0
14 -4 11 68 40 0
-15 -3 11 68 40 0
-6 -3 11 68 40 0
5 -3 11 68 40 0
14 -3 11 68 40 0
-6 -2 11 68 40 0
5 -2 11 68 40 0
-6 -1 11 68 40 0
5 -1 11 68 40 0
-6 0 11 68 40 0
5 0 11 68 40 0
-6 1 11 68 40 0
5 1 11 68 40 0
-15 2 11 68 40 0
-6 2 11 68 40 0
5 2 11 68 40 0
14 2 11 68 40 0
-15 3 11 68 40 0
-6 3 11 68 40 0
5 3 11 68 40 0
14 3 11 68 40 0
-15 4 11 68 40 0
-6 4 11 68 40 0
5 4 11 68 40 0
14 4 11 68 40 0
-15 5 11 68 40 0
-6 5 11 68 40 0
-5 5 11 68 40 0
-4 5 11 68 40 0
-3 5 11 68 40 0
-2 5 11 68 40 0
-1 5 11 68 40 0
0 5 11 68 40 0
1 5 11 68 40 0
2 5 11 68 40 0
3 5 11 68 40 0
4 5 11 68 40 0
5 5 11 68 40 0
14 5 11 68 40 0
-15 6 11 68 40 0
-10 6 11 68 40 0
-9 6 11 68 40 0
-8 6 11 68 40 0
-7 6 11 68 40 0
6 6 11 68 40 0
7 6 11 68 40 0
8 6 11 68 40 0
9 6 11 68 40 0
14 6 11 68 40 0
-15 7 11 68 40 0
-10 7 11 68 40 0
-9 7 11 68 40 0
-8 7 11 68 40 0
-7 7 11 68 40 0
6 7 11 68 40 0
7 7 11 68 40 0
8 7 11 68 40 0
9 7 11 68 40 0
14 7 11 68 40 0
-15 8 11 68 40 0
-10 8 11 68 40 0
-9 8 11 68 40 0
-8 8 11 68 40 0
-7 8 11 68 40 0
6 8 11 68 40 0
7 8 11 68 40 0
8 8 11 68 40 0
9 8 11 68 40 0
14 8 11 68 40 0
-15 9 11 68 40 0
-10 9 11 68 40 0
-9 9 11 68 40 0
-8 9 11 68 40 0
-7 9 11 68 40 0
6 9 11 68 40 0
7 9 11 68 40 0
8 9 11 68 40 0
9 9 11 68 40 0
14 9 11 68 40 0
-15 10 11 68 40 0
14 10 11 68 40 0
-15 11 11 68 40 0
14 11 11 68 40 0
-15 12 11 68 40 0
14 12 11 68 40 0
-15 13 11 68 40 0
14 13 11 68 40 0
-15 14 11 68 40 0
-14 14 11 68 40 0
-13 14 11 68 40 0
-12 14 11 68 40 0
-11 14 11 68 40 0
-10 14 11 68 40 0
-9 14 11 68 40 0
-8 14 11 68 40 0
-7 14 11 68 40 0
-6 14 11 68 40 0
-5 14 11 68 40 0
-4 14 11 68 40 0
-3 14 11 68 40 0
2 14 11 68 40 0
3 14 11 68 40 0
4 14 11 68 40 0
5 14 11 68 40 0
6 14 11 68 40 0
7 14 11 68 40 0
8 14 11 68 40 0
9 14 11 68 40 0
10 14 11 68 40 0
11 14 11 68 40 0
12 14 11 68 40 0
13 14 11 68 40 0
14 14 11 68 40 0
-15 -15 12 68 40 0
-14 -15 12 104 136 204
-13 -15 12 104 136 204
-12 -15 12 104 136 204
-11 -15 12 104 136 204
-10 -15 12 104 136 204
-9 -15 12 104 136 204
-8 -15 12 104 136 204
-7 -15 12 104 136 204
-6 -15 12 104 136 204
-5 -15 12 104 136 204
-4 -15 12 104 136 204
-3 -15 12 68 40 0
2 -15 12 68 40 0
3 -15 12 104 136 204
4 -15 12 104 136 204
5 -15 12 104 136 204
6 -15 12 104 136 204
7 -15 12 104 136 204
8 -15 12 104 136 204
9 -15 12 104 136 204
10 -15 12 104 136 204
11 -15 12 104 136 204
12 -15 12 104 136 204
13 -15 12 104 136 204
14 -15 12 68 40 0
-15 -14 12 252 252 104
14 -14 12 252 252 104
-15 -13 12 252 252 104
14 -13 12 252 252 104
-15 -12 12 252 252 104
14 -12 12 252 252 104
-15 -11 12 252 252 104
14 -11 12 252 252 104
-15 -10 12 252 252 104
-10 -10 12 236 236 236
-9 -10 12 236 236 236
-8 -10 12 236 236 236
-7 -10 12 236 236 236
6 -10 12 236 236 236
7 -10 12 236 236 236
8 -10 12 236 236 236
9 -10 12 236 236 236
14 -10 12 252 252 104
-15 -9 12 252 252 104
-10 -9 12 236 236 236
-9 -9 12 236 236 236
-8 -9 12 236 236 236
-7 -9 12 236 236 236
6 -9 12 236 236 236
7 -9 12 236 236 236
8 -9 12 236 236 236
9 -9 12 236 236 236
14 -9 12 252 252 104
-15 -8 12 252 252 104
-10 -8 12 236 236 236
-9 -8 12 236 236 236
-8 -8 12 236 236 236
-7 -8 12 236 236 236
6 -8 12 236 236 236
7 -8 12 236 236 236
8 -8 12 236 236 236
9 -8 12 236 236 236
14 -8 12 252 252 104
-15 -7 12 252 252 104
-10 -7 12 236 236 236
-9 -7 12 236 236 236
-8 -7 12 236 236 236
-7 -7 12 236 236 236
6 -7 12 236 236 236
7 -7 12 236 236 236
8 -7 12 236 236 236
9 -7 12 236 236 236
14 -7 12 252 252 104
-15 -6 12 252 252 104
14 -6 12 252 252 104
-15 -5 12 252 252 104
14 -5 12 252 252 104
-15 -4 12 252 252 104
14 -4 12 252 252 104
-15 -3 12 68 40 0
14 -3 12 68 40 0
-15 2 12 68 40 0
14 2 12 68 40 0
-15 3 12 252 252 104
14 3 12 252 252 104
-15 4 12 252 252 104
14 4 12 252 252 104
-15 5 12 252 252 104
14 5 12 252 252 104
-15 6 12 252 252 104
-10 6 12 236 236 236
-9 6 12 236 236 236
-8 6 12 236 236 236
-7 6 12 236 236 236
6 6 12 236 236 236
7 6 12 236 236 236
8 6 12 236 236 236
9 6 12 236 236 236
14 6 12 252 252 104
-15 7 12 252 252 104
-10 7 12 236 236 236
-9 7 12 236 236 236
-8 7 12 236 236 236
-7 7 12 236 236 236
6 7 12 236 236 236
7 7 12 236 236 236
8 7 12 236 236 236
9 7 12 236 236 236
14 7 12 252 252 104
-15 8 12 252 252 104
-10 8 12 236 236 236
-9 8 12 236 236 236
-8 8 12 236 236 236
-7 8 12 236 236 236
6 8 12 236 236 236
7 8 12 236 236 236
8 8 12 236 236 236
9 8 12 236 236 236
14 8 12 252 252 104
-15 9 12 252 252 104
-10 9 12 236 236 236
-9 9 12 236 236 236
-8 9 12 236 236 236
-7 9 12 236 236 236
6 9 12 236 236 236
7 9 12 236 236 236
8 9 12 236 236 236
9 9 12 236 236 236
14 9 12 252 252 104
-15 10 12 252 252 104
14 10 12 252 252 104
-15 11 12 252 252 104
14 11 12 252 252 104
-15 12 12 252 252 104
14 12 12 252 252 104
-15 13 12 252 252 104
14 13 12 252 252 104
-15 14 12 68 40 0
-14 14 12 104 136 204
-13 14 12 104 136 204
-12 14 12 104 136 204
-11 14 12 104 136 204
-10 14 12 104 136 204
-9 14 12 104 136 204
-8 14 12 104 136 204
-7 14 12 104 136 204
-6 14 12 104 136 204
-5 14 12 104 136 204
-4 14 12 104 136 204
-3 14 12 68 40 0
2 14 12 68 40 0
3 14 12 104 136 204
4 14 12 104 136 204
5 14 12 104 136 204
6 14 12 104 136 204
7 14 12 104 136 204
8 14 12 104 136 204
9 14 12 104 136 204
10 14 12 104 136 204
11 14 12 104 136 204
12 14 12 104 136 204
13 14 12 104 136 204
14 14 12 68 40 0
-15 -15 13 68 40 0
-14 -15 13 104 136 204
-13 -15 13 104 136 204
-12 -15 13 104 136 204
-11 -15 13 104 136 204
-10 -15 13 104 136 204
-9 -15 13 104 136 204
-8 -15 13 104 136 204
-7 -15 13 104 136 204
-6 -15 13 104 136 204
-5 -15 13 104 136 204
-4 -15 13 104 136 204
-3 -15 13 68 40 0
2 -15 13 68 40 0
3 -15 13 104 136 204
4 -15 13 104 136 204
5 -15 13 104 136 204
6 -15 13 104 136 204
7 -15 13 104 136 204
8 -15 13 104 136 204
9 -15 13 104 136 204
10 -15 13 104 136 204
11 -15 13 104 136 204
12 -15 13 104 136 204
13 -15 13 104 136 204
14 -15 13 68 40 0
-15 -14 13 252 252 104
14 -14 13 252 252 104
-15 -13 13 252 252 104
14 -13 13 252 252 104
-15 -12 13 252 252 104
14 -12 13 252 252 104
-15 -11 13 252 252 104
14 -11 13 252 252 104
-15 -10 13 252 252 104
-10 -10 13 236 236 236
-9 -10 13 236 236 236
-8 -10 13 236 236 236
-7 -10 13 236 236 236
6 -10 13 236 236 236
7 -10 13 236 236 236
8 -10 13 236 236 236
9 -10 13 236 236 236
14 -10 13 252 252 104
-15 -9 13 252 252 104
-10 -9 13 236 236 236
-9 -9 13 236 236 236
-8 -9 13 236 236 236
-7 -9 13 236 236 236
6 -9 13 236 236 236
7 -9 13 236 236 236
8 -9 13 236 236 236
9 -9 13 236 236 236
14 -9 13 252 252 104
-15 -8 13 252 252 104
-10 -8 13 236 236 236
-9 -8 13 236 236 236
-8 -8 13 236 236 236
-7 -8 13 236 236 236
6 -8 13 236 236 236
7 -8 13 236 236 236
8 -8 13 236 236 236
9 -8 13 236 236 236
14 -8 13 252 252 104
-15 -7 13 252 252 104
-10 -7 13 236 236 236
-9 -7 13 236 236 236
-8 -7 13 236 236 236
-7 -7 13 236 236 236
6 -7 13 236 236 236
7 -7 13 236 236 236
8 -7 13 236 236 236
9 -7 13 236 236 236
14 -7 13 252 252 104
-15 -6 13 252 252 104
14 -6 13 252 252 104
-15 -5 13 252 252 104
14 -5 13 252 252 104
-15 -4 13 252 252 104
14 -4 13 252 252 104
-15 -3 13 68 40 0
14 -3 13 68 40 0
-15 2 13 68 40 0
14 2 13 68 40 0
-15 3 13 252 252 104
14 3 13 252 252 104
-15 4 13 252 252 104
14 4 13 252 252 104
-15 5 13 252 252 104
14 5 13 252 252 104
-15 6 13 252 252 104
-10 6 13 236 236 236
-9 6 13 236 236 236
-8 6 13 236 236 236
-7 6 13 236 236 236
6 6 13 236 236 236
7 6 13 236 236 236
8 6 13 236 236 236
9 6 13 236 236 236
14 6 13 252 252 104
-15 7 13 252 252 104
-10 7 13 236 236 236
-9 7 13 236 236 236
-8 7 13 236 236 236
-7 7 13 236 236 236
6 7 13 236 236 236
7 7 13 236 236 236
8 7 13 236 236 236
9 7 13 236 236 236
14 7 13 252 252 104
-15 8 13 252 252 104
-10 8 13 236 236 236
-9 8 13 236 236 236
-8 8 13 236 236 236
-7 8 13 236 236 236
6 8 13 236 236 236
7 8 13 236 236 236
8 8 13 236 236 236
9 8 13 236 236 236
14 8 13 252 252 104
-15 9 13 252 252 104
-10 9 13 236 236 236
-9 9 13 236 236 236
-8 9 13 236 236 236
-7 9 13 236 236 236
6 9 13 236 236 236
7 9 13 236 236 236
8 9 13 236 236 236
9 9 13 236 236 236
14 9 13 252 252 104
-15 10 13 252 252 104
14 10 13 252 252 104
-15 11 13 252 252 104
14 11 13 252 252 104
-15 12 13 252 252 104
14 12 13 252 252 104
-15 13 13 252 252 104
14 13 13 252 252 104
-15 14 13 68 40 0
-14 14 13 104 136 204
-13 14 13 104 136 204
-12 14 13 104 136 204
-11 14 13 104 136 204
-10 14 13 104 136 204
-9 14 13 104 136 204
-8 14 13 104 136 204
-7 14 13 104 136 204
-6 14 13 104 136 204
-5 14 13 104 136 204
-4 14 13 104 136 204
-3 14 13 68 40 0
2 14 13 68 40 0
3 14 13 104 136 204
4 14 13 104 136 204
5 14 13 104 136 204
6 14 13 104 136 204
7 14 13 104 136 204
8 14 13 104 136 204
9 14 13 104 136 204
10 14 13 104 136 204
11 14 13 104 136 204
12 14 13 104 136 204
13 14 13 104 136 204
14 14 13 68 40 0
-15 -15 14 68 40 0
-14 -15 14 104 136 204
-13 -15 14 104 136 204
-12 -15 14 104 136 204
-11 -15 14 104 136 204
-10 -15 14 104 136 204
-9 -15 14 104 136 204
-8 -15 14 104 136 204
-7 -15 14 104 136 204
-6 -15 14 104 136 204
-5 -15 14 104 136 204
-4 -15 14 104 136 204
-3 -15 14 68 40 0
2 -15 14 68 40 0
3 -15 14 104 136 204
4 -15 14 104 136 204
5 -15 14 104 136 204
6 -15 14 104 136 204
7 -15 14 104 136 204
8 -15 14 104 136 204
9 -15 14 104 136 204
10 -15 14 104 136 204
11 -15 14 104 136 204
12 -15 14 104 136 204
13 -15 14 104 136 204
14 -15 14 68 40 0
-15 -14 14 252 252 104
14 -14 14 252 252 104
-15 -13 14 252 252 104
14 -13 14 252 252 104
-15 -12 14 252 252 104
14 -12 14 252 252 104
-15 -11 14 252 252 104
14 -11 14 252 252 104
-15 -10 14 252 252 104
-10 -10 14 236 236 236
-9 -10 14 236 236 236
-8 -10 14 236 236 236
-7 -10 14 236 236 236
6 -10 14 236 236 236
7 -10 14 236 236 236
8 -10 14 236 236 236
9 -10 14 236 236 236
14 -10 14 252 252 104
-15 -9 14 252 252 104
-10 -9 14 236 236 236
-9 -9 14 236 236 236
-8 -9 14 236 236 236
-7 -9 14 236 236 236
6 -9 14 236 236 236
7 -9 14 236 236 236
8 -9 14 236 236 236
9 -9 14 236 236 236
14 -9 14 252 252 104
-15 -8 14 252 252 104
-10 -8 14 236 236 236
-9 -8 14 236 236 236
-8 -8 14 236 236 236
-7 -8 14 236 236 236
6 -8 14 236 236 236
7 -8 14 236 236 236
8 -8 14 236 236 236
9 -8 14 236 236 236
14 -8 14 252 252 104
-15 -7 14 252 252 104
-10 -7 14 236 236 236
-9 -7 14 236 236 236
-8 -7 14 236 236 236
-7 -7 14 236 236 236
6 -7 14 236 236 236
7 -7 14 236 236 236
8 -7 14 236 236 236
9 -7 14 236 236 236
14 -7 14 252 252 104
-15 -6 14 252 252 104
14 -6 14 252 252 104
-15 -5 14 252 252 104
14 -5 14 252 252 104
-15 -4 14 252 252 104
14 -4 14 252 252 104
-15 -3 14 68 40 0
14 -3 14 68 40 0
-15 2 14 68 40 0
14 2 14 68 40 0
-15 3 14 252 252 104
14 3 14 252 252 104
-15 4 14 252 252 104
14 4 14 252 252 104
-15 5 14 252 252 104
14 5 14 252 252 104
-15 6 14 252 252 104
-10 6 14 236 236 236
-9 6 14 236 236 236
-8 6 14 236 236 236
-7 6 14 236 236 236
6 6 14 236 236 236
7 6 14 236 236 236
8 6 14 236 236 236
9 6 14 236 236 236
14 6 14 252 252 104
-15 7 14 252 252 104
-10 7 14 236 236 236
-9 7 14 236 236 236
-8 7 14 236 236 236
-7 7 14 236 236 236
6 7 14 236 236 236
7 7 14 236 236 236
8 7 14 236 236 236
9 7 14 236 236 236
14 7 14 252 252 104
-15 8 14 252 252 104
-10 8 14 236 236 236
-9 8 14 236 236 236
-8 8 14 236 236 236
-7 8 14 236 236 236
6 8 14 236 236 236
7 8 14 236 236 236
8 8 14 236 236 236
9 8 14 236 236 236
14 8 14 252 252 104
-15 9 14 252 252 104
-10 9 14 236 236 236
-9 9 14 236 236 236
-8 9 14 236 236 236
-7 9 14 236 236 236
6 9 14 236 236 236
7 9 14 236 236 236
8 9 14 236 236 236
9 9 14 236 236 236
14 9 14 252 252 104
-15 10 14 252 252 104
14 10 14 252 252 104
-15 11 14 252 252 104
14 11 14 252 252 104
-15 12 14 252 252 104
14 12 14 252 252 104
-15 13 14 252 252 104
14 13 14 252 252 104
-15 14 14 68 40 0
-14 14 14 104 136 204
-13 14 14 104 136 204
-12 14 14 104 136 204
-11 14 14 104 136 204
-10 14 14 104 136 204
-9 14 14 104 136 204
-8 14 14 104 136 204
-7 14 14 104 136 204
-6 14 14 104 136 204
-5 14 14 104 136 204
-4 14 14 104 136 204
-3 14 14 68 40 0
2 14 14 68 40 0
3 14 14 104 136 204
4 14 14 104 136 204
5 14 14 104 136 204
6 14 14 104 136 204
7 14 14 104 136 204
8 14 14 104 136 204
9 14 14 104 136 204
10 14 14 104 136 204
11 14 14 104 136 204
12 14 14 104 136 204
13 14 14 104 136 204
14 14 14 68 40 0
-15 -15 15 68 40 0
-14 -15 15 104 136 204
-13 -15 15 104 136 204
-12 -15 15 104 136 204
-11 -15 15 104 136 204
-10 -15 15 104 136 204
-9 -15 15 104 136 204
-8 -15 15 104 136 204
-7 -15 15 104 136 204
-6 -15 15 104 136 204
-5 -15 15 104 136 204
-4 -15 15 104 136 204
-3 -15 15 68 40 0
2 -15 15 68 40 0
3 -15 15 104 136 204
4 -15 15 104 136 204
5 -15 15 104 136 204
6 -15 15 104 136 204
7 -15 15 104 136 204
8 -15 15 104 136 204
9 -15 15 104 136 204
10 -15 15 104 136 204
11 -15 15 104 136 204
12 -15 15 104 136 204
13 -15 15 104 136 204
14 -15 15 68 40 0
-15 -14 15 252 252 104
14 -14 15 252 252 104
-15 -13 15 252 252 104
14 -13 15 252 252 104
-15 -12 15 252 252 104
14 -12 15 252 252 104
-15 -11 15 252 252 104
14 -11 15 252 252 104
-15 -10 15 252 252 104
-10 -10 15 236 236 236
-9 -10 15 236 236 236
-8 -10 15 236 236 236
-7 -10 15 236 236 236
6 -10 15 236 236 236
7 -10 15 236 236 236
8 -10 15 236 236 236
9 -10 15 236 236 236
14 -10 15 252 252 104
-15 -9 15 252 252 104
-10 -9 15 236 236 236
-9 -9 15 236 236 236
-8 -9 15 236 236 236
-7 -9 15 236 236 236
6 -9 15 236 236 236
7 -9 15 236 236 236
8 -9 15 236 236 236
9 -9 15 236 236 236
14 -9 15 252 252 104
-15 -8 15 252 252 104
-10 -8 15 236 236 236
-9 -8 15 236 236 236
-8 -8 15 236 236 236
-7 -8 15 236 236 236
6 -8 15 236 236 236
7 -8 15 236 236 236
8 -8 15 236 236 236
9 -8 15 236 236 236
14 -8 15 252 252 104
-15 -7 15 252 252 104
-10 -7 15 236 236 236
-9 -7 15 236 236 236
-8 -7 15 236 236 236
-7 -7 15 236 236 236
6 -7 15 236 236 236
7 -7 15 236 236 236
8 -7 15 236 236 236
9 -7 15 236 236 236
14 -7 15 252 252 104
-15 -6 15 252 252 104
14 -6 15 252 252 104
-15 -5 15 252 252 104
14 -5 15 252 252 104
-15 -4 15 252 252 104
14 -4 15 252 252 104
-15 -3 15 68 40 0
14 -3 15 68 40 0
-15 2 15 68 40 0
14 2 15 68 40 0
-15 3 15 252 252 104
14 3 15 252 252 104
-15 4 15 252 252 104
14 4 15 252 252 104
-15 5 15 252 252 104
14 5 15 252 252 104
-15 6 15 252 252 104
-10 6 15 236 236 236
-9 6 15 236 236 236
-8 6 15 236 236 236
-7 6 15 236 236 236
6 6 15 236 236 236
7 6 15 236 236 236
8 6 15 236 236 236
9 6 15 236 236 236
14 6 15 252 252 104
-15 7 15 252 252 104
-10 7 15 236 236 236
-9 7 15 236 236 236
-8 7 15 236 236 236
-7 7 15 236 236 236
6 7 15 236 236 236
7 7 15 236 236 236
8 7 15 236 236 236
9 7 15 236 236 236
14 7 15 252 252 104
-15 8 15 252 252 104
-10 8 15 236 236 236
-9 8 15 236 236 236
-8 8 15 236 236 236
-7 8 15 236 236 236
6 8 15 236 236 236
7 8 15 236 236 236
8 8 15 236 236 236
9 8 15 236 236 236
14 8 15 252 252 104
-15 9 15 252 252 104
-10 9 15 236 236 236
-9 9 15 236 236 236
-8 9 15 236 236 236
-7 9 15 236 236 236
6 9 15 236 236 236
7 9 15 236 236 236
8 9 15 236 236 236
9 9 15 236 236 236
14 9 15 252 252 104
-15 10 15 252 252 104
14 10 15 252 252 104
-15 11 15 252 252 104
14 11 15 252 252 104
-15 12 15 252 252 104
14 12 15 252 252 104
-15 13 15 252 252 104
14 13 15 252 252 104
-15 14 15 68 40 0
-14 14 15 104 136 204
-13 14 15 104 136 204
-12 14 15 104 136 204
-11 14 15 104 136 204
-10 14 15 104 136 204
-9 14 15 104 136 204
-8 14 15 104 136 204
-7 14 15 104 136 204
-6 14 15 104 136 204
-5 14 15 104 136 204
-4 14 15 104 136 204
-3 14 15 68 40 0
2 14 15 68 40 0
3 14 15 104 136 204
4 14 15 104 136 204
5 14 15 104 136 204
6 14 15 104 136 204
7 14 15 104 136 204
8 14 15 104 136 204
9 14 15 104 136 204
10 14 15 104 136 204
11 14 15 104 136 204
12 14 15 104 136 204
13 14 15 104 136 204
14 14 15 68 40 0
-15 -15 16 68 40 0
-14 -15 16 104 136 204
-13 -15 16 104 136 204
-12 -15 16 104 136 204
-11 -15 16 104 136 204
-10 -15 16 104 136 204
-9 -15 16 104 136 204
-8 -15 16 104 136 204
-7 -15 16 104 136 204
-6 -15 16 104 136 204
-5 -15 16 104 136 204
-4 -15 16 104 136 204
-3 -15 16 68 40 0
-2 -15 16 68 40 0
-1 -15 16 68 40 0
0 -15 16 68 40 0
1 -15 16 68 40 0
2 -15 16 68 40 0
3 -15 16 104 136 204
4 -15 16 104 136 204
5 -15 16 104 136 204
6 -15 16 104 136 204
7 -15 16 104 136 204
8 -15 16 104 136 204
9 -15 16 104 136 204
10 -15 16 104 136 204
11 -15 16 104 136 204
12 -15 16 104 136 204
13 -15 16 104 136 204
14 -15 16 68 40 0
-15 -14 16 252 252 104
14 -14 16 252 252 104
-15 -13 16 252 252 104
14 -13 16 252 252 104
-15 -12 16 252 252 104
14 -12 16 252 252 104
-15 -11 16 252 252 104
14 -11 16 252 252 104
-15 -10 16 252 252 104
-10 -10 16 236 236 236
-9 -10 16 236 236 236
-8 -10 16 236 236 236
-7 -10 16 236 236 236
6 -10 16 236 236 236
7 -10 16 236 236 236
8 -10 16 236 236 236
9 -10 16 236 236 236
14 -10 16 252 252 104
-15 -9 16 252 252 104
-10 -9 16 236 236 236
-9 -9 16 236 236 236
-8 -9 16 236 236 236
-7 -9 16 236 236 236
6 -9 16 236 236 236
7 -9 16 236 236 236
8 -9 16 236 236 236
9 -9 16 236 236 236
14 -9 16 252 252 104
-15 -8 16 252 252 104
-10 -8 16 236 236 236
-9 -8 16 236 236 236
-8 -8 16 236 236 236
-7 -8 16 236 236 236
6 -8 16 236 236 236
7 -8 16 236 236 236
8 -8 16 236 236 236
9 -8 16 236 236 236
14 -8 16 252 252 104
-15 -7 16 252 252 104
-10 -7 16 236 236 236
-9 -7 16 236 236 236
-8 -7 16 236 236 236
-7 -7 16 236 236 236
6 -7 16 236 236 236
7 -7 16 236 236 236
8 -7 16 236 236 236
9 -7 16 236 236 236
14 -7 16 252 252 104
-15 -6 16 252 252 104
14 -6 16 252 252 104
-15 -5 16 252 252 104
14 -5 16 252 252 104
-15 -4 16 252 252 104
14 -4 16 252 252 104
-15 -3 16 68 40 0
14 -3 16 68 40 0
-15 -2 16 68 40 0
14 -2 16 68 40 0
-15 -1 16 68 40 0
14 -1 16 68 40 0
-15 0 16 68 40 0
14 0 16 68 40 0
-15 1 16 68 40 0
14 1 16 68 40 0
-15 2 16 68 40 0
14 2 16 68 40 0
-15 3 16 252 252 104
14 3 16 252 252 104
-15 4 16 252 252 104
14 4 16 252 252 104
-15 5 16 252 252 104
14 5 16 252 252 104
-15 6 16 252 252 104
-10 6 16 236 236 236
-9 6 16 236 236 236
-8 6 16 236 236 236
-7 6 16 236 236 236
6 6 16 236 236 236
7 6 16 236 236 236
8 6 16 236 236 236
9 6 16 236 236 236
14 6 16 252 252 104
-15 7 16 252 252 104
-10 7 16 236 236 236
-9 7 16 236 236 236
-8 7 16 236 236 236
-7 7 16 236 236 236
6 7 16 236 236 236
7 7 16 236 236 236
8 7 16 236 236 236
9 7 16 236 236 236
14 7 16 252 252 104
-15 8 16 252 252 104
-10 8 16 236 236 236
-9 8 16 236 236 236
-8 8 16 236 236 236
-7 8 16 236 236 236
6 8 16 236 236 236
7 8 16 236 236 236
8 8 16 236 236 236
9 8 16 236 236 236
14 8 16 252 252 104
-15 9 16 252 252 104
-10 9 16 236 236 236
-9 9 16 236 236 236
-8 9 16 236 236 236
-7 9 16 236 236 236
6 9 16 236 236 236
7 9 16 236 236 236
8 9 16 236 236 236
9 9 16 236 236 236
14 9 16 252 252 104
-15 10 16 252 252 104
14 10 16 252 252 104
-15 11 16 252 252 104
14 11 16 252 252 104
-15 12 16 252 252 104
14 12 16 252 252 104
-15 13 16 252 252 104
14 13 16 252 252 104
-15 14 16 68 40 0
-14 14 16 104 136 204
-13 14 16 104 136 204
-12 14 16 104 136 204
-11 14 16 104 136 204
-10 14 16 104 136 204
-9 14 16 104 136 204
-8 14 16 104 136 204
-7 14 16 104 136 204
-6 14 16 104 136 204
-5 14 16 104 136 204
-4 14 16 104 136 204
-3 14 16 68 40 0
-2 14 16 68 40 0
-1 14 16 68 40 0
0 14 16 68 40 0
1 14 16 68 40 0
2 14 16 68 40 0
3 14 16 104 136 204
4 14 16 104 136 204
5 14 16 104 136 204
6 14 16 104 136 204
7 14 16 104 136 204
8 14 16 104 136 204
9 14 16 104 136 204
10 14 16 104 136 204
11 14 16 104 136 204
12 14 16 104 136 204
13 14 16 104 136 204
14 14 16 68 40 0
-15 -15 17 68 40 0
-14 -15 17 104 136 204
-13 -15 17 104 136 204
-12 -15 17 104 136 204
-11 -15 17 104 136 204
-10 -15 17 104 136 204
-9 -15 17 104 136 204
-8 -15 17 104 136 204
-7 -15 17 104 136 204
-6 -15 17 104 136 204
-5 -15 17 104 136 204
-4 -15 17 104 136 204
-3 -15 17 68 40 0
2 -15 17 68 40 0
3 -15 17 104 136 204
4 -15 17 104 136 204
5 -15 17 104 136 204
6 -15 17 104 136 204
7 -15 17 104 136 204
8 -15 17 104 136 204
9 -15 17 104 136 204
10 -15 17 104 136 204
11 -15 17 104 136 204
12 -15 17 104 136 204
13 -15 17 104 136 204
14 -15 17 68 40 0
-15 -14 17 252 252 104
14 -14 17 252 252 104
-15 -13 17 252 252 104
14 -13 17 252 252 104
-15 -12 17 252 252 104
14 -12 17 252 252 104
-15 -11 17 252 252 104
14 -11 17 252 252 104
-15 -10 17 252 252 104
-10 -10 17 236 236 236
-9 -10 17 236 236 236
-8 -10 17 236 236 236
-7 -10 17 236 236 236
6 -10 17 236 236 236
7 -10 17 236 236 236
8 -10 17 236 236 236
9 -10 17 236 236 236
14 -10 17 252 252 104
-15 -9 17 252 252 104
-10 -9 17 236 236 236
-9 -9 17 236 236 236
-8 -9 17 236 236 236
-7 -9 17 236 236 236
6 -9 17 236 236 236
7 -9 17 236 236 236
8 -9 17 236 236 236
9 -9 17 236 236 236
14 -9 17 252 252 104
-15 -8 17 252 252 104
-10 -8 17 236 236 236
-9 -8 17 236 236 236
-8 -8 17 236 236 236
-7 -8 17 236 236 236
6 -8 17 236 236 236
7 -8 17 236 236 236
8 -8 17 236 236 236
9 -8 17 236 236 236
14 -8 17 252 252 104
-15 -7 17 252 252 104
-10 -7 17 236 236 236
-9 -7 17 236 236 236
-8 -7 17 236 236 236
-7 -7 17 236 236 236
6 -7 17 236 236 236
7 -7 17 236 236 236
8 -7 17 236 236 236
9 -7 17 236 236 236
14 -7 17 252 252 104
-15 -6 17 252 252 104
14 -6 17 252 252 104
-15 -5 17 252 252 104
14 -5 17 252 252 104
-15 -4 17 252 252 104
14 -4 17 252 252 104
-15 -3 17 68 40 0
14 -3 17 68 40 0
-15 2 17 68 40 0
14 2 17 68 40 0
-15 3 17 252 252 104
14 3 17 252 252 104
-15 4 17 252 252 104
14 4 17 252 252 104
-15 5 17 252 252 104
14 5 17 252 252 104
-15 6 17 252 252 104
-10 6 17 236 236 236
-9 6 17 236 236 236
-8 6 17 236 236 236
-7 6 17 236 236 236
6 6 17 236 236 236
7 6 17 236 236 236
8 6 17 236 236 236
9 6 17 236 236 236
14 6 17 252 252 104
-15 7 17 252 252 104
-10 7 17 236 236 236
-9 7 17 236 236 236
-8 7 17 236 236 236
-7 7 17 236 236 236
6 7 17 236 236 236
7 7 17 236 236 236
8 7 17 236 236 236
9 7 17 236 236 236
14 7 17 252 252 104
-15 8 17 252 252 104
-10 8 17 236 236 236
-9 8 17 236 236 236
-8 8 17 236 236 236
-7 8 17 236 236 236
6 8 17 236 236 236
7 8 17 236 236 236
8 8 17 236 236 236
9 8 17 236 236 236
14 8 17 252 252 104
-15 9 17 252 252 104
-10 9 17 236 236 236
-9 9 17 236 236 236
-8 9 17 236 236 236
-7 9 17 236 236 236
6 9 17 236 236 236
7 9 17 236 236 236
8 9 17 236 236 236
9 9 17 236 236 236
14 9 17 252 252 104
-15 10 17 252 252 104
14 10 17 252 252 104
-15 11 17 252 252 104
14 11 17 252 252 104
-15 12 17 252 252 104
14 12 17 252 252 104
-15 13 17 252 252 104
14 13 17 252 252 104
-15 14 17 68 40 0
-14 14 17 104 136 204
-13 14 17 104 136 204
-12 14 17 104 136 204
-11 14 17 104 136 204
-10 14 17 104 136 204
-9 14 17 104 136 204
-8 14 17 104 136 204
-7 14 17 104 136 204
-6 14 17 104 136 204
-5 14 17 104 136 204
-4 14 17 104 136 204
-3 14 17 68 40 0
2 14 17 68 40 0
3 14 17 104 136 204
4 14 17 104 136 204
5 14 17 104 136 204
6 14 17 104 136 204
7 14 17 104 136 204
8 14 17 104 136 204
9 14 17 104 136 204
10 14 17 104 136 204
11 14 17 104 136 204
12 14 17 104 136 204
13 14 17 104 136 204
14 14 17 68 40 0
-15 -15 18 68 40 0
-14 -15 18 104 136 204
-13 -15 18 104 136 204
-12 -15 18 104 136 204
-11 -15 18 104 136 204
-10 -15 18 104 136 204
-9 -15 18 104 136 204
-8 -15 18 104 136 204
-7 -15 18 104 136 204
-6 -15 18 104 136 204
-5 -15 18 104 136 204
-4 -15 18 104 136 204
-3 -15 18 68 40 0
2 -15 18 68 40 0
3 -15 18 104 136 204
4 -15 18 104 136 204
5 -15 18 104 136 204
6 -15 18 104 136 204
7 -15 18 104 136 204
8 -15 18 104 136 204
9 -15 18 104 136 204
10 -15 18 104 136 204
11 -15 18 104 136 204
12 -15 18 104 136 204
13 -15 18 104 136 204
14 -15 18 68 40 0
-15 -14 18 252 252 104
14 -14 18 252 252 104
-15 -13 18 252 252 104
14 -13 18 252 252 104
-15 -12 18 252 252 104
14 -12 18 252 252 104
-15 -11 18 252 252 104
14 -11 18 252 252 104
-15 -10 18 252 252 104
-10 -10 18 236 236 236
-9 -10 18 236 236 236
-8 -10 18 236 236 236
-7 -10 18 236 236 236
6 -10 18 236 236 236
7 -10 18 236 236 236
8 -10 18 236 236 236
9 -10 18 236 236 236
14 -10 18 252 252 104
-15 -9 18 252 252 104
-10 -9 18 236 236 236
-9 -9 18 236 236 236
-8 -9 18 236 236 236
-7 -9 18 236 236 236
6 -9 18 236 236 236
7 -9 18 236 236 236
8 -9 18 236 236 236
9 -9 18 236 236 236
14 -9 18 252 252 104
-15 -8 18 252 252 104
-10 -8 18 236 236 236
-9 -8 18 236 236 236
-8 -8 18 236 236 236
-7 -8 18 236 236 236
6 -8 18 236 236 236
7 -8 18 236 236 236
8 -8 18 236 236 236
9 -8 18 236 236 236
14 -8 18 252 252 104
-15 -7 18 252 252 104
-10 -7 18 236 236 236
-9 -7 18 236 236 236
-8 -7 18 236 236 236
-7 -7 18 236 236 236
6 -7 18 236 236 236
7 -7 18 236 236 236
8 -7 18 236 236 236
9 -7 18 236 236 236
14 -7 18 252 252 104
-15 -6 18 252 252 104
14 -6 18 252 252 104
-15 -5 18 252 252 104
14 -5 18 252 252 104
-15 -4 18 252 252 104
14 -4 18 252 252 104
-15 -3 18 68 40 0
14 -3 18 68 40 0
-15 2 18 68 40 0
14 2 18 68 40 0
-15 3 18 252 252 104
14 3 18 252 252 104
-15 4 18 252 252 104
14 4 18 252 252 104
-15 5 18 252 252 104
14 5 18 252 252 104
-15 6 18 252 252 104
-10 6 18 236 236 236
-9 6 18 236 236 236
-8 6 18 236 236 236
-7 6 18 236 236 236
6 6 18 236 236 236
7 6 18 236 236 236
8 6 18 236 236 236
9 6 18 236 236 236
14 6 18 252 252 104
-15 7 18 252 252 104
-10 7 18 236 236 236
-9 7 18 236 236 236
-8 7 18 236 236 236
-7 7 18 236 236 236
6 7 18 236 236 236
7 7 18 236 236 236
8 7 18 236 236 236
9 7 18 236 236 236
14 7 18 252 252 104
-15 8 18 252 252 104
-10 8 18 236 236 236
-9 8 18 236 236 236
-8 8 18 236 236 236
-7 8 18 236 236 236
6 8 18 236 236 236
7 8 18 236 236 236
8 8 18 236 236 236
9 8 18 236 236 236
14 8 18 252 252 104
-15 9 18 252 252 104
-10 9 18 236 236 236
-9 9 18 236 236 236
-8 9 18 236 236 236
-7 9 18 236 236 236
6 9 18 236 236 236
7 9 18 236 236 236
8 9 18 236 236 236
9 9 18 236 236 236
14 9 18 252 252 104
-15 10 18 252 252 104
14 10 18 252 252 104
-15 11 18 252 252 104
14 11 18 252 252 104
-15 12 18 252 252 104
14 12 18 252 252 104
-15 13 18 252 252 104
14 13 18 252 252 104
-15 14 18 68 40 0
-14 14 18 104 136 204
-13 14 18 104 136 204
-12 14 18 104 136 204
-11 14 18 104 136 204
-10 14 18 104 136 204
-9 14 18 104 136 204
-8 14 18 104 136 204
-7 14 18 104 136 204
-6 14 18 104 136 204
-5 14 18 104 136 204
-4 14 18 104 136 204
-3 14 18 68 40 0
2 14 18 68 40 0
3 14 18 104 136 204
4 14 18 104 136 204
5 14 18 104 136 204
6 14 18 104 136 204
7 14 18 104 136 204
8 14 18 104 136 204
9 14 18 104 136 204
10 14 18 104 136 204
11 14 18 104 136 204
12 14 18 104 136 204
13 14 18 104 136 204
14 14 18 68 40 0
-15 -15 19 68 40 0
-14 -15 19 68 40 0
-13 -15 19 68 40 0
-12 -15 19 68 40 0
-11 -15 19 68 40 0
-10 -15 19 68 40 0
-9 -15 19 68 40 0
-8 -15 19 68 40 0
-7 -15 19 68 40 0
-6 -15 19 68 40 0
-5 -15 19 68 40 0
-4 -15 19 68 40 0
-3 -15 19 68 40 0
-2 -15 19 68 40 0
-1 -15 19 68 40 0
0 -15 19 68 40 0
1 -15 19 68 40 0
2 -15 19 68 40 0
3 -15 19 68 40 0
4 -15 19 68 40 0
5 -15 19 68 40 0
6 -15 19 68 40 0
7 -15 19 68 40 0
8 -15 19 68 40 0
9 -15 19 68 40 0
10 -15 19 68 40 0
11 -15 19 68 40 0
12 -15 19 68 40 0
13 -15 19 68 40 0
14 -15 19 68 40 0
-15 -14 19 68 40 0
-14 -14 19 68 40 0
-13 -14 19 68 40 0
-12 -14 19 68 40 0
-11 -14 19 68 40 0
-10 -14 19 68 40 0
-9 -14 19 68 40 0
-8 -14 19 68 40 0
-7 -14 19 68 40 0
-6 -14 19 68 40 0
-5 -14 19 68 40 0
-4 -14 19 68 40 0
-3 -14 19 68 40 0
-2 -14 19 68 40 0
-1 -14 19 68 40 0
0 -14 19 68 40 0
1 -14 19 68 40 0
2 -14 19 68 40 0
3 -14 19 68 40 0
4 -14 19 68 40 0
5 -14 19 68 40 0
6 -14 19 68 40 0
7 -14 19 68 40 0
8 -14 19 68 40 0
9 -14 19 68 40 0
10 -14 19 68 40 0
11 -14 19 68 40 0
12 -14 19 68 40 0
13 -14 19 68 40 0
14 -14 19 68 40 0
-15 -13 19 68 40 0
-14 -13 19 68 40 0
-13 -13 19 68 40 0
-12 -13 19 68 40 0
-11 -13 19 68 40 0
-10 -13 19 68 40 0
-9 -13 19 68 40 0
-8 -13 19 68 40 0
-7 -13 19 68 40 0
-6 -13 19 68 40 0
-5 -13 19 68 40 0
-4 -13 19 68 40 0
-3 -13 19 68 40 0
-2 -13 19 68 40 0
-1 -13 19 68 40 0
0 -13 19 68 40 0
1 -13 19 68 40 0
2 -13 19 68 40 0
3 -13 19 68 40 0
4 -13 19 68 40 0
5 -13 19 68 40 0
6 -13 19 68 40 0
7 -13 19 68 40 0
8 -13 19 68 40 0
9 -13 19 68 40 0
10 -13 19 68 40 0
11 -13 19 68 40 0
12 -13 19 68 40 0
13 -13 19 68 40 0
14 -13 19 68 40 0
-15 -12 19 68 40 0
-14 -12 19 68 40 0
-13 -12 19 68 40 0
-12 -12 19 68 40 0
-11 -12 19 68 40 0
-10 -12 19 68 40 0
-9 -12 19 68 40 0
-8 -12 19 68 40 0
-7 -12 19 68 40 0
-6 -12 19 68 40 0
-5 -12 19 68 40 0
-4 -12 19 68 40 0
-3 -12 19 68 40 0
-2 -12 19 68 40 0
-1 -12 19 68 40 0
0 -12 19 68 40 0
1 -12 19 68 40 0
2 -12 19 68 40 0
3 -12 19 68 40 0
4 -12 19 68 40 0
5 -12 19 68 40 0
6 -12 19 68 40 0
7 -12 19 68 40 0
8 -12 19 68 40 0
9 -12 19 68 40 0
10 -12 19 68 40 0
11 -12 19 68 40 0
12 -12 19 68 40 0
13 -12 19 68 40 0
14 -12 19 68 40 0
-15 -11 19 68 40 0
-14 -11 19 68 40 0
-13 -11 19 68 40 0
-12 -11 19 68 40 0
-11 -11 19 68 40 0
-10 -11 19 68 40 0
-9 -11 19 68 40 0
-8 -11 19 68 40 0
-7 -11 19 68 40 0
-6 -11 19 68 40 0
-5 -11 19 68 40 0
-4 -11 19 68 40 0
-3 -11 19 68 40 0
-2 -11 19 68 40 0
-1 -11 19 68 40 0
0 -11 19 68 40 0
1 -11 19 68 40 0
2 -11 19 68 40 0
3 -11 19 68 40 0
4 -11 19 68 40 0
5 -11 19 68 40 0
6 -11 19 68 40 0
7 -11 19 68 40 0
8 -11 19 68 40 0
9 -11 19 68 40 0
10 -11 19 68 40 0
11 -11 19 68 40 0
12 -11 19 68 40 0
13 -11 19 68 40 0
14 -11 19 68 40 0
-15 -10 19 68 40 0
-14 -10 19 68 40 0
-13 -10 19 68 40 0
-12 -10 19 68 40 0
-11 -10 19 68 40 0
-10 -10 19 68 40 0
-9 -10 19 68 40 0
-8 -10 19 68 40 0
-7 -10 19 68 40 0
-6 -10 19 68 40 0
-5 -10 19 68 40 0
-4 -10 19 68 40 0
-3 -10 19 68 40 0
-2 -10 19 68 40 0
-1 -10 19 68 40 0
0 -10 19 68 40 0
1 -10 19 68 40 0
2 -10 19 68 40 0
3 -10 19 68 40 0
4 -10 19 68 40 0
5 -10 19 68 40 0
6 -10 19 68 40 0
7 -10 19 68 40 0
8 -10 19 68 40 0
9 -10 19 68 40 0
10 -10 19 68 40 0
11 -10 19 68 40 0
12 -10 19 68 40 0
13 -10 19 68 40 0
14 -10 19 68 40 0
-15 -9 19 68 40 0
-14 -9 19 68 40 0
-13 -9 19 68 40 0
-12 -9 19 68 40 0
-11 -9 19 68 40 0
-10 -9 19 68 40 0
-9 -9 19 68 40 0
-8 -9 19 68 40 0
-7 -9 19 68 40 0
-6 -9 19 68 40 0
-5 -9 19 68 40 0
-4 -9 19 68 40 0
-3 -9 19 68 40 0
-2 -9 19 68 40 0
-1 -9 19 68 40 0
0 -9 19 68 40 0
1 -9 19 68 40 0
2 -9 19 68 40 0
3 -9 19 68 40 0
4 -9 19 68 40 0
5 -9 19 68 40 0
6 -9 19 68 40 0
7 -9 19 68 40 0
8 -9 19 68 40 0
9 -9 19 68 40 0
10 -9 19 68 40 0
11 -9 19 68 40 0
12 -9 19 68 40 0
13 -9 19 68 40 0
14 -9 19 68 40 0
-15 -8 19 68 40 0
-14 -8 19 68 40 0
-13 -8 19 68 40 0
-12 -8 19 68 40 0
-11 -8 19 68 40 0
-10 -8 19 68 40 0
-9 -8 19 68 40 0
-8 -8 19 68 40 0
-7 -8 19 68 40 0
-6 -8 19 68 40 0
-5 -8 19 68 40 0
-4 -8 19 68 40 0
-3 -8 19 68 40 0
-2 -8 19 68 40 0
-1 -8 19 68 40 0
0 -8 19 68 40 0
1 -8 19 68 40 0
2 -8 19 68 40 0
3 -8 19 68 40 0
4 -8 19 68 40 0
5 -8 19 68 40 0
6 -8 19 68 40 0
7 -8 19 68 40 0
8 -8 19 68 40 0
9 -8 19 68 40 0
10 -8 19 68 40 0
11 -8 19 68 40 0
12 -8 19 68 40 0
13 -8 19 68 40 0
14 -8 19 68 40 0
-15 -7 19 68 40 0
-14 -7 19 68 40 0
-13 -7 19 68 40 0
-12 -7 19 68 40 0
-11 -7 19 68 40 0
-10 -7 19 68 40 0
-9 -7 19 68 40 0
-8 -7 19 68 40 0
-7 -7 19 68 40 0
-6 -7 19 68 40 0
-5 -7 19 68 40 0
-4 -7 19 68 40 0
-3 -7 19 68 40 0
-2 -7 19 68 40 0
-1 -7 19 68 40 0
0 -7 19 68 40 0
1 -7 19 68 40 0
2 -7 19 68 40 0
3 -7 19 68 40 0
4 -7 19 68 40 0
5 -7 19 68 40 0
6 -7 19 68 40 0
7 -7 19 68 40 0
8 -7 19 68 40 0
9 -7 19 68 40 0
10 -7 19 68 40 0
11 -7 19 68 40 0
12 -7 19 68 40 0
13 -7 19 68 40 0
14 -7 19 68 40 0
-15 -6 19 68 40 0
-14 -6 19 68 40 0
-13 -6 19 68 40 0
-12 -6 19 68 40 0
-11 -6 19 68 40 0
-10 -6 19 68 40 0
-9 -6 19 68 40 0
-8 -6 19 68 40 0
-7 -6 19 68 40 0
-6 -6 19 68 40 0
-5 -6 19 68 40 0
-4 -6 19 68 40 0
-3 -6 19 68 40 0
-2 -6 19 68 40 0
-1 -6 19 68 40 0
0 -6 19 68 40 0
1 -6 19 68 40 0
2 -6 19 68 40 0
3 -6 19 68 40 0
4 -6 19 68 40 0
5 -6 19 68 40 0
6 -6 19 68 40 0
7 -6 19 68 40 0
8 -6 19 68 40 0
9 -6 19 68 40 0
10 -6 19 68 40 0
11 -6 19 68 40 0
12 -6 19 68 40 0
13 -6 19 68 40 0
14 -6 19 68 40 0
-15 -5 19 68 40 0
-14 -5 19 68 40 0
-13 -5 19 68 40 0
-12 -5 19 68 40 0
-11 -5 19 68 40 0
-10 -5 19 68 40 0
-9 -5 19 68 40 0
-8 -5 19 68 40 0
-7 -5 19 68 40 0
-6 -5 19 68 40 0
-5 -5 19 68 40 0
-4 -5 19 68 40 0
-3 -5 19 68 40 0
-2 -5 19 68 40 0
-1 -5 19 68 40 0
0 -5 19 68 40 0
1 -5 19 68 40 0
2 -5 19 68 40 0
3 -5 19 68 40 0
4 -5 19 68 40 0
5 -5 19 68 40 0
6 -5 19 68 40 0
7 -5 19 68 40 0
8 -5 19 68 40 0
9 -5 19 68 40 0
10 -5 19 68 40 0
11 -5 19 68 40 0
12 -5 19 68 40 0
13 -5 19 68 40 0
14 -5 19 68 40 0
-15 -4 19 68 40 0
-14 -4 19 68 40 0
-13 -4 19 68 40 0
-12 -4 19 68 40 0
-11 -4 19 68 40 0
-10 -4 19 68 40 0
-9 -4 19 68 40 0
-8 -4 19 68 40 0
-7 -4 19 68 40 0
-6 -4 19 68 40 0
-5 -4 19 68 40 0
-4 -4 19 68 40 0
-3 -4 19 68 40 0
-2 -4 19 68 40 0
-1 -4 19 68 40 0
0 -4 19 68 40 0
1 -4 19 68 40 0
2 -4 19 68 40 0
3 -4 19 68 40 0
4 -4 19 68 40 0
5 -4 19 68 40 0
6 -4 19 68 40 0
7 -4 19 68 40 0
8 -4 19 68 40 0
9 -4 19 68 40 0
10 -4 19 68 40 0
11 -4 19 68 40 0
12 -4 19 68 40 0
13 -4 19 68 40 0
14 -4 19 68 40 0
-15 -3 19 68 40 0
-14 -3 19 68 40 0
-13 -3 19 68 40 0
-12 -3 19 68 40 0
-11 -3 19 68 40 0
-10 -3 19 68 40 0
-9 -3 19 68 40 0
-8 -3 19 68 40 0
-7 -3 19 68 40 0
-6 -3 19 68 40 0
-5 -3 19 68 40 0
-4 -3 19 68 40 0
-3 -3 19 68 40 0
-2 -3 19 68 40 0
-1 -3 19 68 40 0
0 -3 19 68 40 0
1 -3 19 68 40 0
2 -3 19 68 40 0
3 -3 19 68 40 0
4 -3 19 68 40 0
5 -3 19 68 40 0
6 -3 19 68 40 0
7 -3 19 68 40 0
8 -3 19 68 40 0
9 -3 19 68 40 0
10 -3 19 68 40 0
11 -3 19 68 40 0
12 -3 19 68 40 0
13 -3 19 68 40 0
14 -3 19 68 40 0
-15 -2 19 68 40 0
-14 -2 19 68 40 0
-13 -2 19 68 40 0
-12 -2 19 68 40 0
-11 -2 19 68 40 0
-10 -2 19 68 40 0
-9 -2 19 68 40 0
-8 -2 19 68 40 0
-7 -2 19 68 40 0
-6 -2 19 68 40 0
-5 -2 19 68 40 0
-4 -2 19 68 40 0
-3 -2 19 68 40 0
-2 -2 19 68 40 0
-1 -2 19 68 40 0
0 -2 19 68 40 0
1 -2 19 68 40 0
2 -2 19 68 40 0
3 -2 19 68 40 0
4 -2 19 68 40 0
5 -2 19 68 40 0
6 -2 19 68 40 0
7 -2 19 68 40 0
8 -2 19 68 40 0
9 -2 19 68 40 0
10 -2 19 68 40 0
11 -2 19 68 40 0
12 -2 19 68 40 0
13 -2 19 68 40 0
14 -2 19 68 40 0
-15 -1 19 68 40 0
-14 -1 19 68 40 0
-13 -1 19 68 40 0
-12 -1 19 68 40 0
-11 -1 19 68 40 0
-10 -1 19 68 40 0
-9 -1 19 68 40 0
-8 -1 19 68 40 0
-7 -1 19 68 40 0
-6 -1 19 68 40 0
-5 -1 19 68 40 0
-4 -1 19 68 40 0
-3 -1 19 68 40 0
-2 -1 19 68 40 0
-1 -1 19 68 40 0
0 -1 19 68 40 0
1 -1 19 68 40 0
2 -1 19 68 40 0
3 -1 19 68 40 0
4 -1 19 68 40 0
5 -1 19 68 40 0
6 -1 19 68 40 0
7 -1 19 68 40 0
8 -1 19 68 40 0
9 -1 19 68 40 0
10 -1 19 68 40 0
11 -1 19 68 40 0
12 -1 19 68 40 0
13 -1 19 68 40 0
14 -1 19 68 40 0
-15 0 19 68 40 0
-14 0 19 68 40 0
-13 0 19 68 40 0
-12 0 19 68 40 0
-11 0 19 68 40 0
-10 0 19 68 40 0
-9 0 19 68 40 0
-8 0 19 68 40 0
-7 0 19 68 40 0
-6 0 19 68 40 0
-5 0 19 68 40 0
-4 0 19 68 40 0
-3 0 19 68 40 0
-2 0 19 68 40 0
-1 0 19 68 40 0
0 0 19 68 40 0
1 0 19 68 40 0
2 0 19 68 40 0
3 0 19 68 40 0
4 0 19 68 40 0
5 0 19 68 40 0
6 0 19 68 40 0
7 0 19 68 40 0
8 0 19 68 40 0
9 0 19 68 40 0
10 0 19 68 40 0
11 0 19 68 40 0
12 0 19 68 40 0
13 0 19 68 40 0
14 0 19 68 40 0
-15 1 19 68 40 0
-14 1 19 68 40 0
-13 1 19 68 40 0
-12 1 19 68 40 0
-11 1 19 68 40 0
-10 1 19 68 40 0
-9 1 19 68 40 0
-8 1 19 68 40 0
-7 1 19 68 40 0
-6 1 19 68 40 0
-5 1 19 68 40 0
-4 1 19 68 40 0
-3 1 19 68 40 0
-2 1 19 68 40 0
-1 1 19 68 40 0
0 1 19 68 40 0
1 1 19 68 40 0
2 1 19 68 40 0
3 1 19 68 40 0
4 1 19 68 40 0
5 1 19 68 40 0
6 1 19 68 40 0
7 1 19 68 40 0
8 1 19 68 40 0
9 1 19 68 40 0
10 1 19 68 40 0
11 1 19 68 40 0
12 1 19 68 40 0
13 1 19 68 40 0
14 1 19 68 40 0
-15 2 19 68 40 0
-14 2 19 68 40 0
-13 2 19 68 40 0
-12 2 19 68 40 0
-11 2 19 68 40 0
-10 2 19 68 40 0
-9 2 19 68 40 0
-8 2 19 68 40 0
-7 2 19 68 40 0
-6 2 19 68 40 0
-5 2 19 68 40 0
-4 2 19 68 40 0
-3 2 19 68 40 0
-2 2 19 68 40 0
-1 2 19 68 40 0
0 2 19 68 40 0
1 2 19 68 40 0
2 2 19 68 40 0
3 2 19 68 40 0
4 2 19 68 40 0
5 2 19 68 40 0
6 2 19 68 40 0
7 2 19 68 40 0
8 2 19 68 40 0
9 2 19 68 40 0
10 2 19 68 40 0
11 2 19 68 40 0
12 2 19 68 40 0
13 2 19 68 40 0
14 2 19 68 40 0
-15 3 19 68 40 0
-14 3 19 68 40 0
-13 3 19 68 40 0
-12 3 19 68 40 0
-11 3 19 68 40 0
-10 3 19 68 40 0
-9 3 19 68 40 0
-8 3 19 68 40 0
-7 3 19 68 40 0
-6 3 19 68 40 0
-5 3 19 68 40 0
-4 3 19 68 40 0
-3 3 19 68 40 0
-2 3 19 68 40 0
-1 3 19 68 40 0
0 3 19 68 40 0
1 3 19 68 40 0
2 3 19 68 40 0
3 3 19 68 40 0
4 3 19 68 40 0
5 3 19 68 40 0
6 3 19 68 40 0
7 3 19 68 40 0
8 3 19 68 40 0
9 3 19 68 40 0
10 3 19 68 40 0
11 3 19 68 40 0
12 3 19 68 40 0
13 3 19 68 40 0
14 3 19 68 40 0
-15 4 19 68 40 0
-14 4 19 68 40 0
-13 4 19 68 40 0
-12 4 19 68 40 0
-11 4 19 68 40 0
-10 4 19 68 40 0
-9 4 19 68 40 0
-8 4 19 68 40 0
-7 4 19 68 40 0
-6 4 19 68 40 0
-5 4 19 68 40 0
-4 4 19 68 40 0
-3 4 19 68 40 0
-2 4 19 68 40 0
-1 4 19 68 40 0
0 4 19 68 40 0
1 4 19 68 40 0
2 4 19 68 40 0
3 4 19 68 40 0
4 4 19 68 40 0
5 4 19 68 40 0
6 4 19 68 40 0
7 4 19 68 40 0
8 4 19 68 40 0
9 4 19 68 40 0
10 4 19 68 40 0
11 4 19 68 40 0
12 4 19 68 40 0
13 4 19 68 40 0
14 4 19 68 40 0
-15 5 19 68 40 0
-14 5 19 68 40 0
-13 5 19 68 40 0
-12 5 19 68 40 0
-11 5 19 68 40 0
-10 5 19 68 40 0
-9 5 19 68 40 0
-8 5 19 68 40 0
-7 5 19 68 40 0
-6 5 19 68 40 0
-5 5 19 68 40 0
-4 5 19 68 40 0
-3 5 19 68 40 0
-2 5 19 68 40 0
-1 5 19 68 40 0
0 5 19 68 40 0
1 5 19 68 40 0
2 5 19 68 40 0
3 5 19 68 40 0
4 5 19 68 40 0
5 5 19 68 40 0
6 5 19 68 40 0
7 5 19 68 40 0
8 5 19 68 40 0
9 5 19 68 40 0
10 5 19 68 40 0
11 5 19 68 40 0
12 5 19 68 40 0
13 5 19 68 40 0
14 5 19 68 40 0
-15 6 19 68 40 0
-14 6 19 68 40 0
-13 6 19 68 40 0
-12 6 19 68 40 0
-11 6 19 68 40 0
-10 6 19 68 40 0
-9 6 19 68 40 0
-8 6 19 68 40 0
-7 6 19 68 40 0
-6 6 19 68 40 0
-5 6 19 68 40 0
-4 6 19 68 40 0
-3 6 19 68 40 0
-2 6 19 68 40 0
-1 6 19 68 40 0
0 6 19 68 40 0
1 6 19 68 40 0
2 6 19 68 40 0
3 6 19 68 40 0
4 6 19 68 40 0
5 6 19 68 40 0
6 6 19 68 40 0
7 6 19 68 40 0
8 6 19 68 40 0
9 6 19 68 40 0
10 6 19 68 40 0
11 6 19 68 40 0
12 6 19 68 40 0
13 6 19 68 40 0
14 6 19 68 40 0
-15 7 19 68 40 0
-14 7 19 68 40 0
-13 7 19 68 40 0
-12 7 19 68 40 0
-11 7 19 68 40 0
-10 7 19 68 40 0
-9 7 19 68 40 0
-8 7 19 68 40 0
-7 7 19 68 40 0
-6 7 19 68 40 0
-5 7 19 68 40 0
-4 7 19 68 40 0
-3 7 19 68 40 0
-2 7 19 68 40 0
-1 7 19 68 40 0
0 7 19 68 40 0
1 7 19 68 40 0
2 7 19 68 40 0
3 7 19 68 40 0
4 7 19 68 40 0
5 7 19 68 40 0
6 7 19 68 40 0
7 7 19 68 40 0
8 7 19 68 40 0
9 7 19 68 40 0
10 7 19 68 40 0
11 7 19 68 40 0
12 7 19 68 40 0
13 7 19 68 40 0
14 7 19 68 40 0
-15 8 19 68 40 0
-14 8 19 68 40 0
-13 8 19 68 40 0
-12 8 19 68 40 0
-11 8 19 68 40 0
-10 8 19 68 40 0
-9 8 19 68 40 0
-8 8 19 68 40 0
-7 8 19 68 40 0
-6 8 19 68 40 0
-5 8 19 68 40 0
-4 8 19 68 40 0
-3 8 19 68 40 0
-2 8 19 68 40 0
-1 8 19 68 40 0
0 8 19 68 40 0
1 8 19 68 40 0
2 8 19 68 40 0
3 8 19 68 40 0
4 8 19 68 40 0
5 8 19 68 40 0
6 8 19 68 40 0
7 8 19 68 40 0
8 8 19 68 40 0
9 8 19 68 40 0
10 8 19 68 40 0
11 8 19 68 40 0
12 8 19 68 40 0
13 8 19 68 40 0
14 8 19 68 40 0
-15 9 19 68 40 0
-14 9 19 68 40 0
-13 9 19 68 40 0
-12 9 19 68 40 0
-11 9 19 68 40 0
-10 9 19 68 40 0
-9 9 19 68 40 0
-8 9 19 68 40 0
