ply
format ascii 1.0
comment : MagicaVoxel @ Ephtracy
element vertex 128
property float x
property float y
property float z
property uchar red
property uchar green
property uchar blue
end_header
-1 -1 0 153 102 0
0 -1 0 153 102 0
-1 0 0 153 102 0
0 0 0 153 102 0
-1 -1 1 153 102 0
0 -1 1 153 102 0
-1 0 1 153 102 0
0 0 1 153 102 0
-1 -1 2 153 102 0
0 -1 2 153 102 0
-1 0 2 153 102 0
0 0 2 153 102 0
-3 -3 3 0 102 0
-2 -3 3 0 102 0
-1 -3 3 0 102 0
0 -3 3 0 102 0
1 -3 3 0 102 0
2 -3 3 0 102 0
-3 -2 3 0 102 0
-2 -2 3 0 102 0
-1 -2 3 0 102 0
0 -2 3 0 102 0
1 -2 3 0 102 0
2 -2 3 0 102 0
-3 -1 3 0 102 0
-2 -1 3 0 102 0
-1 -1 3 153 102 0
0 -1 3 153 102 0
1 -1 3 0 102 0
2 -1 3 0 102 0
-3 0 3 0 102 0
-2 0 3 0 102 0
-1 0 3 153 102 0
0 0 3 153 102 0
1 0 3 0 102 0
2 0 3 0 102 0
-3 1 3 0 102 0
-2 1 3 0 102 0
-1 1 3 0 102 0
0 1 3 0 102 0
1 1 3 0 102 0
2 1 3 0 102 0
-3 2 3 0 102 0
-2 2 3 0 102 0
-1 2 3 0 102 0
0 2 3 0 102 0
1 2 3 0 102 0
2 2 3 0 102 0
-3 -3 4 0 102 0
-2 -3 4 0 102 0
-1 -3 4 0 102 0
0 -3 4 0 102 0
1 -3 4 0 102 0
2 -3 4 0 102 0
-3 -2 4 0 102 0
-2 -2 4 0 102 0
-1 -2 4 0 102 0
0 -2 4 0 102 0
1 -2 4 0 102 0
2 -2 4 0 102 0
-3 -1 4 0 102 0
-2 -1 4 0 102 0
-1 -1 4 153 102 0
0 -1 4 153 102 0
1 -1 4 0 102 0
2 -1 4 0 102 0
-3 0 4 0 102 0
-2 0 4 0 102 0
-1 0 4 153 102 0
0 0 4 153 102 0
1 0 4 0 102 0
2 0 4 0 102 0
-3 1 4 0 102 0
-2 1 4 0 102 0
-1 1 4 0 102 0
0 1 4 0 102 0
1 1 4 0 102 0
2 1 4 0 102 0
-3 2 4 0 102 0
-2 2 4 0 102 0
-1 2 4 0 102 0
0 2 4 0 102 0
1 2 4 0 102 0
2 2 4 0 102 0
-1 -3 5 0 102 0
0 -3 5 0 102 0
-1 -2 5 0 102 0
0 -2 5 0 102 0
-3 -1 5 0 102 0
-2 -1 5 0 102 0
-1 -1 5 153 102 0
0 -1 5 153 102 0
1 -1 5 0 102 0
2 -1 5 0 102 0
-3 0 5 0 102 0
-2 0 5 0 102 0
-1 0 5 153 102 0
0 0 5 153 102 0
1 0 5 0 102 0
2 0 5 0 102 0
-1 1 5 0 102 0
0 1 5 0 102 0
-1 2 5 0 102 0
0 2 5 0 102 0
-1 -3 6 0 102 0
0 -3 6 0 102 0
-1 -2 6 0 102 0
0 -2 6 0 102 0
-3 -1 6 0 102 0
-2 -1 6 0 102 0
-1 -1 6 0 102 0
0 -1 6 0 102 0
1 -1 6 0 102 0
2 -1 6 0 102 0
-3 0 6 0 102 0
-2 0 6 0 102 0
-1 0 6 0 102 0
0 0 6 0 102 0
1 0 6 0 102 0
2 0 6 0 102 0
-1 1 6 0 102 0
0 1 6 0 102 0
-1 2 6 0 102 0
0 2 6 0 102 0
-1 -1 7 0 102 0
0 -1 7 0 102 0
-1 0 7 0 102 0
0 0 7 0 102 0
