ply
format ascii 1.0
comment : MagicaVoxel @ Ephtracy
element vertex 222
property float x
property float y
property float z
property uchar red
property uchar green
property uchar blue
end_header
-5 -5 0 160 132 68
-4 -5 0 132 104 48
-3 -5 0 100 72 24
-2 -5 0 160 132 68
-1 -5 0 132 104 48
0 -5 0 100 72 24
1 -5 0 160 132 68
2 -5 0 132 104 48
3 -5 0 100 72 24
4 -5 0 132 104 48
-5 -4 0 160 132 68
-4 -4 0 132 104 48
-3 -4 0 100 72 24
-2 -4 0 160 132 68
-1 -4 0 132 104 48
0 -4 0 100 72 24
1 -4 0 160 132 68
2 -4 0 132 104 48
3 -4 0 100 72 24
4 -4 0 132 104 48
-5 -3 0 160 132 68
-4 -3 0 132 104 48
-3 -3 0 100 72 24
-2 -3 0 160 132 68
-1 -3 0 132 104 48
0 -3 0 100 72 24
1 -3 0 160 132 68
2 -3 0 132 104 48
3 -3 0 100 72 24
4 -3 0 132 104 48
-5 -2 0 160 132 68
-4 -2 0 132 104 48
-3 -2 0 100 72 24
-2 -2 0 100 72 24
-1 -2 0 100 72 24
0 -2 0 100 72 24
1 -2 0 160 132 68
2 -2 0 132 104 48
3 -2 0 100 72 24
4 -2 0 132 104 48
-5 -1 0 160 132 68
-4 -1 0 132 104 48
-3 -1 0 100 72 24
-2 -1 0 160 132 68
-1 -1 0 160 132 68
0 -1 0 100 72 24
1 -1 0 160 132 68
2 -1 0 132 104 48
3 -1 0 100 72 24
4 -1 0 132 104 48
-5 0 0 160 132 68
-4 0 0 132 104 48
-3 0 0 100 72 24
-2 0 0 160 132 68
-1 0 0 132 104 48
0 0 0 100 72 24
1 0 0 160 132 68
2 0 0 132 104 48
3 0 0 100 72 24
4 0 0 132 104 48
-5 1 0 160 132 68
-4 1 0 132 104 48
-3 1 0 100 72 24
-2 1 0 160 132 68
-1 1 0 132 104 48
0 1 0 100 72 24
1 1 0 100 72 24
2 1 0 100 72 24
3 1 0 100 72 24
4 1 0 132 104 48
-5 2 0 100 72 24
-4 2 0 100 72 24
-3 2 0 100 72 24
-2 2 0 160 132 68
-1 2 0 132 104 48
0 2 0 100 72 24
1 2 0 160 132 68
2 2 0 160 132 68
3 2 0 100 72 24
4 2 0 132 104 48
-5 3 0 160 132 68
-4 3 0 160 132 68
-3 3 0 100 72 24
-2 3 0 160 132 68
-1 3 0 132 104 48
0 3 0 100 72 24
1 3 0 160 132 68
2 3 0 132 104 48
3 3 0 100 72 24
4 3 0 132 104 48
-5 4 0 160 132 68
-4 4 0 132 104 48
-3 4 0 100 72 24
-2 4 0 160 132 68
-1 4 0 132 104 48
0 4 0 100 72 24
1 4 0 160 132 68
2 4 0 132 104 48
3 4 0 100 72 24
4 4 0 132 104 48
4 -5 1 64 64 64
4 -4 1 64 64 64
4 -3 1 64 64 64
4 -2 1 64 64 64
4 -1 1 64 64 64
4 0 1 64 64 64
4 1 1 64 64 64
4 2 1 64 64 64
4 3 1 64 64 64
4 4 1 64 64 64
3 -5 2 108 108 108
4 -5 2 64 64 64
4 -4 2 64 64 64
3 -3 2 108 108 108
4 -3 2 64 64 64
3 -2 2 108 108 108
4 -2 2 64 64 64
3 -1 2 108 108 108
4 -1 2 64 64 64
3 0 2 108 108 108
4 0 2 64 64 64
4 1 2 64 64 64
3 2 2 108 108 108
4 2 2 64 64 64
3 3 2 108 108 108
4 3 2 64 64 64
3 4 2 108 108 108
4 4 2 64 64 64
4 -5 3 64 64 64
4 -4 3 64 64 64
4 -3 3 64 64 64
4 -2 3 64 64 64
4 -1 3 64 64 64
4 0 3 64 64 64
4 1 3 64 64 64
4 2 3 64 64 64
4 3 3 64 64 64
4 4 3 64 64 64
3 -5 4 108 108 108
4 -5 4 64 64 64
3 -4 4 108 108 108
4 -4 4 64 64 64
3 -3 4 108 108 108
4 -3 4 64 64 64
3 -2 4 108 108 108
4 -2 4 64 64 64
4 -1 4 64 64 64
3 0 4 108 108 108
4 0 4 64 64 64
3 1 4 108 108 108
4 1 4 64 64 64
3 2 4 108 108 108
4 2 4 64 64 64
3 3 4 108 108 108
4 3 4 64 64 64
4 4 4 64 64 64
4 -5 5 64 64 64
4 -4 5 64 64 64
4 -3 5 64 64 64
4 -2 5 64 64 64
4 -1 5 64 64 64
4 0 5 64 64 64
4 1 5 64 64 64
4 2 5 64 64 64
4 3 5 64 64 64
4 4 5 64 64 64
3 -5 6 108 108 108
4 -5 6 64 64 64
4 -4 6 64 64 64
3 -3 6 108 108 108
4 -3 6 64 64 64
3 -2 6 108 108 108
4 -2 6 64 64 64
3 -1 6 108 108 108
4 -1 6 64 64 64
3 0 6 108 108 108
4 0 6 64 64 64
4 1 6 64 64 64
3 2 6 108 108 108
4 2 6 64 64 64
3 3 6 108 108 108
4 3 6 64 64 64
3 4 6 108 108 108
4 4 6 64 64 64
4 -5 7 64 64 64
4 -4 7 64 64 64
4 -3 7 64 64 64
4 -2 7 64 64 64
4 -1 7 64 64 64
4 0 7 64 64 64
4 1 7 64 64 64
4 2 7 64 64 64
4 3 7 64 64 64
4 4 7 64 64 64
3 -5 8 108 108 108
4 -5 8 64 64 64
3 -4 8 108 108 108
4 -4 8 64 64 64
3 -3 8 108 108 108
4 -3 8 64 64 64
3 -2 8 108 108 108
4 -2 8 64 64 64
4 -1 8 64 64 64
3 0 8 108 108 108
4 0 8 64 64 64
3 1 8 108 108 108
4 1 8 64 64 64
3 2 8 108 108 108
4 2 8 64 64 64
3 3 8 108 108 108
4 3 8 64 64 64
4 4 8 64 64 64
4 -5 9 64 64 64
4 -4 9 64 64 64
4 -3 9 64 64 64
4 -2 9 64 64 64
4 -1 9 64 64 64
4 0 9 64 64 64
4 1 9 64 64 64
4 2 9 64 64 64
4 3 9 64 64 64
4 4 9 64 64 64
